{"e": "depthUpdate", "E": 1780300157195, "s": "SOLUSDT", "U": 29045644173, "u": 29045644192, "b": [["80.75000000", "1326.07000000"], ["80.74000000", "659.21200000"], ["80.73000000", "612.43900000"], ["80.67000000", "2425.41300000"], ["80.65000000", "1138.85900000"], ["78.73000000", "30.64700000"]], "a": [["80.76000000", "433.11600000"], ["80.77000000", "191.58300000"], ["80.78000000", "428.64200000"], ["80.79000000", "168.95800000"], ["80.80000000", "678.28100000"], ["80.81000000", "2191.56600000"], ["80.82000000", "87.37400000"], ["80.84000000", "409.56300000"], ["80.85000000", "1376.10400000"]], "_local_ts_utc": "2026-06-01T07:49:16.091141+00:00"}
{"e": "depthUpdate", "E": 1780300157295, "s": "SOLUSDT", "U": 29045644193, "u": 29045644223, "b": [["80.75000000", "1330.27000000"], ["80.74000000", "650.45600000"], ["80.73000000", "612.75400000"], ["80.55000000", "3149.05800000"], ["80.45000000", "1098.29800000"], ["80.41000000", "82.11300000"], ["80.40000000", "540.47800000"], ["80.31000000", "218.87900000"], ["79.54000000", "57.28400000"], ["79.13000000", "28.61300000"], ["78.73000000", "33.81600000"]], "a": [["80.76000000", "222.22800000"], ["80.78000000", "425.22900000"], ["80.79000000", "124.85200000"], ["80.81000000", "2234.14300000"], ["80.82000000", "237.30500000"], ["80.85000000", "1206.30400000"], ["80.87000000", "207.40800000"], ["81.03000000", "97.55300000"], ["81.04000000", "682.57800000"], ["81.09000000", "1062.38100000"]], "_local_ts_utc": "2026-06-01T07:49:16.192394+00:00"}
{"e": "depthUpdate", "E": 1780300157395, "s": "SOLUSDT", "U": 29045644224, "u": 29045644457, "b": [["80.76000000", "1228.15800000"], ["80.75000000", "530.92500000"], ["80.74000000", "580.45700000"], ["80.73000000", "629.83000000"], ["80.72000000", "506.55200000"], ["80.71000000", "984.10400000"], ["80.70000000", "2071.75700000"], ["80.69000000", "464.48100000"], ["80.66000000", "165.42300000"], ["80.60000000", "1454.28200000"], ["80.59000000", "785.29000000"], ["80.58000000", "2075.46300000"], ["80.56000000", "723.35400000"], ["80.55000000", "3148.96500000"], ["80.37000000", "40.07700000"], ["80.33000000", "74.80100000"], ["80.07000000", "438.46300000"], ["80.00000000", "23864.66000000"], ["79.99000000", "63.99000000"], ["79.56000000", "496.90400000"], ["79.55000000", "377.91000000"], ["79.14000000", "21.21600000"], ["79.13000000", "31.76600000"]], "a": [["80.76000000", "0.00000000"], ["80.77000000", "460.91800000"], ["80.78000000", "190.09100000"], ["80.79000000", "472.16600000"], ["80.80000000", "375.75300000"], ["80.81000000", "700.24600000"], ["80.82000000", "248.15900000"], ["80.83000000", "552.40400000"], ["80.84000000", "1728.72300000"], ["80.85000000", "858.00600000"], ["80.86000000", "555.35100000"], ["80.87000000", "377.67500000"], ["80.88000000", "1206.24300000"], ["80.89000000", "856.27200000"], ["80.92000000", "744.09400000"], ["80.97000000", "262.26900000"], ["80.98000000", "924.25600000"], ["81.08000000", "6.30800000"], ["81.52000000", "7.44200000"]], "_local_ts_utc": "2026-06-01T07:49:16.292066+00:00"}
{"e": "depthUpdate", "E": 1780300157495, "s": "SOLUSDT", "U": 29045644458, "u": 29045644510, "b": [["80.76000000", "1008.66400000"], ["80.75000000", "579.89100000"], ["80.74000000", "764.74700000"], ["80.73000000", "552.36000000"], ["80.72000000", "504.48800000"], ["80.71000000", "982.04100000"], ["80.69000000", "464.18100000"]], "a": [["80.77000000", "462.98400000"], ["80.78000000", "189.12200000"], ["80.79000000", "537.69000000"], ["80.81000000", "731.46700000"], ["80.82000000", "364.58000000"], ["80.84000000", "1728.58700000"], ["80.85000000", "746.72500000"], ["80.87000000", "377.60700000"], ["80.89000000", "864.43000000"], ["81.09000000", "1062.30200000"], ["81.11000000", "47.12100000"], ["81.33000000", "62.49300000"], ["81.35000000", "6.75100000"], ["81.55000000", "6.63700000"], ["81.57000000", "6.94100000"]], "_local_ts_utc": "2026-06-01T07:49:16.391903+00:00"}
{"e": "depthUpdate", "E": 1780300157595, "s": "SOLUSDT", "U": 29045644511, "u": 29045644535, "b": [["80.76000000", "1028.81900000"], ["80.75000000", "577.82800000"], ["80.74000000", "763.08400000"], ["80.73000000", "436.81700000"], ["80.72000000", "506.75200000"], ["80.71000000", "984.30400000"], ["80.69000000", "464.38100000"], ["80.56000000", "1126.68400000"], ["80.54000000", "170.37500000"], ["79.04000000", "5.94600000"], ["78.63000000", "18.18400000"]], "a": [["80.77000000", "460.94500000"], ["80.78000000", "100.20500000"], ["80.79000000", "190.81900000"], ["80.80000000", "724.03800000"], ["80.81000000", "732.49800000"], ["80.82000000", "365.61100000"]], "_local_ts_utc": "2026-06-01T07:49:16.491799+00:00"}
{"e": "depthUpdate", "E": 1780300157695, "s": "SOLUSDT", "U": 29045644536, "u": 29045644567, "b": [["80.75000000", "579.89100000"], ["80.74000000", "765.20900000"], ["80.72000000", "504.68800000"], ["80.71000000", "982.30300000"], ["80.69000000", "464.44300000"], ["80.68000000", "1106.99800000"], ["80.52000000", "140.54600000"], ["80.46000000", "1522.65200000"]], "a": [["80.77000000", "466.80900000"], ["80.78000000", "107.62300000"], ["80.79000000", "191.85000000"], ["80.81000000", "731.46700000"], ["80.82000000", "364.58000000"], ["80.84000000", "1728.72300000"], ["80.88000000", "1206.33600000"], ["81.02000000", "44.34500000"], ["81.04000000", "682.64000000"]], "_local_ts_utc": "2026-06-01T07:49:16.591750+00:00"}
{"e": "depthUpdate", "E": 1780300157795, "s": "SOLUSDT", "U": 29045644568, "u": 29045644685, "b": [["80.76000000", "423.19500000"], ["80.75000000", "671.41800000"], ["80.74000000", "755.20900000"], ["80.69000000", "464.57900000"], ["80.67000000", "2425.61300000"], ["80.66000000", "627.77800000"], ["80.65000000", "2527.79900000"], ["80.64000000", "2478.60800000"], ["80.63000000", "270.13800000"], ["80.50000000", "2725.91600000"], ["78.63000000", "15.01100000"], ["78.22000000", "30.33200000"]], "a": [["80.77000000", "567.63300000"], ["80.78000000", "217.46100000"], ["80.79000000", "235.17200000"], ["80.81000000", "677.99300000"], ["80.82000000", "248.12000000"], ["80.84000000", "1728.58700000"], ["80.86000000", "215.25300000"], ["80.87000000", "1703.98700000"], ["80.88000000", "711.20900000"], ["80.89000000", "183.73800000"], ["81.11000000", "47.36800000"]], "_local_ts_utc": "2026-06-01T07:49:16.691880+00:00"}
{"e": "depthUpdate", "E": 1780300157895, "s": "SOLUSDT", "U": 29045644686, "u": 29045644745, "b": [["80.76000000", "116.48800000"], ["80.75000000", "590.37600000"], ["80.74000000", "755.34100000"], ["80.73000000", "438.49700000"], ["80.71000000", "986.18500000"], ["80.68000000", "1107.13400000"], ["80.67000000", "2656.11200000"], ["80.66000000", "978.78800000"], ["80.65000000", "2057.52300000"], ["80.64000000", "2035.13600000"], ["80.63000000", "537.40700000"], ["80.52000000", "88.96600000"]], "a": [["80.77000000", "635.31800000"], ["80.78000000", "177.70400000"], ["80.85000000", "647.14100000"], ["80.86000000", "460.25500000"]], "_local_ts_utc": "2026-06-01T07:49:16.791750+00:00"}
{"e": "depthUpdate", "E": 1780300157995, "s": "SOLUSDT", "U": 29045644746, "u": 29045644754, "b": [["80.69000000", "435.34700000"], ["80.64000000", "2034.76400000"], ["80.40000000", "542.21300000"], ["78.63000000", "11.83800000"]], "a": [["80.77000000", "637.40000000"], ["80.78000000", "177.70400000"], ["80.79000000", "235.17200000"], ["80.80000000", "723.00700000"], ["80.82000000", "247.12800000"]], "_local_ts_utc": "2026-06-01T07:49:16.890879+00:00"}
{"e": "depthUpdate", "E": 1780300158095, "s": "SOLUSDT", "U": 29045644755, "u": 29045644770, "b": [["80.76000000", "218.88100000"], ["80.75000000", "590.51200000"], ["80.74000000", "755.41000000"], ["80.70000000", "2072.05700000"], ["80.68000000", "1106.99800000"], ["80.65000000", "1964.92700000"], ["80.63000000", "630.00300000"], ["80.61000000", "2335.71700000"], ["80.25000000", "78.32700000"], ["80.24000000", "42.07600000"], ["79.11000000", "11.31500000"], ["79.03000000", "11.36400000"], ["79.02000000", "113.31800000"], ["78.63000000", "8.66500000"]], "a": [["80.78000000", "130.83500000"]], "_local_ts_utc": "2026-06-01T07:49:16.991873+00:00"}
{"e": "depthUpdate", "E": 1780300158195, "s": "SOLUSDT", "U": 29045644771, "u": 29045644781, "b": [["80.76000000", "284.31100000"], ["80.74000000", "758.90200000"], ["80.73000000", "436.81700000"], ["79.55000000", "381.04700000"]], "a": [["80.77000000", "637.40000000"], ["80.78000000", "154.51300000"]], "_local_ts_utc": "2026-06-01T07:49:17.091872+00:00"}
{"e": "depthUpdate", "E": 1780300158295, "s": "SOLUSDT", "U": 29045644782, "u": 29045644847, "b": [["80.76000000", "104.70900000"], ["80.75000000", "302.26500000"], ["80.74000000", "878.47000000"], ["80.73000000", "423.23400000"], ["80.72000000", "519.28200000"], ["80.70000000", "2075.93900000"], ["80.68000000", "1107.13400000"], ["80.67000000", "2390.47100000"], ["80.66000000", "701.37500000"], ["80.64000000", "2312.42700000"], ["80.62000000", "533.16500000"], ["79.71000000", "46.35400000"], ["79.04000000", "2.78900000"], ["79.02000000", "110.16000000"], ["78.62000000", "32.10500000"]], "a": [["80.77000000", "676.10000000"], ["80.78000000", "145.74400000"], ["80.79000000", "281.07200000"], ["80.81000000", "699.41700000"], ["80.85000000", "604.53400000"]], "_local_ts_utc": "2026-06-01T07:49:17.191882+00:00"}
{"e": "depthUpdate", "E": 1780300158395, "s": "SOLUSDT", "U": 29045644848, "u": 29045645177, "b": [["80.76000000", "0.00000000"], ["80.75000000", "0.00000000"], ["80.74000000", "251.71400000"], ["80.73000000", "503.66700000"], ["80.72000000", "464.83500000"], ["80.71000000", "843.30700000"], ["80.70000000", "2077.52100000"], ["80.69000000", "439.22900000"], ["80.68000000", "1109.19800000"], ["80.67000000", "2319.73000000"], ["80.66000000", "204.54300000"], ["80.65000000", "1131.56300000"], ["80.64000000", "2494.13500000"], ["80.63000000", "1234.27400000"], ["80.62000000", "1089.23700000"], ["80.58000000", "2199.70600000"], ["80.52000000", "86.84100000"], ["80.50000000", "2728.04100000"], ["80.00000000", "23864.72300000"], ["79.14000000", "24.36900000"]], "a": [["80.75000000", "1392.15600000"], ["80.76000000", "808.71600000"], ["80.77000000", "763.54900000"], ["80.78000000", "95.75700000"], ["80.79000000", "125.21000000"], ["80.80000000", "370.50200000"], ["80.81000000", "652.87400000"], ["80.82000000", "97.06100000"], ["80.83000000", "581.50000000"], ["80.84000000", "1864.67900000"], ["80.97000000", "138.60000000"], ["81.16000000", "42.01700000"]], "_local_ts_utc": "2026-06-01T07:49:17.291883+00:00"}
{"e": "depthUpdate", "E": 1780300158495, "s": "SOLUSDT", "U": 29045645178, "u": 29045645345, "b": [["80.74000000", "0.00000000"], ["80.73000000", "463.99200000"], ["80.72000000", "609.93000000"], ["80.71000000", "843.30300000"], ["80.70000000", "2074.12200000"], ["80.69000000", "439.35600000"], ["80.68000000", "1107.13400000"], ["80.66000000", "204.67900000"], ["80.65000000", "983.33600000"], ["80.64000000", "2528.94900000"], ["80.62000000", "1181.83300000"], ["80.60000000", "1453.75700000"], ["80.58000000", "2241.41500000"], ["80.57000000", "404.85000000"], ["80.56000000", "1064.03000000"], ["80.34000000", "33.37800000"], ["80.33000000", "75.01800000"], ["79.99000000", "64.05300000"], ["79.97000000", "25.75200000"]], "a": [["80.74000000", "1026.62400000"], ["80.75000000", "894.76000000"], ["80.76000000", "704.88200000"], ["80.77000000", "730.45700000"], ["80.78000000", "93.27900000"], ["80.79000000", "125.06800000"], ["80.80000000", "363.49800000"], ["80.81000000", "650.69100000"], ["80.86000000", "413.73700000"], ["80.89000000", "183.67000000"], ["80.90000000", "256.86500000"], ["80.93000000", "161.32400000"], ["81.11000000", "47.28900000"], ["81.14000000", "44.51300000"], ["81.18000000", "270.81900000"], ["81.33000000", "62.58300000"], ["81.35000000", "6.66100000"], ["81.50000000", "24.80200000"], ["81.51000000", "2.45200000"], ["81.52000000", "7.37900000"], ["81.55000000", "7.25800000"], ["81.57000000", "6.56400000"]], "_local_ts_utc": "2026-06-01T07:49:17.391953+00:00"}
