{"e": "depthUpdate", "E": 1780300151315, "s": "ETHUSDT", "U": 76583120947, "u": 76583121034, "b": [["1972.80000000", "41.98130000"], ["1972.79000000", "0.00770000"], ["1972.78000000", "0.01310000"], ["1972.77000000", "3.00260000"], ["1972.73000000", "1.18160000"], ["1972.68000000", "0.00000000"], ["1972.67000000", "0.00000000"], ["1972.66000000", "0.00000000"], ["1972.63000000", "0.01130000"], ["1972.62000000", "3.33700000"], ["1972.61000000", "2.12880000"], ["1972.60000000", "9.73950000"], ["1972.57000000", "0.00000000"], ["1972.51000000", "15.92410000"], ["1972.43000000", "0.08300000"], ["1972.24000000", "1.91840000"], ["1972.17000000", "0.28560000"], ["1971.82000000", "7.36540000"], ["1971.75000000", "7.09840000"], ["1970.25000000", "17.89610000"], ["1970.17000000", "0.27260000"], ["1970.08000000", "1.01830000"], ["1969.91000000", "0.28610000"], ["1966.99000000", "1.02970000"], ["1966.79000000", "0.00000000"], ["1966.17000000", "0.34800000"], ["1965.01000000", "1.00000000"], ["1963.04000000", "1.00840000"], ["1943.40000000", "0.00900000"], ["1775.52000000", "0.41860000"]], "a": [["1972.81000000", "21.27500000"], ["1972.89000000", "1.70470000"], ["1972.90000000", "0.01110000"], ["1972.91000000", "2.47740000"], ["1972.95000000", "0.00000000"], ["1972.96000000", "6.56080000"], ["1973.04000000", "12.94130000"], ["1973.05000000", "22.57370000"], ["1973.06000000", "0.00000000"], ["1973.25000000", "0.00260000"], ["1973.32000000", "9.57970000"], ["1973.34000000", "0.05390000"], ["1973.55000000", "0.45900000"], ["1973.63000000", "0.00260000"], ["1973.70000000", "0.20570000"], ["1973.72000000", "0.40000000"], ["1973.79000000", "0.80000000"], ["1973.94000000", "1.50930000"], ["1974.54000000", "0.46280000"], ["1974.55000000", "0.62360000"], ["1974.62000000", "1.32300000"], ["1974.98000000", "4.19400000"], ["1977.50000000", "0.00000000"], ["1987.12000000", "0.03030000"]], "_local_ts_utc": "2026-06-01T07:49:10.211335+00:00"}
{"e": "depthUpdate", "E": 1780300151415, "s": "ETHUSDT", "U": 76583121035, "u": 76583121073, "b": [["1972.80000000", "34.74860000"], ["1972.69000000", "0.00260000"], ["1972.52000000", "29.80910000"], ["1972.51000000", "0.31140000"], ["1972.48000000", "0.03000000"], ["1972.23000000", "15.52740000"], ["1971.65000000", "10.24030000"], ["1971.05000000", "3.60000000"], ["1970.40000000", "2.23630000"], ["1970.21000000", "32.03950000"], ["1966.88000000", "5.64060000"], ["1913.45000000", "0.13040000"], ["1775.52000000", "0.43100000"]], "a": [["1972.81000000", "23.03480000"], ["1972.90000000", "0.00570000"], ["1972.91000000", "2.47200000"], ["1972.94000000", "0.00390000"], ["1973.32000000", "10.03870000"], ["1974.60000000", "1.27810000"], ["1975.20000000", "0.03310000"], ["1975.36000000", "0.00000000"]], "_local_ts_utc": "2026-06-01T07:49:10.312753+00:00"}
{"e": "depthUpdate", "E": 1780300151515, "s": "ETHUSDT", "U": 76583121074, "u": 76583121329, "b": [["1972.80000000", "0.00000000"], ["1972.79000000", "0.00000000"], ["1972.78000000", "0.00000000"], ["1972.77000000", "3.03550000"], ["1972.76000000", "0.00510000"], ["1972.75000000", "0.00510000"], ["1972.74000000", "0.00800000"], ["1972.73000000", "0.17900000"], ["1972.68000000", "0.00540000"], ["1972.67000000", "0.40910000"], ["1972.64000000", "0.00260000"], ["1972.63000000", "0.00850000"], ["1972.62000000", "0.01370000"], ["1972.61000000", "2.12340000"], ["1972.60000000", "0.10400000"], ["1972.59000000", "0.00000000"], ["1972.56000000", "0.00760000"], ["1972.55000000", "0.00540000"], ["1972.54000000", "3.60480000"], ["1972.53000000", "0.50700000"], ["1972.52000000", "0.00300000"], ["1972.51000000", "0.31140000"], ["1972.50000000", "17.24400000"], ["1972.47000000", "7.53380000"], ["1972.44000000", "6.46760000"], ["1972.42000000", "10.83950000"], ["1972.41000000", "5.30300000"], ["1972.37000000", "0.00000000"], ["1972.32000000", "0.03000000"], ["1972.31000000", "8.52100000"], ["1972.30000000", "24.23440000"], ["1972.25000000", "0.27260000"], ["1972.24000000", "2.17210000"], ["1972.21000000", "8.52600000"], ["1972.20000000", "3.21830000"], ["1972.13000000", "12.29290000"], ["1972.10000000", "0.00570000"], ["1972.04000000", "2.53770000"], ["1972.00000000", "0.17130000"], ["1971.86000000", "0.00690000"], ["1971.82000000", "8.86540000"], ["1971.80000000", "0.00570000"], ["1971.77000000", "13.17780000"], ["1971.59000000", "0.27000000"], ["1971.53000000", "0.20300000"], ["1971.48000000", "17.79470000"], ["1971.39000000", "9.47810000"], ["1971.38000000", "0.35460000"], ["1971.20000000", "21.26060000"], ["1971.10000000", "8.51600000"], ["1971.09000000", "0.80300000"], ["1970.82000000", "7.10380000"], ["1970.78000000", "3.11950000"], ["1970.71000000", "0.30820000"], ["1970.61000000", "7.09980000"], ["1970.52000000", "8.48180000"], ["1970.21000000", "31.76950000"], ["1970.10000000", "0.08750000"], ["1970.08000000", "1.04830000"], ["1969.49000000", "4.85360000"], ["1969.46000000", "13.52930000"], ["1967.60000000", "0.20590000"], ["1967.52000000", "36.83110000"], ["1945.57000000", "0.00980000"], ["1775.52000000", "0.40000000"], ["1775.50000000", "0.01690000"]], "a": [["1972.78000000", "81.38880000"], ["1972.79000000", "5.06460000"], ["1972.80000000", "4.98790000"], ["1972.81000000", "3.72570000"], ["1972.86000000", "6.47020000"], ["1972.87000000", "0.03560000"], ["1972.88000000", "0.01420000"], ["1972.91000000", "7.01830000"], ["1972.95000000", "21.29010000"], ["1972.96000000", "0.09320000"], ["1972.98000000", "1.85130000"], ["1973.03000000", "13.61760000"], ["1973.04000000", "35.51500000"], ["1973.05000000", "0.00000000"], ["1973.07000000", "8.53900000"], ["1973.22000000", "21.78780000"], ["1973.59000000", "13.68510000"], ["1973.61000000", "17.80080000"], ["1973.94000000", "0.00650000"], ["1974.42000000", "9.65650000"], ["1974.47000000", "0.02000000"], ["1974.60000000", "0.81910000"], ["1974.61000000", "0.00300000"], ["1974.67000000", "5.00260000"], ["1974.69000000", "0.00000000"], ["1974.83000000", "1.02040000"], ["1975.79000000", "1.90850000"], ["1976.78000000", "0.00260000"], ["1977.81000000", "0.00000000"], ["1977.83000000", "37.01640000"], ["1977.98000000", "0.00000000"], ["1978.41000000", "4.10180000"], ["1978.82000000", "0.00260000"], ["1980.59000000", "0.00000000"], ["1992.84000000", "0.02420000"]], "_local_ts_utc": "2026-06-01T07:49:10.411203+00:00"}
{"e": "depthUpdate", "E": 1780300151615, "s": "ETHUSDT", "U": 76583121330, "u": 76583121384, "b": [["1972.77000000", "1.93250000"], ["1972.76000000", "0.00770000"], ["1972.75000000", "0.00770000"], ["1972.69000000", "0.00260000"], ["1972.68000000", "0.00800000"], ["1972.64000000", "0.00000000"], ["1972.63000000", "0.00590000"], ["1972.62000000", "0.00570000"], ["1972.61000000", "0.12340000"], ["1972.55000000", "0.00000000"], ["1972.54000000", "0.01560000"], ["1972.52000000", "0.00840000"], ["1972.51000000", "0.31410000"], ["1972.39000000", "7.36700000"], ["1972.28000000", "13.51760000"], ["1972.19000000", "5.38120000"], ["1972.16000000", "0.58280000"], ["1972.14000000", "13.79130000"], ["1971.90000000", "9.33840000"], ["1971.68000000", "23.04720000"], ["1971.39000000", "9.07810000"], ["1970.25000000", "17.62610000"], ["1970.17000000", "0.00260000"], ["1969.55000000", "0.27000000"], ["1968.31000000", "0.57870000"], ["1967.78000000", "0.58590000"], ["1967.06000000", "0.00000000"], ["1923.45000000", "0.13280000"], ["1775.50000000", "0.02930000"]], "a": [["1972.78000000", "88.54040000"], ["1972.80000000", "5.01790000"], ["1972.91000000", "8.37490000"], ["1972.92000000", "1.32370000"], ["1973.29000000", "11.99060000"], ["1973.31000000", "0.49460000"], ["1973.50000000", "11.01020000"], ["1973.51000000", "8.92810000"], ["1973.55000000", "0.00000000"], ["1974.82000000", "0.54600000"], ["1974.85000000", "0.46160000"], ["1975.20000000", "0.00310000"]], "_local_ts_utc": "2026-06-01T07:49:10.511347+00:00"}
{"e": "depthUpdate", "E": 1780300151715, "s": "ETHUSDT", "U": 76583121385, "u": 76583121482, "b": [["1972.77000000", "1.73830000"], ["1972.76000000", "0.01550000"], ["1972.75000000", "0.01030000"], ["1972.71000000", "0.00260000"], ["1972.63000000", "0.00260000"], ["1972.62000000", "0.00000000"], ["1972.61000000", "0.00000000"], ["1972.52000000", "0.00840000"], ["1972.50000000", "0.61630000"], ["1972.49000000", "0.00000000"], ["1972.44000000", "0.00000000"], ["1972.42000000", "10.21300000"], ["1972.40000000", "0.00570000"], ["1972.32000000", "7.12670000"], ["1972.31000000", "22.71200000"], ["1972.28000000", "0.00000000"], ["1972.27000000", "0.00950000"], ["1972.22000000", "7.12970000"], ["1972.21000000", "15.62270000"], ["1972.17000000", "7.38230000"], ["1972.14000000", "0.27000000"], ["1972.09000000", "22.21140000"], ["1972.03000000", "13.61900000"], ["1971.68000000", "22.64720000"], ["1971.53000000", "0.00300000"], ["1971.34000000", "7.09930000"], ["1971.24000000", "1.40000000"], ["1971.23000000", "0.10000000"], ["1971.09000000", "0.00300000"], ["1971.02000000", "1.52330000"], ["1970.90000000", "8.51600000"], ["1970.62000000", "0.00260000"], ["1970.41000000", "1.02340000"], ["1970.32000000", "0.27710000"], ["1970.02000000", "68.67710000"], ["1969.91000000", "0.01610000"], ["1969.02000000", "0.21770000"], ["1775.50000000", "0.04170000"]], "a": [["1972.78000000", "88.53690000"], ["1972.85000000", "1.31550000"], ["1972.91000000", "9.01300000"], ["1973.01000000", "0.34000000"], ["1973.02000000", "20.71970000"], ["1973.04000000", "22.57890000"], ["1973.22000000", "21.14970000"], ["1973.34000000", "0.25390000"], ["1973.52000000", "8.33890000"], ["1973.70000000", "0.00570000"], ["1973.94000000", "0.17700000"], ["1974.30000000", "0.00000000"], ["1974.52000000", "0.00000000"], ["1974.83000000", "1.01780000"], ["2001.43000000", "0.06940000"]], "_local_ts_utc": "2026-06-01T07:49:10.611460+00:00"}
{"e": "depthUpdate", "E": 1780300151815, "s": "ETHUSDT", "U": 76583121483, "u": 76583121530, "b": [["1972.63000000", "0.00000000"], ["1972.58000000", "0.00000000"], ["1972.39000000", "13.33210000"], ["1972.35000000", "11.88400000"], ["1972.34000000", "6.46760000"], ["1972.33000000", "21.29010000"], ["1972.32000000", "0.03000000"], ["1972.31000000", "8.51860000"], ["1972.24000000", "1.31000000"], ["1972.16000000", "0.83650000"], ["1971.90000000", "9.94680000"], ["1971.53000000", "0.60300000"], ["1971.49000000", "14.98250000"], ["1971.48000000", "11.43850000"], ["1971.24000000", "0.80000000"], ["1970.02000000", "13.69460000"], ["1969.74000000", "13.97690000"], ["1969.55000000", "0.00000000"], ["1967.13000000", "0.00640000"], ["1967.04000000", "0.06330000"], ["1775.50000000", "0.05410000"], ["1192.00000000", "0.00000000"]], "a": [["1972.78000000", "88.57040000"], ["1972.79000000", "7.35970000"], ["1972.90000000", "8.52170000"], ["1973.34000000", "0.05390000"], ["1973.48000000", "3.74740000"], ["1973.56000000", "1.31300000"], ["1973.63000000", "0.20260000"], ["1973.72000000", "0.00000000"], ["1973.79000000", "0.00000000"], ["1974.20000000", "14.17720000"], ["1974.31000000", "0.00000000"], ["1988.26000000", "3.18570000"]], "_local_ts_utc": "2026-06-01T07:49:10.711227+00:00"}
{"e": "depthUpdate", "E": 1780300151915, "s": "ETHUSDT", "U": 76583121531, "u": 76583121545, "b": [["1972.77000000", "1.73570000"], ["1972.76000000", "0.01290000"], ["1972.74000000", "0.00260000"], ["1972.73000000", "0.00260000"], ["1972.52000000", "0.01100000"], ["1972.51000000", "0.31680000"], ["1972.48000000", "0.03270000"], ["1972.43000000", "8.59900000"], ["1972.24000000", "14.82760000"], ["1775.50000000", "0.06650000"]], "a": [["1972.78000000", "88.46140000"], ["1972.86000000", "6.47280000"]], "_local_ts_utc": "2026-06-01T07:49:10.810727+00:00"}
{"e": "depthUpdate", "E": 1780300152015, "s": "ETHUSDT", "U": 76583121546, "u": 76583121572, "b": [["1972.77000000", "3.78690000"], ["1972.25000000", "0.00260000"], ["1972.24000000", "14.01760000"], ["1972.23000000", "15.25740000"], ["1972.18000000", "0.00000000"], ["1972.17000000", "7.11230000"], ["1972.16000000", "0.29650000"], ["1972.14000000", "0.00000000"], ["1971.97000000", "0.32330000"], ["1971.78000000", "2.71560000"], ["1971.48000000", "11.31170000"], ["1970.21000000", "31.77210000"], ["1970.12000000", "0.04800000"], ["1775.50000000", "0.07890000"]], "a": [["1972.94000000", "4.38090000"], ["1973.04000000", "22.57630000"], ["1973.13000000", "0.36370000"], ["1973.18000000", "0.51600000"], ["1973.29000000", "7.62160000"], ["1973.33000000", "7.49540000"], ["1974.45000000", "1.46220000"], ["2014.30000000", "0.01600000"]], "_local_ts_utc": "2026-06-01T07:49:10.911627+00:00"}
{"e": "depthUpdate", "E": 1780300152115, "s": "ETHUSDT", "U": 76583121573, "u": 76583121598, "b": [["1972.77000000", "3.86070000"], ["1972.76000000", "0.01030000"], ["1972.61000000", "0.01920000"], ["1972.47000000", "4.51320000"], ["1972.40000000", "0.00260000"], ["1972.39000000", "13.83960000"], ["1972.02000000", "7.11610000"], ["1971.92000000", "7.36540000"], ["1971.59000000", "0.00000000"], ["1971.23000000", "0.00000000"], ["1928.31000000", "13.10110000"], ["1775.50000000", "0.09130000"]], "a": [["1972.78000000", "88.40140000"], ["1973.08000000", "14.25410000"], ["1973.20000000", "0.57270000"], ["1973.31000000", "0.69680000"], ["1973.40000000", "7.91410000"], ["1974.46000000", "0.56700000"], ["1975.61000000", "0.01940000"], ["1976.20000000", "0.02360000"], ["1977.33000000", "0.00000000"], ["1977.92000000", "0.00260000"], ["2029.37000000", "0.00680000"]], "_local_ts_utc": "2026-06-01T07:49:11.011314+00:00"}
{"e": "depthUpdate", "E": 1780300152215, "s": "ETHUSDT", "U": 76583121599, "u": 76583122046, "b": [["1972.77000000", "0.00000000"], ["1972.76000000", "0.00000000"], ["1972.75000000", "0.00000000"], ["1972.74000000", "0.00000000"], ["1972.73000000", "0.00000000"], ["1972.72000000", "0.00000000"], ["1972.71000000", "0.00000000"], ["1972.70000000", "0.00000000"], ["1972.69000000", "0.00000000"], ["1972.68000000", "0.00000000"], ["1972.67000000", "0.20200000"], ["1972.66000000", "0.00520000"], ["1972.65000000", "0.00260000"], ["1972.61000000", "0.02180000"], ["1972.60000000", "0.10660000"], ["1972.56000000", "0.01020000"], ["1972.54000000", "0.01820000"], ["1972.53000000", "0.50960000"], ["1972.52000000", "0.00820000"], ["1972.51000000", "0.01060000"], ["1972.50000000", "0.61890000"], ["1972.48000000", "0.00800000"], ["1972.47000000", "2.51320000"], ["1972.44000000", "0.00000000"], ["1972.43000000", "0.08300000"], ["1972.42000000", "0.00000000"], ["1972.41000000", "0.01320000"], ["1972.39000000", "0.00000000"], ["1972.37000000", "0.00000000"], ["1972.36000000", "0.00540000"], ["1972.35000000", "9.60350000"], ["1972.33000000", "0.00000000"], ["1972.32000000", "10.24370000"], ["1972.31000000", "0.00260000"], ["1972.30000000", "16.86290000"], ["1972.29000000", "22.62420000"], ["1972.27000000", "0.00000000"], ["1972.24000000", "0.50000000"], ["1972.22000000", "0.03300000"], ["1972.21000000", "8.52600000"], ["1972.16000000", "0.04280000"], ["1972.15000000", "6.78310000"], ["1972.13000000", "0.00000000"], ["1972.11000000", "15.61700000"], ["1972.08000000", "24.83050000"], ["1972.04000000", "0.00000000"], ["1972.01000000", "15.60990000"], ["1971.97000000", "12.61660000"], ["1971.96000000", "18.51820000"], ["1971.85000000", "9.65510000"], ["1971.84000000", "0.04010000"], ["1971.82000000", "7.36540000"], ["1971.70000000", "16.44610000"], ["1971.62000000", "1.50000000"], ["1971.54000000", "13.52220000"], ["1971.53000000", "0.20300000"], ["1971.48000000", "8.53520000"], ["1971.41000000", "0.00000000"], ["1971.24000000", "0.40000000"], ["1971.02000000", "2.32330000"], ["1970.78000000", "5.18880000"], ["1970.70000000", "14.30800000"], ["1970.41000000", "8.12000000"], ["1970.40000000", "4.18590000"], ["1970.32000000", "7.37370000"], ["1970.24000000", "23.55480000"], ["1969.54000000", "0.00260000"], ["1965.35000000", "0.00490000"], ["1965.12000000", "0.02520000"], ["1962.96000000", "0.44040000"], ["1962.86000000", "0.97830000"], ["1775.50000000", "0.00450000"], ["1775.41000000", "0.01240000"], ["1472.70000000", "0.00600000"]], "a": [["1972.68000000", "104.83510000"], ["1972.69000000", "27.51360000"], ["1972.70000000", "3.01080000"], ["1972.71000000", "13.57050000"], ["1972.72000000", "0.00000000"], ["1972.73000000", "0.00000000"], ["1972.74000000", "0.00000000"], ["1972.75000000", "0.00000000"], ["1972.76000000", "6.46760000"], ["1972.77000000", "43.87110000"], ["1972.78000000", "3.42420000"], ["1972.79000000", "0.00000000"], ["1972.80000000", "10.78630000"], ["1972.86000000", "0.00520000"], ["1972.87000000", "0.03300000"], ["1972.88000000", "0.00000000"], ["1972.89000000", "1.70210000"], ["1972.90000000", "8.52430000"], ["1972.98000000", "1.20550000"], ["1973.02000000", "21.51970000"], ["1973.14000000", "0.51080000"], ["1973.38000000", "24.22830000"], ["1973.45000000", "22.71250000"], ["1973.48000000", "2.94740000"], ["1973.70000000", "0.00310000"], ["1973.95000000", "11.60060000"], ["1974.02000000", "0.20210000"], ["1974.14000000", "0.00390000"], ["1974.16000000", "0.00000000"], ["1974.39000000", "1.22130000"], ["1974.43000000", "3.60260000"], ["1974.48000000", "0.00000000"], ["1975.00000000", "5.00570000"], ["1975.46000000", "13.55430000"], ["1976.18000000", "10.58360000"], ["1976.78000000", "0.00000000"], ["1977.74000000", "0.13390000"], ["1977.78000000", "0.00000000"], ["1977.81000000", "0.00000000"], ["1977.94000000", "0.00260000"], ["1981.91000000", "0.49170000"], ["1982.63000000", "0.00590000"], ["2472.71000000", "0.02150000"]], "_local_ts_utc": "2026-06-01T07:49:11.112168+00:00"}
{"e": "depthUpdate", "E": 1780300152315, "s": "ETHUSDT", "U": 76583122047, "u": 76583122390, "b": [["1972.67000000", "68.71230000"], ["1972.66000000", "0.00260000"], ["1972.65000000", "0.00520000"], ["1972.64000000", "0.00540000"], ["1972.63000000", "0.40270000"], ["1972.54000000", "0.01820000"], ["1972.51000000", "0.00520000"], ["1972.50000000", "0.61630000"], ["1972.49000000", "0.00000000"], ["1972.48000000", "2.71960000"], ["1972.47000000", "8.98080000"], ["1972.46000000", "7.10050000"], ["1972.45000000", "8.51590000"], ["1972.44000000", "0.25370000"], ["1972.43000000", "7.17960000"], ["1972.42000000", "7.09660000"], ["1972.37000000", "22.59120000"], ["1972.36000000", "7.09660000"], ["1972.35000000", "9.60080000"], ["1972.34000000", "0.00000000"], ["1972.32000000", "0.03000000"], ["1972.31000000", "35.00350000"], ["1972.29000000", "0.05050000"], ["1972.26000000", "0.00390000"], ["1972.24000000", "14.01730000"], ["1972.22000000", "8.43860000"], ["1972.21000000", "16.23100000"], ["1972.19000000", "6.00960000"], ["1972.08000000", "24.57670000"], ["1972.07000000", "10.69860000"], ["1972.01000000", "15.78040000"], ["1971.97000000", "0.32330000"], ["1971.90000000", "9.33840000"], ["1971.84000000", "0.04970000"], ["1971.83000000", "0.30690000"], ["1971.75000000", "7.69840000"], ["1971.68000000", "22.64720000"], ["1971.62000000", "1.30000000"], ["1971.58000000", "0.62130000"], ["1971.53000000", "0.00300000"], ["1971.46000000", "0.80390000"], ["1971.44000000", "1.20550000"], ["1971.24000000", "0.00000000"], ["1971.02000000", "1.52330000"], ["1970.82000000", "0.00710000"], ["1970.70000000", "5.79210000"], ["1970.61000000", "0.00310000"], ["1970.52000000", "1.38510000"], ["1970.41000000", "1.02340000"], ["1970.40000000", "2.23630000"], ["1970.32000000", "0.27710000"], ["1970.08000000", "1.01830000"], ["1969.54000000", "0.59900000"], ["1965.78000000", "0.00000000"], ["1965.12000000", "0.01510000"], ["1945.21000000", "1.49310000"], ["1913.49000000", "0.13040000"], ["1775.41000000", "0.02480000"], ["1578.14000000", "0.01400000"], ["1577.38000000", "0.00000000"]], "a": [["1972.68000000", "1.64480000"], ["1972.69000000", "0.01830000"], ["1972.70000000", "3.92650000"], ["1972.71000000", "0.00000000"], ["1972.72000000", "0.00000000"], ["1972.75000000", "0.00000000"], ["1972.76000000", "0.00000000"], ["1972.77000000", "0.00000000"], ["1972.78000000", "0.00000000"], ["1972.79000000", "0.00000000"], ["1972.80000000", "0.01110000"], ["1972.81000000", "0.70210000"], ["1972.84000000", "0.00000000"], ["1972.85000000", "0.00560000"], ["1972.86000000", "0.00260000"], ["1972.87000000", "0.03840000"], ["1972.88000000", "0.00540000"], ["1972.90000000", "0.00830000"], ["1972.91000000", "1.99470000"], ["1972.92000000", "0.00000000"], ["1972.94000000", "0.63860000"], ["1972.95000000", "0.00000000"], ["1972.97000000", "0.01160000"], ["1972.98000000", "0.00000000"], ["1973.00000000", "0.10710000"], ["1973.01000000", "0.00000000"], ["1973.02000000", "20.71970000"], ["1973.03000000", "0.10000000"], ["1973.04000000", "0.00260000"], ["1973.07000000", "0.02300000"], ["1973.08000000", "0.06070000"], ["1973.10000000", "0.00570000"], ["1973.11000000", "0.57700000"], ["1973.13000000", "0.16370000"], ["1973.16000000", "0.00000000"], ["1973.17000000", "0.00000000"], ["1973.20000000", "7.66930000"], ["1973.21000000", "8.51590000"], ["1973.22000000", "21.14970000"], ["1973.24000000", "0.00000000"], ["1973.25000000", "7.09920000"], ["1973.27000000", "0.00000000"], ["1973.29000000", "0.52620000"], ["1973.30000000", "0.50110000"], ["1973.31000000", "7.79340000"], ["1973.33000000", "1.40000000"], ["1973.37000000", "13.76620000"], ["1973.38000000", "10.70700000"], ["1973.48000000", "2.54740000"], ["1973.50000000", "1.08570000"], ["1973.56000000", "0.51300000"], ["1973.57000000", "0.00260000"], ["1973.59000000", "15.03630000"], ["1973.61000000", "14.20080000"], ["1973.63000000", "0.00260000"], ["1973.64000000", "8.51890000"], ["1973.67000000", "0.08660000"], ["1973.70000000", "0.00310000"], ["1973.77000000", "7.31820000"], ["1973.78000000", "1.40000000"], ["1973.95000000", "20.49120000"], ["1974.07000000", "16.42960000"], ["1974.16000000", "8.66090000"], ["1974.17000000", "7.73880000"], ["1974.20000000", "21.64490000"], ["1974.31000000", "8.51590000"], ["1974.39000000", "8.31790000"], ["1974.43000000", "10.69920000"], ["1974.48000000", "15.61250000"], ["1974.61000000", "7.09960000"], ["1974.67000000", "12.09920000"], ["1974.69000000", "7.09660000"], ["1974.74000000", "0.20840000"], ["1974.83000000", "8.11440000"], ["1974.89000000", "14.19320000"], ["1975.05000000", "7.09960000"], ["1975.25000000", "0.03300000"], ["1975.36000000", "0.03000000"], ["1975.47000000", "23.14220000"], ["1975.79000000", "15.42580000"], ["1976.12000000", "0.00000000"], ["1977.01000000", "0.00000000"], ["1977.16000000", "0.06840000"], ["1980.59000000", "0.15110000"]], "_local_ts_utc": "2026-06-01T07:49:11.211183+00:00"}
{"e": "depthUpdate", "E": 1780300152415, "s": "ETHUSDT", "U": 76583122391, "u": 76583122617, "b": [["1972.69000000", "101.74750000"], ["1972.68000000", "23.95180000"], ["1972.67000000", "4.96580000"], ["1972.65000000", "0.00520000"], ["1972.64000000", "0.00260000"], ["1972.63000000", "0.40530000"], ["1972.62000000", "0.00000000"], ["1972.61000000", "6.48940000"], ["1972.56000000", "7.13120000"], ["1972.55000000", "8.51590000"], ["1972.54000000", "7.10940000"], ["1972.53000000", "7.60360000"], ["1972.52000000", "0.00560000"], ["1972.51000000", "0.00260000"], ["1972.50000000", "19.69930000"], ["1972.49000000", "22.57370000"], ["1972.48000000", "0.03000000"], ["1972.47000000", "2.51320000"], ["1972.40000000", "0.00570000"], ["1972.38000000", "13.51730000"], ["1972.37000000", "15.44430000"], ["1972.29000000", "22.62420000"], ["1972.10000000", "0.15680000"], ["1972.03000000", "13.51760000"], ["1972.00000000", "0.27270000"], ["1971.70000000", "16.44350000"], ["1971.01000000", "7.40840000"], ["1970.90000000", "0.00000000"], ["1970.78000000", "0.92670000"], ["1970.72000000", "0.69280000"], ["1969.49000000", "0.01710000"], ["1969.46000000", "1.16100000"], ["1965.41000000", "0.05950000"], ["1961.82000000", "0.02000000"], ["1945.21000000", "0.00000000"], ["1775.41000000", "0.00000000"]], "a": [["1972.68000000", "0.00000000"], ["1972.69000000", "0.00000000"], ["1972.70000000", "3.85710000"], ["1972.71000000", "0.01290000"], ["1972.72000000", "0.00510000"], ["1972.73000000", "0.10000000"], ["1972.86000000", "0.00000000"], ["1972.87000000", "0.03300000"], ["1972.89000000", "1.69950000"], ["1972.90000000", "0.01370000"], ["1972.91000000", "1.35660000"], ["1972.94000000", "0.00390000"], ["1972.97000000", "0.00000000"], ["1973.00000000", "0.00570000"], ["1973.02000000", "0.00260000"], ["1973.08000000", "0.08470000"], ["1973.11000000", "4.27280000"], ["1973.12000000", "0.04160000"], ["1973.13000000", "0.16370000"], ["1973.14000000", "6.97840000"], ["1973.15000000", "0.00260000"], ["1973.17000000", "0.10420000"], ["1973.26000000", "26.95370000"], ["1973.30000000", "0.00830000"], ["1973.58000000", "0.00000000"], ["1973.59000000", "13.53400000"], ["1973.82000000", "7.94150000"], ["1973.85000000", "7.10040000"], ["1973.94000000", "0.00650000"], ["1974.30000000", "5.33860000"], ["1974.42000000", "23.03140000"], ["1974.52000000", "0.79030000"], ["1974.53000000", "28.66550000"], ["1974.69000000", "7.74460000"], ["1974.85000000", "14.65480000"], ["1974.89000000", "0.00000000"], ["1975.05000000", "7.09960000"], ["1975.45000000", "0.20200000"], ["1976.78000000", "0.00260000"], ["1977.94000000", "0.00000000"]], "_local_ts_utc": "2026-06-01T07:49:11.311975+00:00"}
{"e": "depthUpdate", "E": 1780300152515, "s": "ETHUSDT", "U": 76583122618, "u": 76583122679, "b": [["1972.69000000", "123.52560000"], ["1972.68000000", "3.58330000"], ["1972.67000000", "3.98060000"], ["1972.64000000", "0.03800000"], ["1972.62000000", "0.00540000"], ["1972.57000000", "0.00270000"], ["1972.56000000", "7.13120000"], ["1972.54000000", "7.10680000"], ["1972.52000000", "0.00300000"], ["1972.47000000", "2.51580000"], ["1972.22000000", "8.44810000"], ["1972.21000000", "16.25510000"], ["1971.84000000", "0.04010000"], ["1971.83000000", "0.28280000"], ["1971.17000000", "2.88660000"], ["1970.24000000", "23.52480000"], ["1967.04000000", "0.06070000"], ["1775.43000000", "0.02520000"]], "a": [["1972.70000000", "3.84670000"], ["1972.71000000", "0.01030000"], ["1972.80000000", "0.01370000"], ["1972.85000000", "0.00300000"], ["1973.02000000", "0.01420000"], ["1973.04000000", "0.01420000"], ["1973.08000000", "1.07580000"], ["1973.10000000", "0.01540000"], ["1973.11000000", "6.04960000"], ["1973.13000000", "14.35690000"], ["1973.18000000", "0.00300000"], ["1973.20000000", "7.10230000"], ["1973.23000000", "28.06370000"], ["1973.67000000", "0.00000000"], ["1973.83000000", "11.31790000"], ["1974.07000000", "16.51670000"], ["1974.85000000", "0.46160000"], ["1975.00000000", "0.00570000"]], "_local_ts_utc": "2026-06-01T07:49:11.411251+00:00"}
{"e": "depthUpdate", "E": 1780300152615, "s": "ETHUSDT", "U": 76583122680, "u": 76583123154, "b": [["1972.86000000", "96.80980000"], ["1972.85000000", "12.97370000"], ["1972.84000000", "0.86610000"], ["1972.81000000", "0.00540000"], ["1972.80000000", "17.79960000"], ["1972.79000000", "6.17510000"], ["1972.77000000", "0.00540000"], ["1972.76000000", "6.47300000"], ["1972.75000000", "7.67970000"], ["1972.72000000", "0.00000000"], ["1972.71000000", "0.00000000"], ["1972.70000000", "14.83900000"], ["1972.69000000", "25.70290000"], ["1972.68000000", "0.00260000"], ["1972.66000000", "0.00650000"], ["1972.64000000", "0.03000000"], ["1972.63000000", "0.40570000"], ["1972.62000000", "0.00000000"], ["1972.61000000", "0.01920000"], ["1972.60000000", "0.10400000"], ["1972.57000000", "0.00000000"], ["1972.56000000", "7.12860000"], ["1972.22000000", "7.13910000"], ["1972.00000000", "0.17130000"], ["1971.80000000", "0.00310000"], ["1971.75000000", "7.69840000"], ["1971.68000000", "23.44720000"], ["1971.56000000", "3.85500000"], ["1971.46000000", "0.00390000"], ["1971.10000000", "0.00000000"], ["1970.81000000", "2.29710000"], ["1970.04000000", "0.00000000"], ["1967.77000000", "0.33150000"], ["1775.43000000", "0.01280000"]], "a": [["1972.70000000", "0.00000000"], ["1972.71000000", "0.00000000"], ["1972.72000000", "0.00000000"], ["1972.73000000", "0.00000000"], ["1972.80000000", "0.00000000"], ["1972.81000000", "0.00000000"], ["1972.85000000", "0.00000000"], ["1972.87000000", "2.55310000"], ["1972.88000000", "0.01060000"], ["1972.89000000", "1.79950000"], ["1972.90000000", "0.01110000"], ["1972.91000000", "2.64550000"], ["1972.96000000", "0.06320000"], ["1973.02000000", "0.00000000"], ["1973.04000000", "0.00260000"], ["1973.07000000", "0.02840000"], ["1973.08000000", "1.07850000"], ["1973.12000000", "0.03000000"], ["1973.24000000", "0.01160000"], ["1973.59000000", "13.52390000"], ["1973.70000000", "0.00570000"], ["1973.77000000", "7.10300000"], ["1973.78000000", "0.00000000"], ["1973.80000000", "7.10610000"], ["1973.85000000", "8.50040000"], ["1973.86000000", "0.01010000"], ["1974.15000000", "1.42080000"], ["1974.83000000", "7.09960000"], ["1974.87000000", "0.99480000"], ["1975.52000000", "0.03000000"], ["1976.17000000", "0.20190000"], ["1976.78000000", "0.00000000"], ["1981.71000000", "0.00000000"], ["1981.91000000", "0.00000000"], ["1981.94000000", "0.47970000"], ["1982.63000000", "0.00850000"], ["1988.26000000", "0.00000000"]], "_local_ts_utc": "2026-06-01T07:49:11.511394+00:00"}
{"e": "depthUpdate", "E": 1780300152715, "s": "ETHUSDT", "U": 76583123155, "u": 76583123847, "b": [["1973.02000000", "84.07000000"], ["1973.01000000", "2.31230000"], ["1973.00000000", "0.00770000"], ["1972.99000000", "0.02120000"], ["1972.98000000", "0.00000000"], ["1972.97000000", "0.00000000"], ["1972.96000000", "0.00260000"], ["1972.95000000", "0.00000000"], ["1972.94000000", "0.00000000"], ["1972.93000000", "0.00000000"], ["1972.92000000", "0.00000000"], ["1972.91000000", "0.00540000"], ["1972.90000000", "14.84430000"], ["1972.89000000", "0.00000000"], ["1972.88000000", "0.42050000"], ["1972.87000000", "17.78600000"], ["1972.86000000", "7.82320000"], ["1972.85000000", "0.00260000"], ["1972.84000000", "0.86610000"], ["1972.81000000", "0.00260000"], ["1972.80000000", "19.03770000"], ["1972.79000000", "5.86740000"], ["1972.77000000", "8.51590000"], ["1972.76000000", "0.25370000"], ["1972.75000000", "12.94620000"], ["1972.74000000", "0.00260000"], ["1972.71000000", "26.48270000"], ["1972.70000000", "29.47610000"], ["1972.69000000", "3.12660000"], ["1972.68000000", "0.00000000"], ["1972.67000000", "3.97800000"], ["1972.66000000", "0.00390000"], ["1972.65000000", "18.18240000"], ["1972.64000000", "0.03260000"], ["1972.60000000", "0.10710000"], ["1972.57000000", "11.36490000"], ["1972.56000000", "7.10420000"], ["1972.52000000", "13.52030000"], ["1972.50000000", "19.70240000"], ["1972.44000000", "0.00000000"], ["1972.42000000", "10.69660000"], ["1972.36000000", "7.47470000"], ["1972.33000000", "0.10140000"], ["1972.31000000", "22.71170000"], ["1972.23000000", "15.42790000"], ["1972.19000000", "5.38120000"], ["1972.18000000", "11.03760000"], ["1972.17000000", "15.20670000"], ["1972.16000000", "0.29370000"], ["1972.15000000", "0.00000000"], ["1972.00000000", "0.17140000"], ["1971.98000000", "0.00000000"], ["1971.96000000", "19.11820000"], ["1971.90000000", "9.33580000"], ["1971.85000000", "7.11730000"], ["1971.75000000", "7.09840000"], ["1971.62000000", "0.00000000"], ["1971.48000000", "0.02070000"], ["1971.39000000", "5.03460000"], ["1971.31000000", "0.01830000"], ["1971.30000000", "3.81390000"], ["1971.20000000", "10.59770000"], ["1971.11000000", "0.59930000"], ["1971.01000000", "0.31300000"], ["1970.98000000", "7.74190000"], ["1970.97000000", "10.49100000"], ["1970.95000000", "0.00000000"], ["1970.93000000", "0.01730000"], ["1970.92000000", "0.33570000"], ["1970.40000000", "2.20630000"], ["1970.20000000", "5.30380000"], ["1970.19000000", "1.08040000"], ["1970.12000000", "0.04540000"], ["1969.74000000", "0.45930000"], ["1968.90000000", "0.02870000"], ["1968.83000000", "0.00260000"], ["1967.87000000", "0.58640000"], ["1967.84000000", "0.00000000"], ["1967.80000000", "0.00000000"], ["1967.78000000", "0.00460000"], ["1967.35000000", "0.00000000"], ["1965.32000000", "2.50140000"], ["1965.05000000", "0.00000000"], ["1961.82000000", "0.00000000"], ["1959.29000000", "0.04450000"], ["1944.00000000", "5.54060000"], ["1775.72000000", "0.00620000"], ["1775.58000000", "0.00000000"]], "a": [["1972.87000000", "0.00000000"], ["1972.88000000", "0.00000000"], ["1972.89000000", "0.00000000"], ["1972.90000000", "0.00000000"], ["1972.91000000", "0.00000000"], ["1972.94000000", "0.00000000"], ["1972.96000000", "0.00000000"], ["1973.00000000", "0.00000000"], ["1973.03000000", "8.99520000"], ["1973.04000000", "0.00520000"], ["1973.07000000", "0.02300000"], ["1973.08000000", "0.00260000"], ["1973.09000000", "0.03300000"], ["1973.10000000", "0.00570000"], ["1973.11000000", "0.00000000"], ["1973.12000000", "0.03540000"], ["1973.13000000", "0.16370000"], ["1973.14000000", "0.00390000"], ["1973.17000000", "0.01440000"], ["1973.19000000", "0.01160000"], ["1973.20000000", "0.00570000"], ["1973.21000000", "0.00540000"], ["1973.22000000", "13.20480000"], ["1973.23000000", "27.41570000"], ["1973.25000000", "0.00260000"], ["1973.26000000", "5.67090000"], ["1973.27000000", "0.00000000"], ["1973.29000000", "0.01320000"], ["1973.30000000", "0.00830000"], ["1973.31000000", "0.23780000"], ["1973.32000000", "0.01150000"], ["1973.33000000", "4.28610000"], ["1973.34000000", "7.02830000"], ["1973.35000000", "0.00000000"], ["1973.36000000", "7.23130000"], ["1973.37000000", "0.24890000"], ["1973.38000000", "0.00000000"], ["1973.40000000", "0.00870000"], ["1973.42000000", "9.62980000"], ["1973.44000000", "8.54590000"], ["1973.45000000", "14.19800000"], ["1973.48000000", "0.01020000"], ["1973.49000000", "0.00000000"], ["1973.51000000", "5.03070000"], ["1973.53000000", "1.52260000"], ["1973.54000000", "0.05440000"], ["1973.59000000", "0.00260000"], ["1973.60000000", "18.57370000"], ["1973.68000000", "2.53700000"], ["1973.71000000", "7.74180000"], ["1973.72000000", "9.92400000"], ["1973.73000000", "13.52030000"], ["1973.82000000", "5.29520000"], ["1973.83000000", "8.52150000"], ["1973.85000000", "7.10040000"], ["1973.89000000", "0.00000000"], ["1973.90000000", "1.29920000"], ["1973.99000000", "0.37810000"], ["1974.00000000", "22.62940000"], ["1974.02000000", "0.80210000"], ["1974.09000000", "0.80000000"], ["1974.10000000", "0.03990000"], ["1974.47000000", "0.02760000"], ["1974.52000000", "9.28750000"], ["1974.65000000", "15.42600000"], ["1974.66000000", "9.26100000"], ["1974.67000000", "7.09920000"], ["1974.77000000", "3.66170000"], ["1974.85000000", "4.61970000"], ["1974.87000000", "0.00000000"], ["1974.89000000", "14.19320000"], ["1975.10000000", "6.89840000"], ["1975.11000000", "7.09660000"], ["1975.13000000", "7.09920000"], ["1975.25000000", "7.12960000"], ["1975.29000000", "0.00000000"], ["1975.33000000", "0.00000000"], ["1975.38000000", "0.01910000"], ["1975.71000000", "0.00300000"], ["1976.12000000", "13.51730000"], ["1976.78000000", "0.00000000"], ["1976.83000000", "1.88000000"], ["1976.88000000", "0.20180000"], ["1977.05000000", "0.00000000"], ["1977.95000000", "1.24530000"], ["1978.00000000", "0.01250000"], ["1978.02000000", "0.00560000"], ["1978.11000000", "0.00520000"], ["1979.52000000", "0.00000000"], ["1981.08000000", "127.05940000"], ["1981.89000000", "0.00000000"], ["1981.94000000", "0.00260000"], ["1984.48000000", "0.02380000"], ["1987.08000000", "0.00000000"], ["1988.42000000", "0.00000000"]], "_local_ts_utc": "2026-06-01T07:49:11.611398+00:00"}
{"e": "depthUpdate", "E": 1780300152815, "s": "ETHUSDT", "U": 76583123848, "u": 76583124798, "b": [["1973.12000000", "70.12700000"], ["1973.11000000", "6.13800000"], ["1973.10000000", "11.62210000"], ["1973.09000000", "15.17360000"], ["1973.08000000", "8.07430000"], ["1973.07000000", "0.00260000"], ["1973.06000000", "1.80790000"], ["1973.05000000", "0.00260000"], ["1973.04000000", "0.00000000"], ["1973.03000000", "0.00260000"], ["1973.02000000", "2.13080000"], ["1973.01000000", "0.00000000"], ["1973.00000000", "0.00260000"], ["1972.99000000", "0.01860000"], ["1972.98000000", "14.72220000"], ["1972.97000000", "0.00000000"], ["1972.96000000", "0.03000000"], ["1972.91000000", "14.19320000"], ["1972.90000000", "14.84480000"], ["1972.88000000", "0.00000000"], ["1972.87000000", "24.91020000"], ["1972.86000000", "1.36710000"], ["1972.85000000", "0.00000000"], ["1972.84000000", "0.86350000"], ["1972.81000000", "14.84280000"], ["1972.80000000", "19.67150000"], ["1972.72000000", "13.51730000"], ["1972.70000000", "29.47870000"], ["1972.69000000", "0.00000000"], ["1972.67000000", "1.00000000"], ["1972.63000000", "0.00300000"], ["1972.62000000", "4.39300000"], ["1972.60000000", "0.10970000"], ["1972.53000000", "7.09660000"], ["1972.52000000", "14.12870000"], ["1972.47000000", "0.00260000"], ["1972.45000000", "8.68640000"], ["1972.40000000", "0.10710000"], ["1972.37000000", "10.99140000"], ["1972.35000000", "0.00260000"], ["1972.34000000", "6.59440000"], ["1972.33000000", "0.00000000"], ["1972.23000000", "0.17050000"], ["1972.21000000", "15.64670000"], ["1972.20000000", "1.21120000"], ["1972.19000000", "1.60220000"], ["1972.17000000", "15.19110000"], ["1972.10000000", "0.15420000"], ["1972.08000000", "24.70670000"], ["1972.05000000", "0.05000000"], ["1972.01000000", "15.60990000"], ["1971.97000000", "0.27300000"], ["1971.96000000", "18.58400000"], ["1971.95000000", "8.09540000"], ["1971.90000000", "10.13580000"], ["1971.87000000", "0.00000000"], ["1971.78000000", "2.66530000"], ["1971.68000000", "22.64720000"], ["1971.67000000", "0.02680000"], ["1971.58000000", "0.50260000"], ["1971.49000000", "9.43280000"], ["1971.45000000", "0.00000000"], ["1971.40000000", "0.54310000"], ["1971.39000000", "0.54000000"], ["1971.38000000", "0.30430000"], ["1971.34000000", "2.17330000"], ["1971.28000000", "0.00880000"], ["1971.27000000", "11.01440000"], ["1971.26000000", "23.52940000"], ["1971.24000000", "0.08560000"], ["1971.20000000", "3.50230000"], ["1971.17000000", "0.00000000"], ["1970.98000000", "11.52740000"], ["1970.94000000", "17.27110000"], ["1970.85000000", "3.74740000"], ["1970.83000000", "0.01640000"], ["1970.80000000", "0.08210000"], ["1970.77000000", "1.40640000"], ["1970.56000000", "0.76350000"], ["1970.50000000", "0.27240000"], ["1970.20000000", "1.28670000"], ["1970.18000000", "1.63530000"], ["1970.11000000", "1.08980000"], ["1970.02000000", "0.13180000"], ["1969.74000000", "0.22960000"], ["1969.60000000", "26.13150000"], ["1969.55000000", "0.53650000"], ["1969.54000000", "0.00260000"], ["1969.53000000", "0.43470000"], ["1969.22000000", "0.04260000"], ["1968.53000000", "5.83080000"], ["1968.35000000", "0.00000000"], ["1968.10000000", "0.39890000"], ["1968.06000000", "0.00000000"], ["1968.05000000", "3.64850000"], ["1968.00000000", "75.51360000"], ["1967.96000000", "0.01420000"], ["1967.33000000", "0.13010000"], ["1967.29000000", "0.00000000"], ["1967.21000000", "0.00000000"], ["1967.13000000", "0.00380000"], ["1965.69000000", "5.44480000"], ["1965.41000000", "0.05090000"], ["1962.86000000", "0.50180000"], ["1962.15000000", "0.00000000"], ["1943.84000000", "33.53650000"], ["1943.35000000", "0.00710000"], ["1775.79000000", "0.01540000"], ["1775.72000000", "0.00000000"]], "a": [["1973.03000000", "0.00000000"], ["1973.04000000", "0.00000000"], ["1973.07000000", "0.00000000"], ["1973.08000000", "0.00000000"], ["1973.09000000", "0.00000000"], ["1973.10000000", "0.00000000"], ["1973.11000000", "0.00000000"], ["1973.12000000", "0.00000000"], ["1973.13000000", "17.53650000"], ["1973.15000000", "0.00000000"], ["1973.17000000", "0.00000000"], ["1973.19000000", "0.00000000"], ["1973.21000000", "0.00000000"], ["1973.22000000", "0.00260000"], ["1973.23000000", "0.00260000"], ["1973.24000000", "0.00000000"], ["1973.25000000", "0.00260000"], ["1973.26000000", "0.00000000"], ["1973.30000000", "0.01110000"], ["1973.32000000", "0.01150000"], ["1973.33000000", "0.65590000"], ["1973.34000000", "0.56070000"], ["1973.35000000", "0.01160000"], ["1973.36000000", "0.13470000"], ["1973.37000000", "1.48170000"], ["1973.41000000", "0.01160000"], ["1973.42000000", "7.28390000"], ["1973.44000000", "0.03000000"], ["1973.45000000", "22.57370000"], ["1973.46000000", "0.00000000"], ["1973.47000000", "0.02620000"], ["1973.50000000", "0.46470000"], ["1973.51000000", "1.81170000"], ["1973.52000000", "0.03300000"], ["1973.53000000", "0.02260000"], ["1973.54000000", "7.16010000"], ["1973.55000000", "4.19940000"], ["1973.56000000", "0.00000000"], ["1973.60000000", "28.68070000"], ["1973.61000000", "0.00000000"], ["1973.64000000", "0.00000000"], ["1973.65000000", "0.00000000"], ["1973.68000000", "11.05290000"], ["1973.70000000", "8.60230000"], ["1973.73000000", "0.00300000"], ["1973.81000000", "12.25670000"], ["1973.82000000", "26.77800000"], ["1973.86000000", "0.00000000"], ["1973.90000000", "1.21120000"], ["1974.02000000", "0.20210000"], ["1974.05000000", "1.86300000"], ["1974.08000000", "0.03000000"], ["1974.09000000", "0.00000000"], ["1974.10000000", "0.00260000"], ["1974.11000000", "4.10930000"], ["1974.13000000", "0.01270000"], ["1974.15000000", "1.42080000"], ["1974.18000000", "0.00000000"], ["1974.19000000", "7.17410000"], ["1974.23000000", "0.09110000"], ["1974.30000000", "5.73860000"], ["1974.45000000", "0.51300000"], ["1974.49000000", "23.16770000"], ["1974.53000000", "31.46760000"], ["1974.84000000", "8.51590000"], ["1974.85000000", "14.94820000"], ["1974.97000000", "1.25360000"], ["1975.04000000", "2.43330000"], ["1975.05000000", "8.04860000"], ["1975.08000000", "0.00000000"], ["1975.10000000", "6.89840000"], ["1975.18000000", "4.62550000"], ["1975.22000000", "0.69600000"], ["1975.24000000", "5.03910000"], ["1975.33000000", "7.09660000"], ["1975.37000000", "7.09660000"], ["1975.45000000", "14.39520000"], ["1975.46000000", "20.99670000"], ["1975.47000000", "23.49740000"], ["1975.61000000", "0.01940000"], ["1975.68000000", "0.06300000"], ["1975.76000000", "0.00000000"], ["1975.79000000", "13.52750000"], ["1976.09000000", "0.90680000"], ["1976.18000000", "1.20550000"], ["1976.36000000", "0.51130000"], ["1976.39000000", "1.89620000"], ["1976.45000000", "13.51730000"], ["1976.85000000", "9.37810000"], ["1977.16000000", "0.00000000"], ["1977.30000000", "0.00270000"], ["1977.53000000", "1.27390000"], ["1977.60000000", "0.20480000"], ["1978.20000000", "0.00260000"], ["1978.29000000", "0.00520000"], ["1978.33000000", "0.00870000"], ["1978.42000000", "0.01280000"], ["1982.20000000", "0.00000000"], ["1988.60000000", "3.08710000"]], "_local_ts_utc": "2026-06-01T07:49:11.711718+00:00"}
{"e": "depthUpdate", "E": 1780300152915, "s": "ETHUSDT", "U": 76583124799, "u": 76583124963, "b": [["1973.12000000", "70.07750000"], ["1973.11000000", "6.94930000"], ["1973.09000000", "15.17900000"], ["1973.03000000", "0.00530000"], ["1973.02000000", "9.22740000"], ["1973.01000000", "7.09660000"], ["1972.99000000", "10.17420000"], ["1972.98000000", "15.61250000"], ["1972.88000000", "13.51730000"], ["1972.82000000", "0.50690000"], ["1972.81000000", "14.19320000"], ["1972.59000000", "0.00940000"], ["1972.57000000", "17.72500000"], ["1972.55000000", "8.53980000"], ["1972.51000000", "26.78060000"], ["1972.23000000", "0.00000000"], ["1972.22000000", "7.12960000"], ["1972.21000000", "15.62260000"], ["1972.17000000", "8.59670000"], ["1971.96000000", "9.79040000"], ["1971.93000000", "0.00000000"], ["1971.79000000", "6.12320000"], ["1971.77000000", "4.66330000"], ["1971.71000000", "13.51520000"], ["1971.70000000", "7.88000000"], ["1971.69000000", "0.36630000"], ["1971.65000000", "3.14490000"], ["1971.60000000", "5.53760000"], ["1971.55000000", "0.51110000"], ["1971.52000000", "0.03260000"], ["1971.51000000", "0.34830000"], ["1971.20000000", "2.86590000"], ["1970.29000000", "15.67260000"], ["1970.25000000", "4.11090000"], ["1969.80000000", "4.56000000"], ["1969.55000000", "0.00000000"], ["1967.48000000", "1.20810000"], ["1967.39000000", "0.00000000"], ["1962.76000000", "0.00300000"], ["1775.81000000", "0.01240000"]], "a": [["1973.13000000", "10.28850000"], ["1973.14000000", "0.00000000"], ["1973.27000000", "0.01160000"], ["1973.32000000", "0.01300000"], ["1973.33000000", "0.65590000"], ["1973.41000000", "0.65510000"], ["1973.42000000", "0.00260000"], ["1973.45000000", "0.00000000"], ["1973.50000000", "0.00570000"], ["1973.52000000", "11.26320000"], ["1973.53000000", "14.21580000"], ["1973.55000000", "0.00000000"], ["1973.59000000", "15.61510000"], ["1973.60000000", "14.97050000"], ["1973.67000000", "14.19320000"], ["1973.68000000", "2.53700000"], ["1973.69000000", "36.09100000"], ["1973.70000000", "1.50570000"], ["1973.71000000", "10.89890000"], ["1973.77000000", "0.00260000"], ["1973.79000000", "29.80570000"], ["1973.80000000", "0.00570000"], ["1973.81000000", "0.00000000"], ["1973.82000000", "0.00000000"], ["1973.83000000", "0.00260000"], ["1973.85000000", "0.00000000"], ["1973.92000000", "7.12660000"], ["1973.93000000", "15.80340000"], ["1973.94000000", "13.52380000"], ["1973.95000000", "7.13460000"], ["1973.96000000", "0.65500000"], ["1974.15000000", "2.42080000"], ["1975.04000000", "2.43330000"], ["1975.08000000", "0.00000000"], ["1975.32000000", "4.36650000"], ["1975.33000000", "0.00000000"], ["1975.45000000", "0.20200000"], ["1975.47000000", "22.58390000"], ["1975.61000000", "0.01940000"], ["1975.72000000", "0.63420000"], ["1976.45000000", "0.00000000"], ["1978.31000000", "0.20170000"], ["1978.42000000", "0.01020000"], ["1982.08000000", "2.52790000"]], "_local_ts_utc": "2026-06-01T07:49:11.811349+00:00"}
{"e": "depthUpdate", "E": 1780300153015, "s": "ETHUSDT", "U": 76583124964, "u": 76583125087, "b": [["1973.12000000", "36.76290000"], ["1973.11000000", "2.98390000"], ["1973.10000000", "0.01030000"], ["1973.09000000", "0.00800000"], ["1973.08000000", "3.81630000"], ["1973.07000000", "0.00800000"], ["1973.04000000", "0.00540000"], ["1973.03000000", "0.00530000"], ["1973.02000000", "2.13080000"], ["1973.01000000", "0.00000000"], ["1973.00000000", "0.00260000"], ["1972.99000000", "1.95980000"], ["1972.98000000", "6.46760000"], ["1972.94000000", "0.00000000"], ["1972.92000000", "10.21070000"], ["1972.91000000", "0.00000000"], ["1972.88000000", "0.00000000"], ["1972.87000000", "17.81360000"], ["1972.85000000", "0.00300000"], ["1972.82000000", "0.50690000"], ["1972.79000000", "5.82170000"], ["1972.73000000", "0.00520000"], ["1972.72000000", "0.00000000"], ["1972.71000000", "14.19320000"], ["1972.66000000", "13.52120000"], ["1972.65000000", "15.64550000"], ["1972.58000000", "12.56000000"], ["1972.53000000", "7.14690000"], ["1972.20000000", "0.00570000"], ["1972.19000000", "1.00220000"], ["1971.91000000", "7.69540000"], ["1971.90000000", "9.33580000"], ["1971.84000000", "0.09040000"], ["1971.70000000", "11.10800000"], ["1971.62000000", "7.89660000"], ["1971.61000000", "7.22700000"], ["1971.55000000", "7.60770000"], ["1971.50000000", "1.04990000"], ["1971.42000000", "7.25510000"], ["1971.41000000", "7.09660000"], ["1971.36000000", "4.43510000"], ["1971.35000000", "7.36660000"], ["1971.34000000", "0.00390000"], ["1970.83000000", "0.01900000"], ["1970.74000000", "0.27260000"], ["1970.04000000", "0.27000000"], ["1962.15000000", "1.20550000"], ["1775.81000000", "0.03100000"], ["1472.70000000", "0.00000000"]], "a": [["1973.13000000", "26.85780000"], ["1973.21000000", "0.00260000"], ["1973.22000000", "0.01420000"], ["1973.24000000", "0.01160000"], ["1973.25000000", "0.00000000"], ["1973.30000000", "0.00570000"], ["1973.32000000", "0.00760000"], ["1973.33000000", "0.65590000"], ["1973.34000000", "0.05390000"], ["1973.40000000", "8.89370000"], ["1973.41000000", "7.11110000"], ["1973.49000000", "22.57370000"], ["1973.52000000", "7.71980000"], ["1973.54000000", "1.89800000"], ["1973.63000000", "4.38660000"], ["1973.91000000", "23.79270000"], ["1973.92000000", "33.90560000"], ["1973.93000000", "0.00260000"], ["1975.32000000", "0.10000000"], ["1975.46000000", "13.55430000"], ["1975.53000000", "0.94500000"], ["1975.82000000", "0.00300000"], ["1979.02000000", "0.33280000"], ["2472.71000000", "0.01550000"]], "_local_ts_utc": "2026-06-01T07:49:11.911430+00:00"}
{"e": "depthUpdate", "E": 1780300153115, "s": "ETHUSDT", "U": 76583125088, "u": 76583125141, "b": [["1973.12000000", "34.22640000"], ["1973.05000000", "0.00260000"], ["1973.04000000", "0.00260000"], ["1973.03000000", "0.00800000"], ["1973.02000000", "2.12820000"], ["1973.00000000", "0.00530000"], ["1972.99000000", "4.75960000"], ["1972.95000000", "0.50740000"], ["1972.90000000", "10.96080000"], ["1972.88000000", "1.29260000"], ["1972.81000000", "27.70810000"], ["1972.73000000", "0.00780000"], ["1972.70000000", "32.22660000"], ["1972.64000000", "0.30260000"], ["1972.62000000", "4.66300000"], ["1972.12000000", "7.30140000"], ["1971.94000000", "0.05030000"], ["1971.91000000", "7.49540000"], ["1970.10000000", "0.35750000"], ["1970.08000000", "1.28830000"], ["1970.04000000", "0.00000000"], ["1968.67000000", "0.00260000"], ["1968.40000000", "0.52620000"], ["1846.52000000", "0.00000000"], ["1775.81000000", "0.04340000"]], "a": [["1973.13000000", "17.08140000"], ["1973.33000000", "6.77490000"], ["1973.35000000", "0.00000000"], ["1973.39000000", "14.19060000"], ["1973.40000000", "15.98900000"], ["1973.47000000", "0.00260000"], ["1973.51000000", "1.83590000"], ["1973.58000000", "0.50670000"], ["1974.15000000", "1.42080000"], ["1974.20000000", "21.84490000"], ["1974.25000000", "0.80000000"], ["1975.10000000", "7.68140000"], ["1975.11000000", "0.00000000"], ["1975.12000000", "0.81000000"], ["1975.24000000", "0.00000000"], ["1975.25000000", "0.03300000"], ["1975.37000000", "0.00000000"], ["1979.74000000", "0.20150000"], ["2011.44000000", "0.17520000"]], "_local_ts_utc": "2026-06-01T07:49:12.011650+00:00"}
{"e": "depthUpdate", "E": 1780300153215, "s": "ETHUSDT", "U": 76583125142, "u": 76583125178, "b": [["1973.10000000", "0.01570000"], ["1973.09000000", "2.33260000"], ["1973.00000000", "0.00260000"], ["1972.99000000", "3.99680000"], ["1972.98000000", "0.00000000"], ["1972.95000000", "0.00000000"], ["1972.90000000", "15.33920000"], ["1972.88000000", "7.76020000"], ["1972.85000000", "7.09830000"], ["1972.73000000", "0.01300000"], ["1972.43000000", "7.22990000"], ["1972.34000000", "6.64470000"], ["1972.04000000", "0.05030000"], ["1971.93000000", "2.90440000"], ["1775.81000000", "0.05580000"]], "a": [["1973.13000000", "7.32510000"], ["1973.22000000", "0.00260000"], ["1973.24000000", "0.00000000"], ["1973.27000000", "0.00000000"], ["1973.30000000", "0.01110000"], ["1973.31000000", "6.70540000"], ["1973.32000000", "0.01300000"], ["1973.39000000", "14.20220000"], ["1973.41000000", "0.64350000"], ["1973.68000000", "0.00000000"], ["1973.88000000", "1.11880000"], ["1973.89000000", "2.53680000"], ["1976.43000000", "0.01020000"], ["1976.63000000", "0.79390000"], ["1980.45000000", "0.20140000"]], "_local_ts_utc": "2026-06-01T07:49:12.110562+00:00"}
{"e": "depthUpdate", "E": 1780300153315, "s": "ETHUSDT", "U": 76583125179, "u": 76583125241, "b": [["1973.00000000", "10.67710000"], ["1972.99000000", "6.48620000"], ["1972.91000000", "14.19060000"], ["1972.88000000", "1.29260000"], ["1972.82000000", "0.55690000"], ["1972.74000000", "0.00560000"], ["1972.73000000", "0.01820000"], ["1972.61000000", "0.28920000"], ["1972.60000000", "0.64970000"], ["1972.53000000", "7.41690000"], ["1972.15000000", "0.06840000"], ["1972.14000000", "0.05030000"], ["1972.12000000", "7.10140000"], ["1972.10000000", "0.15420000"], ["1972.05000000", "0.00000000"], ["1972.02000000", "7.51610000"], ["1971.96000000", "9.72200000"], ["1971.95000000", "8.29540000"], ["1971.91000000", "7.09540000"], ["1971.81000000", "7.09540000"], ["1971.00000000", "13.17170000"], ["1970.41000000", "1.29340000"], ["1970.25000000", "4.38090000"], ["1970.17000000", "0.27260000"], ["1970.08000000", "1.01830000"], ["1969.91000000", "0.28610000"], ["1945.85000000", "1.50220000"], ["1775.81000000", "0.06820000"]], "a": [["1973.31000000", "0.23780000"], ["1973.43000000", "6.46760000"], ["1973.69000000", "37.76500000"], ["1973.73000000", "0.05300000"], ["1973.76000000", "0.54300000"], ["1974.20000000", "21.64490000"], ["1974.25000000", "1.48500000"], ["1974.30000000", "5.33860000"], ["1974.31000000", "8.51590000"], ["1974.34000000", "1.40380000"], ["1975.04000000", "3.51330000"], ["1975.09000000", "5.00260000"], ["1975.11000000", "0.51300000"], ["1975.48000000", "1.79950000"], ["1977.53000000", "1.20550000"], ["1977.72000000", "0.07860000"], ["1981.17000000", "0.20140000"]], "_local_ts_utc": "2026-06-01T07:49:12.210609+00:00"}
{"e": "depthUpdate", "E": 1780300153415, "s": "ETHUSDT", "U": 76583125242, "u": 76583125750, "b": [["1973.27000000", "68.49510000"], ["1973.26000000", "0.00510000"], ["1973.25000000", "7.66210000"], ["1973.24000000", "0.00000000"], ["1973.23000000", "0.42050000"], ["1973.22000000", "8.85960000"], ["1973.21000000", "0.14720000"], ["1973.20000000", "11.78900000"], ["1973.19000000", "0.00000000"], ["1973.18000000", "0.00000000"], ["1973.17000000", "0.00260000"], ["1973.16000000", "0.50630000"], ["1973.15000000", "0.00000000"], ["1973.14000000", "0.00540000"], ["1973.13000000", "13.31640000"], ["1973.12000000", "1.34100000"], ["1973.11000000", "2.97880000"], ["1973.10000000", "0.00520000"], ["1973.09000000", "0.00520000"], ["1973.08000000", "0.81370000"], ["1973.07000000", "9.68930000"], ["1973.06000000", "1.80920000"], ["1973.05000000", "0.00000000"], ["1973.04000000", "7.09530000"], ["1973.03000000", "0.00000000"], ["1973.01000000", "7.09790000"], ["1973.00000000", "8.29990000"], ["1972.99000000", "0.01860000"], ["1972.97000000", "8.51440000"], ["1972.95000000", "7.09530000"], ["1972.92000000", "0.00260000"], ["1972.82000000", "0.05000000"], ["1972.81000000", "27.72740000"], ["1972.76000000", "0.30420000"], ["1972.75000000", "11.74970000"], ["1972.67000000", "4.60000000"], ["1972.61000000", "0.54000000"], ["1972.55000000", "15.13540000"], ["1972.50000000", "19.90240000"], ["1972.40000000", "0.00570000"], ["1972.36000000", "7.87470000"], ["1972.29000000", "22.57370000"], ["1972.24000000", "14.01730000"], ["1972.22000000", "7.15020000"], ["1972.21000000", "16.42260000"], ["1972.20000000", "0.00310000"], ["1972.02000000", "7.09540000"], ["1971.95000000", "8.09540000"], ["1971.62000000", "0.00000000"], ["1971.42000000", "0.15850000"], ["1971.41000000", "0.00000000"], ["1971.35000000", "0.27000000"], ["1970.65000000", "58.59180000"], ["1970.41000000", "1.02340000"], ["1970.21000000", "32.04210000"], ["1968.34000000", "0.20280000"], ["1968.11000000", "0.00320000"], ["1968.10000000", "0.39890000"], ["1968.05000000", "3.64850000"], ["1965.25000000", "0.12290000"], ["1963.79000000", "2.65900000"], ["1963.45000000", "0.49430000"], ["1775.95000000", "0.03140000"], ["1775.81000000", "0.00000000"], ["1473.13000000", "0.00600000"]], "a": [["1973.13000000", "0.00000000"], ["1973.14000000", "0.00000000"], ["1973.18000000", "0.00000000"], ["1973.20000000", "0.00000000"], ["1973.21000000", "0.00000000"], ["1973.22000000", "0.00000000"], ["1973.23000000", "0.00000000"], ["1973.28000000", "0.02570000"], ["1973.33000000", "0.00000000"], ["1973.34000000", "0.05390000"], ["1973.36000000", "0.13750000"], ["1973.39000000", "0.00000000"], ["1973.40000000", "0.01670000"], ["1973.42000000", "0.00260000"], ["1973.43000000", "0.00000000"], ["1973.49000000", "0.00270000"], ["1973.50000000", "0.94390000"], ["1973.51000000", "1.81170000"], ["1973.52000000", "0.04460000"], ["1973.53000000", "0.02260000"], ["1973.54000000", "0.69250000"], ["1973.58000000", "0.50930000"], ["1973.59000000", "0.00260000"], ["1973.60000000", "14.98210000"], ["1973.65000000", "0.02420000"], ["1973.69000000", "24.70670000"], ["1973.88000000", "4.25270000"], ["1973.89000000", "0.00000000"], ["1973.90000000", "14.72610000"], ["1973.94000000", "0.00650000"], ["1974.05000000", "1.40400000"], ["1974.07000000", "16.42960000"], ["1974.11000000", "0.50930000"], ["1974.12000000", "0.00000000"], ["1974.14000000", "9.10960000"], ["1974.15000000", "14.72040000"], ["1974.16000000", "0.00000000"], ["1974.20000000", "8.12400000"], ["1974.34000000", "0.00380000"], ["1974.36000000", "0.00000000"], ["1974.39000000", "8.31790000"], ["1974.48000000", "15.69830000"], ["1974.53000000", "28.66550000"], ["1974.55000000", "0.83880000"], ["1974.58000000", "0.16360000"], ["1974.68000000", "0.45900000"], ["1975.04000000", "6.99610000"], ["1975.08000000", "15.60970000"], ["1975.09000000", "0.00260000"], ["1975.18000000", "3.60000000"], ["1975.20000000", "0.03310000"], ["1975.25000000", "14.22360000"], ["1975.29000000", "0.43620000"], ["1975.37000000", "7.09530000"], ["1975.45000000", "7.29730000"], ["1975.48000000", "1.20550000"], ["1975.61000000", "7.09530000"], ["1975.81000000", "0.01930000"], ["1975.93000000", "0.00300000"], ["1976.20000000", "0.00310000"], ["1976.40000000", "0.02380000"], ["1976.45000000", "13.51490000"], ["1978.45000000", "0.00260000"], ["1978.54000000", "0.00260000"], ["1981.88000000", "0.20130000"], ["1982.29000000", "0.00260000"], ["1982.98000000", "3.60780000"], ["1988.60000000", "0.00970000"], ["2473.14000000", "0.00600000"]], "_local_ts_utc": "2026-06-01T07:49:12.311743+00:00"}
{"e": "depthUpdate", "E": 1780300153515, "s": "ETHUSDT", "U": 76583125751, "u": 76583126083, "b": [["1973.39000000", "18.61410000"], ["1973.36000000", "13.93400000"], ["1973.35000000", "20.10970000"], ["1973.33000000", "17.24760000"], ["1973.32000000", "28.86100000"], ["1973.31000000", "93.41600000"], ["1973.30000000", "9.26390000"], ["1973.29000000", "36.26310000"], ["1973.28000000", "12.81690000"], ["1973.27000000", "33.52640000"], ["1973.26000000", "0.00260000"], ["1973.25000000", "0.00260000"], ["1973.24000000", "0.00000000"], ["1973.23000000", "0.00260000"], ["1973.22000000", "8.85960000"], ["1973.21000000", "0.00530000"], ["1973.18000000", "0.00260000"], ["1973.17000000", "0.00000000"], ["1973.16000000", "0.50630000"], ["1973.15000000", "0.00000000"], ["1973.14000000", "7.09530000"], ["1973.13000000", "3.10410000"], ["1973.12000000", "1.33840000"], ["1973.11000000", "10.07150000"], ["1973.10000000", "0.00260000"], ["1973.09000000", "0.00260000"], ["1973.08000000", "8.76720000"], ["1973.07000000", "8.51440000"], ["1973.06000000", "8.90450000"], ["1973.05000000", "0.25360000"], ["1972.96000000", "0.53690000"], ["1972.95000000", "7.72440000"], ["1972.86000000", "1.23880000"], ["1972.79000000", "4.60000000"], ["1972.76000000", "0.05050000"], ["1972.75000000", "8.89660000"], ["1972.74000000", "0.38370000"], ["1972.63000000", "0.00580000"], ["1972.62000000", "4.76300000"], ["1972.59000000", "0.11080000"], ["1972.36000000", "7.49660000"], ["1972.34000000", "0.05030000"], ["1972.30000000", "16.86030000"], ["1972.27000000", "0.00390000"], ["1972.22000000", "8.35570000"], ["1972.12000000", "7.09860000"], ["1971.93000000", "0.00000000"], ["1971.70000000", "7.88000000"], ["1971.61000000", "0.13040000"], ["1971.55000000", "0.51110000"], ["1971.36000000", "2.31680000"], ["1970.78000000", "5.59210000"], ["1970.70000000", "21.76620000"], ["1970.48000000", "0.00000000"], ["1970.21000000", "31.77210000"], ["1970.10000000", "0.08750000"], ["1969.80000000", "3.04970000"], ["1969.08000000", "5.88000000"], ["1968.27000000", "0.00000000"], ["1968.22000000", "0.79690000"], ["1968.13000000", "0.55000000"], ["1967.69000000", "0.00000000"], ["1967.59000000", "0.00000000"], ["1967.54000000", "0.00000000"], ["1963.44000000", "0.08170000"], ["1962.15000000", "0.00000000"], ["1943.84000000", "0.00260000"], ["1874.63000000", "0.00760000"], ["1874.51000000", "0.00000000"], ["1846.52000000", "0.03580000"], ["1775.95000000", "0.02520000"]], "a": [["1973.28000000", "0.00000000"], ["1973.29000000", "0.00000000"], ["1973.30000000", "0.00000000"], ["1973.31000000", "0.00000000"], ["1973.32000000", "0.00000000"], ["1973.34000000", "0.00000000"], ["1973.36000000", "0.00000000"], ["1973.37000000", "0.00000000"], ["1973.40000000", "0.00000000"], ["1973.41000000", "0.00000000"], ["1973.42000000", "0.00000000"], ["1973.44000000", "0.00000000"], ["1973.47000000", "0.00000000"], ["1973.49000000", "0.00540000"], ["1973.50000000", "0.94930000"], ["1973.52000000", "0.03300000"], ["1973.53000000", "0.02530000"], ["1973.54000000", "0.69510000"], ["1973.59000000", "0.62600000"], ["1973.60000000", "14.97050000"], ["1973.67000000", "0.00000000"], ["1973.69000000", "0.00000000"], ["1973.71000000", "10.89890000"], ["1973.72000000", "0.00000000"], ["1973.76000000", "0.03000000"], ["1973.77000000", "0.00540000"], ["1973.79000000", "0.00000000"], ["1973.90000000", "1.21120000"], ["1973.97000000", "11.43490000"], ["1973.99000000", "0.00000000"], ["1974.13000000", "13.52760000"], ["1974.15000000", "1.20550000"], ["1974.16000000", "2.86660000"], ["1974.30000000", "5.34120000"], ["1974.33000000", "0.89500000"], ["1974.42000000", "13.37490000"], ["1974.43000000", "7.09920000"], ["1974.46000000", "0.56700000"], ["1974.53000000", "14.92350000"], ["1975.16000000", "9.65680000"], ["1975.32000000", "8.61440000"], ["1975.44000000", "7.10050000"], ["1975.49000000", "0.00300000"], ["1975.60000000", "8.20010000"], ["1975.72000000", "0.98950000"], ["1976.55000000", "23.94070000"], ["1976.78000000", "13.51490000"], ["1977.36000000", "0.00680000"], ["1978.38000000", "0.13380000"], ["1978.39000000", "8.24280000"], ["1981.28000000", "0.05370000"], ["1982.59000000", "0.23400000"]], "_local_ts_utc": "2026-06-01T07:49:12.412742+00:00"}
{"e": "depthUpdate", "E": 1780300153615, "s": "ETHUSDT", "U": 76583126084, "u": 76583126795, "b": [["1973.47000000", "68.45930000"], ["1973.46000000", "0.00510000"], ["1973.45000000", "0.01050000"], ["1973.44000000", "3.30010000"], ["1973.43000000", "0.92140000"], ["1973.42000000", "0.00000000"], ["1973.41000000", "0.00540000"], ["1973.40000000", "8.51700000"], ["1973.39000000", "17.02840000"], ["1973.38000000", "6.47030000"], ["1973.37000000", "7.09530000"], ["1973.36000000", "0.50520000"], ["1973.35000000", "0.00260000"], ["1973.34000000", "14.19060000"], ["1973.33000000", "0.92130000"], ["1973.32000000", "0.00260000"], ["1973.31000000", "8.48320000"], ["1973.30000000", "0.00520000"], ["1973.29000000", "18.41310000"], ["1973.28000000", "22.05930000"], ["1973.27000000", "18.37230000"], ["1973.26000000", "0.00390000"], ["1973.25000000", "0.00260000"], ["1973.23000000", "0.00000000"], ["1973.22000000", "8.85700000"], ["1973.21000000", "7.09530000"], ["1973.20000000", "13.64460000"], ["1973.19000000", "0.01020000"], ["1973.18000000", "0.00560000"], ["1973.17000000", "0.00260000"], ["1973.15000000", "12.28690000"], ["1973.13000000", "16.61900000"], ["1973.12000000", "1.36840000"], ["1973.10000000", "0.00570000"], ["1973.09000000", "0.03560000"], ["1973.08000000", "8.76980000"], ["1973.05000000", "0.00000000"], ["1973.00000000", "12.07370000"], ["1972.99000000", "0.00000000"], ["1972.98000000", "13.51490000"], ["1972.96000000", "0.03000000"], ["1972.88000000", "0.00000000"], ["1972.87000000", "21.41360000"], ["1972.86000000", "1.62510000"], ["1972.81000000", "27.92870000"], ["1972.78000000", "0.10140000"], ["1972.77000000", "15.11150000"], ["1972.72000000", "0.27000000"], ["1972.68000000", "0.17050000"], ["1972.64000000", "0.50260000"], ["1972.62000000", "5.96300000"], ["1972.61000000", "0.64000000"], ["1972.59000000", "0.00940000"], ["1972.58000000", "0.27000000"], ["1972.55000000", "8.53980000"], ["1972.54000000", "7.37680000"], ["1972.52000000", "13.52030000"], ["1972.44000000", "0.00000000"], ["1972.40000000", "0.00310000"], ["1972.17000000", "7.09670000"], ["1972.01000000", "7.09540000"], ["1971.96000000", "5.21990000"], ["1971.91000000", "0.00000000"], ["1971.90000000", "11.31940000"], ["1971.89000000", "13.51780000"], ["1971.82000000", "0.27000000"], ["1971.81000000", "0.00000000"], ["1971.77000000", "3.66330000"], ["1971.75000000", "0.00300000"], ["1971.69000000", "0.58010000"], ["1971.68000000", "22.73230000"], ["1971.26000000", "23.31590000"], ["1971.24000000", "0.00000000"], ["1970.98000000", "7.74190000"], ["1970.91000000", "0.27000000"], ["1970.88000000", "0.00260000"], ["1970.72000000", "0.66280000"], ["1970.71000000", "0.30560000"], ["1970.68000000", "1.20920000"], ["1970.49000000", "2.75900000"], ["1970.43000000", "1.18980000"], ["1970.25000000", "4.11090000"], ["1970.17000000", "0.00260000"], ["1970.03000000", "1.72980000"], ["1969.66000000", "16.33270000"], ["1969.55000000", "0.27000000"], ["1968.13000000", "0.54730000"], ["1967.77000000", "0.32890000"], ["1967.68000000", "0.03310000"], ["1966.01000000", "0.05550000"], ["1965.69000000", "5.43500000"], ["1965.45000000", "0.29940000"], ["1963.53000000", "1.36600000"], ["1963.45000000", "0.00420000"], ["1962.81000000", "0.06110000"], ["1962.04000000", "0.00000000"], ["1945.85000000", "0.01650000"], ["1944.16000000", "23.72310000"], ["1776.13000000", "0.01240000"], ["1578.78000000", "0.01400000"], ["1577.64000000", "0.01700000"], ["1192.00000000", "0.00000000"]], "a": [["1973.48000000", "0.10750000"], ["1973.49000000", "0.00780000"], ["1973.50000000", "0.01110000"], ["1973.52000000", "0.03840000"], ["1973.53000000", "1.30520000"], ["1973.54000000", "0.00650000"], ["1973.57000000", "0.00260000"], ["1973.58000000", "0.00540000"], ["1973.59000000", "0.62340000"], ["1973.60000000", "0.00570000"], ["1973.63000000", "0.00000000"], ["1973.65000000", "0.00000000"], ["1973.70000000", "0.00570000"], ["1973.71000000", "0.00260000"], ["1973.77000000", "0.01700000"], ["1973.78000000", "0.00260000"], ["1973.80000000", "0.00570000"], ["1973.81000000", "0.00000000"], ["1973.82000000", "0.01160000"], ["1973.87000000", "0.64070000"], ["1973.88000000", "0.00000000"], ["1973.89000000", "0.00000000"], ["1973.90000000", "0.00570000"], ["1973.91000000", "10.73220000"], ["1973.92000000", "0.03000000"], ["1973.93000000", "0.02640000"], ["1973.94000000", "0.00650000"], ["1973.95000000", "0.03600000"], ["1973.96000000", "0.65500000"], ["1973.98000000", "0.00260000"], ["1973.99000000", "0.56350000"], ["1974.00000000", "22.62940000"], ["1974.01000000", "6.47780000"], ["1974.02000000", "1.03220000"], ["1974.03000000", "0.46650000"], ["1974.06000000", "0.01060000"], ["1974.07000000", "0.81260000"], ["1974.10000000", "13.45560000"], ["1974.11000000", "0.50930000"], ["1974.12000000", "29.80030000"], ["1974.13000000", "0.00260000"], ["1974.14000000", "1.50390000"], ["1974.17000000", "0.64020000"], ["1974.18000000", "0.00000000"], ["1974.19000000", "0.07550000"], ["1974.20000000", "15.42210000"], ["1974.22000000", "0.00000000"], ["1974.24000000", "0.03260000"], ["1974.25000000", "0.00000000"], ["1974.27000000", "7.09530000"], ["1974.28000000", "29.13020000"], ["1974.30000000", "0.00260000"], ["1974.31000000", "0.00000000"], ["1974.33000000", "0.38200000"], ["1974.38000000", "0.03300000"], ["1974.40000000", "0.03570000"], ["1974.44000000", "0.39730000"], ["1974.52000000", "5.12160000"], ["1974.53000000", "13.72350000"], ["1974.56000000", "0.03000000"], ["1974.60000000", "1.21910000"], ["1974.64000000", "0.15110000"], ["1974.66000000", "9.10990000"], ["1974.67000000", "7.89920000"], ["1974.72000000", "0.01060000"], ["1974.75000000", "0.00000000"], ["1974.92000000", "9.25800000"], ["1974.93000000", "26.80000000"], ["1974.97000000", "0.00000000"], ["1975.11000000", "0.73990000"], ["1975.12000000", "0.81000000"], ["1975.16000000", "0.00300000"], ["1975.24000000", "11.11510000"], ["1975.26000000", "22.57370000"], ["1975.31000000", "6.22870000"], ["1975.32000000", "9.12740000"], ["1975.33000000", "0.02390000"], ["1975.34000000", "0.46660000"], ["1975.41000000", "0.00000000"], ["1975.44000000", "20.42670000"], ["1975.55000000", "0.00260000"], ["1975.56000000", "0.00260000"], ["1975.60000000", "18.93390000"], ["1975.61000000", "7.09530000"], ["1975.62000000", "0.00260000"], ["1975.72000000", "0.00000000"], ["1975.73000000", "8.55840000"], ["1975.78000000", "0.00260000"], ["1975.80000000", "0.76310000"], ["1975.81000000", "0.01930000"], ["1975.82000000", "21.28890000"], ["1975.84000000", "1.05400000"], ["1975.96000000", "0.55810000"], ["1976.04000000", "3.97700000"], ["1976.06000000", "0.00260000"], ["1976.16000000", "0.03000000"], ["1976.26000000", "0.00000000"], ["1977.11000000", "1.51780000"], ["1977.22000000", "0.43810000"], ["1978.65000000", "0.15370000"], ["1978.74000000", "0.03910000"], ["1978.78000000", "0.00260000"], ["1978.87000000", "0.00260000"], ["1981.63000000", "0.00270000"], ["1982.34000000", "0.00000000"], ["1982.43000000", "0.01000000"], ["1982.44000000", "0.00000000"], ["1982.52000000", "100.51320000"], ["1982.57000000", "0.00270000"], ["1982.58000000", "3.60000000"], ["1982.83000000", "64.08910000"], ["1983.18000000", "3.60000000"], ["1983.31000000", "0.29760000"], ["1988.68000000", "0.00000000"], ["1988.84000000", "0.00000000"]], "_local_ts_utc": "2026-06-01T07:49:12.512747+00:00"}
{"e": "depthUpdate", "E": 1780300153715, "s": "ETHUSDT", "U": 76583126796, "u": 76583127022, "b": [["1973.50000000", "53.22120000"], ["1973.49000000", "7.02150000"], ["1973.48000000", "0.01050000"], ["1973.47000000", "5.37330000"], ["1973.46000000", "0.00260000"], ["1973.45000000", "0.00260000"], ["1973.44000000", "0.03800000"], ["1973.43000000", "0.92140000"], ["1973.41000000", "0.00800000"], ["1973.40000000", "17.18710000"], ["1973.39000000", "0.43970000"], ["1973.38000000", "0.51480000"], ["1973.36000000", "0.50260000"], ["1973.35000000", "0.00000000"], ["1973.33000000", "0.91870000"], ["1973.32000000", "0.00000000"], ["1973.31000000", "8.48060000"], ["1973.30000000", "0.00570000"], ["1973.29000000", "26.50490000"], ["1973.28000000", "8.54440000"], ["1973.22000000", "9.49340000"], ["1973.02000000", "2.11720000"], ["1972.99000000", "0.00940000"], ["1972.95000000", "7.26580000"], ["1972.94000000", "0.02410000"], ["1972.82000000", "0.15140000"], ["1972.78000000", "0.00000000"], ["1972.59000000", "0.00000000"], ["1972.55000000", "8.51590000"], ["1972.50000000", "19.89980000"], ["1972.45000000", "8.51590000"], ["1971.81000000", "0.76000000"], ["1971.04000000", "1.03920000"], ["1970.03000000", "0.21970000"], ["1969.91000000", "0.01610000"], ["1968.43000000", "0.00000000"], ["1968.33000000", "0.03310000"], ["1967.95000000", "0.18320000"], ["1967.88000000", "0.78530000"], ["1967.86000000", "7.87010000"], ["1967.79000000", "0.00260000"], ["1776.15000000", "0.01240000"], ["1776.13000000", "0.00000000"]], "a": [["1973.48000000", "0.00000000"], ["1973.49000000", "0.00000000"], ["1973.50000000", "0.00000000"], ["1973.51000000", "1.91690000"], ["1973.52000000", "0.03300000"], ["1973.53000000", "0.02000000"], ["1973.58000000", "0.00000000"], ["1973.59000000", "0.00000000"], ["1973.80000000", "0.00570000"], ["1973.91000000", "15.37470000"], ["1973.96000000", "7.75030000"], ["1973.97000000", "10.86790000"], ["1973.99000000", "7.65880000"], ["1974.00000000", "38.65870000"], ["1974.01000000", "6.98440000"], ["1974.02000000", "0.20210000"], ["1974.09000000", "13.51490000"], ["1974.10000000", "9.41730000"], ["1974.16000000", "0.00000000"], ["1974.30000000", "4.39370000"], ["1974.35000000", "0.00000000"], ["1974.38000000", "2.52650000"], ["1974.53000000", "13.52350000"], ["1974.60000000", "0.81910000"], ["1974.61000000", "7.29960000"], ["1974.67000000", "7.49920000"], ["1974.72000000", "0.81060000"], ["1975.59000000", "2.04320000"], ["1975.72000000", "0.00000000"], ["1975.73000000", "0.00000000"], ["1975.82000000", "0.00300000"], ["1975.96000000", "0.00000000"], ["1976.15000000", "0.00300000"], ["1976.78000000", "0.00000000"], ["1978.59000000", "0.00520000"], ["1983.71000000", "0.00000000"], ["1984.02000000", "0.20110000"], ["1984.56000000", "0.10000000"]], "_local_ts_utc": "2026-06-01T07:49:12.611512+00:00"}
{"e": "depthUpdate", "E": 1780300153815, "s": "ETHUSDT", "U": 76583127023, "u": 76583127074, "b": [["1973.50000000", "59.69140000"], ["1973.49000000", "7.02410000"], ["1973.48000000", "0.01570000"], ["1973.41000000", "0.00260000"], ["1973.39000000", "0.43710000"], ["1973.38000000", "0.50680000"], ["1973.15000000", "16.68490000"], ["1973.09000000", "0.03300000"], ["1972.68000000", "0.00000000"], ["1972.62000000", "1.57000000"], ["1972.42000000", "11.17160000"], ["1971.78000000", "2.53860000"], ["1970.79000000", "0.93640000"], ["1970.78000000", "0.00460000"], ["1970.24000000", "24.08320000"], ["1969.73000000", "17.58870000"], ["1969.55000000", "0.00000000"], ["1967.87000000", "0.00520000"], ["1967.79000000", "0.00000000"], ["1966.89000000", "1.32850000"], ["1776.15000000", "0.01860000"]], "a": [["1973.51000000", "2.46410000"], ["1973.75000000", "0.00260000"], ["1973.82000000", "0.64190000"], ["1974.14000000", "0.10390000"], ["1974.20000000", "16.22210000"], ["1974.48000000", "15.61250000"], ["1974.55000000", "0.62360000"], ["1975.10000000", "15.46340000"], ["1975.11000000", "15.87620000"], ["1975.18000000", "13.25020000"], ["1975.60000000", "15.29540000"], ["1975.74000000", "0.00640000"], ["1975.88000000", "0.00520000"], ["1976.17000000", "0.75990000"], ["1976.34000000", "15.00000000"], ["1976.64000000", "100.83100000"], ["1976.72000000", "64.28460000"], ["1978.86000000", "126.49410000"], ["1978.87000000", "0.00000000"], ["1984.74000000", "0.20100000"], ["2170.86000000", "0.00260000"]], "_local_ts_utc": "2026-06-01T07:49:12.711380+00:00"}
{"e": "depthUpdate", "E": 1780300153915, "s": "ETHUSDT", "U": 76583127075, "u": 76583127685, "b": [["1973.65000000", "84.97880000"], ["1973.64000000", "8.60480000"], ["1973.63000000", "0.00770000"], ["1973.62000000", "0.00540000"], ["1973.61000000", "8.32870000"], ["1973.60000000", "0.03260000"], ["1973.59000000", "0.00000000"], ["1973.57000000", "0.00540000"], ["1973.56000000", "3.00000000"], ["1973.55000000", "0.00540000"], ["1973.54000000", "16.41050000"], ["1973.53000000", "0.40600000"], ["1973.52000000", "0.01290000"], ["1973.51000000", "8.51960000"], ["1973.50000000", "0.81030000"], ["1973.49000000", "0.00260000"], ["1973.48000000", "12.41960000"], ["1973.47000000", "12.16350000"], ["1973.46000000", "0.00260000"], ["1973.45000000", "7.09530000"], ["1973.44000000", "7.12530000"], ["1973.43000000", "0.00260000"], ["1973.42000000", "1.30720000"], ["1973.41000000", "0.00000000"], ["1973.40000000", "17.18760000"], ["1973.34000000", "14.19320000"], ["1973.33000000", "0.77690000"], ["1973.30000000", "0.03870000"], ["1973.20000000", "14.25300000"], ["1973.12000000", "1.74650000"], ["1973.09000000", "0.18410000"], ["1973.06000000", "8.90130000"], ["1973.02000000", "2.00000000"], ["1972.96000000", "6.72700000"], ["1972.90000000", "15.53920000"], ["1972.86000000", "1.01670000"], ["1972.85000000", "7.34920000"], ["1972.82000000", "0.05000000"], ["1972.74000000", "0.00560000"], ["1972.64000000", "0.30260000"], ["1972.60000000", "0.64710000"], ["1972.56000000", "7.09660000"], ["1972.53000000", "7.41950000"], ["1972.41000000", "0.00560000"], ["1972.30000000", "16.92870000"], ["1972.21000000", "16.41500000"], ["1972.18000000", "6.50950000"], ["1972.15000000", "0.00000000"], ["1972.14000000", "0.06550000"], ["1972.11000000", "7.09860000"], ["1972.01000000", "0.00000000"], ["1971.97000000", "1.79980000"], ["1971.96000000", "3.18600000"], ["1971.95000000", "1.00000000"], ["1971.92000000", "0.27000000"], ["1971.90000000", "11.10680000"], ["1971.85000000", "0.02190000"], ["1971.56000000", "3.60410000"], ["1971.47000000", "22.64960000"], ["1971.25000000", "1.03250000"], ["1971.20000000", "2.83590000"], ["1970.80000000", "0.00570000"], ["1970.79000000", "5.29460000"], ["1970.74000000", "0.27000000"], ["1970.71000000", "15.30560000"], ["1970.24000000", "23.95960000"], ["1970.20000000", "0.95660000"], ["1970.11000000", "0.06070000"], ["1969.73000000", "12.79030000"], ["1969.72000000", "32.27830000"], ["1969.60000000", "25.43520000"], ["1969.53000000", "0.00000000"], ["1969.03000000", "2.32950000"], ["1968.53000000", "0.00000000"], ["1968.47000000", "0.00260000"], ["1968.02000000", "0.00330000"], ["1967.99000000", "0.00000000"], ["1967.88000000", "0.78270000"], ["1966.29000000", "0.12210000"], ["1966.01000000", "0.04620000"], ["1962.09000000", "0.00420000"], ["1957.42000000", "3.11580000"], ["1956.39000000", "0.00000000"], ["1944.42000000", "28.14240000"], ["1944.16000000", "0.02340000"], ["1776.29000000", "0.01240000"], ["1776.15000000", "0.00000000"]], "a": [["1973.51000000", "0.00000000"], ["1973.52000000", "0.00000000"], ["1973.53000000", "0.00000000"], ["1973.54000000", "0.00000000"], ["1973.57000000", "0.00000000"], ["1973.60000000", "0.00000000"], ["1973.62000000", "0.00000000"], ["1973.63000000", "0.00000000"], ["1973.66000000", "4.72980000"], ["1973.67000000", "0.00260000"], ["1973.71000000", "0.00000000"], ["1973.72000000", "0.00000000"], ["1973.73000000", "0.05300000"], ["1973.76000000", "0.00000000"], ["1973.77000000", "0.00280000"], ["1973.78000000", "0.00000000"], ["1973.81000000", "0.00000000"], ["1973.82000000", "0.00000000"], ["1973.83000000", "0.00000000"], ["1973.85000000", "0.01160000"], ["1973.86000000", "0.00000000"], ["1973.87000000", "0.00000000"], ["1973.88000000", "0.00260000"], ["1973.90000000", "0.00570000"], ["1973.91000000", "0.00000000"], ["1973.94000000", "0.01810000"], ["1973.96000000", "0.14460000"], ["1973.97000000", "0.00000000"], ["1973.98000000", "0.01420000"], ["1973.99000000", "0.05050000"], ["1974.00000000", "3.37170000"], ["1974.01000000", "0.51680000"], ["1974.03000000", "0.00750000"], ["1974.05000000", "0.00000000"], ["1974.07000000", "0.00260000"], ["1974.09000000", "0.00000000"], ["1974.10000000", "2.85850000"], ["1974.11000000", "21.79520000"], ["1974.12000000", "0.00000000"], ["1974.13000000", "6.47020000"], ["1974.14000000", "0.00390000"], ["1974.17000000", "0.04620000"], ["1974.18000000", "0.63810000"], ["1974.20000000", "15.42210000"], ["1974.23000000", "0.00000000"], ["1974.24000000", "0.73260000"], ["1974.26000000", "13.51490000"], ["1974.28000000", "15.61530000"], ["1974.30000000", "5.19370000"], ["1974.33000000", "5.47120000"], ["1974.34000000", "9.92670000"], ["1974.38000000", "0.03300000"], ["1974.44000000", "0.38720000"], ["1974.50000000", "0.20680000"], ["1974.55000000", "0.62100000"], ["1974.60000000", "0.82170000"], ["1974.71000000", "0.37810000"], ["1974.81000000", "1.29660000"], ["1974.84000000", "8.52600000"], ["1974.89000000", "14.27880000"], ["1974.97000000", "0.21680000"], ["1974.99000000", "2.89090000"], ["1975.05000000", "7.09960000"], ["1975.56000000", "8.51700000"], ["1975.59000000", "3.72420000"], ["1975.62000000", "0.00260000"], ["1975.66000000", "1.09980000"], ["1975.82000000", "21.28890000"], ["1976.04000000", "3.97700000"], ["1976.06000000", "0.00260000"], ["1976.32000000", "0.03000000"], ["1976.63000000", "0.00000000"], ["1976.71000000", "13.51490000"], ["1976.84000000", "22.57630000"], ["1976.85000000", "0.00000000"], ["1977.04000000", "0.00000000"], ["1977.68000000", "0.79380000"], ["1977.72000000", "0.01020000"], ["1977.82000000", "9.38680000"], ["1977.88000000", "3.86920000"], ["1978.86000000", "126.49670000"], ["1978.95000000", "0.00260000"], ["1979.01000000", "1.20810000"], ["1985.45000000", "0.20830000"], ["1989.05000000", "0.00300000"], ["2170.86000000", "0.00000000"]], "_local_ts_utc": "2026-06-01T07:49:12.811350+00:00"}
{"e": "depthUpdate", "E": 1780300154015, "s": "ETHUSDT", "U": 76583127686, "u": 76583127824, "b": [["1973.65000000", "53.09520000"], ["1973.64000000", "0.00770000"], ["1973.63000000", "0.00770000"], ["1973.62000000", "0.00800000"], ["1973.61000000", "8.32870000"], ["1973.60000000", "0.03520000"], ["1973.58000000", "0.00260000"], ["1973.57000000", "0.00800000"], ["1973.56000000", "3.00800000"], ["1973.55000000", "15.54280000"], ["1973.54000000", "9.32050000"], ["1973.53000000", "0.40340000"], ["1973.51000000", "0.00260000"], ["1973.50000000", "1.44040000"], ["1973.49000000", "0.00000000"], ["1973.48000000", "8.52550000"], ["1973.47000000", "5.06560000"], ["1973.46000000", "0.00000000"], ["1973.40000000", "17.19060000"], ["1973.31000000", "1.70350000"], ["1973.22000000", "8.85700000"], ["1973.18000000", "0.00300000"], ["1973.02000000", "2.27000000"], ["1972.92000000", "0.40240000"], ["1972.77000000", "8.51590000"], ["1972.54000000", "7.77680000"], ["1972.36000000", "7.09660000"], ["1972.25000000", "0.00260000"], ["1972.21000000", "15.61500000"], ["1972.10000000", "0.15110000"], ["1972.09000000", "14.67340000"], ["1972.02000000", "0.00000000"], ["1971.96000000", "3.98600000"], ["1971.90000000", "11.10370000"], ["1971.72000000", "0.00260000"], ["1971.70000000", "7.87690000"], ["1971.63000000", "0.01370000"], ["1970.35000000", "0.75410000"], ["1970.31000000", "0.68330000"], ["1969.77000000", "0.00500000"], ["1968.08000000", "1.20550000"], ["1776.29000000", "0.02480000"], ["1473.13000000", "0.00000000"]], "a": [["1973.66000000", "19.22560000"], ["1973.67000000", "0.00000000"], ["1973.80000000", "0.01730000"], ["1973.83000000", "0.01160000"], ["1973.84000000", "0.00820000"], ["1973.94000000", "0.00650000"], ["1973.98000000", "10.73360000"], ["1973.99000000", "36.81480000"], ["1974.00000000", "0.85810000"], ["1974.01000000", "1.79260000"], ["1974.05000000", "0.64280000"], ["1974.10000000", "8.86190000"], ["1974.12000000", "8.51440000"], ["1974.13000000", "0.00260000"], ["1974.50000000", "1.00680000"], ["1974.72000000", "0.01060000"], ["1975.28000000", "0.51300000"], ["1975.56000000", "0.00260000"], ["1975.82000000", "7.09830000"], ["1976.00000000", "3.63580000"], ["1976.32000000", "0.00000000"], ["1976.35000000", "31.66750000"], ["1976.83000000", "11.25810000"], ["1977.34000000", "0.79380000"], ["1977.82000000", "0.00870000"], ["1978.89000000", "0.00000000"], ["2473.14000000", "0.00000000"]], "_local_ts_utc": "2026-06-01T07:49:12.911728+00:00"}
{"e": "depthUpdate", "E": 1780300154115, "s": "ETHUSDT", "U": 76583127825, "u": 76583127867, "b": [["1973.61000000", "8.83610000"], ["1973.60000000", "0.03520000"], ["1973.58000000", "0.00520000"], ["1973.56000000", "10.43430000"], ["1973.55000000", "10.21530000"], ["1973.54000000", "9.31520000"], ["1973.52000000", "0.01020000"], ["1973.49000000", "0.00000000"], ["1973.01000000", "7.36790000"], ["1972.54000000", "7.37680000"], ["1972.25000000", "0.40260000"], ["1972.14000000", "0.05030000"], ["1970.13000000", "4.08160000"], ["1970.00000000", "409.36310000"], ["1969.82000000", "0.00260000"], ["1969.73000000", "12.20960000"], ["1968.89000000", "11.83760000"], ["1934.17000000", "0.00000000"], ["1776.29000000", "0.03720000"]], "a": [["1973.66000000", "2.44090000"], ["1973.98000000", "6.49770000"], ["1973.99000000", "22.62420000"], ["1974.11000000", "28.26280000"], ["1974.50000000", "0.20680000"], ["1974.57000000", "0.93200000"], ["1975.34000000", "1.03360000"], ["1975.78000000", "14.18940000"], ["1976.26000000", "0.00300000"], ["1980.35000000", "0.18210000"]], "_local_ts_utc": "2026-06-01T07:49:13.011366+00:00"}
{"e": "depthUpdate", "E": 1780300154215, "s": "ETHUSDT", "U": 76583127868, "u": 76583127922, "b": [["1973.65000000", "63.30210000"], ["1973.64000000", "0.01310000"], ["1973.63000000", "6.79640000"], ["1973.62000000", "0.00800000"], ["1973.56000000", "3.00260000"], ["1973.55000000", "0.00260000"], ["1973.47000000", "12.15900000"], ["1972.54000000", "7.50350000"], ["1970.35000000", "0.15790000"], ["1970.20000000", "2.02230000"], ["1970.18000000", "1.36530000"], ["1776.29000000", "0.04960000"]], "a": [["1973.66000000", "0.71860000"], ["1973.67000000", "0.00260000"], ["1973.70000000", "0.10570000"], ["1973.80000000", "0.00570000"], ["1973.83000000", "0.00000000"], ["1973.85000000", "0.00000000"], ["1973.88000000", "0.00000000"], ["1973.98000000", "0.00260000"], ["1973.99000000", "0.05050000"], ["1974.00000000", "0.86970000"], ["1974.11000000", "36.77490000"], ["1974.12000000", "0.00000000"], ["1974.30000000", "4.39370000"], ["1974.34000000", "10.72670000"], ["1975.56000000", "0.00260000"], ["1976.09000000", "0.00000000"], ["1976.17000000", "0.20190000"], ["1976.18000000", "1.20810000"], ["1976.83000000", "1.88000000"], ["1977.82000000", "9.38680000"], ["1979.06000000", "0.00580000"]], "_local_ts_utc": "2026-06-01T07:49:13.111611+00:00"}
{"e": "depthUpdate", "E": 1780300154315, "s": "ETHUSDT", "U": 76583127923, "u": 76583128070, "b": [["1973.65000000", "69.56970000"], ["1973.64000000", "0.00770000"], ["1973.63000000", "0.00770000"], ["1973.62000000", "0.01060000"], ["1973.61000000", "2.36850000"], ["1973.55000000", "0.00800000"], ["1973.53000000", "0.40880000"], ["1973.52000000", "1.29120000"], ["1973.51000000", "0.00800000"], ["1973.50000000", "1.44040000"], ["1973.48000000", "4.40100000"], ["1973.47000000", "5.06560000"], ["1973.45000000", "0.00000000"], ["1973.44000000", "0.03000000"], ["1973.41000000", "14.18680000"], ["1973.40000000", "0.00870000"], ["1973.38000000", "9.01890000"], ["1973.37000000", "0.00000000"], ["1973.35000000", "0.05000000"], ["1973.34000000", "7.09790000"], ["1973.31000000", "8.79690000"], ["1973.30000000", "7.13210000"], ["1973.29000000", "12.99300000"], ["1973.28000000", "22.05570000"], ["1973.15000000", "39.06790000"], ["1973.05000000", "0.05000000"], ["1972.82000000", "0.00000000"], ["1972.51000000", "0.00260000"], ["1972.50000000", "19.28610000"], ["1972.43000000", "7.17990000"], ["1971.92000000", "7.36340000"], ["1971.91000000", "7.09340000"], ["1971.72000000", "0.00260000"], ["1971.45000000", "0.04760000"], ["1971.25000000", "0.01140000"], ["1970.77000000", "1.35870000"], ["1970.63000000", "1.51230000"], ["1969.88000000", "1.21270000"], ["1968.34000000", "0.12680000"], ["1963.49000000", "0.62170000"], ["1946.37000000", "1.50800000"], ["1776.29000000", "0.06200000"]], "a": [["1973.66000000", "2.42940000"], ["1973.67000000", "0.00000000"], ["1973.70000000", "0.00570000"], ["1973.73000000", "0.00300000"], ["1973.78000000", "0.00000000"], ["1973.82000000", "0.01160000"], ["1973.88000000", "0.00260000"], ["1973.91000000", "0.00000000"], ["1973.93000000", "0.03800000"], ["1973.96000000", "0.19460000"], ["1974.09000000", "15.60550000"], ["1974.10000000", "23.04870000"], ["1974.11000000", "0.46160000"], ["1974.19000000", "0.00000000"], ["1974.20000000", "21.91470000"], ["1974.21000000", "22.57370000"], ["1974.26000000", "13.56130000"], ["1974.32000000", "13.70400000"], ["1974.33000000", "26.78490000"], ["1974.78000000", "7.76800000"], ["1974.79000000", "1.51620000"], ["1974.88000000", "0.10600000"], ["1974.92000000", "2.19190000"], ["1974.93000000", "0.02000000"], ["1975.22000000", "0.00000000"], ["1975.56000000", "0.00260000"], ["1975.93000000", "0.68940000"], ["1976.00000000", "3.63580000"], ["1976.06000000", "0.00260000"], ["1976.18000000", "1.20550000"], ["1976.56000000", "1.47120000"], ["1976.85000000", "0.91040000"], ["1977.04000000", "0.00000000"], ["1979.06000000", "0.00320000"], ["1979.10000000", "0.00260000"], ["1983.32000000", "0.87870000"], ["2011.37000000", "0.04770000"]], "_local_ts_utc": "2026-06-01T07:49:13.211407+00:00"}
{"e": "depthUpdate", "E": 1780300154415, "s": "ETHUSDT", "U": 76583128071, "u": 76583128163, "b": [["1973.65000000", "69.56940000"], ["1973.59000000", "0.00000000"], ["1973.58000000", "0.00520000"], ["1973.57000000", "0.00800000"], ["1973.56000000", "3.00260000"], ["1973.55000000", "0.00260000"], ["1973.53000000", "0.40340000"], ["1973.51000000", "0.00260000"], ["1973.49000000", "0.00000000"], ["1973.48000000", "12.91310000"], ["1973.44000000", "7.12340000"], ["1973.42000000", "14.81850000"], ["1973.39000000", "0.43710000"], ["1973.20000000", "21.29610000"], ["1973.13000000", "16.88900000"], ["1972.62000000", "2.04500000"], ["1972.57000000", "11.36490000"], ["1972.55000000", "8.91590000"], ["1972.25000000", "0.00260000"], ["1971.97000000", "6.14070000"], ["1971.08000000", "12.65350000"], ["1971.07000000", "0.15640000"], ["1970.87000000", "8.57970000"], ["1970.63000000", "1.58830000"], ["1776.29000000", "0.07440000"]], "a": [["1973.66000000", "0.76750000"], ["1973.74000000", "0.03300000"], ["1973.82000000", "0.00000000"], ["1973.88000000", "0.00000000"], ["1974.00000000", "4.74600000"], ["1974.01000000", "0.51680000"], ["1974.05000000", "0.00000000"], ["1974.09000000", "7.09340000"], ["1974.10000000", "16.90780000"], ["1974.17000000", "6.51380000"], ["1974.26000000", "0.05000000"], ["1974.28000000", "29.12660000"], ["1975.32000000", "9.77540000"], ["1975.56000000", "8.51470000"], ["1976.37000000", "0.13490000"], ["1977.04000000", "0.00000000"]], "_local_ts_utc": "2026-06-01T07:49:13.311241+00:00"}
{"e": "depthUpdate", "E": 1780300154515, "s": "ETHUSDT", "U": 76583128164, "u": 76583128983, "b": [["1973.87000000", "82.79910000"], ["1973.86000000", "0.00510000"], ["1973.85000000", "0.00510000"], ["1973.84000000", "23.10030000"], ["1973.83000000", "2.84620000"], ["1973.82000000", "0.00000000"], ["1973.81000000", "0.00000000"], ["1973.80000000", "0.00260000"], ["1973.79000000", "0.00000000"], ["1973.77000000", "0.00000000"], ["1973.76000000", "2.99430000"], ["1973.75000000", "0.00260000"], ["1973.74000000", "17.63370000"], ["1973.73000000", "0.04780000"], ["1973.72000000", "0.00000000"], ["1973.71000000", "0.00000000"], ["1973.70000000", "0.00570000"], ["1973.69000000", "8.57050000"], ["1973.67000000", "7.33900000"], ["1973.66000000", "7.35330000"], ["1973.65000000", "0.24420000"], ["1973.64000000", "0.00260000"], ["1973.63000000", "0.00260000"], ["1973.62000000", "14.19200000"], ["1973.61000000", "3.01640000"], ["1973.60000000", "0.03570000"], ["1973.58000000", "8.51470000"], ["1973.57000000", "0.00000000"], ["1973.56000000", "0.00000000"], ["1973.55000000", "10.24580000"], ["1973.54000000", "16.40860000"], ["1973.52000000", "1.32420000"], ["1973.51000000", "14.18940000"], ["1973.50000000", "1.44350000"], ["1973.48000000", "25.21300000"], ["1973.46000000", "0.00390000"], ["1973.42000000", "13.51130000"], ["1973.39000000", "10.39960000"], ["1973.36000000", "0.24900000"], ["1973.23000000", "0.05050000"], ["1973.17000000", "0.17310000"], ["1973.16000000", "0.14000000"], ["1973.14000000", "15.28610000"], ["1973.13000000", "17.38490000"], ["1973.12000000", "0.40810000"], ["1973.11000000", "7.09530000"], ["1973.09000000", "0.45410000"], ["1973.08000000", "7.95610000"], ["1973.06000000", "8.89870000"], ["1972.96000000", "6.62560000"], ["1972.94000000", "0.00000000"], ["1972.90000000", "15.33920000"], ["1972.84000000", "0.86750000"], ["1972.80000000", "19.66890000"], ["1972.77000000", "8.91590000"], ["1972.76000000", "0.00000000"], ["1972.70000000", "32.42400000"], ["1972.62000000", "0.84500000"], ["1972.61000000", "0.54000000"], ["1972.55000000", "9.31590000"], ["1972.50000000", "19.08610000"], ["1972.38000000", "13.58570000"], ["1972.33000000", "0.00000000"], ["1972.31000000", "7.09920000"], ["1972.30000000", "16.86030000"], ["1972.22000000", "1.25910000"], ["1972.21000000", "0.00000000"], ["1972.18000000", "2.26620000"], ["1972.17000000", "0.00000000"], ["1972.12000000", "0.00000000"], ["1972.11000000", "0.00000000"], ["1972.07000000", "3.60000000"], ["1971.97000000", "1.79980000"], ["1971.96000000", "3.18600000"], ["1971.95000000", "0.00000000"], ["1971.92000000", "0.27000000"], ["1971.91000000", "0.00000000"], ["1971.85000000", "16.00740000"], ["1971.84000000", "0.09300000"], ["1971.76000000", "10.44580000"], ["1971.69000000", "0.36630000"], ["1971.68000000", "22.61720000"], ["1971.36000000", "2.28680000"], ["1971.31000000", "0.24770000"], ["1971.25000000", "1.04870000"], ["1970.98000000", "5.35970000"], ["1970.97000000", "0.03880000"], ["1970.94000000", "1.27580000"], ["1970.78000000", "0.50640000"], ["1970.50000000", "0.04450000"], ["1969.66000000", "16.32880000"], ["1969.39000000", "0.25980000"], ["1968.75000000", "0.06270000"], ["1968.73000000", "31.91820000"], ["1968.69000000", "0.00000000"], ["1968.61000000", "0.00000000"], ["1968.50000000", "0.06740000"], ["1968.17000000", "0.13690000"], ["1968.13000000", "0.54730000"], ["1966.82000000", "0.35030000"], ["1966.29000000", "0.11380000"], ["1965.65000000", "0.50140000"], ["1965.30000000", "0.04180000"], ["1964.66000000", "6.75570000"], ["1963.75000000", "0.44730000"], ["1962.19000000", "0.01770000"], ["1961.76000000", "90.18590000"], ["1946.37000000", "0.00000000"], ["1934.39000000", "0.00000000"], ["1934.35000000", "0.01980000"], ["1776.45000000", "0.00000000"], ["1776.36000000", "0.00000000"], ["1776.29000000", "0.00000000"], ["1579.07000000", "0.01400000"], ["1577.67000000", "0.00700000"], ["1473.66000000", "0.02030000"]], "a": [["1973.66000000", "0.00000000"], ["1973.70000000", "0.00000000"], ["1973.73000000", "0.00000000"], ["1973.74000000", "0.00000000"], ["1973.75000000", "0.00000000"], ["1973.76000000", "0.00000000"], ["1973.77000000", "0.00000000"], ["1973.80000000", "0.00000000"], ["1973.82000000", "0.00000000"], ["1973.84000000", "0.00000000"], ["1973.88000000", "0.10210000"], ["1973.89000000", "0.00780000"], ["1973.92000000", "0.00000000"], ["1973.93000000", "0.00260000"], ["1973.94000000", "0.00390000"], ["1973.95000000", "0.04140000"], ["1973.96000000", "0.19200000"], ["1973.98000000", "0.00000000"], ["1973.99000000", "0.00000000"], ["1974.00000000", "0.03110000"], ["1974.01000000", "0.52220000"], ["1974.06000000", "0.00300000"], ["1974.08000000", "0.03000000"], ["1974.09000000", "0.00540000"], ["1974.10000000", "0.00570000"], ["1974.11000000", "0.00260000"], ["1974.14000000", "0.00650000"], ["1974.15000000", "0.01160000"], ["1974.16000000", "0.00000000"], ["1974.17000000", "0.04620000"], ["1974.19000000", "0.00000000"], ["1974.20000000", "13.83900000"], ["1974.21000000", "0.00000000"], ["1974.24000000", "0.03260000"], ["1974.26000000", "0.05000000"], ["1974.27000000", "0.64750000"], ["1974.28000000", "0.00560000"], ["1974.29000000", "0.02400000"], ["1974.31000000", "7.09340000"], ["1974.34000000", "9.92670000"], ["1974.38000000", "6.50060000"], ["1974.39000000", "7.16290000"], ["1974.41000000", "0.03130000"], ["1974.44000000", "0.00000000"], ["1974.48000000", "15.61250000"], ["1974.50000000", "0.20990000"], ["1974.52000000", "0.79030000"], ["1974.53000000", "0.00000000"], ["1974.54000000", "0.46280000"], ["1974.57000000", "0.13200000"], ["1974.59000000", "1.50000000"], ["1974.61000000", "7.09960000"], ["1974.64000000", "13.51130000"], ["1974.65000000", "15.42600000"], ["1974.67000000", "7.09920000"], ["1974.70000000", "22.57940000"], ["1974.72000000", "0.01060000"], ["1974.77000000", "3.66170000"], ["1974.78000000", "4.16800000"], ["1974.79000000", "0.00000000"], ["1974.80000000", "4.54950000"], ["1974.90000000", "23.04890000"], ["1974.92000000", "1.32890000"], ["1974.94000000", "0.00680000"], ["1974.99000000", "0.60000000"], ["1975.00000000", "0.80570000"], ["1975.11000000", "0.73990000"], ["1975.40000000", "3.62310000"], ["1975.53000000", "1.53900000"], ["1975.55000000", "7.10990000"], ["1975.59000000", "0.00000000"], ["1975.60000000", "18.83740000"], ["1975.65000000", "0.00000000"], ["1975.76000000", "26.21420000"], ["1975.77000000", "8.64400000"], ["1975.81000000", "9.87350000"], ["1975.94000000", "0.00640000"], ["1976.00000000", "17.82260000"], ["1976.02000000", "1.38840000"], ["1976.06000000", "7.09600000"], ["1976.08000000", "0.00000000"], ["1976.11000000", "0.04570000"], ["1976.18000000", "8.29890000"], ["1976.30000000", "7.09600000"], ["1976.32000000", "0.03000000"], ["1976.33000000", "1.30740000"], ["1976.36000000", "0.00260000"], ["1976.39000000", "0.00000000"], ["1976.48000000", "0.03000000"], ["1976.78000000", "0.00000000"], ["1976.99000000", "0.50830000"], ["1977.03000000", "1.89510000"], ["1977.04000000", "13.51130000"], ["1977.20000000", "22.57680000"], ["1977.88000000", "3.80080000"], ["1977.96000000", "0.06840000"], ["1979.09000000", "0.00260000"], ["1979.10000000", "0.00000000"], ["1979.18000000", "0.00260000"], ["1979.30000000", "0.00260000"], ["1980.06000000", "0.00000000"], ["1980.78000000", "0.00260000"], ["1982.51000000", "0.15110000"], ["1983.32000000", "0.38770000"], ["1983.58000000", "4.11480000"], ["1983.64000000", "0.00260000"], ["1989.60000000", "0.00310000"], ["1998.50000000", "0.00000000"], ["2473.70000000", "0.01180000"]], "_local_ts_utc": "2026-06-01T07:49:13.411393+00:00"}
{"e": "depthUpdate", "E": 1780300154621, "s": "ETHUSDT", "U": 76583128984, "u": 76583130499, "b": [["1974.27000000", "20.48580000"], ["1974.25000000", "91.40790000"], ["1974.24000000", "31.03110000"], ["1974.23000000", "2.08240000"], ["1974.20000000", "0.00260000"], ["1974.19000000", "0.00000000"], ["1974.18000000", "0.00800000"], ["1974.17000000", "8.57200000"], ["1974.16000000", "0.41250000"], ["1974.15000000", "0.00000000"], ["1974.14000000", "0.00000000"], ["1974.13000000", "0.00000000"], ["1974.12000000", "0.00000000"], ["1974.11000000", "5.50230000"], ["1974.10000000", "0.41770000"], ["1974.09000000", "0.00000000"], ["1974.07000000", "0.50630000"], ["1974.06000000", "0.00000000"], ["1974.05000000", "0.00260000"], ["1974.04000000", "4.47030000"], ["1974.03000000", "18.19410000"], ["1974.02000000", "4.28870000"], ["1974.01000000", "1.00260000"], ["1974.00000000", "0.00260000"], ["1973.99000000", "0.00000000"], ["1973.97000000", "15.53440000"], ["1973.96000000", "42.71080000"], ["1973.95000000", "11.81210000"], ["1973.94000000", "17.20850000"], ["1973.93000000", "2.09940000"], ["1973.92000000", "0.03000000"], ["1973.90000000", "5.78780000"], ["1973.89000000", "10.66400000"], ["1973.88000000", "10.20350000"], ["1973.87000000", "1.38890000"], ["1973.86000000", "0.00380000"], ["1973.85000000", "0.01020000"], ["1973.84000000", "0.00000000"], ["1973.83000000", "2.84360000"], ["1973.80000000", "10.27170000"], ["1973.79000000", "9.82240000"], ["1973.76000000", "7.12340000"], ["1973.75000000", "0.00000000"], ["1973.74000000", "14.18680000"], ["1973.73000000", "0.07820000"], ["1973.70000000", "13.51700000"], ["1973.69000000", "8.51210000"], ["1973.68000000", "0.00260000"], ["1973.66000000", "7.35070000"], ["1973.65000000", "0.00000000"], ["1973.64000000", "0.61530000"], ["1973.63000000", "0.00000000"], ["1973.62000000", "14.18940000"], ["1973.61000000", "1.50890000"], ["1973.58000000", "8.51210000"], ["1973.57000000", "20.77160000"], ["1973.56000000", "13.51130000"], ["1973.55000000", "0.00000000"], ["1973.54000000", "7.09340000"], ["1973.53000000", "0.00000000"], ["1973.52000000", "0.04320000"], ["1973.51000000", "14.35990000"], ["1973.50000000", "0.38380000"], ["1973.47000000", "2.00000000"], ["1973.42000000", "13.76220000"], ["1973.39000000", "9.97200000"], ["1973.38000000", "8.51210000"], ["1973.36000000", "0.00000000"], ["1973.34000000", "10.69790000"], ["1973.33000000", "0.00000000"], ["1973.31000000", "7.09340000"], ["1973.30000000", "7.35790000"], ["1973.27000000", "1.00000000"], ["1973.23000000", "0.00000000"], ["1973.22000000", "0.00000000"], ["1973.20000000", "20.68510000"], ["1973.19000000", "0.26110000"], ["1973.14000000", "13.68470000"], ["1973.12000000", "0.03000000"], ["1973.10000000", "0.00310000"], ["1973.06000000", "10.10420000"], ["1973.00000000", "12.07110000"], ["1972.99000000", "0.00000000"], ["1972.97000000", "8.91440000"], ["1972.96000000", "0.03000000"], ["1972.95000000", "7.09530000"], ["1972.91000000", "14.39060000"], ["1972.90000000", "15.33660000"], ["1972.87000000", "12.14890000"], ["1972.79000000", "5.40000000"], ["1972.77000000", "0.00000000"], ["1972.73000000", "0.00000000"], ["1972.70000000", "32.22400000"], ["1972.67000000", "3.60000000"], ["1972.65000000", "7.12960000"], ["1972.55000000", "0.00000000"], ["1972.53000000", "0.27260000"], ["1972.50000000", "12.07600000"], ["1972.46000000", "0.00390000"], ["1972.45000000", "0.00000000"], ["1972.43000000", "0.03300000"], ["1972.42000000", "3.60000000"], ["1972.39000000", "4.06580000"], ["1972.37000000", "0.00000000"], ["1972.36000000", "0.00000000"], ["1972.34000000", "0.00000000"], ["1972.31000000", "0.00260000"], ["1972.30000000", "11.30840000"], ["1972.19000000", "0.00300000"], ["1972.18000000", "0.00000000"], ["1972.16000000", "0.04280000"], ["1972.14000000", "0.00000000"], ["1972.13000000", "0.08650000"], ["1972.09000000", "14.88730000"], ["1972.08000000", "22.70670000"], ["1972.04000000", "0.00000000"], ["1971.96000000", "0.09380000"], ["1971.94000000", "0.00000000"], ["1971.90000000", "15.47740000"], ["1971.84000000", "0.04270000"], ["1971.71000000", "0.00000000"], ["1971.60000000", "1.83900000"], ["1971.54000000", "0.00700000"], ["1971.52000000", "0.00260000"], ["1971.27000000", "7.68350000"], ["1971.22000000", "0.27000000"], ["1970.98000000", "0.58510000"], ["1970.67000000", "70.25910000"], ["1970.56000000", "107.64090000"], ["1970.29000000", "9.00880000"], ["1970.21000000", "0.00980000"], ["1969.99000000", "0.00000000"], ["1969.86000000", "0.01540000"], ["1969.85000000", "4.80470000"], ["1969.54000000", "8.76550000"], ["1969.28000000", "1.21230000"], ["1969.17000000", "0.00000000"], ["1969.14000000", "0.00000000"], ["1969.08000000", "4.96470000"], ["1969.05000000", "3.60000000"], ["1969.03000000", "0.00700000"], ["1969.02000000", "0.21770000"], ["1969.01000000", "1.62360000"], ["1968.96000000", "0.00300000"], ["1968.94000000", "0.01370000"], ["1968.93000000", "22.57630000"], ["1968.87000000", "0.22170000"], ["1968.83000000", "0.00260000"], ["1968.43000000", "0.00000000"], ["1968.42000000", "0.00540000"], ["1968.38000000", "0.00730000"], ["1968.33000000", "0.03570000"], ["1968.31000000", "0.57610000"], ["1968.22000000", "0.79430000"], ["1967.46000000", "0.00300000"], ["1967.27000000", "0.12870000"], ["1966.76000000", "0.00790000"], ["1966.68000000", "0.00720000"], ["1966.53000000", "0.02000000"], ["1966.48000000", "0.00000000"], ["1966.08000000", "0.06690000"], ["1966.05000000", "2.85240000"], ["1965.85000000", "0.05460000"], ["1963.76000000", "0.49800000"], ["1963.49000000", "0.14610000"], ["1963.25000000", "11.12090000"], ["1962.84000000", "0.00380000"], ["1962.74000000", "0.00000000"], ["1962.14000000", "0.04950000"], ["1944.98000000", "38.38820000"], ["1944.77000000", "0.00500000"], ["1944.42000000", "0.51090000"], ["1934.68000000", "0.00000000"], ["1934.48000000", "0.01900000"], ["1776.76000000", "0.03640000"], ["1776.55000000", "0.04230000"], ["1577.67000000", "0.00000000"]], "a": [["1973.88000000", "0.00000000"], ["1973.89000000", "0.00000000"], ["1973.90000000", "0.00000000"], ["1973.93000000", "0.00000000"], ["1973.94000000", "0.00000000"], ["1973.95000000", "0.00000000"], ["1973.96000000", "0.00000000"], ["1973.97000000", "0.00000000"], ["1974.00000000", "0.00000000"], ["1974.01000000", "0.00000000"], ["1974.02000000", "0.00000000"], ["1974.03000000", "0.00000000"], ["1974.06000000", "0.00000000"], ["1974.07000000", "0.00000000"], ["1974.08000000", "0.00000000"], ["1974.09000000", "0.00000000"], ["1974.10000000", "0.00000000"], ["1974.11000000", "0.00000000"], ["1974.12000000", "0.00000000"], ["1974.13000000", "0.00000000"], ["1974.14000000", "0.00000000"], ["1974.15000000", "0.00000000"], ["1974.16000000", "0.00000000"], ["1974.17000000", "0.00000000"], ["1974.18000000", "0.00000000"], ["1974.19000000", "0.00000000"], ["1974.20000000", "0.00000000"], ["1974.24000000", "0.00000000"], ["1974.25000000", "0.00000000"], ["1974.26000000", "0.00000000"], ["1974.27000000", "0.00000000"], ["1974.28000000", "0.00560000"], ["1974.29000000", "0.00000000"], ["1974.30000000", "0.10260000"], ["1974.31000000", "0.00000000"], ["1974.32000000", "0.00260000"], ["1974.33000000", "0.00390000"], ["1974.34000000", "0.00380000"], ["1974.37000000", "0.00800000"], ["1974.38000000", "0.03300000"], ["1974.39000000", "0.06370000"], ["1974.41000000", "0.03670000"], ["1974.42000000", "0.00000000"], ["1974.43000000", "0.00520000"], ["1974.45000000", "0.00000000"], ["1974.46000000", "0.00000000"], ["1974.47000000", "0.02000000"], ["1974.48000000", "0.00800000"], ["1974.49000000", "0.00000000"], ["1974.51000000", "0.00530000"], ["1974.52000000", "0.79030000"], ["1974.53000000", "0.00000000"], ["1974.55000000", "0.00000000"], ["1974.59000000", "0.00000000"], ["1974.60000000", "0.03870000"], ["1974.61000000", "0.00300000"], ["1974.62000000", "0.00000000"], ["1974.63000000", "0.01160000"], ["1974.64000000", "0.00000000"], ["1974.65000000", "15.42600000"], ["1974.66000000", "0.00000000"], ["1974.67000000", "0.00260000"], ["1974.69000000", "0.64800000"], ["1974.70000000", "0.00570000"], ["1974.71000000", "0.00000000"], ["1974.73000000", "4.34060000"], ["1974.77000000", "1.31450000"], ["1974.78000000", "0.04800000"], ["1974.81000000", "0.00000000"], ["1974.83000000", "0.00300000"], ["1974.84000000", "0.00000000"], ["1974.85000000", "14.94820000"], ["1974.86000000", "0.00000000"], ["1974.89000000", "0.00000000"], ["1974.90000000", "23.05460000"], ["1974.91000000", "0.00000000"], ["1974.92000000", "0.00260000"], ["1974.96000000", "0.00000000"], ["1974.97000000", "0.00000000"], ["1974.98000000", "8.59060000"], ["1974.99000000", "26.78100000"], ["1975.00000000", "0.00830000"], ["1975.05000000", "7.09960000"], ["1975.08000000", "16.07890000"], ["1975.10000000", "7.68400000"], ["1975.15000000", "0.02020000"], ["1975.17000000", "1.35010000"], ["1975.18000000", "0.00000000"], ["1975.20000000", "0.03570000"], ["1975.29000000", "0.00000000"], ["1975.43000000", "0.21720000"], ["1975.66000000", "0.15110000"], ["1975.82000000", "11.09830000"], ["1975.89000000", "0.03300000"], ["1975.98000000", "8.14760000"], ["1975.99000000", "8.51210000"], ["1976.03000000", "6.18720000"], ["1976.04000000", "13.62300000"], ["1976.05000000", "0.43010000"], ["1976.11000000", "15.48530000"], ["1976.14000000", "0.00640000"], ["1976.17000000", "15.80740000"], ["1976.18000000", "8.29890000"], ["1976.21000000", "3.60000000"], ["1976.32000000", "5.07970000"], ["1976.33000000", "24.00630000"], ["1976.34000000", "15.00380000"], ["1976.35000000", "0.00380000"], ["1976.40000000", "0.02380000"], ["1976.54000000", "21.31310000"], ["1976.56000000", "0.00000000"], ["1976.63000000", "13.19730000"], ["1976.64000000", "100.86100000"], ["1976.66000000", "0.00000000"], ["1976.70000000", "7.09640000"], ["1976.77000000", "2.23030000"], ["1976.80000000", "0.03310000"], ["1976.86000000", "32.61580000"], ["1976.91000000", "31.65490000"], ["1977.29000000", "1.01920000"], ["1977.37000000", "13.51130000"], ["1977.51000000", "0.33450000"], ["1977.56000000", "22.57370000"], ["1977.68000000", "0.00000000"], ["1977.70000000", "13.51130000"], ["1977.81000000", "22.57370000"], ["1978.34000000", "31.63190000"], ["1979.24000000", "0.94750000"], ["1979.37000000", "0.00260000"], ["1979.46000000", "0.00260000"], ["1979.93000000", "31.60920000"], ["1983.09000000", "0.00000000"], ["1983.58000000", "3.62970000"], ["1983.69000000", "0.01480000"], ["1985.32000000", "10.80990000"]], "_local_ts_utc": "2026-06-01T07:49:13.520055+00:00"}
{"e": "depthUpdate", "E": 1780300154715, "s": "ETHUSDT", "U": 76583130500, "u": 76583131176, "b": [["1974.37000000", "82.80500000"], ["1974.36000000", "0.00510000"], ["1974.35000000", "0.00510000"], ["1974.34000000", "1.23070000"], ["1974.33000000", "0.50630000"], ["1974.32000000", "0.00260000"], ["1974.31000000", "0.00000000"], ["1974.30000000", "9.54080000"], ["1974.29000000", "10.11230000"], ["1974.28000000", "0.00000000"], ["1974.27000000", "0.00260000"], ["1974.26000000", "0.00000000"], ["1974.25000000", "0.15720000"], ["1974.24000000", "0.03260000"], ["1974.23000000", "1.94990000"], ["1974.20000000", "0.01530000"], ["1974.18000000", "0.00260000"], ["1974.17000000", "13.22780000"], ["1974.16000000", "0.00000000"], ["1974.15000000", "0.65010000"], ["1974.13000000", "8.51210000"], ["1974.12000000", "0.25350000"], ["1974.11000000", "5.49970000"], ["1974.10000000", "0.00570000"], ["1974.08000000", "18.54890000"], ["1974.07000000", "14.18680000"], ["1974.06000000", "0.00380000"], ["1974.05000000", "0.50920000"], ["1974.04000000", "0.00000000"], ["1974.03000000", "18.28520000"], ["1974.02000000", "4.28610000"], ["1974.01000000", "1.00000000"], ["1974.00000000", "0.00570000"], ["1973.98000000", "0.61530000"], ["1973.96000000", "42.70820000"], ["1973.94000000", "21.61050000"], ["1973.90000000", "5.78780000"], ["1973.89000000", "8.51470000"], ["1973.88000000", "0.00000000"], ["1973.87000000", "0.05780000"], ["1973.83000000", "1.00000000"], ["1973.79000000", "8.52180000"], ["1973.76000000", "7.14710000"], ["1973.73000000", "26.98710000"], ["1973.66000000", "7.09720000"], ["1973.64000000", "0.00000000"], ["1973.61000000", "1.61030000"], ["1973.58000000", "25.39870000"], ["1973.57000000", "3.60000000"], ["1973.56000000", "20.10070000"], ["1973.48000000", "20.81200000"], ["1973.39000000", "9.96250000"], ["1973.30000000", "7.33160000"], ["1973.29000000", "9.00590000"], ["1973.28000000", "22.05950000"], ["1973.17000000", "0.00260000"], ["1973.15000000", "12.28690000"], ["1973.12000000", "0.23000000"], ["1972.99000000", "0.80000000"], ["1972.91000000", "14.19060000"], ["1972.79000000", "3.60000000"], ["1972.65000000", "0.03300000"], ["1972.62000000", "0.37000000"], ["1972.57000000", "8.56300000"], ["1972.56000000", "0.00000000"], ["1972.53000000", "0.48550000"], ["1972.50000000", "5.27570000"], ["1972.13000000", "0.00000000"], ["1972.09000000", "14.67340000"], ["1972.05000000", "0.00750000"], ["1971.96000000", "0.00260000"], ["1971.84000000", "0.00260000"], ["1971.68000000", "22.58720000"], ["1971.60000000", "1.83640000"], ["1970.86000000", "23.17370000"], ["1970.79000000", "9.41000000"], ["1970.70000000", "36.96110000"], ["1970.63000000", "0.07860000"], ["1970.60000000", "40.25420000"], ["1970.06000000", "0.04550000"], ["1970.05000000", "4.38030000"], ["1969.30000000", "0.00000000"], ["1969.27000000", "0.19480000"], ["1969.25000000", "3.60000000"], ["1969.15000000", "0.13490000"], ["1968.76000000", "0.04920000"], ["1968.67000000", "0.00260000"], ["1968.66000000", "1.18420000"], ["1968.58000000", "6.96270000"], ["1968.54000000", "0.00000000"], ["1968.47000000", "0.00000000"], ["1968.42000000", "0.00280000"], ["1968.33000000", "0.03310000"], ["1968.26000000", "0.02560000"], ["1968.01000000", "0.00000000"], ["1967.86000000", "0.00000000"], ["1967.43000000", "0.00260000"], ["1966.76000000", "0.00000000"], ["1964.45000000", "0.00000000"], ["1934.88000000", "0.01050000"], ["1934.80000000", "0.00000000"], ["1934.78000000", "0.00000000"], ["1776.87000000", "0.00000000"], ["1776.84000000", "0.00000000"], ["1579.40000000", "0.00700000"]], "a": [["1974.28000000", "0.00000000"], ["1974.30000000", "0.00000000"], ["1974.32000000", "0.00000000"], ["1974.33000000", "0.00000000"], ["1974.34000000", "0.00000000"], ["1974.36000000", "0.00000000"], ["1974.37000000", "0.00000000"], ["1974.38000000", "0.03610000"], ["1974.39000000", "0.01320000"], ["1974.40000000", "0.00570000"], ["1974.41000000", "0.03130000"], ["1974.43000000", "0.00260000"], ["1974.45000000", "0.10000000"], ["1974.48000000", "0.00000000"], ["1974.49000000", "0.00540000"], ["1974.51000000", "0.00000000"], ["1974.52000000", "0.00000000"], ["1974.53000000", "0.00000000"], ["1974.54000000", "0.00380000"], ["1974.57000000", "0.13740000"], ["1974.58000000", "0.16100000"], ["1974.61000000", "0.00560000"], ["1974.63000000", "0.00000000"], ["1974.65000000", "0.00000000"], ["1974.68000000", "0.96550000"], ["1974.69000000", "0.64800000"], ["1974.72000000", "2.66350000"], ["1974.77000000", "0.00000000"], ["1974.78000000", "0.04800000"], ["1974.79000000", "7.09340000"], ["1974.81000000", "12.95540000"], ["1974.82000000", "14.73280000"], ["1974.85000000", "0.46160000"], ["1974.89000000", "9.15020000"], ["1974.90000000", "22.57940000"], ["1974.92000000", "0.00260000"], ["1974.93000000", "0.02000000"], ["1974.96000000", "13.94220000"], ["1974.97000000", "30.52430000"], ["1974.98000000", "2.09400000"], ["1975.08000000", "15.98780000"], ["1975.10000000", "7.68710000"], ["1975.11000000", "0.51300000"], ["1975.14000000", "0.00380000"], ["1975.17000000", "1.54000000"], ["1975.21000000", "0.00000000"], ["1975.27000000", "0.40300000"], ["1975.29000000", "0.00000000"], ["1975.30000000", "0.00260000"], ["1975.34000000", "1.83360000"], ["1975.35000000", "0.09370000"], ["1975.37000000", "7.18140000"], ["1975.46000000", "13.56440000"], ["1975.47000000", "22.62380000"], ["1975.84000000", "0.03260000"], ["1975.92000000", "0.23110000"], ["1976.04000000", "9.64900000"], ["1976.20000000", "3.19750000"], ["1976.32000000", "11.07820000"], ["1976.33000000", "15.49420000"], ["1976.34000000", "0.00380000"], ["1976.40000000", "5.14610000"], ["1976.52000000", "1.02110000"], ["1976.53000000", "0.00000000"], ["1976.56000000", "0.00000000"], ["1976.63000000", "0.00000000"], ["1976.69000000", "0.00000000"], ["1976.70000000", "0.00300000"], ["1976.83000000", "0.00000000"], ["1976.96000000", "0.03000000"], ["1976.99000000", "0.00000000"], ["1977.03000000", "0.00000000"], ["1977.21000000", "0.01000000"], ["1977.58000000", "0.51050000"], ["1977.62000000", "1.92720000"], ["1977.70000000", "0.00000000"], ["1977.81000000", "25.69940000"], ["1978.02000000", "2.16560000"], ["1978.39000000", "0.00000000"], ["1979.19000000", "0.00000000"], ["1979.24000000", "0.00260000"], ["1979.40000000", "8.58550000"], ["1979.56000000", "0.00260000"], ["1979.62000000", "0.00260000"], ["1979.71000000", "0.00520000"], ["1979.82000000", "0.00260000"], ["1980.05000000", "0.00000000"], ["1980.13000000", "0.20060000"], ["1980.51000000", "0.38610000"], ["1980.58000000", "2.15150000"], ["1981.74000000", "2.25840000"], ["1981.84000000", "1.93500000"], ["1983.30000000", "0.00300000"], ["1984.18000000", "3.60000000"]], "_local_ts_utc": "2026-06-01T07:49:13.611723+00:00"}
{"e": "depthUpdate", "E": 1780300154815, "s": "ETHUSDT", "U": 76583131177, "u": 76583131758, "b": [["1974.49000000", "86.06440000"], ["1974.48000000", "10.64870000"], ["1974.47000000", "0.01050000"], ["1974.46000000", "1.58730000"], ["1974.43000000", "0.00540000"], ["1974.42000000", "6.47020000"], ["1974.41000000", "0.00540000"], ["1974.40000000", "0.86670000"], ["1974.39000000", "0.00270000"], ["1974.38000000", "2.76950000"], ["1974.37000000", "2.37550000"], ["1974.36000000", "0.00260000"], ["1974.35000000", "0.00260000"], ["1974.34000000", "0.00260000"], ["1974.33000000", "0.50890000"], ["1974.32000000", "0.00000000"], ["1974.31000000", "0.00000000"], ["1974.30000000", "0.00260000"], ["1974.29000000", "1.51960000"], ["1974.28000000", "2.13220000"], ["1974.27000000", "7.09600000"], ["1974.26000000", "0.00380000"], ["1974.25000000", "0.15460000"], ["1974.24000000", "0.03000000"], ["1974.23000000", "10.45940000"], ["1974.20000000", "0.01580000"], ["1974.19000000", "11.17450000"], ["1974.18000000", "7.09340000"], ["1974.17000000", "16.29880000"], ["1974.16000000", "0.03300000"], ["1973.95000000", "1.74360000"], ["1973.94000000", "14.08440000"], ["1973.93000000", "0.00000000"], ["1973.88000000", "0.00260000"], ["1973.87000000", "0.00000000"], ["1973.80000000", "18.77400000"], ["1973.77000000", "3.60000000"], ["1973.70000000", "24.98100000"], ["1973.68000000", "6.59200000"], ["1973.67000000", "0.00000000"], ["1973.61000000", "1.50890000"], ["1973.51000000", "14.18940000"], ["1973.50000000", "0.00310000"], ["1973.40000000", "0.00610000"], ["1973.20000000", "14.92350000"], ["1973.17000000", "0.40260000"], ["1973.14000000", "7.09530000"], ["1972.99000000", "0.85030000"], ["1972.97000000", "8.51440000"], ["1972.87000000", "3.63300000"], ["1972.86000000", "0.01670000"], ["1972.80000000", "12.46170000"], ["1972.75000000", "1.80000000"], ["1972.70000000", "29.47610000"], ["1972.57000000", "4.38990000"], ["1972.54000000", "0.40690000"], ["1972.16000000", "0.11810000"], ["1971.63000000", "0.01110000"], ["1971.47000000", "22.57370000"], ["1971.45000000", "0.54940000"], ["1971.00000000", "14.07310000"], ["1970.99000000", "1.07830000"], ["1970.98000000", "0.00560000"], ["1970.92000000", "0.76190000"], ["1970.86000000", "22.57760000"], ["1970.31000000", "0.00000000"], ["1970.26000000", "1.01970000"], ["1970.24000000", "23.52480000"], ["1969.29000000", "22.57880000"], ["1968.67000000", "0.00000000"], ["1967.52000000", "0.00740000"], ["1966.97000000", "0.01620000"], ["1966.25000000", "0.02140000"], ["1965.86000000", "0.40120000"], ["1964.15000000", "0.00300000"], ["1963.79000000", "0.35380000"], ["1963.19000000", "0.03560000"], ["1962.86000000", "0.00000000"], ["1935.00000000", "42.21460000"], ["1934.99000000", "0.00000000"], ["1934.89000000", "0.00000000"], ["1777.05000000", "0.01090000"], ["1777.04000000", "0.03110000"], ["1776.94000000", "0.02810000"]], "a": [["1974.38000000", "0.00000000"], ["1974.39000000", "0.00000000"], ["1974.40000000", "0.00000000"], ["1974.41000000", "0.00000000"], ["1974.43000000", "0.00000000"], ["1974.45000000", "0.00000000"], ["1974.47000000", "0.00000000"], ["1974.49000000", "0.00000000"], ["1974.50000000", "11.75820000"], ["1974.56000000", "0.03540000"], ["1974.61000000", "0.10300000"], ["1974.67000000", "0.00000000"], ["1974.68000000", "0.50650000"], ["1974.69000000", "0.00000000"], ["1974.71000000", "0.00000000"], ["1974.72000000", "4.52210000"], ["1974.77000000", "0.01160000"], ["1974.78000000", "0.04800000"], ["1974.79000000", "0.00000000"], ["1974.80000000", "5.87300000"], ["1974.94000000", "0.00680000"], ["1974.95000000", "7.10500000"], ["1975.03000000", "10.01940000"], ["1975.04000000", "7.57760000"], ["1975.08000000", "15.60970000"], ["1975.17000000", "1.34000000"], ["1975.23000000", "0.20260000"], ["1975.27000000", "0.00300000"], ["1975.30000000", "0.00570000"], ["1975.33000000", "0.00000000"], ["1975.34000000", "1.03360000"], ["1975.37000000", "7.58140000"], ["1975.40000000", "3.62570000"], ["1975.41000000", "0.80000000"], ["1975.47000000", "22.58390000"], ["1975.72000000", "0.02210000"], ["1976.32000000", "5.07970000"], ["1976.47000000", "0.94830000"], ["1976.54000000", "14.21970000"], ["1976.61000000", "0.99260000"], ["1976.70000000", "7.09640000"], ["1976.79000000", "0.55790000"], ["1976.98000000", "15.03290000"], ["1977.83000000", "0.00000000"], ["1979.76000000", "0.00260000"], ["1979.88000000", "0.00260000"], ["1979.97000000", "0.00260000"], ["1980.03000000", "2.55960000"], ["1984.31000000", "0.03480000"], ["1984.35000000", "13.51750000"], ["1984.39000000", "113.37150000"]], "_local_ts_utc": "2026-06-01T07:49:13.711660+00:00"}
{"e": "depthUpdate", "E": 1780300154915, "s": "ETHUSDT", "U": 76583131759, "u": 76583131865, "b": [["1974.49000000", "52.33340000"], ["1974.48000000", "1.34740000"], ["1974.47000000", "0.01310000"], ["1974.46000000", "1.44550000"], ["1974.43000000", "0.00800000"], ["1974.42000000", "6.47020000"], ["1974.41000000", "0.00800000"], ["1974.40000000", "0.86930000"], ["1974.39000000", "0.00530000"], ["1974.37000000", "2.37290000"], ["1974.36000000", "0.00000000"], ["1974.35000000", "0.00000000"], ["1974.34000000", "0.00000000"], ["1974.33000000", "0.50630000"], ["1974.29000000", "0.22960000"], ["1974.28000000", "12.33530000"], ["1974.27000000", "7.74110000"], ["1974.19000000", "6.37800000"], ["1974.15000000", "0.00260000"], ["1973.98000000", "0.62050000"], ["1973.97000000", "17.35210000"], ["1973.94000000", "14.11170000"], ["1973.88000000", "0.00520000"], ["1973.81000000", "6.58940000"], ["1973.62000000", "14.18680000"], ["1973.61000000", "1.00260000"], ["1973.59000000", "15.27180000"], ["1973.58000000", "10.06240000"], ["1973.56000000", "13.51130000"], ["1973.29000000", "9.05620000"], ["1972.67000000", "6.35540000"], ["1972.15000000", "0.04730000"], ["1971.97000000", "0.27300000"], ["1971.45000000", "0.50180000"], ["1971.28000000", "0.60480000"], ["1968.76000000", "0.04660000"], ["1965.87000000", "0.96050000"], ["1965.49000000", "2.36110000"], ["1964.11000000", "0.00000000"], ["1777.05000000", "0.02330000"]], "a": [["1974.50000000", "17.14790000"], ["1974.56000000", "0.00540000"], ["1974.60000000", "0.05030000"], ["1974.61000000", "0.00300000"], ["1974.72000000", "0.01060000"], ["1974.73000000", "0.01420000"], ["1974.78000000", "0.00000000"], ["1974.79000000", "1.75310000"], ["1974.81000000", "15.19110000"], ["1974.82000000", "14.21980000"], ["1974.85000000", "0.00260000"], ["1974.86000000", "0.62050000"], ["1974.88000000", "0.03000000"], ["1974.90000000", "0.00570000"], ["1974.96000000", "22.68890000"], ["1974.98000000", "24.66770000"], ["1975.05000000", "11.41660000"], ["1975.43000000", "0.00000000"], ["1975.48000000", "1.25380000"], ["1975.55000000", "9.87870000"], ["1975.59000000", "0.07670000"], ["1975.84000000", "0.24830000"], ["1976.70000000", "0.00300000"], ["1976.79000000", "0.00000000"], ["1977.12000000", "0.03000000"], ["1978.17000000", "22.57370000"], ["1980.03000000", "2.55700000"], ["1984.39000000", "0.00000000"], ["1984.41000000", "113.37150000"]], "_local_ts_utc": "2026-06-01T07:49:13.811280+00:00"}
{"e": "depthUpdate", "E": 1780300155015, "s": "ETHUSDT", "U": 76583131866, "u": 76583132013, "b": [["1974.49000000", "50.80000000"], ["1974.41000000", "0.00260000"], ["1974.40000000", "0.03520000"], ["1974.39000000", "0.00800000"], ["1974.38000000", "2.77220000"], ["1974.37000000", "10.88500000"], ["1974.30000000", "11.33980000"], ["1974.29000000", "14.41640000"], ["1974.28000000", "1.30150000"], ["1974.19000000", "10.43770000"], ["1974.17000000", "16.30180000"], ["1974.10000000", "13.51700000"], ["1974.05000000", "0.00260000"], ["1973.98000000", "0.67100000"], ["1973.88000000", "0.01300000"], ["1973.87000000", "0.37810000"], ["1973.84000000", "0.27000000"], ["1973.68000000", "0.05290000"], ["1973.29000000", "9.10650000"], ["1973.27000000", "1.01940000"], ["1972.97000000", "0.00000000"], ["1972.90000000", "15.33350000"], ["1972.81000000", "27.90940000"], ["1972.80000000", "8.22520000"], ["1972.71000000", "0.00000000"], ["1972.70000000", "29.47300000"], ["1972.68000000", "0.02050000"], ["1972.52000000", "13.52290000"], ["1972.50000000", "5.27260000"], ["1972.43000000", "0.03560000"], ["1972.30000000", "11.30530000"], ["1972.22000000", "1.23850000"], ["1972.09000000", "7.90080000"], ["1972.03000000", "0.00000000"], ["1972.00000000", "0.14140000"], ["1971.89000000", "0.00260000"], ["1970.79000000", "5.55010000"], ["1969.80000000", "3.04660000"], ["1969.40000000", "0.53240000"], ["1969.10000000", "36.81750000"], ["1968.46000000", "0.00900000"], ["1963.64000000", "236.56160000"], ["1961.94000000", "0.10170000"], ["1777.05000000", "0.03570000"], ["1473.66000000", "0.01430000"]], "a": [["1974.50000000", "2.36600000"], ["1974.56000000", "0.10540000"], ["1974.60000000", "0.03870000"], ["1974.67000000", "0.00000000"], ["1974.68000000", "0.00000000"], ["1974.73000000", "0.00800000"], ["1974.81000000", "0.00000000"], ["1974.82000000", "0.03300000"], ["1974.89000000", "0.63810000"], ["1974.96000000", "16.52460000"], ["1974.97000000", "17.01300000"], ["1974.98000000", "0.59660000"], ["1975.01000000", "16.33950000"], ["1975.02000000", "22.57370000"], ["1975.03000000", "0.97800000"], ["1975.10000000", "9.18710000"], ["1975.23000000", "0.00260000"], ["1975.26000000", "22.77370000"], ["1975.32000000", "9.67540000"], ["1975.37000000", "7.49530000"], ["1975.46000000", "13.94250000"], ["1975.78000000", "14.27650000"], ["1975.81000000", "9.85420000"], ["1975.86000000", "0.13000000"], ["1975.93000000", "0.00300000"], ["1976.02000000", "2.33340000"], ["1976.27000000", "0.01920000"], ["1976.40000000", "5.12540000"], ["1976.41000000", "12.11210000"], ["1976.53000000", "7.09340000"], ["1976.61000000", "0.00000000"], ["1976.65000000", "4.29970000"], ["1976.70000000", "14.18980000"], ["1976.85000000", "0.00000000"], ["1976.86000000", "32.63640000"], ["1977.21000000", "0.56770000"], ["1977.70000000", "13.51130000"], ["1979.51000000", "36.15720000"], ["1984.41000000", "0.00000000"], ["1984.43000000", "0.00380000"], ["1986.03000000", "113.37150000"], ["2038.11000000", "0.09890000"], ["2473.70000000", "0.00580000"]], "_local_ts_utc": "2026-06-01T07:49:13.911735+00:00"}
{"e": "depthUpdate", "E": 1780300155115, "s": "ETHUSDT", "U": 76583132014, "u": 76583132106, "b": [["1974.49000000", "50.60000000"], ["1974.44000000", "0.00540000"], ["1974.43000000", "1.95060000"], ["1974.40000000", "0.03790000"], ["1974.39000000", "5.15830000"], ["1974.38000000", "2.76950000"], ["1974.37000000", "2.37290000"], ["1974.33000000", "1.01360000"], ["1974.30000000", "11.34290000"], ["1974.29000000", "0.22960000"], ["1974.19000000", "10.94430000"], ["1973.95000000", "2.01360000"], ["1973.93000000", "0.27000000"], ["1973.43000000", "0.47740000"], ["1973.09000000", "0.50440000"], ["1970.54000000", "0.00300000"], ["1970.03000000", "0.71970000"], ["1969.83000000", "0.50260000"], ["1969.24000000", "0.53170000"], ["1969.04000000", "0.50260000"], ["1968.65000000", "4.10000000"], ["1966.64000000", "0.11290000"], ["1963.76000000", "0.00640000"], ["1950.82000000", "0.01670000"], ["1777.05000000", "0.04810000"]], "a": [["1974.50000000", "15.02450000"], ["1974.54000000", "0.00000000"], ["1974.56000000", "0.00540000"], ["1974.71000000", "0.01160000"], ["1974.73000000", "0.00260000"], ["1974.82000000", "0.53940000"], ["1974.98000000", "14.10210000"], ["1975.10000000", "7.68710000"], ["1975.16000000", "1.50300000"], ["1975.26000000", "22.57370000"], ["1975.33000000", "0.20000000"], ["1975.37000000", "7.09530000"], ["1975.41000000", "1.20000000"], ["1975.62000000", "0.78560000"], ["1975.65000000", "0.81000000"], ["1976.11000000", "16.26830000"], ["1976.14000000", "0.81640000"], ["1976.33000000", "14.22230000"], ["1976.48000000", "0.03300000"], ["1976.54000000", "14.22350000"], ["1976.63000000", "1.01910000"], ["1976.87000000", "28.34600000"], ["1976.94000000", "1.27140000"], ["1977.66000000", "0.93240000"], ["1977.70000000", "0.00000000"], ["2063.63000000", "0.11950000"], ["2106.08000000", "0.00630000"], ["2158.29000000", "0.00990000"], ["2221.13000000", "0.00830000"], ["2295.60000000", "0.02310000"]], "_local_ts_utc": "2026-06-01T07:49:14.011644+00:00"}
{"e": "depthUpdate", "E": 1780300155215, "s": "ETHUSDT", "U": 76583132107, "u": 76583132134, "b": [["1974.46000000", "1.44550000"], ["1974.44000000", "0.00260000"], ["1974.43000000", "1.94010000"], ["1974.40000000", "0.04320000"], ["1974.39000000", "1.84460000"], ["1974.38000000", "2.76690000"], ["1974.30000000", "5.56800000"], ["1974.28000000", "8.39190000"], ["1972.72000000", "0.27000000"], ["1968.89000000", "11.25670000"], ["1968.69000000", "0.58100000"], ["1955.34000000", "0.12760000"], ["1777.05000000", "0.06050000"]], "a": [["1974.50000000", "15.02000000"], ["1974.59000000", "0.01160000"], ["1974.73000000", "0.00520000"], ["1974.81000000", "0.54900000"], ["1974.95000000", "7.12850000"], ["1976.63000000", "0.00000000"], ["1983.32000000", "0.63860000"], ["1993.90000000", "0.00000000"]], "_local_ts_utc": "2026-06-01T07:49:14.110711+00:00"}
{"e": "depthUpdate", "E": 1780300155315, "s": "ETHUSDT", "U": 76583132135, "u": 76583132204, "b": [["1974.49000000", "50.19260000"], ["1974.44000000", "0.00260000"], ["1974.43000000", "0.00800000"], ["1974.39000000", "2.92180000"], ["1974.31000000", "4.40500000"], ["1974.27000000", "7.09600000"], ["1974.19000000", "10.99430000"], ["1974.07000000", "14.45680000"], ["1974.06000000", "0.54680000"], ["1973.99000000", "0.27000000"], ["1973.94000000", "9.70970000"], ["1973.89000000", "8.56470000"], ["1973.35000000", "0.00000000"], ["1973.05000000", "0.00000000"], ["1972.66000000", "13.52120000"], ["1970.58000000", "0.13720000"], ["1970.21000000", "0.00680000"], ["1963.79000000", "0.84360000"], ["1947.16000000", "1.48640000"], ["1777.05000000", "0.07290000"]], "a": [["1974.50000000", "14.67930000"], ["1974.57000000", "0.14900000"], ["1974.77000000", "3.88450000"], ["1974.78000000", "7.09040000"], ["1974.79000000", "0.00000000"], ["1974.80000000", "5.92300000"], ["1974.93000000", "13.57800000"], ["1974.95000000", "7.12030000"], ["1975.04000000", "1.11000000"], ["1975.10000000", "7.73710000"], ["1975.61000000", "8.55940000"], ["1975.62000000", "2.45960000"], ["1975.69000000", "0.51560000"], ["1976.12000000", "15.19130000"], ["1976.18000000", "8.81190000"], ["1976.54000000", "7.13010000"], ["1976.70000000", "7.09640000"], ["1977.34000000", "0.00000000"], ["1977.84000000", "0.82630000"], ["2038.11000000", "0.05930000"], ["2382.90000000", "0.01350000"], ["2484.43000000", "0.01260000"], ["2601.91000000", "0.01450000"], ["2737.41000000", "0.01670000"], ["2893.52000000", "0.01920000"]], "_local_ts_utc": "2026-06-01T07:49:14.213141+00:00"}
{"e": "depthUpdate", "E": 1780300155415, "s": "ETHUSDT", "U": 76583132205, "u": 76583132227, "b": [["1974.44000000", "0.00800000"], ["1974.43000000", "1.95240000"], ["1974.39000000", "2.91910000"], ["1974.26000000", "0.63600000"], ["1974.06000000", "0.81680000"], ["1970.91000000", "0.00000000"], ["1946.58000000", "0.12820000"], ["1932.49000000", "0.02190000"], ["1922.79000000", "0.00600000"], ["1913.16000000", "0.14770000"], ["1777.05000000", "0.08530000"], ["1192.00000000", "0.00000000"]], "a": [["1974.50000000", "11.46660000"], ["1974.92000000", "8.51110000"], ["1975.12000000", "1.26900000"], ["1975.62000000", "2.91860000"], ["1976.12000000", "15.65030000"], ["1976.41000000", "3.60000000"], ["1976.59000000", "0.00300000"]], "_local_ts_utc": "2026-06-01T07:49:14.311331+00:00"}
{"e": "depthUpdate", "E": 1780300155515, "s": "ETHUSDT", "U": 76583132228, "u": 76583132250, "b": [["1974.33000000", "0.50630000"], ["1971.90000000", "14.65920000"], ["1970.71000000", "15.03560000"], ["1970.60000000", "39.98420000"], ["1946.58000000", "0.00000000"], ["1934.03000000", "0.12900000"], ["1777.05000000", "0.09770000"]], "a": [["1974.50000000", "12.55560000"], ["1974.57000000", "0.13740000"], ["1974.59000000", "0.00000000"], ["1974.73000000", "2.54280000"], ["1974.75000000", "2.53760000"], ["1975.51000000", "0.40740000"], ["1976.02000000", "0.95250000"], ["1976.62000000", "1.38040000"], ["2038.11000000", "0.03950000"]], "_local_ts_utc": "2026-06-01T07:49:14.413220+00:00"}
{"e": "depthUpdate", "E": 1780300155615, "s": "ETHUSDT", "U": 76583132251, "u": 76583132268, "b": [["1974.49000000", "50.23840000"], ["1973.97000000", "17.62210000"], ["1973.95000000", "2.28360000"], ["1973.53000000", "0.41310000"], ["1972.92000000", "0.00260000"], ["1970.74000000", "0.00000000"], ["1970.67000000", "69.98910000"], ["1970.32000000", "0.27410000"], ["1777.05000000", "0.11010000"]], "a": [["1974.50000000", "9.50720000"], ["1975.11000000", "1.02600000"], ["1975.13000000", "7.55820000"], ["1975.32000000", "9.16240000"], ["1976.10000000", "0.51300000"], ["1976.12000000", "16.10930000"], ["1978.38000000", "0.92720000"], ["3073.49000000", "0.02210000"]], "_local_ts_utc": "2026-06-01T07:49:14.511459+00:00"}
{"e": "depthUpdate", "E": 1780300155715, "s": "ETHUSDT", "U": 76583132269, "u": 76583132318, "b": [["1974.49000000", "48.64760000"], ["1974.30000000", "9.47450000"], ["1974.29000000", "7.32000000"], ["1973.84000000", "0.27300000"], ["1973.36000000", "0.61970000"], ["1972.76000000", "0.82630000"], ["1970.40000000", "1.93630000"], ["1946.31000000", "0.12820000"], ["1942.37000000", "0.00510000"], ["1893.84000000", "0.01930000"], ["1777.05000000", "0.12250000"]], "a": [["1974.50000000", "0.27670000"], ["1974.51000000", "0.00520000"], ["1974.55000000", "0.10000000"], ["1974.59000000", "0.00260000"], ["1974.69000000", "2.53760000"], ["1974.71000000", "0.00000000"], ["1974.72000000", "2.97310000"], ["1974.73000000", "0.01060000"], ["1974.74000000", "0.21110000"], ["1974.77000000", "0.00000000"], ["1974.78000000", "0.00000000"], ["1974.80000000", "4.59950000"], ["1974.81000000", "0.00000000"], ["1974.86000000", "0.00000000"], ["1974.87000000", "0.01160000"], ["1974.88000000", "0.03260000"], ["1975.16000000", "0.70300000"], ["1975.19000000", "14.49960000"], ["1975.34000000", "0.57460000"], ["1975.41000000", "0.40000000"], ["1975.43000000", "0.80000000"], ["1976.52000000", "8.11150000"], ["1976.81000000", "0.00300000"], ["2038.11000000", "0.00000000"]], "_local_ts_utc": "2026-06-01T07:49:14.611417+00:00"}
{"e": "depthUpdate", "E": 1780300155815, "s": "ETHUSDT", "U": 76583132319, "u": 76583132379, "b": [["1970.05000000", "4.11030000"], ["1777.05000000", "0.13490000"]], "a": [["1974.50000000", "5.06340000"], ["1974.51000000", "0.00520000"], ["1974.67000000", "0.00000000"], ["1974.68000000", "0.69840000"], ["1974.69000000", "0.00540000"], ["1974.70000000", "1.37960000"], ["1974.71000000", "0.00000000"], ["1974.72000000", "0.01060000"], ["1974.73000000", "0.00520000"], ["1974.74000000", "0.20840000"], ["1974.75000000", "0.00000000"], ["1974.76000000", "0.02180000"], ["1974.78000000", "0.01160000"], ["1974.82000000", "0.55100000"], ["1976.81000000", "1.01740000"], ["2021.50000000", "0.15780000"]], "_local_ts_utc": "2026-06-01T07:49:14.711568+00:00"}
{"e": "depthUpdate", "E": 1780300155915, "s": "ETHUSDT", "U": 76583132380, "u": 76583132458, "b": [["1974.49000000", "48.54760000"], ["1972.67000000", "3.60000000"], ["1969.09000000", "0.22460000"], ["1777.05000000", "0.14730000"]], "a": [["1974.50000000", "12.07390000"], ["1974.51000000", "0.00520000"], ["1974.55000000", "0.00000000"], ["1974.64000000", "0.59780000"], ["1974.65000000", "0.00000000"], ["1974.66000000", "0.01160000"], ["1974.67000000", "0.00000000"], ["1974.68000000", "0.00000000"], ["1974.69000000", "0.00000000"], ["1974.73000000", "0.00520000"], ["1974.87000000", "0.00000000"], ["1974.91000000", "14.18080000"], ["1974.92000000", "8.51110000"], ["1974.93000000", "6.48760000"], ["1974.94000000", "7.09720000"], ["1974.95000000", "0.02690000"], ["1974.96000000", "20.12290000"], ["1974.97000000", "32.49330000"], ["1974.98000000", "0.59660000"], ["1975.00000000", "13.51380000"], ["1975.01000000", "10.17520000"], ["1975.02000000", "0.00000000"], ["1975.55000000", "7.10990000"], ["1976.41000000", "3.60000000"], ["1976.69000000", "0.00000000"], ["1976.85000000", "0.00000000"], ["1976.87000000", "0.00000000"], ["1977.70000000", "0.00000000"]], "_local_ts_utc": "2026-06-01T07:49:14.811552+00:00"}
{"e": "depthUpdate", "E": 1780300156015, "s": "ETHUSDT", "U": 76583132459, "u": 76583132733, "b": [["1974.49000000", "9.17620000"], ["1974.48000000", "0.00770000"], ["1974.46000000", "0.00260000"], ["1974.43000000", "0.00800000"], ["1974.42000000", "0.00260000"], ["1974.39000000", "0.00260000"], ["1974.38000000", "0.00000000"], ["1974.37000000", "1.37290000"], ["1974.31000000", "0.00000000"], ["1974.30000000", "0.00260000"], ["1974.29000000", "0.22960000"], ["1974.28000000", "0.00000000"], ["1974.27000000", "0.00260000"], ["1974.26000000", "0.00380000"], ["1974.23000000", "0.94730000"], ["1974.19000000", "0.55660000"], ["1974.18000000", "0.00000000"], ["1974.17000000", "2.11500000"], ["1974.13000000", "0.00000000"], ["1974.12000000", "0.00000000"], ["1974.10000000", "0.00570000"], ["1974.09000000", "0.00000000"], ["1974.08000000", "11.45550000"], ["1974.07000000", "0.27000000"], ["1974.05000000", "0.27260000"], ["1974.04000000", "8.50850000"], ["1974.03000000", "9.77310000"], ["1974.02000000", "4.28610000"], ["1974.01000000", "1.00000000"], ["1974.00000000", "4.41370000"], ["1973.99000000", "0.27000000"], ["1973.97000000", "24.96600000"], ["1973.96000000", "6.09100000"], ["1973.95000000", "0.57860000"], ["1973.94000000", "18.21820000"], ["1973.92000000", "7.12040000"], ["1973.91000000", "7.09040000"], ["1973.89000000", "0.05260000"], ["1973.86000000", "7.09420000"], ["1973.83000000", "1.00000000"], ["1973.81000000", "29.27870000"], ["1973.79000000", "0.00970000"], ["1973.77000000", "0.00000000"], ["1973.76000000", "0.05370000"], ["1973.75000000", "13.50550000"], ["1973.74000000", "7.09340000"], ["1973.73000000", "26.99010000"], ["1973.70000000", "11.46970000"], ["1973.58000000", "8.56240000"], ["1973.56000000", "0.00000000"], ["1973.53000000", "0.00000000"], ["1973.46000000", "1.50390000"], ["1973.17000000", "0.00260000"], ["1973.12000000", "0.03000000"], ["1973.02000000", "2.87000000"], ["1972.99000000", "0.05030000"], ["1972.87000000", "12.14150000"], ["1972.84000000", "0.00400000"], ["1972.71000000", "15.59890000"], ["1972.66000000", "14.32120000"], ["1972.61000000", "14.72340000"], ["1972.53000000", "7.57590000"], ["1972.51000000", "8.51110000"], ["1972.41000000", "14.18640000"], ["1972.34000000", "0.00260000"], ["1972.33000000", "0.00000000"], ["1972.21000000", "7.09040000"], ["1971.96000000", "13.50810000"], ["1971.69000000", "13.87180000"], ["1971.41000000", "13.50550000"], ["1970.43000000", "1.18680000"], ["1963.79000000", "0.35380000"], ["1963.53000000", "0.00640000"], ["1948.82000000", "0.14130000"], ["1947.16000000", "0.01350000"], ["1777.05000000", "0.15970000"], ["1579.60000000", "1.84970000"], ["1577.78000000", "0.00480000"]], "a": [["1974.50000000", "28.90270000"], ["1974.51000000", "0.00510000"], ["1974.52000000", "0.00510000"], ["1974.56000000", "0.00000000"], ["1974.57000000", "0.13200000"], ["1974.58000000", "0.17260000"], ["1974.60000000", "0.63840000"], ["1974.61000000", "0.00300000"], ["1974.62000000", "0.01160000"], ["1974.63000000", "0.00000000"], ["1974.64000000", "0.00000000"], ["1974.78000000", "0.00000000"], ["1974.79000000", "8.29590000"], ["1974.82000000", "0.53940000"], ["1974.90000000", "14.18650000"], ["1974.91000000", "22.01400000"], ["1974.92000000", "0.00260000"], ["1974.93000000", "6.68760000"], ["1974.94000000", "0.00680000"], ["1974.98000000", "7.68440000"], ["1975.00000000", "0.00830000"], ["1975.04000000", "15.29080000"], ["1975.05000000", "4.32000000"], ["1975.06000000", "0.51300000"], ["1975.07000000", "8.50850000"], ["1975.08000000", "0.00000000"], ["1975.13000000", "0.46160000"], ["1975.16000000", "0.50300000"], ["1975.18000000", "14.18080000"], ["1975.19000000", "2.17830000"], ["1975.23000000", "29.10700000"], ["1975.25000000", "0.03300000"], ["1975.32000000", "0.75800000"], ["1975.37000000", "0.00000000"], ["1975.40000000", "10.71610000"], ["1975.41000000", "0.00000000"], ["1975.42000000", "7.09040000"], ["1975.43000000", "29.10440000"], ["1975.44000000", "13.33140000"], ["1975.45000000", "0.20200000"], ["1975.46000000", "0.42120000"], ["1975.56000000", "0.00260000"], ["1975.59000000", "29.85640000"], ["1975.60000000", "4.64680000"], ["1975.61000000", "0.00000000"], ["1975.75000000", "13.50550000"], ["1975.79000000", "0.01020000"], ["1976.06000000", "7.60900000"], ["1976.17000000", "7.29530000"], ["1976.41000000", "3.60000000"], ["1976.51000000", "15.38890000"], ["1976.52000000", "1.02110000"], ["1976.53000000", "0.00000000"], ["1976.63000000", "0.00000000"], ["1976.69000000", "0.00000000"], ["1976.70000000", "0.00300000"], ["1976.83000000", "0.00000000"], ["1977.70000000", "0.00000000"], ["1978.03000000", "1.20550000"], ["1979.32000000", "0.15000000"], ["1980.11000000", "0.01030000"], ["1983.78000000", "1.33710000"], ["2021.53000000", "0.11200000"]], "_local_ts_utc": "2026-06-01T07:49:14.912794+00:00"}
{"e": "depthUpdate", "E": 1780300156115, "s": "ETHUSDT", "U": 76583132734, "u": 76583132931, "b": [["1974.49000000", "8.60620000"], ["1974.47000000", "0.00770000"], ["1974.44000000", "0.00260000"], ["1974.43000000", "0.00260000"], ["1974.40000000", "0.00780000"], ["1974.39000000", "0.00260000"], ["1974.38000000", "0.00540000"], ["1974.34000000", "0.00000000"], ["1974.33000000", "0.00000000"], ["1974.30000000", "0.00800000"], ["1974.24000000", "0.03540000"], ["1974.23000000", "1.45970000"], ["1974.22000000", "1.93840000"], ["1974.21000000", "6.46760000"], ["1974.20000000", "0.00260000"], ["1974.19000000", "0.55660000"], ["1974.18000000", "2.28530000"], ["1974.09000000", "7.09040000"], ["1974.08000000", "12.76220000"], ["1974.05000000", "14.45340000"], ["1974.04000000", "9.13410000"], ["1973.98000000", "7.76140000"], ["1973.97000000", "11.20110000"], ["1973.95000000", "14.08410000"], ["1973.90000000", "10.67200000"], ["1973.86000000", "7.36420000"], ["1973.84000000", "0.52650000"], ["1973.75000000", "13.51560000"], ["1973.59000000", "10.04750000"], ["1973.36000000", "0.00000000"], ["1973.24000000", "0.20000000"], ["1973.02000000", "2.67000000"], ["1972.95000000", "7.89530000"], ["1972.80000000", "12.32480000"], ["1972.76000000", "0.00000000"], ["1972.71000000", "29.77970000"], ["1972.66000000", "13.52120000"], ["1972.57000000", "6.38030000"], ["1972.54000000", "0.40690000"], ["1972.53000000", "0.48550000"], ["1972.41000000", "0.00560000"], ["1972.21000000", "0.00000000"], ["1971.97000000", "4.38580000"], ["1971.84000000", "0.03260000"], ["1971.79000000", "4.24700000"], ["1971.78000000", "0.00000000"], ["1971.70000000", "10.88260000"], ["1970.99000000", "0.80830000"], ["1970.32000000", "0.00410000"], ["1963.21000000", "0.00000000"], ["1957.86000000", "0.00000000"], ["1946.22000000", "0.25640000"], ["1942.27000000", "0.12840000"], ["1777.05000000", "0.15970000"]], "a": [["1974.50000000", "41.21840000"], ["1974.56000000", "0.03000000"], ["1974.60000000", "0.03870000"], ["1974.65000000", "5.88320000"], ["1974.66000000", "6.47920000"], ["1974.69000000", "0.00000000"], ["1974.70000000", "16.35700000"], ["1974.72000000", "0.04060000"], ["1974.75000000", "8.50850000"], ["1974.76000000", "0.01020000"], ["1974.77000000", "22.57370000"], ["1974.78000000", "14.18080000"], ["1974.79000000", "8.29590000"], ["1974.89000000", "4.87280000"], ["1974.93000000", "0.22000000"], ["1974.98000000", "7.68700000"], ["1975.12000000", "1.83600000"], ["1975.22000000", "15.43910000"], ["1975.24000000", "0.00000000"], ["1975.28000000", "0.00000000"], ["1975.31000000", "0.02790000"], ["1975.39000000", "3.19880000"], ["1975.42000000", "23.08210000"], ["1975.44000000", "0.00520000"], ["1975.60000000", "1.10480000"], ["1975.61000000", "2.40620000"], ["1975.74000000", "15.62750000"], ["1975.76000000", "15.13270000"], ["1975.98000000", "5.32000000"], ["1975.99000000", "0.00000000"], ["1976.11000000", "16.83530000"], ["1976.32000000", "0.03000000"], ["1976.33000000", "0.03550000"], ["1976.39000000", "14.18080000"], ["1976.40000000", "0.00310000"], ["1976.50000000", "0.00260000"], ["1976.51000000", "1.20810000"], ["1976.92000000", "0.00560000"], ["1976.96000000", "0.00000000"], ["1977.12000000", "0.00000000"]], "_local_ts_utc": "2026-06-01T07:49:15.011292+00:00"}
{"e": "depthUpdate", "E": 1780300156215, "s": "ETHUSDT", "U": 76583132932, "u": 76583132967, "b": [["1974.49000000", "0.01310000"], ["1974.40000000", "0.01320000"], ["1974.39000000", "0.49360000"], ["1974.27000000", "10.14560000"], ["1974.22000000", "2.66950000"], ["1973.22000000", "2.83780000"], ["1972.22000000", "32.96830000"], ["1971.78000000", "2.53590000"], ["1971.72000000", "31.74050000"], ["1971.28000000", "0.75690000"], ["1971.23000000", "31.74570000"], ["1970.92000000", "0.49190000"], ["1970.72000000", "32.41690000"], ["1962.22000000", "0.18050000"], ["1777.05000000", "0.15350000"]], "a": [["1974.50000000", "41.20600000"], ["1974.65000000", "12.97360000"], ["1975.34000000", "0.00760000"], ["1975.49000000", "2.80900000"], ["1976.39000000", "7.09040000"], ["2021.77000000", "0.04990000"]], "_local_ts_utc": "2026-06-01T07:49:15.111171+00:00"}
{"e": "depthUpdate", "E": 1780300156315, "s": "ETHUSDT", "U": 76583132968, "u": 76583133338, "b": [["1974.49000000", "0.00000000"], ["1974.48000000", "0.00000000"], ["1974.47000000", "0.00000000"], ["1974.46000000", "0.00000000"], ["1974.44000000", "0.00000000"], ["1974.43000000", "0.00000000"], ["1974.42000000", "0.00000000"], ["1974.41000000", "0.00000000"], ["1974.40000000", "0.00000000"], ["1974.39000000", "0.00000000"], ["1974.38000000", "0.00000000"], ["1974.37000000", "18.19420000"], ["1974.30000000", "6.48580000"], ["1974.29000000", "0.23220000"], ["1974.28000000", "0.00000000"], ["1974.27000000", "0.00520000"], ["1974.26000000", "0.01180000"], ["1974.25000000", "10.30030000"], ["1974.24000000", "0.03800000"], ["1974.23000000", "0.95530000"], ["1974.22000000", "0.73910000"], ["1974.21000000", "0.00260000"], ["1974.20000000", "0.00530000"], ["1974.19000000", "2.84190000"], ["1974.18000000", "0.00000000"], ["1974.06000000", "0.82440000"], ["1973.88000000", "0.02060000"], ["1973.64000000", "0.00760000"], ["1973.62000000", "15.17180000"], ["1973.50000000", "0.00570000"], ["1973.44000000", "7.13100000"], ["1973.40000000", "0.00870000"], ["1973.24000000", "0.20000000"], ["1973.17000000", "0.40260000"], ["1973.11000000", "7.10290000"], ["1973.02000000", "2.27000000"], ["1972.85000000", "7.41750000"], ["1972.38000000", "13.51730000"], ["1972.30000000", "19.32550000"], ["1971.79000000", "13.93900000"], ["1971.41000000", "14.10140000"], ["1971.28000000", "0.00880000"], ["1971.27000000", "16.17770000"], ["1970.79000000", "14.15910000"], ["1970.54000000", "0.00000000"], ["1968.87000000", "0.80260000"], ["1968.69000000", "0.00000000"], ["1955.34000000", "0.25520000"], ["1946.99000000", "1.50490000"], ["1934.90000000", "0.00760000"], ["1934.88000000", "0.01050000"], ["1777.05000000", "0.00470000"], ["1776.94000000", "0.04050000"], ["1474.39000000", "0.01220000"]], "a": [["1974.38000000", "61.57050000"], ["1974.39000000", "0.01050000"], ["1974.40000000", "6.23660000"], ["1974.41000000", "0.00000000"], ["1974.42000000", "0.01160000"], ["1974.43000000", "0.00000000"], ["1974.44000000", "0.00000000"], ["1974.45000000", "0.00000000"], ["1974.47000000", "0.00540000"], ["1974.48000000", "3.00540000"], ["1974.49000000", "0.46500000"], ["1974.50000000", "3.24150000"], ["1974.51000000", "0.00000000"], ["1974.52000000", "0.00000000"], ["1974.59000000", "0.00000000"], ["1974.61000000", "0.00560000"], ["1974.62000000", "0.00000000"], ["1974.63000000", "7.53140000"], ["1974.64000000", "7.09040000"], ["1974.65000000", "0.00000000"], ["1974.66000000", "6.46760000"], ["1974.72000000", "0.45060000"], ["1974.73000000", "0.00260000"], ["1974.76000000", "22.58390000"], ["1974.77000000", "0.00000000"], ["1974.84000000", "0.01240000"], ["1974.86000000", "0.00000000"], ["1974.95000000", "0.00000000"], ["1975.19000000", "0.97830000"], ["1975.23000000", "30.61160000"], ["1975.40000000", "10.71350000"], ["1975.41000000", "1.20000000"], ["1975.44000000", "1.47060000"], ["1975.49000000", "0.00300000"], ["1975.60000000", "1.30770000"], ["1976.04000000", "13.62300000"], ["1976.11000000", "1.39570000"], ["1976.20000000", "0.00310000"], ["1976.38000000", "7.09040000"], ["1976.39000000", "0.00000000"], ["1976.40000000", "0.00310000"], ["1976.53000000", "7.09040000"], ["1976.54000000", "0.03670000"], ["1977.96000000", "0.00000000"], ["1978.43000000", "1.27380000"], ["1979.43000000", "0.00000000"], ["1979.49000000", "0.18990000"], ["1979.50000000", "0.00000000"], ["1979.97000000", "0.00000000"], ["2474.40000000", "0.00820000"]], "_local_ts_utc": "2026-06-01T07:49:15.212582+00:00"}
{"e": "depthUpdate", "E": 1780300156415, "s": "ETHUSDT", "U": 76583133339, "u": 76583133388, "b": [["1974.37000000", "19.53580000"], ["1974.32000000", "0.00540000"], ["1974.31000000", "5.28370000"], ["1974.30000000", "16.62320000"], ["1974.26000000", "0.00640000"], ["1974.25000000", "0.15720000"], ["1974.24000000", "0.03800000"], ["1974.23000000", "0.94990000"], ["1974.20000000", "0.00800000"], ["1974.18000000", "0.00270000"], ["1973.83000000", "1.27000000"], ["1971.69000000", "13.71060000"], ["1971.38000000", "0.03430000"], ["1971.20000000", "2.67470000"], ["1970.72000000", "32.25570000"], ["1970.24000000", "23.36350000"], ["1969.76000000", "0.01050000"], ["1969.27000000", "0.03340000"], ["1968.79000000", "0.01280000"], ["1968.31000000", "0.41470000"], ["1967.83000000", "0.00000000"], ["1946.23000000", "0.00000000"], ["1942.50000000", "0.16340000"], ["1922.56000000", "0.00000000"], ["1776.94000000", "0.05290000"]], "a": [["1974.38000000", "55.02940000"], ["1974.39000000", "3.88070000"], ["1974.40000000", "6.24820000"], ["1974.48000000", "3.00000000"], ["1974.58000000", "0.01160000"], ["1974.63000000", "12.26760000"], ["1974.66000000", "0.00000000"], ["1974.72000000", "0.04060000"], ["1974.76000000", "29.05150000"], ["1974.83000000", "0.01450000"], ["1974.84000000", "0.00000000"], ["1975.10000000", "8.38510000"], ["1976.09000000", "0.64800000"], ["1976.38000000", "0.00000000"], ["1977.03000000", "0.00300000"], ["1977.47000000", "0.00000000"], ["1978.92000000", "0.03560000"], ["1979.40000000", "8.42500000"], ["1979.88000000", "0.00000000"], ["1979.89000000", "0.00000000"], ["1980.37000000", "0.00000000"], ["1980.85000000", "0.00380000"], ["1981.33000000", "0.00000000"], ["1981.82000000", "0.20040000"], ["1982.30000000", "0.00000000"], ["2021.52000000", "0.04530000"], ["2021.58000000", "0.09420000"]], "_local_ts_utc": "2026-06-01T07:49:15.312215+00:00"}
{"e": "depthUpdate", "E": 1780300156515, "s": "ETHUSDT", "U": 76583133389, "u": 76583133490, "b": [["1974.37000000", "22.71500000"], ["1974.33000000", "0.00000000"], ["1974.32000000", "3.52040000"], ["1974.31000000", "0.32430000"], ["1974.30000000", "6.48040000"], ["1974.24000000", "0.03260000"], ["1974.22000000", "0.73650000"], ["1974.21000000", "0.00000000"], ["1974.20000000", "0.00260000"], ["1974.18000000", "0.00000000"], ["1974.16000000", "1.35780000"], ["1974.14000000", "0.63750000"], ["1973.79000000", "0.27970000"], ["1972.00000000", "0.17140000"], ["1971.84000000", "0.00260000"], ["1965.66000000", "0.05080000"], ["1944.76000000", "0.13990000"], ["1776.94000000", "0.06530000"]], "a": [["1974.38000000", "3.82740000"], ["1974.39000000", "0.01290000"], ["1974.40000000", "0.01080000"], ["1974.42000000", "0.00000000"], ["1974.44000000", "0.00000000"], ["1974.45000000", "0.00000000"], ["1974.48000000", "3.00000000"], ["1974.49000000", "0.00540000"], ["1974.50000000", "0.25310000"], ["1974.51000000", "0.10000000"], ["1974.58000000", "0.00000000"], ["1974.62000000", "0.00540000"], ["1974.63000000", "1.12840000"], ["1974.64000000", "0.00000000"], ["1974.70000000", "0.00570000"], ["1974.75000000", "0.00000000"], ["1974.76000000", "22.58390000"], ["1974.77000000", "0.01160000"], ["1974.79000000", "7.09040000"], ["1974.86000000", "0.00000000"], ["1974.87000000", "6.46760000"], ["1974.89000000", "0.63810000"], ["1974.91000000", "8.50850000"], ["1975.03000000", "14.48350000"], ["1975.14000000", "0.59780000"], ["1975.46000000", "3.20970000"], ["1975.99000000", "8.50850000"], ["1976.13000000", "0.59400000"], ["1976.39000000", "7.09040000"], ["1976.40000000", "7.09350000"]], "_local_ts_utc": "2026-06-01T07:49:15.411260+00:00"}
{"e": "depthUpdate", "E": 1780300156615, "s": "ETHUSDT", "U": 76583133491, "u": 76583133956, "b": [["1974.47000000", "116.96390000"], ["1974.46000000", "16.37070000"], ["1974.41000000", "0.00540000"], ["1974.40000000", "9.46450000"], ["1974.39000000", "0.00800000"], ["1974.38000000", "3.68430000"], ["1974.37000000", "4.41220000"], ["1974.33000000", "0.00000000"], ["1974.32000000", "0.00260000"], ["1974.31000000", "0.31890000"], ["1974.30000000", "0.01590000"], ["1974.26000000", "0.50380000"], ["1974.25000000", "8.05860000"], ["1974.24000000", "8.53850000"], ["1974.23000000", "0.94730000"], ["1974.21000000", "7.09040000"], ["1974.20000000", "7.47720000"], ["1974.19000000", "0.55660000"], ["1974.16000000", "8.44820000"], ["1974.15000000", "7.09300000"], ["1974.14000000", "9.14600000"], ["1974.10000000", "19.73280000"], ["1974.09000000", "20.59590000"], ["1974.08000000", "1.33670000"], ["1973.94000000", "8.70630000"], ["1973.84000000", "0.27300000"], ["1973.68000000", "0.25290000"], ["1973.46000000", "1.30390000"], ["1973.40000000", "0.00610000"], ["1973.11000000", "7.09530000"], ["1972.71000000", "14.18080000"], ["1972.61000000", "0.54260000"], ["1972.57000000", "4.38990000"], ["1972.51000000", "0.00260000"], ["1972.00000000", "0.14140000"], ["1971.41000000", "0.59590000"], ["1969.38000000", "0.00000000"], ["1968.91000000", "0.00000000"], ["1968.85000000", "3.68560000"], ["1968.76000000", "0.04920000"], ["1963.64000000", "237.03660000"], ["1948.71000000", "0.13260000"], ["1946.99000000", "0.00000000"], ["1944.76000000", "0.26820000"], ["1934.97000000", "0.01320000"], ["1777.03000000", "0.00620000"], ["1777.02000000", "0.00990000"], ["1776.94000000", "0.02810000"]], "a": [["1974.38000000", "0.00000000"], ["1974.39000000", "0.00000000"], ["1974.40000000", "0.00000000"], ["1974.47000000", "0.00000000"], ["1974.48000000", "3.01560000"], ["1974.49000000", "0.01060000"], ["1974.50000000", "0.24790000"], ["1974.51000000", "0.00000000"], ["1974.56000000", "0.00000000"], ["1974.63000000", "1.13380000"], ["1974.64000000", "0.50710000"], ["1974.65000000", "0.00260000"], ["1974.66000000", "0.10000000"], ["1974.73000000", "0.00800000"], ["1974.74000000", "0.20460000"], ["1974.75000000", "0.00000000"], ["1974.76000000", "0.01020000"], ["1974.78000000", "0.00000000"], ["1974.79000000", "1.37300000"], ["1974.86000000", "0.00000000"], ["1974.87000000", "0.00000000"], ["1974.89000000", "7.72850000"], ["1974.90000000", "7.09610000"], ["1974.91000000", "0.00000000"], ["1974.92000000", "0.00550000"], ["1974.93000000", "0.02000000"], ["1974.97000000", "32.49330000"], ["1974.98000000", "0.59660000"], ["1975.02000000", "20.59590000"], ["1975.03000000", "0.97800000"], ["1975.08000000", "6.46760000"], ["1975.09000000", "0.00260000"], ["1975.13000000", "0.46160000"], ["1975.16000000", "0.00300000"], ["1975.19000000", "0.17830000"], ["1975.21000000", "0.00000000"], ["1975.30000000", "1.50570000"], ["1975.32000000", "0.11000000"], ["1975.40000000", "10.71610000"], ["1975.44000000", "0.00520000"], ["1975.53000000", "0.94500000"], ["1975.60000000", "1.10480000"], ["1975.69000000", "0.51560000"], ["1975.76000000", "15.13270000"], ["1976.11000000", "18.18240000"], ["1976.16000000", "8.53850000"], ["1976.18000000", "8.81190000"], ["1976.20000000", "3.07710000"], ["1976.38000000", "4.21280000"], ["1976.61000000", "7.09040000"], ["1976.62000000", "8.47080000"], ["1976.70000000", "7.09340000"], ["1976.74000000", "0.00900000"], ["1976.81000000", "0.00300000"], ["1976.83000000", "0.00000000"], ["1976.85000000", "0.00000000"], ["1976.86000000", "33.65180000"], ["1977.12000000", "0.03000000"], ["1977.70000000", "0.00000000"], ["1979.76000000", "0.00000000"], ["1979.82000000", "0.00000000"], ["1979.83000000", "0.00260000"], ["1979.92000000", "0.00530000"], ["1984.61000000", "0.00000000"], ["1990.44000000", "3.13840000"]], "_local_ts_utc": "2026-06-01T07:49:15.511463+00:00"}
{"e": "depthUpdate", "E": 1780300156715, "s": "ETHUSDT", "U": 76583133957, "u": 76583134281, "b": [["1974.56000000", "96.82310000"], ["1974.52000000", "0.00540000"], ["1974.51000000", "9.77610000"], ["1974.50000000", "0.00800000"], ["1974.49000000", "0.55970000"], ["1974.48000000", "3.00800000"], ["1974.47000000", "15.52550000"], ["1974.46000000", "9.90310000"], ["1974.41000000", "0.00260000"], ["1974.40000000", "9.46710000"], ["1974.39000000", "0.00260000"], ["1974.38000000", "3.67890000"], ["1974.35000000", "8.50850000"], ["1974.34000000", "0.00260000"], ["1974.32000000", "0.00000000"], ["1974.31000000", "7.40670000"], ["1974.30000000", "0.01330000"], ["1974.29000000", "0.22960000"], ["1974.27000000", "0.00260000"], ["1974.26000000", "7.59420000"], ["1974.25000000", "16.47740000"], ["1974.08000000", "0.03000000"], ["1974.03000000", "0.09110000"], ["1973.96000000", "2.98910000"], ["1973.92000000", "7.82040000"], ["1973.88000000", "0.82060000"], ["1973.86000000", "7.46550000"], ["1973.80000000", "18.67260000"], ["1973.73000000", "26.81960000"], ["1973.68000000", "0.05290000"], ["1973.51000000", "14.19240000"], ["1973.50000000", "0.00310000"], ["1973.46000000", "0.60390000"], ["1973.24000000", "0.80000000"], ["1973.17000000", "0.00260000"], ["1972.95000000", "7.09530000"], ["1972.90000000", "10.95510000"], ["1972.87000000", "3.63300000"], ["1972.85000000", "0.32220000"], ["1972.80000000", "8.46890000"], ["1972.71000000", "0.00000000"], ["1970.65000000", "58.58880000"], ["1970.55000000", "1.53760000"], ["1969.46000000", "1.16100000"], ["1969.12000000", "1.00000000"], ["1967.19000000", "0.00780000"], ["1967.15000000", "1.01060000"], ["1966.99000000", "0.02970000"], ["1966.97000000", "0.00670000"], ["1965.18000000", "1.38160000"], ["1965.01000000", "0.00000000"], ["1963.20000000", "1.05980000"], ["1963.04000000", "0.00840000"], ["1961.07000000", "0.00900000"], ["1955.33000000", "0.12760000"], ["1948.81000000", "0.12800000"], ["1935.06000000", "0.02810000"], ["1934.98000000", "0.00000000"], ["1777.11000000", "0.01240000"], ["1777.03000000", "0.00000000"], ["1579.58000000", "0.00700000"], ["1577.56000000", "0.00700000"]], "a": [["1974.48000000", "0.00000000"], ["1974.49000000", "0.00000000"], ["1974.50000000", "0.00000000"], ["1974.57000000", "1.95070000"], ["1974.58000000", "0.00520000"], ["1974.60000000", "0.03560000"], ["1974.61000000", "0.00300000"], ["1974.63000000", "1.12840000"], ["1974.64000000", "0.00000000"], ["1974.65000000", "0.00000000"], ["1974.72000000", "0.00300000"], ["1974.74000000", "0.20200000"], ["1974.77000000", "0.00000000"], ["1974.78000000", "0.00540000"], ["1974.79000000", "1.37840000"], ["1974.81000000", "0.00270000"], ["1974.83000000", "0.02610000"], ["1974.88000000", "0.03260000"], ["1974.89000000", "0.01160000"], ["1974.90000000", "0.00570000"], ["1974.94000000", "0.01840000"], ["1974.95000000", "9.31370000"], ["1974.96000000", "7.09040000"], ["1974.97000000", "9.91960000"], ["1974.98000000", "7.09300000"], ["1974.99000000", "0.00000000"], ["1975.00000000", "7.09870000"], ["1975.01000000", "10.17520000"], ["1975.02000000", "0.00000000"], ["1975.03000000", "8.54150000"], ["1975.04000000", "0.03000000"], ["1975.05000000", "0.00300000"], ["1975.06000000", "23.08670000"], ["1975.07000000", "1.20550000"], ["1975.10000000", "7.60210000"], ["1975.11000000", "0.51300000"], ["1975.12000000", "1.02600000"], ["1975.17000000", "13.64000000"], ["1975.22000000", "16.07720000"], ["1975.23000000", "17.10610000"], ["1975.26000000", "24.07370000"], ["1975.30000000", "0.00570000"], ["1975.33000000", "0.00000000"], ["1975.41000000", "1.40000000"], ["1975.50000000", "0.00260000"], ["1975.56000000", "0.00000000"], ["1975.77000000", "8.64400000"], ["1975.86000000", "0.13000000"], ["1975.88000000", "0.00520000"], ["1975.96000000", "3.01560000"], ["1976.37000000", "0.13490000"], ["1976.44000000", "4.33050000"], ["1976.52000000", "8.39140000"], ["1976.77000000", "1.20810000"], ["1976.83000000", "14.18080000"], ["1976.85000000", "0.00000000"], ["1976.86000000", "31.67620000"], ["1977.05000000", "0.00000000"], ["1977.14000000", "0.00560000"], ["1977.28000000", "0.03000000"], ["1977.29000000", "0.00000000"], ["1977.34000000", "2.38000000"], ["1977.70000000", "13.50550000"], ["1977.85000000", "1.98210000"], ["1977.99000000", "3.55200000"], ["1978.02000000", "0.00560000"], ["1978.03000000", "1.20550000"], ["1980.01000000", "7.60520000"], ["1980.10000000", "0.00260000"], ["1983.78000000", "0.00610000"], ["1990.59000000", "0.00000000"]], "_local_ts_utc": "2026-06-01T07:49:15.611516+00:00"}
{"e": "depthUpdate", "E": 1780300156815, "s": "ETHUSDT", "U": 76583134282, "u": 76583134362, "b": [["1974.56000000", "96.85570000"], ["1974.52000000", "0.00800000"], ["1974.51000000", "9.77870000"], ["1974.50000000", "0.01060000"], ["1974.49000000", "0.56230000"], ["1974.40000000", "0.03520000"], ["1974.39000000", "0.00000000"], ["1974.38000000", "3.67630000"], ["1974.37000000", "13.13880000"], ["1974.36000000", "7.09040000"], ["1974.35000000", "15.59890000"], ["1974.31000000", "7.09040000"], ["1974.30000000", "4.42330000"], ["1974.28000000", "16.25800000"], ["1974.27000000", "13.50810000"], ["1974.25000000", "8.57340000"], ["1974.00000000", "0.00570000"], ["1972.93000000", "0.12670000"], ["1972.90000000", "5.28110000"], ["1972.81000000", "13.71620000"], ["1972.54000000", "0.28020000"], ["1972.16000000", "0.08810000"], ["1972.03000000", "0.22850000"], ["1971.70000000", "7.87690000"], ["1971.69000000", "0.20510000"], ["1971.31000000", "0.01830000"], ["1968.76000000", "0.04660000"], ["1955.33000000", "0.25520000"], ["1777.11000000", "0.02480000"]], "a": [["1974.57000000", "2.04020000"], ["1974.73000000", "0.01060000"], ["1974.95000000", "0.00000000"], ["1974.96000000", "2.96430000"], ["1974.97000000", "0.00000000"], ["1974.98000000", "0.00260000"], ["1975.00000000", "0.00830000"], ["1975.01000000", "15.13000000"], ["1975.02000000", "14.18080000"], ["1975.03000000", "0.03300000"], ["1975.05000000", "7.09340000"], ["1975.07000000", "9.71400000"], ["1975.08000000", "0.00000000"], ["1975.09000000", "4.34160000"], ["1975.10000000", "10.90330000"], ["1975.18000000", "20.64840000"], ["1975.32000000", "11.34750000"], ["1975.33000000", "26.78000000"], ["1975.39000000", "0.00000000"], ["1975.41000000", "0.00000000"], ["1975.55000000", "7.70990000"], ["1975.62000000", "3.71860000"], ["1975.94000000", "1.95710000"], ["1975.96000000", "0.00000000"], ["1976.05000000", "0.00000000"], ["1976.37000000", "0.13490000"], ["1976.76000000", "0.46110000"], ["1976.85000000", "0.00000000"], ["1977.03000000", "0.00300000"], ["1980.19000000", "0.00560000"], ["1980.28000000", "0.00260000"]], "_local_ts_utc": "2026-06-01T07:49:15.711293+00:00"}
{"e": "depthUpdate", "E": 1780300156915, "s": "ETHUSDT", "U": 76583134363, "u": 76583134381, "b": [["1974.56000000", "97.18220000"], ["1974.48000000", "3.01060000"], ["1974.40000000", "0.03520000"], ["1974.10000000", "19.88390000"], ["1964.07000000", "0.01050000"], ["1944.86000000", "0.18200000"], ["1777.11000000", "0.03720000"]], "a": [["1974.57000000", "0.14240000"], ["1974.96000000", "0.00000000"], ["1975.26000000", "33.97950000"], ["1975.46000000", "0.42120000"], ["1976.78000000", "0.00260000"], ["1976.94000000", "29.61740000"], ["1979.75000000", "0.00260000"], ["1980.28000000", "0.00000000"]], "_local_ts_utc": "2026-06-01T07:49:15.810988+00:00"}
{"e": "depthUpdate", "E": 1780300157015, "s": "ETHUSDT", "U": 76583134382, "u": 76583134699, "b": [["1974.62000000", "103.60350000"], ["1974.61000000", "0.00510000"], ["1974.60000000", "3.00770000"], ["1974.59000000", "0.41250000"], ["1974.58000000", "0.00000000"], ["1974.57000000", "9.01390000"], ["1974.56000000", "11.46020000"], ["1974.52000000", "0.00260000"], ["1974.51000000", "9.77610000"], ["1974.50000000", "0.00520000"], ["1974.49000000", "0.41510000"], ["1974.48000000", "1.81350000"], ["1974.47000000", "15.52280000"], ["1974.46000000", "32.17990000"], ["1974.45000000", "7.09040000"], ["1974.40000000", "0.03830000"], ["1974.39000000", "0.00300000"], ["1974.38000000", "3.70930000"], ["1974.30000000", "5.03860000"], ["1974.25000000", "7.24500000"], ["1974.22000000", "0.73910000"], ["1974.16000000", "7.12340000"], ["1974.14000000", "8.50850000"], ["1974.10000000", "14.46950000"], ["1974.04000000", "8.50850000"], ["1974.02000000", "1.26510000"], ["1973.98000000", "7.14610000"], ["1973.96000000", "0.00000000"], ["1973.93000000", "6.85510000"], ["1973.82000000", "3.60000000"], ["1973.60000000", "0.03310000"], ["1973.54000000", "7.09600000"], ["1973.28000000", "13.54510000"], ["1973.11000000", "7.36530000"], ["1973.10000000", "0.00000000"], ["1973.08000000", "0.00260000"], ["1973.07000000", "1.35860000"], ["1973.06000000", "3.00890000"], ["1973.04000000", "0.00000000"], ["1973.02000000", "1.27000000"], ["1973.01000000", "0.27260000"], ["1973.00000000", "4.09990000"], ["1972.95000000", "0.00000000"], ["1972.91000000", "0.00000000"], ["1972.87000000", "3.63560000"], ["1972.80000000", "16.86050000"], ["1972.78000000", "0.00260000"], ["1972.71000000", "31.72190000"], ["1972.50000000", "10.28030000"], ["1972.48000000", "10.47370000"], ["1971.76000000", "0.00000000"], ["1971.71000000", "15.00000000"], ["1970.79000000", "9.63350000"], ["1970.71000000", "0.03560000"], ["1970.44000000", "0.02000000"], ["1970.05000000", "9.95620000"], ["1969.54000000", "0.00260000"], ["1969.47000000", "0.02190000"], ["1969.46000000", "1.16100000"], ["1968.58000000", "0.00000000"], ["1966.62000000", "0.20200000"], ["1959.29000000", "0.02450000"], ["1945.35000000", "37.29700000"], ["1944.98000000", "0.13250000"], ["1935.12000000", "0.03890000"], ["1777.16000000", "0.08590000"], ["1777.11000000", "0.00000000"], ["1474.39000000", "0.00620000"]], "a": [["1974.57000000", "0.00000000"], ["1974.58000000", "0.00000000"], ["1974.60000000", "0.00000000"], ["1974.61000000", "0.00000000"], ["1974.62000000", "0.00000000"], ["1974.63000000", "1.10980000"], ["1974.64000000", "0.00780000"], ["1974.66000000", "0.00000000"], ["1974.70000000", "0.10570000"], ["1974.78000000", "0.00000000"], ["1974.79000000", "0.00540000"], ["1974.81000000", "0.00540000"], ["1974.83000000", "0.01450000"], ["1974.88000000", "0.00260000"], ["1974.89000000", "0.00000000"], ["1974.92000000", "0.00260000"], ["1975.01000000", "10.17520000"], ["1975.02000000", "0.00000000"], ["1975.05000000", "0.00300000"], ["1975.06000000", "22.57370000"], ["1975.07000000", "1.20550000"], ["1975.08000000", "0.00530000"], ["1975.09000000", "25.61280000"], ["1975.10000000", "3.35690000"], ["1975.11000000", "0.00000000"], ["1975.12000000", "0.45900000"], ["1975.13000000", "0.00260000"], ["1975.14000000", "0.00380000"], ["1975.17000000", "0.13450000"], ["1975.18000000", "6.46760000"], ["1975.23000000", "2.45220000"], ["1975.25000000", "29.81270000"], ["1975.26000000", "32.77950000"], ["1975.38000000", "1.21910000"], ["1975.39000000", "13.50550000"], ["1975.42000000", "19.05150000"], ["1975.43000000", "15.59890000"], ["1975.55000000", "7.30990000"], ["1975.60000000", "1.10740000"], ["1975.62000000", "3.31860000"], ["1975.64000000", "0.00000000"], ["1975.72000000", "0.82210000"], ["1975.73000000", "13.50550000"], ["1975.74000000", "11.60800000"], ["1975.75000000", "0.00000000"], ["1975.80000000", "0.80300000"], ["1975.91000000", "0.00260000"], ["1975.92000000", "0.43390000"], ["1975.94000000", "0.00640000"], ["1976.03000000", "9.92760000"], ["1976.06000000", "21.11450000"], ["1976.12000000", "2.59200000"], ["1976.37000000", "6.90860000"], ["1976.38000000", "8.50850000"], ["1976.52000000", "9.33640000"], ["1976.60000000", "0.00000000"], ["1976.63000000", "9.97080000"], ["1976.85000000", "0.00000000"], ["1976.86000000", "0.02060000"], ["1976.94000000", "1.27140000"], ["1977.05000000", "0.00000000"], ["1977.09000000", "0.13390000"], ["1977.44000000", "0.03000000"], ["1978.03000000", "14.71100000"], ["1978.33000000", "0.00870000"], ["1978.38000000", "0.13380000"], ["1978.70000000", "0.79330000"], ["1978.86000000", "0.00260000"], ["1978.88000000", "31.62330000"], ["1979.50000000", "0.00260000"], ["1980.10000000", "0.00000000"], ["1980.19000000", "0.00300000"], ["1980.66000000", "3.74670000"], ["1982.31000000", "3.07730000"], ["1982.84000000", "126.24070000"], ["1984.38000000", "3.60000000"], ["1984.86000000", "1.68820000"], ["2474.40000000", "0.00220000"]], "_local_ts_utc": "2026-06-01T07:49:15.912732+00:00"}
{"e": "depthUpdate", "E": 1780300157115, "s": "ETHUSDT", "U": 76583134700, "u": 76583134759, "b": [["1974.62000000", "103.60610000"], ["1974.61000000", "0.01570000"], ["1974.60000000", "3.01570000"], ["1974.59000000", "0.41510000"], ["1974.58000000", "0.00540000"], ["1974.57000000", "0.50800000"], ["1974.52000000", "0.00260000"], ["1974.48000000", "1.81090000"], ["1974.47000000", "15.52020000"], ["1974.46000000", "32.17730000"], ["1974.41000000", "0.00000000"], ["1974.20000000", "7.74720000"], ["1974.19000000", "0.56610000"], ["1974.18000000", "0.27000000"], ["1974.15000000", "7.11650000"], ["1973.84000000", "0.00300000"], ["1973.81000000", "22.68930000"], ["1973.79000000", "0.27000000"], ["1973.76000000", "0.03000000"], ["1973.47000000", "2.10000000"], ["1973.21000000", "7.36530000"], ["1973.19000000", "0.53110000"], ["1972.97000000", "0.08700000"], ["1972.93000000", "0.34450000"], ["1972.57000000", "4.30300000"], ["1972.53000000", "0.27260000"], ["1971.29000000", "0.00460000"], ["1968.95000000", "0.01020000"], ["1968.85000000", "3.68300000"], ["1968.66000000", "0.10150000"], ["1777.16000000", "0.09830000"]], "a": [["1974.68000000", "0.00540000"], ["1974.69000000", "0.65780000"], ["1974.70000000", "0.00570000"], ["1974.75000000", "0.10000000"], ["1974.98000000", "0.00000000"], ["1975.10000000", "2.23620000"], ["1975.11000000", "0.00260000"], ["1975.12000000", "0.00000000"], ["1975.23000000", "1.50720000"], ["1975.38000000", "2.00210000"], ["1975.39000000", "14.31550000"], ["1975.51000000", "0.00260000"], ["1975.53000000", "0.00000000"], ["1976.61000000", "7.87340000"], ["1976.64000000", "101.67100000"], ["1977.21000000", "0.01000000"], ["1977.25000000", "0.00300000"], ["1980.01000000", "7.60260000"]], "_local_ts_utc": "2026-06-01T07:49:16.010701+00:00"}
{"e": "depthUpdate", "E": 1780300157215, "s": "ETHUSDT", "U": 76583134760, "u": 76583135081, "b": [["1974.67000000", "114.41990000"], ["1974.66000000", "24.33350000"], ["1974.65000000", "11.34840000"], ["1974.64000000", "0.00000000"], ["1974.63000000", "29.30390000"], ["1974.62000000", "3.76450000"], ["1974.61000000", "0.00520000"], ["1974.60000000", "0.00520000"], ["1974.59000000", "0.41510000"], ["1974.58000000", "0.00260000"], ["1974.57000000", "0.00260000"], ["1974.56000000", "4.99260000"], ["1974.52000000", "0.00260000"], ["1974.51000000", "9.77350000"], ["1974.50000000", "0.00260000"], ["1974.49000000", "0.01020000"], ["1974.48000000", "15.31550000"], ["1974.43000000", "0.63090000"], ["1974.40000000", "0.12940000"], ["1974.38000000", "3.40420000"], ["1974.16000000", "7.29390000"], ["1974.11000000", "1.76210000"], ["1974.03000000", "0.00000000"], ["1974.02000000", "0.00000000"], ["1973.95000000", "13.81410000"], ["1973.93000000", "6.58510000"], ["1973.44000000", "7.92340000"], ["1973.24000000", "0.00000000"], ["1973.23000000", "0.01000000"], ["1972.93000000", "0.41280000"], ["1972.85000000", "0.25390000"], ["1971.97000000", "0.27300000"], ["1971.96000000", "0.00260000"], ["1969.78000000", "0.00000000"], ["1925.13000000", "0.15610000"], ["1777.16000000", "0.07350000"], ["1192.00000000", "0.00000000"]], "a": [["1974.63000000", "0.00000000"], ["1974.64000000", "0.00000000"], ["1974.68000000", "0.01310000"], ["1974.69000000", "0.67070000"], ["1974.70000000", "0.00770000"], ["1974.94000000", "0.00680000"], ["1975.01000000", "0.05310000"], ["1975.06000000", "0.00000000"], ["1975.07000000", "0.00000000"], ["1975.09000000", "4.34160000"], ["1975.10000000", "2.23620000"], ["1975.12000000", "0.01160000"], ["1975.15000000", "0.01020000"], ["1975.18000000", "0.00000000"], ["1975.24000000", "14.17980000"], ["1975.25000000", "0.03300000"], ["1975.26000000", "32.47950000"], ["1975.28000000", "6.46760000"], ["1975.31000000", "7.11780000"], ["1975.35000000", "0.39370000"], ["1975.38000000", "14.30670000"], ["1975.39000000", "0.81000000"], ["1975.40000000", "7.11610000"], ["1975.42000000", "20.25150000"], ["1975.50000000", "0.00570000"], ["1975.55000000", "7.10990000"], ["1975.62000000", "2.13560000"], ["1975.63000000", "3.60260000"], ["1975.65000000", "0.00000000"], ["1975.66000000", "0.00000000"], ["1975.67000000", "0.20000000"], ["1975.72000000", "0.02210000"], ["1975.73000000", "13.50550000"], ["1975.75000000", "0.40000000"], ["1975.76000000", "0.00000000"], ["1975.80000000", "0.80300000"], ["1975.83000000", "23.37370000"], ["1975.90000000", "2.89850000"], ["1976.03000000", "9.93760000"], ["1976.42000000", "15.18500000"], ["1976.60000000", "8.50790000"], ["1976.64000000", "0.84000000"], ["1976.72000000", "0.00000000"], ["1976.78000000", "0.00000000"], ["1976.90000000", "7.08990000"], ["1976.91000000", "0.00000000"], ["1977.05000000", "14.17980000"], ["1977.14000000", "0.00560000"], ["1977.27000000", "0.02000000"], ["1977.45000000", "1.47040000"], ["1977.51000000", "0.00000000"], ["1977.82000000", "0.00870000"], ["1977.94000000", "101.15570000"], ["1978.03000000", "78.96790000"], ["1978.14000000", "0.33420000"], ["1978.16000000", "9.37810000"], ["1978.33000000", "0.00870000"], ["1978.43000000", "1.20550000"], ["1978.51000000", "0.06830000"], ["1978.90000000", "31.62300000"], ["1984.49000000", "0.15110000"], ["1984.56000000", "0.00000000"], ["1984.86000000", "1.20550000"], ["1985.90000000", "0.04290000"]], "_local_ts_utc": "2026-06-01T07:49:16.111496+00:00"}
{"e": "depthUpdate", "E": 1780300157315, "s": "ETHUSDT", "U": 76583135082, "u": 76583136005, "b": [["1974.82000000", "75.60390000"], ["1974.81000000", "17.64460000"], ["1974.80000000", "0.27300000"], ["1974.79000000", "7.29050000"], ["1974.78000000", "0.00000000"], ["1974.77000000", "0.00000000"], ["1974.76000000", "0.00000000"], ["1974.75000000", "21.71920000"], ["1974.74000000", "9.28670000"], ["1974.73000000", "1.11360000"], ["1974.72000000", "0.03260000"], ["1974.71000000", "8.00520000"], ["1974.70000000", "2.70910000"], ["1974.69000000", "0.00000000"], ["1974.68000000", "16.49440000"], ["1974.67000000", "17.95040000"], ["1974.66000000", "0.00760000"], ["1974.65000000", "11.34070000"], ["1974.63000000", "0.50000000"], ["1974.62000000", "3.76190000"], ["1974.61000000", "0.00260000"], ["1974.60000000", "0.25910000"], ["1974.59000000", "0.41250000"], ["1974.58000000", "0.00260000"], ["1974.57000000", "12.15870000"], ["1974.56000000", "19.16980000"], ["1974.55000000", "7.08990000"], ["1974.52000000", "0.62340000"], ["1974.50000000", "0.00870000"], ["1974.49000000", "21.16300000"], ["1974.47000000", "6.08100000"], ["1974.46000000", "26.56480000"], ["1974.38000000", "0.03300000"], ["1974.37000000", "9.72920000"], ["1974.29000000", "0.00000000"], ["1974.25000000", "7.46850000"], ["1974.23000000", "0.00000000"], ["1974.20000000", "7.49370000"], ["1974.19000000", "0.32950000"], ["1974.17000000", "1.01320000"], ["1974.11000000", "7.58510000"], ["1974.03000000", "0.10130000"], ["1974.02000000", "3.60000000"], ["1973.94000000", "8.53580000"], ["1973.87000000", "0.00000000"], ["1973.86000000", "7.36420000"], ["1973.85000000", "0.01780000"], ["1973.80000000", "18.67000000"], ["1973.79000000", "0.47000000"], ["1973.70000000", "11.46710000"], ["1973.68000000", "0.15290000"], ["1973.64000000", "0.80000000"], ["1973.47000000", "1.00000000"], ["1973.46000000", "0.40390000"], ["1973.44000000", "7.12340000"], ["1973.29000000", "4.75840000"], ["1973.27000000", "0.82940000"], ["1973.21000000", "0.27000000"], ["1973.20000000", "9.09140000"], ["1973.16000000", "0.90000000"], ["1973.14000000", "0.00000000"], ["1973.11000000", "0.27000000"], ["1973.02000000", "0.27000000"], ["1972.70000000", "32.16060000"], ["1972.64000000", "16.32190000"], ["1972.32000000", "0.00000000"], ["1972.24000000", "13.51730000"], ["1971.90000000", "7.14120000"], ["1971.85000000", "0.02190000"], ["1971.81000000", "0.00000000"], ["1971.20000000", "2.40470000"], ["1970.87000000", "8.57670000"], ["1970.66000000", "1.08220000"], ["1970.46000000", "0.00000000"], ["1969.85000000", "3.89200000"], ["1969.42000000", "0.50000000"], ["1969.39000000", "0.25980000"], ["1969.04000000", "0.50000000"], ["1969.03000000", "0.00960000"], ["1967.41000000", "0.06680000"], ["1967.28000000", "0.00000000"], ["1967.19000000", "0.00000000"], ["1966.45000000", "0.12170000"], ["1965.57000000", "6.80300000"], ["1964.66000000", "0.05970000"], ["1964.03000000", "0.49950000"], ["1963.64000000", "236.56160000"], ["1963.50000000", "0.02560000"], ["1963.42000000", "0.00000000"], ["1947.35000000", "1.50080000"], ["1944.87000000", "0.13930000"], ["1935.31000000", "0.04830000"], ["1935.24000000", "0.00000000"], ["1935.17000000", "0.00460000"], ["1935.00000000", "42.34350000"], ["1777.33000000", "0.00670000"], ["1777.32000000", "0.00000000"]], "a": [["1974.68000000", "0.00000000"], ["1974.69000000", "0.00000000"], ["1974.70000000", "0.00000000"], ["1974.72000000", "0.00000000"], ["1974.73000000", "0.00000000"], ["1974.74000000", "0.00000000"], ["1974.75000000", "0.00000000"], ["1974.76000000", "0.00000000"], ["1974.77000000", "0.00000000"], ["1974.79000000", "0.00000000"], ["1974.80000000", "0.00000000"], ["1974.81000000", "0.00000000"], ["1974.82000000", "0.00000000"], ["1974.83000000", "0.02230000"], ["1974.84000000", "0.00260000"], ["1974.85000000", "0.00000000"], ["1974.87000000", "0.00260000"], ["1974.88000000", "0.00000000"], ["1974.90000000", "0.00570000"], ["1974.94000000", "0.00300000"], ["1974.95000000", "0.10000000"], ["1975.01000000", "0.05050000"], ["1975.02000000", "0.00260000"], ["1975.07000000", "0.00000000"], ["1975.08000000", "1.30140000"], ["1975.10000000", "0.05570000"], ["1975.12000000", "0.00000000"], ["1975.21000000", "0.01160000"], ["1975.22000000", "10.15870000"], ["1975.23000000", "1.51880000"], ["1975.24000000", "0.00000000"], ["1975.25000000", "0.03300000"], ["1975.26000000", "22.57370000"], ["1975.27000000", "0.00300000"], ["1975.28000000", "0.05000000"], ["1975.30000000", "7.09560000"], ["1975.31000000", "0.02790000"], ["1975.32000000", "11.23750000"], ["1975.35000000", "0.00260000"], ["1975.38000000", "0.80210000"], ["1975.39000000", "0.81000000"], ["1975.42000000", "19.75150000"], ["1975.46000000", "0.03300000"], ["1975.48000000", "7.72140000"], ["1975.49000000", "9.90690000"], ["1975.56000000", "0.80000000"], ["1975.61000000", "0.81170000"], ["1975.63000000", "0.00260000"], ["1975.67000000", "0.00000000"], ["1975.70000000", "0.00260000"], ["1975.72000000", "11.23530000"], ["1975.73000000", "13.50550000"], ["1975.74000000", "0.00640000"], ["1975.75000000", "0.00000000"], ["1975.78000000", "14.18940000"], ["1975.80000000", "0.76570000"], ["1975.81000000", "9.85420000"], ["1975.83000000", "23.04290000"], ["1975.84000000", "0.23260000"], ["1975.86000000", "0.13000000"], ["1975.88000000", "0.01530000"], ["1975.92000000", "0.23110000"], ["1975.93000000", "1.20300000"], ["1975.94000000", "0.00640000"], ["1975.97000000", "0.00000000"], ["1976.04000000", "13.62300000"], ["1976.05000000", "0.00000000"], ["1976.09000000", "1.31870000"], ["1976.24000000", "0.21800000"], ["1976.41000000", "12.46440000"], ["1976.44000000", "0.00260000"], ["1976.52000000", "12.83960000"], ["1976.60000000", "17.08330000"], ["1976.61000000", "8.92640000"], ["1976.62000000", "9.09180000"], ["1976.63000000", "0.00000000"], ["1976.68000000", "0.51300000"], ["1976.70000000", "11.32570000"], ["1976.82000000", "11.62660000"], ["1976.94000000", "1.27520000"], ["1976.98000000", "0.03290000"], ["1977.07000000", "1.21570000"], ["1977.14000000", "7.09550000"], ["1977.27000000", "7.10990000"], ["1977.59000000", "15.00000000"], ["1978.33000000", "13.51330000"], ["1980.03000000", "2.55960000"], ["1980.12000000", "0.00260000"], ["1980.21000000", "0.00260000"], ["1980.30000000", "0.00260000"], ["1984.65000000", "0.02110000"], ["1985.00000000", "4.24840000"], ["1985.03000000", "0.48110000"], ["1990.76000000", "0.00300000"], ["2474.69000000", "0.01200000"]], "_local_ts_utc": "2026-06-01T07:49:16.211477+00:00"}
{"e": "depthUpdate", "E": 1780300157415, "s": "ETHUSDT", "U": 76583136006, "u": 76583136997, "b": [["1975.02000000", "59.07450000"], ["1975.01000000", "0.01050000"], ["1975.00000000", "5.57030000"], ["1974.99000000", "7.83250000"], ["1974.98000000", "0.00000000"], ["1974.95000000", "0.00000000"], ["1974.94000000", "0.00800000"], ["1974.93000000", "8.50790000"], ["1974.92000000", "1.15990000"], ["1974.91000000", "0.00540000"], ["1974.90000000", "14.50340000"], ["1974.89000000", "4.59600000"], ["1974.88000000", "0.00260000"], ["1974.87000000", "0.00000000"], ["1974.86000000", "7.08990000"], ["1974.85000000", "16.65780000"], ["1974.84000000", "12.79450000"], ["1974.83000000", "7.53370000"], ["1974.82000000", "6.08900000"], ["1974.81000000", "0.13970000"], ["1974.80000000", "0.26530000"], ["1974.79000000", "0.82030000"], ["1974.78000000", "8.50790000"], ["1974.76000000", "0.00000000"], ["1974.75000000", "22.58310000"], ["1974.74000000", "9.28410000"], ["1974.73000000", "1.11100000"], ["1974.72000000", "0.03000000"], ["1974.71000000", "4.68260000"], ["1974.70000000", "0.65760000"], ["1974.68000000", "24.88700000"], ["1974.67000000", "12.50790000"], ["1974.66000000", "0.01140000"], ["1974.62000000", "14.50460000"], ["1974.60000000", "0.29210000"], ["1974.59000000", "0.00000000"], ["1974.57000000", "10.85170000"], ["1974.56000000", "15.20980000"], ["1974.52000000", "0.00260000"], ["1974.49000000", "14.89350000"], ["1974.48000000", "13.50720000"], ["1974.47000000", "0.00000000"], ["1974.46000000", "23.69310000"], ["1974.45000000", "7.36040000"], ["1974.43000000", "0.00000000"], ["1974.41000000", "0.05050000"], ["1974.40000000", "0.29990000"], ["1974.33000000", "26.77800000"], ["1974.29000000", "0.80000000"], ["1974.28000000", "22.84430000"], ["1974.24000000", "8.67850000"], ["1974.14000000", "8.70850000"], ["1974.08000000", "0.28090000"], ["1974.03000000", "0.00000000"], ["1974.00000000", "0.00580000"], ["1973.99000000", "0.00000000"], ["1973.98000000", "7.09560000"], ["1973.93000000", "0.00000000"], ["1973.92000000", "7.62040000"], ["1973.90000000", "10.66940000"], ["1973.88000000", "0.02060000"], ["1973.85000000", "0.01020000"], ["1973.83000000", "2.47550000"], ["1973.79000000", "0.87000000"], ["1973.73000000", "0.03860000"], ["1973.61000000", "0.00260000"], ["1973.48000000", "12.29990000"], ["1973.47000000", "0.00000000"], ["1973.46000000", "0.27390000"], ["1973.39000000", "1.14650000"], ["1973.38000000", "0.00000000"], ["1973.34000000", "3.60260000"], ["1973.31000000", "0.00000000"], ["1973.30000000", "0.23820000"], ["1973.15000000", "0.00000000"], ["1972.93000000", "0.28610000"], ["1972.85000000", "0.00560000"], ["1972.24000000", "0.00000000"], ["1971.41000000", "0.00000000"], ["1971.39000000", "0.27000000"], ["1970.67000000", "74.07620000"], ["1970.66000000", "1.07830000"], ["1970.40000000", "2.43630000"], ["1970.00000000", "409.36040000"], ["1969.67000000", "0.58070000"], ["1969.11000000", "0.01240000"], ["1969.03000000", "0.00700000"], ["1968.89000000", "0.00000000"], ["1968.87000000", "0.22170000"], ["1968.74000000", "0.00280000"], ["1968.13000000", "0.04730000"], ["1967.94000000", "1.32500000"], ["1967.82000000", "0.02760000"], ["1967.00000000", "47.91890000"], ["1966.89000000", "0.00350000"], ["1966.65000000", "0.00000000"], ["1965.52000000", "0.19580000"], ["1965.23000000", "4.98820000"], ["1965.18000000", "71.28260000"], ["1964.92000000", "107.22130000"], ["1964.61000000", "1.45440000"], ["1964.43000000", "0.00000000"], ["1963.64000000", "0.02110000"], ["1963.39000000", "0.00860000"], ["1963.33000000", "0.07830000"], ["1963.05000000", "0.00000000"], ["1961.65000000", "0.00000000"], ["1961.44000000", "0.00000000"], ["1935.50000000", "0.03590000"], ["1935.34000000", "0.07150000"], ["1935.32000000", "0.00310000"], ["1777.50000000", "0.00000000"], ["1777.37000000", "0.00560000"]], "a": [["1974.83000000", "0.00000000"], ["1974.84000000", "0.00000000"], ["1974.85000000", "0.00000000"], ["1974.86000000", "0.00000000"], ["1974.87000000", "0.00000000"], ["1974.90000000", "0.00000000"], ["1974.91000000", "0.00000000"], ["1974.92000000", "0.00000000"], ["1974.93000000", "0.00000000"], ["1974.94000000", "0.00000000"], ["1974.95000000", "0.00000000"], ["1975.00000000", "0.00000000"], ["1975.01000000", "0.00000000"], ["1975.02000000", "0.00000000"], ["1975.03000000", "6.77590000"], ["1975.04000000", "0.00260000"], ["1975.07000000", "0.00000000"], ["1975.08000000", "0.00000000"], ["1975.09000000", "0.00000000"], ["1975.11000000", "0.00000000"], ["1975.13000000", "0.00000000"], ["1975.16000000", "0.00840000"], ["1975.18000000", "0.00540000"], ["1975.19000000", "0.17570000"], ["1975.21000000", "0.00540000"], ["1975.22000000", "0.64350000"], ["1975.23000000", "1.50460000"], ["1975.25000000", "0.03300000"], ["1975.26000000", "0.00000000"], ["1975.30000000", "0.00570000"], ["1975.31000000", "0.02790000"], ["1975.34000000", "0.00760000"], ["1975.36000000", "0.04160000"], ["1975.38000000", "0.01910000"], ["1975.39000000", "0.01160000"], ["1975.40000000", "0.02570000"], ["1975.42000000", "11.96110000"], ["1975.43000000", "0.00000000"], ["1975.44000000", "4.39070000"], ["1975.46000000", "14.21280000"], ["1975.47000000", "0.01020000"], ["1975.48000000", "1.25380000"], ["1975.49000000", "9.90950000"], ["1975.53000000", "0.00000000"], ["1975.54000000", "0.00380000"], ["1975.56000000", "6.46760000"], ["1975.63000000", "0.10260000"], ["1975.64000000", "0.00000000"], ["1975.66000000", "1.40000000"], ["1975.70000000", "0.00570000"], ["1975.73000000", "0.00000000"], ["1975.76000000", "13.50460000"], ["1975.78000000", "14.59420000"], ["1975.80000000", "0.00570000"], ["1975.90000000", "0.00260000"], ["1975.91000000", "0.00000000"], ["1975.92000000", "0.00000000"], ["1976.00000000", "17.82250000"], ["1976.02000000", "0.96450000"], ["1976.03000000", "6.19720000"], ["1976.04000000", "0.00300000"], ["1976.09000000", "0.64800000"], ["1976.11000000", "18.18240000"], ["1976.13000000", "0.79680000"], ["1976.23000000", "0.08670000"], ["1976.47000000", "0.00000000"], ["1976.52000000", "11.81850000"], ["1976.61000000", "9.38540000"], ["1976.62000000", "7.71140000"], ["1976.66000000", "0.76000000"], ["1976.70000000", "13.97970000"], ["1976.72000000", "9.64600000"], ["1976.73000000", "0.22580000"], ["1976.81000000", "8.51090000"], ["1976.94000000", "0.00380000"], ["1977.03000000", "3.13940000"], ["1977.14000000", "8.12000000"], ["1977.16000000", "0.00000000"], ["1977.17000000", "0.94810000"], ["1977.22000000", "1.81820000"], ["1977.26000000", "7.09250000"], ["1977.36000000", "7.09670000"], ["1977.45000000", "0.00000000"], ["1977.54000000", "1.27110000"], ["1977.58000000", "0.00260000"], ["1977.60000000", "0.23480000"], ["1977.62000000", "0.03290000"], ["1977.81000000", "22.57370000"], ["1978.24000000", "1.89290000"], ["1978.25000000", "0.50720000"], ["1978.32000000", "13.50460000"], ["1978.33000000", "0.00870000"], ["1978.47000000", "3.12440000"], ["1978.53000000", "22.57370000"], ["1978.70000000", "0.00000000"], ["1978.87000000", "22.57370000"], ["1978.99000000", "0.79330000"], ["1980.36000000", "0.00260000"], ["1980.45000000", "0.20400000"], ["1980.94000000", "0.00260000"], ["1983.96000000", "0.00300000"], ["1984.14000000", "0.00000000"], ["1984.78000000", "3.69260000"], ["1985.03000000", "0.00000000"], ["1985.23000000", "0.00000000"], ["1986.03000000", "0.00000000"], ["1988.00000000", "0.12610000"], ["1990.87000000", "0.00000000"]], "_local_ts_utc": "2026-06-01T07:49:16.311548+00:00"}
{"e": "depthUpdate", "E": 1780300157515, "s": "ETHUSDT", "U": 76583136998, "u": 76583137116, "b": [["1975.02000000", "65.88950000"], ["1975.01000000", "0.01310000"], ["1974.94000000", "0.00800000"], ["1974.93000000", "8.51590000"], ["1974.92000000", "1.15990000"], ["1974.91000000", "0.00800000"], ["1974.88000000", "0.00000000"], ["1974.86000000", "7.08990000"], ["1974.85000000", "16.65520000"], ["1974.84000000", "6.94580000"], ["1974.83000000", "5.07140000"], ["1974.82000000", "5.77770000"], ["1974.80000000", "0.27100000"], ["1974.76000000", "13.50460000"], ["1974.71000000", "9.09560000"], ["1974.69000000", "11.38040000"], ["1974.68000000", "17.77670000"], ["1974.48000000", "13.50460000"], ["1974.37000000", "18.27130000"], ["1974.34000000", "0.10390000"], ["1974.30000000", "0.62860000"], ["1974.16000000", "7.12340000"], ["1974.11000000", "1.00000000"], ["1973.98000000", "7.09040000"], ["1973.88000000", "0.00760000"], ["1973.80000000", "6.47140000"], ["1973.68000000", "0.10260000"], ["1973.59000000", "9.99720000"], ["1973.58000000", "8.51210000"], ["1973.29000000", "4.65780000"], ["1973.23000000", "0.13660000"], ["1973.20000000", "5.64970000"], ["1973.09000000", "0.45410000"], ["1972.99000000", "0.00000000"], ["1972.61000000", "0.27260000"], ["1972.39000000", "0.00000000"], ["1972.38000000", "0.00000000"], ["1971.78000000", "3.13180000"], ["1971.40000000", "0.27310000"], ["1971.22000000", "0.00000000"], ["1969.24000000", "0.52910000"], ["1969.20000000", "0.00310000"], ["1967.44000000", "1.00000000"], ["1967.41000000", "0.05840000"], ["1965.99000000", "0.16270000"], ["1965.47000000", "1.00000000"], ["1965.43000000", "0.13170000"], ["1963.49000000", "1.14610000"], ["1963.46000000", "0.00000000"], ["1961.49000000", "0.01770000"], ["1947.35000000", "0.00000000"], ["1935.51000000", "0.00000000"], ["1933.35000000", "0.00000000"], ["1777.52000000", "0.01240000"]], "a": [["1975.03000000", "6.78650000"], ["1975.04000000", "0.58080000"], ["1975.10000000", "0.05830000"], ["1975.14000000", "0.00000000"], ["1975.16000000", "0.00300000"], ["1975.21000000", "0.00000000"], ["1975.22000000", "0.00540000"], ["1975.25000000", "0.04460000"], ["1975.26000000", "0.00260000"], ["1975.30000000", "0.01730000"], ["1975.32000000", "8.02110000"], ["1975.41000000", "1.29950000"], ["1975.43000000", "22.57370000"], ["1975.45000000", "7.29190000"], ["1975.55000000", "24.40990000"], ["1975.56000000", "0.00000000"], ["1975.61000000", "7.89490000"], ["1975.63000000", "22.67630000"], ["1975.68000000", "6.56730000"], ["1975.90000000", "0.00260000"], ["1976.13000000", "0.59400000"], ["1976.27000000", "0.01920000"], ["1976.34000000", "0.00380000"], ["1976.35000000", "3.04620000"], ["1976.78000000", "0.00260000"], ["1976.94000000", "1.12910000"], ["1977.36000000", "0.00680000"], ["1977.71000000", "0.55760000"], ["1978.32000000", "0.00000000"], ["1980.56000000", "0.00260000"], ["1980.65000000", "0.03550000"]], "_local_ts_utc": "2026-06-01T07:49:16.411214+00:00"}
{"e": "depthUpdate", "E": 1780300157615, "s": "ETHUSDT", "U": 76583137117, "u": 76583137168, "b": [["1975.02000000", "73.03310000"], ["1975.00000000", "12.24390000"], ["1974.94000000", "0.00260000"], ["1974.93000000", "0.00800000"], ["1974.90000000", "14.50610000"], ["1974.89000000", "4.59600000"], ["1974.77000000", "14.08040000"], ["1974.76000000", "13.50460000"], ["1974.70000000", "0.00830000"], ["1974.45000000", "7.63040000"], ["1974.43000000", "0.27000000"], ["1974.06000000", "0.55440000"], ["1973.94000000", "8.50850000"], ["1973.64000000", "0.00000000"], ["1973.53000000", "0.80000000"], ["1973.46000000", "0.54390000"], ["1973.44000000", "7.39340000"], ["1972.81000000", "13.51490000"], ["1971.69000000", "0.00370000"], ["1971.40000000", "0.00310000"], ["1971.32000000", "0.02020000"], ["1971.12000000", "0.00300000"], ["1970.56000000", "107.43930000"], ["1970.00000000", "409.15880000"], ["1969.44000000", "0.00300000"], ["1968.87000000", "0.02000000"], ["1968.31000000", "0.21290000"], ["1967.75000000", "0.00000000"], ["1967.18000000", "3.98690000"], ["1966.62000000", "0.00000000"], ["1966.46000000", "0.16260000"], ["1966.06000000", "0.00970000"], ["1965.50000000", "0.00000000"], ["1964.93000000", "0.05650000"], ["1964.37000000", "0.00000000"], ["1963.81000000", "0.00000000"], ["1946.31000000", "0.00000000"], ["1942.62000000", "0.00340000"], ["1933.11000000", "0.00000000"], ["1923.45000000", "0.00310000"], ["1777.52000000", "0.02480000"]], "a": [["1975.03000000", "9.48750000"], ["1975.04000000", "0.57820000"], ["1975.23000000", "1.51620000"], ["1975.39000000", "0.00000000"], ["1975.46000000", "14.84870000"], ["1975.67000000", "0.51300000"], ["1975.69000000", "0.97460000"], ["1976.36000000", "2.82160000"], ["1976.66000000", "1.27300000"], ["1976.68000000", "0.97200000"], ["1977.84000000", "0.03290000"], ["1977.88000000", "3.60000000"], ["1978.34000000", "32.42510000"], ["1979.00000000", "3.97660000"], ["1979.57000000", "0.03290000"], ["1980.13000000", "0.00000000"], ["1980.65000000", "0.03290000"], ["1980.69000000", "0.00000000"], ["1981.25000000", "0.00600000"], ["1981.82000000", "0.00000000"], ["1982.38000000", "3.63280000"], ["1982.94000000", "0.00000000"], ["1983.50000000", "1.24200000"], ["1984.07000000", "0.00000000"], ["1984.63000000", "0.00000000"], ["1985.19000000", "0.00460000"], ["1985.76000000", "0.00000000"], ["1986.32000000", "0.00000000"]], "_local_ts_utc": "2026-06-01T07:49:16.511231+00:00"}
