{"e": "depthUpdate", "E": 1780300142814, "s": "BTCUSDT", "U": 94551772994, "u": 94551773199, "b": [["72730.61000000", "1.71297000"], ["72730.01000000", "0.00024000"], ["72729.83000000", "0.00000000"], ["72729.05000000", "0.00000000"], ["72728.00000000", "0.02296000"], ["72727.37000000", "0.02938000"], ["72727.27000000", "0.00555000"], ["72727.01000000", "0.00000000"], ["72726.72000000", "0.00000000"], ["72726.38000000", "0.00000000"], ["72725.50000000", "0.00054000"], ["72725.03000000", "0.01376000"], ["72724.98000000", "0.05942000"], ["72724.97000000", "0.00000000"], ["72723.56000000", "0.00400000"], ["72722.48000000", "0.00000000"], ["72721.60000000", "0.00000000"], ["72719.70000000", "0.00000000"], ["72719.39000000", "0.36902000"], ["72718.33000000", "0.00000000"], ["72717.64000000", "0.03407000"], ["72717.24000000", "0.65949000"], ["72716.51000000", "0.17933000"], ["72714.13000000", "0.00000000"], ["72712.64000000", "0.00400000"], ["72711.80000000", "0.17926000"], ["72711.12000000", "0.00000000"], ["72709.56000000", "0.00000000"], ["72708.26000000", "0.00000000"], ["72708.03000000", "0.38729000"], ["72707.18000000", "0.00400000"], ["72706.74000000", "0.00000000"], ["72704.34000000", "0.00000000"], ["72702.70000000", "0.00459000"], ["72700.01000000", "0.00063000"], ["72699.99000000", "0.02728000"], ["72698.44000000", "0.00000000"], ["72698.33000000", "0.00102000"], ["72696.43000000", "0.00000000"], ["72694.44000000", "0.00000000"], ["72692.62000000", "0.00000000"], ["72671.27000000", "0.00007000"], ["72648.41000000", "0.00282000"], ["72609.81000000", "0.01866000"], ["72597.72000000", "0.00000000"], ["72575.34000000", "0.00113000"], ["72014.58000000", "0.00000000"], ["72009.35000000", "0.00007000"], ["69104.90000000", "0.00116000"], ["65463.00000000", "0.00020000"], ["65457.55000000", "0.00068000"]], "a": [["72730.62000000", "3.95318000"], ["72730.85000000", "0.00000000"], ["72730.86000000", "0.11136000"], ["72731.02000000", "0.17022000"], ["72731.03000000", "0.00016000"], ["72731.04000000", "0.65973000"], ["72731.06000000", "0.00667000"], ["72731.33000000", "0.00031000"], ["72731.81000000", "0.00016000"], ["72732.01000000", "0.00000000"], ["72732.21000000", "0.00000000"], ["72732.31000000", "0.00000000"], ["72732.32000000", "0.04131000"], ["72732.40000000", "0.00000000"], ["72732.41000000", "0.10458000"], ["72732.60000000", "0.16095000"], ["72732.61000000", "0.66438000"], ["72734.81000000", "0.17926000"], ["72734.83000000", "0.57906000"], ["72735.31000000", "0.05619000"], ["72735.81000000", "0.00000000"], ["72736.22000000", "0.17799000"], ["72736.26000000", "0.17926000"], ["72737.43000000", "0.04000000"], ["72737.67000000", "0.17542000"], ["72738.01000000", "0.17926000"], ["72739.11000000", "0.00000000"], ["72739.70000000", "0.00000000"], ["72739.75000000", "0.00028000"], ["72740.47000000", "0.17926000"], ["72740.48000000", "0.00000000"], ["72741.90000000", "0.17926000"], ["72741.98000000", "0.00000000"], ["72742.13000000", "0.00000000"], ["72743.72000000", "0.00000000"], ["72744.40000000", "0.16586000"], ["72744.41000000", "0.00000000"], ["72746.02000000", "0.17799000"], ["72746.08000000", "0.35562000"], ["72746.10000000", "0.00008000"], ["72746.68000000", "0.00000000"], ["72747.36000000", "0.68834000"], ["72749.07000000", "1.45827000"], ["72753.77000000", "0.00000000"], ["72753.78000000", "0.66832000"], ["72757.72000000", "0.58507000"], ["72758.80000000", "0.00199000"], ["72802.57000000", "0.27000000"], ["72829.25000000", "0.23280000"], ["72833.93000000", "0.03445000"], ["72841.09000000", "0.11056000"], ["72849.08000000", "0.00000000"], ["73187.51000000", "0.00136000"], ["73464.10000000", "0.00007000"], ["73469.44000000", "0.00000000"]], "_local_ts_utc": "2026-06-01T07:49:01.710273+00:00"}
{"e": "depthUpdate", "E": 1780300142914, "s": "BTCUSDT", "U": 94551773200, "u": 94551773327, "b": [["72730.61000000", "2.45310000"], ["72730.02000000", "0.00016000"], ["72730.01000000", "0.05552000"], ["72728.35000000", "0.00031000"], ["72727.75000000", "0.00007000"], ["72727.40000000", "0.00000000"], ["72727.38000000", "0.00000000"], ["72727.27000000", "0.00555000"], ["72727.01000000", "0.64790000"], ["72725.50000000", "0.00023000"], ["72723.61000000", "0.17799000"], ["72722.21000000", "0.17799000"], ["72719.40000000", "2.74944000"], ["72716.51000000", "0.17940000"], ["72716.07000000", "0.00007000"], ["72710.23000000", "0.01289000"], ["72709.61000000", "0.17799000"], ["72708.21000000", "0.17799000"], ["72708.04000000", "0.17799000"], ["72705.41000000", "0.17799000"], ["72702.62000000", "0.17799000"], ["72701.51000000", "0.00686000"], ["72698.41000000", "0.17808000"], ["72697.01000000", "0.17816000"], ["72694.69000000", "0.00102000"], ["72686.97000000", "0.00685000"], ["72683.34000000", "0.00102000"], ["72671.27000000", "0.00350000"], ["72654.13000000", "0.00354000"], ["72634.30000000", "0.00000000"], ["72615.76000000", "0.00034000"], ["72597.72000000", "0.00137000"], ["72422.40000000", "0.00008000"], ["72009.35000000", "0.00000000"], ["72003.73000000", "0.00007000"], ["65463.00000000", "0.00000000"], ["65457.55000000", "0.00102000"]], "a": [["72730.62000000", "3.52913000"], ["72730.85000000", "0.00016000"], ["72730.86000000", "0.11136000"], ["72731.01000000", "0.00016000"], ["72731.02000000", "0.17038000"], ["72731.03000000", "0.00016000"], ["72731.04000000", "0.00024000"], ["72731.06000000", "0.00667000"], ["72731.81000000", "0.00000000"], ["72732.31000000", "0.00016000"], ["72732.40000000", "0.00008000"], ["72732.41000000", "0.10458000"], ["72732.60000000", "0.16111000"], ["72733.23000000", "0.00164000"], ["72734.81000000", "1.07378000"], ["72734.83000000", "0.00000000"], ["72736.22000000", "0.00000000"], ["72736.26000000", "0.00000000"], ["72736.97000000", "0.04000000"], ["72737.43000000", "0.00000000"], ["72737.67000000", "0.00000000"], ["72738.01000000", "0.00000000"], ["72738.88000000", "0.00008000"], ["72740.47000000", "0.44926000"], ["72742.00000000", "0.03708000"], ["72742.01000000", "0.11059000"], ["72743.87000000", "0.00000000"], ["72745.16000000", "0.00008000"], ["72746.74000000", "0.00400000"], ["72747.55000000", "0.00000000"], ["72748.08000000", "0.00008000"], ["72748.35000000", "0.00890000"], ["72753.78000000", "0.65949000"], ["72756.56000000", "0.00000000"], ["72759.72000000", "0.00686000"], ["72771.50000000", "0.02669000"], ["72774.26000000", "0.00685000"], ["72775.62000000", "0.00000000"], ["72844.27000000", "0.08171000"], ["72852.96000000", "0.00000000"], ["73106.88000000", "0.00000000"], ["73458.38000000", "0.00007000"], ["73464.10000000", "0.00000000"], ["75384.85000000", "0.00000000"]], "_local_ts_utc": "2026-06-01T07:49:01.810404+00:00"}
{"e": "depthUpdate", "E": 1780300143014, "s": "BTCUSDT", "U": 94551773328, "u": 94551773454, "b": [["72730.61000000", "2.64659000"], ["72730.60000000", "0.00088000"], ["72730.02000000", "0.00016000"], ["72730.01000000", "0.05560000"], ["72729.93000000", "0.00031000"], ["72729.75000000", "0.00031000"], ["72728.35000000", "0.00000000"], ["72727.38000000", "0.00000000"], ["72727.27000000", "0.00539000"], ["72725.11000000", "0.00000000"], ["72725.03000000", "0.00000000"], ["72724.98000000", "0.00000000"], ["72722.22000000", "0.25412000"], ["72722.16000000", "0.00000000"], ["72720.50000000", "0.15218000"], ["72719.41000000", "1.28742000"], ["72719.39000000", "0.00000000"], ["72719.33000000", "0.00000000"], ["72717.92000000", "0.00000000"], ["72716.51000000", "0.00014000"], ["72716.07000000", "0.00014000"], ["72716.06000000", "0.00300000"], ["72711.79000000", "1.15264000"], ["72711.27000000", "0.01383000"], ["72711.14000000", "0.77217000"], ["72709.61000000", "0.00000000"], ["72709.55000000", "0.00000000"], ["72708.21000000", "0.00000000"], ["72708.04000000", "0.00000000"], ["72705.23000000", "0.00000000"], ["72705.16000000", "0.00102000"], ["72702.62000000", "0.00000000"], ["72702.57000000", "0.00011000"], ["72701.89000000", "0.00200000"], ["72700.78000000", "0.00000000"], ["72699.99000000", "0.00000000"], ["72695.53000000", "0.02690000"], ["72686.97000000", "0.00000000"], ["72686.49000000", "0.00021000"], ["72683.56000000", "0.49592000"], ["72681.57000000", "0.00343000"], ["72675.20000000", "0.02000000"], ["72671.24000000", "0.02791000"], ["72665.88000000", "0.00000000"], ["72608.01000000", "0.00137000"], ["72003.73000000", "0.00000000"], ["72003.30000000", "0.00007000"], ["65457.55000000", "0.00136000"], ["58184.49000000", "0.00034000"]], "a": [["72730.62000000", "3.56388000"], ["72731.01000000", "0.00000000"], ["72731.02000000", "0.00016000"], ["72731.03000000", "0.00000000"], ["72731.04000000", "0.00008000"], ["72732.01000000", "0.00016000"], ["72732.02000000", "0.17799000"], ["72732.40000000", "0.48160000"], ["72732.59000000", "0.00016000"], ["72732.60000000", "0.16111000"], ["72733.19000000", "0.07557000"], ["72736.96000000", "0.04000000"], ["72736.97000000", "0.00000000"], ["72737.90000000", "0.00300000"], ["72738.29000000", "0.49829000"], ["72740.42000000", "0.17799000"], ["72742.60000000", "0.08200000"], ["72748.94000000", "0.45885000"], ["72748.95000000", "0.17944000"], ["72759.26000000", "0.00000000"], ["72760.08000000", "0.00200000"], ["72761.36000000", "0.00000000"], ["72774.26000000", "0.00000000"], ["72787.07000000", "0.00189000"], ["72809.85000000", "0.27000000"], ["72843.23000000", "0.00000000"], ["72859.90000000", "0.00075000"], ["73457.93000000", "0.00007000"], ["73458.38000000", "0.00000000"]], "_local_ts_utc": "2026-06-01T07:49:01.912766+00:00"}
{"e": "depthUpdate", "E": 1780300143114, "s": "BTCUSDT", "U": 94551773455, "u": 94551773547, "b": [["72730.61000000", "2.51382000"], ["72729.93000000", "0.00000000"], ["72729.75000000", "0.00000000"], ["72728.69000000", "0.00031000"], ["72726.74000000", "0.05942000"], ["72725.38000000", "0.00400000"], ["72725.01000000", "0.17801000"], ["72717.25000000", "0.16191000"], ["72715.21000000", "0.17801000"], ["72714.15000000", "0.00165000"], ["72710.54000000", "0.02000000"], ["72705.41000000", "0.00000000"], ["72705.12000000", "0.00000000"], ["72701.33000000", "0.00000000"], ["72701.21000000", "0.17801000"], ["72696.26000000", "0.00000000"], ["72691.48000000", "0.02733000"], ["72681.57000000", "0.00000000"], ["72672.81000000", "0.02000000"], ["72672.09000000", "0.02000000"], ["72608.01000000", "0.00000000"], ["65457.55000000", "0.00170000"], ["58184.00000000", "0.00600000"]], "a": [["72730.62000000", "2.78933000"], ["72730.85000000", "0.00000000"], ["72730.86000000", "0.00016000"], ["72731.02000000", "0.00000000"], ["72731.06000000", "0.00667000"], ["72732.01000000", "0.00000000"], ["72732.02000000", "0.17817000"], ["72732.32000000", "0.04131000"], ["72732.39000000", "0.17817000"], ["72732.40000000", "0.35302000"], ["72732.59000000", "0.00000000"], ["72732.60000000", "0.00040000"], ["72733.18000000", "0.00016000"], ["72733.19000000", "0.07541000"], ["72738.01000000", "0.17801000"], ["72740.42000000", "0.17801000"], ["72740.47000000", "0.27000000"], ["72741.25000000", "0.00196000"], ["72741.82000000", "0.17801000"], ["72744.86000000", "0.05400000"], ["72745.60000000", "0.05400000"], ["72746.09000000", "0.18411000"], ["72747.36000000", "0.00000000"], ["72748.34000000", "0.00000000"], ["72748.94000000", "0.45903000"], ["72748.95000000", "0.17926000"], ["72749.28000000", "0.68832000"], ["72753.18000000", "0.00000000"], ["72767.57000000", "0.02737000"], ["72771.50000000", "0.00000000"], ["72802.30000000", "0.00021000"], ["72805.23000000", "0.00000000"]], "_local_ts_utc": "2026-06-01T07:49:02.009683+00:00"}
{"e": "depthUpdate", "E": 1780300143214, "s": "BTCUSDT", "U": 94551773548, "u": 94551773677, "b": [["72730.61000000", "1.77443000"], ["72730.02000000", "0.00000000"], ["72730.01000000", "0.00040000"], ["72729.07000000", "0.00000000"], ["72728.75000000", "0.00031000"], ["72728.69000000", "0.00000000"], ["72728.04000000", "0.00000000"], ["72727.38000000", "0.00008000"], ["72727.01000000", "0.00000000"], ["72726.74000000", "0.00000000"], ["72725.01000000", "0.00000000"], ["72723.61000000", "0.00000000"], ["72722.22000000", "0.15929000"], ["72722.15000000", "0.00000000"], ["72721.94000000", "0.01376000"], ["72720.50000000", "0.00000000"], ["72719.41000000", "0.21989000"], ["72719.40000000", "0.00000000"], ["72718.01000000", "0.17801000"], ["72717.25000000", "0.17801000"], ["72715.10000000", "0.00000000"], ["72714.15000000", "0.17966000"], ["72710.54000000", "0.00000000"], ["72709.24000000", "0.08789000"], ["72706.41000000", "0.00000000"], ["72705.41000000", "0.16164000"], ["72704.34000000", "0.17801000"], ["72704.30000000", "0.02000000"], ["72702.62000000", "0.17801000"], ["72700.68000000", "0.03352000"], ["72681.57000000", "0.00000000"], ["72678.03000000", "0.01374000"], ["72639.52000000", "0.00008000"], ["72634.30000000", "2.74987000"], ["72608.01000000", "0.00000000"], ["65457.55000000", "0.00221000"], ["58184.49000000", "0.00000000"], ["58184.00000000", "0.00000000"]], "a": [["72730.62000000", "3.05876000"], ["72730.86000000", "0.00000000"], ["72731.73000000", "0.00028000"], ["72732.01000000", "0.00000000"], ["72732.31000000", "0.00000000"], ["72732.32000000", "0.04131000"], ["72732.38000000", "0.00000000"], ["72732.39000000", "0.17817000"], ["72732.40000000", "0.35286000"], ["72732.41000000", "0.10458000"], ["72732.60000000", "0.00008000"], ["72732.61000000", "0.67832000"], ["72733.18000000", "0.00008000"], ["72733.19000000", "0.07557000"], ["72736.22000000", "0.17801000"], ["72736.96000000", "0.00000000"], ["72737.53000000", "0.17801000"], ["72738.66000000", "0.04000000"], ["72738.79000000", "0.00000000"], ["72738.80000000", "0.00000000"], ["72741.25000000", "0.00008000"], ["72742.56000000", "0.65968000"], ["72745.11000000", "0.00000000"], ["72745.47000000", "0.00400000"], ["72746.01000000", "0.68833000"], ["72746.74000000", "0.00000000"], ["72749.28000000", "0.00000000"], ["72753.42000000", "0.00200000"], ["72849.28000000", "0.00000000"], ["72871.10000000", "0.00000000"], ["75376.16000000", "0.00007000"]], "_local_ts_utc": "2026-06-01T07:49:02.111023+00:00"}
{"e": "depthUpdate", "E": 1780300143314, "s": "BTCUSDT", "U": 94551773678, "u": 94551773855, "b": [["72730.61000000", "0.11527000"], ["72730.60000000", "0.00080000"], ["72730.01000000", "0.00024000"], ["72728.75000000", "0.00000000"], ["72727.38000000", "0.00000000"], ["72727.37000000", "0.00016000"], ["72727.27000000", "0.00555000"], ["72727.19000000", "0.00000000"], ["72727.18000000", "0.00000000"], ["72726.28000000", "0.01097000"], ["72726.01000000", "0.00008000"], ["72725.57000000", "0.00000000"], ["72725.38000000", "0.00000000"], ["72724.49000000", "0.00000000"], ["72724.20000000", "0.00016000"], ["72723.39000000", "0.00000000"], ["72722.91000000", "0.00031000"], ["72722.22000000", "0.00041000"], ["72722.21000000", "0.00000000"], ["72721.95000000", "0.04502000"], ["72720.81000000", "0.00000000"], ["72720.74000000", "0.00000000"], ["72719.41000000", "0.30424000"], ["72717.64000000", "0.00000000"], ["72717.26000000", "0.65949000"], ["72717.24000000", "0.00000000"], ["72716.07000000", "0.00021000"], ["72711.82000000", "1.40985000"], ["72711.81000000", "2.74987000"], ["72711.80000000", "0.00000000"], ["72711.79000000", "0.00000000"], ["72711.78000000", "0.00000000"], ["72711.14000000", "0.00008000"], ["72710.63000000", "0.00000000"], ["72709.23000000", "0.02000000"], ["72708.80000000", "0.00102000"], ["72708.02000000", "0.00000000"], ["72705.41000000", "0.00000000"], ["72704.35000000", "0.77226000"], ["72702.62000000", "0.00000000"], ["72702.57000000", "0.00000000"], ["72701.89000000", "0.00000000"], ["72701.51000000", "0.01371000"], ["72700.00000000", "0.71607000"], ["72698.99000000", "0.00200000"], ["72698.41000000", "0.00009000"], ["72692.81000000", "0.64610000"], ["72692.62000000", "0.00400000"], ["72681.57000000", "0.00343000"], ["72678.18000000", "0.02000000"], ["72677.96000000", "0.02000000"], ["72676.59000000", "0.02000000"], ["72675.73000000", "0.02000000"], ["72674.04000000", "0.00000000"], ["72668.61000000", "1.40245000"], ["72666.69000000", "1.12326000"], ["72665.77000000", "0.00011000"], ["72622.66000000", "0.00000000"], ["72608.01000000", "0.00137000"], ["72379.91000000", "0.00137000"], ["71787.36000000", "0.03470000"], ["65457.55000000", "0.00255000"], ["58184.00000000", "0.00200000"]], "a": [["72730.62000000", "2.99905000"], ["72731.65000000", "0.03000000"], ["72731.96000000", "0.07136000"], ["72732.07000000", "0.03407000"], ["72733.52000000", "0.00000000"], ["72734.54000000", "0.00000000"], ["72737.00000000", "0.03407000"], ["72738.61000000", "0.00000000"], ["72738.66000000", "0.00000000"], ["72738.81000000", "0.04000000"], ["72739.36000000", "0.12000000"], ["72739.64000000", "0.00000000"], ["72741.99000000", "1.42413000"], ["72742.54000000", "0.08600000"], ["72742.55000000", "2.74987000"], ["72742.59000000", "0.08000000"], ["72742.67000000", "0.07400000"], ["72743.22000000", "0.68836000"], ["72745.14000000", "0.06200000"], ["72746.00000000", "0.36472000"], ["72746.01000000", "0.00000000"], ["72746.08000000", "0.00000000"], ["72751.02000000", "0.00256000"], ["72751.62000000", "0.17801000"], ["72753.02000000", "0.17801000"], ["72753.77000000", "0.17801000"], ["72754.97000000", "0.00000000"], ["72757.18000000", "0.00200000"], ["72757.72000000", "0.92103000"], ["72758.13000000", "1.36238000"], ["72759.72000000", "0.01371000"], ["72760.08000000", "0.00000000"], ["72806.78000000", "0.00000000"], ["72820.32000000", "1.43524000"], ["72820.33000000", "0.00000000"], ["72839.23000000", "0.02154000"], ["72848.44000000", "0.00000000"], ["72901.20000000", "0.00000000"]], "_local_ts_utc": "2026-06-01T07:49:02.210262+00:00"}
{"e": "depthUpdate", "E": 1780300143414, "s": "BTCUSDT", "U": 94551773856, "u": 94551773950, "b": [["72730.61000000", "0.11457000"], ["72728.00000000", "0.02296000"], ["72727.37000000", "0.00000000"], ["72727.01000000", "0.00008000"], ["72727.00000000", "1.25062000"], ["72726.46000000", "0.00000000"], ["72726.01000000", "0.00000000"], ["72725.37000000", "0.00000000"], ["72724.99000000", "0.00000000"], ["72724.25000000", "0.00031000"], ["72723.72000000", "0.00031000"], ["72723.56000000", "0.00000000"], ["72722.91000000", "0.00000000"], ["72722.01000000", "0.04813000"], ["72721.95000000", "0.00000000"], ["72721.94000000", "0.00000000"], ["72719.42000000", "0.17801000"], ["72716.07000000", "0.00028000"], ["72715.94000000", "0.00000000"], ["72715.12000000", "0.01209000"], ["72714.97000000", "0.14320000"], ["72712.07000000", "0.00185000"], ["72711.83000000", "0.17801000"], ["72711.27000000", "0.00007000"], ["72708.03000000", "0.27910000"], ["72705.41000000", "0.17801000"], ["72701.52000000", "0.00102000"], ["72695.88000000", "0.04307000"], ["72694.44000000", "0.00400000"], ["72678.15000000", "0.02000000"], ["71933.12000000", "0.03806000"], ["71422.96000000", "0.01745000"], ["65457.55000000", "0.00289000"], ["58184.00000000", "0.00000000"]], "a": [["72731.06000000", "0.00667000"], ["72731.65000000", "0.03016000"], ["72731.96000000", "0.07152000"], ["72732.02000000", "0.17825000"], ["72732.07000000", "0.00016000"], ["72732.41000000", "0.10442000"], ["72732.61000000", "0.67816000"], ["72733.19000000", "0.07541000"], ["72738.76000000", "0.04000000"], ["72738.81000000", "0.00000000"], ["72742.47000000", "0.08600000"], ["72751.62000000", "0.00000000"], ["72753.02000000", "0.00000000"], ["72753.77000000", "0.00000000"], ["72758.80000000", "0.00000000"], ["72812.51000000", "0.01563000"], ["72825.02000000", "0.00000000"], ["72833.10000000", "0.00939000"], ["72839.23000000", "0.00000000"], ["72841.67000000", "0.00000000"], ["72843.35000000", "0.00000000"], ["72884.52000000", "0.00185000"], ["72898.94000000", "0.00000000"], ["73396.68000000", "0.00000000"]], "_local_ts_utc": "2026-06-01T07:49:02.310321+00:00"}
{"e": "depthUpdate", "E": 1780300143514, "s": "BTCUSDT", "U": 94551773951, "u": 94551774021, "b": [["72730.61000000", "0.11063000"], ["72724.39000000", "0.00000000"], ["72724.25000000", "0.00000000"], ["72723.74000000", "0.00041000"], ["72723.72000000", "0.00000000"], ["72722.02000000", "0.08024000"], ["72722.01000000", "0.00000000"], ["72721.05000000", "0.05942000"], ["72719.42000000", "0.00000000"], ["72719.41000000", "0.21172000"], ["72718.01000000", "0.00000000"], ["72717.25000000", "0.00000000"], ["72708.03000000", "0.26534000"], ["72704.34000000", "0.00000000"], ["72701.51000000", "0.00686000"], ["72701.11000000", "0.00000000"], ["72700.04000000", "0.16516000"], ["72695.53000000", "0.00000000"], ["72686.98000000", "0.00102000"], ["72685.58000000", "0.28997000"], ["72685.41000000", "0.00000000"], ["72681.57000000", "0.00000000"], ["72640.00000000", "0.19030000"], ["72637.70000000", "0.00000000"], ["72608.01000000", "0.00000000"], ["72550.45000000", "0.00000000"], ["72531.55000000", "0.00822000"], ["72432.36000000", "4.14727000"], ["65457.55000000", "0.00323000"], ["58184.49000000", "0.00034000"]], "a": [["72730.62000000", "3.30330000"], ["72731.73000000", "0.00000000"], ["72732.02000000", "0.17825000"], ["72732.07000000", "0.00000000"], ["72732.41000000", "0.10458000"], ["72738.67000000", "0.00000000"], ["72738.76000000", "0.04000000"], ["72741.26000000", "0.29140000"], ["72741.98000000", "0.00400000"], ["72745.47000000", "0.00000000"], ["72748.95000000", "0.17944000"], ["72751.02000000", "0.00000000"], ["72759.72000000", "0.00686000"], ["72806.05000000", "0.00000000"], ["72824.98000000", "0.00000000"]], "_local_ts_utc": "2026-06-01T07:49:02.410309+00:00"}
{"e": "depthUpdate", "E": 1780300143614, "s": "BTCUSDT", "U": 94551774022, "u": 94551774146, "b": [["72730.61000000", "0.08433000"], ["72724.53000000", "0.00000000"], ["72723.74000000", "0.00010000"], ["72722.82000000", "0.00000000"], ["72722.02000000", "0.00000000"], ["72721.93000000", "0.01386000"], ["72721.16000000", "0.00031000"], ["72721.05000000", "0.00000000"], ["72720.37000000", "0.00031000"], ["72720.18000000", "0.00000000"], ["72719.41000000", "0.00000000"], ["72718.69000000", "0.01375000"], ["72718.32000000", "0.05942000"], ["72717.26000000", "0.00000000"], ["72716.59000000", "0.01376000"], ["72716.07000000", "0.00028000"], ["72715.21000000", "0.00000000"], ["72714.97000000", "0.00000000"], ["72714.16000000", "0.65949000"], ["72714.14000000", "0.00000000"], ["72713.71000000", "0.00000000"], ["72713.65000000", "0.02000000"], ["72713.52000000", "0.00000000"], ["72712.97000000", "0.02000000"], ["72711.26000000", "0.01376000"], ["72709.73000000", "0.00000000"], ["72709.23000000", "0.00000000"], ["72708.79000000", "0.00013000"], ["72707.80000000", "0.04000000"], ["72707.53000000", "0.03000000"], ["72705.41000000", "0.00000000"], ["72704.30000000", "0.00000000"], ["72704.14000000", "0.00000000"], ["72703.52000000", "0.00687000"], ["72702.40000000", "0.02000000"], ["72701.85000000", "0.00000000"], ["72700.46000000", "0.01376000"], ["72698.99000000", "0.00000000"], ["72698.35000000", "0.00000000"], ["72697.18000000", "0.00200000"], ["72694.72000000", "0.00008000"], ["72686.98000000", "0.00000000"], ["72686.97000000", "0.00013000"], ["72683.56000000", "0.00000000"], ["72679.64000000", "0.03663000"], ["72679.22000000", "0.00000000"], ["72676.53000000", "0.00486000"], ["72673.44000000", "0.04710000"], ["72667.80000000", "0.02000000"], ["72667.12000000", "0.02000000"], ["72665.15000000", "0.00013000"], ["72656.83000000", "0.49610000"], ["72654.71000000", "0.00000000"], ["72643.33000000", "0.00013000"], ["72635.13000000", "0.00679000"], ["72632.89000000", "0.00000000"], ["72621.51000000", "0.00024000"], ["72549.45000000", "0.00000000"], ["72441.58000000", "0.00000000"], ["65457.55000000", "0.00357000"], ["58184.49000000", "0.00000000"]], "a": [["72730.62000000", "3.60315000"], ["72731.04000000", "0.00073000"], ["72731.65000000", "0.00016000"], ["72731.68000000", "0.03407000"], ["72732.42000000", "0.00028000"], ["72733.18000000", "0.00116000"], ["72737.63000000", "0.00007000"], ["72738.47000000", "0.04000000"], ["72738.67000000", "0.00000000"], ["72738.76000000", "0.00000000"], ["72739.36000000", "0.00000000"], ["72740.10000000", "0.00007000"], ["72741.26000000", "0.25073000"], ["72742.01000000", "0.10982000"], ["72742.81000000", "0.00000000"], ["72744.11000000", "0.06200000"], ["72744.88000000", "0.05400000"], ["72751.62000000", "0.17801000"], ["72752.44000000", "0.00013000"], ["72753.02000000", "0.17475000"], ["72753.77000000", "0.17801000"], ["72755.37000000", "0.00200000"], ["72757.18000000", "0.00000000"], ["72762.88000000", "0.00349000"], ["72763.83000000", "0.00000000"], ["72774.26000000", "0.00013000"], ["72785.66000000", "0.00000000"], ["72786.98000000", "0.18721000"], ["72787.07000000", "0.00000000"], ["72792.04000000", "0.66499000"], ["72796.08000000", "0.00013000"], ["72807.48000000", "0.00000000"], ["72815.51000000", "0.77566000"], ["72817.73000000", "2.43980000"], ["72817.90000000", "0.00013000"], ["72826.58000000", "0.00000000"], ["72829.23000000", "0.00000000"], ["72829.26000000", "0.00000000"], ["72829.30000000", "0.00000000"], ["72834.10000000", "0.00028000"], ["72838.48000000", "0.13190000"], ["72838.49000000", "0.00000000"], ["72839.72000000", "0.00013000"], ["72848.59000000", "0.00000000"], ["72851.12000000", "0.00000000"], ["72859.90000000", "0.00000000"]], "_local_ts_utc": "2026-06-01T07:49:02.510287+00:00"}
{"e": "depthUpdate", "E": 1780300143714, "s": "BTCUSDT", "U": 94551774147, "u": 94551774363, "b": [["72730.61000000", "0.11777000"], ["72727.01000000", "0.00016000"], ["72726.28000000", "0.00010000"], ["72726.02000000", "0.00792000"], ["72722.54000000", "0.00247000"], ["72722.01000000", "0.00008000"], ["72721.74000000", "0.00000000"], ["72721.54000000", "0.00000000"], ["72721.16000000", "0.00000000"], ["72720.95000000", "0.00031000"], ["72720.37000000", "0.00000000"], ["72719.80000000", "0.00000000"], ["72718.69000000", "0.01375000"], ["72718.33000000", "0.00008000"], ["72718.32000000", "0.00000000"], ["72717.93000000", "0.00000000"], ["72716.52000000", "0.00000000"], ["72716.29000000", "0.00008000"], ["72716.28000000", "0.07192000"], ["72715.11000000", "0.00000000"], ["72714.17000000", "0.00041000"], ["72714.16000000", "0.00000000"], ["72714.15000000", "0.00165000"], ["72713.27000000", "0.00007000"], ["72712.59000000", "0.00000000"], ["72711.86000000", "0.16846000"], ["72711.85000000", "1.17008000"], ["72711.84000000", "3.40944000"], ["72711.83000000", "0.00000000"], ["72711.82000000", "0.00008000"], ["72711.81000000", "0.00000000"], ["72711.14000000", "0.00000000"], ["72711.13000000", "0.00000000"], ["72708.03000000", "0.08878000"], ["72708.01000000", "0.00000000"], ["72708.00000000", "0.02361000"], ["72707.53000000", "0.00000000"], ["72706.53000000", "0.00000000"], ["72705.54000000", "0.17801000"], ["72705.53000000", "0.15000000"], ["72705.37000000", "0.00000000"], ["72704.37000000", "0.17801000"], ["72704.36000000", "0.65949000"], ["72704.21000000", "0.00008000"], ["72704.20000000", "0.90461000"], ["72703.57000000", "0.00000000"], ["72702.61000000", "0.00020000"], ["72702.40000000", "0.00000000"], ["72701.51000000", "0.00000000"], ["72700.46000000", "0.00000000"], ["72700.01000000", "0.00055000"], ["72699.50000000", "0.02000000"], ["72694.21000000", "0.17801000"], ["72692.81000000", "0.00000000"], ["72691.89000000", "0.00193000"], ["72688.98000000", "0.00400000"], ["72687.74000000", "0.00000000"], ["72686.97000000", "0.00013000"], ["72685.81000000", "0.17801000"], ["72685.02000000", "0.17410000"], ["72683.01000000", "0.17801000"], ["72682.03000000", "0.17801000"], ["72678.65000000", "0.00000000"], ["72677.90000000", "0.00000000"], ["72672.13000000", "0.02534000"], ["72666.02000000", "0.00456000"], ["72658.45000000", "0.00000000"], ["72648.58000000", "0.01691000"], ["72622.66000000", "0.00000000"], ["72550.44000000", "0.09873000"], ["71933.12000000", "0.03460000"], ["65457.55000000", "0.00391000"]], "a": [["72730.62000000", "3.60330000"], ["72731.04000000", "0.00065000"], ["72731.05000000", "0.00000000"], ["72731.06000000", "0.00667000"], ["72731.65000000", "0.00000000"], ["72731.68000000", "0.03423000"], ["72731.75000000", "0.09927000"], ["72731.96000000", "0.00016000"], ["72732.01000000", "0.00008000"], ["72733.18000000", "0.00108000"], ["72733.40000000", "0.00000000"], ["72734.80000000", "0.00008000"], ["72734.82000000", "0.65949000"], ["72735.71000000", "0.00008000"], ["72736.00000000", "0.00000000"], ["72736.12000000", "0.00000000"], ["72736.21000000", "0.00008000"], ["72737.28000000", "0.00007000"], ["72738.50000000", "0.00008000"], ["72739.35000000", "0.00000000"], ["72739.99000000", "0.00008000"], ["72740.46000000", "0.00008000"], ["72740.80000000", "0.00000000"], ["72742.00000000", "0.03700000"], ["72742.37000000", "0.00007000"], ["72742.54000000", "0.08608000"], ["72743.21000000", "0.00008000"], ["72744.39000000", "0.00008000"], ["72744.40000000", "0.16578000"], ["72744.41000000", "0.00008000"], ["72745.13000000", "0.00008000"], ["72745.85000000", "0.00190000"], ["72745.99000000", "0.00008000"], ["72746.09000000", "0.18403000"], ["72746.10000000", "0.00000000"], ["72747.53000000", "0.00008000"], ["72748.93000000", "0.00008000"], ["72749.07000000", "1.45835000"], ["72749.10000000", "0.00000000"], ["72749.29000000", "0.27300000"], ["72751.00000000", "0.00100000"], ["72753.77000000", "0.17809000"], ["72753.82000000", "1.64265000"], ["72754.97000000", "0.00008000"], ["72754.98000000", "2.74944000"], ["72757.36000000", "0.00000000"], ["72757.71000000", "0.00008000"], ["72758.00000000", "0.02088000"], ["72758.12000000", "0.00008000"], ["72759.28000000", "0.00000000"], ["72759.72000000", "0.00686000"], ["72761.87000000", "0.00008000"], ["72762.37000000", "0.02645000"], ["72762.79000000", "0.00000000"], ["72767.57000000", "0.00000000"], ["72768.68000000", "0.00000000"], ["72770.19000000", "0.00000000"], ["72772.91000000", "0.00000000"], ["72774.99000000", "1.33931000"], ["72781.94000000", "1.46980000"], ["72782.19000000", "1.49768000"], ["72784.51000000", "0.18721000"], ["72803.48000000", "0.00686000"], ["72813.48000000", "0.00000000"], ["72823.43000000", "0.08401000"], ["72823.99000000", "0.00000000"], ["72826.08000000", "0.31422000"], ["72826.09000000", "0.00000000"], ["72828.03000000", "0.00000000"], ["72934.19000000", "0.01923000"], ["72976.66000000", "0.00000000"]], "_local_ts_utc": "2026-06-01T07:49:02.610611+00:00"}
{"e": "depthUpdate", "E": 1780300143814, "s": "BTCUSDT", "U": 94551774364, "u": 94551774450, "b": [["72730.61000000", "0.11330000"], ["72730.60000000", "0.00080000"], ["72728.41000000", "0.00000000"], ["72727.00000000", "1.25062000"], ["72726.16000000", "0.01045000"], ["72726.02000000", "0.00000000"], ["72723.14000000", "0.00000000"], ["72721.93000000", "0.00010000"], ["72721.10000000", "0.00165000"], ["72720.95000000", "0.00000000"], ["72718.69000000", "0.04065000"], ["72717.85000000", "0.00000000"], ["72712.22000000", "0.18092000"], ["72708.03000000", "0.13057000"], ["72704.26000000", "0.00120000"], ["72702.40000000", "0.00000000"], ["72698.41000000", "0.17655000"], ["72678.02000000", "0.65956000"], ["72642.88000000", "0.00110000"], ["72550.06000000", "0.00115000"], ["71787.36000000", "0.03123000"], ["71422.96000000", "0.01396000"], ["71058.56000000", "0.01053000"], ["65457.55000000", "0.00425000"]], "a": [["72731.66000000", "0.71259000"], ["72731.67000000", "0.65949000"], ["72731.68000000", "0.03423000"], ["72731.75000000", "0.00016000"], ["72731.96000000", "0.00000000"], ["72732.15000000", "0.08370000"], ["72732.40000000", "0.00016000"], ["72732.42000000", "0.00000000"], ["72748.93000000", "0.00044000"], ["72748.94000000", "0.45885000"], ["72748.95000000", "0.17926000"], ["72754.00000000", "0.00280000"], ["72755.92000000", "0.00000000"], ["72759.72000000", "0.00000000"], ["72826.75000000", "0.00000000"], ["72870.51000000", "0.00000000"], ["73104.38000000", "0.00000000"]], "_local_ts_utc": "2026-06-01T07:49:02.710595+00:00"}
{"e": "depthUpdate", "E": 1780300143914, "s": "BTCUSDT", "U": 94551774451, "u": 94551774560, "b": [["72730.61000000", "0.12102000"], ["72730.60000000", "0.00094000"], ["72730.59000000", "0.00014000"], ["72727.00000000", "1.25062000"], ["72724.32000000", "0.00031000"], ["72723.83000000", "0.00031000"], ["72723.60000000", "0.00000000"], ["72722.54000000", "0.00216000"], ["72722.01000000", "0.04747000"], ["72718.69000000", "0.07041000"], ["72716.61000000", "0.17801000"], ["72716.37000000", "0.15323000"], ["72716.28000000", "0.16013000"], ["72715.21000000", "0.17801000"], ["72713.81000000", "0.16381000"], ["72712.22000000", "0.00000000"], ["72708.22000000", "0.24990000"], ["72708.21000000", "0.17801000"], ["72708.03000000", "0.00000000"], ["72706.81000000", "0.17801000"], ["72704.35000000", "0.00010000"], ["72702.61000000", "0.17821000"], ["72697.25000000", "0.00200000"], ["72697.18000000", "0.00000000"], ["72696.35000000", "0.63919000"], ["72690.80000000", "0.00400000"], ["72688.98000000", "0.00000000"], ["72673.13000000", "1.21330000"], ["72605.39000000", "0.08263000"], ["72531.55000000", "0.00000000"], ["72520.94000000", "0.00822000"], ["72025.12000000", "0.00346000"], ["65457.55000000", "0.00425000"]], "a": [["72730.62000000", "3.63683000"], ["72731.06000000", "0.00667000"], ["72731.66000000", "0.71275000"], ["72731.67000000", "0.65965000"], ["72731.68000000", "0.03423000"], ["72731.75000000", "0.00000000"], ["72732.02000000", "0.17825000"], ["72732.15000000", "0.08386000"], ["72732.39000000", "0.17817000"], ["72732.40000000", "0.00000000"], ["72732.41000000", "0.10442000"], ["72745.00000000", "0.01289000"], ["72751.62000000", "0.00000000"], ["72753.02000000", "0.00000000"], ["72753.77000000", "0.00008000"], ["72755.37000000", "0.00000000"], ["72755.44000000", "0.00200000"], ["72877.33000000", "0.10000000"], ["72899.15000000", "0.10000000"]], "_local_ts_utc": "2026-06-01T07:49:02.810257+00:00"}
{"e": "depthUpdate", "E": 1780300144014, "s": "BTCUSDT", "U": 94551774561, "u": 94551774608, "b": [["72730.61000000", "1.39209000"], ["72730.60000000", "0.00102000"], ["72729.80000000", "0.00016000"], ["72725.33000000", "0.00031000"], ["72724.83000000", "0.00031000"], ["72724.32000000", "0.00000000"], ["72723.83000000", "0.00000000"], ["72718.69000000", "0.11455000"], ["72718.42000000", "0.05942000"], ["72718.01000000", "0.17801000"], ["72708.35000000", "0.01376000"], ["72706.82000000", "0.77213000"], ["72701.36000000", "0.08254000"], ["72696.42000000", "0.51398000"], ["72696.26000000", "0.00400000"], ["72690.80000000", "0.00000000"], ["72681.57000000", "0.00343000"], ["72673.29000000", "0.53987000"], ["72669.57000000", "0.02000000"], ["72608.01000000", "0.00137000"], ["71933.12000000", "0.02768000"], ["71787.36000000", "0.02776000"], ["65457.55000000", "0.00425000"], ["58195.00000000", "0.01379000"], ["58184.49000000", "0.00034000"]], "a": [["72730.62000000", "3.62483000"], ["72742.15000000", "0.09400000"], ["72746.02000000", "0.00000000"], ["72746.09000000", "0.01289000"], ["72786.97000000", "0.00189000"], ["72797.73000000", "0.08242000"], ["72859.90000000", "0.00075000"]], "_local_ts_utc": "2026-06-01T07:49:02.911461+00:00"}
{"e": "depthUpdate", "E": 1780300144114, "s": "BTCUSDT", "U": 94551774609, "u": 94551774771, "b": [["72730.61000000", "1.38433000"], ["72730.60000000", "0.00102000"], ["72730.00000000", "0.07433000"], ["72729.80000000", "0.00000000"], ["72729.09000000", "0.00000000"], ["72729.08000000", "0.00016000"], ["72729.00000000", "0.01392000"], ["72728.18000000", "0.00031000"], ["72728.14000000", "0.00000000"], ["72728.05000000", "0.00028000"], ["72727.94000000", "0.00000000"], ["72727.58000000", "0.00000000"], ["72727.26000000", "0.00016000"], ["72727.25000000", "0.02352000"], ["72727.19000000", "0.00000000"], ["72727.02000000", "0.00085000"], ["72727.01000000", "0.57405000"], ["72726.16000000", "0.00000000"], ["72725.90000000", "0.00030000"], ["72725.33000000", "0.00000000"], ["72724.83000000", "0.00000000"], ["72723.94000000", "0.00764000"], ["72722.22000000", "0.17719000"], ["72722.21000000", "0.00000000"], ["72722.07000000", "0.05942000"], ["72722.01000000", "0.00008000"], ["72721.74000000", "0.00400000"], ["72720.81000000", "0.17801000"], ["72720.63000000", "0.00000000"], ["72720.30000000", "0.00745000"], ["72719.41000000", "0.17801000"], ["72718.69000000", "0.19530000"], ["72718.42000000", "0.00000000"], ["72716.66000000", "0.00815000"], ["72716.37000000", "0.00000000"], ["72716.28000000", "0.35307000"], ["72714.75000000", "0.65949000"], ["72713.02000000", "0.00744000"], ["72711.26000000", "0.00000000"], ["72709.61000000", "0.00000000"], ["72708.22000000", "0.44843000"], ["72708.21000000", "0.00000000"], ["72706.81000000", "0.00000000"], ["72701.51000000", "0.01371000"], ["72694.21000000", "0.00000000"], ["72693.77000000", "0.00000000"], ["72692.62000000", "0.00000000"], ["72687.26000000", "0.02689000"], ["72685.81000000", "0.00000000"], ["72685.02000000", "0.00000000"], ["72667.51000000", "0.02000000"], ["65457.55000000", "0.00425000"], ["65457.00000000", "0.00000000"]], "a": [["72731.06000000", "0.01411000"], ["72731.65000000", "0.65949000"], ["72731.66000000", "0.50103000"], ["72731.67000000", "0.00016000"], ["72731.68000000", "0.00016000"], ["72732.15000000", "0.00016000"], ["72733.72000000", "0.04834000"], ["72741.90000000", "0.00000000"], ["72741.98000000", "0.17801000"], ["72741.99000000", "1.41999000"], ["72742.55000000", "0.00000000"], ["72743.21000000", "2.74995000"], ["72743.22000000", "0.00000000"], ["72744.30000000", "0.06600000"], ["72744.40000000", "0.00000000"], ["72744.41000000", "0.00008000"], ["72745.84000000", "0.00400000"], ["72745.99000000", "0.00008000"], ["72746.00000000", "0.37425000"], ["72746.93000000", "0.00000000"], ["72746.94000000", "0.68838000"], ["72747.19000000", "0.00000000"], ["72747.37000000", "0.00000000"], ["72747.54000000", "0.00000000"], ["72748.82000000", "0.16569000"], ["72748.93000000", "0.17845000"], ["72748.94000000", "0.45903000"], ["72748.95000000", "0.00000000"], ["72754.00000000", "0.00080000"], ["72758.13000000", "1.36438000"], ["72759.72000000", "0.01371000"], ["72770.62000000", "0.26000000"], ["72788.25000000", "0.00000000"], ["72807.41000000", "0.00000000"], ["72827.52000000", "0.00000000"], ["72838.16000000", "0.00000000"], ["72848.44000000", "0.53423000"], ["72899.88000000", "4.12040000"]], "_local_ts_utc": "2026-06-01T07:49:03.010272+00:00"}
{"e": "depthUpdate", "E": 1780300144214, "s": "BTCUSDT", "U": 94551774772, "u": 94551774836, "b": [["72730.61000000", "1.20472000"], ["72729.15000000", "0.00600000"], ["72729.08000000", "0.00000000"], ["72728.18000000", "0.00000000"], ["72727.27000000", "0.00555000"], ["72727.25000000", "0.02368000"], ["72727.17000000", "0.00758000"], ["72727.01000000", "0.57421000"], ["72727.00000000", "1.25046000"], ["72726.03000000", "0.00031000"], ["72722.22000000", "0.12212000"], ["72025.12000000", "0.00692000"], ["71787.36000000", "0.02429000"], ["65457.55000000", "0.00425000"], ["58184.49000000", "0.00000000"]], "a": [["72730.62000000", "3.62469000"], ["72731.06000000", "0.00667000"], ["72731.09000000", "0.00771000"], ["72731.65000000", "0.65965000"], ["72731.66000000", "0.50103000"], ["72731.67000000", "0.00000000"], ["72731.68000000", "0.00000000"], ["72732.02000000", "0.17825000"], ["72732.15000000", "0.00000000"], ["72732.41000000", "0.10458000"], ["72732.61000000", "0.67832000"], ["72826.20000000", "0.00000000"], ["73618.20000000", "0.00000000"], ["77854.72000000", "0.00000000"]], "_local_ts_utc": "2026-06-01T07:49:03.110389+00:00"}
{"e": "depthUpdate", "E": 1780300144314, "s": "BTCUSDT", "U": 94551774837, "u": 94551774896, "b": [["72730.61000000", "0.74320000"], ["72730.60000000", "0.00094000"], ["72728.05000000", "0.00000000"], ["72727.25000000", "0.02368000"], ["72727.17000000", "0.00774000"], ["72727.02000000", "0.00077000"], ["72727.01000000", "0.00032000"], ["72726.17000000", "0.00000000"], ["72726.03000000", "0.00000000"], ["72724.67000000", "0.00031000"], ["72723.52000000", "0.00031000"], ["72722.22000000", "0.06896000"], ["72720.81000000", "0.00000000"], ["72719.41000000", "0.00000000"], ["72718.69000000", "0.13442000"], ["72714.19000000", "0.19239000"], ["72698.41000000", "0.00009000"], ["72685.02000000", "0.17801000"], ["72666.69000000", "0.18721000"], ["72025.12000000", "0.01038000"], ["71785.11000000", "0.00347000"], ["65457.55000000", "0.00425000"]], "a": [["72730.62000000", "3.62448000"], ["72731.06000000", "0.00667000"], ["72731.09000000", "0.00787000"], ["72731.97000000", "0.03407000"], ["72732.61000000", "0.67816000"], ["72744.41000000", "0.17809000"], ["72745.99000000", "0.17809000"], ["72746.93000000", "0.17801000"], ["72748.82000000", "0.16623000"], ["72748.93000000", "0.17809000"], ["72748.94000000", "0.45885000"]], "_local_ts_utc": "2026-06-01T07:49:03.210291+00:00"}
{"e": "depthUpdate", "E": 1780300144414, "s": "BTCUSDT", "U": 94551774897, "u": 94551774935, "b": [["72730.61000000", "0.74338000"], ["72730.60000000", "0.00102000"], ["72727.17000000", "0.00774000"], ["72727.01000000", "0.00016000"], ["72727.00000000", "1.25062000"], ["72725.69000000", "0.00031000"], ["72725.18000000", "0.00031000"], ["72724.67000000", "0.00000000"], ["72723.52000000", "0.00000000"], ["72713.69000000", "0.01376000"], ["72710.33000000", "0.02000000"], ["72700.88000000", "0.00349000"], ["72673.88000000", "0.02000000"], ["66912.16000000", "0.00015000"], ["65457.55000000", "0.00425000"]], "a": [["72731.66000000", "0.50103000"], ["72731.97000000", "0.03423000"], ["72732.41000000", "0.10442000"], ["72743.94000000", "0.07400000"], ["72744.29000000", "0.68838000"], ["72746.94000000", "0.00000000"], ["72756.62000000", "0.00200000"], ["72758.13000000", "1.36238000"], ["72826.66000000", "0.00028000"], ["72891.88000000", "0.10000000"], ["73385.19000000", "0.00010000"]], "_local_ts_utc": "2026-06-01T07:49:03.312788+00:00"}
{"e": "depthUpdate", "E": 1780300144514, "s": "BTCUSDT", "U": 94551774936, "u": 94551774993, "b": [["72730.61000000", "0.74360000"], ["72727.33000000", "0.00031000"], ["72727.16000000", "0.00031000"], ["72725.92000000", "0.00000000"], ["72725.69000000", "0.00000000"], ["72725.18000000", "0.00000000"], ["72722.22000000", "0.11335000"], ["72720.81000000", "0.17801000"], ["72719.42000000", "0.25282000"], ["72719.41000000", "0.17801000"], ["72718.69000000", "0.00000000"], ["72718.07000000", "0.20239000"], ["72714.19000000", "0.00000000"], ["72708.23000000", "0.17801000"], ["72706.83000000", "0.17187000"], ["72698.95000000", "0.00200000"], ["72698.41000000", "0.17810000"], ["72697.35000000", "0.00000000"], ["72697.25000000", "0.00000000"], ["72694.21000000", "0.17801000"], ["72693.77000000", "0.17801000"], ["72673.44000000", "0.00000000"], ["72664.53000000", "0.04710000"], ["71933.12000000", "0.02422000"], ["71785.11000000", "0.00694000"], ["65457.55000000", "0.00425000"], ["58184.49000000", "0.00034000"]], "a": [["72744.41000000", "0.00008000"], ["72745.22000000", "0.04600000"], ["72745.99000000", "0.00008000"], ["72746.00000000", "0.11449000"], ["72746.93000000", "0.00000000"], ["72748.82000000", "0.00054000"], ["72748.93000000", "0.00026000"], ["72755.44000000", "0.00000000"], ["72757.15000000", "0.00200000"]], "_local_ts_utc": "2026-06-01T07:49:03.410383+00:00"}
{"e": "depthUpdate", "E": 1780300144614, "s": "BTCUSDT", "U": 94551774994, "u": 94551775208, "b": [["72730.61000000", "2.57744000"], ["72730.60000000", "0.00118000"], ["72730.02000000", "0.00016000"], ["72730.01000000", "0.00024000"], ["72729.46000000", "0.00031000"], ["72728.99000000", "0.01351000"], ["72728.82000000", "0.00031000"], ["72728.10000000", "0.00016000"], ["72728.09000000", "0.02982000"], ["72727.82000000", "0.00000000"], ["72727.81000000", "0.00000000"], ["72727.33000000", "0.00000000"], ["72727.26000000", "0.00000000"], ["72727.25000000", "0.00016000"], ["72727.16000000", "0.00000000"], ["72727.02000000", "0.92002000"], ["72727.01000000", "0.00008000"], ["72727.00000000", "1.25046000"], ["72725.01000000", "0.00000000"], ["72724.97000000", "0.05942000"], ["72723.61000000", "0.00000000"], ["72723.56000000", "0.00400000"], ["72722.28000000", "0.15715000"], ["72722.27000000", "0.00000000"], ["72722.23000000", "0.00000000"], ["72722.22000000", "0.00041000"], ["72722.07000000", "0.00000000"], ["72719.42000000", "0.41736000"], ["72718.08000000", "0.65949000"], ["72718.07000000", "0.00000000"], ["72716.59000000", "0.00000000"], ["72710.14000000", "0.01376000"], ["72709.61000000", "0.00000000"], ["72709.11000000", "0.00000000"], ["72708.35000000", "0.00000000"], ["72705.41000000", "0.02000000"], ["72702.61000000", "0.00020000"], ["72699.50000000", "0.00000000"], ["72698.41000000", "0.00009000"], ["72694.44000000", "0.00000000"], ["72694.21000000", "0.00000000"], ["72693.77000000", "0.00000000"], ["72692.55000000", "0.00000000"], ["72685.81000000", "0.00000000"], ["72685.58000000", "0.65904000"], ["72685.23000000", "1.36374000"], ["72685.02000000", "0.00000000"], ["72683.13000000", "0.49592000"], ["72683.01000000", "0.00000000"], ["72682.03000000", "0.00000000"], ["72656.83000000", "0.00000000"], ["72616.15000000", "0.06023000"], ["72578.50000000", "0.00137000"], ["72433.20000000", "0.00034000"], ["72430.93000000", "0.00000000"], ["72025.12000000", "0.01730000"], ["71933.12000000", "0.02076000"], ["65457.55000000", "0.00425000"], ["58184.49000000", "0.00000000"]], "a": [["72730.62000000", "3.18120000"], ["72731.04000000", "0.00081000"], ["72731.05000000", "0.08000000"], ["72731.09000000", "0.00016000"], ["72731.64000000", "0.74476000"], ["72731.65000000", "0.65981000"], ["72731.66000000", "0.00016000"], ["72731.97000000", "0.00016000"], ["72732.01000000", "0.00008000"], ["72732.02000000", "0.00024000"], ["72732.38000000", "0.00000000"], ["72732.39000000", "0.00016000"], ["72732.40000000", "0.00016000"], ["72732.60000000", "0.00016000"], ["72733.72000000", "0.00000000"], ["72734.80000000", "0.17809000"], ["72734.81000000", "0.89452000"], ["72735.08000000", "0.04278000"], ["72735.15000000", "0.00007000"], ["72736.22000000", "0.00000000"], ["72737.53000000", "0.17801000"], ["72738.01000000", "0.17801000"], ["72740.42000000", "0.17801000"], ["72741.82000000", "0.17801000"], ["72741.98000000", "0.17801000"], ["72744.29000000", "0.00000000"], ["72746.00000000", "0.12449000"], ["72746.94000000", "0.00000000"], ["72748.00000000", "0.01080000"], ["72749.28000000", "0.68834000"], ["72750.00000000", "0.01088000"], ["72752.00000000", "0.01080000"], ["72752.47000000", "0.00007000"], ["72753.42000000", "0.00000000"], ["72754.00000000", "0.01080000"], ["72770.62000000", "0.00000000"], ["72786.96000000", "0.00189000"], ["72786.97000000", "0.00000000"], ["72792.04000000", "0.67049000"], ["72859.89000000", "0.00075000"], ["72859.90000000", "0.00000000"], ["72913.69000000", "0.10000000"]], "_local_ts_utc": "2026-06-01T07:49:03.510146+00:00"}
{"e": "depthUpdate", "E": 1780300144714, "s": "BTCUSDT", "U": 94551775209, "u": 94551775372, "b": [["72730.61000000", "1.73978000"], ["72730.60000000", "0.00102000"], ["72730.02000000", "0.00000000"], ["72729.46000000", "0.00000000"], ["72729.00000000", "0.01408000"], ["72728.99000000", "0.01367000"], ["72728.82000000", "0.00000000"], ["72728.09000000", "0.02970000"], ["72727.93000000", "0.00031000"], ["72727.87000000", "0.00031000"], ["72727.27000000", "0.00555000"], ["72727.25000000", "0.00000000"], ["72727.17000000", "0.00774000"], ["72727.02000000", "0.59027000"], ["72725.38000000", "0.00400000"], ["72725.22000000", "0.00000000"], ["72724.98000000", "0.00008000"], ["72722.28000000", "0.10402000"], ["72722.01000000", "0.00000000"], ["72720.82000000", "0.00016000"], ["72720.01000000", "0.00000000"], ["72719.43000000", "0.00008000"], ["72718.33000000", "0.00000000"], ["72718.09000000", "0.00008000"], ["72714.76000000", "0.00008000"], ["72714.17000000", "0.00033000"], ["72713.27000000", "0.00007000"], ["72711.85000000", "1.17016000"], ["72711.84000000", "3.40936000"], ["72711.82000000", "0.00000000"], ["72708.23000000", "0.17809000"], ["72704.21000000", "0.00000000"], ["72698.41000000", "0.17810000"], ["72696.26000000", "0.00000000"], ["72694.21000000", "0.17547000"], ["72693.77000000", "0.17801000"], ["72691.16000000", "0.02654000"], ["72687.26000000", "0.00000000"], ["72685.59000000", "0.17801000"], ["72605.39000000", "0.00000000"], ["71787.36000000", "0.02082000"], ["71785.11000000", "0.01041000"], ["71639.65000000", "0.00348000"], ["71276.00000000", "0.00350000"], ["70548.69000000", "0.00353000"], ["65457.55000000", "0.00425000"]], "a": [["72730.62000000", "3.23925000"], ["72731.05000000", "0.08016000"], ["72731.06000000", "0.00667000"], ["72731.09000000", "0.00000000"], ["72731.63000000", "0.00024000"], ["72731.64000000", "0.74492000"], ["72731.65000000", "0.65965000"], ["72731.66000000", "0.00000000"], ["72731.97000000", "0.00000000"], ["72732.01000000", "0.00000000"], ["72732.02000000", "0.00008000"], ["72732.32000000", "0.04131000"], ["72732.39000000", "0.00000000"], ["72732.40000000", "0.00016000"], ["72732.41000000", "0.10458000"], ["72732.59000000", "0.00008000"], ["72732.60000000", "0.17809000"], ["72732.61000000", "0.67832000"], ["72733.19000000", "0.07557000"], ["72734.81000000", "0.89460000"], ["72736.21000000", "0.00000000"], ["72737.52000000", "0.00008000"], ["72742.37000000", "0.00007000"], ["72742.54000000", "0.08600000"], ["72742.55000000", "0.00008000"], ["72743.20000000", "0.00008000"], ["72743.21000000", "2.74987000"], ["72743.93000000", "0.00008000"], ["72744.39000000", "0.00000000"], ["72744.87000000", "0.00008000"], ["72745.84000000", "0.00000000"], ["72747.21000000", "0.00400000"], ["72747.53000000", "0.00000000"], ["72748.82000000", "0.00000000"], ["72748.94000000", "0.45939000"], ["72752.37000000", "0.00200000"], ["72753.77000000", "0.00000000"], ["72756.62000000", "0.00000000"], ["72758.00000000", "0.02080000"], ["72759.21000000", "0.00200000"], ["72765.51000000", "0.75584000"], ["72765.64000000", "0.00000000"], ["72806.84000000", "0.00000000"]], "_local_ts_utc": "2026-06-01T07:49:03.610690+00:00"}
{"e": "depthUpdate", "E": 1780300144814, "s": "BTCUSDT", "U": 94551775373, "u": 94551775442, "b": [["72730.61000000", "1.73413000"], ["72728.19000000", "0.00031000"], ["72727.93000000", "0.00000000"], ["72727.87000000", "0.00000000"], ["72727.36000000", "0.00031000"], ["72726.63000000", "0.00031000"], ["72725.89000000", "0.00000000"], ["72722.98000000", "0.00017000"], ["72719.60000000", "0.01376000"], ["72708.93000000", "0.01376000"], ["72700.99000000", "0.00200000"], ["72698.95000000", "0.00000000"], ["72694.21000000", "0.00000000"], ["72693.77000000", "0.17801000"], ["72685.59000000", "0.00000000"], ["69500.00000000", "21.49982000"], ["65457.55000000", "0.00408000"]], "a": [["72730.62000000", "3.24048000"], ["72731.04000000", "0.00081000"], ["72731.63000000", "0.00024000"], ["72731.64000000", "0.74492000"], ["72732.40000000", "0.00016000"], ["72732.41000000", "0.10458000"], ["72732.59000000", "0.00008000"], ["72732.60000000", "0.17825000"], ["72733.19000000", "0.07541000"], ["72736.12000000", "0.00688000"], ["72736.22000000", "0.17801000"], ["72736.99000000", "0.00688000"], ["72748.82000000", "0.00072000"], ["72748.93000000", "0.00008000"], ["72748.94000000", "0.45885000"], ["72757.15000000", "0.00000000"], ["72759.18000000", "0.00200000"], ["72771.23000000", "0.00343000"], ["72784.74000000", "0.00000000"], ["72792.04000000", "0.67599000"], ["72793.99000000", "0.00343000"], ["72797.73000000", "0.00000000"], ["72807.31000000", "0.00000000"], ["72843.99000000", "0.00137000"], ["72866.66000000", "0.00137000"], ["72885.55000000", "0.00000000"], ["72907.96000000", "0.00000000"]], "_local_ts_utc": "2026-06-01T07:49:03.710229+00:00"}
{"e": "depthUpdate", "E": 1780300144914, "s": "BTCUSDT", "U": 94551775443, "u": 94551775500, "b": [["72730.61000000", "1.72649000"], ["72729.52000000", "0.00000000"], ["72729.43000000", "0.00000000"], ["72728.19000000", "0.00000000"], ["72727.36000000", "0.00000000"], ["72726.63000000", "0.00000000"], ["72722.28000000", "0.15115000"], ["72720.27000000", "0.20254000"], ["72702.61000000", "0.16801000"], ["72698.41000000", "0.00009000"], ["72660.25000000", "0.26000000"], ["71276.00000000", "0.00700000"], ["65457.55000000", "0.00408000"]], "a": [["72730.62000000", "3.23361000"], ["72731.63000000", "0.00008000"], ["72731.64000000", "0.74476000"], ["72732.40000000", "0.00000000"], ["72732.59000000", "0.00000000"], ["72738.01000000", "0.16050000"], ["72740.42000000", "0.17801000"], ["72741.98000000", "0.17046000"], ["72748.00000000", "0.02080000"], ["72748.82000000", "0.00000000"], ["72748.93000000", "0.00080000"], ["72750.00000000", "0.02088000"], ["72752.00000000", "0.02080000"], ["72754.00000000", "0.02080000"], ["72756.00000000", "0.02080000"], ["86422.88000000", "0.01891000"]], "_local_ts_utc": "2026-06-01T07:49:03.810313+00:00"}
{"e": "depthUpdate", "E": 1780300145014, "s": "BTCUSDT", "U": 94551775501, "u": 94551775565, "b": [["72730.61000000", "1.75201000"], ["72729.41000000", "0.00039000"], ["72729.28000000", "0.00000000"], ["72727.02000000", "0.00077000"], ["72727.01000000", "0.57310000"], ["72726.86000000", "0.00031000"], ["72724.97000000", "0.00000000"], ["72722.98000000", "0.00000000"], ["72722.29000000", "0.00018000"], ["72722.28000000", "0.10402000"], ["72720.27000000", "0.00000000"], ["72708.23000000", "0.00008000"], ["72702.61000000", "0.00020000"], ["71639.65000000", "0.00696000"], ["70912.34000000", "0.00351000"], ["66912.16000000", "0.00000000"], ["65457.55000000", "0.00425000"], ["58184.49000000", "0.00034000"]], "a": [["72730.62000000", "3.18069000"], ["72730.63000000", "0.00118000"], ["72731.04000000", "0.00065000"], ["72731.63000000", "0.00008000"], ["72731.64000000", "0.74476000"], ["72732.40000000", "0.00000000"], ["72732.59000000", "0.00000000"], ["72735.70000000", "0.00688000"], ["72736.11000000", "0.00688000"], ["72736.12000000", "0.00000000"], ["72736.99000000", "0.00000000"], ["72748.94000000", "0.45903000"], ["72752.26000000", "0.00228000"], ["72752.37000000", "0.00000000"], ["72758.40000000", "0.00199000"], ["72759.21000000", "0.00000000"], ["72759.22000000", "0.00200000"], ["86422.88000000", "0.03782000"]], "_local_ts_utc": "2026-06-01T07:49:03.910762+00:00"}
{"e": "depthUpdate", "E": 1780300145114, "s": "BTCUSDT", "U": 94551775566, "u": 94551775736, "b": [["72730.61000000", "0.08449000"], ["72730.60000000", "0.00102000"], ["72728.10000000", "0.00000000"], ["72728.09000000", "0.00016000"], ["72727.17000000", "0.00774000"], ["72727.08000000", "0.00008000"], ["72727.07000000", "0.00000000"], ["72727.01000000", "0.00008000"], ["72726.86000000", "0.00000000"], ["72726.20000000", "0.00992000"], ["72725.38000000", "0.00000000"], ["72725.27000000", "0.00000000"], ["72723.92000000", "0.00031000"], ["72723.52000000", "0.00000000"], ["72722.37000000", "0.00000000"], ["72722.29000000", "0.00000000"], ["72722.28000000", "0.00000000"], ["72721.81000000", "0.00000000"], ["72720.81000000", "0.00000000"], ["72720.49000000", "0.00000000"], ["72719.60000000", "0.00000000"], ["72719.55000000", "0.00000000"], ["72719.42000000", "0.00000000"], ["72719.41000000", "0.00000000"], ["72718.25000000", "0.00018000"], ["72718.09000000", "0.65957000"], ["72718.08000000", "0.00000000"], ["72718.01000000", "0.00000000"], ["72716.61000000", "0.00000000"], ["72716.28000000", "0.00400000"], ["72715.21000000", "0.00000000"], ["72713.81000000", "0.00000000"], ["72713.69000000", "0.00000000"], ["72710.14000000", "0.00000000"], ["72709.13000000", "0.00000000"], ["72708.22000000", "0.24990000"], ["72706.83000000", "0.00000000"], ["72705.54000000", "0.00000000"], ["72705.53000000", "0.01000000"], ["72704.38000000", "0.17801000"], ["72704.37000000", "0.00000000"], ["72703.53000000", "0.14000000"], ["72702.61000000", "0.16547000"], ["72701.51000000", "0.00000000"], ["72700.99000000", "0.00000000"], ["72700.70000000", "0.00200000"], ["72698.41000000", "0.16450000"], ["72692.62000000", "0.00400000"], ["72685.58000000", "0.28997000"], ["72685.23000000", "0.00000000"], ["72683.14000000", "0.17801000"], ["72682.03000000", "0.17801000"], ["72681.57000000", "0.00000000"], ["72608.01000000", "0.00000000"], ["72433.86000000", "4.14710000"], ["72025.12000000", "0.02076000"], ["71785.11000000", "0.01388000"], ["70912.34000000", "0.00702000"], ["65457.55000000", "0.00425000"]], "a": [["72730.62000000", "3.13518000"], ["72730.63000000", "0.00374000"], ["72731.32000000", "0.00000000"], ["72732.01000000", "0.03407000"], ["72732.22000000", "0.08552000"], ["72732.30000000", "0.00028000"], ["72733.50000000", "0.00000000"], ["72734.00000000", "0.00000000"], ["72735.08000000", "0.00000000"], ["72735.30000000", "0.00000000"], ["72735.70000000", "0.00000000"], ["72736.11000000", "0.00000000"], ["72742.46000000", "0.68839000"], ["72744.41000000", "0.17809000"], ["72745.99000000", "0.17809000"], ["72746.00000000", "0.31085000"], ["72746.08000000", "0.00000000"], ["72747.42000000", "0.17801000"], ["72748.82000000", "0.17801000"], ["72748.93000000", "0.17013000"], ["72749.28000000", "0.00000000"], ["72750.00000000", "0.02288000"], ["72752.00000000", "0.02280000"], ["72754.00000000", "0.02280000"], ["72758.88000000", "0.00200000"], ["72759.18000000", "0.00000000"], ["72786.96000000", "0.00000000"], ["72859.89000000", "0.00000000"]], "_local_ts_utc": "2026-06-01T07:49:04.010276+00:00"}
{"e": "depthUpdate", "E": 1780300145214, "s": "BTCUSDT", "U": 94551775737, "u": 94551775900, "b": [["72730.61000000", "0.11725000"], ["72730.60000000", "0.00102000"], ["72728.99000000", "0.01367000"], ["72728.09000000", "0.00000000"], ["72727.17000000", "0.00774000"], ["72727.08000000", "0.00000000"], ["72727.01000000", "0.00016000"], ["72724.43000000", "0.00031000"], ["72723.92000000", "0.00000000"], ["72723.56000000", "0.00000000"], ["72722.58000000", "0.00031000"], ["72722.36000000", "0.00000000"], ["72721.88000000", "0.00000000"], ["72719.54000000", "0.00000000"], ["72718.11000000", "0.17801000"], ["72718.10000000", "0.66349000"], ["72718.09000000", "0.00008000"], ["72716.61000000", "0.17801000"], ["72715.21000000", "0.17801000"], ["72714.76000000", "0.30752000"], ["72713.81000000", "0.17801000"], ["72711.68000000", "0.15563000"], ["72708.93000000", "0.00000000"], ["72708.23000000", "0.16528000"], ["72708.22000000", "0.15908000"], ["72706.83000000", "0.17801000"], ["72706.82000000", "0.00000000"], ["72706.05000000", "0.01376000"], ["72705.41000000", "0.17801000"], ["72702.00000000", "0.04280000"], ["72698.41000000", "0.17810000"], ["72694.44000000", "0.00400000"], ["72694.21000000", "0.17801000"], ["72685.02000000", "0.16893000"], ["72683.13000000", "0.00000000"], ["72681.58000000", "0.00343000"], ["72661.57000000", "0.39306000"], ["72658.45000000", "0.49609000"], ["72608.02000000", "0.00137000"], ["72593.93000000", "0.00007000"], ["72550.44000000", "0.00000000"], ["72549.45000000", "0.09872000"], ["72517.88000000", "0.00000000"], ["65457.55000000", "0.00425000"], ["58184.49000000", "0.00000000"]], "a": [["72730.62000000", "3.18638000"], ["72731.65000000", "0.65965000"], ["72732.01000000", "0.03423000"], ["72732.22000000", "0.08568000"], ["72732.30000000", "0.00000000"], ["72732.60000000", "0.17809000"], ["72732.61000000", "0.67816000"], ["72748.82000000", "0.17891000"], ["72748.93000000", "0.16941000"], ["72748.94000000", "0.00000000"], ["72752.26000000", "0.00028000"], ["72753.02000000", "0.00000000"], ["72753.77000000", "0.00000000"], ["72755.80000000", "0.49542000"], ["72756.00000000", "0.02280000"], ["72758.00000000", "0.02280000"], ["72759.72000000", "0.00686000"], ["72782.90000000", "0.00000000"], ["72786.95000000", "0.00189000"], ["72792.04000000", "0.86320000"], ["72859.88000000", "0.00075000"], ["80298.72000000", "0.02508000"]], "_local_ts_utc": "2026-06-01T07:49:04.110379+00:00"}
{"e": "depthUpdate", "E": 1780300145314, "s": "BTCUSDT", "U": 94551775901, "u": 94551776046, "b": [["72730.61000000", "0.04514000"], ["72730.60000000", "0.00102000"], ["72727.00000000", "1.25062000"], ["72726.31000000", "0.00012000"], ["72726.20000000", "0.00000000"], ["72725.90000000", "0.00762000"], ["72724.43000000", "0.00000000"], ["72723.68000000", "0.00031000"], ["72722.58000000", "0.00000000"], ["72720.94000000", "0.00031000"], ["72718.58000000", "0.06918000"], ["72718.57000000", "0.05942000"], ["72718.25000000", "0.00000000"], ["72718.12000000", "0.00000000"], ["72718.11000000", "0.00000000"], ["72718.10000000", "0.00400000"], ["72717.86000000", "0.00007000"], ["72716.61000000", "0.00000000"], ["72716.08000000", "0.00018000"], ["72715.21000000", "0.00000000"], ["72714.77000000", "0.05747000"], ["72714.76000000", "0.00008000"], ["72714.75000000", "0.00000000"], ["72713.81000000", "0.00000000"], ["72711.89000000", "0.17801000"], ["72711.88000000", "1.21552000"], ["72711.87000000", "3.40936000"], ["72711.86000000", "0.00000000"], ["72711.85000000", "0.00008000"], ["72711.84000000", "0.00000000"], ["72708.23000000", "0.00008000"], ["72708.22000000", "0.10594000"], ["72706.83000000", "0.00000000"], ["72703.49000000", "0.00000000"], ["72702.61000000", "0.00020000"], ["72701.36000000", "0.00000000"], ["72698.41000000", "0.17810000"], ["72696.42000000", "0.33556000"], ["72696.35000000", "0.00000000"], ["72694.21000000", "0.17801000"], ["72693.77000000", "0.17801000"], ["72691.16000000", "0.00000000"], ["72685.81000000", "0.17801000"], ["72685.02000000", "0.17801000"], ["72681.59000000", "0.00343000"], ["72681.58000000", "0.00000000"], ["72674.40000000", "0.02816000"], ["72673.29000000", "0.19691000"], ["72673.13000000", "0.00000000"], ["72663.31000000", "0.36892000"], ["72662.03000000", "0.18446000"], ["72650.61000000", "0.00087000"], ["72637.57000000", "0.00000000"], ["72622.66000000", "0.00000000"], ["72608.03000000", "0.00137000"], ["72608.02000000", "0.00000000"], ["72590.29000000", "0.00007000"], ["72521.51000000", "0.00000000"], ["72025.12000000", "0.02422000"], ["65457.55000000", "0.00425000"], ["65457.00000000", "0.00020000"]], "a": [["72730.62000000", "4.06286000"], ["72731.05000000", "0.00016000"], ["72731.67000000", "0.11197000"], ["72732.22000000", "0.00016000"], ["72732.35000000", "0.00028000"], ["72732.40000000", "0.00000000"], ["72734.00000000", "0.00080000"], ["72740.33000000", "0.00400000"], ["72746.00000000", "0.18842000"], ["72747.21000000", "0.00000000"], ["72748.46000000", "0.00200000"], ["72753.02000000", "0.17801000"], ["72753.77000000", "0.17801000"], ["72784.50000000", "0.18446000"], ["79890.03000000", "0.02121000"]], "_local_ts_utc": "2026-06-01T07:49:04.210439+00:00"}
{"e": "depthUpdate", "E": 1780300145414, "s": "BTCUSDT", "U": 94551776047, "u": 94551777492, "b": [["72730.61000000", "0.00000000"], ["72730.60000000", "0.00000000"], ["72730.59000000", "0.00000000"], ["72730.39000000", "0.00000000"], ["72730.25000000", "0.00000000"], ["72730.17000000", "0.00000000"], ["72730.06000000", "0.00000000"], ["72730.01000000", "0.00000000"], ["72730.00000000", "0.00000000"], ["72729.99000000", "0.00000000"], ["72729.94000000", "0.00000000"], ["72729.90000000", "0.00000000"], ["72729.41000000", "0.00000000"], ["72729.35000000", "0.00000000"], ["72729.21000000", "0.00000000"], ["72729.15000000", "0.00000000"], ["72729.01000000", "0.00000000"], ["72729.00000000", "0.00000000"], ["72728.99000000", "0.00000000"], ["72728.90000000", "0.00000000"], ["72728.86000000", "0.00000000"], ["72728.76000000", "0.00000000"], ["72728.01000000", "0.00000000"], ["72728.00000000", "0.00000000"], ["72727.86000000", "0.00000000"], ["72727.85000000", "0.00000000"], ["72727.84000000", "0.00000000"], ["72727.75000000", "0.00000000"], ["72727.70000000", "0.00000000"], ["72727.69000000", "0.00000000"], ["72727.60000000", "0.00000000"], ["72727.57000000", "0.00000000"], ["72727.51000000", "0.00000000"], ["72727.45000000", "0.00000000"], ["72727.44000000", "0.00000000"], ["72727.43000000", "0.00000000"], ["72727.39000000", "0.00000000"], ["72727.30000000", "0.00000000"], ["72727.27000000", "0.00000000"], ["72727.17000000", "0.00000000"], ["72727.05000000", "0.00000000"], ["72727.02000000", "0.00000000"], ["72727.01000000", "0.00000000"], ["72727.00000000", "1.26639000"], ["72726.99000000", "0.00072000"], ["72726.01000000", "0.00016000"], ["72725.81000000", "0.00033000"], ["72725.22000000", "0.00016000"], ["72724.77000000", "0.00016000"], ["72724.04000000", "0.00000000"], ["72724.01000000", "0.00016000"], ["72723.68000000", "0.00000000"], ["72723.62000000", "0.00000000"], ["72722.01000000", "0.00008000"], ["72721.74000000", "0.00000000"], ["72721.65000000", "0.00000000"], ["72720.94000000", "0.00000000"], ["72719.92000000", "0.00000000"], ["72719.05000000", "0.00000000"], ["72718.62000000", "0.00031000"], ["72718.60000000", "0.00000000"], ["72718.59000000", "0.00000000"], ["72718.58000000", "0.00000000"], ["72718.57000000", "0.00000000"], ["72718.38000000", "0.00053000"], ["72717.89000000", "0.00000000"], ["72716.08000000", "0.00000000"], ["72715.24000000", "0.00000000"], ["72714.79000000", "0.00000000"], ["72714.78000000", "0.00000000"], ["72714.77000000", "0.00000000"], ["72712.58000000", "0.00000000"], ["72712.55000000", "0.01376000"], ["72711.90000000", "0.29802000"], ["72711.89000000", "0.65949000"], ["72711.88000000", "0.00000000"], ["72711.87000000", "0.00000000"], ["72711.68000000", "0.00000000"], ["72710.23000000", "0.00000000"], ["72709.36000000", "0.00027000"], ["72705.53000000", "0.00000000"], ["72704.38000000", "0.00000000"], ["72704.37000000", "0.17802000"], ["72704.26000000", "0.00000000"], ["72703.75000000", "0.00798000"], ["72703.53000000", "0.00000000"], ["72702.70000000", "0.00260000"], ["72702.00000000", "0.02280000"], ["72701.80000000", "0.17802000"], ["72701.56000000", "0.00000000"], ["72700.70000000", "0.00000000"], ["72699.30000000", "0.00000000"], ["72698.73000000", "0.15000000"], ["72698.41000000", "0.00009000"], ["72698.05000000", "0.16579000"], ["72697.69000000", "0.00200000"], ["72696.85000000", "0.00000000"], ["72696.43000000", "0.00000000"], ["72694.80000000", "0.17802000"], ["72694.39000000", "0.02000000"], ["72693.77000000", "0.00000000"], ["72693.00000000", "0.00007000"], ["72690.53000000", "0.00118000"], ["72688.98000000", "0.00400000"], ["72687.16000000", "0.00400000"], ["72685.81000000", "0.00000000"], ["72685.59000000", "0.17802000"], ["72685.02000000", "0.00000000"], ["72684.05000000", "0.17802000"], ["72682.04000000", "0.17801000"], ["72682.03000000", "0.00000000"], ["72678.01000000", "0.45223000"], ["72677.82000000", "0.00000000"], ["72676.91000000", "0.00000000"], ["72671.20000000", "0.00020000"], ["72670.20000000", "0.00000000"], ["72664.53000000", "0.00000000"], ["72660.67000000", "0.04710000"], ["72652.49000000", "0.33448000"], ["72652.39000000", "0.49613000"], ["72650.01000000", "0.54666000"], ["72647.60000000", "1.36445000"], ["72635.84000000", "0.00008000"], ["72622.66000000", "2.74987000"], ["72587.13000000", "0.00000000"], ["72541.63000000", "0.01374000"], ["65457.55000000", "0.00000000"], ["65457.00000000", "0.00000000"], ["65454.30000000", "0.00017000"]], "a": [["72727.01000000", "6.75397000"], ["72727.02000000", "0.00038000"], ["72727.03000000", "0.00014000"], ["72727.06000000", "0.00000000"], ["72727.16000000", "0.49721000"], ["72727.18000000", "0.00000000"], ["72727.28000000", "0.49721000"], ["72727.31000000", "0.00000000"], ["72727.38000000", "0.49721000"], ["72727.40000000", "0.00000000"], ["72727.42000000", "0.00000000"], ["72727.43000000", "0.00000000"], ["72727.44000000", "0.11120000"], ["72727.45000000", "0.49721000"], ["72727.46000000", "0.56958000"], ["72727.47000000", "0.00000000"], ["72727.48000000", "0.00000000"], ["72727.61000000", "0.00000000"], ["72727.70000000", "0.00000000"], ["72727.71000000", "0.00000000"], ["72727.76000000", "0.00000000"], ["72727.85000000", "3.81981000"], ["72727.86000000", "0.00000000"], ["72727.87000000", "0.45886000"], ["72727.88000000", "0.00000000"], ["72727.89000000", "0.00000000"], ["72727.99000000", "0.00000000"], ["72728.00000000", "0.65949000"], ["72728.01000000", "0.14972000"], ["72728.02000000", "0.00000000"], ["72728.14000000", "0.03407000"], ["72728.77000000", "0.10185000"], ["72728.78000000", "0.00000000"], ["72728.79000000", "0.00000000"], ["72728.85000000", "0.00000000"], ["72728.91000000", "0.00000000"], ["72729.00000000", "0.00000000"], ["72729.01000000", "0.00000000"], ["72729.02000000", "0.00400000"], ["72729.16000000", "0.00000000"], ["72729.20000000", "0.00000000"], ["72729.22000000", "0.00000000"], ["72729.25000000", "0.17802000"], ["72729.26000000", "0.00000000"], ["72729.36000000", "0.00000000"], ["72729.42000000", "0.00000000"], ["72729.60000000", "0.00000000"], ["72729.70000000", "0.00000000"], ["72729.90000000", "0.00007000"], ["72729.91000000", "0.00000000"], ["72729.93000000", "0.00000000"], ["72729.95000000", "0.00000000"], ["72730.00000000", "0.17802000"], ["72730.01000000", "4.00449000"], ["72730.02000000", "0.00000000"], ["72730.07000000", "0.00000000"], ["72730.18000000", "0.00000000"], ["72730.26000000", "0.00000000"], ["72730.38000000", "0.00000000"], ["72730.39000000", "0.00000000"], ["72730.40000000", "1.45936000"], ["72730.60000000", "0.00000000"], ["72730.61000000", "0.00016000"], ["72730.62000000", "0.42068000"], ["72730.63000000", "0.00336000"], ["72730.64000000", "0.00000000"], ["72731.05000000", "0.00000000"], ["72731.06000000", "0.00651000"], ["72731.33000000", "0.00000000"], ["72731.63000000", "0.00008000"], ["72731.64000000", "0.60848000"], ["72731.65000000", "0.65949000"], ["72731.67000000", "0.11197000"], ["72732.01000000", "0.03407000"], ["72732.22000000", "0.00000000"], ["72732.32000000", "0.04115000"], ["72732.41000000", "0.09906000"], ["72732.60000000", "0.00008000"], ["72733.22000000", "0.00000000"], ["72734.21000000", "0.00000000"], ["72734.46000000", "0.00000000"], ["72734.60000000", "0.00000000"], ["72734.80000000", "0.00008000"], ["72735.17000000", "0.00011000"], ["72735.20000000", "0.00163000"], ["72735.21000000", "0.02318000"], ["72736.00000000", "0.00080000"], ["72736.22000000", "0.00000000"], ["72737.38000000", "0.00028000"], ["72737.46000000", "0.00000000"], ["72737.53000000", "0.00000000"], ["72737.87000000", "0.00000000"], ["72738.00000000", "0.00080000"], ["72738.01000000", "0.00000000"], ["72739.62000000", "0.00573000"], ["72739.81000000", "0.00000000"], ["72739.99000000", "0.68850000"], ["72740.00000000", "0.02977000"], ["72740.01000000", "0.00752000"], ["72740.20000000", "0.00000000"], ["72740.42000000", "0.00000000"], ["72740.62000000", "0.00000000"], ["72741.77000000", "0.00000000"], ["72741.82000000", "0.00000000"], ["72741.98000000", "0.00000000"], ["72742.00000000", "0.03780000"], ["72742.01000000", "0.01359000"], ["72742.46000000", "0.00000000"], ["72743.20000000", "0.00008000"], ["72744.29000000", "0.00000000"], ["72744.41000000", "0.00008000"], ["72745.59000000", "0.03692000"], ["72745.99000000", "0.00008000"], ["72746.00000000", "0.01080000"], ["72746.13000000", "0.00000000"], ["72746.73000000", "0.00000000"], ["72747.42000000", "0.00000000"], ["72748.46000000", "0.00290000"], ["72748.82000000", "0.00000000"], ["72748.93000000", "0.00008000"], ["72750.71000000", "0.00000000"], ["72750.72000000", "1.36252000"], ["72751.01000000", "0.00000000"], ["72751.62000000", "0.00000000"], ["72753.02000000", "0.00000000"], ["72753.49000000", "0.00114000"], ["72753.77000000", "0.00000000"], ["72755.88000000", "0.00200000"], ["72757.96000000", "0.00000000"], ["72758.14000000", "0.00054000"], ["72758.25000000", "0.00000000"], ["72758.40000000", "0.00000000"], ["72758.88000000", "0.00000000"], ["72759.72000000", "0.00000000"], ["72760.00000000", "0.02843000"], ["72761.35000000", "0.00000000"], ["72766.80000000", "0.00000000"], ["72771.22000000", "0.00412000"], ["72771.23000000", "0.07403000"], ["72772.56000000", "0.00000000"], ["72772.92000000", "0.00330000"], ["72778.01000000", "0.00007000"], ["72780.01000000", "0.68091000"], ["72784.49000000", "0.92230000"], ["72786.85000000", "0.00000000"], ["72790.44000000", "1.51402000"], ["72790.45000000", "4.12660000"], ["72790.57000000", "0.00000000"], ["72790.59000000", "0.00000000"], ["72792.03000000", "0.00000000"], ["72806.91000000", "0.00000000"], ["72807.68000000", "0.00000000"], ["72813.17000000", "0.00000000"], ["72813.27000000", "0.00000000"], ["72815.51000000", "0.00000000"], ["72820.32000000", "0.00000000"], ["72823.43000000", "0.00000000"], ["72826.08000000", "0.00000000"], ["72829.25000000", "0.00000000"], ["72833.93000000", "0.00000000"], ["72838.48000000", "0.00000000"], ["72841.09000000", "0.00000000"], ["72844.27000000", "0.00000000"], ["72845.60000000", "0.00000000"], ["72848.44000000", "0.00000000"], ["72869.39000000", "0.00000000"], ["72882.97000000", "0.00000000"], ["72898.02000000", "0.00000000"], ["72899.88000000", "0.00000000"], ["72926.48000000", "0.00000000"], ["72954.54000000", "0.00078000"], ["72955.25000000", "0.04709000"], ["72957.25000000", "0.00025000"], ["72958.19000000", "0.00008000"], ["72962.11000000", "0.00010000"], ["72974.98000000", "0.00000000"], ["73000.00000000", "0.59448000"], ["73002.55000000", "0.00000000"], ["73025.63000000", "0.00029000"], ["73041.87000000", "0.00011000"], ["73046.15000000", "0.00000000"], ["73070.58000000", "0.00021000"], ["73077.22000000", "0.00000000"], ["73086.96000000", "0.00104000"], ["73090.90000000", "0.00087000"], ["73123.62000000", "0.36749000"], ["73128.79000000", "0.00024000"], ["73164.88000000", "0.00000000"], ["73166.58000000", "0.00155000"], ["73211.76000000", "0.00027000"], ["73219.51000000", "0.00059000"], ["73294.10000000", "0.00016000"], ["73295.35000000", "0.00000000"], ["73368.19000000", "0.00029000"], ["73385.19000000", "0.00000000"], ["73397.34000000", "0.00041000"], ["73414.73000000", "0.00165000"], ["73661.43000000", "0.00011000"], ["73667.88000000", "0.00017000"], ["73806.10000000", "2.01159000"], ["73811.94000000", "0.00000000"], ["73840.12000000", "0.00081000"]], "_local_ts_utc": "2026-06-01T07:49:04.310702+00:00"}
{"e": "depthUpdate", "E": 1780300145524, "s": "BTCUSDT", "U": 94551777493, "u": 94551779149, "b": [["72727.00000000", "0.00000000"], ["72726.99000000", "0.00000000"], ["72726.92000000", "0.00000000"], ["72726.83000000", "0.00000000"], ["72726.80000000", "0.00000000"], ["72726.61000000", "0.00000000"], ["72726.31000000", "0.00000000"], ["72726.28000000", "0.00000000"], ["72726.26000000", "0.00000000"], ["72726.21000000", "0.00000000"], ["72726.01000000", "0.00000000"], ["72726.00000000", "0.00000000"], ["72725.97000000", "0.00000000"], ["72725.90000000", "0.00000000"], ["72725.81000000", "0.00000000"], ["72725.71000000", "0.00000000"], ["72725.50000000", "0.00000000"], ["72725.22000000", "0.00000000"], ["72725.21000000", "0.00000000"], ["72725.16000000", "0.00000000"], ["72725.01000000", "0.00000000"], ["72725.00000000", "0.00000000"], ["72724.98000000", "0.00000000"], ["72724.77000000", "0.00000000"], ["72724.76000000", "0.00000000"], ["72724.45000000", "0.00000000"], ["72724.40000000", "0.00000000"], ["72724.37000000", "0.00000000"], ["72724.20000000", "0.00000000"], ["72724.16000000", "0.00000000"], ["72724.13000000", "0.00000000"], ["72724.01000000", "0.00000000"], ["72724.00000000", "0.00000000"], ["72723.94000000", "0.00000000"], ["72723.90000000", "0.00000000"], ["72723.86000000", "0.00000000"], ["72723.80000000", "0.00000000"], ["72723.77000000", "0.00000000"], ["72723.74000000", "0.00000000"], ["72723.57000000", "0.00000000"], ["72723.51000000", "0.00000000"], ["72723.40000000", "0.00000000"], ["72723.12000000", "0.00000000"], ["72723.11000000", "0.00000000"], ["72722.97000000", "0.00000000"], ["72722.80000000", "0.00000000"], ["72722.73000000", "0.00000000"], ["72722.68000000", "0.00000000"], ["72722.66000000", "0.00000000"], ["72722.54000000", "0.00000000"], ["72722.52000000", "0.00000000"], ["72722.50000000", "0.00000000"], ["72722.25000000", "0.00000000"], ["72722.22000000", "0.00000000"], ["72722.02000000", "0.00000000"], ["72722.01000000", "0.00000000"], ["72722.00000000", "0.00000000"], ["72721.93000000", "0.00000000"], ["72721.80000000", "0.00000000"], ["72721.56000000", "0.00000000"], ["72721.21000000", "0.00000000"], ["72721.10000000", "0.00000000"], ["72721.00000000", "0.00000000"], ["72720.89000000", "0.00000000"], ["72720.84000000", "0.00000000"], ["72720.82000000", "0.00000000"], ["72720.76000000", "0.00000000"], ["72720.73000000", "0.00000000"], ["72720.48000000", "0.00000000"], ["72720.40000000", "0.00000000"], ["72720.35000000", "0.00000000"], ["72720.30000000", "0.00000000"], ["72720.25000000", "0.00000000"], ["72720.01000000", "0.00000000"], ["72720.00000000", "0.00000000"], ["72719.98000000", "0.00000000"], ["72719.94000000", "0.00000000"], ["72719.44000000", "0.00000000"], ["72719.43000000", "0.00000000"], ["72719.31000000", "0.00000000"], ["72719.26000000", "0.00000000"], ["72719.14000000", "0.00000000"], ["72719.00000000", "0.00000000"], ["72718.99000000", "0.00000000"], ["72718.92000000", "0.00000000"], ["72718.85000000", "0.00000000"], ["72718.83000000", "0.00000000"], ["72718.71000000", "0.00000000"], ["72718.68000000", "0.00000000"], ["72718.62000000", "0.00000000"], ["72718.38000000", "0.00000000"], ["72718.26000000", "0.00000000"], ["72718.24000000", "0.00000000"], ["72718.23000000", "0.00000000"], ["72718.18000000", "0.00000000"], ["72718.17000000", "0.00000000"], ["72718.10000000", "0.00000000"], ["72718.09000000", "0.00000000"], ["72718.01000000", "0.00000000"], ["72718.00000000", "0.05417000"], ["72717.86000000", "0.00000000"], ["72717.60000000", "0.00000000"], ["72716.85000000", "0.00016000"], ["72716.34000000", "0.00000000"], ["72716.28000000", "0.00000000"], ["72716.01000000", "0.00016000"], ["72715.39000000", "0.00000000"], ["72715.38000000", "0.00000000"], ["72714.90000000", "0.00000000"], ["72714.63000000", "0.00000000"], ["72714.62000000", "0.00016000"], ["72714.61000000", "0.00000000"], ["72714.46000000", "0.00000000"], ["72714.41000000", "0.00000000"], ["72714.15000000", "0.00000000"], ["72714.05000000", "0.00000000"], ["72713.65000000", "0.00000000"], ["72713.27000000", "0.00000000"], ["72713.13000000", "0.00000000"], ["72713.05000000", "0.00000000"], ["72712.97000000", "0.00000000"], ["72712.72000000", "0.01387000"], ["72712.70000000", "0.00000000"], ["72712.64000000", "0.00000000"], ["72712.55000000", "0.00000000"], ["72712.20000000", "0.00008000"], ["72712.19000000", "0.00000000"], ["72711.90000000", "0.00000000"], ["72711.89000000", "0.00000000"], ["72711.65000000", "0.00000000"], ["72711.59000000", "0.00165000"], ["72711.33000000", "0.00000000"], ["72710.37000000", "0.00000000"], ["72710.33000000", "0.00000000"], ["72710.30000000", "0.00000000"], ["72709.36000000", "0.00000000"], ["72709.26000000", "0.00000000"], ["72708.81000000", "0.00000000"], ["72708.80000000", "0.00102000"], ["72708.74000000", "0.00000000"], ["72708.54000000", "0.00000000"], ["72708.22000000", "0.00000000"], ["72707.97000000", "0.00063000"], ["72707.41000000", "0.00000000"], ["72707.40000000", "0.00000000"], ["72706.00000000", "0.02280000"], ["72705.45000000", "0.00008000"], ["72705.44000000", "0.01380000"], ["72705.41000000", "0.00000000"], ["72705.39000000", "0.00308000"], ["72704.37000000", "0.00000000"], ["72704.36000000", "0.00000000"], ["72704.33000000", "0.00000000"], ["72704.20000000", "0.00000000"], ["72704.19000000", "0.00000000"], ["72703.65000000", "0.01485000"], ["72701.80000000", "0.00000000"], ["72701.21000000", "0.00000000"], ["72700.88000000", "0.00000000"], ["72700.42000000", "0.00000000"], ["72700.06000000", "0.17821000"], ["72700.05000000", "0.00000000"], ["72700.04000000", "0.00000000"], ["72700.03000000", "0.00000000"], ["72700.02000000", "0.00000000"], ["72699.83000000", "0.00000000"], ["72699.32000000", "0.00000000"], ["72699.25000000", "0.00028000"], ["72698.73000000", "0.00000000"], ["72698.20000000", "0.16191000"], ["72698.16000000", "0.01366000"], ["72698.08000000", "0.00407000"], ["72698.05000000", "0.00000000"], ["72697.64000000", "0.00137000"], ["72697.53000000", "0.15000000"], ["72697.02000000", "0.00000000"], ["72696.42000000", "0.00000000"], ["72696.01000000", "0.00000000"], ["72695.37000000", "0.00000000"], ["72694.98000000", "0.00000000"], ["72694.80000000", "0.00000000"], ["72694.39000000", "0.00000000"], ["72694.23000000", "0.17822000"], ["72694.21000000", "0.00000000"], ["72693.78000000", "0.00000000"], ["72693.77000000", "0.17822000"], ["72693.76000000", "0.00000000"], ["72693.75000000", "0.00000000"], ["72693.02000000", "0.00165000"], ["72692.72000000", "0.00000000"], ["72692.56000000", "0.00000000"], ["72692.55000000", "0.00000000"], ["72692.54000000", "0.00000000"], ["72692.50000000", "0.00000000"], ["72692.03000000", "0.00000000"], ["72692.01000000", "0.17822000"], ["72690.88000000", "0.01351000"], ["72690.60000000", "0.17822000"], ["72689.62000000", "0.00000000"], ["72689.61000000", "0.17822000"], ["72689.60000000", "0.51154000"], ["72689.59000000", "0.00000000"], ["72689.31000000", "0.00007000"], ["72688.59000000", "0.00000000"], ["72688.45000000", "0.17822000"], ["72686.88000000", "0.04663000"], ["72686.43000000", "0.17822000"], ["72686.42000000", "0.21487000"], ["72686.41000000", "0.00000000"], ["72686.40000000", "0.00000000"], ["72685.62000000", "0.00007000"], ["72685.59000000", "0.00000000"], ["72685.58000000", "0.00000000"], ["72685.34000000", "0.00400000"], ["72685.04000000", "0.00000000"], ["72685.01000000", "0.00000000"], ["72685.00000000", "0.17822000"], ["72684.54000000", "0.00000000"], ["72684.20000000", "0.17821000"], ["72684.05000000", "0.00000000"], ["72683.52000000", "0.00400000"], ["72683.14000000", "0.00000000"], ["72683.02000000", "0.00000000"], ["72682.52000000", "0.17821000"], ["72682.06000000", "1.92588000"], ["72682.05000000", "3.40944000"], ["72682.04000000", "0.00000000"], ["72682.02000000", "0.00000000"], ["72682.01000000", "0.00000000"], ["72681.70000000", "0.00400000"], ["72681.59000000", "0.12084000"], ["72680.89000000", "0.00000000"], ["72679.88000000", "0.00400000"], ["72679.86000000", "0.00400000"], ["72678.38000000", "0.00000000"], ["72678.02000000", "0.00007000"], ["72675.53000000", "0.00000000"], ["72674.62000000", "0.00000000"], ["72674.02000000", "0.17822000"], ["72674.01000000", "0.21698000"], ["72673.80000000", "0.00011000"], ["72673.32000000", "0.65949000"], ["72673.30000000", "0.00000000"], ["72673.29000000", "0.00000000"], ["72673.28000000", "0.00000000"], ["72672.40000000", "0.17822000"], ["72671.27000000", "0.17829000"], ["72671.26000000", "1.08448000"], ["72671.25000000", "0.00000000"], ["72670.74000000", "0.00000000"], ["72670.71000000", "0.00000000"], ["72669.60000000", "0.17822000"], ["72669.28000000", "0.17822000"], ["72669.27000000", "0.65949000"], ["72669.26000000", "0.00000000"], ["72669.13000000", "0.00000000"], ["72669.05000000", "0.00000000"], ["72668.64000000", "0.00000000"], ["72668.63000000", "0.00000000"], ["72668.61000000", "0.38828000"], ["72668.60000000", "0.00000000"], ["72668.58000000", "0.00000000"], ["72668.06000000", "0.00000000"], ["72667.97000000", "0.00000000"], ["72667.40000000", "0.00000000"], ["72666.91000000", "0.00000000"], ["72666.89000000", "0.00000000"], ["72666.71000000", "0.00000000"], ["72666.69000000", "0.00000000"], ["72666.34000000", "0.00000000"], ["72663.84000000", "0.00000000"], ["72661.57000000", "0.20805000"], ["72661.56000000", "0.00000000"], ["72660.82000000", "0.02672000"], ["72660.25000000", "0.00000000"], ["72659.08000000", "0.00000000"], ["72658.46000000", "0.17822000"], ["72658.32000000", "0.00000000"], ["72657.91000000", "0.03360000"], ["72657.61000000", "0.17822000"], ["72656.93000000", "0.00000000"], ["72656.83000000", "0.00024000"], ["72655.72000000", "0.18446000"], ["72655.16000000", "0.00000000"], ["72655.10000000", "0.06954000"], ["72654.41000000", "1.47568000"], ["72653.51000000", "0.92555000"], ["72653.50000000", "1.10676000"], ["72653.49000000", "0.18446000"], ["72652.56000000", "0.73784000"], ["72652.49000000", "0.00000000"], ["72652.05000000", "0.00063000"], ["72649.29000000", "0.00008000"], ["72648.81000000", "0.36892000"], ["72648.41000000", "0.00000000"], ["72647.00000000", "0.49616000"], ["72641.52000000", "0.45696000"], ["72641.12000000", "1.36465000"], ["72640.00000000", "0.19023000"], ["72639.38000000", "0.36472000"], ["72635.69000000", "0.00000000"], ["72634.31000000", "0.82310000"], ["72629.62000000", "0.27155000"], ["72629.61000000", "0.65949000"], ["72626.61000000", "0.16122000"], ["72625.07000000", "0.00000000"], ["72622.68000000", "1.01923000"], ["72622.67000000", "0.65949000"], ["72619.41000000", "0.00000000"], ["72616.27000000", "0.65949000"], ["72616.26000000", "0.00060000"], ["72615.24000000", "2.74987000"], ["72614.28000000", "0.00115000"], ["72613.04000000", "0.00000000"], ["72609.90000000", "0.00000000"], ["72608.03000000", "0.00000000"], ["72607.54000000", "0.65949000"], ["72603.60000000", "0.00000000"], ["72600.54000000", "0.65949000"], ["72600.53000000", "0.00000000"], ["72597.72000000", "0.00000000"], ["72591.81000000", "0.65949000"], ["72585.59000000", "0.00000000"], ["72583.06000000", "0.00275000"], ["72581.01000000", "0.00000000"], ["72578.50000000", "0.00000000"], ["72577.56000000", "0.00137000"], ["72576.57000000", "0.00008000"], ["72575.34000000", "0.00000000"], ["72563.30000000", "0.40856000"], ["72562.17000000", "0.00000000"], ["72561.48000000", "2.84261000"], ["72549.46000000", "0.00412000"], ["72531.54000000", "0.00000000"], ["72523.49000000", "4.14196000"], ["72521.90000000", "0.00007000"], ["72518.27000000", "0.00000000"], ["72517.68000000", "0.12264000"], ["72512.86000000", "0.00000000"], ["72503.84000000", "0.00008000"], ["72441.17000000", "0.00032000"], ["72440.13000000", "0.00000000"], ["72433.20000000", "0.00000000"], ["72431.12000000", "0.00008000"], ["72425.22000000", "3.04775000"], ["72422.26000000", "1.84192000"], ["72420.88000000", "0.00028000"], ["72413.60000000", "0.00028000"], ["72406.32000000", "0.00028000"], ["72404.28000000", "0.00008000"], ["72398.06000000", "0.00000000"], ["72367.39000000", "0.00000000"], ["72358.40000000", "0.00008000"], ["72315.64000000", "0.36755000"], ["72294.66000000", "0.00103000"], ["72285.68000000", "0.00008000"], ["72221.93000000", "0.00000000"], ["72212.96000000", "0.00008000"], ["72160.00000000", "0.02331000"], ["72149.20000000", "0.00000000"], ["72140.23000000", "0.00008000"], ["65454.30000000", "0.00000000"], ["65448.00000000", "0.00017000"], ["58547.20000000", "0.00038000"], ["58498.45000000", "0.00000000"], ["58400.00000000", "2.57540000"], ["58396.13000000", "0.00000000"], ["58372.88000000", "0.00038000"], ["58353.58000000", "0.00209000"], ["58236.57000000", "0.00000000"], ["58231.23000000", "0.00019000"], ["58176.00000000", "0.01237000"]], "a": [["72718.01000000", "0.87862000"], ["72718.02000000", "0.30000000"], ["72718.69000000", "0.30000000"], ["72718.93000000", "1.05795000"], ["72719.01000000", "0.41760000"], ["72719.34000000", "0.10000000"], ["72719.43000000", "0.05517000"], ["72719.44000000", "0.31577000"], ["72719.45000000", "0.00008000"], ["72719.92000000", "0.00400000"], ["72719.95000000", "0.00000000"], ["72719.97000000", "0.66166000"], ["72719.99000000", "0.66166000"], ["72720.01000000", "2.05482000"], ["72720.02000000", "0.00024000"], ["72720.03000000", "0.00000000"], ["72720.26000000", "0.00000000"], ["72720.31000000", "0.00000000"], ["72720.83000000", "0.00000000"], ["72720.85000000", "0.00000000"], ["72721.10000000", "0.00000000"], ["72721.11000000", "0.00000000"], ["72721.22000000", "0.00000000"], ["72721.73000000", "0.17822000"], ["72721.74000000", "0.00400000"], ["72721.81000000", "0.00000000"], ["72721.93000000", "0.00000000"], ["72721.94000000", "0.18656000"], ["72721.99000000", "0.00000000"], ["72722.00000000", "1.75067000"], ["72722.01000000", "1.14292000"], ["72722.02000000", "1.07478000"], ["72722.03000000", "0.03649000"], ["72722.52000000", "0.00007000"], ["72722.71000000", "0.01264000"], ["72723.13000000", "0.00000000"], ["72723.14000000", "0.00000000"], ["72723.40000000", "1.24564000"], ["72723.41000000", "0.11649000"], ["72723.42000000", "0.00000000"], ["72723.43000000", "0.00000000"], ["72723.56000000", "0.00400000"], ["72723.87000000", "0.00000000"], ["72723.95000000", "0.00000000"], ["72724.01000000", "0.00000000"], ["72724.21000000", "0.00000000"], ["72724.53000000", "0.17822000"], ["72724.77000000", "0.00000000"], ["72724.78000000", "0.00000000"], ["72724.81000000", "0.17822000"], ["72724.83000000", "0.17821000"], ["72724.99000000", "0.00009000"], ["72725.00000000", "0.65949000"], ["72725.01000000", "0.47381000"], ["72725.02000000", "0.00000000"], ["72725.17000000", "0.00000000"], ["72725.22000000", "0.00016000"], ["72725.23000000", "0.00000000"], ["72725.38000000", "0.00400000"], ["72725.64000000", "0.00165000"], ["72725.82000000", "0.00000000"], ["72725.90000000", "0.00000000"], ["72725.91000000", "0.01272000"], ["72725.92000000", "0.00000000"], ["72726.00000000", "1.75918000"], ["72726.01000000", "0.00000000"], ["72726.02000000", "0.00000000"], ["72726.21000000", "0.00007000"], ["72726.22000000", "0.00000000"], ["72726.27000000", "0.00000000"], ["72726.29000000", "0.00000000"], ["72726.32000000", "0.49721000"], ["72726.62000000", "0.49721000"], ["72726.81000000", "0.00000000"], ["72726.84000000", "0.00000000"], ["72726.93000000", "1.13293000"], ["72727.00000000", "1.06662000"], ["72727.01000000", "0.65753000"], ["72727.02000000", "0.00000000"], ["72727.03000000", "0.00000000"], ["72727.16000000", "0.00000000"], ["72727.20000000", "0.00400000"], ["72727.28000000", "0.00000000"], ["72727.37000000", "0.00008000"], ["72727.38000000", "0.00000000"], ["72727.44000000", "0.00000000"], ["72727.45000000", "0.00000000"], ["72727.46000000", "0.33299000"], ["72727.72000000", "0.00000000"], ["72727.78000000", "0.00011000"], ["72727.84000000", "0.00008000"], ["72727.85000000", "0.00000000"], ["72727.86000000", "1.38293000"], ["72727.87000000", "0.40856000"], ["72727.99000000", "0.00008000"], ["72728.01000000", "0.04000000"], ["72728.14000000", "0.00000000"], ["72728.77000000", "0.29625000"], ["72729.09000000", "0.00007000"], ["72729.25000000", "0.00000000"], ["72729.94000000", "0.00028000"], ["72729.99000000", "2.74987000"], ["72730.00000000", "0.00008000"], ["72730.01000000", "0.45425000"], ["72730.40000000", "1.04880000"], ["72730.61000000", "0.00008000"], ["72730.62000000", "0.38724000"], ["72731.63000000", "0.68851000"], ["72731.64000000", "0.60856000"], ["72731.67000000", "0.00000000"], ["72732.01000000", "0.00000000"], ["72732.02000000", "0.00000000"], ["72732.29000000", "0.00000000"], ["72732.38000000", "0.00009000"], ["72732.40000000", "0.00008000"], ["72732.41000000", "0.01977000"], ["72732.49000000", "0.00007000"], ["72732.60000000", "0.00008000"], ["72732.61000000", "0.51394000"], ["72733.19000000", "0.00000000"], ["72733.23000000", "0.00000000"], ["72733.34000000", "0.00758000"], ["72733.86000000", "0.43346000"], ["72733.90000000", "1.36283000"], ["72734.00000000", "0.00080000"], ["72734.01000000", "0.00000000"], ["72734.80000000", "0.00008000"], ["72734.81000000", "0.89452000"], ["72735.20000000", "0.00008000"], ["72735.21000000", "0.00000000"], ["72735.30000000", "0.00008000"], ["72735.31000000", "0.00000000"], ["72735.72000000", "0.00000000"], ["72735.91000000", "0.00008000"], ["72736.09000000", "0.00007000"], ["72736.12000000", "0.00000000"], ["72736.13000000", "0.00000000"], ["72736.21000000", "0.00000000"], ["72736.43000000", "0.00000000"], ["72736.81000000", "0.00000000"], ["72737.37000000", "0.23224000"], ["72737.46000000", "0.00000000"], ["72737.52000000", "0.00000000"], ["72737.53000000", "0.00008000"], ["72737.87000000", "0.00000000"], ["72738.01000000", "0.00000000"], ["72738.29000000", "1.03595000"], ["72739.56000000", "0.00000000"], ["72739.61000000", "0.00000000"], ["72739.98000000", "0.00008000"], ["72739.99000000", "0.00000000"], ["72740.01000000", "0.00752000"], ["72740.44000000", "0.00008000"], ["72740.62000000", "0.00000000"], ["72741.06000000", "0.00000000"], ["72741.24000000", "1.36269000"], ["72741.25000000", "0.00000000"], ["72741.29000000", "0.00137000"], ["72741.81000000", "0.00000000"], ["72741.90000000", "0.00400000"], ["72741.98000000", "0.00000000"], ["72742.14000000", "0.00008000"], ["72742.37000000", "0.00000000"], ["72742.46000000", "0.00000000"], ["72743.23000000", "0.00000000"], ["72743.34000000", "0.00000000"], ["72743.47000000", "0.00120000"], ["72743.93000000", "0.00000000"], ["72744.41000000", "0.00008000"], ["72744.87000000", "0.00000000"], ["72745.13000000", "0.00000000"], ["72745.54000000", "0.13750000"], ["72745.59000000", "0.03692000"], ["72745.99000000", "0.00000000"], ["72746.01000000", "0.00000000"], ["72746.23000000", "0.00000000"], ["72746.61000000", "0.00000000"], ["72747.29000000", "0.00200000"], ["72747.99000000", "0.00000000"], ["72748.82000000", "0.00018000"], ["72748.93000000", "0.00000000"], ["72749.04000000", "0.00000000"], ["72749.06000000", "0.00000000"], ["72749.14000000", "0.49547000"], ["72750.71000000", "0.00008000"], ["72750.85000000", "0.00000000"], ["72750.86000000", "0.00000000"], ["72751.37000000", "0.00000000"], ["72751.44000000", "0.00000000"], ["72752.68000000", "0.00000000"], ["72754.50000000", "0.00000000"], ["72755.12000000", "0.00000000"], ["72755.14000000", "0.00000000"], ["72755.79000000", "0.00008000"], ["72756.32000000", "0.00000000"], ["72758.01000000", "0.32958000"], ["72758.55000000", "0.00000000"], ["72759.03000000", "0.00000000"], ["72759.22000000", "0.00000000"], ["72759.42000000", "0.00000000"], ["72761.33000000", "0.00000000"], ["72762.46000000", "0.00000000"], ["72762.47000000", "0.00000000"], ["72763.11000000", "0.00000000"], ["72765.51000000", "0.44559000"], ["72765.52000000", "0.00000000"], ["72765.65000000", "0.00000000"], ["72766.21000000", "0.00000000"], ["72767.46000000", "0.00000000"], ["72774.50000000", "0.09385000"], ["72774.92000000", "0.36892000"], ["72775.56000000", "0.01733000"], ["72775.67000000", "0.00110000"], ["72776.15000000", "0.00000000"], ["72777.99000000", "0.00137000"], ["72779.74000000", "0.21776000"], ["72780.01000000", "0.00000000"], ["72781.72000000", "0.00000000"], ["72782.08000000", "0.00000000"], ["72786.73000000", "0.00007000"], ["72786.88000000", "0.00000000"], ["72788.75000000", "0.00000000"], ["72790.44000000", "0.27674000"], ["72790.45000000", "0.00000000"], ["72795.85000000", "0.00008000"], ["72797.00000000", "0.00000000"], ["72800.00000000", "0.02620000"], ["72801.95000000", "0.00000000"], ["72803.13000000", "0.00000000"], ["72803.35000000", "0.00000000"], ["72805.91000000", "0.18695000"], ["72806.37000000", "0.00000000"], ["72806.38000000", "0.00000000"], ["72806.40000000", "0.00000000"], ["72809.33000000", "0.16307000"], ["72809.34000000", "0.00000000"], ["72812.50000000", "0.15185000"], ["72813.17000000", "0.00000000"], ["72813.18000000", "0.00000000"], ["72817.72000000", "0.74532000"], ["72819.45000000", "0.00000000"], ["72821.06000000", "1.23138000"], ["72823.44000000", "0.00000000"], ["72826.05000000", "0.00000000"], ["72829.57000000", "0.17647000"], ["72842.44000000", "0.03981000"], ["72855.04000000", "0.00000000"], ["72865.65000000", "0.00000000"], ["72868.58000000", "0.00008000"], ["72872.07000000", "0.00019000"], ["72875.58000000", "0.00000000"], ["72879.48000000", "0.00000000"], ["72890.69000000", "0.00000000"], ["72912.35000000", "0.00008000"], ["72922.01000000", "0.00000000"], ["72924.40000000", "0.00000000"], ["72928.48000000", "0.00000000"], ["72930.97000000", "0.11526000"], ["72945.54000000", "0.00020000"], ["72949.59000000", "0.00032000"], ["72951.64000000", "0.00008000"], ["72954.54000000", "0.00112000"], ["72958.07000000", "0.00028000"], ["72958.30000000", "0.00033000"], ["73000.00000000", "0.59583000"], ["73011.67000000", "0.00016000"], ["73014.02000000", "0.00008000"], ["73021.54000000", "0.00000000"], ["73030.30000000", "0.00028000"], ["73032.65000000", "0.00023000"], ["73035.48000000", "0.00016000"], ["73041.46000000", "0.00009000"], ["73061.56000000", "0.00007000"], ["73069.77000000", "0.00000000"], ["73070.56000000", "0.00000000"], ["73082.68000000", "0.00000000"], ["73086.20000000", "0.00007000"], ["73086.75000000", "0.00008000"], ["73089.69000000", "0.00000000"], ["73094.27000000", "0.00000000"], ["73114.80000000", "0.00000000"], ["73180.91000000", "0.00077000"], ["73181.81000000", "0.00224000"], ["73192.38000000", "0.00000000"], ["73232.19000000", "0.00008000"], ["73239.73000000", "0.00000000"], ["73250.71000000", "0.00000000"], ["73258.15000000", "0.00000000"], ["73265.59000000", "0.00000000"], ["73272.72000000", "0.00250000"], ["73273.03000000", "0.00000000"], ["73280.00000000", "0.00709000"], ["73280.47000000", "0.00000000"], ["73287.91000000", "0.00000000"], ["73295.45000000", "0.00033000"], ["73409.09000000", "0.00240000"], ["73419.16000000", "0.00008000"], ["73455.09000000", "0.00033000"], ["73556.81000000", "0.00088000"], ["73571.79000000", "1.09488000"], ["73613.11000000", "0.00113000"], ["73636.36000000", "0.00409000"], ["73644.92000000", "0.00030000"], ["73659.90000000", "0.00000000"], ["73801.97000000", "1.86230000"], ["73806.10000000", "0.00000000"], ["74538.00000000", "0.04305000"], ["74567.82000000", "0.00000000"], ["74727.00000000", "6.00015000"], ["76358.85000000", "0.00050000"], ["76361.26000000", "0.00010000"], ["76383.31000000", "0.00000000"], ["76383.56000000", "0.00010000"], ["76410.61000000", "0.00010000"], ["76411.81000000", "0.00000000"]], "_local_ts_utc": "2026-06-01T07:49:04.421124+00:00"}
{"e": "depthUpdate", "E": 1780300145614, "s": "BTCUSDT", "U": 94551779150, "u": 94551781132, "b": [["72718.00000000", "0.00000000"], ["72717.99000000", "0.00000000"], ["72717.89000000", "0.00000000"], ["72717.88000000", "0.00000000"], ["72717.87000000", "0.00000000"], ["72717.79000000", "0.00000000"], ["72717.69000000", "0.00000000"], ["72717.52000000", "0.00000000"], ["72717.39000000", "0.00000000"], ["72717.37000000", "0.00000000"], ["72717.00000000", "0.00000000"], ["72716.95000000", "0.00000000"], ["72716.88000000", "0.00000000"], ["72716.85000000", "0.00000000"], ["72716.84000000", "0.00000000"], ["72716.80000000", "0.00000000"], ["72716.66000000", "0.00000000"], ["72716.51000000", "0.00000000"], ["72716.29000000", "0.00000000"], ["72716.07000000", "0.00000000"], ["72716.06000000", "0.00000000"], ["72716.01000000", "0.00000000"], ["72716.00000000", "0.00000000"], ["72715.92000000", "0.00000000"], ["72715.84000000", "0.00000000"], ["72715.81000000", "0.00000000"], ["72715.58000000", "0.00000000"], ["72715.34000000", "0.00000000"], ["72715.14000000", "0.00000000"], ["72715.13000000", "0.00000000"], ["72715.12000000", "0.00000000"], ["72715.06000000", "0.00000000"], ["72714.95000000", "0.00000000"], ["72714.91000000", "0.00000000"], ["72714.82000000", "0.00000000"], ["72714.76000000", "0.00000000"], ["72714.70000000", "0.00000000"], ["72714.66000000", "0.00000000"], ["72714.62000000", "0.00000000"], ["72714.59000000", "0.00000000"], ["72714.28000000", "0.00000000"], ["72714.21000000", "0.00000000"], ["72714.17000000", "0.00000000"], ["72714.04000000", "0.00000000"], ["72714.00000000", "0.00000000"], ["72713.25000000", "0.00000000"], ["72713.12000000", "0.00000000"], ["72713.02000000", "0.00000000"], ["72712.91000000", "0.00000000"], ["72712.73000000", "0.00000000"], ["72712.72000000", "0.00000000"], ["72712.61000000", "0.00000000"], ["72712.36000000", "0.00000000"], ["72712.28000000", "0.00000000"], ["72712.26000000", "0.00000000"], ["72712.20000000", "0.00000000"], ["72712.16000000", "0.00000000"], ["72712.07000000", "0.00000000"], ["72712.00000000", "2.44036000"], ["72711.99000000", "0.00064000"], ["72711.85000000", "0.00000000"], ["72711.76000000", "0.00000000"], ["72711.66000000", "0.00000000"], ["72711.59000000", "0.00000000"], ["72711.45000000", "0.00007000"], ["72711.27000000", "0.00000000"], ["72711.11000000", "0.00000000"], ["72711.03000000", "0.00000000"], ["72711.00000000", "0.00000000"], ["72710.97000000", "0.00000000"], ["72710.89000000", "0.00016000"], ["72710.88000000", "0.02726000"], ["72710.87000000", "0.00000000"], ["72710.82000000", "0.00000000"], ["72710.44000000", "0.00000000"], ["72710.20000000", "0.00100000"], ["72710.12000000", "0.00000000"], ["72710.01000000", "0.00008000"], ["72709.78000000", "0.00016000"], ["72709.25000000", "0.00024000"], ["72708.80000000", "0.00000000"], ["72708.24000000", "0.00000000"], ["72708.23000000", "0.00000000"], ["72708.21000000", "0.00000000"], ["72708.20000000", "0.00573000"], ["72708.01000000", "0.00016000"], ["72707.97000000", "0.00008000"], ["72707.81000000", "0.00019000"], ["72707.24000000", "0.00766000"], ["72707.18000000", "0.00428000"], ["72706.80000000", "0.00000000"], ["72706.47000000", "0.03702000"], ["72706.39000000", "0.00000000"], ["72706.05000000", "0.00000000"], ["72706.03000000", "0.00000000"], ["72705.40000000", "0.00000000"], ["72705.16000000", "0.00000000"], ["72705.01000000", "0.00008000"], ["72705.00000000", "0.17874000"], ["72704.78000000", "0.00011000"], ["72704.04000000", "0.00008000"], ["72704.03000000", "0.00116000"], ["72704.02000000", "0.00000000"], ["72704.01000000", "0.00000000"], ["72703.96000000", "0.00000000"], ["72703.60000000", "0.00771000"], ["72702.60000000", "0.00000000"], ["72702.48000000", "0.17472000"], ["72702.21000000", "0.00008000"], ["72702.20000000", "0.17824000"], ["72701.66000000", "0.00007000"], ["72701.52000000", "0.00000000"], ["72701.31000000", "0.00000000"], ["72701.20000000", "0.00000000"], ["72700.80000000", "0.17824000"], ["72700.73000000", "0.00000000"], ["72700.72000000", "0.00000000"], ["72700.49000000", "0.00000000"], ["72700.07000000", "2.74987000"], ["72700.06000000", "0.00000000"], ["72700.02000000", "0.38857000"], ["72700.01000000", "0.00063000"], ["72699.96000000", "0.00744000"], ["72699.44000000", "0.00048000"], ["72699.17000000", "0.01376000"], ["72698.81000000", "0.00048000"], ["72698.72000000", "0.17963000"], ["72698.43000000", "0.00000000"], ["72698.33000000", "0.00000000"], ["72698.20000000", "0.00000000"], ["72697.53000000", "0.01000000"], ["72697.40000000", "0.00011000"], ["72697.14000000", "0.00000000"], ["72697.04000000", "0.17472000"], ["72697.02000000", "0.47150000"], ["72696.32000000", "0.00741000"], ["72696.05000000", "0.03407000"], ["72696.02000000", "0.00000000"], ["72696.01000000", "0.65957000"], ["72694.75000000", "0.00000000"], ["72694.69000000", "0.00000000"], ["72694.53000000", "0.00008000"], ["72694.52000000", "0.17824000"], ["72694.23000000", "0.00000000"], ["72693.90000000", "0.01377000"], ["72693.84000000", "0.01376000"], ["72693.82000000", "0.00000000"], ["72693.79000000", "0.00189000"], ["72693.77000000", "0.00000000"], ["72692.96000000", "0.17472000"], ["72692.76000000", "0.17824000"], ["72692.64000000", "0.05609000"], ["72692.57000000", "0.00000000"], ["72692.56000000", "0.89989000"], ["72692.55000000", "2.74987000"], ["72692.53000000", "0.14000000"], ["72692.32000000", "0.00000000"], ["72692.02000000", "0.65949000"], ["72692.01000000", "0.00939000"], ["72691.89000000", "0.00000000"], ["72691.00000000", "0.17824000"], ["72690.80000000", "0.00400000"], ["72690.60000000", "0.00000000"], ["72689.62000000", "0.40856000"], ["72689.61000000", "0.17824000"], ["72689.54000000", "0.00000000"], ["72689.47000000", "0.00000000"], ["72688.60000000", "0.17823000"], ["72688.45000000", "0.65957000"], ["72686.81000000", "0.17824000"], ["72686.80000000", "0.00000000"], ["72686.43000000", "0.00000000"], ["72686.42000000", "0.52382000"], ["72685.40000000", "0.17824000"], ["72685.33000000", "0.65949000"], ["72685.26000000", "0.00000000"], ["72685.07000000", "0.65670000"], ["72685.00000000", "0.00000000"], ["72684.20000000", "0.00000000"], ["72683.34000000", "0.00000000"], ["72683.32000000", "0.17824000"], ["72683.00000000", "0.00086000"], ["72682.60000000", "0.00000000"], ["72682.52000000", "0.00000000"], ["72682.48000000", "0.00000000"], ["72682.07000000", "0.58680000"], ["72682.06000000", "1.92596000"], ["72681.93000000", "0.00007000"], ["72681.56000000", "0.00000000"], ["72680.48000000", "0.00000000"], ["72680.20000000", "0.00000000"], ["72680.01000000", "0.00315000"], ["72679.89000000", "0.00189000"], ["72678.64000000", "0.00012000"], ["72678.24000000", "0.00007000"], ["72678.06000000", "0.00000000"], ["72678.02000000", "0.00007000"], ["72678.01000000", "0.32979000"], ["72676.42000000", "0.00000000"], ["72676.01000000", "0.00000000"], ["72675.53000000", "0.00000000"], ["72675.52000000", "0.00000000"], ["72675.21000000", "0.00000000"], ["72674.55000000", "0.00000000"], ["72674.02000000", "0.00000000"], ["72674.01000000", "0.00000000"], ["72673.33000000", "0.20300000"], ["72672.40000000", "0.00000000"], ["72672.31000000", "0.00000000"], ["72671.66000000", "0.00000000"], ["72671.60000000", "0.00000000"], ["72671.28000000", "0.40856000"], ["72671.27000000", "0.00007000"], ["72670.29000000", "0.03589000"], ["72670.25000000", "0.00000000"], ["72669.60000000", "0.00000000"], ["72669.28000000", "0.00000000"], ["72668.62000000", "0.00000000"], ["72667.60000000", "0.00000000"], ["72666.20000000", "0.00000000"], ["72666.02000000", "0.00022000"], ["72665.50000000", "0.00000000"], ["72664.80000000", "0.00000000"], ["72664.56000000", "0.00000000"], ["72664.55000000", "1.18739000"], ["72664.29000000", "0.00000000"], ["72663.32000000", "0.00000000"], ["72661.85000000", "1.23225000"], ["72661.57000000", "0.20805000"], ["72661.20000000", "0.00000000"], ["72660.60000000", "0.00000000"], ["72659.23000000", "0.00000000"], ["72658.47000000", "0.00000000"], ["72658.46000000", "0.00000000"], ["72657.85000000", "0.01158000"], ["72657.61000000", "0.00000000"], ["72655.10000000", "0.00000000"], ["72654.86000000", "0.01163000"], ["72653.92000000", "0.00000000"], ["72652.57000000", "0.00343000"], ["72651.09000000", "0.00009000"], ["72651.02000000", "0.00425000"], ["72649.58000000", "0.02000000"], ["72649.29000000", "0.00000000"], ["72648.89000000", "0.02000000"], ["72648.23000000", "0.06983000"], ["72647.92000000", "0.00431000"], ["72646.77000000", "0.00000000"], ["72646.64000000", "0.00000000"], ["72646.47000000", "0.00000000"], ["72644.27000000", "0.02662000"], ["72643.58000000", "0.00007000"], ["72641.52000000", "0.45694000"], ["72641.12000000", "0.00008000"], ["72640.92000000", "1.36458000"], ["72639.36000000", "0.00007000"], ["72638.17000000", "0.00008000"], ["72636.01000000", "0.00000000"], ["72632.09000000", "0.00000000"], ["72630.20000000", "0.01063000"], ["72630.01000000", "0.00282000"], ["72629.58000000", "0.01707000"], ["72624.81000000", "0.00000000"], ["72621.01000000", "1.40517000"], ["72616.15000000", "0.00000000"], ["72615.65000000", "2.81768000"], ["72615.25000000", "0.00619000"], ["72615.24000000", "0.00000000"], ["72608.75000000", "0.04624000"], ["72605.90000000", "0.04644000"], ["72601.52000000", "0.69990000"], ["72593.91000000", "0.00000000"], ["72585.64000000", "0.00000000"], ["72578.86000000", "0.00137000"], ["72577.37000000", "0.02000000"], ["72576.57000000", "0.00000000"], ["72574.76000000", "0.00000000"], ["72570.10000000", "0.02000000"], ["72569.39000000", "0.00000000"], ["72565.46000000", "0.00008000"], ["72563.31000000", "0.00000000"], ["72562.83000000", "0.02000000"], ["72560.49000000", "0.00718000"], ["72558.30000000", "0.00000000"], ["72558.03000000", "1.20000000"], ["72555.96000000", "0.00113000"], ["72555.56000000", "0.02000000"], ["72552.59000000", "0.40856000"], ["72548.28000000", "0.02000000"], ["72541.81000000", "0.09412000"], ["72523.84000000", "0.00007000"], ["72516.58000000", "0.00007000"], ["72512.90000000", "0.00007000"], ["72503.84000000", "0.00000000"], ["72492.75000000", "0.00008000"], ["72449.08000000", "0.00500000"], ["72431.12000000", "0.00000000"], ["72421.65000000", "0.00041000"], ["72420.04000000", "0.00008000"], ["72358.40000000", "0.00000000"], ["72350.29000000", "0.00007000"], ["72347.33000000", "0.00008000"], ["72285.68000000", "0.00000000"], ["72274.61000000", "0.00008000"], ["72212.96000000", "0.00000000"], ["72201.90000000", "0.00008000"], ["72163.87000000", "0.10241000"], ["72140.23000000", "0.00000000"], ["72129.19000000", "0.00008000"], ["72067.28000000", "0.00009000"], ["71773.65000000", "0.00347000"], ["71186.48000000", "0.00000000"], ["65448.00000000", "0.00000000"], ["65446.20000000", "0.00000000"], ["65440.80000000", "0.00017000"], ["58231.23000000", "0.00000000"], ["58228.80000000", "0.00000000"], ["58217.60000000", "0.00000000"], ["58216.35000000", "0.00000000"], ["58176.00000000", "0.01203000"], ["58175.20000000", "0.00114000"], ["58175.14000000", "0.00076000"], ["58174.40000000", "0.00076000"]], "a": [["72712.01000000", "4.59186000"], ["72712.02000000", "0.50165000"], ["72712.03000000", "0.00014000"], ["72712.29000000", "0.00000000"], ["72712.34000000", "0.00024000"], ["72712.35000000", "0.00016000"], ["72712.36000000", "0.00016000"], ["72712.37000000", "0.11136000"], ["72712.38000000", "0.00000000"], ["72712.72000000", "0.00016000"], ["72712.73000000", "0.28179000"], ["72713.03000000", "0.00016000"], ["72713.69000000", "0.00000000"], ["72713.99000000", "0.00016000"], ["72714.00000000", "0.65949000"], ["72714.01000000", "0.00016000"], ["72714.29000000", "0.00016000"], ["72714.39000000", "0.01264000"], ["72714.65000000", "0.00000000"], ["72715.06000000", "0.05801000"], ["72715.08000000", "0.00008000"], ["72715.09000000", "0.00000000"], ["72715.13000000", "0.00016000"], ["72715.14000000", "0.00007000"], ["72716.01000000", "0.00016000"], ["72716.07000000", "0.00000000"], ["72716.28000000", "0.00400000"], ["72716.67000000", "0.00000000"], ["72716.81000000", "0.00000000"], ["72716.85000000", "0.00000000"], ["72717.40000000", "0.00000000"], ["72717.53000000", "0.00000000"], ["72717.70000000", "0.00000000"], ["72717.80000000", "0.00000000"], ["72717.88000000", "0.00008000"], ["72717.89000000", "0.68564000"], ["72717.90000000", "0.00000000"], ["72718.00000000", "0.00000000"], ["72718.01000000", "0.40897000"], ["72718.02000000", "0.00000000"], ["72718.03000000", "0.00000000"], ["72718.10000000", "0.00400000"], ["72718.11000000", "0.00000000"], ["72718.24000000", "0.00000000"], ["72718.25000000", "0.00000000"], ["72718.39000000", "0.00000000"], ["72718.68000000", "0.00000000"], ["72718.69000000", "0.00000000"], ["72718.81000000", "0.00000000"], ["72718.83000000", "0.00007000"], ["72718.92000000", "0.00008000"], ["72718.93000000", "1.22629000"], ["72718.94000000", "0.00000000"], ["72719.00000000", "0.00000000"], ["72719.01000000", "0.00000000"], ["72719.02000000", "0.00000000"], ["72719.29000000", "0.27000000"], ["72719.33000000", "0.00000000"], ["72719.34000000", "0.10000000"], ["72719.43000000", "0.00008000"], ["72719.44000000", "0.25704000"], ["72719.45000000", "0.00000000"], ["72719.96000000", "0.00000000"], ["72719.97000000", "0.00000000"], ["72719.98000000", "0.00000000"], ["72719.99000000", "0.00000000"], ["72720.00000000", "0.00000000"], ["72720.01000000", "0.11120000"], ["72720.02000000", "0.00000000"], ["72720.39000000", "0.00011000"], ["72721.06000000", "0.00008000"], ["72721.07000000", "0.00000000"], ["72721.73000000", "0.00000000"], ["72721.81000000", "0.00000000"], ["72721.94000000", "0.00000000"], ["72721.99000000", "0.00000000"], ["72722.00000000", "0.00000000"], ["72722.01000000", "0.00039000"], ["72722.02000000", "1.07434000"], ["72722.03000000", "0.00000000"], ["72722.50000000", "0.00028000"], ["72722.71000000", "0.00000000"], ["72723.39000000", "0.00000000"], ["72723.40000000", "0.14369000"], ["72723.41000000", "0.00176000"], ["72723.50000000", "0.00000000"], ["72723.61000000", "0.00000000"], ["72724.53000000", "0.00000000"], ["72724.81000000", "0.00000000"], ["72724.83000000", "0.00000000"], ["72724.99000000", "0.00017000"], ["72725.01000000", "0.11001000"], ["72725.22000000", "0.00000000"], ["72725.26000000", "0.00007000"], ["72725.91000000", "0.00000000"], ["72725.99000000", "0.00008000"], ["72726.00000000", "0.55776000"], ["72726.31000000", "0.68849000"], ["72726.32000000", "0.00000000"], ["72726.39000000", "0.00370000"], ["72726.61000000", "0.00000000"], ["72726.62000000", "0.00000000"], ["72726.86000000", "0.00008000"], ["72726.87000000", "0.96853000"], ["72726.92000000", "0.00000000"], ["72726.93000000", "0.00000000"], ["72727.00000000", "0.14516000"], ["72727.01000000", "0.02126000"], ["72727.09000000", "0.00007000"], ["72727.37000000", "0.00000000"], ["72727.45000000", "0.00008000"], ["72727.46000000", "0.04040000"], ["72727.56000000", "0.00000000"], ["72727.57000000", "0.00000000"], ["72727.74000000", "0.00007000"], ["72727.84000000", "0.00000000"], ["72727.85000000", "0.00008000"], ["72727.86000000", "1.21161000"], ["72727.99000000", "0.00000000"], ["72728.01000000", "0.04000000"], ["72728.76000000", "0.00000000"], ["72729.44000000", "0.00000000"], ["72729.97000000", "0.00008000"], ["72729.98000000", "0.00000000"], ["72729.99000000", "0.00000000"], ["72730.00000000", "0.00000000"], ["72730.01000000", "0.04000000"], ["72730.39000000", "0.00008000"], ["72730.40000000", "0.27000000"], ["72730.61000000", "0.00000000"], ["72730.62000000", "0.10852000"], ["72731.06000000", "0.00000000"], ["72731.19000000", "0.00007000"], ["72731.61000000", "0.37231000"], ["72731.62000000", "0.00000000"], ["72731.63000000", "0.00000000"], ["72731.64000000", "0.00008000"], ["72732.32000000", "0.00000000"], ["72732.40000000", "0.00000000"], ["72732.41000000", "0.00000000"], ["72732.60000000", "0.00000000"], ["72732.61000000", "0.01394000"], ["72733.01000000", "0.00000000"], ["72733.29000000", "0.00000000"], ["72733.41000000", "0.00000000"], ["72733.84000000", "0.00000000"], ["72733.85000000", "0.00189000"], ["72733.86000000", "0.00000000"], ["72733.90000000", "0.00000000"], ["72734.80000000", "0.00000000"], ["72734.81000000", "1.35499000"], ["72735.30000000", "0.00000000"], ["72735.48000000", "0.00200000"], ["72735.50000000", "0.00012000"], ["72735.71000000", "0.00000000"], ["72735.91000000", "0.00000000"], ["72736.36000000", "0.00275000"], ["72736.60000000", "0.00000000"], ["72737.03000000", "0.00008000"], ["72737.04000000", "2.74987000"], ["72737.36000000", "0.00008000"], ["72737.53000000", "0.00000000"], ["72737.54000000", "0.00000000"], ["72737.98000000", "0.00007000"], ["72738.01000000", "0.00000000"], ["72738.02000000", "0.05846000"], ["72738.28000000", "0.00008000"], ["72738.50000000", "0.00000000"], ["72739.98000000", "0.00000000"], ["72740.01000000", "0.00000000"], ["72740.29000000", "0.00000000"], ["72741.23000000", "0.00008000"], ["72741.26000000", "0.24309000"], ["72741.98000000", "0.00000000"], ["72742.14000000", "0.00000000"], ["72742.37000000", "0.00008000"], ["72742.38000000", "0.38337000"], ["72743.84000000", "0.00200000"], ["72744.41000000", "0.00000000"], ["72745.00000000", "0.00000000"], ["72745.40000000", "0.00000000"], ["72745.53000000", "0.03069000"], ["72745.54000000", "0.00000000"], ["72745.59000000", "0.00000000"], ["72745.85000000", "0.00000000"], ["72746.09000000", "0.00000000"], ["72747.22000000", "0.00000000"], ["72747.29000000", "0.00000000"], ["72748.46000000", "0.00090000"], ["72748.69000000", "0.00000000"], ["72748.82000000", "0.00000000"], ["72748.93000000", "0.00018000"], ["72749.06000000", "0.00000000"], ["72749.09000000", "0.00000000"], ["72751.80000000", "0.00429000"], ["72752.04000000", "0.00000000"], ["72752.10000000", "0.00000000"], ["72752.98000000", "0.00342000"], ["72755.00000000", "0.00000000"], ["72755.04000000", "0.00424000"], ["72755.73000000", "0.00000000"], ["72755.79000000", "0.00000000"], ["72756.96000000", "0.00007000"], ["72758.12000000", "0.00000000"], ["72759.51000000", "0.01142000"], ["72759.97000000", "0.00000000"], ["72760.56000000", "0.00412000"], ["72765.51000000", "0.03769000"], ["72766.81000000", "0.01069000"], ["72771.23000000", "0.07060000"], ["72774.92000000", "0.55338000"], ["72775.16000000", "0.00343000"], ["72778.74000000", "0.01158000"], ["72779.83000000", "0.00550000"], ["72781.94000000", "3.05729000"], ["72783.15000000", "4.12701000"], ["72784.72000000", "0.00015000"], ["72789.58000000", "0.00000000"], ["72792.05000000", "0.00000000"], ["72793.34000000", "0.27678000"], ["72793.99000000", "0.00000000"], ["72795.55000000", "0.00000000"], ["72795.85000000", "0.00000000"], ["72798.65000000", "0.46978000"], ["72798.66000000", "0.00000000"], ["72800.15000000", "0.05226000"], ["72803.94000000", "0.00000000"], ["72806.57000000", "0.00000000"], ["72809.33000000", "0.16307000"], ["72810.63000000", "0.00000000"], ["72814.20000000", "0.00000000"], ["72818.15000000", "0.04633000"], ["72821.99000000", "0.02964000"], ["72824.06000000", "0.04268000"], ["72825.80000000", "0.00137000"], ["72825.81000000", "0.00000000"], ["72828.00000000", "0.25269000"], ["72833.93000000", "0.00000000"], ["72834.33000000", "0.00000000"], ["72839.64000000", "0.12984000"], ["72843.99000000", "0.00000000"], ["72845.99000000", "0.00000000"], ["72847.98000000", "0.00137000"], ["72857.43000000", "0.00008000"], ["72858.71000000", "0.00000000"], ["72862.70000000", "0.02981000"], ["72863.45000000", "0.00010000"], ["72866.66000000", "0.00000000"], ["72868.19000000", "0.00000000"], ["72868.58000000", "0.00000000"], ["72876.08000000", "0.00000000"], ["72880.57000000", "0.00000000"], ["72884.20000000", "0.00031000"], ["72896.55000000", "0.00019000"], ["72900.00000000", "0.07702000"], ["72905.88000000", "0.00010000"], ["72912.58000000", "0.00008000"], ["72915.78000000", "0.00012000"], ["72917.12000000", "0.00000000"], ["72919.11000000", "0.00000000"], ["72935.88000000", "0.00041000"], ["72942.80000000", "0.07690000"], ["72945.50000000", "0.00090000"], ["72945.54000000", "0.00029000"], ["72945.86000000", "0.00010000"], ["72946.36000000", "0.00014000"], ["72951.50000000", "0.00008000"], ["72952.16000000", "0.00008000"], ["72952.38000000", "0.00011000"], ["72958.41000000", "0.00007000"], ["72960.00000000", "0.02361000"], ["72960.67000000", "0.00022000"], ["72973.00000000", "0.00708000"], ["72977.67000000", "0.00008000"], ["72978.03000000", "0.00030000"], ["72988.31000000", "1.19998000"], ["72991.68000000", "0.00000000"], ["73000.00000000", "0.59603000"], ["73002.86000000", "0.00008000"], ["73011.78000000", "0.00022000"], ["73014.02000000", "0.00000000"], ["73017.00000000", "0.00000000"], ["73024.93000000", "0.00032000"], ["73035.48000000", "0.00036000"], ["73039.22000000", "0.00022000"], ["73040.00000000", "0.00865000"], ["73041.46000000", "0.00019000"], ["73057.35000000", "0.00000000"], ["73057.76000000", "0.00015000"], ["73062.32000000", "0.00000000"], ["73066.66000000", "0.00107000"], ["73075.57000000", "0.00008000"], ["73080.00000000", "0.02600000"], ["73082.87000000", "0.00033000"], ["73083.33000000", "0.00075000"], ["73086.75000000", "0.00000000"], ["73096.89000000", "0.00073000"], ["73100.00000000", "1.16105000"], ["73113.71000000", "0.00021000"], ["73137.02000000", "0.00016000"], ["73142.85000000", "0.00512000"], ["73158.43000000", "0.00114000"], ["73169.67000000", "0.00012000"], ["73176.15000000", "0.00007000"], ["73185.04000000", "0.00000000"], ["73191.48000000", "0.00634000"], ["73195.04000000", "0.00008000"], ["73198.63000000", "0.00000000"], ["73200.00000000", "1.20402000"], ["73206.07000000", "0.00000000"], ["73208.71000000", "0.00022000"], ["73213.51000000", "0.00000000"], ["73214.13000000", "0.00011000"], ["73214.87000000", "0.00042000"], ["73220.95000000", "0.00000000"], ["73220.99000000", "0.00008000"], ["73228.39000000", "0.00000000"], ["73232.19000000", "0.00000000"], ["73233.33000000", "0.00478000"], ["73235.83000000", "0.00000000"], ["73236.36000000", "0.00014000"], ["73239.13000000", "0.00008000"], ["73240.00000000", "0.00879000"], ["73243.27000000", "0.00000000"], ["73273.18000000", "0.00011000"], ["73293.86000000", "0.00107000"], ["73343.05000000", "0.00008000"], ["73364.44000000", "0.00014000"], ["73387.73000000", "0.00009000"], ["73424.20000000", "0.00214000"], ["73428.57000000", "0.00550000"], ["73448.83000000", "0.00008000"], ["73451.75000000", "0.00015000"], ["73455.09000000", "0.00058000"], ["73462.62000000", "0.00100000"], ["73469.97000000", "0.00020000"], ["73546.00000000", "0.00032000"], ["73600.64000000", "0.00059000"], ["73655.01000000", "0.00034000"], ["73667.02000000", "0.00043000"], ["73739.62000000", "0.00012000"], ["74040.00000000", "1.00307000"], ["74184.34000000", "0.00019000"], ["74492.15000000", "0.01356000"], ["74526.66000000", "0.00040000"], ["74557.11000000", "0.00000000"], ["74927.64000000", "0.00000000"], ["74939.99000000", "0.00000000"], ["75662.23000000", "0.00000000"], ["76396.81000000", "0.00000000"], ["77131.40000000", "0.00000000"], ["80804.32000000", "0.00000000"], ["81538.91000000", "0.00000000"], ["83008.08000000", "0.00000000"], ["83742.66000000", "0.00000000"], ["84477.25000000", "0.00000000"], ["85211.83000000", "0.00000000"], ["85946.42000000", "0.00000000"], ["86000.00000000", "16.66826000"], ["86681.00000000", "0.00000000"], ["89619.34000000", "0.00000000"], ["90353.93000000", "0.00000000"], ["91088.51000000", "0.00000000"], ["91823.10000000", "0.00000000"], ["92557.68000000", "0.00000000"], ["93292.26000000", "0.00000000"], ["94026.85000000", "0.00000000"], ["96230.60000000", "0.00000000"], ["96965.19000000", "0.00000000"], ["97699.77000000", "0.00000000"], ["98434.36000000", "0.00000000"], ["99168.94000000", "0.00000000"], ["99903.53000000", "0.00000000"], ["100638.11000000", "0.00000000"], ["102107.28000000", "0.00000000"], ["102841.87000000", "0.00000000"], ["103576.45000000", "0.00000000"], ["105045.62000000", "0.00000000"], ["105780.21000000", "0.00000000"], ["106514.79000000", "0.00000000"]], "_local_ts_utc": "2026-06-01T07:49:04.510759+00:00"}
{"e": "depthUpdate", "E": 1780300145714, "s": "BTCUSDT", "U": 94551781133, "u": 94551781492, "b": [["72712.00000000", "2.30799000"], ["72711.99000000", "0.00080000"], ["72711.08000000", "0.00000000"], ["72710.88000000", "0.02542000"], ["72710.62000000", "0.00642000"], ["72710.21000000", "0.00000000"], ["72710.17000000", "0.00546000"], ["72710.01000000", "0.00024000"], ["72710.00000000", "0.08518000"], ["72709.99000000", "0.01091000"], ["72709.77000000", "0.05040000"], ["72709.57000000", "0.00031000"], ["72709.24000000", "0.08805000"], ["72709.00000000", "0.00000000"], ["72708.97000000", "0.00000000"], ["72708.43000000", "0.00000000"], ["72708.33000000", "0.00046000"], ["72708.32000000", "0.02749000"], ["72708.26000000", "0.00000000"], ["72708.25000000", "0.00000000"], ["72708.01000000", "0.00008000"], ["72707.81000000", "0.00011000"], ["72706.47000000", "0.00000000"], ["72705.20000000", "0.00000000"], ["72705.00000000", "0.00050000"], ["72704.78000000", "0.00000000"], ["72703.84000000", "0.17482000"], ["72700.09000000", "0.00000000"], ["72700.08000000", "3.40936000"], ["72700.07000000", "0.00000000"], ["72700.02000000", "0.00000000"], ["72699.28000000", "0.05942000"], ["72698.72000000", "0.00139000"], ["72698.40000000", "0.17480000"], ["72697.69000000", "0.00000000"], ["72697.53000000", "0.00000000"], ["72697.02000000", "0.00000000"], ["72697.01000000", "0.00017000"], ["72696.03000000", "0.58700000"], ["72696.02000000", "0.17472000"], ["72694.53000000", "0.01008000"], ["72694.52000000", "0.00000000"], ["72694.32000000", "0.00000000"], ["72693.90000000", "0.00000000"], ["72692.64000000", "0.00192000"], ["72692.53000000", "0.06000000"], ["72691.00000000", "0.00000000"], ["72690.53000000", "0.00000000"], ["72690.24000000", "0.00000000"], ["72689.83000000", "0.08000000"], ["72689.63000000", "0.00000000"], ["72689.61000000", "0.00000000"], ["72688.60000000", "0.00000000"], ["72688.46000000", "0.00000000"], ["72686.88000000", "0.02000000"], ["72686.81000000", "0.00000000"], ["72686.53000000", "0.00000000"], ["72686.42000000", "0.32118000"], ["72686.16000000", "0.00000000"], ["72685.40000000", "0.00000000"], ["72685.36000000", "0.00000000"], ["72685.11000000", "0.00200000"], ["72685.07000000", "0.00000000"], ["72683.44000000", "0.00000000"], ["72683.32000000", "0.00000000"], ["72682.33000000", "0.02737000"], ["72682.08000000", "0.17472000"], ["72682.07000000", "0.40856000"], ["72676.24000000", "0.00400000"], ["72667.90000000", "0.03388000"], ["72661.85000000", "0.00000000"], ["72658.96000000", "0.00000000"], ["72657.61000000", "0.00000000"], ["72653.99000000", "1.04055000"], ["72652.57000000", "0.00000000"], ["72648.23000000", "0.06826000"], ["72646.27000000", "0.45583000"], ["72643.16000000", "0.27548000"], ["72631.11000000", "0.00000000"], ["72615.65000000", "1.99684000"], ["72611.02000000", "0.00000000"], ["72607.12000000", "0.04634000"], ["72598.21000000", "1.83771000"], ["72578.86000000", "0.00000000"], ["72510.53000000", "0.00007000"], ["72506.90000000", "0.00017000"], ["72452.90000000", "0.00000000"], ["72452.64000000", "0.00000000"], ["72003.30000000", "0.00000000"], ["71999.72000000", "0.00007000"], ["71933.12000000", "0.01730000"], ["71111.24000000", "0.00492000"], ["65440.80000000", "0.00051000"], ["58169.60000000", "0.00133000"]], "a": [["72712.01000000", "4.57540000"], ["72712.02000000", "0.54303000"], ["72712.34000000", "0.00008000"], ["72712.35000000", "0.00000000"], ["72712.36000000", "0.00016000"], ["72712.55000000", "0.00031000"], ["72712.72000000", "0.00016000"], ["72712.73000000", "0.28179000"], ["72712.81000000", "0.00016000"], ["72712.82000000", "0.50000000"], ["72713.03000000", "0.00000000"], ["72713.36000000", "0.00008000"], ["72713.37000000", "0.17472000"], ["72713.99000000", "0.17480000"], ["72714.00000000", "0.65965000"], ["72714.01000000", "0.00000000"], ["72714.29000000", "0.00000000"], ["72714.39000000", "0.01280000"], ["72714.46000000", "0.00400000"], ["72714.73000000", "0.00000000"], ["72715.06000000", "0.00016000"], ["72715.13000000", "0.00000000"], ["72715.16000000", "0.05016000"], ["72715.57000000", "0.00000000"], ["72716.01000000", "0.00000000"], ["72716.09000000", "0.17472000"], ["72717.45000000", "0.17472000"], ["72717.88000000", "0.17480000"], ["72717.89000000", "0.68580000"], ["72718.01000000", "0.40372000"], ["72718.92000000", "0.17480000"], ["72721.09000000", "0.00007000"], ["72721.53000000", "0.17472000"], ["72722.01000000", "0.17480000"], ["72724.25000000", "0.17472000"], ["72724.72000000", "0.00007000"], ["72724.99000000", "0.17489000"], ["72725.99000000", "0.17480000"], ["72727.85000000", "0.00008000"], ["72727.86000000", "1.26376000"], ["72729.15000000", "0.00573000"], ["72729.69000000", "0.00000000"], ["72729.98000000", "2.74987000"], ["72731.05000000", "0.00000000"], ["72731.59000000", "0.20697000"], ["72731.60000000", "0.00000000"], ["72731.61000000", "0.00000000"], ["72733.77000000", "0.00000000"], ["72734.80000000", "0.00000000"], ["72736.37000000", "0.97615000"], ["72736.49000000", "0.00000000"], ["72737.03000000", "0.00008000"], ["72738.28000000", "0.00008000"], ["72740.46000000", "0.00008000"], ["72741.23000000", "0.00008000"], ["72741.76000000", "0.00000000"], ["72742.33000000", "0.00458000"], ["72742.38000000", "0.00000000"], ["72743.08000000", "0.00200000"], ["72743.58000000", "0.00000000"], ["72745.53000000", "0.33575000"], ["72748.66000000", "1.03920000"], ["72748.93000000", "0.00000000"], ["72749.07000000", "1.45853000"], ["72750.57000000", "0.43346000"], ["72755.49000000", "0.00000000"], ["72755.88000000", "0.00000000"], ["72758.53000000", "0.02652000"], ["72762.37000000", "0.00000000"], ["72763.00000000", "0.09179000"], ["72770.62000000", "0.26000000"], ["72770.70000000", "0.00100000"], ["72774.50000000", "0.00000000"], ["72786.95000000", "0.00000000"], ["72810.61000000", "0.00032000"], ["72828.20000000", "0.00000000"], ["72833.89000000", "0.02332000"], ["72859.88000000", "0.00000000"], ["72912.22000000", "0.00000000"], ["72914.11000000", "0.00000000"], ["72957.41000000", "0.00000000"], ["73010.70000000", "0.00100000"], ["73086.17000000", "0.00000000"], ["73183.76000000", "0.00000000"], ["73191.20000000", "0.00000000"], ["73192.52000000", "0.00100000"], ["73268.18000000", "0.00000000"], ["73454.29000000", "0.00007000"], ["73457.93000000", "0.00000000"], ["77865.98000000", "0.00011000"], ["78600.57000000", "0.00000000"], ["79335.15000000", "0.00000000"], ["80069.74000000", "0.00000000"], ["82273.49000000", "0.00000000"], ["87415.59000000", "0.00000000"], ["88150.17000000", "0.00000000"], ["88884.76000000", "0.00000000"], ["94761.43000000", "0.00000000"], ["95496.02000000", "0.00006000"], ["101372.70000000", "0.00000000"], ["104311.04000000", "0.00000000"]], "_local_ts_utc": "2026-06-01T07:49:04.610753+00:00"}
{"e": "depthUpdate", "E": 1780300145814, "s": "BTCUSDT", "U": 94551781493, "u": 94551781618, "b": [["72712.00000000", "2.50146000"], ["72711.73000000", "0.00000000"], ["72711.09000000", "0.00000000"], ["72710.01000000", "0.00024000"], ["72709.57000000", "0.00000000"], ["72709.24000000", "0.08805000"], ["72706.43000000", "0.01376000"], ["72705.20000000", "0.16194000"], ["72703.52000000", "0.00000000"], ["72702.80000000", "0.17057000"], ["72702.14000000", "0.05942000"], ["72700.09000000", "3.40936000"], ["72700.08000000", "0.00000000"], ["72699.28000000", "0.00000000"], ["72698.40000000", "0.00008000"], ["72697.46000000", "0.00007000"], ["72694.65000000", "0.03982000"], ["72687.13000000", "0.08255000"], ["72686.56000000", "0.00112000"], ["72682.08000000", "0.17472000"], ["72682.07000000", "0.58328000"], ["72678.00000000", "1.05451000"], ["72677.54000000", "0.00023000"], ["72658.96000000", "0.16916000"], ["72657.61000000", "0.17472000"], ["72652.57000000", "0.00343000"], ["72648.23000000", "0.00000000"], ["72648.22000000", "0.06921000"], ["72632.16000000", "0.00032000"], ["72618.20000000", "0.00008000"], ["72611.02000000", "0.00000000"], ["72578.86000000", "0.00137000"], ["72520.94000000", "0.00000000"], ["72501.01000000", "0.00822000"], ["72173.63000000", "0.04485000"], ["71999.72000000", "0.00000000"], ["71990.81000000", "0.00007000"], ["71787.36000000", "0.01735000"], ["71621.32000000", "0.00348000"], ["71422.96000000", "0.01047000"], ["70694.15000000", "0.01067000"], ["65440.80000000", "0.00085000"]], "a": [["72712.01000000", "3.86092000"], ["72712.37000000", "0.00016000"], ["72712.55000000", "0.00000000"], ["72712.72000000", "0.00016000"], ["72712.73000000", "0.28179000"], ["72712.80000000", "0.00000000"], ["72712.81000000", "0.00016000"], ["72712.82000000", "0.50016000"], ["72713.36000000", "0.00000000"], ["72713.37000000", "0.00016000"], ["72713.99000000", "0.00032000"], ["72714.39000000", "0.01280000"], ["72714.46000000", "0.00431000"], ["72715.06000000", "0.00000000"], ["72717.89000000", "0.68564000"], ["72718.01000000", "0.40356000"], ["72718.92000000", "0.00008000"], ["72720.48000000", "0.00008000"], ["72721.53000000", "0.00000000"], ["72722.01000000", "0.54021000"], ["72724.99000000", "0.71469000"], ["72725.99000000", "0.00008000"], ["72726.00000000", "0.00000000"], ["72726.31000000", "0.00000000"], ["72726.60000000", "0.00021000"], ["72729.97000000", "0.68857000"], ["72735.48000000", "0.00000000"], ["72748.46000000", "0.00000000"], ["72748.93000000", "0.00108000"], ["72749.07000000", "1.45835000"], ["72752.90000000", "0.02647000"], ["72758.53000000", "0.00000000"], ["72803.48000000", "0.00000000"], ["72828.00000000", "0.02280000"], ["73445.20000000", "0.00007000"], ["73454.29000000", "0.00000000"], ["77479.82000000", "0.00051000"]], "_local_ts_utc": "2026-06-01T07:49:04.710387+00:00"}
{"e": "depthUpdate", "E": 1780300145914, "s": "BTCUSDT", "U": 94551781619, "u": 94551781895, "b": [["72712.00000000", "2.65478000"], ["72711.99000000", "0.00088000"], ["72710.02000000", "0.00016000"], ["72710.01000000", "0.00024000"], ["72708.33000000", "0.00038000"], ["72708.01000000", "0.00000000"], ["72707.28000000", "0.00000000"], ["72707.18000000", "0.00400000"], ["72706.60000000", "0.00000000"], ["72706.56000000", "0.00035000"], ["72706.43000000", "0.00000000"], ["72705.25000000", "0.00000000"], ["72705.20000000", "0.00000000"], ["72705.01000000", "0.05950000"], ["72703.91000000", "0.00000000"], ["72703.90000000", "0.17343000"], ["72702.80000000", "0.00000000"], ["72702.20000000", "0.00000000"], ["72702.14000000", "0.00000000"], ["72700.11000000", "0.00000000"], ["72700.10000000", "3.40936000"], ["72700.09000000", "0.00000000"], ["72698.50000000", "0.17343000"], ["72697.46000000", "0.00014000"], ["72697.15000000", "0.17343000"], ["72696.19000000", "0.55991000"], ["72696.06000000", "0.65949000"], ["72696.05000000", "0.00000000"], ["72696.03000000", "0.00000000"], ["72696.02000000", "0.00000000"], ["72696.01000000", "0.00008000"], ["72694.53000000", "0.00008000"], ["72694.45000000", "0.17350000"], ["72693.53000000", "0.03000000"], ["72693.10000000", "0.17343000"], ["72692.76000000", "0.00000000"], ["72692.57000000", "0.65949000"], ["72692.53000000", "0.00000000"], ["72692.02000000", "0.00000000"], ["72689.83000000", "0.00000000"], ["72689.63000000", "0.40856000"], ["72689.62000000", "0.00000000"], ["72685.53000000", "0.12000000"], ["72683.65000000", "0.17343000"], ["72683.38000000", "0.64883000"], ["72682.91000000", "0.00686000"], ["72682.30000000", "0.17352000"], ["72682.07000000", "0.40856000"], ["72679.28000000", "0.00102000"], ["72676.24000000", "0.00000000"], ["72670.29000000", "0.00000000"], ["72664.55000000", "0.79905000"], ["72663.31000000", "0.00000000"], ["72661.57000000", "0.29312000"], ["72660.16000000", "1.21670000"], ["72659.35000000", "0.17343000"], ["72658.96000000", "0.00000000"], ["72658.46000000", "0.17343000"], ["72657.97000000", "0.03298000"], ["72657.91000000", "0.00060000"], ["72657.61000000", "0.17343000"], ["72653.83000000", "0.00685000"], ["72650.01000000", "0.76218000"], ["72649.02000000", "0.36892000"], ["72648.58000000", "0.00000000"], ["72647.14000000", "0.03300000"], ["72646.87000000", "0.04127000"], ["72611.09000000", "0.01692000"], ["72611.02000000", "0.00000000"], ["71990.81000000", "0.00000000"], ["71984.88000000", "0.00007000"], ["71500.00000000", "18.10843000"], ["71277.37000000", "0.02415000"], ["65440.80000000", "0.00119000"]], "a": [["72712.01000000", "3.53419000"], ["72712.02000000", "0.18116000"], ["72712.36000000", "0.00000000"], ["72712.37000000", "0.00000000"], ["72712.71000000", "0.00016000"], ["72712.72000000", "0.17359000"], ["72712.80000000", "0.00016000"], ["72712.81000000", "0.00016000"], ["72712.82000000", "0.50016000"], ["72712.99000000", "0.00031000"], ["72713.37000000", "0.00000000"], ["72713.68000000", "0.00031000"], ["72713.90000000", "0.00031000"], ["72713.99000000", "0.00008000"], ["72714.46000000", "0.00400000"], ["72715.16000000", "0.05032000"], ["72716.03000000", "0.00028000"], ["72716.06000000", "0.17343000"], ["72716.08000000", "0.00000000"], ["72716.09000000", "0.17488000"], ["72717.45000000", "0.17488000"], ["72717.88000000", "0.00008000"], ["72718.01000000", "0.40325000"], ["72718.92000000", "0.17351000"], ["72721.46000000", "0.17343000"], ["72723.16000000", "0.03407000"], ["72723.40000000", "0.00742000"], ["72724.16000000", "0.17343000"], ["72724.25000000", "0.00000000"], ["72724.99000000", "0.53997000"], ["72726.86000000", "0.17351000"], ["72727.85000000", "0.00008000"], ["72728.29000000", "0.00000000"], ["72728.32000000", "0.00000000"], ["72728.46000000", "0.00000000"], ["72728.77000000", "0.20000000"], ["72729.12000000", "0.00000000"], ["72729.13000000", "0.00000000"], ["72729.27000000", "0.00000000"], ["72729.28000000", "0.00000000"], ["72729.43000000", "0.00000000"], ["72729.51000000", "0.00000000"], ["72729.52000000", "0.00000000"], ["72729.56000000", "0.00400000"], ["72729.63000000", "0.00000000"], ["72729.69000000", "0.00000000"], ["72729.75000000", "0.00000000"], ["72729.76000000", "0.00000000"], ["72729.96000000", "0.00000000"], ["72729.98000000", "2.74987000"], ["72730.00000000", "0.00000000"], ["72730.02000000", "0.00000000"], ["72730.08000000", "0.00000000"], ["72730.18000000", "0.00000000"], ["72730.40000000", "0.27000000"], ["72730.75000000", "0.00000000"], ["72730.94000000", "0.00000000"], ["72731.05000000", "0.00000000"], ["72732.80000000", "0.00008000"], ["72734.95000000", "0.00200000"], ["72740.33000000", "0.00000000"], ["72741.44000000", "0.00686000"], ["72748.66000000", "1.04028000"], ["72748.93000000", "0.00000000"], ["72770.52000000", "0.00685000"], ["72777.46000000", "0.00687000"], ["72779.72000000", "0.00000000"], ["72807.74000000", "0.50000000"], ["72847.01000000", "0.00032000"], ["72847.40000000", "0.00000000"], ["73439.14000000", "0.00007000"], ["73445.20000000", "0.00000000"], ["73464.70000000", "0.00017000"], ["74917.40000000", "0.00000000"]], "_local_ts_utc": "2026-06-01T07:49:04.810271+00:00"}
{"e": "depthUpdate", "E": 1780300146014, "s": "BTCUSDT", "U": 94551781896, "u": 94551782060, "b": [["72712.00000000", "2.29491000"], ["72711.99000000", "0.00080000"], ["72711.67000000", "0.00000000"], ["72710.02000000", "0.00000000"], ["72710.01000000", "0.00024000"], ["72709.28000000", "0.00031000"], ["72708.33000000", "0.00046000"], ["72708.21000000", "0.00000000"], ["72705.02000000", "0.00020000"], ["72704.72000000", "0.00300000"], ["72703.91000000", "0.18667000"], ["72700.11000000", "1.30258000"], ["72700.10000000", "0.65949000"], ["72698.50000000", "0.00000000"], ["72697.44000000", "0.00300000"], ["72697.15000000", "0.00000000"], ["72697.04000000", "0.00000000"], ["72696.65000000", "0.02000000"], ["72696.08000000", "0.03407000"], ["72694.45000000", "0.00007000"], ["72693.11000000", "0.77228000"], ["72692.96000000", "0.00000000"], ["72687.80000000", "0.00000000"], ["72685.70000000", "0.00686000"], ["72685.38000000", "0.00200000"], ["72685.11000000", "0.00000000"], ["72683.65000000", "0.00000000"], ["72683.38000000", "0.00000000"], ["72682.33000000", "0.00000000"], ["72677.57000000", "0.02731000"], ["72662.92000000", "0.00343000"], ["72661.57000000", "0.21618000"], ["72660.16000000", "0.00000000"], ["72659.35000000", "0.00000000"], ["72658.46000000", "0.00000000"], ["72657.61000000", "0.00000000"], ["72656.50000000", "0.02828000"], ["72651.35000000", "0.02000000"], ["72650.12000000", "0.01436000"], ["72646.27000000", "0.00000000"], ["72643.16000000", "0.00000000"], ["72627.51000000", "0.00000000"], ["72611.02000000", "2.74987000"], ["72604.89000000", "0.06336000"], ["72598.21000000", "0.00000000"], ["72589.51000000", "0.00137000"], ["72432.29000000", "3.04775000"], ["72429.34000000", "1.84192000"], ["72425.22000000", "0.00000000"], ["72422.26000000", "0.00000000"], ["72173.63000000", "0.03795000"], ["65440.80000000", "0.00153000"], ["58170.00000000", "0.03009000"], ["58169.60000000", "0.00167000"]], "a": [["72712.01000000", "3.53428000"], ["72712.02000000", "0.18116000"], ["72712.72000000", "0.72979000"], ["72712.80000000", "0.00000000"], ["72713.01000000", "0.00008000"], ["72713.90000000", "0.00000000"], ["72713.99000000", "0.17351000"], ["72715.16000000", "0.05032000"], ["72716.06000000", "0.17359000"], ["72716.09000000", "0.17472000"], ["72717.45000000", "0.17472000"], ["72718.82000000", "0.01376000"], ["72719.29000000", "0.27300000"], ["72724.98000000", "0.17343000"], ["72725.78000000", "0.09400000"], ["72726.57000000", "0.00300000"], ["72728.89000000", "0.00000000"], ["72728.91000000", "0.00400000"], ["72729.15000000", "0.00573000"], ["72729.19000000", "0.00000000"], ["72729.23000000", "0.00000000"], ["72729.24000000", "0.00000000"], ["72729.25000000", "0.00000000"], ["72729.26000000", "0.00000000"], ["72729.28000000", "0.00000000"], ["72729.39000000", "0.00000000"], ["72729.42000000", "0.00000000"], ["72729.45000000", "0.00000000"], ["72729.46000000", "0.00000000"], ["72729.50000000", "0.00000000"], ["72729.51000000", "0.00000000"], ["72729.55000000", "0.00000000"], ["72729.56000000", "0.00000000"], ["72729.58000000", "0.00000000"], ["72729.62000000", "0.00000000"], ["72729.66000000", "0.00000000"], ["72729.96000000", "0.45885000"], ["72737.90000000", "0.00000000"], ["72743.08000000", "0.00000000"], ["72743.52000000", "0.00200000"], ["72749.07000000", "1.45853000"], ["72749.29000000", "0.27000000"], ["72768.66000000", "0.00189000"], ["72807.73000000", "0.34217000"], ["72809.33000000", "0.00000000"], ["72828.45000000", "0.00000000"], ["72841.09000000", "0.00075000"], ["73057.54000000", "0.00000000"]], "_local_ts_utc": "2026-06-01T07:49:04.912778+00:00"}
{"e": "depthUpdate", "E": 1780300146115, "s": "BTCUSDT", "U": 94551782061, "u": 94551783098, "b": [["72712.00000000", "0.00000000"], ["72711.99000000", "0.00000000"], ["72711.45000000", "0.00000000"], ["72710.89000000", "0.00000000"], ["72710.88000000", "0.00000000"], ["72710.87000000", "0.00000000"], ["72710.86000000", "0.00000000"], ["72710.80000000", "0.00000000"], ["72710.76000000", "0.00000000"], ["72710.75000000", "0.00000000"], ["72710.72000000", "0.00000000"], ["72710.62000000", "0.00000000"], ["72710.52000000", "0.00000000"], ["72710.40000000", "0.00000000"], ["72710.38000000", "0.00000000"], ["72710.20000000", "0.00000000"], ["72710.17000000", "0.00000000"], ["72710.01000000", "0.00000000"], ["72710.00000000", "0.00000000"], ["72709.99000000", "0.00000000"], ["72709.98000000", "0.00000000"], ["72709.88000000", "0.00000000"], ["72709.84000000", "0.00000000"], ["72709.78000000", "0.00000000"], ["72709.77000000", "0.00000000"], ["72709.67000000", "0.00000000"], ["72709.54000000", "0.00000000"], ["72709.44000000", "0.00000000"], ["72709.37000000", "0.00000000"], ["72709.34000000", "0.00000000"], ["72709.28000000", "0.00000000"], ["72709.27000000", "0.00000000"], ["72709.25000000", "0.00000000"], ["72709.24000000", "0.00000000"], ["72709.09000000", "0.00000000"], ["72709.06000000", "0.00000000"], ["72709.05000000", "0.00000000"], ["72708.33000000", "0.00054000"], ["72708.32000000", "0.00026000"], ["72708.20000000", "0.00589000"], ["72708.01000000", "0.00016000"], ["72708.00000000", "0.02377000"], ["72707.91000000", "0.00000000"], ["72707.81000000", "0.00019000"], ["72707.80000000", "0.04016000"], ["72707.43000000", "0.00000000"], ["72707.18000000", "0.00000000"], ["72706.56000000", "0.00007000"], ["72705.36000000", "0.00000000"], ["72705.02000000", "0.00000000"], ["72705.01000000", "0.00008000"], ["72703.91000000", "0.00000000"], ["72703.90000000", "0.00000000"], ["72703.84000000", "0.00010000"], ["72703.65000000", "0.00000000"], ["72702.86000000", "0.00000000"], ["72702.82000000", "0.00000000"], ["72702.61000000", "0.00000000"], ["72702.48000000", "0.00000000"], ["72702.46000000", "0.00000000"], ["72702.01000000", "0.02838000"], ["72701.74000000", "0.00000000"], ["72700.94000000", "0.00000000"], ["72700.80000000", "0.00000000"], ["72700.68000000", "0.00000000"], ["72700.56000000", "0.00000000"], ["72700.11000000", "0.00000000"], ["72700.10000000", "0.00000000"], ["72698.80000000", "0.00000000"], ["72697.46000000", "0.00021000"], ["72696.20000000", "0.00000000"], ["72696.19000000", "0.00000000"], ["72696.08000000", "0.00000000"], ["72696.06000000", "0.00000000"], ["72695.88000000", "0.00000000"], ["72694.74000000", "0.00000000"], ["72694.71000000", "0.02000000"], ["72694.47000000", "0.00000000"], ["72693.97000000", "0.00000000"], ["72693.53000000", "0.00000000"], ["72693.11000000", "0.00000000"], ["72693.10000000", "0.00000000"], ["72692.63000000", "0.00000000"], ["72692.58000000", "0.00000000"], ["72692.57000000", "0.00000000"], ["72692.56000000", "0.00008000"], ["72692.55000000", "0.00000000"], ["72692.53000000", "0.00000000"], ["72691.53000000", "0.00000000"], ["72691.48000000", "0.00000000"], ["72690.19000000", "0.00102000"], ["72689.64000000", "0.00000000"], ["72689.63000000", "0.00000000"], ["72689.60000000", "0.31439000"], ["72689.53000000", "0.00000000"], ["72688.46000000", "0.65949000"], ["72688.45000000", "0.17352000"], ["72688.44000000", "0.00000000"], ["72687.53000000", "0.03000000"], ["72687.13000000", "0.00000000"], ["72687.04000000", "0.17389000"], ["72686.88000000", "0.00000000"], ["72686.58000000", "0.17343000"], ["72686.42000000", "0.10631000"], ["72685.70000000", "0.00000000"], ["72685.33000000", "0.00000000"], ["72685.23000000", "0.17343000"], ["72685.09000000", "0.65949000"], ["72684.75000000", "0.00000000"], ["72684.29000000", "0.00000000"], ["72683.88000000", "0.17343000"], ["72683.65000000", "0.00000000"], ["72682.91000000", "0.00000000"], ["72682.53000000", "0.17355000"], ["72682.30000000", "0.00009000"], ["72682.17000000", "0.65949000"], ["72682.09000000", "2.75064000"], ["72682.08000000", "0.00000000"], ["72682.07000000", "0.00000000"], ["72682.06000000", "0.88093000"], ["72682.05000000", "0.00008000"], ["72681.59000000", "0.00000000"], ["72680.29000000", "0.17344000"], ["72680.15000000", "0.02000000"], ["72680.01000000", "0.17658000"], ["72679.64000000", "0.00000000"], ["72678.48000000", "0.17343000"], ["72678.03000000", "0.00000000"], ["72678.02000000", "0.00007000"], ["72676.24000000", "0.17344000"], ["72676.07000000", "0.03353000"], ["72675.78000000", "0.17343000"], ["72674.55000000", "0.00007000"], ["72674.43000000", "0.17356000"], ["72673.34000000", "0.17343000"], ["72671.74000000", "0.00000000"], ["72671.73000000", "0.17343000"], ["72671.29000000", "0.00000000"], ["72669.49000000", "0.27364000"], ["72669.48000000", "0.02848000"], ["72669.28000000", "0.17343000"], ["72667.22000000", "0.00000000"], ["72666.33000000", "0.17343000"], ["72664.98000000", "0.17343000"], ["72664.56000000", "0.00000000"], ["72664.55000000", "0.33678000"], ["72662.92000000", "0.00000000"], ["72662.91000000", "0.00000000"], ["72662.74000000", "0.17357000"], ["72662.28000000", "0.17343000"], ["72662.03000000", "0.00000000"], ["72661.57000000", "0.00000000"], ["72660.93000000", "0.17343000"], ["72660.67000000", "0.00000000"], ["72659.58000000", "0.17343000"], ["72659.35000000", "0.00000000"], ["72658.94000000", "0.00020000"], ["72658.46000000", "0.00000000"], ["72658.45000000", "0.00000000"], ["72658.23000000", "0.17343000"], ["72658.00000000", "0.02300000"], ["72657.61000000", "0.00000000"], ["72657.58000000", "0.04710000"], ["72656.01000000", "0.17214000"], ["72653.99000000", "0.00000000"], ["72653.83000000", "0.00000000"], ["72653.41000000", "0.01375000"], ["72652.39000000", "0.00000000"], ["72650.81000000", "0.00020000"], ["72650.12000000", "0.00000000"], ["72650.04000000", "0.00686000"], ["72649.28000000", "0.02000000"], ["72647.11000000", "0.18446000"], ["72645.67000000", "0.01276000"], ["72644.46000000", "0.04103000"], ["72643.47000000", "0.00000000"], ["72643.20000000", "0.49627000"], ["72642.83000000", "0.00017000"], ["72633.14000000", "1.36472000"], ["72628.48000000", "0.00008000"], ["72619.51000000", "0.01286000"], ["72617.88000000", "0.00686000"], ["72615.64000000", "0.00000000"], ["72615.23000000", "0.00000000"], ["72615.14000000", "0.00000000"], ["72607.52000000", "0.00686000"], ["72600.55000000", "2.75057000"], ["72593.14000000", "1.83883000"], ["72589.51000000", "0.00000000"], ["72584.64000000", "0.02000000"], ["72578.84000000", "0.00000000"], ["72561.48000000", "0.00000000"], ["72561.39000000", "2.84261000"], ["72542.44000000", "0.00000000"], ["72519.85000000", "0.00007000"], ["72511.10000000", "4.14250000"], ["72421.65000000", "0.00000000"], ["72201.65000000", "0.00000000"], ["72073.35000000", "0.60277000"], ["65440.80000000", "0.00000000"], ["58372.88000000", "0.00019000"], ["58170.00000000", "0.02809000"]], "a": [["72709.25000000", "2.77570000"], ["72709.78000000", "2.24280000"], ["72710.00000000", "5.55894000"], ["72710.01000000", "6.07844000"], ["72710.02000000", "0.00014000"], ["72710.18000000", "0.00000000"], ["72710.21000000", "0.00000000"], ["72710.39000000", "0.00000000"], ["72710.41000000", "0.00000000"], ["72710.53000000", "0.00000000"], ["72710.63000000", "0.00000000"], ["72710.76000000", "0.00000000"], ["72710.77000000", "1.26440000"], ["72710.78000000", "0.00000000"], ["72710.79000000", "0.00000000"], ["72710.80000000", "0.00024000"], ["72710.81000000", "0.00000000"], ["72710.88000000", "0.45806000"], ["72710.89000000", "3.59114000"], ["72710.90000000", "0.00000000"], ["72710.91000000", "0.00000000"], ["72711.45000000", "0.00007000"], ["72711.46000000", "0.19660000"], ["72711.99000000", "0.00000000"], ["72712.00000000", "0.19413000"], ["72712.01000000", "1.18377000"], ["72712.02000000", "0.18003000"], ["72712.03000000", "0.00000000"], ["72712.71000000", "0.00000000"], ["72712.72000000", "0.00016000"], ["72712.73000000", "0.00016000"], ["72712.81000000", "0.00000000"], ["72712.82000000", "0.50016000"], ["72713.13000000", "0.00000000"], ["72713.41000000", "0.01370000"], ["72713.67000000", "0.00000000"], ["72713.68000000", "0.00000000"], ["72713.99000000", "0.00008000"], ["72714.00000000", "0.65949000"], ["72714.39000000", "0.01264000"], ["72714.60000000", "0.03407000"], ["72714.65000000", "0.00750000"], ["72715.07000000", "0.00000000"], ["72715.16000000", "0.00000000"], ["72715.21000000", "0.00008000"], ["72716.06000000", "0.00000000"], ["72716.09000000", "0.00000000"], ["72717.45000000", "0.00000000"], ["72717.60000000", "0.00009000"], ["72717.88000000", "0.00008000"], ["72718.29000000", "0.00740000"], ["72718.82000000", "0.00000000"], ["72718.92000000", "0.00008000"], ["72719.34000000", "0.00000000"], ["72720.34000000", "0.00000000"], ["72720.65000000", "0.59053000"], ["72720.66000000", "0.50000000"], ["72720.77000000", "0.00008000"], ["72720.89000000", "0.00016000"], ["72721.45000000", "0.68854000"], ["72721.46000000", "0.00000000"], ["72722.01000000", "0.00008000"], ["72722.81000000", "0.00400000"], ["72723.41000000", "0.00159000"], ["72723.61000000", "2.75057000"], ["72724.16000000", "0.00008000"], ["72724.23000000", "0.00000000"], ["72724.54000000", "0.00000000"], ["72724.96000000", "0.91070000"], ["72724.97000000", "0.00000000"], ["72724.98000000", "0.00000000"], ["72724.99000000", "0.00017000"], ["72725.01000000", "0.04098000"], ["72726.83000000", "0.00000000"], ["72726.86000000", "0.00008000"], ["72726.91000000", "0.00000000"], ["72726.93000000", "0.00000000"], ["72726.94000000", "0.00000000"], ["72727.00000000", "0.00025000"], ["72727.45000000", "0.00008000"], ["72727.46000000", "0.04000000"], ["72727.85000000", "0.00008000"], ["72727.89000000", "0.00008000"], ["72727.91000000", "0.06600000"], ["72728.24000000", "0.00000000"], ["72728.33000000", "0.00000000"], ["72728.38000000", "0.00000000"], ["72728.39000000", "0.00000000"], ["72728.41000000", "0.00000000"], ["72728.42000000", "0.00000000"], ["72728.44000000", "0.00000000"], ["72728.45000000", "0.00000000"], ["72728.63000000", "0.00000000"], ["72728.82000000", "0.00000000"], ["72728.83000000", "0.00000000"], ["72728.84000000", "0.00000000"], ["72728.91000000", "0.00000000"], ["72728.94000000", "0.00000000"], ["72729.56000000", "0.00000000"], ["72729.95000000", "0.00000000"], ["72729.96000000", "0.00000000"], ["72729.97000000", "0.00008000"], ["72731.58000000", "0.00000000"], ["72731.59000000", "0.58508000"], ["72733.34000000", "0.00000000"], ["72733.36000000", "1.36284000"], ["72733.61000000", "0.00000000"], ["72734.80000000", "0.00000000"], ["72736.31000000", "0.00000000"], ["72736.36000000", "0.00000000"], ["72736.37000000", "0.96874000"], ["72737.03000000", "0.00008000"], ["72740.84000000", "0.00000000"], ["72741.23000000", "0.00008000"], ["72741.44000000", "0.00000000"], ["72742.37000000", "0.49559000"], ["72746.95000000", "0.00000000"], ["72748.35000000", "0.00883000"], ["72748.75000000", "0.02651000"], ["72752.90000000", "0.00000000"], ["72757.86000000", "1.36238000"], ["72758.13000000", "0.00000000"], ["72763.78000000", "0.01373000"], ["72768.46000000", "0.00686000"], ["72769.28000000", "0.00000000"], ["72770.52000000", "0.00000000"], ["72790.25000000", "0.02415000"], ["72800.44000000", "0.00000000"], ["72807.73000000", "0.00000000"], ["72815.52000000", "0.00000000"], ["72817.72000000", "0.00000000"], ["72817.73000000", "0.00000000"], ["72821.06000000", "0.00009000"], ["72821.99000000", "0.00000000"], ["72829.57000000", "0.00000000"], ["72833.89000000", "0.00000000"], ["72838.24000000", "0.00000000"], ["72839.64000000", "0.00000000"], ["72855.42000000", "0.00010000"], ["72863.45000000", "0.00000000"], ["72883.67000000", "0.22299000"], ["72902.53000000", "0.00000000"], ["72910.11000000", "0.00000000"], ["72912.36000000", "0.00007000"], ["72915.99000000", "0.00007000"], ["73027.01000000", "0.00000000"], ["73038.18000000", "0.00000000"], ["73792.87000000", "1.72600000"], ["73801.97000000", "0.00000000"], ["77843.57000000", "0.00421000"]], "_local_ts_utc": "2026-06-01T07:49:05.010760+00:00"}
{"e": "depthUpdate", "E": 1780300146214, "s": "BTCUSDT", "U": 94551783099, "u": 94551784738, "b": [["72709.05000000", "0.00000000"], ["72709.04000000", "0.00000000"], ["72708.86000000", "0.00000000"], ["72708.85000000", "0.00000000"], ["72708.79000000", "0.00000000"], ["72708.78000000", "0.00000000"], ["72708.62000000", "0.00000000"], ["72708.49000000", "0.00000000"], ["72708.33000000", "0.00000000"], ["72708.32000000", "0.00000000"], ["72708.20000000", "0.00000000"], ["72708.01000000", "0.00000000"], ["72708.00000000", "0.00000000"], ["72707.97000000", "0.00000000"], ["72707.95000000", "0.00000000"], ["72707.81000000", "0.00000000"], ["72707.80000000", "0.00000000"], ["72707.79000000", "0.00000000"], ["72707.76000000", "0.00000000"], ["72707.71000000", "0.00000000"], ["72707.62000000", "0.00000000"], ["72707.24000000", "0.00000000"], ["72707.09000000", "0.00000000"], ["72707.00000000", "0.00000000"], ["72706.67000000", "0.00000000"], ["72706.56000000", "0.00000000"], ["72706.35000000", "0.00000000"], ["72706.16000000", "0.00000000"], ["72706.11000000", "0.00000000"], ["72706.04000000", "0.00000000"], ["72706.01000000", "0.00000000"], ["72706.00000000", "0.00000000"], ["72705.90000000", "0.00000000"], ["72705.88000000", "0.00000000"], ["72705.76000000", "0.00000000"], ["72705.75000000", "0.00000000"], ["72705.66000000", "0.00000000"], ["72705.50000000", "0.00000000"], ["72705.49000000", "0.00000000"], ["72705.45000000", "0.00000000"], ["72705.44000000", "0.00000000"], ["72705.39000000", "0.00000000"], ["72705.11000000", "0.00000000"], ["72705.08000000", "0.00000000"], ["72705.01000000", "0.00000000"], ["72705.00000000", "0.00000000"], ["72704.72000000", "0.00000000"], ["72704.67000000", "0.00000000"], ["72704.64000000", "0.00000000"], ["72704.49000000", "0.00000000"], ["72704.35000000", "0.00000000"], ["72704.07000000", "0.00000000"], ["72704.04000000", "0.00000000"], ["72704.03000000", "0.00000000"], ["72704.01000000", "0.00000000"], ["72704.00000000", "3.05121000"], ["72703.99000000", "0.00056000"], ["72703.60000000", "0.00787000"], ["72703.54000000", "0.00000000"], ["72703.09000000", "0.00000000"], ["72703.03000000", "0.00000000"], ["72703.02000000", "0.00000000"], ["72702.95000000", "0.00016000"], ["72702.02000000", "0.00016000"], ["72702.01000000", "0.02854000"], ["72701.72000000", "0.00000000"], ["72701.66000000", "0.00000000"], ["72700.37000000", "0.00031000"], ["72700.33000000", "0.00000000"], ["72700.01000000", "0.00079000"], ["72699.90000000", "0.00000000"], ["72699.55000000", "0.02122000"], ["72699.49000000", "0.00000000"], ["72699.44000000", "0.00000000"], ["72699.33000000", "0.00000000"], ["72699.25000000", "0.00000000"], ["72698.87000000", "0.00000000"], ["72698.11000000", "0.00028000"], ["72698.01000000", "0.00000000"], ["72697.64000000", "0.00000000"], ["72694.68000000", "0.00940000"], ["72694.32000000", "0.00008000"], ["72693.97000000", "0.00000000"], ["72693.36000000", "0.16758000"], ["72693.02000000", "0.00000000"], ["72692.03000000", "0.17110000"], ["72692.01000000", "0.00000000"], ["72691.85000000", "0.00000000"], ["72691.50000000", "0.00000000"], ["72690.79000000", "0.00020000"], ["72690.70000000", "0.17110000"], ["72690.50000000", "0.16219000"], ["72690.15000000", "0.00000000"], ["72690.02000000", "0.00022000"], ["72689.60000000", "0.00000000"], ["72689.59000000", "0.00048000"], ["72689.15000000", "0.17345000"], ["72688.99000000", "0.00000000"], ["72688.83000000", "0.00007000"], ["72688.47000000", "0.00000000"], ["72688.46000000", "0.00000000"], ["72688.45000000", "0.00008000"], ["72687.70000000", "0.01376000"], ["72686.58000000", "0.00000000"], ["72686.43000000", "0.00000000"], ["72686.42000000", "0.00000000"], ["72685.73000000", "0.00000000"], ["72685.38000000", "0.17110000"], ["72685.24000000", "0.65949000"], ["72685.09000000", "0.00000000"], ["72682.86000000", "0.00626000"], ["72682.81000000", "0.00000000"], ["72682.27000000", "0.00550000"], ["72682.19000000", "0.00137000"], ["72682.18000000", "0.00000000"], ["72682.11000000", "1.40970000"], ["72682.10000000", "0.00000000"], ["72682.09000000", "0.00007000"], ["72682.06000000", "0.00008000"], ["72681.12000000", "0.00000000"], ["72680.55000000", "0.00165000"], ["72680.47000000", "0.04633000"], ["72680.29000000", "0.00000000"], ["72680.06000000", "0.17110000"], ["72680.02000000", "2.75057000"], ["72680.01000000", "0.17660000"], ["72679.86000000", "0.00000000"], ["72678.48000000", "0.00000000"], ["72678.35000000", "0.00000000"], ["72678.02000000", "0.16903000"], ["72677.57000000", "0.00000000"], ["72676.24000000", "0.00000000"], ["72676.08000000", "0.17110000"], ["72675.78000000", "0.00000000"], ["72675.65000000", "0.00000000"], ["72675.42000000", "0.12054000"], ["72675.21000000", "0.23374000"], ["72674.74000000", "0.17110000"], ["72674.43000000", "0.00013000"], ["72674.31000000", "0.17345000"], ["72674.30000000", "0.00000000"], ["72673.35000000", "0.16039000"], ["72673.34000000", "0.00000000"], ["72673.33000000", "0.00012000"], ["72671.77000000", "0.00200000"], ["72671.74000000", "0.15830000"], ["72671.73000000", "0.00000000"], ["72671.29000000", "0.17345000"], ["72670.86000000", "0.00007000"], ["72669.50000000", "0.17110000"], ["72669.49000000", "0.10020000"], ["72669.28000000", "0.17345000"], ["72667.70000000", "0.00239000"], ["72666.33000000", "0.00000000"], ["72666.20000000", "0.00000000"], ["72664.98000000", "0.00000000"], ["72664.85000000", "0.00000000"], ["72664.56000000", "0.00000000"], ["72664.35000000", "0.00420000"], ["72662.77000000", "0.17110000"], ["72662.74000000", "0.00013000"], ["72662.28000000", "0.00000000"], ["72662.16000000", "0.17345000"], ["72662.15000000", "0.00000000"], ["72661.79000000", "0.00102000"], ["72660.94000000", "0.25217000"], ["72660.68000000", "0.00000000"], ["72657.62000000", "0.00000000"], ["72656.01000000", "0.00000000"], ["72655.72000000", "0.00000000"], ["72654.87000000", "0.00343000"], ["72652.57000000", "0.00000000"], ["72650.02000000", "0.65949000"], ["72647.15000000", "0.00342000"], ["72644.77000000", "0.18446000"], ["72642.88000000", "0.00000000"], ["72635.13000000", "0.00000000"], ["72634.32000000", "0.65982000"], ["72630.01000000", "0.00000000"], ["72626.62000000", "0.00000000"], ["72625.70000000", "0.00000000"], ["72624.96000000", "0.00112000"], ["72624.35000000", "0.00000000"], ["72622.01000000", "0.00282000"], ["72616.28000000", "0.36778000"], ["72615.65000000", "0.00000000"], ["72611.03000000", "0.82323000"], ["72610.03000000", "0.35141000"], ["72605.91000000", "0.08131000"], ["72602.92000000", "0.00008000"], ["72593.14000000", "0.00000000"], ["72588.91000000", "0.00000000"], ["72581.83000000", "0.00137000"], ["72561.39000000", "0.00000000"], ["72561.10000000", "0.00000000"], ["72560.49000000", "0.00000000"], ["72559.23000000", "0.00000000"], ["72541.64000000", "0.00412000"], ["72531.94000000", "2.84261000"], ["72525.46000000", "0.00009000"], ["72506.80000000", "0.12264000"], ["72506.16000000", "0.00007000"], ["72502.53000000", "0.00007000"], ["72492.61000000", "0.00000000"], ["72451.98000000", "0.28066000"], ["72426.85000000", "0.00000000"], ["72395.16000000", "1.87787000"], ["72392.19000000", "1.84371000"], ["72173.63000000", "0.03105000"], ["71998.77000000", "0.00346000"], ["71933.12000000", "0.01384000"], ["71787.36000000", "0.01388000"], ["71422.96000000", "0.00698000"], ["71058.56000000", "0.00702000"], ["70522.88000000", "0.00353000"], ["65437.02000000", "0.00000000"], ["65433.60000000", "0.00017000"], ["58372.88000000", "0.00000000"], ["58368.58000000", "0.00000000"], ["58339.93000000", "0.00000000"], ["58292.96000000", "0.00000000"], ["58292.80000000", "0.00000000"], ["58169.60000000", "0.00133000"], ["58167.09000000", "0.00000000"], ["58163.20000000", "0.00171000"]], "a": [["72704.01000000", "3.54406000"], ["72704.02000000", "0.00038000"], ["72704.03000000", "0.00014000"], ["72704.69000000", "0.00016000"], ["72704.70000000", "0.04387000"], ["72705.34000000", "0.17110000"], ["72705.35000000", "0.00016000"], ["72705.36000000", "0.17345000"], ["72705.40000000", "0.00000000"], ["72705.44000000", "0.00024000"], ["72705.45000000", "0.00016000"], ["72705.50000000", "0.00000000"], ["72705.51000000", "0.00000000"], ["72705.56000000", "0.00000000"], ["72705.67000000", "0.00000000"], ["72705.76000000", "0.00016000"], ["72705.77000000", "0.11120000"], ["72705.99000000", "0.00000000"], ["72706.00000000", "0.00000000"], ["72706.01000000", "0.00016000"], ["72706.05000000", "0.00000000"], ["72706.12000000", "0.00000000"], ["72706.17000000", "0.00000000"], ["72706.36000000", "0.00000000"], ["72706.55000000", "0.00008000"], ["72706.56000000", "0.45551000"], ["72706.57000000", "0.00000000"], ["72706.67000000", "0.00000000"], ["72706.68000000", "0.21280000"], ["72706.69000000", "0.00000000"], ["72706.70000000", "0.00000000"], ["72706.99000000", "0.00000000"], ["72707.01000000", "0.00000000"], ["72707.10000000", "0.00000000"], ["72707.15000000", "0.00000000"], ["72707.25000000", "0.00000000"], ["72707.48000000", "0.00000000"], ["72707.63000000", "0.00000000"], ["72707.69000000", "0.00000000"], ["72707.72000000", "0.00000000"], ["72707.76000000", "0.17360000"], ["72707.77000000", "0.00000000"], ["72707.80000000", "0.65949000"], ["72707.81000000", "0.23841000"], ["72707.82000000", "0.00000000"], ["72707.94000000", "0.00000000"], ["72707.98000000", "0.00000000"], ["72707.99000000", "0.00000000"], ["72708.00000000", "0.00000000"], ["72708.01000000", "0.00016000"], ["72708.02000000", "0.00000000"], ["72708.10000000", "0.02000000"], ["72708.19000000", "0.00000000"], ["72708.21000000", "0.00016000"], ["72708.33000000", "0.00000000"], ["72708.34000000", "0.00000000"], ["72708.48000000", "0.00000000"], ["72708.50000000", "0.00000000"], ["72708.63000000", "0.00000000"], ["72708.79000000", "0.00000000"], ["72708.80000000", "0.00000000"], ["72708.87000000", "0.00000000"], ["72708.91000000", "0.00155000"], ["72708.97000000", "0.00000000"], ["72709.04000000", "0.17353000"], ["72709.05000000", "2.00995000"], ["72709.06000000", "0.28566000"], ["72709.07000000", "0.00000000"], ["72709.08000000", "0.00000000"], ["72709.24000000", "0.00000000"], ["72709.25000000", "0.32362000"], ["72709.26000000", "0.00000000"], ["72709.27000000", "0.00000000"], ["72709.38000000", "0.00000000"], ["72709.68000000", "0.00000000"], ["72709.77000000", "0.00688000"], ["72709.78000000", "0.00000000"], ["72709.79000000", "0.00000000"], ["72709.85000000", "0.00000000"], ["72709.89000000", "0.00000000"], ["72709.99000000", "0.00000000"], ["72710.00000000", "0.07328000"], ["72710.01000000", "0.00000000"], ["72710.02000000", "0.00000000"], ["72710.28000000", "0.00000000"], ["72710.76000000", "0.00008000"], ["72710.77000000", "0.60467000"], ["72710.80000000", "0.00000000"], ["72710.88000000", "0.36039000"], ["72710.89000000", "2.56155000"], ["72711.29000000", "0.27000000"], ["72711.46000000", "0.00000000"], ["72711.93000000", "0.65949000"], ["72711.99000000", "0.00688000"], ["72712.00000000", "0.00000000"], ["72712.01000000", "1.18353000"], ["72712.02000000", "0.13865000"], ["72712.34000000", "0.00000000"], ["72712.72000000", "0.00000000"], ["72712.73000000", "0.00000000"], ["72712.81000000", "0.47340000"], ["72712.82000000", "0.50000000"], ["72712.99000000", "0.00000000"], ["72713.00000000", "0.00011000"], ["72713.09000000", "0.00007000"], ["72714.00000000", "0.00000000"], ["72714.39000000", "0.00000000"], ["72714.88000000", "0.00000000"], ["72715.06000000", "0.00028000"], ["72715.08000000", "0.00000000"], ["72715.65000000", "0.65949000"], ["72715.76000000", "0.00007000"], ["72716.61000000", "0.04000000"], ["72717.70000000", "1.54395000"], ["72717.71000000", "0.00000000"], ["72717.81000000", "0.00000000"], ["72717.89000000", "0.00000000"], ["72718.01000000", "0.12084000"], ["72718.43000000", "0.00007000"], ["72718.46000000", "0.00000000"], ["72718.67000000", "0.00573000"], ["72718.92000000", "0.68864000"], ["72718.93000000", "1.06805000"], ["72719.06000000", "0.00000000"], ["72719.25000000", "0.00000000"], ["72719.43000000", "0.00000000"], ["72719.44000000", "0.02127000"], ["72719.52000000", "0.00400000"], ["72719.76000000", "0.00008000"], ["72719.77000000", "0.00000000"], ["72720.00000000", "0.00008000"], ["72720.64000000", "0.00008000"], ["72720.77000000", "0.00000000"], ["72720.89000000", "0.00000000"], ["72721.06000000", "0.00000000"], ["72721.45000000", "0.00000000"], ["72722.01000000", "0.00008000"], ["72722.73000000", "0.00000000"], ["72722.81000000", "0.00000000"], ["72723.41000000", "0.00028000"], ["72723.60000000", "4.10952000"], ["72723.61000000", "0.00000000"], ["72724.15000000", "0.00000000"], ["72724.96000000", "0.00000000"], ["72725.16000000", "0.00008000"], ["72725.82000000", "0.00137000"], ["72725.99000000", "0.00000000"], ["72726.55000000", "0.00008000"], ["72727.00000000", "0.00000000"], ["72727.01000000", "0.02106000"], ["72727.42000000", "0.00121000"], ["72727.45000000", "0.00000000"], ["72727.48000000", "0.00008000"], ["72727.49000000", "0.00000000"], ["72727.86000000", "1.26376000"], ["72727.88000000", "0.00200000"], ["72727.89000000", "0.00000000"], ["72728.42000000", "0.58512000"], ["72728.43000000", "0.00275000"], ["72728.52000000", "0.38337000"], ["72728.77000000", "0.00000000"], ["72729.94000000", "0.00228000"], ["72730.62000000", "0.10077000"], ["72731.19000000", "0.00000000"], ["72733.35000000", "0.00008000"], ["72733.36000000", "0.00000000"], ["72734.44000000", "0.00000000"], ["72734.48000000", "0.00000000"], ["72736.30000000", "0.00000000"], ["72736.36000000", "0.00008000"], ["72737.36000000", "0.00000000"], ["72737.37000000", "0.00000000"], ["72737.44000000", "0.23247000"], ["72738.12000000", "0.00000000"], ["72738.29000000", "0.76760000"], ["72738.47000000", "0.00000000"], ["72739.94000000", "0.00000000"], ["72740.46000000", "0.00000000"], ["72740.97000000", "0.00000000"], ["72741.29000000", "0.00000000"], ["72742.32000000", "0.00426000"], ["72742.37000000", "0.49551000"], ["72742.55000000", "0.00000000"], ["72742.78000000", "0.43387000"], ["72742.87000000", "0.00011000"], ["72743.47000000", "0.00000000"], ["72743.52000000", "0.00000000"], ["72743.84000000", "0.00000000"], ["72744.66000000", "0.00000000"], ["72745.16000000", "0.00000000"], ["72745.53000000", "0.03069000"], ["72748.66000000", "0.00108000"], ["72750.57000000", "0.00000000"], ["72750.71000000", "0.00000000"], ["72753.82000000", "0.81229000"], ["72755.01000000", "0.00000000"], ["72755.04000000", "0.00000000"], ["72757.45000000", "0.02751000"], ["72757.71000000", "0.00000000"], ["72757.85000000", "0.00008000"], ["72757.94000000", "0.00000000"], ["72758.01000000", "0.00000000"], ["72760.47000000", "0.00112000"], ["72761.09000000", "0.01733000"], ["72767.46000000", "1.54839000"], ["72775.56000000", "0.00000000"], ["72775.67000000", "0.00000000"], ["72776.71000000", "0.00008000"], ["72781.94000000", "2.96465000"], ["72784.63000000", "0.00000000"], ["72784.72000000", "0.00007000"], ["72785.97000000", "0.26835000"], ["72785.99000000", "0.00000000"], ["72788.23000000", "0.00000000"], ["72788.24000000", "0.00000000"], ["72790.44000000", "0.00000000"], ["72792.04000000", "0.20371000"], ["72792.13000000", "2.75057000"], ["72793.34000000", "0.00000000"], ["72795.81000000", "0.00693000"], ["72798.65000000", "0.00000000"], ["72799.40000000", "0.00000000"], ["72800.43000000", "0.18446000"], ["72805.91000000", "0.00000000"], ["72806.62000000", "0.00000000"], ["72807.69000000", "0.00000000"], ["72809.98000000", "0.00000000"], ["72812.50000000", "0.00000000"], ["72833.10000000", "0.00000000"], ["72835.96000000", "0.00940000"], ["72847.43000000", "2.06252000"], ["72849.42000000", "0.00008000"], ["72853.98000000", "0.00008000"], ["72857.43000000", "0.00000000"], ["72860.80000000", "0.00000000"], ["72870.37000000", "0.00013000"], ["72877.79000000", "0.00000000"], ["72894.23000000", "0.00011000"], ["72907.88000000", "0.00000000"], ["72911.03000000", "0.00009000"], ["72912.36000000", "0.00000000"], ["72915.99000000", "0.00000000"], ["72919.44000000", "0.00491000"], ["72928.16000000", "1.54487000"], ["72929.61000000", "0.00027000"], ["72936.36000000", "0.00026000"], ["72939.33000000", "0.00007000"], ["72940.37000000", "0.00008000"], ["72941.17000000", "0.00085000"], ["72946.14000000", "0.00007000"], ["72956.54000000", "0.00044000"], ["72960.75000000", "0.00009000"], ["72986.89000000", "4.11573000"], ["72994.83000000", "0.00024000"], ["73002.86000000", "0.00000000"], ["73004.90000000", "0.00116000"], ["73011.16000000", "0.00008000"], ["73018.71000000", "0.00000000"], ["73025.23000000", "0.00000000"], ["73043.36000000", "0.00026000"], ["73052.36000000", "0.00009000"], ["73052.38000000", "0.00000000"], ["73058.82000000", "0.00023000"], ["73067.53000000", "0.00008000"], ["73075.57000000", "0.00000000"], ["73086.36000000", "0.00046000"], ["73092.10000000", "0.00054000"], ["73096.77000000", "0.00025000"], ["73113.92000000", "0.00011000"], ["73124.74000000", "0.00008000"], ["73170.91000000", "0.00009000"], ["73177.70000000", "0.00000000"], ["73181.81000000", "0.00233000"], ["73201.82000000", "0.00007000"], ["73207.31000000", "0.00059000"], ["73212.94000000", "0.00008000"], ["73220.99000000", "0.00000000"], ["73231.32000000", "0.04080000"], ["73294.11000000", "0.00835000"], ["73299.20000000", "0.00014000"], ["73360.58000000", "0.00013000"], ["73383.25000000", "0.00010000"], ["73397.82000000", "0.00011000"], ["73402.06000000", "0.00023000"], ["73416.66000000", "0.00337000"], ["73427.36000000", "0.00530000"], ["73480.00000000", "0.00721000"], ["73513.03000000", "0.00037000"], ["73586.85000000", "0.00010000"], ["73750.00000000", "0.06038000"], ["73751.83000000", "0.00071000"], ["73876.59000000", "0.00008000"], ["73997.39000000", "0.00009000"], ["74040.00000000", "1.00320000"], ["74117.64000000", "0.00645000"], ["74220.47000000", "0.00000000"], ["74322.70000000", "0.00073000"], ["74331.32000000", "0.00025000"], ["75082.14000000", "0.00000000"]], "_local_ts_utc": "2026-06-01T07:49:05.110750+00:00"}
{"e": "depthUpdate", "E": 1780300146314, "s": "BTCUSDT", "U": 94551784739, "u": 94551785926, "b": [["72706.67000000", "3.77490000"], ["72706.66000000", "0.00024000"], ["72706.56000000", "0.00000000"], ["72706.55000000", "0.34044000"], ["72706.54000000", "0.00000000"], ["72706.00000000", "0.00000000"], ["72705.87000000", "0.05776000"], ["72705.86000000", "0.00000000"], ["72705.82000000", "0.12389000"], ["72705.81000000", "1.90198000"], ["72705.80000000", "0.00000000"], ["72705.77000000", "0.00000000"], ["72705.76000000", "2.55730000"], ["72705.75000000", "0.00008000"], ["72705.74000000", "0.00000000"], ["72705.62000000", "0.00028000"], ["72705.44000000", "0.00000000"], ["72705.43000000", "0.60731000"], ["72705.42000000", "0.00000000"], ["72705.36000000", "0.00000000"], ["72705.35000000", "0.52527000"], ["72705.34000000", "0.00000000"], ["72705.33000000", "0.18713000"], ["72705.32000000", "1.65934000"], ["72705.31000000", "0.00000000"], ["72704.75000000", "0.00000000"], ["72704.74000000", "0.00008000"], ["72704.73000000", "0.00000000"], ["72704.69000000", "0.00000000"], ["72704.68000000", "0.00000000"], ["72704.07000000", "0.00007000"], ["72704.02000000", "0.00000000"], ["72704.01000000", "0.00000000"], ["72704.00000000", "1.09177000"], ["72703.99000000", "0.00000000"], ["72703.75000000", "0.00814000"], ["72703.60000000", "0.00787000"], ["72703.59000000", "0.01288000"], ["72703.08000000", "0.03407000"], ["72702.95000000", "0.00000000"], ["72702.94000000", "0.02415000"], ["72702.82000000", "0.00009000"], ["72702.67000000", "0.00000000"], ["72702.02000000", "0.00000000"], ["72702.01000000", "0.02838000"], ["72702.00000000", "0.02280000"], ["72701.34000000", "0.00000000"], ["72700.87000000", "0.00000000"], ["72700.86000000", "0.00000000"], ["72700.79000000", "0.01379000"], ["72700.41000000", "0.00825000"], ["72700.37000000", "0.00000000"], ["72700.28000000", "0.00000000"], ["72700.02000000", "0.23178000"], ["72700.01000000", "0.00063000"], ["72699.55000000", "0.00000000"], ["72699.18000000", "0.00000000"], ["72698.81000000", "0.00000000"], ["72698.68000000", "0.00000000"], ["72698.36000000", "0.00165000"], ["72697.40000000", "0.00011000"], ["72697.36000000", "0.15792000"], ["72697.35000000", "0.00000000"], ["72697.13000000", "0.00000000"], ["72696.51000000", "0.03407000"], ["72696.03000000", "0.17109000"], ["72696.02000000", "0.33436000"], ["72696.01000000", "0.00008000"], ["72695.81000000", "0.00020000"], ["72695.75000000", "0.00000000"], ["72694.72000000", "0.17117000"], ["72694.69000000", "0.00000000"], ["72694.51000000", "0.00014000"], ["72693.80000000", "0.07128000"], ["72693.46000000", "0.00000000"], ["72693.38000000", "0.17109000"], ["72693.37000000", "0.00008000"], ["72693.36000000", "0.00000000"], ["72693.16000000", "0.02000000"], ["72692.04000000", "0.17109000"], ["72692.03000000", "0.00000000"], ["72691.68000000", "0.65949000"], ["72690.79000000", "0.00000000"], ["72690.72000000", "0.17109000"], ["72690.71000000", "0.20733000"], ["72690.70000000", "0.00000000"], ["72690.50000000", "0.00209000"], ["72690.02000000", "0.00011000"], ["72689.65000000", "0.00011000"], ["72689.59000000", "0.00000000"], ["72689.38000000", "0.17109000"], ["72689.15000000", "0.00000000"], ["72688.96000000", "0.00000000"], ["72688.76000000", "0.17121000"], ["72688.75000000", "0.65949000"], ["72687.82000000", "0.40856000"], ["72687.70000000", "0.00000000"], ["72687.61000000", "2.75057000"], ["72687.24000000", "0.00000000"], ["72687.13000000", "0.00000000"], ["72687.04000000", "0.00045000"], ["72686.72000000", "0.17109000"], ["72686.56000000", "0.03519000"], ["72685.55000000", "0.17109000"], ["72685.54000000", "0.26152000"], ["72685.38000000", "0.00000000"], ["72685.23000000", "0.00000000"], ["72684.06000000", "0.17109000"], ["72683.88000000", "0.00000000"], ["72682.73000000", "0.17109000"], ["72682.53000000", "0.00012000"], ["72682.27000000", "0.00000000"], ["72682.18000000", "0.17109000"], ["72681.72000000", "0.08256000"], ["72680.90000000", "0.00000000"], ["72680.59000000", "0.00000000"], ["72680.55000000", "0.00000000"], ["72680.48000000", "0.00000000"], ["72680.15000000", "0.00000000"], ["72680.08000000", "0.17109000"], ["72680.07000000", "0.40856000"], ["72680.06000000", "0.00000000"], ["72680.03000000", "0.17109000"], ["72680.01000000", "0.00315000"], ["72679.86000000", "0.00360000"], ["72678.02000000", "0.17116000"], ["72678.01000000", "0.47757000"], ["72677.72000000", "0.62783000"], ["72677.70000000", "0.00686000"], ["72677.58000000", "0.00686000"], ["72677.45000000", "0.00020000"], ["72676.49000000", "0.00000000"], ["72676.08000000", "0.00000000"], ["72675.87000000", "0.00200000"], ["72675.21000000", "0.23374000"], ["72674.75000000", "0.15389000"], ["72674.74000000", "0.00000000"], ["72674.31000000", "0.00000000"], ["72673.42000000", "0.17109000"], ["72673.35000000", "0.00000000"], ["72672.40000000", "0.17109000"], ["72672.39000000", "1.88238000"], ["72672.38000000", "1.36399000"], ["72671.77000000", "0.00000000"], ["72671.74000000", "0.00000000"], ["72671.29000000", "0.00000000"], ["72671.26000000", "0.00000000"], ["72670.36000000", "0.02683000"], ["72669.84000000", "0.00000000"], ["72669.50000000", "0.00000000"], ["72669.28000000", "0.00000000"], ["72668.61000000", "0.57896000"], ["72667.18000000", "0.00000000"], ["72666.86000000", "0.03940000"], ["72666.76000000", "0.00000000"], ["72665.43000000", "0.00102000"], ["72665.42000000", "0.00000000"], ["72665.41000000", "0.96858000"], ["72664.56000000", "0.00000000"], ["72664.55000000", "0.75359000"], ["72663.75000000", "0.00000000"], ["72663.74000000", "1.36415000"], ["72662.77000000", "0.00000000"], ["72662.16000000", "0.00000000"], ["72661.43000000", "0.00000000"], ["72661.35000000", "0.00686000"], ["72660.94000000", "0.05399000"], ["72660.93000000", "0.00000000"], ["72660.11000000", "0.00000000"], ["72659.58000000", "0.00000000"], ["72658.79000000", "0.16258000"], ["72658.23000000", "0.00000000"], ["72658.00000000", "0.02280000"], ["72657.61000000", "0.17109000"], ["72657.60000000", "2.08094000"], ["72656.11000000", "0.00000000"], ["72655.82000000", "0.00000000"], ["72654.51000000", "1.19867000"], ["72653.77000000", "0.49612000"], ["72650.81000000", "0.00000000"], ["72647.26000000", "0.00000000"], ["72644.77000000", "0.00000000"], ["72643.21000000", "0.20751000"], ["72641.52000000", "0.00000000"], ["72640.92000000", "0.00000000"], ["72639.77000000", "0.49621000"], ["72617.88000000", "0.00000000"], ["72607.52000000", "0.00000000"], ["72600.56000000", "0.00000000"], ["72600.55000000", "0.00000000"], ["72596.31000000", "1.83950000"], ["72545.31000000", "0.00718000"], ["72502.53000000", "0.00000000"], ["72433.86000000", "0.00019000"], ["72420.00000000", "0.00206000"], ["72392.19000000", "0.00000000"], ["71998.77000000", "0.00692000"], ["65435.23000000", "0.00000000"], ["65433.60000000", "0.00000000"], ["58163.20000000", "0.00171000"]], "a": [["72704.01000000", "0.00000000"], ["72704.02000000", "0.00000000"], ["72704.03000000", "0.00000000"], ["72704.69000000", "0.00000000"], ["72704.70000000", "0.00000000"], ["72705.33000000", "0.00000000"], ["72705.34000000", "0.00000000"], ["72705.35000000", "0.00000000"], ["72705.36000000", "0.00000000"], ["72705.44000000", "0.00000000"], ["72705.45000000", "0.00000000"], ["72705.76000000", "0.00000000"], ["72705.77000000", "0.00000000"], ["72705.82000000", "0.00000000"], ["72705.83000000", "0.00000000"], ["72705.87000000", "0.00000000"], ["72706.01000000", "0.00000000"], ["72706.55000000", "0.00000000"], ["72706.56000000", "0.00000000"], ["72706.67000000", "0.00000000"], ["72706.68000000", "0.21142000"], ["72706.69000000", "0.00016000"], ["72707.47000000", "0.00000000"], ["72707.75000000", "0.00000000"], ["72707.76000000", "0.00031000"], ["72707.79000000", "0.00000000"], ["72707.80000000", "0.00016000"], ["72707.81000000", "0.00016000"], ["72708.01000000", "0.00000000"], ["72708.10000000", "0.00016000"], ["72708.21000000", "0.00000000"], ["72708.48000000", "0.00016000"], ["72708.49000000", "0.00016000"], ["72708.50000000", "0.00000000"], ["72708.91000000", "0.00000000"], ["72709.04000000", "0.00040000"], ["72709.05000000", "0.00016000"], ["72709.06000000", "0.00016000"], ["72709.25000000", "0.00016000"], ["72709.77000000", "0.00000000"], ["72710.00000000", "0.00000000"], ["72710.76000000", "0.00024000"], ["72710.77000000", "0.40856000"], ["72710.88000000", "0.00008000"], ["72710.89000000", "0.00000000"], ["72711.24000000", "0.02000000"], ["72711.29000000", "0.00000000"], ["72711.50000000", "0.01395000"], ["72711.93000000", "0.00000000"], ["72711.99000000", "0.00000000"], ["72712.00000000", "0.00008000"], ["72712.01000000", "0.09627000"], ["72712.02000000", "0.00000000"], ["72712.25000000", "0.00000000"], ["72712.26000000", "0.00000000"], ["72712.80000000", "0.00008000"], ["72713.24000000", "0.00000000"], ["72713.41000000", "0.00000000"], ["72714.46000000", "0.00000000"], ["72714.58000000", "0.00189000"], ["72714.60000000", "0.00000000"], ["72714.65000000", "0.00000000"], ["72714.85000000", "0.00000000"], ["72714.94000000", "0.00048000"], ["72715.34000000", "0.00000000"], ["72715.61000000", "0.04000000"], ["72715.65000000", "0.00000000"], ["72715.71000000", "0.00000000"], ["72715.78000000", "0.00000000"], ["72716.03000000", "0.00000000"], ["72716.20000000", "0.00031000"], ["72716.24000000", "0.00000000"], ["72716.61000000", "0.00000000"], ["72716.83000000", "0.00031000"], ["72717.44000000", "0.08000000"], ["72717.68000000", "0.33250000"], ["72717.69000000", "0.00000000"], ["72717.70000000", "0.00008000"], ["72718.01000000", "0.00000000"], ["72718.65000000", "0.15319000"], ["72718.71000000", "0.02000000"], ["72718.79000000", "0.00155000"], ["72718.92000000", "0.17117000"], ["72718.93000000", "0.40856000"], ["72719.29000000", "0.00300000"], ["72719.52000000", "0.00000000"], ["72720.00000000", "0.00000000"], ["72720.01000000", "0.00000000"], ["72720.38000000", "0.00000000"], ["72720.64000000", "0.17117000"], ["72721.24000000", "0.27000000"], ["72722.00000000", "0.00000000"], ["72722.01000000", "0.15892000"], ["72722.02000000", "0.41485000"], ["72723.16000000", "0.00000000"], ["72723.44000000", "0.00000000"], ["72723.58000000", "0.17109000"], ["72723.59000000", "0.24677000"], ["72723.60000000", "0.00008000"], ["72724.99000000", "0.17126000"], ["72725.06000000", "0.00000000"], ["72726.39000000", "0.00000000"], ["72726.51000000", "0.00000000"], ["72726.63000000", "0.17109000"], ["72726.87000000", "0.00000000"], ["72726.93000000", "0.00000000"], ["72727.00000000", "0.00688000"], ["72727.01000000", "0.01345000"], ["72727.71000000", "0.00000000"], ["72727.85000000", "0.17117000"], ["72729.94000000", "0.00028000"], ["72729.98000000", "0.00000000"], ["72730.62000000", "0.00077000"], ["72731.36000000", "0.00000000"], ["72731.59000000", "0.20697000"], ["72731.68000000", "0.00000000"], ["72731.91000000", "0.03696000"], ["72734.04000000", "0.00200000"], ["72734.61000000", "0.15801000"], ["72734.80000000", "0.85950000"], ["72734.85000000", "0.00000000"], ["72736.37000000", "0.00000000"], ["72737.04000000", "0.00000000"], ["72738.29000000", "0.00000000"], ["72738.50000000", "0.36290000"], ["72740.97000000", "0.00007000"], ["72741.24000000", "0.00000000"], ["72741.45000000", "0.00686000"], ["72742.37000000", "0.00000000"], ["72743.17000000", "0.00436000"], ["72744.27000000", "0.02642000"], ["72748.35000000", "0.00000000"], ["72748.75000000", "0.00901000"], ["72749.07000000", "1.45835000"], ["72749.14000000", "0.00000000"], ["72751.80000000", "0.00000000"], ["72761.27000000", "0.49539000"], ["72764.10000000", "0.45981000"], ["72764.11000000", "1.36227000"], ["72764.85000000", "0.00685000"], ["72765.51000000", "0.00000000"], ["72765.81000000", "0.00686000"], ["72768.66000000", "0.00000000"], ["72770.62000000", "0.00000000"], ["72774.91000000", "0.00550000"], ["72783.08000000", "0.00000000"], ["72785.97000000", "0.58886000"], ["72792.02000000", "0.89202000"], ["72792.03000000", "2.75057000"], ["72792.12000000", "0.00000000"], ["72792.13000000", "0.00000000"], ["72793.34000000", "0.27576000"], ["72795.81000000", "0.00007000"], ["72800.42000000", "0.33162000"], ["72802.21000000", "2.75057000"], ["72805.91000000", "0.17534000"], ["72807.73000000", "0.28506000"], ["72807.74000000", "0.00000000"], ["72811.79000000", "0.00000000"], ["72812.39000000", "2.75057000"], ["72812.57000000", "0.14331000"], ["72815.99000000", "0.03789000"], ["72821.06000000", "1.12863000"], ["72838.66000000", "0.00000000"], ["72841.09000000", "0.00000000"], ["72847.43000000", "0.00000000"], ["72847.84000000", "0.00000000"], ["72848.66000000", "2.06252000"], ["78207.33000000", "0.00050000"]], "_local_ts_utc": "2026-06-01T07:49:05.210726+00:00"}
{"e": "depthUpdate", "E": 1780300146414, "s": "BTCUSDT", "U": 94551785927, "u": 94551786265, "b": [["72706.67000000", "3.77563000"], ["72706.56000000", "0.00016000"], ["72706.55000000", "0.00016000"], ["72706.31000000", "0.00016000"], ["72706.30000000", "0.04442000"], ["72705.87000000", "0.00016000"], ["72705.83000000", "0.00016000"], ["72705.82000000", "2.05790000"], ["72705.81000000", "1.24265000"], ["72705.77000000", "0.00008000"], ["72705.76000000", "1.01391000"], ["72705.75000000", "0.00000000"], ["72705.62000000", "0.00000000"], ["72705.43000000", "0.44240000"], ["72705.35000000", "0.34902000"], ["72705.33000000", "0.00000000"], ["72705.32000000", "0.84480000"], ["72704.74000000", "0.00000000"], ["72704.00000000", "1.09153000"], ["72703.75000000", "0.00798000"], ["72703.60000000", "0.00771000"], ["72702.21000000", "0.00000000"], ["72700.97000000", "0.04000000"], ["72700.03000000", "0.00008000"], ["72697.36000000", "0.00000000"], ["72696.67000000", "0.02000000"], ["72696.05000000", "0.63338000"], ["72696.04000000", "1.06805000"], ["72696.03000000", "0.00000000"], ["72696.02000000", "0.00000000"], ["72694.73000000", "0.00008000"], ["72694.72000000", "0.00008000"], ["72694.53000000", "0.00000000"], ["72693.80000000", "0.32447000"], ["72693.38000000", "0.00000000"], ["72693.16000000", "0.00000000"], ["72692.56000000", "0.00000000"], ["72692.04000000", "0.00000000"], ["72691.69000000", "0.00008000"], ["72690.72000000", "0.00008000"], ["72690.71000000", "1.26790000"], ["72690.44000000", "0.01376000"], ["72690.01000000", "0.02000000"], ["72689.38000000", "0.00000000"], ["72688.45000000", "0.00000000"], ["72688.26000000", "0.00000000"], ["72687.62000000", "0.00008000"], ["72686.72000000", "0.00000000"], ["72685.55000000", "0.00000000"], ["72685.25000000", "0.00008000"], ["72684.06000000", "0.00000000"], ["72682.73000000", "0.00000000"], ["72682.18000000", "0.00000000"], ["72682.12000000", "0.00008000"], ["72682.06000000", "0.00000000"], ["72680.08000000", "0.00000000"], ["72680.03000000", "0.00008000"], ["72678.02000000", "0.00007000"], ["72674.75000000", "0.00000000"], ["72673.42000000", "0.00000000"], ["72672.40000000", "0.00000000"], ["72666.39000000", "0.49603000"], ["72660.94000000", "0.05399000"], ["72658.79000000", "0.00000000"], ["72657.61000000", "0.00000000"], ["72654.13000000", "0.00000000"], ["72653.56000000", "0.02000000"], ["72652.62000000", "1.04057000"], ["72615.76000000", "0.00000000"], ["72615.56000000", "0.00679000"], ["72605.90000000", "0.00000000"], ["72602.31000000", "0.00137000"], ["72598.75000000", "2.44715000"], ["72400.32000000", "0.00008000"], ["65436.01000000", "0.00034000"]], "a": [["72706.68000000", "0.32503000"], ["72707.75000000", "0.00643000"], ["72707.76000000", "0.00015000"], ["72707.80000000", "0.00000000"], ["72707.81000000", "0.00000000"], ["72708.10000000", "0.00000000"], ["72708.48000000", "0.00000000"], ["72708.49000000", "0.00000000"], ["72709.04000000", "0.00008000"], ["72709.05000000", "0.00000000"], ["72709.06000000", "0.00000000"], ["72709.23000000", "0.00016000"], ["72709.24000000", "0.04018000"], ["72709.25000000", "0.00000000"], ["72710.67000000", "0.17112000"], ["72710.70000000", "0.00016000"], ["72710.71000000", "0.04000000"], ["72710.75000000", "0.00016000"], ["72710.76000000", "0.16230000"], ["72710.77000000", "0.40872000"], ["72711.07000000", "0.00031000"], ["72711.24000000", "0.02016000"], ["72711.49000000", "0.01714000"], ["72711.50000000", "0.00016000"], ["72711.67000000", "0.00031000"], ["72712.00000000", "0.17128000"], ["72712.01000000", "0.09643000"], ["72712.80000000", "0.17109000"], ["72712.81000000", "0.38981000"], ["72712.82000000", "0.50016000"], ["72713.95000000", "0.00000000"], ["72714.66000000", "0.17109000"], ["72714.95000000", "0.00031000"], ["72715.02000000", "0.00000000"], ["72715.03000000", "0.00000000"], ["72715.38000000", "0.65949000"], ["72715.61000000", "0.00016000"], ["72715.99000000", "0.17109000"], ["72716.03000000", "0.00028000"], ["72716.20000000", "0.00000000"], ["72716.28000000", "0.00000000"], ["72716.80000000", "0.00008000"], ["72716.83000000", "0.00000000"], ["72717.32000000", "0.17109000"], ["72717.43000000", "0.00000000"], ["72717.44000000", "0.08016000"], ["72717.68000000", "0.40460000"], ["72718.29000000", "0.00000000"], ["72718.66000000", "0.01289000"], ["72718.91000000", "0.65949000"], ["72719.44000000", "0.01379000"], ["72720.39000000", "0.12095000"], ["72720.65000000", "1.31325000"], ["72720.99000000", "0.00766000"], ["72722.00000000", "2.75057000"], ["72722.08000000", "0.65949000"], ["72727.82000000", "0.17109000"], ["72727.83000000", "1.71125000"], ["72727.84000000", "2.75057000"], ["72727.85000000", "0.00008000"], ["72727.86000000", "0.00000000"], ["72727.99000000", "0.00000000"], ["72728.19000000", "0.07400000"], ["72730.01000000", "0.00000000"], ["72730.39000000", "0.00008000"], ["72731.58000000", "0.00000000"], ["72731.59000000", "0.52892000"], ["72733.28000000", "0.00000000"], ["72733.91000000", "0.96858000"], ["72734.61000000", "0.00000000"], ["72734.79000000", "1.49712000"], ["72734.80000000", "0.68841000"], ["72734.81000000", "0.00000000"], ["72737.03000000", "2.75065000"], ["72737.04000000", "0.00000000"], ["72737.44000000", "0.00000000"], ["72738.49000000", "0.00000000"], ["72739.93000000", "0.00000000"], ["72741.25000000", "0.00000000"], ["72741.98000000", "0.00000000"], ["72742.32000000", "0.00000000"], ["72742.78000000", "0.00000000"], ["72745.53000000", "0.33203000"], ["72748.66000000", "0.00000000"], ["72748.75000000", "0.00000000"], ["72748.97000000", "1.03920000"], ["72749.06000000", "0.00000000"], ["72749.07000000", "1.46844000"], ["72754.21000000", "0.00434000"], ["72754.47000000", "0.23247000"], ["72761.64000000", "0.43387000"], ["72762.99000000", "0.00189000"], ["72767.46000000", "0.00000000"], ["72770.44000000", "0.49532000"], ["72797.99000000", "0.01484000"], ["72798.89000000", "1.54904000"], ["72800.42000000", "1.01765000"], ["72802.21000000", "0.00000000"], ["72802.88000000", "2.44029000"], ["72807.73000000", "0.00000000"], ["72808.42000000", "0.12830000"], ["72808.43000000", "0.00000000"], ["72812.38000000", "0.14800000"], ["72812.39000000", "0.00000000"], ["72812.57000000", "0.00000000"], ["72822.75000000", "0.03557000"], ["72828.00000000", "0.10342000"], ["72829.57000000", "0.17647000"], ["72834.56000000", "0.00000000"], ["72835.82000000", "0.00075000"], ["72848.24000000", "0.00000000"], ["72848.31000000", "2.06252000"], ["72848.66000000", "0.00000000"], ["72893.80000000", "0.02154000"], ["73084.80000000", "0.00000000"], ["73361.03000000", "0.00010000"], ["73816.08000000", "0.00000000"]], "_local_ts_utc": "2026-06-01T07:49:05.310709+00:00"}
{"e": "depthUpdate", "E": 1780300146514, "s": "BTCUSDT", "U": 94551786266, "u": 94551786747, "b": [["72709.23000000", "5.69118000"], ["72709.22000000", "0.00024000"], ["72709.03000000", "0.00259000"], ["72708.60000000", "0.00016000"], ["72708.59000000", "0.05942000"], ["72708.31000000", "0.00016000"], ["72708.30000000", "0.08486000"], ["72707.89000000", "0.00000000"], ["72707.77000000", "0.00000000"], ["72707.76000000", "0.00771000"], ["72707.75000000", "0.00000000"], ["72707.74000000", "0.00000000"], ["72706.70000000", "1.34985000"], ["72706.69000000", "0.00008000"], ["72706.68000000", "0.00016000"], ["72706.67000000", "0.13015000"], ["72706.66000000", "0.00000000"], ["72706.56000000", "0.00000000"], ["72706.55000000", "0.00000000"], ["72706.31000000", "0.00000000"], ["72706.30000000", "0.00016000"], ["72705.98000000", "0.00000000"], ["72705.87000000", "0.00000000"], ["72705.83000000", "0.00008000"], ["72705.82000000", "0.12336000"], ["72705.81000000", "1.18323000"], ["72705.77000000", "0.00000000"], ["72705.35000000", "0.34902000"], ["72705.33000000", "0.49246000"], ["72705.32000000", "0.64319000"], ["72704.00000000", "0.89914000"], ["72703.08000000", "0.00000000"], ["72701.24000000", "0.00010000"], ["72700.98000000", "0.00008000"], ["72700.03000000", "0.00000000"], ["72697.76000000", "0.00000000"], ["72697.17000000", "0.16537000"], ["72696.67000000", "0.00000000"], ["72696.06000000", "0.17240000"], ["72696.05000000", "0.63346000"], ["72696.01000000", "0.00000000"], ["72694.74000000", "0.00000000"], ["72694.73000000", "0.00000000"], ["72693.84000000", "0.00000000"], ["72693.80000000", "0.21636000"], ["72693.37000000", "0.00193000"], ["72692.64000000", "0.00007000"], ["72692.13000000", "0.00007000"], ["72691.81000000", "0.17240000"], ["72690.72000000", "0.17248000"], ["72690.44000000", "0.00000000"], ["72689.13000000", "0.17240000"], ["72688.76000000", "0.00012000"], ["72688.26000000", "0.02000000"], ["72687.83000000", "0.17240000"], ["72687.62000000", "0.17248000"], ["72682.43000000", "0.17240000"], ["72682.18000000", "0.17240000"], ["72679.88000000", "0.00000000"], ["72677.58000000", "0.00000000"], ["72672.40000000", "0.00008000"], ["72670.86000000", "0.00000000"], ["72670.32000000", "0.00102000"], ["72651.71000000", "0.02000000"], ["72607.60000000", "0.04480000"], ["72603.82000000", "0.00000000"], ["72564.48000000", "0.01692000"], ["72409.96000000", "0.01373000"], ["71984.88000000", "0.00000000"], ["71976.96000000", "0.00007000"], ["71761.48000000", "0.00347000"], ["65438.31000000", "0.00017000"], ["65436.01000000", "0.00000000"], ["58167.39000000", "0.00034000"]], "a": [["72706.68000000", "0.00000000"], ["72706.69000000", "0.00000000"], ["72707.75000000", "0.00000000"], ["72707.76000000", "0.00000000"], ["72709.04000000", "0.00000000"], ["72709.23000000", "0.00000000"], ["72709.24000000", "0.11231000"], ["72709.25000000", "0.00071000"], ["72709.36000000", "0.00000000"], ["72709.81000000", "0.01854000"], ["72709.82000000", "0.04000000"], ["72710.61000000", "0.00000000"], ["72710.64000000", "0.00016000"], ["72710.65000000", "0.00000000"], ["72710.66000000", "0.00000000"], ["72710.67000000", "0.00016000"], ["72710.70000000", "0.00000000"], ["72710.71000000", "0.00016000"], ["72710.75000000", "0.00000000"], ["72710.76000000", "0.00024000"], ["72710.77000000", "0.00016000"], ["72711.07000000", "0.00000000"], ["72711.23000000", "0.00016000"], ["72711.24000000", "0.02016000"], ["72711.49000000", "0.00016000"], ["72711.50000000", "0.00000000"], ["72711.67000000", "0.00000000"], ["72711.80000000", "0.04000000"], ["72711.99000000", "0.00000000"], ["72712.00000000", "0.00016000"], ["72712.01000000", "0.00016000"], ["72712.79000000", "0.00016000"], ["72712.80000000", "0.17117000"], ["72712.81000000", "0.38965000"], ["72712.82000000", "0.50000000"], ["72713.09000000", "0.00000000"], ["72713.50000000", "0.00000000"], ["72713.73000000", "0.00031000"], ["72713.96000000", "0.00000000"], ["72714.30000000", "0.01075000"], ["72714.95000000", "0.00000000"], ["72714.99000000", "0.00000000"], ["72715.42000000", "0.00031000"], ["72715.61000000", "0.00000000"], ["72717.44000000", "0.08000000"], ["72718.81000000", "0.00007000"], ["72719.17000000", "0.00755000"], ["72721.99000000", "2.75057000"], ["72722.00000000", "0.00000000"], ["72722.01000000", "0.00008000"], ["72723.34000000", "0.03407000"], ["72723.58000000", "0.00000000"], ["72724.99000000", "0.00017000"], ["72726.63000000", "0.00000000"], ["72727.82000000", "0.00000000"], ["72727.88000000", "0.00000000"], ["72728.41000000", "0.00000000"], ["72729.57000000", "0.04600000"], ["72731.58000000", "0.00000000"], ["72733.90000000", "0.68845000"], ["72734.80000000", "0.00000000"], ["72741.00000000", "0.50000000"], ["72741.76000000", "0.00200000"], ["72744.66000000", "0.00007000"], ["72748.97000000", "1.04947000"], ["72749.07000000", "1.45835000"], ["72764.85000000", "0.00000000"], ["72797.99000000", "0.47530000"], ["72835.96000000", "0.00000000"], ["72836.69000000", "0.00940000"], ["72884.52000000", "0.00000000"], ["72885.25000000", "0.00185000"], ["72893.28000000", "0.09603000"], ["72907.57000000", "0.00000000"], ["72964.38000000", "0.00000000"], ["72965.11000000", "0.00626000"], ["73431.06000000", "0.00007000"], ["73439.14000000", "0.00000000"], ["73629.85000000", "0.00000000"]], "_local_ts_utc": "2026-06-01T07:49:05.410364+00:00"}
