{"e": "depthUpdate", "E": 1780300141615, "s": "ETHUSDT", "U": 76583085740, "u": 76583086455, "b": [["1973.84000000", "0.00000000"], ["1973.83000000", "0.00000000"], ["1973.82000000", "0.00000000"], ["1973.80000000", "0.00000000"], ["1973.79000000", "0.00000000"], ["1973.78000000", "0.00000000"], ["1973.70000000", "30.35490000"], ["1973.69000000", "0.00520000"], ["1973.68000000", "0.00260000"], ["1973.66000000", "0.00640000"], ["1973.63000000", "0.00520000"], ["1973.62000000", "0.00560000"], ["1973.60000000", "0.00520000"], ["1973.59000000", "0.00800000"], ["1973.58000000", "1.31110000"], ["1973.57000000", "0.00260000"], ["1973.54000000", "0.00260000"], ["1973.53000000", "0.00540000"], ["1973.52000000", "0.66550000"], ["1973.47000000", "0.00000000"], ["1973.46000000", "0.00390000"], ["1973.45000000", "0.01280000"], ["1973.44000000", "0.00000000"], ["1973.43000000", "0.00000000"], ["1973.42000000", "0.00000000"], ["1973.41000000", "0.00000000"], ["1973.40000000", "0.00560000"], ["1973.39000000", "0.00000000"], ["1973.38000000", "0.00000000"], ["1973.37000000", "0.00260000"], ["1973.36000000", "0.03000000"], ["1973.35000000", "1.00000000"], ["1973.34000000", "0.00000000"], ["1973.33000000", "0.00000000"], ["1973.32000000", "0.00000000"], ["1973.31000000", "0.00000000"], ["1973.30000000", "3.31290000"], ["1973.29000000", "0.61070000"], ["1973.28000000", "0.03520000"], ["1973.27000000", "0.00000000"], ["1973.26000000", "0.00390000"], ["1973.25000000", "0.00000000"], ["1973.24000000", "0.00000000"], ["1973.23000000", "8.51420000"], ["1973.22000000", "0.00000000"], ["1973.20000000", "7.13090000"], ["1973.19000000", "15.68100000"], ["1973.17000000", "0.25360000"], ["1973.15000000", "3.35740000"], ["1973.14000000", "0.00260000"], ["1973.13000000", "0.01020000"], ["1973.12000000", "15.63940000"], ["1973.11000000", "7.09520000"], ["1973.10000000", "7.10090000"], ["1973.09000000", "0.34740000"], ["1973.08000000", "2.89150000"], ["1973.07000000", "0.05030000"], ["1973.05000000", "0.00000000"], ["1973.04000000", "0.57000000"], ["1973.01000000", "6.96770000"], ["1972.97000000", "9.19390000"], ["1972.96000000", "20.64250000"], ["1972.93000000", "0.00000000"], ["1972.90000000", "0.00830000"], ["1972.88000000", "0.08030000"], ["1972.84000000", "12.43150000"], ["1972.81000000", "7.09780000"], ["1972.80000000", "28.62380000"], ["1972.79000000", "3.61020000"], ["1972.76000000", "0.00550000"], ["1972.75000000", "0.01260000"], ["1972.73000000", "22.87370000"], ["1972.69000000", "7.34550000"], ["1972.67000000", "9.27280000"], ["1972.60000000", "10.79980000"], ["1972.59000000", "3.73420000"], ["1972.54000000", "0.40410000"], ["1972.47000000", "4.50680000"], ["1972.40000000", "0.80310000"], ["1972.29000000", "0.00540000"], ["1972.18000000", "0.15840000"], ["1972.16000000", "0.03580000"], ["1972.07000000", "1.02250000"], ["1972.05000000", "4.15930000"], ["1972.02000000", "0.54270000"], ["1971.98000000", "0.27000000"], ["1971.90000000", "18.44220000"], ["1971.87000000", "8.55880000"], ["1971.68000000", "8.55770000"], ["1971.59000000", "7.03960000"], ["1971.50000000", "16.61930000"], ["1971.48000000", "7.27700000"], ["1971.43000000", "0.00000000"], ["1971.40000000", "9.10830000"], ["1971.37000000", "0.00000000"], ["1971.34000000", "7.09910000"], ["1971.30000000", "7.86100000"], ["1971.29000000", "7.09980000"], ["1971.15000000", "4.40070000"], ["1971.14000000", "7.13480000"], ["1971.10000000", "7.09520000"], ["1971.09000000", "1.05030000"], ["1971.04000000", "0.05500000"], ["1970.95000000", "0.00000000"], ["1970.88000000", "0.00260000"], ["1970.75000000", "0.42550000"], ["1970.29000000", "12.56320000"], ["1970.28000000", "13.54770000"], ["1970.27000000", "0.18760000"], ["1970.25000000", "3.60380000"], ["1970.14000000", "0.00640000"], ["1970.02000000", "14.07550000"], ["1969.74000000", "0.52710000"], ["1969.53000000", "0.00000000"], ["1968.92000000", "0.00000000"], ["1968.70000000", "127.15370000"], ["1968.31000000", "0.36580000"], ["1968.17000000", "0.13950000"], ["1968.08000000", "1.20810000"], ["1967.99000000", "0.00260000"], ["1967.90000000", "0.16370000"], ["1965.85000000", "3.65460000"], ["1964.36000000", "0.00000000"], ["1962.74000000", "1.20550000"], ["1776.52000000", "0.00000000"], ["1776.33000000", "0.00620000"], ["1579.00000000", "1.54250000"], ["1578.52000000", "0.14630000"], ["1473.84000000", "0.01200000"]], "a": [["1973.71000000", "68.67220000"], ["1973.72000000", "0.00510000"], ["1973.73000000", "0.00510000"], ["1973.76000000", "8.54970000"], ["1973.77000000", "22.57370000"], ["1973.78000000", "6.63970000"], ["1973.79000000", "3.21660000"], ["1973.80000000", "0.00570000"], ["1973.81000000", "0.00000000"], ["1973.82000000", "1.49050000"], ["1973.83000000", "4.98230000"], ["1973.84000000", "0.00000000"], ["1973.85000000", "2.97040000"], ["1973.86000000", "0.00260000"], ["1973.87000000", "0.00000000"], ["1973.90000000", "0.00830000"], ["1973.91000000", "0.00260000"], ["1973.92000000", "4.96960000"], ["1973.93000000", "1.31300000"], ["1973.94000000", "0.00910000"], ["1973.95000000", "0.03600000"], ["1973.96000000", "0.20080000"], ["1973.98000000", "7.51770000"], ["1973.99000000", "7.71720000"], ["1974.00000000", "24.56280000"], ["1974.01000000", "0.01020000"], ["1974.03000000", "0.01160000"], ["1974.06000000", "0.00300000"], ["1974.07000000", "0.40260000"], ["1974.08000000", "0.67640000"], ["1974.10000000", "6.89710000"], ["1974.11000000", "14.19300000"], ["1974.19000000", "13.56520000"], ["1974.22000000", "0.20260000"], ["1974.33000000", "0.51690000"], ["1974.34000000", "6.82790000"], ["1974.35000000", "1.25900000"], ["1974.40000000", "23.49410000"], ["1974.41000000", "19.82090000"], ["1974.43000000", "30.45660000"], ["1974.48000000", "8.54420000"], ["1974.61000000", "17.56850000"], ["1974.66000000", "0.15110000"], ["1974.70000000", "22.57680000"], ["1974.73000000", "0.25020000"], ["1974.80000000", "4.57690000"], ["1974.85000000", "15.14090000"], ["1974.90000000", "22.57370000"], ["1975.02000000", "7.09580000"], ["1975.13000000", "0.00260000"], ["1975.55000000", "3.69670000"], ["1975.56000000", "0.00260000"], ["1975.57000000", "20.60150000"], ["1975.62000000", "1.51340000"], ["1975.72000000", "0.94500000"], ["1975.74000000", "8.26260000"], ["1975.81000000", "7.20500000"], ["1975.88000000", "31.67660000"], ["1975.94000000", "0.51940000"], ["1976.10000000", "0.00000000"], ["1976.18000000", "1.20810000"], ["1976.28000000", "0.00000000"], ["1976.36000000", "0.00260000"], ["1976.43000000", "3.59280000"], ["1976.44000000", "0.00260000"], ["1977.58000000", "0.00260000"], ["1978.71000000", "1.23840000"], ["1978.92000000", "0.19620000"], ["1979.27000000", "0.00000000"], ["1979.32000000", "0.00000000"], ["1979.36000000", "0.00000000"], ["1979.93000000", "31.60920000"], ["1980.54000000", "0.00000000"], ["1981.69000000", "0.00000000"], ["1982.50000000", "0.48400000"], ["1983.64000000", "0.00000000"], ["1989.08000000", "3.19700000"], ["2031.43000000", "0.01000000"], ["2116.01000000", "0.01260000"]], "_local_ts_utc": "2026-06-01T07:49:00.513573+00:00"}
{"e": "depthUpdate", "E": 1780300141715, "s": "ETHUSDT", "U": 76583086456, "u": 76583086758, "b": [["1973.70000000", "0.57710000"], ["1973.69000000", "0.00520000"], ["1973.66000000", "0.00260000"], ["1973.63000000", "0.00260000"], ["1973.59000000", "0.00260000"], ["1973.58000000", "0.00260000"], ["1973.54000000", "0.00000000"], ["1973.53000000", "0.00000000"], ["1973.52000000", "0.03300000"], ["1973.46000000", "0.00000000"], ["1973.36000000", "0.03000000"], ["1973.35000000", "0.00000000"], ["1973.24000000", "0.00000000"], ["1973.23000000", "0.00000000"], ["1973.22000000", "2.56780000"], ["1973.21000000", "8.56680000"], ["1973.20000000", "0.03570000"], ["1973.19000000", "17.84260000"], ["1973.17000000", "44.11290000"], ["1973.16000000", "0.13000000"], ["1973.12000000", "0.03000000"], ["1973.11000000", "0.00000000"], ["1973.10000000", "0.00570000"], ["1973.08000000", "20.67330000"], ["1973.07000000", "14.24070000"], ["1973.04000000", "7.12520000"], ["1973.03000000", "13.51470000"], ["1973.02000000", "0.00260000"], ["1973.01000000", "6.69770000"], ["1972.97000000", "31.62850000"], ["1972.96000000", "0.03260000"], ["1972.94000000", "0.00000000"], ["1972.92000000", "4.39000000"], ["1972.89000000", "20.11050000"], ["1972.88000000", "13.59500000"], ["1972.87000000", "8.54720000"], ["1972.86000000", "7.09910000"], ["1972.82000000", "0.00000000"], ["1972.81000000", "0.00260000"], ["1972.80000000", "38.33730000"], ["1972.79000000", "10.70540000"], ["1972.77000000", "16.23300000"], ["1972.71000000", "13.51730000"], ["1972.69000000", "0.31870000"], ["1972.67000000", "11.57040000"], ["1972.66000000", "7.10450000"], ["1972.65000000", "0.19850000"], ["1972.64000000", "0.38090000"], ["1972.62000000", "26.91140000"], ["1972.61000000", "7.09780000"], ["1972.59000000", "10.82940000"], ["1972.57000000", "8.51420000"], ["1972.53000000", "25.41200000"], ["1972.52000000", "0.00570000"], ["1972.51000000", "0.00000000"], ["1972.47000000", "5.70680000"], ["1972.46000000", "7.38650000"], ["1972.45000000", "0.02720000"], ["1972.43000000", "13.55880000"], ["1972.39000000", "10.69520000"], ["1972.38000000", "11.52770000"], ["1972.37000000", "0.00510000"], ["1972.36000000", "0.14570000"], ["1972.21000000", "8.65630000"], ["1972.18000000", "0.05840000"], ["1972.16000000", "8.24340000"], ["1972.15000000", "20.77120000"], ["1972.14000000", "7.09780000"], ["1972.10000000", "0.00570000"], ["1972.00000000", "34.72280000"], ["1971.91000000", "7.09520000"], ["1971.31000000", "0.26860000"], ["1971.15000000", "2.61710000"], ["1971.11000000", "0.41690000"], ["1971.10000000", "10.82010000"], ["1971.09000000", "1.05030000"], ["1971.06000000", "0.76390000"], ["1970.95000000", "0.00000000"], ["1970.75000000", "0.42550000"], ["1969.86000000", "0.01540000"], ["1969.74000000", "0.52710000"], ["1969.66000000", "0.00000000"], ["1969.30000000", "0.00000000"], ["1969.16000000", "0.00000000"], ["1969.06000000", "0.00300000"], ["1967.90000000", "0.16110000"], ["1956.85000000", "0.00580000"], ["1918.91000000", "0.00000000"], ["1776.33000000", "0.01860000"]], "a": [["1973.71000000", "42.56410000"], ["1973.72000000", "0.01030000"], ["1973.73000000", "6.02900000"], ["1973.74000000", "0.00000000"], ["1973.75000000", "0.00000000"], ["1973.76000000", "0.00260000"], ["1973.77000000", "0.00260000"], ["1973.78000000", "7.26090000"], ["1973.79000000", "3.21660000"], ["1973.80000000", "0.00830000"], ["1973.82000000", "1.49310000"], ["1973.85000000", "2.96780000"], ["1973.86000000", "0.00000000"], ["1973.88000000", "0.53590000"], ["1973.89000000", "0.00000000"], ["1973.90000000", "0.00570000"], ["1973.91000000", "0.00000000"], ["1973.92000000", "3.05870000"], ["1973.94000000", "0.00650000"], ["1973.96000000", "11.02800000"], ["1973.97000000", "7.09520000"], ["1973.98000000", "0.00000000"], ["1973.99000000", "7.09520000"], ["1974.00000000", "27.04590000"], ["1974.09000000", "7.09520000"], ["1974.10000000", "15.41130000"], ["1974.26000000", "0.00000000"], ["1974.34000000", "6.05890000"], ["1974.41000000", "0.03410000"], ["1974.52000000", "0.00000000"], ["1974.61000000", "0.00300000"], ["1974.62000000", "0.00000000"], ["1974.74000000", "0.00640000"], ["1974.81000000", "1.41940000"], ["1974.97000000", "1.25050000"], ["1975.01000000", "0.09370000"], ["1975.10000000", "2.88850000"], ["1975.20000000", "0.00310000"], ["1975.34000000", "0.00760000"], ["1975.44000000", "0.00520000"], ["1975.45000000", "14.19040000"], ["1975.55000000", "0.43820000"], ["1975.57000000", "13.50630000"], ["1975.62000000", "0.00260000"], ["1975.73000000", "0.00000000"], ["1975.74000000", "1.16740000"], ["1975.81000000", "0.48600000"], ["1976.03000000", "0.00260000"], ["1976.10000000", "13.51470000"], ["1976.11000000", "0.04570000"], ["1976.43000000", "0.01020000"], ["1977.36000000", "0.70340000"], ["1978.09000000", "3.70760000"], ["1978.25000000", "0.03040000"], ["1978.27000000", "0.10380000"], ["1979.09000000", "0.00000000"], ["1979.15000000", "0.00000000"], ["1979.18000000", "0.00000000"], ["1980.07000000", "0.00260000"]], "_local_ts_utc": "2026-06-01T07:49:00.610986+00:00"}
{"e": "depthUpdate", "E": 1780300141815, "s": "ETHUSDT", "U": 76583086759, "u": 76583087590, "b": [["1973.70000000", "0.00000000"], ["1973.69000000", "0.00000000"], ["1973.68000000", "0.00000000"], ["1973.66000000", "0.00000000"], ["1973.63000000", "0.00000000"], ["1973.62000000", "0.00000000"], ["1973.60000000", "0.00000000"], ["1973.59000000", "0.00000000"], ["1973.58000000", "0.00000000"], ["1973.57000000", "0.00000000"], ["1973.52000000", "0.00000000"], ["1973.50000000", "0.00000000"], ["1973.45000000", "0.00000000"], ["1973.40000000", "0.00000000"], ["1973.38000000", "0.00000000"], ["1973.37000000", "0.00000000"], ["1973.36000000", "0.00000000"], ["1973.31000000", "0.00000000"], ["1973.30000000", "34.94730000"], ["1973.29000000", "0.00780000"], ["1973.28000000", "0.00520000"], ["1973.26000000", "0.00650000"], ["1973.23000000", "0.00000000"], ["1973.22000000", "0.00260000"], ["1973.21000000", "0.05260000"], ["1973.20000000", "0.00520000"], ["1973.19000000", "0.00260000"], ["1973.18000000", "0.00540000"], ["1973.17000000", "0.00000000"], ["1973.16000000", "0.00540000"], ["1973.15000000", "3.35740000"], ["1973.10000000", "0.00800000"], ["1973.09000000", "0.34740000"], ["1973.08000000", "0.00000000"], ["1973.07000000", "0.05030000"], ["1973.04000000", "0.03000000"], ["1973.03000000", "0.00000000"], ["1973.01000000", "0.00000000"], ["1972.98000000", "0.00000000"], ["1972.97000000", "8.92390000"], ["1972.93000000", "8.51420000"], ["1972.92000000", "11.48520000"], ["1972.91000000", "7.14520000"], ["1972.90000000", "7.10350000"], ["1972.89000000", "13.01530000"], ["1972.88000000", "0.69100000"], ["1972.87000000", "0.03300000"], ["1972.86000000", "0.00390000"], ["1972.83000000", "0.00000000"], ["1972.82000000", "8.51420000"], ["1972.81000000", "14.19300000"], ["1972.80000000", "20.03570000"], ["1972.79000000", "3.61020000"], ["1972.78000000", "0.00000000"], ["1972.77000000", "0.62360000"], ["1972.76000000", "7.10070000"], ["1972.74000000", "15.03970000"], ["1972.73000000", "22.57370000"], ["1972.72000000", "9.00690000"], ["1972.71000000", "7.09780000"], ["1972.70000000", "7.10090000"], ["1972.69000000", "0.11870000"], ["1972.63000000", "0.03390000"], ["1972.62000000", "33.60910000"], ["1972.61000000", "7.29780000"], ["1972.60000000", "16.52950000"], ["1972.58000000", "13.56500000"], ["1972.55000000", "1.20630000"], ["1972.54000000", "0.00410000"], ["1972.53000000", "25.40940000"], ["1972.52000000", "0.05600000"], ["1972.50000000", "0.37060000"], ["1972.47000000", "4.50680000"], ["1972.40000000", "1.20570000"], ["1972.38000000", "13.02770000"], ["1972.21000000", "8.55630000"], ["1972.17000000", "0.16110000"], ["1972.07000000", "1.02250000"], ["1972.03000000", "7.09520000"], ["1972.00000000", "37.45110000"], ["1971.92000000", "0.11170000"], ["1971.69000000", "0.36630000"], ["1971.68000000", "8.55770000"], ["1971.59000000", "0.00000000"], ["1971.48000000", "0.02070000"], ["1971.40000000", "0.00310000"], ["1971.36000000", "0.16560000"], ["1971.31000000", "8.78280000"], ["1971.24000000", "1.24440000"], ["1971.15000000", "0.00260000"], ["1971.11000000", "23.12150000"], ["1971.10000000", "0.00000000"], ["1970.95000000", "7.09520000"], ["1970.94000000", "0.00280000"], ["1970.90000000", "0.00000000"], ["1970.78000000", "0.00460000"], ["1970.75000000", "7.52070000"], ["1970.72000000", "0.69280000"], ["1970.70000000", "0.00270000"], ["1970.60000000", "0.00310000"], ["1970.58000000", "0.13720000"], ["1970.50000000", "0.04450000"], ["1970.33000000", "0.03460000"], ["1970.29000000", "0.00000000"], ["1970.01000000", "22.83520000"], ["1969.92000000", "0.00820000"], ["1969.75000000", "0.00000000"], ["1969.74000000", "14.04180000"], ["1969.66000000", "0.00000000"], ["1969.46000000", "13.52640000"], ["1967.95000000", "0.05340000"], ["1967.86000000", "0.00260000"], ["1967.77000000", "0.33150000"], ["1967.68000000", "0.61700000"], ["1966.29000000", "0.11380000"], ["1966.02000000", "0.03570000"], ["1964.35000000", "0.00260000"], ["1964.07000000", "0.16160000"], ["1963.44000000", "0.08430000"], ["1961.84000000", "0.02000000"], ["1961.82000000", "0.00000000"], ["1954.16000000", "0.12770000"], ["1776.33000000", "0.00000000"], ["1775.97000000", "0.00620000"]], "a": [["1973.31000000", "31.60940000"], ["1973.32000000", "0.00510000"], ["1973.33000000", "0.01670000"], ["1973.35000000", "1.70740000"], ["1973.36000000", "0.00540000"], ["1973.37000000", "0.20670000"], ["1973.38000000", "3.00000000"], ["1973.39000000", "0.00000000"], ["1973.40000000", "0.00570000"], ["1973.41000000", "0.00000000"], ["1973.42000000", "0.78190000"], ["1973.43000000", "6.46760000"], ["1973.44000000", "0.00000000"], ["1973.46000000", "0.00000000"], ["1973.47000000", "0.00000000"], ["1973.50000000", "0.00570000"], ["1973.51000000", "0.00000000"], ["1973.52000000", "0.56890000"], ["1973.53000000", "0.00260000"], ["1973.54000000", "0.00390000"], ["1973.56000000", "1.83460000"], ["1973.57000000", "0.00000000"], ["1973.58000000", "0.00000000"], ["1973.59000000", "6.02700000"], ["1973.60000000", "0.11890000"], ["1973.61000000", "1.13710000"], ["1973.62000000", "0.01020000"], ["1973.63000000", "1.32090000"], ["1973.64000000", "0.00260000"], ["1973.66000000", "0.00000000"], ["1973.67000000", "1.85520000"], ["1973.69000000", "29.66890000"], ["1973.70000000", "12.08060000"], ["1973.71000000", "4.40450000"], ["1973.72000000", "1.48470000"], ["1973.73000000", "0.64290000"], ["1973.74000000", "0.03690000"], ["1973.75000000", "0.45000000"], ["1973.76000000", "0.00000000"], ["1973.77000000", "0.64640000"], ["1973.78000000", "7.25830000"], ["1973.79000000", "3.21400000"], ["1973.80000000", "0.00570000"], ["1973.81000000", "7.09520000"], ["1973.82000000", "0.00000000"], ["1973.83000000", "12.07490000"], ["1973.85000000", "10.05140000"], ["1973.88000000", "0.00000000"], ["1973.90000000", "1.21120000"], ["1973.92000000", "3.04710000"], ["1973.93000000", "0.00000000"], ["1973.94000000", "12.23110000"], ["1973.95000000", "15.64540000"], ["1973.96000000", "0.20080000"], ["1973.97000000", "7.19520000"], ["1973.98000000", "13.51730000"], ["1974.00000000", "32.55570000"], ["1974.03000000", "0.00000000"], ["1974.08000000", "0.03000000"], ["1974.10000000", "8.51990000"], ["1974.20000000", "0.00830000"], ["1974.22000000", "0.00000000"], ["1974.30000000", "0.01070000"], ["1974.34000000", "0.00380000"], ["1974.40000000", "13.54780000"], ["1974.41000000", "0.03410000"], ["1974.43000000", "30.35660000"], ["1974.50000000", "0.20730000"], ["1974.55000000", "0.00260000"], ["1974.59000000", "23.65110000"], ["1974.60000000", "0.03610000"], ["1974.88000000", "8.54420000"], ["1975.21000000", "0.00000000"], ["1975.28000000", "0.00000000"], ["1975.30000000", "0.00000000"], ["1975.35000000", "1.45630000"], ["1975.45000000", "0.00000000"], ["1975.59000000", "0.00000000"], ["1976.10000000", "0.00000000"], ["1976.18000000", "1.20550000"], ["1976.55000000", "0.59570000"], ["1977.36000000", "0.00940000"], ["1978.52000000", "0.00000000"], ["1978.61000000", "126.51070000"], ["1978.71000000", "1.23840000"], ["1978.79000000", "0.00000000"], ["1978.83000000", "0.00000000"], ["1978.85000000", "0.00000000"], ["1978.96000000", "0.00000000"], ["1979.00000000", "4.17730000"], ["1982.21000000", "0.48270000"], ["1982.50000000", "0.00270000"], ["1987.07000000", "0.02000000"], ["1987.09000000", "0.02000000"], ["2125.19000000", "0.00380000"]], "_local_ts_utc": "2026-06-01T07:49:00.711908+00:00"}
{"e": "depthUpdate", "E": 1780300141915, "s": "ETHUSDT", "U": 76583087591, "u": 76583087788, "b": [["1973.30000000", "8.12630000"], ["1973.29000000", "0.00780000"], ["1973.28000000", "0.00260000"], ["1973.26000000", "0.00260000"], ["1973.21000000", "0.05520000"], ["1973.18000000", "0.00540000"], ["1973.16000000", "0.00000000"], ["1973.15000000", "0.00000000"], ["1973.10000000", "0.51490000"], ["1973.08000000", "0.00540000"], ["1973.07000000", "0.05030000"], ["1973.00000000", "0.01110000"], ["1972.98000000", "0.00000000"], ["1972.96000000", "0.03260000"], ["1972.95000000", "0.00000000"], ["1972.93000000", "0.00000000"], ["1972.92000000", "0.00000000"], ["1972.91000000", "0.05000000"], ["1972.90000000", "0.00830000"], ["1972.89000000", "0.00000000"], ["1972.84000000", "12.43150000"], ["1972.82000000", "0.00000000"], ["1972.81000000", "0.00260000"], ["1972.80000000", "26.50330000"], ["1972.79000000", "0.01020000"], ["1972.77000000", "0.62360000"], ["1972.76000000", "0.00550000"], ["1972.75000000", "0.01260000"], ["1972.74000000", "1.52500000"], ["1972.71000000", "7.09780000"], ["1972.70000000", "0.00570000"], ["1972.69000000", "7.16360000"], ["1972.67000000", "0.00560000"], ["1972.63000000", "0.03390000"], ["1972.58000000", "4.42730000"], ["1972.57000000", "22.02890000"], ["1972.40000000", "0.40570000"], ["1972.38000000", "12.22770000"], ["1972.37000000", "0.80510000"], ["1972.25000000", "8.10630000"], ["1972.18000000", "1.07200000"], ["1972.03000000", "7.09520000"], ["1971.97000000", "0.09320000"], ["1971.92000000", "0.01170000"], ["1971.86000000", "22.68600000"], ["1971.77000000", "0.24860000"], ["1971.62000000", "1.01330000"], ["1971.36000000", "0.25100000"], ["1970.94000000", "22.70740000"], ["1970.93000000", "31.84350000"], ["1970.74000000", "7.09520000"], ["1970.58000000", "7.23240000"], ["1965.79000000", "0.01550000"], ["1965.65000000", "4.10140000"], ["1964.16000000", "0.00300000"], ["1775.97000000", "0.01860000"]], "a": [["1973.31000000", "46.27840000"], ["1973.32000000", "0.00770000"], ["1973.33000000", "0.01930000"], ["1973.35000000", "0.00260000"], ["1973.36000000", "0.00260000"], ["1973.37000000", "0.20390000"], ["1973.38000000", "3.00260000"], ["1973.40000000", "0.00830000"], ["1973.42000000", "0.00260000"], ["1973.43000000", "0.00260000"], ["1973.47000000", "22.57370000"], ["1973.53000000", "1.20810000"], ["1973.54000000", "0.62960000"], ["1973.58000000", "0.00000000"], ["1973.59000000", "10.30940000"], ["1973.61000000", "1.13450000"], ["1973.62000000", "0.01320000"], ["1973.63000000", "1.31830000"], ["1973.64000000", "0.00000000"], ["1973.67000000", "1.85260000"], ["1973.70000000", "12.07800000"], ["1973.71000000", "3.67070000"], ["1973.72000000", "1.48210000"], ["1973.73000000", "0.50670000"], ["1973.77000000", "9.16060000"], ["1973.78000000", "6.63710000"], ["1973.83000000", "38.82990000"], ["1974.00000000", "32.55310000"], ["1974.14000000", "0.00390000"], ["1974.19000000", "13.94330000"], ["1974.24000000", "0.13260000"], ["1974.28000000", "0.00260000"], ["1974.37000000", "0.46160000"], ["1974.43000000", "3.60260000"], ["1974.78000000", "14.81580000"], ["1975.01000000", "7.18890000"], ["1975.04000000", "0.03000000"], ["1975.09000000", "0.00260000"], ["1975.22000000", "5.00000000"], ["1975.37000000", "45.18590000"], ["1975.80000000", "1.32610000"], ["1976.00000000", "3.60580000"], ["1977.37000000", "0.00000000"], ["1977.47000000", "0.14080000"], ["1978.61000000", "0.00000000"]], "_local_ts_utc": "2026-06-01T07:49:00.811376+00:00"}
{"e": "depthUpdate", "E": 1780300142015, "s": "ETHUSDT", "U": 76583087789, "u": 76583087932, "b": [["1973.30000000", "2.17950000"], ["1973.29000000", "0.00520000"], ["1973.18000000", "0.00540000"], ["1973.14000000", "0.00000000"], ["1973.12000000", "0.00000000"], ["1973.11000000", "0.00540000"], ["1973.09000000", "0.34480000"], ["1973.08000000", "0.00260000"], ["1973.07000000", "0.00000000"], ["1973.04000000", "0.00000000"], ["1973.02000000", "0.00260000"], ["1973.01000000", "0.00000000"], ["1973.00000000", "0.01110000"], ["1972.98000000", "10.20950000"], ["1972.97000000", "0.05030000"], ["1972.88000000", "0.64070000"], ["1972.85000000", "10.39820000"], ["1972.84000000", "0.14400000"], ["1972.81000000", "14.19300000"], ["1972.78000000", "0.37760000"], ["1972.75000000", "16.38340000"], ["1972.74000000", "15.03970000"], ["1972.71000000", "7.36780000"], ["1972.67000000", "26.81630000"], ["1972.58000000", "6.91370000"], ["1972.53000000", "22.57370000"], ["1972.38000000", "12.17740000"], ["1972.24000000", "1.27220000"], ["1972.01000000", "29.13180000"], ["1971.94000000", "8.44250000"], ["1971.84000000", "0.03260000"], ["1971.72000000", "0.27260000"], ["1971.70000000", "0.00000000"], ["1971.68000000", "21.39780000"], ["1971.52000000", "0.03260000"], ["1971.28000000", "0.22610000"], ["1971.24000000", "1.01340000"], ["1970.74000000", "0.00000000"], ["1970.62000000", "0.00260000"], ["1970.51000000", "13.76070000"], ["1970.50000000", "16.12550000"], ["1970.01000000", "145.17930000"], ["1969.47000000", "5.20790000"], ["1969.46000000", "0.01170000"], ["1968.91000000", "0.00000000"], ["1967.59000000", "0.00260000"], ["1951.41000000", "1.49280000"], ["1775.97000000", "0.03100000"], ["1473.84000000", "0.00000000"]], "a": [["1973.31000000", "44.27800000"], ["1973.37000000", "1.49630000"], ["1973.38000000", "4.32130000"], ["1973.43000000", "0.00260000"], ["1973.46000000", "6.74000000"], ["1973.51000000", "0.10140000"], ["1973.53000000", "0.00260000"], ["1973.56000000", "4.99620000"], ["1973.58000000", "7.09520000"], ["1973.61000000", "2.34000000"], ["1973.63000000", "0.00000000"], ["1973.67000000", "8.94780000"], ["1973.68000000", "12.46140000"], ["1973.71000000", "12.15220000"], ["1973.72000000", "0.20260000"], ["1973.76000000", "13.51470000"], ["1973.80000000", "0.00850000"], ["1973.96000000", "0.71380000"], ["1974.03000000", "0.51040000"], ["1974.19000000", "14.02080000"], ["1974.20000000", "15.68530000"], ["1974.35000000", "1.34570000"], ["1974.40000000", "13.76520000"], ["1974.41000000", "16.81100000"], ["1974.81000000", "1.20550000"], ["1974.84000000", "22.07860000"], ["1974.91000000", "0.00260000"], ["1975.01000000", "0.09370000"], ["1975.10000000", "0.00000000"], ["1975.25000000", "0.03300000"], ["1975.26000000", "0.00260000"], ["1975.27000000", "10.79920000"], ["1975.35000000", "0.00520000"], ["1975.36000000", "14.98740000"], ["1975.77000000", "0.00000000"], ["1975.87000000", "9.79060000"], ["1976.14000000", "0.92970000"], ["1976.36000000", "9.45600000"], ["1976.49000000", "9.37810000"], ["1976.83000000", "59.46450000"], ["1976.90000000", "0.00000000"], ["1977.85000000", "0.00000000"], ["1978.14000000", "0.00000000"], ["1980.06000000", "0.00000000"], ["1980.65000000", "0.03290000"]], "_local_ts_utc": "2026-06-01T07:49:00.912799+00:00"}
{"e": "depthUpdate", "E": 1780300142115, "s": "ETHUSDT", "U": 76583087933, "u": 76583088074, "b": [["1973.30000000", "0.43210000"], ["1973.18000000", "0.00540000"], ["1973.08000000", "0.00000000"], ["1973.00000000", "0.00800000"], ["1972.99000000", "3.93180000"], ["1972.98000000", "10.20960000"], ["1972.97000000", "0.00000000"], ["1972.92000000", "0.64020000"], ["1972.91000000", "0.05260000"], ["1972.86000000", "4.50490000"], ["1972.85000000", "0.00260000"], ["1972.82000000", "0.00000000"], ["1972.81000000", "0.00260000"], ["1972.76000000", "7.10010000"], ["1972.75000000", "16.12970000"], ["1972.74000000", "15.03870000"], ["1972.73000000", "22.82740000"], ["1972.62000000", "34.11640000"], ["1972.61000000", "7.56780000"], ["1972.38000000", "11.47740000"], ["1972.37000000", "0.00510000"], ["1972.35000000", "1.50000000"], ["1972.32000000", "15.69480000"], ["1971.78000000", "0.98520000"], ["1971.62000000", "1.28330000"], ["1971.55000000", "7.13110000"], ["1971.50000000", "24.36180000"], ["1971.35000000", "11.98320000"], ["1971.27000000", "8.88250000"], ["1971.15000000", "9.39440000"], ["1971.06000000", "8.56230000"], ["1970.95000000", "23.39830000"], ["1970.88000000", "8.97000000"], ["1970.78000000", "6.51510000"], ["1970.67000000", "2.12010000"], ["1970.66000000", "0.15440000"], ["1970.58000000", "18.14830000"], ["1970.33000000", "4.57410000"], ["1970.29000000", "12.56320000"], ["1969.92000000", "9.65530000"], ["1969.90000000", "0.03550000"], ["1969.86000000", "2.31340000"], ["1969.75000000", "4.36690000"], ["1969.66000000", "15.47620000"], ["1969.61000000", "0.50000000"], ["1969.55000000", "0.52510000"], ["1969.47000000", "1.17380000"], ["1968.91000000", "0.00260000"], ["1967.47000000", "0.05310000"], ["1963.80000000", "1.39280000"], ["1951.41000000", "0.00000000"], ["1775.97000000", "0.04340000"]], "a": [["1973.31000000", "45.02430000"], ["1973.38000000", "4.32130000"], ["1973.43000000", "0.00260000"], ["1973.54000000", "9.17650000"], ["1973.55000000", "7.09460000"], ["1973.56000000", "0.00000000"], ["1973.57000000", "8.51360000"], ["1973.82000000", "14.95260000"], ["1973.94000000", "20.02100000"], ["1973.97000000", "7.76220000"], ["1974.05000000", "0.04810000"], ["1974.08000000", "4.69110000"], ["1974.10000000", "17.49660000"], ["1974.38000000", "4.50560000"], ["1974.46000000", "0.56700000"], ["1974.58000000", "7.23420000"], ["1974.66000000", "13.46670000"], ["1974.73000000", "0.20260000"], ["1974.74000000", "10.03450000"], ["1974.88000000", "0.03000000"], ["1974.97000000", "2.46380000"], ["1974.99000000", "0.45900000"], ["1975.01000000", "7.15120000"], ["1975.10000000", "9.01820000"], ["1975.21000000", "4.72750000"], ["1975.46000000", "7.13500000"], ["1975.77000000", "7.13790000"], ["1975.87000000", "0.02000000"], ["1975.97000000", "0.00000000"], ["1976.23000000", "0.00000000"], ["1976.36000000", "0.00260000"], ["1976.55000000", "0.00000000"], ["1976.57000000", "0.00520000"], ["1976.64000000", "0.00000000"], ["1976.83000000", "0.00000000"], ["1977.34000000", "0.01920000"], ["1977.55000000", "0.00000000"], ["1977.93000000", "0.02320000"], ["1979.06000000", "0.02470000"], ["1979.21000000", "0.00880000"], ["1979.65000000", "0.03140000"], ["1990.74000000", "0.00430000"], ["2134.65000000", "0.00890000"]], "_local_ts_utc": "2026-06-01T07:49:01.010771+00:00"}
{"e": "depthUpdate", "E": 1780300142215, "s": "ETHUSDT", "U": 76583088075, "u": 76583088561, "b": [["1973.30000000", "0.00000000"], ["1973.29000000", "0.00000000"], ["1973.28000000", "0.00000000"], ["1973.26000000", "0.00000000"], ["1973.22000000", "0.00000000"], ["1973.21000000", "0.00000000"], ["1973.20000000", "0.00000000"], ["1973.19000000", "0.00000000"], ["1973.18000000", "0.00000000"], ["1973.13000000", "0.00000000"], ["1973.11000000", "0.00000000"], ["1973.10000000", "10.66550000"], ["1973.09000000", "0.36030000"], ["1973.08000000", "0.00510000"], ["1973.07000000", "0.00300000"], ["1973.06000000", "0.00650000"], ["1973.02000000", "0.00260000"], ["1973.00000000", "0.01060000"], ["1972.99000000", "0.84470000"], ["1972.98000000", "0.00260000"], ["1972.96000000", "0.00260000"], ["1972.93000000", "0.00000000"], ["1972.92000000", "0.00260000"], ["1972.91000000", "0.06040000"], ["1972.90000000", "0.00520000"], ["1972.89000000", "0.00540000"], ["1972.87000000", "10.24620000"], ["1972.86000000", "7.38420000"], ["1972.84000000", "0.00000000"], ["1972.82000000", "0.00000000"], ["1972.80000000", "20.03260000"], ["1972.76000000", "12.20670000"], ["1972.75000000", "0.01260000"], ["1972.74000000", "0.00300000"], ["1972.73000000", "0.00000000"], ["1972.72000000", "0.11460000"], ["1972.71000000", "0.27260000"], ["1972.70000000", "0.05570000"], ["1972.69000000", "0.06840000"], ["1972.68000000", "29.18260000"], ["1972.67000000", "0.00560000"], ["1972.66000000", "0.00930000"], ["1972.63000000", "13.80130000"], ["1972.62000000", "33.50770000"], ["1972.61000000", "0.27260000"], ["1972.59000000", "0.13420000"], ["1972.57000000", "8.51360000"], ["1972.56000000", "14.18920000"], ["1972.54000000", "19.38860000"], ["1972.52000000", "0.10630000"], ["1972.47000000", "4.93890000"], ["1972.46000000", "14.48110000"], ["1972.42000000", "8.52880000"], ["1972.40000000", "3.33450000"], ["1972.35000000", "0.00000000"], ["1972.31000000", "0.43400000"], ["1972.30000000", "6.42070000"], ["1972.25000000", "7.70630000"], ["1972.24000000", "1.27220000"], ["1972.20000000", "0.01090000"], ["1972.18000000", "1.21610000"], ["1972.09000000", "16.09800000"], ["1972.06000000", "1.52120000"], ["1972.03000000", "7.89520000"], ["1972.02000000", "0.59300000"], ["1971.86000000", "22.58600000"], ["1971.82000000", "13.51730000"], ["1971.81000000", "7.09520000"], ["1971.68000000", "21.49780000"], ["1971.31000000", "8.52950000"], ["1970.89000000", "0.00390000"], ["1970.79000000", "0.00910000"], ["1970.74000000", "22.70280000"], ["1970.67000000", "1.53650000"], ["1970.62000000", "0.22470000"], ["1970.59000000", "7.09460000"], ["1970.41000000", "7.09460000"], ["1970.40000000", "32.89480000"], ["1965.79000000", "0.00780000"], ["1965.45000000", "3.69640000"], ["1964.02000000", "0.00000000"], ["1963.80000000", "0.00000000"], ["1961.47000000", "0.06920000"], ["1775.97000000", "0.00000000"]], "a": [["1973.11000000", "83.39580000"], ["1973.12000000", "0.00770000"], ["1973.13000000", "10.05470000"], ["1973.14000000", "0.41770000"], ["1973.19000000", "0.00260000"], ["1973.20000000", "0.00830000"], ["1973.21000000", "15.56670000"], ["1973.22000000", "1.00260000"], ["1973.23000000", "0.00000000"], ["1973.27000000", "0.00000000"], ["1973.29000000", "0.01020000"], ["1973.30000000", "22.77680000"], ["1973.31000000", "4.15670000"], ["1973.32000000", "0.00260000"], ["1973.33000000", "0.01420000"], ["1973.35000000", "0.00000000"], ["1973.36000000", "0.00000000"], ["1973.37000000", "0.20130000"], ["1973.38000000", "1.31870000"], ["1973.39000000", "0.63660000"], ["1973.40000000", "0.00570000"], ["1973.42000000", "0.00000000"], ["1973.43000000", "0.00000000"], ["1973.44000000", "0.00000000"], ["1973.46000000", "13.83460000"], ["1973.49000000", "0.20000000"], ["1973.53000000", "7.19720000"], ["1973.56000000", "13.51370000"], ["1973.59000000", "10.30680000"], ["1973.60000000", "0.10730000"], ["1973.61000000", "2.39000000"], ["1973.65000000", "0.40000000"], ["1973.71000000", "12.14060000"], ["1973.72000000", "0.00000000"], ["1973.73000000", "0.05050000"], ["1973.83000000", "33.85280000"], ["1973.91000000", "0.05000000"], ["1973.97000000", "7.66220000"], ["1974.07000000", "0.00260000"], ["1974.10000000", "17.49400000"], ["1974.11000000", "17.79300000"], ["1974.12000000", "0.52300000"], ["1974.19000000", "13.97030000"], ["1974.20000000", "15.68270000"], ["1974.37000000", "1.86160000"], ["1974.59000000", "22.45110000"], ["1974.73000000", "0.00260000"], ["1974.89000000", "0.00000000"], ["1975.01000000", "5.03310000"], ["1975.02000000", "0.00000000"], ["1975.22000000", "0.00000000"], ["1975.57000000", "0.00000000"], ["1975.58000000", "0.00000000"], ["1976.29000000", "22.57370000"], ["1976.55000000", "0.55790000"], ["1977.82000000", "8.91970000"], ["1978.34000000", "0.00000000"], ["1978.59000000", "0.00260000"], ["1978.92000000", "0.19620000"], ["1981.98000000", "0.47890000"], ["1982.21000000", "0.00000000"], ["1984.10000000", "0.03280000"], ["2002.27000000", "0.00000000"], ["2002.51000000", "32.90810000"], ["2019.17000000", "0.00680000"]], "_local_ts_utc": "2026-06-01T07:49:01.111518+00:00"}
{"e": "depthUpdate", "E": 1780300142315, "s": "ETHUSDT", "U": 76583088562, "u": 76583088964, "b": [["1973.10000000", "51.20090000"], ["1973.09000000", "0.35250000"], ["1973.08000000", "0.00770000"], ["1973.06000000", "0.00260000"], ["1972.99000000", "0.83930000"], ["1972.92000000", "0.00000000"], ["1972.91000000", "0.06300000"], ["1972.90000000", "0.00830000"], ["1972.89000000", "16.36270000"], ["1972.88000000", "22.57370000"], ["1972.87000000", "6.50060000"], ["1972.86000000", "0.00390000"], ["1972.82000000", "0.00000000"], ["1972.81000000", "0.25910000"], ["1972.80000000", "20.03570000"], ["1972.79000000", "7.99020000"], ["1972.78000000", "0.37760000"], ["1972.77000000", "0.62360000"], ["1972.76000000", "0.00550000"], ["1972.74000000", "0.00300000"], ["1972.73000000", "0.63180000"], ["1972.71000000", "0.43100000"], ["1972.70000000", "3.65570000"], ["1972.69000000", "38.59790000"], ["1972.68000000", "0.01590000"], ["1972.64000000", "7.47550000"], ["1972.63000000", "0.03390000"], ["1972.61000000", "0.00260000"], ["1972.60000000", "25.97480000"], ["1972.57000000", "22.02730000"], ["1972.56000000", "14.18920000"], ["1972.55000000", "1.21820000"], ["1972.52000000", "0.71700000"], ["1972.47000000", "11.29930000"], ["1972.43000000", "13.66020000"], ["1972.40000000", "3.73450000"], ["1972.31000000", "0.05590000"], ["1972.28000000", "0.20000000"], ["1972.25000000", "8.10630000"], ["1972.24000000", "4.31780000"], ["1972.22000000", "0.37110000"], ["1972.09000000", "22.22340000"], ["1972.06000000", "1.32120000"], ["1972.03000000", "7.09520000"], ["1971.97000000", "0.00560000"], ["1971.78000000", "1.08520000"], ["1971.68000000", "21.39780000"], ["1971.56000000", "0.27410000"], ["1971.20000000", "0.85200000"], ["1970.78000000", "6.51510000"], ["1970.74000000", "0.00000000"], ["1970.67000000", "4.59470000"], ["1970.66000000", "10.70230000"], ["1970.60000000", "0.00310000"], ["1970.59000000", "0.00000000"], ["1970.56000000", "0.24160000"], ["1970.41000000", "0.00000000"], ["1970.40000000", "32.86480000"], ["1970.23000000", "0.01020000"], ["1969.57000000", "0.68130000"], ["1967.48000000", "1.21070000"], ["1967.39000000", "0.00260000"], ["1965.56000000", "0.24590000"], ["1962.09000000", "0.15530000"], ["1775.79000000", "0.03400000"]], "a": [["1973.11000000", "2.17280000"], ["1973.12000000", "0.00770000"], ["1973.13000000", "0.00770000"], ["1973.14000000", "0.00520000"], ["1973.15000000", "0.00000000"], ["1973.16000000", "0.00000000"], ["1973.18000000", "0.00000000"], ["1973.19000000", "0.00800000"], ["1973.20000000", "0.01370000"], ["1973.21000000", "3.00260000"], ["1973.22000000", "0.00260000"], ["1973.23000000", "0.10000000"], ["1973.28000000", "0.00000000"], ["1973.29000000", "0.00800000"], ["1973.30000000", "1.00720000"], ["1973.31000000", "1.32850000"], ["1973.32000000", "6.46760000"], ["1973.33000000", "0.00000000"], ["1973.34000000", "0.00390000"], ["1973.40000000", "0.00870000"], ["1973.42000000", "0.00260000"], ["1973.43000000", "0.00000000"], ["1973.44000000", "0.01160000"], ["1973.46000000", "22.57370000"], ["1973.47000000", "0.00000000"], ["1973.49000000", "0.00000000"], ["1973.51000000", "0.00000000"], ["1973.52000000", "15.55490000"], ["1973.53000000", "0.00260000"], ["1973.54000000", "0.00650000"], ["1973.55000000", "7.09460000"], ["1973.56000000", "7.09460000"], ["1973.57000000", "0.00000000"], ["1973.58000000", "0.00000000"], ["1973.61000000", "1.18450000"], ["1973.65000000", "0.00000000"], ["1973.66000000", "17.25580000"], ["1973.67000000", "2.55260000"], ["1973.68000000", "7.09460000"], ["1973.69000000", "22.57370000"], ["1973.70000000", "4.98280000"], ["1973.71000000", "9.60390000"], ["1973.75000000", "28.15290000"], ["1973.76000000", "0.00000000"], ["1973.77000000", "0.64640000"], ["1973.80000000", "17.04680000"], ["1973.81000000", "0.00000000"], ["1973.82000000", "0.00000000"], ["1973.83000000", "26.75760000"], ["1973.85000000", "2.95620000"], ["1973.87000000", "0.00260000"], ["1973.96000000", "14.22750000"], ["1973.98000000", "0.00260000"], ["1974.15000000", "1.37600000"], ["1974.18000000", "13.51370000"], ["1974.19000000", "0.45560000"], ["1974.33000000", "0.55680000"], ["1974.37000000", "0.46160000"], ["1974.51000000", "0.00260000"], ["1974.57000000", "9.86600000"], ["1974.59000000", "23.85110000"], ["1974.73000000", "7.09720000"], ["1974.75000000", "7.09580000"], ["1974.83000000", "8.51660000"], ["1974.84000000", "15.30090000"], ["1974.87000000", "0.00000000"], ["1974.94000000", "5.38590000"], ["1974.95000000", "7.09460000"], ["1974.97000000", "8.34510000"], ["1975.02000000", "7.09460000"], ["1975.05000000", "2.02800000"], ["1975.17000000", "2.01810000"], ["1975.19000000", "7.27290000"], ["1975.21000000", "0.00000000"], ["1975.26000000", "0.00260000"], ["1975.27000000", "0.93210000"], ["1975.35000000", "0.00520000"], ["1975.40000000", "5.13070000"], ["1975.46000000", "7.13500000"], ["1975.70000000", "13.51370000"], ["1975.77000000", "0.00000000"], ["1975.96000000", "12.59410000"], ["1975.97000000", "0.00000000"], ["1976.03000000", "0.00260000"], ["1976.28000000", "3.07990000"], ["1978.62000000", "3.60000000"], ["1978.67000000", "0.02000000"], ["1978.76000000", "0.98020000"], ["1978.82000000", "0.00260000"], ["1979.72000000", "0.15110000"], ["2144.39000000", "0.01350000"]], "_local_ts_utc": "2026-06-01T07:49:01.211610+00:00"}
{"e": "depthUpdate", "E": 1780300142415, "s": "ETHUSDT", "U": 76583088965, "u": 76583089067, "b": [["1973.10000000", "38.95290000"], ["1973.07000000", "0.00560000"], ["1972.97000000", "0.00540000"], ["1972.96000000", "1.29690000"], ["1972.91000000", "0.06560000"], ["1972.90000000", "10.22290000"], ["1972.89000000", "16.36810000"], ["1972.88000000", "23.87410000"], ["1972.87000000", "0.03300000"], ["1972.80000000", "21.77980000"], ["1972.79000000", "0.01020000"], ["1972.61000000", "0.05290000"], ["1972.36000000", "0.41570000"], ["1971.99000000", "1.01970000"], ["1971.78000000", "0.98520000"], ["1971.70000000", "0.10000000"], ["1971.37000000", "0.27000000"], ["1970.62000000", "0.78310000"], ["1775.79000000", "0.04640000"]], "a": [["1973.11000000", "7.56810000"], ["1973.16000000", "10.14880000"], ["1973.19000000", "0.00260000"], ["1973.21000000", "3.01420000"], ["1973.22000000", "0.00260000"], ["1973.23000000", "0.00260000"], ["1973.24000000", "0.00000000"], ["1973.27000000", "0.01160000"], ["1973.28000000", "4.52790000"], ["1973.29000000", "0.00260000"], ["1973.30000000", "1.80530000"], ["1973.31000000", "0.00000000"], ["1973.33000000", "0.00000000"], ["1973.39000000", "0.00000000"], ["1973.45000000", "4.28580000"], ["1973.51000000", "11.98990000"], ["1973.52000000", "7.63440000"], ["1973.70000000", "5.63080000"], ["1973.71000000", "15.42680000"], ["1973.82000000", "9.23190000"], ["1974.00000000", "22.60940000"], ["1974.16000000", "2.88330000"], ["1974.20000000", "16.33070000"], ["1974.83000000", "8.51660000"], ["1974.97000000", "8.17460000"], ["1975.54000000", "0.69200000"], ["1975.64000000", "4.63450000"], ["1975.76000000", "0.00000000"], ["1975.96000000", "0.45900000"], ["1976.25000000", "0.00000000"], ["1980.73000000", "0.16080000"]], "_local_ts_utc": "2026-06-01T07:49:01.310939+00:00"}
{"e": "depthUpdate", "E": 1780300142519, "s": "ETHUSDT", "U": 76583089068, "u": 76583089958, "b": [["1973.10000000", "0.00000000"], ["1973.09000000", "0.00000000"], ["1973.08000000", "0.00000000"], ["1973.07000000", "0.00000000"], ["1973.06000000", "0.00000000"], ["1973.02000000", "0.00000000"], ["1973.00000000", "0.00000000"], ["1972.99000000", "0.00000000"], ["1972.98000000", "0.00000000"], ["1972.97000000", "0.00000000"], ["1972.96000000", "0.00000000"], ["1972.91000000", "0.08070000"], ["1972.90000000", "0.02100000"], ["1972.89000000", "0.00260000"], ["1972.88000000", "0.00260000"], ["1972.87000000", "0.03560000"], ["1972.85000000", "0.00000000"], ["1972.81000000", "0.00820000"], ["1972.80000000", "20.03260000"], ["1972.74000000", "0.00300000"], ["1972.73000000", "0.00000000"], ["1972.72000000", "0.11460000"], ["1972.71000000", "0.05290000"], ["1972.70000000", "0.05260000"], ["1972.69000000", "0.00000000"], ["1972.67000000", "0.07400000"], ["1972.66000000", "0.00930000"], ["1972.64000000", "0.38090000"], ["1972.62000000", "0.01640000"], ["1972.61000000", "0.05830000"], ["1972.60000000", "0.02260000"], ["1972.59000000", "0.13960000"], ["1972.58000000", "0.00000000"], ["1972.57000000", "0.00000000"], ["1972.56000000", "0.00270000"], ["1972.55000000", "0.94820000"], ["1972.54000000", "0.00410000"], ["1972.53000000", "0.00000000"], ["1972.51000000", "0.00000000"], ["1972.50000000", "0.37060000"], ["1972.48000000", "7.88850000"], ["1972.47000000", "0.01020000"], ["1972.46000000", "0.11120000"], ["1972.44000000", "0.11860000"], ["1972.43000000", "0.04410000"], ["1972.42000000", "0.01520000"], ["1972.41000000", "0.10400000"], ["1972.40000000", "25.70820000"], ["1972.39000000", "0.00000000"], ["1972.38000000", "19.22230000"], ["1972.37000000", "0.00510000"], ["1972.36000000", "0.58530000"], ["1972.35000000", "0.27000000"], ["1972.34000000", "0.03040000"], ["1972.33000000", "0.01430000"], ["1972.32000000", "0.08540000"], ["1972.31000000", "0.05590000"], ["1972.30000000", "4.94920000"], ["1972.29000000", "0.00540000"], ["1972.28000000", "0.00000000"], ["1972.26000000", "0.01000000"], ["1972.25000000", "0.21110000"], ["1972.24000000", "1.27220000"], ["1972.23000000", "0.00570000"], ["1972.22000000", "0.37110000"], ["1972.21000000", "0.04210000"], ["1972.20000000", "31.73470000"], ["1972.19000000", "0.00300000"], ["1972.17000000", "4.54210000"], ["1972.16000000", "0.03580000"], ["1972.15000000", "0.01020000"], ["1972.14000000", "0.00260000"], ["1972.13000000", "0.04350000"], ["1972.12000000", "0.00000000"], ["1972.11000000", "0.05370000"], ["1972.10000000", "0.00830000"], ["1972.07000000", "0.00000000"], ["1972.06000000", "26.77920000"], ["1972.05000000", "11.25390000"], ["1972.04000000", "0.67000000"], ["1972.03000000", "7.09460000"], ["1972.02000000", "0.59300000"], ["1972.01000000", "0.00760000"], ["1972.00000000", "34.75270000"], ["1971.99000000", "1.02980000"], ["1971.98000000", "0.27000000"], ["1971.94000000", "1.34730000"], ["1971.91000000", "20.60830000"], ["1971.90000000", "20.65340000"], ["1971.87000000", "7.13920000"], ["1971.83000000", "0.01020000"], ["1971.82000000", "0.00260000"], ["1971.76000000", "6.29420000"], ["1971.74000000", "20.62590000"], ["1971.70000000", "0.00000000"], ["1971.67000000", "7.91940000"], ["1971.66000000", "24.14010000"], ["1971.53000000", "0.00300000"], ["1971.46000000", "0.00390000"], ["1971.36000000", "0.67210000"], ["1971.31000000", "8.53250000"], ["1971.30000000", "7.96100000"], ["1970.95000000", "13.92070000"], ["1970.93000000", "0.09280000"], ["1970.78000000", "12.45960000"], ["1970.74000000", "22.70280000"], ["1970.70000000", "0.00270000"], ["1970.65000000", "3.60270000"], ["1970.60000000", "19.87690000"], ["1970.59000000", "22.70280000"], ["1970.58000000", "7.23240000"], ["1970.41000000", "29.79740000"], ["1970.30000000", "7.09720000"], ["1970.24000000", "23.55480000"], ["1970.21000000", "14.19340000"], ["1969.47000000", "5.13640000"], ["1969.46000000", "13.52540000"], ["1969.30000000", "41.67040000"], ["1969.29000000", "22.57880000"], ["1969.26000000", "13.51370000"], ["1969.09000000", "0.00450000"], ["1968.93000000", "54.35660000"], ["1968.70000000", "0.00710000"], ["1968.18000000", "7.26510000"], ["1965.56000000", "0.23600000"], ["1965.54000000", "0.13260000"], ["1965.48000000", "5.01800000"], ["1964.75000000", "127.43190000"], ["1963.75000000", "0.44730000"], ["1962.15000000", "1.20550000"], ["1961.84000000", "0.00000000"], ["1961.82000000", "0.02000000"], ["1958.25000000", "0.00000000"], ["1957.14000000", "0.53100000"], ["1944.00000000", "5.54330000"], ["1942.33000000", "0.00830000"], ["1926.41000000", "0.08050000"], ["1910.49000000", "0.00000000"], ["1894.57000000", "0.01150000"], ["1878.65000000", "0.00000000"], ["1862.73000000", "0.00000000"], ["1846.81000000", "0.00000000"], ["1830.89000000", "0.00000000"], ["1814.97000000", "0.00520000"], ["1799.05000000", "0.09840000"], ["1783.12000000", "0.01400000"], ["1775.79000000", "0.01540000"], ["1775.65000000", "0.00300000"], ["1767.20000000", "0.03820000"], ["1751.28000000", "0.00000000"], ["1735.36000000", "0.00530000"], ["1719.44000000", "0.06030000"], ["1703.52000000", "0.01990000"], ["1687.60000000", "0.00000000"], ["1671.68000000", "0.00000000"], ["1655.76000000", "0.00000000"], ["1639.84000000", "0.03410000"], ["1623.92000000", "0.00000000"], ["1608.00000000", "6.18960000"], ["1592.08000000", "0.00000000"], ["1578.60000000", "0.04200000"], ["1578.52000000", "0.13230000"], ["1578.48000000", "0.07520000"]], "a": [["1972.92000000", "106.74290000"], ["1972.93000000", "0.00510000"], ["1972.94000000", "0.00510000"], ["1972.96000000", "30.75840000"], ["1972.97000000", "19.52080000"], ["1972.98000000", "3.09730000"], ["1972.99000000", "32.30880000"], ["1973.00000000", "32.31300000"], ["1973.01000000", "0.63090000"], ["1973.02000000", "0.00000000"], ["1973.03000000", "0.00000000"], ["1973.07000000", "0.00000000"], ["1973.08000000", "15.98320000"], ["1973.09000000", "0.00260000"], ["1973.10000000", "7.43750000"], ["1973.11000000", "4.62810000"], ["1973.12000000", "0.00000000"], ["1973.13000000", "0.00000000"], ["1973.14000000", "0.00260000"], ["1973.15000000", "0.00000000"], ["1973.16000000", "0.00000000"], ["1973.18000000", "0.57160000"], ["1973.19000000", "0.00000000"], ["1973.20000000", "0.91860000"], ["1973.21000000", "0.01160000"], ["1973.22000000", "0.00000000"], ["1973.23000000", "0.00260000"], ["1973.25000000", "0.00000000"], ["1973.26000000", "22.57370000"], ["1973.27000000", "0.00000000"], ["1973.28000000", "0.00000000"], ["1973.29000000", "0.01020000"], ["1973.30000000", "0.00830000"], ["1973.31000000", "0.03300000"], ["1973.32000000", "7.20230000"], ["1973.33000000", "0.00000000"], ["1973.34000000", "7.09850000"], ["1973.35000000", "8.51360000"], ["1973.36000000", "7.09460000"], ["1973.38000000", "7.09460000"], ["1973.40000000", "0.00870000"], ["1973.41000000", "0.20000000"], ["1973.44000000", "0.00000000"], ["1973.46000000", "23.22010000"], ["1973.51000000", "20.50350000"], ["1973.52000000", "11.93310000"], ["1973.54000000", "13.52020000"], ["1973.60000000", "0.00570000"], ["1973.61000000", "1.18190000"], ["1973.67000000", "2.59770000"], ["1973.70000000", "5.76080000"], ["1973.77000000", "0.00260000"], ["1973.91000000", "3.65000000"], ["1973.92000000", "0.03000000"], ["1973.94000000", "20.19150000"], ["1974.00000000", "22.60950000"], ["1974.12000000", "0.00000000"], ["1974.17000000", "0.62960000"], ["1974.19000000", "0.07750000"], ["1974.33000000", "1.91690000"], ["1974.59000000", "22.45110000"], ["1974.67000000", "13.51730000"], ["1974.73000000", "0.00260000"], ["1974.78000000", "7.72000000"], ["1974.83000000", "31.69130000"], ["1974.94000000", "3.48730000"], ["1974.95000000", "0.00000000"], ["1974.97000000", "1.08000000"], ["1975.02000000", "0.00000000"], ["1975.19000000", "0.17830000"], ["1975.64000000", "0.00000000"], ["1975.70000000", "0.00000000"], ["1977.01000000", "0.00000000"], ["1977.34000000", "0.00000000"], ["1977.62000000", "0.98460000"], ["1977.93000000", "0.00260000"], ["1978.00000000", "0.15310000"], ["1978.01000000", "0.01010000"], ["1978.11000000", "0.00520000"], ["1978.21000000", "0.02060000"], ["1978.23000000", "0.03040000"], ["1978.25000000", "0.06840000"], ["1978.27000000", "0.03550000"], ["1978.59000000", "0.00260000"], ["1978.70000000", "0.00000000"], ["1979.72000000", "0.00000000"], ["1981.19000000", "0.00000000"], ["1981.98000000", "0.00300000"], ["1983.90000000", "0.00550000"], ["1987.07000000", "0.04000000"], ["1987.09000000", "0.00000000"], ["1998.67000000", "0.00280000"]], "_local_ts_utc": "2026-06-01T07:49:01.416962+00:00"}
{"e": "depthUpdate", "E": 1780300142615, "s": "ETHUSDT", "U": 76583089959, "u": 76583090481, "b": [["1972.91000000", "0.00000000"], ["1972.90000000", "0.00000000"], ["1972.89000000", "0.00000000"], ["1972.88000000", "0.00000000"], ["1972.87000000", "0.00000000"], ["1972.86000000", "0.00000000"], ["1972.85000000", "0.00000000"], ["1972.81000000", "0.00000000"], ["1972.80000000", "16.02580000"], ["1972.79000000", "0.01580000"], ["1972.78000000", "0.38560000"], ["1972.77000000", "0.62620000"], ["1972.76000000", "0.00810000"], ["1972.75000000", "0.01260000"], ["1972.74000000", "0.00560000"], ["1972.72000000", "0.08720000"], ["1972.71000000", "0.00520000"], ["1972.66000000", "0.01470000"], ["1972.65000000", "0.20390000"], ["1972.64000000", "1.66240000"], ["1972.61000000", "0.00540000"], ["1972.59000000", "0.13420000"], ["1972.56000000", "0.00270000"], ["1972.52000000", "0.66670000"], ["1972.49000000", "0.00000000"], ["1972.48000000", "0.04480000"], ["1972.42000000", "4.03030000"], ["1972.41000000", "10.31640000"], ["1972.40000000", "3.13450000"], ["1972.38000000", "0.00810000"], ["1972.36000000", "0.38530000"], ["1972.35000000", "0.00000000"], ["1972.32000000", "0.03510000"], ["1972.31000000", "2.09660000"], ["1972.30000000", "17.72450000"], ["1972.28000000", "0.00000000"], ["1972.26000000", "0.26370000"], ["1972.25000000", "0.21110000"], ["1972.23000000", "0.00570000"], ["1972.22000000", "0.32080000"], ["1972.21000000", "29.84700000"], ["1972.20000000", "30.22100000"], ["1972.19000000", "0.00300000"], ["1972.18000000", "1.21610000"], ["1972.17000000", "0.16110000"], ["1972.12000000", "0.10140000"], ["1972.10000000", "25.81410000"], ["1972.08000000", "0.00760000"], ["1972.06000000", "0.02120000"], ["1972.04000000", "1.53000000"], ["1972.03000000", "7.47270000"], ["1972.02000000", "16.15090000"], ["1972.00000000", "42.57730000"], ["1971.93000000", "6.65190000"], ["1971.92000000", "7.10630000"], ["1971.90000000", "20.65600000"], ["1971.89000000", "0.00000000"], ["1971.88000000", "1.51130000"], ["1971.86000000", "22.58600000"], ["1971.84000000", "0.03000000"], ["1971.67000000", "7.11940000"], ["1971.49000000", "33.85320000"], ["1971.36000000", "0.58670000"], ["1971.30000000", "7.86100000"], ["1971.28000000", "0.00880000"], ["1971.24000000", "1.11340000"], ["1971.17000000", "0.00000000"], ["1970.91000000", "0.21550000"], ["1970.88000000", "9.05660000"], ["1970.62000000", "0.00260000"], ["1970.52000000", "0.00290000"], ["1970.50000000", "22.96410000"], ["1970.42000000", "15.61080000"], ["1970.41000000", "14.23710000"], ["1970.40000000", "32.89480000"], ["1970.33000000", "8.22920000"], ["1970.31000000", "21.28380000"], ["1970.30000000", "0.00260000"], ["1970.21000000", "0.00420000"], ["1970.12000000", "4.31000000"], ["1970.11000000", "14.19920000"], ["1970.08000000", "0.08690000"], ["1970.02000000", "13.64650000"], ["1969.27000000", "0.19480000"], ["1969.25000000", "58.96940000"], ["1969.16000000", "0.52290000"], ["1967.54000000", "1.00260000"], ["1967.27000000", "0.13130000"], ["1967.18000000", "4.19140000"], ["1967.09000000", "0.00260000"], ["1966.82000000", "0.35290000"], ["1966.18000000", "0.00000000"], ["1966.14000000", "0.13550000"], ["1965.92000000", "0.01200000"], ["1965.89000000", "0.00970000"], ["1965.53000000", "0.02470000"], ["1965.25000000", "3.72290000"], ["1964.65000000", "0.10000000"], ["1964.15000000", "0.38780000"], ["1964.11000000", "0.96390000"], ["1963.79000000", "2.35480000"], ["1963.73000000", "6.93580000"], ["1958.53000000", "0.00000000"], ["1956.93000000", "3.14970000"], ["1954.98000000", "4.15240000"], ["1775.52000000", "0.41240000"], ["1578.33000000", "0.00700000"], ["1472.80000000", "0.02740000"]], "a": [["1972.81000000", "56.32860000"], ["1972.82000000", "3.00510000"], ["1972.83000000", "0.00510000"], ["1972.86000000", "0.00000000"], ["1972.87000000", "0.00000000"], ["1972.88000000", "0.00000000"], ["1972.89000000", "0.00000000"], ["1972.90000000", "0.00570000"], ["1972.91000000", "4.97710000"], ["1972.92000000", "1.56020000"], ["1972.93000000", "0.00260000"], ["1972.94000000", "0.00260000"], ["1972.95000000", "36.76650000"], ["1972.96000000", "7.10920000"], ["1972.97000000", "2.01320000"], ["1972.98000000", "0.09730000"], ["1972.99000000", "0.00260000"], ["1973.00000000", "1.79330000"], ["1973.03000000", "0.00260000"], ["1973.06000000", "3.31550000"], ["1973.07000000", "7.09760000"], ["1973.08000000", "0.00000000"], ["1973.09000000", "0.03300000"], ["1973.10000000", "4.90130000"], ["1973.11000000", "13.14120000"], ["1973.13000000", "1.20550000"], ["1973.14000000", "0.00650000"], ["1973.19000000", "0.00000000"], ["1973.20000000", "10.28830000"], ["1973.21000000", "0.00000000"], ["1973.22000000", "7.59720000"], ["1973.23000000", "7.09720000"], ["1973.32000000", "12.12190000"], ["1973.33000000", "13.51370000"], ["1973.45000000", "10.59020000"], ["1973.50000000", "30.77740000"], ["1973.51000000", "8.51360000"], ["1973.54000000", "13.51760000"], ["1973.73000000", "0.00000000"], ["1973.80000000", "7.10050000"], ["1973.85000000", "0.00000000"], ["1973.90000000", "1.20860000"], ["1973.92000000", "0.11660000"], ["1973.96000000", "29.36750000"], ["1974.22000000", "0.76000000"], ["1974.35000000", "1.25900000"], ["1974.40000000", "13.54780000"], ["1974.44000000", "0.22650000"], ["1974.48000000", "0.03000000"], ["1974.56000000", "5.50040000"], ["1974.58000000", "0.16360000"], ["1974.59000000", "8.26070000"], ["1974.72000000", "0.45970000"], ["1974.74000000", "3.96360000"], ["1974.75000000", "0.00000000"], ["1974.82000000", "18.59990000"], ["1974.84000000", "0.00000000"], ["1974.85000000", "0.00260000"], ["1974.91000000", "0.00520000"], ["1974.94000000", "1.40940000"], ["1975.10000000", "0.00000000"], ["1975.18000000", "32.51290000"], ["1975.27000000", "0.70130000"], ["1975.36000000", "0.00000000"], ["1975.37000000", "31.67960000"], ["1975.46000000", "0.03300000"], ["1975.49000000", "100.85850000"], ["1975.54000000", "0.00380000"], ["1975.55000000", "0.00260000"], ["1975.60000000", "1.10480000"], ["1975.69000000", "1.02040000"], ["1976.18000000", "1.20810000"], ["1976.28000000", "0.00000000"], ["1976.65000000", "3.60260000"], ["1976.89000000", "0.00000000"], ["1977.25000000", "0.00000000"], ["1977.97000000", "1.45000000"], ["1978.11000000", "0.00520000"], ["1978.27000000", "0.03290000"], ["1978.36000000", "0.00000000"], ["1978.40000000", "0.02190000"], ["1978.46000000", "0.00000000"], ["1978.51000000", "0.00000000"], ["1978.55000000", "0.01030000"], ["1979.60000000", "0.03570000"], ["1979.93000000", "31.60660000"], ["1979.95000000", "0.00000000"], ["1980.26000000", "0.00000000"], ["1981.74000000", "0.00000000"], ["2154.42000000", "0.14110000"]], "_local_ts_utc": "2026-06-01T07:49:01.511786+00:00"}
{"e": "depthUpdate", "E": 1780300142715, "s": "ETHUSDT", "U": 76583090482, "u": 76583091005, "b": [["1972.80000000", "54.74520000"], ["1972.79000000", "0.00780000"], ["1972.78000000", "0.00800000"], ["1972.73000000", "0.50700000"], ["1972.70000000", "0.05520000"], ["1972.67000000", "0.07940000"], ["1972.66000000", "0.63650000"], ["1972.65000000", "0.19850000"], ["1972.64000000", "0.01520000"], ["1972.63000000", "0.03930000"], ["1972.62000000", "1.34300000"], ["1972.56000000", "0.00000000"], ["1972.52000000", "0.05600000"], ["1972.50000000", "0.36750000"], ["1972.46000000", "22.68490000"], ["1972.43000000", "6.51170000"], ["1972.42000000", "22.72370000"], ["1972.40000000", "3.13450000"], ["1972.37000000", "7.10150000"], ["1972.36000000", "20.45270000"], ["1972.35000000", "0.00000000"], ["1972.34000000", "0.03040000"], ["1972.32000000", "22.74360000"], ["1972.31000000", "0.05590000"], ["1972.30000000", "17.72450000"], ["1972.27000000", "7.10280000"], ["1972.26000000", "22.83740000"], ["1972.25000000", "0.21110000"], ["1972.24000000", "0.00000000"], ["1972.23000000", "0.00570000"], ["1972.22000000", "36.54300000"], ["1972.21000000", "0.04210000"], ["1972.20000000", "9.44540000"], ["1972.18000000", "0.20250000"], ["1972.16000000", "7.33220000"], ["1972.14000000", "0.61330000"], ["1972.13000000", "0.04350000"], ["1972.12000000", "15.20770000"], ["1972.11000000", "0.05370000"], ["1972.10000000", "12.30040000"], ["1972.09000000", "31.44000000"], ["1972.06000000", "36.10860000"], ["1972.05000000", "3.61930000"], ["1972.03000000", "14.19100000"], ["1972.02000000", "15.88090000"], ["1972.01000000", "0.00760000"], ["1971.94000000", "0.00000000"], ["1971.93000000", "0.06130000"], ["1971.92000000", "20.62000000"], ["1971.91000000", "7.09460000"], ["1971.88000000", "0.01130000"], ["1971.87000000", "7.93920000"], ["1971.83000000", "1.21570000"], ["1971.78000000", "6.53290000"], ["1971.77000000", "4.61660000"], ["1971.76000000", "0.01280000"], ["1971.74000000", "7.11220000"], ["1971.72000000", "0.27260000"], ["1971.70000000", "21.11830000"], ["1971.69000000", "13.88000000"], ["1971.68000000", "8.55770000"], ["1971.55000000", "10.25330000"], ["1971.51000000", "13.52650000"], ["1971.50000000", "31.36010000"], ["1971.49000000", "33.95320000"], ["1971.47000000", "0.27000000"], ["1971.46000000", "0.00390000"], ["1971.45000000", "5.25160000"], ["1971.36000000", "0.48670000"], ["1971.26000000", "0.71060000"], ["1971.24000000", "1.01340000"], ["1970.88000000", "9.08660000"], ["1970.60000000", "20.09900000"], ["1970.59000000", "14.18920000"], ["1970.43000000", "0.16650000"], ["1970.42000000", "0.00260000"], ["1970.37000000", "1.04710000"], ["1970.31000000", "0.00000000"], ["1970.30000000", "0.00260000"], ["1970.12000000", "0.04540000"], ["1970.11000000", "0.01000000"], ["1970.08000000", "0.05690000"], ["1970.01000000", "145.17930000"], ["1969.26000000", "0.00000000"], ["1969.06000000", "3.62790000"], ["1968.99000000", "37.47550000"], ["1966.74000000", "0.13250000"], ["1965.48000000", "5.00880000"], ["1965.24000000", "0.00810000"], ["1963.44000000", "0.58190000"], ["1963.17000000", "1.39880000"], ["1962.15000000", "0.00000000"], ["1961.82000000", "0.00000000"], ["1956.93000000", "0.00000000"], ["1956.80000000", "3.16080000"], ["1775.52000000", "0.42480000"], ["1579.13000000", "0.04510000"], ["1578.94000000", "0.00360000"], ["1578.91000000", "0.00000000"], ["1578.81000000", "0.00000000"], ["1578.71000000", "0.00000000"], ["1578.24000000", "0.07000000"]], "a": [["1972.81000000", "19.02540000"], ["1972.82000000", "3.00770000"], ["1972.83000000", "0.00770000"], ["1972.86000000", "0.00000000"], ["1972.87000000", "0.00000000"], ["1972.90000000", "0.00830000"], ["1972.91000000", "6.47020000"], ["1972.92000000", "0.04610000"], ["1972.94000000", "0.00260000"], ["1972.95000000", "0.00260000"], ["1972.96000000", "0.01820000"], ["1972.97000000", "2.01060000"], ["1972.98000000", "0.09470000"], ["1972.99000000", "0.00540000"], ["1973.00000000", "0.37820000"], ["1973.01000000", "0.62830000"], ["1973.04000000", "0.00000000"], ["1973.05000000", "15.10430000"], ["1973.06000000", "0.00000000"], ["1973.07000000", "0.00300000"], ["1973.08000000", "0.01160000"], ["1973.09000000", "0.03300000"], ["1973.10000000", "5.12440000"], ["1973.11000000", "3.54870000"], ["1973.13000000", "0.00000000"], ["1973.16000000", "0.00000000"], ["1973.17000000", "0.60000000"], ["1973.19000000", "0.00000000"], ["1973.20000000", "17.80890000"], ["1973.22000000", "0.00260000"], ["1973.23000000", "26.76060000"], ["1973.25000000", "0.00000000"], ["1973.30000000", "2.20030000"], ["1973.31000000", "14.22580000"], ["1973.32000000", "0.05050000"], ["1973.33000000", "0.00000000"], ["1973.34000000", "0.00390000"], ["1973.35000000", "0.00000000"], ["1973.36000000", "0.50680000"], ["1973.38000000", "0.00000000"], ["1973.41000000", "0.00000000"], ["1973.43000000", "23.04800000"], ["1973.44000000", "29.80490000"], ["1973.45000000", "0.00000000"], ["1973.46000000", "22.57370000"], ["1973.50000000", "9.94940000"], ["1973.51000000", "4.55440000"], ["1973.52000000", "4.93850000"], ["1973.54000000", "0.00390000"], ["1973.55000000", "0.00000000"], ["1973.56000000", "0.00000000"], ["1973.63000000", "8.51570000"], ["1973.65000000", "27.55710000"], ["1973.66000000", "0.00000000"], ["1973.67000000", "2.44660000"], ["1973.71000000", "0.00260000"], ["1973.73000000", "0.00000000"], ["1973.74000000", "9.46750000"], ["1973.75000000", "14.63920000"], ["1973.82000000", "0.00000000"], ["1973.83000000", "0.00260000"], ["1973.94000000", "20.56960000"], ["1973.97000000", "7.87520000"], ["1974.13000000", "0.00260000"], ["1974.15000000", "1.20550000"], ["1974.20000000", "17.73070000"], ["1974.33000000", "0.51690000"], ["1974.39000000", "8.31470000"], ["1974.42000000", "14.19040000"], ["1974.48000000", "8.54570000"], ["1974.56000000", "3.66580000"], ["1974.59000000", "1.16550000"], ["1974.61000000", "7.09940000"], ["1974.64000000", "7.12640000"], ["1974.65000000", "15.61210000"], ["1974.80000000", "22.08520000"], ["1974.81000000", "22.49470000"], ["1974.82000000", "0.03560000"], ["1974.83000000", "0.00300000"], ["1975.03000000", "8.07440000"], ["1975.05000000", "9.12440000"], ["1975.10000000", "9.01820000"], ["1975.18000000", "4.16700000"], ["1975.25000000", "0.03300000"], ["1975.35000000", "6.03920000"], ["1975.36000000", "13.51370000"], ["1975.69000000", "13.51630000"], ["1975.80000000", "0.75910000"], ["1975.87000000", "1.16690000"], ["1976.30000000", "0.00260000"], ["1976.55000000", "0.00000000"], ["1977.14000000", "0.02300000"], ["1979.72000000", "0.00000000"], ["1980.13000000", "2.72560000"], ["1980.55000000", "126.38660000"], ["1981.40000000", "1.48680000"], ["1981.98000000", "1.33470000"], ["1982.70000000", "0.00000000"], ["1983.53000000", "0.00000000"], ["1985.37000000", "0.00260000"], ["1987.07000000", "0.02000000"], ["1989.08000000", "0.00000000"], ["1996.51000000", "0.10000000"]], "_local_ts_utc": "2026-06-01T07:49:01.611784+00:00"}
{"e": "depthUpdate", "E": 1780300142815, "s": "ETHUSDT", "U": 76583091006, "u": 76583091566, "b": [["1972.89000000", "38.82840000"], ["1972.84000000", "0.00000000"], ["1972.83000000", "0.00000000"], ["1972.82000000", "0.00800000"], ["1972.81000000", "0.00800000"], ["1972.80000000", "15.54830000"], ["1972.79000000", "0.01280000"], ["1972.78000000", "0.00260000"], ["1972.74000000", "0.00560000"], ["1972.73000000", "0.50700000"], ["1972.72000000", "0.08460000"], ["1972.71000000", "0.00260000"], ["1972.70000000", "0.05260000"], ["1972.69000000", "0.00000000"], ["1972.68000000", "0.01590000"], ["1972.67000000", "1.38340000"], ["1972.66000000", "0.63500000"], ["1972.64000000", "0.04520000"], ["1972.63000000", "0.03390000"], ["1972.57000000", "0.00000000"], ["1972.56000000", "6.46760000"], ["1972.55000000", "11.88910000"], ["1972.54000000", "14.19690000"], ["1972.53000000", "0.00000000"], ["1972.52000000", "8.57170000"], ["1972.50000000", "0.37060000"], ["1972.47000000", "39.89130000"], ["1972.46000000", "0.11120000"], ["1972.45000000", "0.63790000"], ["1972.43000000", "7.79380000"], ["1972.41000000", "0.48150000"], ["1972.37000000", "19.42170000"], ["1972.36000000", "13.62900000"], ["1972.30000000", "18.06020000"], ["1972.29000000", "3.60540000"], ["1972.22000000", "36.27300000"], ["1972.16000000", "7.13220000"], ["1972.14000000", "0.00260000"], ["1972.09000000", "31.04000000"], ["1972.04000000", "1.26000000"], ["1972.02000000", "16.48090000"], ["1971.98000000", "0.00000000"], ["1971.92000000", "20.82000000"], ["1971.90000000", "20.65340000"], ["1971.89000000", "1.27240000"], ["1971.87000000", "7.13920000"], ["1971.80000000", "0.80310000"], ["1971.78000000", "10.50830000"], ["1971.74000000", "7.11220000"], ["1971.70000000", "20.91830000"], ["1971.68000000", "8.55770000"], ["1971.65000000", "4.93800000"], ["1971.64000000", "0.01270000"], ["1971.49000000", "33.85320000"], ["1971.47000000", "0.27000000"], ["1971.41000000", "0.10000000"], ["1971.23000000", "24.61180000"], ["1970.74000000", "14.18920000"], ["1970.60000000", "13.32220000"], ["1970.59000000", "0.00000000"], ["1970.50000000", "16.12550000"], ["1970.41000000", "0.04790000"], ["1970.33000000", "4.57410000"], ["1970.24000000", "23.52480000"], ["1969.47000000", "0.09790000"], ["1969.46000000", "1.16010000"], ["1967.81000000", "0.00000000"], ["1967.34000000", "0.13250000"], ["1965.24000000", "0.00000000"], ["1775.61000000", "0.01240000"], ["1775.52000000", "0.40000000"], ["1192.00000000", "0.00000000"]], "a": [["1972.81000000", "0.00000000"], ["1972.82000000", "0.00000000"], ["1972.83000000", "0.00000000"], ["1972.90000000", "37.77950000"], ["1972.91000000", "0.00260000"], ["1972.92000000", "0.00260000"], ["1972.94000000", "0.01420000"], ["1972.97000000", "1.86720000"], ["1972.98000000", "0.01420000"], ["1972.99000000", "0.00260000"], ["1973.00000000", "0.01110000"], ["1973.02000000", "0.00540000"], ["1973.03000000", "0.00260000"], ["1973.04000000", "0.00000000"], ["1973.05000000", "0.00000000"], ["1973.06000000", "0.00000000"], ["1973.08000000", "6.46760000"], ["1973.09000000", "0.03300000"], ["1973.10000000", "2.41390000"], ["1973.11000000", "1.61100000"], ["1973.14000000", "0.00390000"], ["1973.16000000", "0.01160000"], ["1973.17000000", "0.00000000"], ["1973.20000000", "21.07530000"], ["1973.22000000", "22.57630000"], ["1973.25000000", "21.28920000"], ["1973.26000000", "0.00000000"], ["1973.27000000", "0.00000000"], ["1973.30000000", "0.00830000"], ["1973.31000000", "0.03300000"], ["1973.36000000", "2.68860000"], ["1973.37000000", "7.29770000"], ["1973.39000000", "0.00280000"], ["1973.40000000", "0.00870000"], ["1973.42000000", "50.68480000"], ["1973.43000000", "0.00000000"], ["1973.44000000", "1.20550000"], ["1973.45000000", "7.74280000"], ["1973.47000000", "0.60000000"], ["1973.50000000", "17.04580000"], ["1973.51000000", "4.84430000"], ["1973.52000000", "0.13300000"], ["1973.58000000", "7.09640000"], ["1973.62000000", "22.07710000"], ["1973.65000000", "0.00000000"], ["1973.67000000", "2.59770000"], ["1973.70000000", "9.36080000"], ["1973.73000000", "13.51370000"], ["1973.80000000", "7.10030000"], ["1973.94000000", "20.39910000"], ["1973.96000000", "14.22750000"], ["1974.16000000", "0.03000000"], ["1974.20000000", "16.33070000"], ["1974.28000000", "1.40260000"], ["1974.60000000", "24.28230000"], ["1974.61000000", "22.24320000"], ["1974.63000000", "8.51570000"], ["1974.65000000", "7.09640000"], ["1974.66000000", "0.15110000"], ["1974.79000000", "0.00000000"], ["1974.81000000", "8.30190000"], ["1974.89000000", "0.00000000"], ["1975.01000000", "5.03310000"], ["1975.02000000", "0.00000000"], ["1975.03000000", "0.97800000"], ["1975.04000000", "0.03000000"], ["1975.05000000", "2.02800000"], ["1975.24000000", "0.00000000"], ["1975.68000000", "0.03300000"], ["1975.69000000", "0.00260000"], ["1976.18000000", "1.20810000"], ["1976.42000000", "0.59580000"], ["1978.25000000", "0.07100000"], ["1979.72000000", "0.00000000"], ["1981.40000000", "1.00380000"], ["1988.11000000", "4.10190000"], ["2164.76000000", "0.01440000"]], "_local_ts_utc": "2026-06-01T07:49:01.711281+00:00"}
{"e": "depthUpdate", "E": 1780300142915, "s": "ETHUSDT", "U": 76583091567, "u": 76583092013, "b": [["1972.97000000", "19.49940000"], ["1972.96000000", "101.64120000"], ["1972.95000000", "41.29190000"], ["1972.94000000", "0.04980000"], ["1972.93000000", "0.00260000"], ["1972.92000000", "0.00260000"], ["1972.91000000", "0.00800000"], ["1972.90000000", "5.70490000"], ["1972.89000000", "4.65930000"], ["1972.82000000", "0.00260000"], ["1972.81000000", "0.00260000"], ["1972.80000000", "15.54570000"], ["1972.79000000", "0.01020000"], ["1972.78000000", "0.00000000"], ["1972.77000000", "0.62360000"], ["1972.76000000", "0.00550000"], ["1972.75000000", "0.01000000"], ["1972.74000000", "0.00300000"], ["1972.73000000", "0.50960000"], ["1972.69000000", "0.00000000"], ["1972.68000000", "2.90110000"], ["1972.66000000", "7.10260000"], ["1972.63000000", "8.54960000"], ["1972.58000000", "16.26060000"], ["1972.57000000", "20.61010000"], ["1972.56000000", "0.00000000"], ["1972.55000000", "0.94820000"], ["1972.52000000", "8.52140000"], ["1972.48000000", "22.40020000"], ["1972.47000000", "29.68030000"], ["1972.43000000", "0.04410000"], ["1972.38000000", "12.19530000"], ["1972.37000000", "7.10150000"], ["1972.23000000", "4.57470000"], ["1972.16000000", "7.53220000"], ["1972.14000000", "1.50260000"], ["1972.12000000", "8.61710000"], ["1972.02000000", "16.68090000"], ["1971.92000000", "20.62000000"], ["1971.82000000", "0.05290000"], ["1971.80000000", "0.00310000"], ["1971.77000000", "0.24860000"], ["1971.70000000", "19.61830000"], ["1971.63000000", "7.20890000"], ["1971.41000000", "0.00000000"], ["1971.20000000", "0.85500000"], ["1970.94000000", "14.19320000"], ["1970.74000000", "7.09460000"], ["1967.95000000", "0.18580000"], ["1967.90000000", "0.16110000"], ["1967.89000000", "0.50050000"], ["1967.80000000", "0.00000000"], ["1967.33000000", "0.13270000"], ["1965.48000000", "5.01800000"], ["1775.61000000", "0.00000000"]], "a": [["1972.90000000", "0.00000000"], ["1972.91000000", "0.00000000"], ["1972.92000000", "0.00000000"], ["1972.93000000", "0.00000000"], ["1972.94000000", "0.00000000"], ["1972.95000000", "0.00000000"], ["1972.96000000", "0.00000000"], ["1972.97000000", "0.00000000"], ["1972.98000000", "2.01840000"], ["1973.00000000", "0.01370000"], ["1973.01000000", "0.00260000"], ["1973.02000000", "0.00260000"], ["1973.03000000", "0.00260000"], ["1973.06000000", "2.74350000"], ["1973.07000000", "0.01100000"], ["1973.08000000", "0.00260000"], ["1973.09000000", "0.04100000"], ["1973.10000000", "0.66700000"], ["1973.11000000", "0.00260000"], ["1973.12000000", "0.00000000"], ["1973.16000000", "0.00000000"], ["1973.18000000", "0.56300000"], ["1973.20000000", "10.28830000"], ["1973.22000000", "0.00260000"], ["1973.23000000", "0.00260000"], ["1973.24000000", "22.57370000"], ["1973.25000000", "0.00000000"], ["1973.33000000", "0.01160000"], ["1973.36000000", "7.56370000"], ["1973.37000000", "0.20130000"], ["1973.40000000", "17.26630000"], ["1973.41000000", "0.00000000"], ["1973.42000000", "15.61470000"], ["1973.44000000", "0.00000000"], ["1973.47000000", "0.00000000"], ["1973.53000000", "0.60260000"], ["1973.59000000", "6.02180000"], ["1973.63000000", "8.51830000"], ["1973.67000000", "2.44660000"], ["1973.70000000", "5.76080000"], ["1973.75000000", "14.64180000"], ["1973.84000000", "0.00260000"], ["1973.90000000", "1.21120000"], ["1974.09000000", "7.26570000"], ["1974.28000000", "0.00260000"], ["1974.35000000", "1.45900000"], ["1974.42000000", "15.39040000"], ["1974.79000000", "14.19280000"], ["1974.82000000", "0.03560000"], ["1975.01000000", "12.12950000"], ["1975.03000000", "8.07440000"], ["1975.69000000", "13.51630000"], ["1976.18000000", "1.20550000"], ["1977.14000000", "0.02000000"], ["1979.06000000", "0.00320000"], ["1979.65000000", "0.00000000"], ["1979.72000000", "0.15110000"], ["1981.49000000", "0.00260000"], ["1988.11000000", "0.99410000"], ["2804.23000000", "0.00000000"]], "_local_ts_utc": "2026-06-01T07:49:01.811380+00:00"}
{"e": "depthUpdate", "E": 1780300143015, "s": "ETHUSDT", "U": 76583092014, "u": 76583092305, "b": [["1972.97000000", "92.70170000"], ["1972.96000000", "10.50410000"], ["1972.95000000", "19.66840000"], ["1972.94000000", "0.00260000"], ["1972.91000000", "0.00800000"], ["1972.90000000", "10.01070000"], ["1972.84000000", "0.00880000"], ["1972.82000000", "6.47020000"], ["1972.81000000", "0.00000000"], ["1972.80000000", "15.57570000"], ["1972.79000000", "0.01020000"], ["1972.78000000", "7.35010000"], ["1972.77000000", "7.60240000"], ["1972.76000000", "7.10190000"], ["1972.74000000", "7.09940000"], ["1972.73000000", "9.02530000"], ["1972.70000000", "0.05570000"], ["1972.68000000", "24.32110000"], ["1972.67000000", "23.95710000"], ["1972.66000000", "14.14870000"], ["1972.65000000", "7.29490000"], ["1972.64000000", "7.14160000"], ["1972.63000000", "0.03390000"], ["1972.62000000", "9.85870000"], ["1972.60000000", "2.56250000"], ["1972.58000000", "20.68830000"], ["1972.57000000", "0.00000000"], ["1972.52000000", "22.03510000"], ["1972.44000000", "0.49670000"], ["1972.41000000", "0.48930000"], ["1972.39000000", "0.15110000"], ["1972.32000000", "23.01360000"], ["1972.28000000", "6.69200000"], ["1972.26000000", "22.58370000"], ["1972.21000000", "0.09240000"], ["1972.20000000", "15.84430000"], ["1972.15000000", "26.76920000"], ["1972.12000000", "8.51570000"], ["1972.02000000", "16.41090000"], ["1971.55000000", "7.13110000"], ["1971.52000000", "0.08290000"], ["1971.50000000", "20.74350000"], ["1971.49000000", "7.09520000"], ["1971.15000000", "6.85290000"], ["1971.11000000", "14.60730000"], ["1970.97000000", "3.31160000"], ["1970.95000000", "7.09520000"], ["1970.94000000", "0.00280000"], ["1970.88000000", "9.00000000"], ["1970.79000000", "0.00910000"], ["1970.78000000", "4.39720000"], ["1970.75000000", "0.42550000"], ["1970.74000000", "0.00000000"], ["1970.58000000", "0.13720000"], ["1970.54000000", "0.27000000"], ["1970.40000000", "32.86480000"], ["1969.75000000", "0.00000000"], ["1969.74000000", "0.52710000"], ["1968.55000000", "0.21620000"], ["1967.18000000", "4.18880000"], ["1967.09000000", "0.00000000"], ["1951.90000000", "0.00000000"], ["1775.68000000", "0.01240000"], ["1579.13000000", "0.03810000"], ["1578.38000000", "0.00700000"], ["1472.80000000", "0.01540000"]], "a": [["1972.98000000", "0.65930000"], ["1973.00000000", "0.00830000"], ["1973.03000000", "0.00260000"], ["1973.05000000", "0.00000000"], ["1973.06000000", "0.00260000"], ["1973.07000000", "0.00560000"], ["1973.09000000", "0.03560000"], ["1973.10000000", "0.00570000"], ["1973.11000000", "0.00000000"], ["1973.17000000", "0.00540000"], ["1973.19000000", "0.01700000"], ["1973.20000000", "1.94350000"], ["1973.22000000", "6.47020000"], ["1973.23000000", "0.00260000"], ["1973.24000000", "0.00000000"], ["1973.30000000", "0.01990000"], ["1973.36000000", "3.93760000"], ["1973.40000000", "11.28060000"], ["1973.42000000", "0.00260000"], ["1973.44000000", "4.30200000"], ["1973.45000000", "7.84420000"], ["1973.47000000", "0.00260000"], ["1973.48000000", "0.94500000"], ["1973.49000000", "7.09640000"], ["1973.50000000", "9.94940000"], ["1973.52000000", "0.03300000"], ["1973.53000000", "0.00260000"], ["1973.58000000", "7.79640000"], ["1973.73000000", "21.46380000"], ["1973.74000000", "26.79590000"], ["1973.77000000", "16.05310000"], ["1973.97000000", "8.60720000"], ["1974.36000000", "0.21570000"], ["1974.50000000", "0.20420000"], ["1974.70000000", "22.57370000"], ["1974.74000000", "7.41070000"], ["1974.78000000", "16.23570000"], ["1974.94000000", "3.67070000"], ["1975.00000000", "16.30600000"], ["1975.01000000", "7.19010000"], ["1975.23000000", "0.00260000"], ["1975.25000000", "0.03300000"], ["1975.35000000", "14.26120000"], ["1975.48000000", "10.61790000"], ["1975.97000000", "0.00000000"], ["1976.22000000", "0.94500000"], ["1976.80000000", "0.00570000"], ["1978.25000000", "0.06840000"], ["1983.60000000", "0.00000000"]], "_local_ts_utc": "2026-06-01T07:49:01.912766+00:00"}
{"e": "depthUpdate", "E": 1780300143115, "s": "ETHUSDT", "U": 76583092306, "u": 76583092371, "b": [["1972.89000000", "4.65930000"], ["1972.84000000", "0.01140000"], ["1972.82000000", "6.46760000"], ["1972.78000000", "7.96080000"], ["1972.76000000", "7.60930000"], ["1972.66000000", "13.52300000"], ["1972.58000000", "20.69090000"], ["1972.50000000", "0.37320000"], ["1972.45000000", "0.02720000"], ["1972.24000000", "0.27000000"], ["1972.22000000", "36.54300000"], ["1972.11000000", "0.10400000"], ["1971.94000000", "0.01380000"], ["1971.87000000", "7.10920000"], ["1971.79000000", "0.08330000"], ["1971.78000000", "3.61380000"], ["1971.26000000", "3.51930000"], ["1971.22000000", "0.08490000"], ["1970.97000000", "10.58850000"], ["1970.90000000", "31.75110000"], ["1970.76000000", "0.02160000"], ["1970.73000000", "0.10820000"], ["1969.15000000", "0.92830000"], ["1964.75000000", "0.02930000"], ["1775.68000000", "0.02480000"]], "a": [["1972.98000000", "0.46380000"], ["1973.04000000", "0.00260000"], ["1973.19000000", "0.00540000"], ["1973.20000000", "1.94090000"], ["1973.21000000", "0.00540000"], ["1973.23000000", "0.64960000"], ["1973.25000000", "0.00260000"], ["1973.40000000", "16.42140000"], ["1973.44000000", "11.39780000"], ["1973.56000000", "0.78300000"], ["1973.58000000", "8.60640000"], ["1974.04000000", "2.85680000"], ["1974.05000000", "0.83110000"], ["1974.07000000", "0.81260000"], ["1975.00000000", "14.20960000"], ["1975.35000000", "6.03920000"], ["1975.37000000", "0.00000000"], ["1975.72000000", "0.00000000"], ["1976.22000000", "0.00000000"], ["1976.32000000", "0.81000000"], ["1980.25000000", "0.00000000"], ["1981.11000000", "126.55820000"], ["1982.00000000", "0.01310000"], ["1983.00000000", "0.01340000"], ["1984.19000000", "0.00860000"], ["1984.78000000", "0.09260000"], ["1985.36000000", "0.01890000"], ["1985.95000000", "0.00000000"], ["1986.54000000", "0.00000000"], ["1987.13000000", "0.00000000"], ["1987.71000000", "0.00000000"], ["1988.30000000", "0.00000000"], ["1988.89000000", "0.00000000"], ["1989.48000000", "0.00380000"], ["2017.96000000", "0.16350000"], ["2046.13000000", "0.01060000"], ["2175.40000000", "0.00380000"]], "_local_ts_utc": "2026-06-01T07:49:02.011689+00:00"}
{"e": "depthUpdate", "E": 1780300143215, "s": "ETHUSDT", "U": 76583092372, "u": 76583092491, "b": [["1972.97000000", "79.76530000"], ["1972.96000000", "10.76290000"], ["1972.95000000", "0.00260000"], ["1972.90000000", "15.84070000"], ["1972.88000000", "0.00270000"], ["1972.87000000", "0.00000000"], ["1972.83000000", "0.00000000"], ["1972.82000000", "0.00000000"], ["1972.81000000", "0.62310000"], ["1972.78000000", "0.61070000"], ["1972.76000000", "0.00550000"], ["1972.75000000", "0.26370000"], ["1972.74000000", "0.00300000"], ["1972.73000000", "0.50960000"], ["1972.67000000", "22.64770000"], ["1972.66000000", "0.00930000"], ["1972.62000000", "8.53210000"], ["1972.58000000", "20.69090000"], ["1972.50000000", "0.37840000"], ["1972.37000000", "7.15150000"], ["1972.20000000", "15.89460000"], ["1971.81000000", "7.14550000"], ["1971.78000000", "2.85100000"], ["1971.31000000", "0.01830000"], ["1971.15000000", "4.73500000"], ["1971.11000000", "7.51210000"], ["1971.10000000", "7.09580000"], ["1971.09000000", "1.05330000"], ["1970.95000000", "0.00000000"], ["1970.94000000", "7.09860000"], ["1970.91000000", "7.31130000"], ["1970.02000000", "0.13180000"], ["1969.75000000", "0.13230000"], ["1967.68000000", "0.03570000"], ["1966.70000000", "0.60620000"], ["1775.68000000", "0.03720000"]], "a": [["1972.98000000", "15.00390000"], ["1973.03000000", "0.00260000"], ["1973.04000000", "0.00520000"], ["1973.09000000", "0.03300000"], ["1973.17000000", "0.00000000"], ["1973.18000000", "1.89010000"], ["1973.19000000", "0.00000000"], ["1973.21000000", "0.00000000"], ["1973.22000000", "6.47020000"], ["1973.25000000", "0.01420000"], ["1973.28000000", "0.05000000"], ["1973.35000000", "14.19160000"], ["1973.36000000", "0.50940000"], ["1973.39000000", "7.09860000"], ["1973.43000000", "8.51500000"], ["1973.44000000", "4.30200000"], ["1973.45000000", "0.64640000"], ["1973.48000000", "8.04080000"], ["1973.57000000", "13.51590000"], ["1973.91000000", "3.60000000"], ["1973.92000000", "0.03000000"], ["1974.31000000", "0.08670000"], ["1974.35000000", "1.25900000"], ["1974.42000000", "15.59040000"], ["1974.78000000", "7.72000000"], ["1974.99000000", "0.45900000"], ["1975.01000000", "0.09370000"], ["1975.03000000", "0.97800000"], ["1975.24000000", "1.22600000"], ["1975.25000000", "0.03300000"], ["1975.69000000", "0.00260000"], ["1991.73000000", "0.00000000"]], "_local_ts_utc": "2026-06-01T07:49:02.111023+00:00"}
{"e": "depthUpdate", "E": 1780300143315, "s": "ETHUSDT", "U": 76583092492, "u": 76583092806, "b": [["1972.97000000", "2.98060000"], ["1972.96000000", "0.01040000"], ["1972.91000000", "0.00800000"], ["1972.90000000", "1.01060000"], ["1972.89000000", "4.65930000"], ["1972.88000000", "0.00260000"], ["1972.84000000", "0.00000000"], ["1972.82000000", "0.00000000"], ["1972.81000000", "0.00540000"], ["1972.79000000", "0.01560000"], ["1972.78000000", "1.93560000"], ["1972.77000000", "0.62360000"], ["1972.75000000", "4.09210000"], ["1972.74000000", "2.53860000"], ["1972.70000000", "9.76820000"], ["1972.69000000", "32.78460000"], ["1972.68000000", "0.01590000"], ["1972.67000000", "0.07400000"], ["1972.65000000", "0.19850000"], ["1972.64000000", "0.04520000"], ["1972.62000000", "0.01640000"], ["1972.60000000", "0.02570000"], ["1972.59000000", "0.13420000"], ["1972.58000000", "8.80980000"], ["1972.54000000", "6.47170000"], ["1972.53000000", "14.19160000"], ["1972.52000000", "8.52070000"], ["1972.51000000", "0.25370000"], ["1972.49000000", "7.09580000"], ["1972.48000000", "22.40020000"], ["1972.47000000", "22.58390000"], ["1972.43000000", "14.23570000"], ["1972.42000000", "11.06720000"], ["1972.41000000", "14.00520000"], ["1972.39000000", "7.09580000"], ["1972.38000000", "7.06320000"], ["1972.37000000", "0.86510000"], ["1972.36000000", "0.11530000"], ["1972.32000000", "14.49670000"], ["1972.31000000", "8.57090000"], ["1972.30000000", "18.33020000"], ["1972.29000000", "10.70120000"], ["1972.27000000", "13.52230000"], ["1972.22000000", "0.32080000"], ["1972.14000000", "0.00260000"], ["1972.12000000", "15.61150000"], ["1972.02000000", "17.91090000"], ["1971.82000000", "1.06660000"], ["1971.63000000", "7.10890000"], ["1971.55000000", "10.29810000"], ["1971.54000000", "7.32220000"], ["1971.38000000", "0.57430000"], ["1971.31000000", "0.28830000"], ["1971.30000000", "16.37600000"], ["1971.26000000", "0.71060000"], ["1971.15000000", "8.78980000"], ["1971.10000000", "15.61080000"], ["1970.92000000", "7.16150000"], ["1970.91000000", "15.82630000"], ["1970.90000000", "0.00000000"], ["1970.78000000", "12.76110000"], ["1970.74000000", "7.09580000"], ["1970.73000000", "0.02000000"], ["1970.72000000", "7.78860000"], ["1970.71000000", "15.64900000"], ["1970.54000000", "7.36580000"], ["1970.52000000", "14.19450000"], ["1970.50000000", "16.21370000"], ["1970.35000000", "4.69740000"], ["1970.34000000", "0.00000000"], ["1970.33000000", "0.03460000"], ["1970.14000000", "0.00640000"], ["1970.02000000", "13.64770000"], ["1969.75000000", "4.49960000"], ["1969.74000000", "14.04300000"], ["1969.47000000", "5.28430000"], ["1969.46000000", "13.52760000"], ["1965.23000000", "127.37800000"], ["1963.44000000", "0.08430000"], ["1950.08000000", "1.53510000"], ["1946.13000000", "1.40270000"], ["1934.19000000", "1.15110000"], ["1775.68000000", "0.04960000"], ["1579.13000000", "0.01010000"], ["1579.00000000", "1.53550000"], ["1578.38000000", "0.04200000"]], "a": [["1972.98000000", "73.69390000"], ["1973.00000000", "0.01090000"], ["1973.03000000", "0.01420000"], ["1973.06000000", "0.01420000"], ["1973.09000000", "0.03300000"], ["1973.10000000", "0.00570000"], ["1973.17000000", "1.18920000"], ["1973.20000000", "0.00570000"], ["1973.22000000", "0.00260000"], ["1973.26000000", "22.57370000"], ["1973.29000000", "0.01320000"], ["1973.30000000", "0.00830000"], ["1973.33000000", "0.00000000"], ["1973.34000000", "6.41910000"], ["1973.36000000", "0.70940000"], ["1973.48000000", "9.24630000"], ["1973.51000000", "8.02890000"], ["1973.55000000", "1.67400000"], ["1973.58000000", "8.40640000"], ["1973.62000000", "22.59010000"], ["1974.05000000", "2.50510000"], ["1974.12000000", "0.51300000"], ["1974.82000000", "1.03110000"], ["1974.94000000", "1.40940000"], ["1975.00000000", "9.97310000"], ["1975.24000000", "0.00000000"], ["1975.37000000", "31.67950000"], ["1975.82000000", "0.00300000"], ["1976.32000000", "0.00000000"], ["1977.03000000", "0.00260000"], ["1977.89000000", "0.00000000"], ["1980.55000000", "0.00000000"], ["1981.59000000", "0.48430000"], ["1988.23000000", "3.06530000"], ["1990.80000000", "0.01660000"], ["1991.27000000", "0.00000000"], ["2186.37000000", "0.01620000"]], "_local_ts_utc": "2026-06-01T07:49:02.211275+00:00"}
{"e": "depthUpdate", "E": 1780300143415, "s": "ETHUSDT", "U": 76583092807, "u": 76583092906, "b": [["1972.97000000", "13.49500000"], ["1972.96000000", "0.00780000"], ["1972.89000000", "1.80210000"], ["1972.88000000", "0.00260000"], ["1972.79000000", "3.38980000"], ["1972.78000000", "1.93560000"], ["1972.76000000", "0.00550000"], ["1972.75000000", "0.01000000"], ["1972.74000000", "0.00300000"], ["1972.71000000", "0.00530000"], ["1972.70000000", "5.03530000"], ["1972.69000000", "22.57370000"], ["1972.59000000", "10.34570000"], ["1972.55000000", "14.46410000"], ["1972.54000000", "14.19570000"], ["1972.53000000", "0.00000000"], ["1972.52000000", "8.52070000"], ["1972.51000000", "0.00000000"], ["1972.50000000", "2.91400000"], ["1972.49000000", "7.09580000"], ["1972.43000000", "14.84640000"], ["1972.41000000", "20.72650000"], ["1972.37000000", "1.13510000"], ["1972.33000000", "0.10550000"], ["1972.16000000", "14.62800000"], ["1971.95000000", "0.21810000"], ["1971.78000000", "4.22420000"], ["1971.73000000", "2.85570000"], ["1971.59000000", "1.34750000"], ["1971.38000000", "0.84430000"], ["1970.52000000", "7.09870000"], ["1970.44000000", "0.25340000"], ["1969.47000000", "1.24980000"], ["1969.46000000", "0.01170000"], ["1963.64000000", "0.32530000"], ["1950.08000000", "1.40820000"], ["1934.19000000", "1.02320000"], ["1924.32000000", "0.64570000"], ["1775.68000000", "0.06200000"]], "a": [["1972.98000000", "81.54540000"], ["1973.24000000", "8.96390000"], ["1973.25000000", "7.09840000"], ["1973.39000000", "7.09580000"], ["1973.55000000", "2.13300000"], ["1974.41000000", "16.81380000"], ["1974.59000000", "0.00000000"], ["1974.79000000", "7.09640000"], ["1975.74000000", "0.60040000"], ["1975.87000000", "0.02000000"], ["1976.24000000", "0.00260000"]], "_local_ts_utc": "2026-06-01T07:49:02.311330+00:00"}
{"e": "depthUpdate", "E": 1780300143515, "s": "ETHUSDT", "U": 76583092907, "u": 76583092953, "b": [["1972.97000000", "9.38180000"], ["1972.80000000", "16.48920000"], ["1972.79000000", "0.01020000"], ["1972.78000000", "0.00000000"], ["1972.71000000", "1.51100000"], ["1972.70000000", "5.03800000"], ["1972.60000000", "15.08210000"], ["1972.58000000", "0.00260000"], ["1972.50000000", "0.37840000"], ["1972.16000000", "14.22800000"], ["1972.09000000", "31.44000000"], ["1972.02000000", "17.91090000"], ["1971.65000000", "4.93800000"], ["1970.98000000", "0.00560000"], ["1970.24000000", "23.55480000"], ["1775.68000000", "0.07440000"]], "a": [["1972.98000000", "81.47880000"], ["1973.22000000", "1.20810000"], ["1973.23000000", "7.74540000"], ["1973.67000000", "3.22990000"], ["1973.83000000", "0.71640000"], ["1973.84000000", "1.17750000"], ["1974.81000000", "1.20550000"], ["1975.75000000", "0.43200000"], ["1975.80000000", "0.00310000"], ["1976.86000000", "31.65820000"]], "_local_ts_utc": "2026-06-01T07:49:02.411363+00:00"}
{"e": "depthUpdate", "E": 1780300143615, "s": "ETHUSDT", "U": 76583092954, "u": 76583093623, "b": [["1972.97000000", "0.00000000"], ["1972.96000000", "0.00000000"], ["1972.95000000", "0.00000000"], ["1972.94000000", "0.00000000"], ["1972.93000000", "0.00000000"], ["1972.92000000", "0.00000000"], ["1972.91000000", "0.00000000"], ["1972.90000000", "0.00000000"], ["1972.89000000", "0.00000000"], ["1972.88000000", "0.00000000"], ["1972.87000000", "0.00000000"], ["1972.81000000", "0.00000000"], ["1972.80000000", "19.39230000"], ["1972.79000000", "0.02060000"], ["1972.78000000", "0.00540000"], ["1972.77000000", "0.62620000"], ["1972.76000000", "0.00810000"], ["1972.75000000", "0.01260000"], ["1972.74000000", "0.01100000"], ["1972.73000000", "0.00260000"], ["1972.72000000", "0.08720000"], ["1972.71000000", "0.00520000"], ["1972.70000000", "0.05520000"], ["1972.69000000", "0.00000000"], ["1972.67000000", "0.00560000"], ["1972.66000000", "0.01470000"], ["1972.61000000", "0.00540000"], ["1972.60000000", "0.02800000"], ["1972.58000000", "0.00260000"], ["1972.57000000", "0.00000000"], ["1972.56000000", "0.00270000"], ["1972.55000000", "0.94820000"], ["1972.54000000", "0.00410000"], ["1972.52000000", "0.00570000"], ["1972.50000000", "0.37530000"], ["1972.49000000", "0.00270000"], ["1972.48000000", "4.03670000"], ["1972.47000000", "0.01020000"], ["1972.44000000", "0.11860000"], ["1972.43000000", "0.65480000"], ["1972.42000000", "0.01520000"], ["1972.41000000", "0.48930000"], ["1972.39000000", "0.00000000"], ["1972.38000000", "7.13160000"], ["1972.37000000", "0.32510000"], ["1972.31000000", "11.10650000"], ["1972.29000000", "13.82250000"], ["1972.25000000", "0.48110000"], ["1972.23000000", "4.64470000"], ["1972.16000000", "16.76540000"], ["1972.09000000", "31.04000000"], ["1972.04000000", "1.63810000"], ["1972.02000000", "15.61090000"], ["1971.94000000", "0.61380000"], ["1971.90000000", "20.65600000"], ["1971.87000000", "7.10920000"], ["1971.83000000", "0.01020000"], ["1971.81000000", "7.44550000"], ["1971.75000000", "1.20300000"], ["1971.72000000", "0.27260000"], ["1971.65000000", "4.93800000"], ["1971.58000000", "0.50260000"], ["1971.56000000", "1.07410000"], ["1971.54000000", "7.22220000"], ["1971.46000000", "0.00390000"], ["1971.42000000", "1.17190000"], ["1971.26000000", "0.98060000"], ["1971.25000000", "3.71140000"], ["1971.24000000", "1.28340000"], ["1970.53000000", "7.09840000"], ["1970.35000000", "8.36360000"], ["1970.34000000", "7.09580000"], ["1970.33000000", "7.13040000"], ["1965.48000000", "5.00880000"], ["1963.72000000", "0.48390000"], ["1962.15000000", "1.20550000"], ["1775.68000000", "0.00000000"], ["1775.61000000", "0.00000000"], ["1472.93000000", "0.00600000"]], "a": [["1972.81000000", "100.90330000"], ["1972.82000000", "52.09460000"], ["1972.83000000", "0.00510000"], ["1972.87000000", "0.00000000"], ["1972.88000000", "24.65600000"], ["1972.89000000", "0.00260000"], ["1972.90000000", "14.93060000"], ["1972.91000000", "0.41250000"], ["1972.92000000", "0.00000000"], ["1972.93000000", "18.52120000"], ["1972.94000000", "4.97970000"], ["1972.95000000", "0.00000000"], ["1972.96000000", "0.00000000"], ["1972.97000000", "0.01020000"], ["1972.98000000", "4.79560000"], ["1973.02000000", "0.00000000"], ["1973.03000000", "0.00000000"], ["1973.04000000", "0.00260000"], ["1973.06000000", "0.00000000"], ["1973.07000000", "0.00300000"], ["1973.08000000", "0.00000000"], ["1973.13000000", "0.00260000"], ["1973.14000000", "0.20390000"], ["1973.17000000", "0.00000000"], ["1973.18000000", "0.50300000"], ["1973.22000000", "21.84110000"], ["1973.23000000", "7.09840000"], ["1973.24000000", "0.00000000"], ["1973.25000000", "15.61340000"], ["1973.28000000", "0.05260000"], ["1973.34000000", "9.88640000"], ["1973.36000000", "0.13470000"], ["1973.38000000", "13.51590000"], ["1973.50000000", "10.46240000"], ["1973.51000000", "8.03190000"], ["1973.52000000", "0.49200000"], ["1973.58000000", "7.90640000"], ["1973.59000000", "1.04470000"], ["1973.67000000", "3.38100000"], ["1973.70000000", "4.38370000"], ["1973.80000000", "7.09770000"], ["1973.86000000", "0.17050000"], ["1973.90000000", "1.20860000"], ["1974.06000000", "0.20300000"], ["1974.20000000", "16.33070000"], ["1974.28000000", "1.20260000"], ["1974.30000000", "0.00310000"], ["1974.42000000", "14.19040000"], ["1974.44000000", "1.79300000"], ["1974.60000000", "0.03610000"], ["1974.63000000", "0.00000000"], ["1974.74000000", "2.31390000"], ["1974.79000000", "0.00000000"], ["1974.80000000", "5.79540000"], ["1974.94000000", "3.04500000"], ["1975.10000000", "0.00000000"], ["1975.35000000", "0.00520000"], ["1975.36000000", "0.00000000"], ["1975.48000000", "1.20550000"], ["1975.74000000", "0.00640000"], ["1975.75000000", "0.00000000"], ["1975.81000000", "0.00000000"], ["1975.87000000", "9.39810000"], ["1976.18000000", "1.20810000"], ["1976.49000000", "0.00000000"], ["1976.61000000", "0.00000000"], ["1976.62000000", "0.00000000"], ["1976.68000000", "0.37760000"], ["1976.80000000", "0.00310000"], ["1976.92000000", "0.00520000"], ["1977.90000000", "0.00000000"], ["1977.91000000", "0.00000000"], ["1977.96000000", "0.06840000"], ["1977.97000000", "1.45000000"], ["1977.98000000", "0.00000000"], ["1978.18000000", "0.00000000"], ["1978.25000000", "0.00000000"], ["1979.72000000", "0.00000000"], ["2197.66000000", "0.36550000"], ["2472.94000000", "0.00900000"]], "_local_ts_utc": "2026-06-01T07:49:02.511305+00:00"}
{"e": "depthUpdate", "E": 1780300143715, "s": "ETHUSDT", "U": 76583093624, "u": 76583093814, "b": [["1972.80000000", "12.43010000"], ["1972.79000000", "0.01040000"], ["1972.78000000", "0.00800000"], ["1972.74000000", "0.00560000"], ["1972.70000000", "0.05260000"], ["1972.64000000", "0.01520000"], ["1972.60000000", "0.02260000"], ["1972.59000000", "0.13420000"], ["1972.58000000", "0.00000000"], ["1972.56000000", "0.00540000"], ["1972.51000000", "0.00540000"], ["1972.50000000", "0.37530000"], ["1972.48000000", "0.63890000"], ["1972.44000000", "0.11860000"], ["1972.43000000", "0.04410000"], ["1972.42000000", "1.09600000"], ["1972.40000000", "7.18350000"], ["1972.39000000", "10.21290000"], ["1972.38000000", "0.07650000"], ["1972.37000000", "0.05510000"], ["1972.32000000", "0.03510000"], ["1972.31000000", "2.59150000"], ["1972.30000000", "18.06020000"], ["1972.29000000", "0.25910000"], ["1972.28000000", "0.10140000"], ["1972.27000000", "0.00640000"], ["1972.25000000", "0.21110000"], ["1972.24000000", "0.00000000"], ["1972.23000000", "4.37470000"], ["1972.22000000", "15.66160000"], ["1972.21000000", "13.60830000"], ["1972.18000000", "0.20250000"], ["1972.12000000", "22.19440000"], ["1972.09000000", "31.65070000"], ["1972.07000000", "13.51590000"], ["1972.06000000", "22.59490000"], ["1971.94000000", "0.21380000"], ["1971.81000000", "7.14550000"], ["1971.79000000", "0.03300000"], ["1971.75000000", "0.00300000"], ["1971.73000000", "0.01170000"], ["1971.72000000", "0.67260000"], ["1971.70000000", "21.11830000"], ["1971.65000000", "3.61520000"], ["1971.22000000", "0.00000000"], ["1971.18000000", "2.77390000"], ["1970.79000000", "0.09510000"], ["1970.60000000", "18.50650000"], ["1970.58000000", "8.65220000"], ["1970.50000000", "16.12550000"], ["1970.41000000", "7.14370000"], ["1970.15000000", "4.32050000"], ["1970.14000000", "7.10220000"], ["1970.13000000", "7.20340000"], ["1970.08000000", "0.08690000"], ["1969.92000000", "9.68530000"], ["1969.47000000", "5.13700000"], ["1969.46000000", "13.52760000"], ["1969.31000000", "14.53800000"], ["1967.18000000", "4.19140000"], ["1967.09000000", "0.00000000"], ["1965.21000000", "0.12070000"], ["1946.13000000", "1.27560000"], ["1775.52000000", "0.41240000"]], "a": [["1972.81000000", "135.47210000"], ["1972.82000000", "14.70350000"], ["1972.86000000", "0.55160000"], ["1972.87000000", "0.00000000"], ["1972.88000000", "2.54130000"], ["1972.89000000", "7.19840000"], ["1972.90000000", "7.94340000"], ["1972.92000000", "8.26820000"], ["1972.93000000", "0.00000000"], ["1972.94000000", "4.97710000"], ["1972.97000000", "14.20180000"], ["1972.98000000", "4.79300000"], ["1972.99000000", "0.00000000"], ["1973.00000000", "4.31830000"], ["1973.01000000", "0.00000000"], ["1973.02000000", "8.86960000"], ["1973.03000000", "22.57630000"], ["1973.04000000", "0.00000000"], ["1973.09000000", "15.64380000"], ["1973.10000000", "4.32560000"], ["1973.11000000", "14.19160000"], ["1973.14000000", "0.85030000"], ["1973.15000000", "26.76000000"], ["1973.44000000", "0.00000000"], ["1973.45000000", "0.00000000"], ["1973.61000000", "1.56000000"], ["1973.74000000", "0.03690000"], ["1973.75000000", "14.19180000"], ["1973.84000000", "1.26450000"], ["1973.93000000", "0.21660000"], ["1973.94000000", "20.02100000"], ["1973.96000000", "14.35950000"], ["1974.04000000", "0.00000000"], ["1974.06000000", "0.60300000"], ["1974.09000000", "7.09520000"], ["1974.28000000", "0.80260000"], ["1974.31000000", "0.00000000"], ["1974.36000000", "0.00000000"], ["1974.38000000", "4.50560000"], ["1974.39000000", "1.21830000"], ["1974.41000000", "8.62210000"], ["1974.42000000", "0.00000000"], ["1974.48000000", "0.03000000"], ["1974.60000000", "18.78910000"], ["1974.61000000", "15.14680000"], ["1974.64000000", "0.03000000"], ["1974.65000000", "0.00000000"], ["1976.29000000", "0.00000000"], ["1978.11000000", "0.00260000"], ["1981.97000000", "0.19990000"]], "_local_ts_utc": "2026-06-01T07:49:02.611626+00:00"}
{"e": "depthUpdate", "E": 1780300143815, "s": "ETHUSDT", "U": 76583093815, "u": 76583093866, "b": [["1972.80000000", "13.43010000"], ["1972.66000000", "0.01080000"], ["1972.57000000", "0.00540000"], ["1972.56000000", "0.55630000"], ["1972.53000000", "0.00540000"], ["1972.52000000", "0.51270000"], ["1972.51000000", "0.00000000"], ["1972.49000000", "0.00000000"], ["1972.42000000", "0.01520000"], ["1972.31000000", "0.05590000"], ["1972.27000000", "14.19800000"], ["1972.26000000", "25.11930000"], ["1972.20000000", "23.41350000"], ["1972.19000000", "0.00300000"], ["1970.40000000", "32.89480000"], ["1969.92000000", "9.65530000"], ["1969.32000000", "3.25840000"], ["1953.66000000", "0.12770000"], ["1950.08000000", "1.28130000"], ["1934.19000000", "0.89530000"], ["1924.32000000", "0.51710000"], ["1775.52000000", "0.42480000"]], "a": [["1972.81000000", "122.72060000"], ["1972.90000000", "6.54190000"], ["1973.02000000", "12.59320000"], ["1973.10000000", "12.08390000"], ["1973.15000000", "27.26690000"], ["1973.67000000", "2.59770000"], ["1973.73000000", "9.67910000"], ["1974.06000000", "0.20300000"], ["1974.13000000", "0.40260000"], ["1974.57000000", "9.99800000"], ["1975.49000000", "115.85850000"], ["1975.94000000", "0.00640000"], ["1976.50000000", "0.00260000"], ["2170.09000000", "0.71170000"], ["2209.29000000", "0.01020000"]], "_local_ts_utc": "2026-06-01T07:49:02.711602+00:00"}
{"e": "depthUpdate", "E": 1780300143915, "s": "ETHUSDT", "U": 76583093867, "u": 76583093921, "b": [["1972.80000000", "25.04300000"], ["1972.41000000", "0.49190000"], ["1972.32000000", "8.55010000"], ["1972.28000000", "6.56900000"], ["1972.26000000", "22.58370000"], ["1972.16000000", "14.22800000"], ["1971.62000000", "1.33360000"], ["1970.87000000", "23.96170000"], ["1970.00000000", "409.36310000"], ["1965.00000000", "94.36980000"], ["1960.00000000", "403.19970000"], ["1950.08000000", "1.15440000"], ["1775.52000000", "0.43720000"]], "a": [["1972.81000000", "132.65230000"], ["1972.86000000", "0.55420000"], ["1973.00000000", "4.31570000"], ["1973.48000000", "9.25640000"], ["1973.54000000", "0.09510000"], ["1973.57000000", "13.51850000"], ["1973.66000000", "0.00260000"], ["1973.73000000", "9.68210000"], ["1973.83000000", "0.00260000"], ["1973.84000000", "0.08960000"], ["1974.06000000", "0.00300000"], ["1974.13000000", "0.60260000"], ["1974.96000000", "0.62400000"], ["1975.01000000", "0.00260000"], ["1975.17000000", "2.15000000"], ["1976.81000000", "0.00000000"], ["2170.09000000", "0.70910000"]], "_local_ts_utc": "2026-06-01T07:49:02.810767+00:00"}
{"e": "depthUpdate", "E": 1780300144015, "s": "ETHUSDT", "U": 76583093922, "u": 76583094073, "b": [["1972.80000000", "33.69980000"], ["1972.69000000", "0.00540000"], ["1972.68000000", "0.47710000"], ["1972.57000000", "0.00540000"], ["1972.56000000", "5.52480000"], ["1972.53000000", "9.79930000"], ["1972.52000000", "7.62440000"], ["1972.51000000", "0.69180000"], ["1972.48000000", "0.01480000"], ["1972.47000000", "0.63950000"], ["1972.43000000", "7.13990000"], ["1972.42000000", "18.23990000"], ["1972.41000000", "28.45310000"], ["1972.40000000", "17.03600000"], ["1972.33000000", "7.20130000"], ["1972.29000000", "0.00540000"], ["1972.28000000", "0.10140000"], ["1972.21000000", "16.14560000"], ["1972.16000000", "14.42800000"], ["1972.09000000", "32.05070000"], ["1972.01000000", "0.27760000"], ["1971.94000000", "0.01380000"], ["1971.87000000", "7.90920000"], ["1971.72000000", "0.00260000"], ["1971.56000000", "0.27410000"], ["1971.01000000", "0.58300000"], ["1970.71000000", "7.13400000"], ["1970.58000000", "0.13720000"], ["1970.53000000", "0.00260000"], ["1970.41000000", "0.04790000"], ["1970.34000000", "0.00000000"], ["1970.16000000", "0.00270000"], ["1970.15000000", "0.00760000"], ["1970.14000000", "0.00640000"], ["1970.13000000", "0.10760000"], ["1969.32000000", "0.00280000"], ["1969.31000000", "1.02210000"], ["1950.08000000", "0.90060000"], ["1946.13000000", "1.14850000"], ["1775.52000000", "0.45300000"], ["1472.93000000", "0.00000000"]], "a": [["1972.81000000", "73.92030000"], ["1972.82000000", "9.47270000"], ["1972.85000000", "0.58120000"], ["1972.87000000", "0.00540000"], ["1972.88000000", "0.15600000"], ["1972.89000000", "0.10800000"], ["1972.90000000", "1.10550000"], ["1972.91000000", "0.00270000"], ["1972.92000000", "3.81700000"], ["1972.94000000", "0.00000000"], ["1972.97000000", "0.01020000"], ["1972.98000000", "3.48430000"], ["1973.06000000", "0.43000000"], ["1973.08000000", "0.10140000"], ["1973.09000000", "7.12880000"], ["1973.18000000", "1.01600000"], ["1973.30000000", "0.01110000"], ["1973.38000000", "16.05320000"], ["1973.70000000", "7.28310000"], ["1973.77000000", "13.51630000"], ["1974.41000000", "15.94980000"], ["1974.44000000", "0.22650000"], ["1974.45000000", "14.19160000"], ["1974.47000000", "7.09580000"], ["1974.48000000", "8.54500000"], ["1975.77000000", "0.13190000"], ["1975.87000000", "0.02000000"], ["1976.36000000", "9.38070000"], ["1977.40000000", "0.22100000"], ["2472.94000000", "0.00300000"]], "_local_ts_utc": "2026-06-01T07:49:02.911461+00:00"}
{"e": "depthUpdate", "E": 1780300144115, "s": "ETHUSDT", "U": 76583094074, "u": 76583094281, "b": [["1972.80000000", "51.86490000"], ["1972.79000000", "0.00260000"], ["1972.76000000", "0.51560000"], ["1972.66000000", "0.01080000"], ["1972.57000000", "10.21130000"], ["1972.56000000", "9.14270000"], ["1972.54000000", "14.19690000"], ["1972.52000000", "6.99620000"], ["1972.51000000", "8.04190000"], ["1972.50000000", "0.37840000"], ["1972.48000000", "0.04480000"], ["1972.47000000", "23.21320000"], ["1972.44000000", "17.64960000"], ["1972.43000000", "7.13990000"], ["1972.42000000", "8.53020000"], ["1972.41000000", "28.19940000"], ["1972.40000000", "11.18220000"], ["1972.39000000", "0.00000000"], ["1972.09000000", "31.44000000"], ["1972.01000000", "0.74760000"], ["1971.91000000", "8.01690000"], ["1971.83000000", "1.21570000"], ["1971.70000000", "20.91830000"], ["1971.48000000", "0.12070000"], ["1971.25000000", "3.61140000"], ["1971.02000000", "0.27000000"], ["1970.60000000", "13.10010000"], ["1970.54000000", "0.27000000"], ["1970.35000000", "4.69740000"], ["1970.33000000", "0.03460000"], ["1970.08000000", "0.05690000"], ["1969.61000000", "0.00000000"], ["1969.58000000", "0.88040000"], ["1969.55000000", "0.00000000"], ["1969.50000000", "0.75640000"], ["1965.92000000", "0.13380000"], ["1965.21000000", "0.11240000"], ["1962.15000000", "0.00000000"], ["1962.07000000", "0.00850000"], ["1775.52000000", "0.46820000"]], "a": [["1972.81000000", "18.05650000"], ["1972.82000000", "3.00510000"], ["1972.84000000", "0.00000000"], ["1972.85000000", "0.00000000"], ["1972.86000000", "0.00260000"], ["1972.87000000", "0.00000000"], ["1972.88000000", "0.00260000"], ["1972.90000000", "0.46420000"], ["1972.91000000", "0.00540000"], ["1972.92000000", "5.17070000"], ["1972.93000000", "0.00540000"], ["1972.94000000", "6.46760000"], ["1972.95000000", "0.55160000"], ["1972.96000000", "0.01160000"], ["1972.97000000", "0.01290000"], ["1973.02000000", "0.00000000"], ["1973.03000000", "0.00260000"], ["1973.06000000", "0.00000000"], ["1973.09000000", "0.03300000"], ["1973.10000000", "8.49550000"], ["1973.11000000", "0.00000000"], ["1973.14000000", "0.65030000"], ["1973.17000000", "0.00000000"], ["1973.18000000", "0.51600000"], ["1973.22000000", "20.63560000"], ["1973.23000000", "7.66540000"], ["1973.24000000", "0.00000000"], ["1973.25000000", "15.61340000"], ["1973.28000000", "0.05260000"], ["1973.35000000", "14.89160000"], ["1973.38000000", "13.51590000"], ["1973.52000000", "2.09650000"], ["1973.60000000", "2.54290000"], ["1973.70000000", "4.38370000"], ["1974.13000000", "0.20260000"], ["1974.20000000", "16.73070000"], ["1974.67000000", "27.71010000"], ["1974.69000000", "7.09640000"], ["1974.74000000", "3.38510000"], ["1974.80000000", "15.25440000"], ["1975.52000000", "0.00000000"], ["1975.96000000", "0.00000000"], ["1976.37000000", "31.79840000"], ["1976.42000000", "0.00000000"], ["2221.28000000", "0.00950000"]], "_local_ts_utc": "2026-06-01T07:49:03.012280+00:00"}
{"e": "depthUpdate", "E": 1780300144215, "s": "ETHUSDT", "U": 76583094282, "u": 76583094343, "b": [["1972.80000000", "51.86490000"], ["1972.77000000", "0.62620000"], ["1972.76000000", "0.00810000"], ["1972.63000000", "2.56950000"], ["1972.60000000", "0.02800000"], ["1972.59000000", "23.62670000"], ["1972.58000000", "23.72840000"], ["1972.57000000", "0.00000000"], ["1972.56000000", "0.00000000"], ["1972.55000000", "1.59450000"], ["1972.48000000", "25.06580000"], ["1972.44000000", "0.11860000"], ["1972.40000000", "8.33050000"], ["1971.62000000", "1.06360000"], ["1970.65000000", "3.60570000"], ["1970.49000000", "16.25530000"], ["1969.47000000", "1.24980000"], ["1969.46000000", "0.01170000"], ["1966.45000000", "3.72170000"], ["1965.42000000", "0.00770000"], ["1950.31000000", "0.26790000"], ["1946.13000000", "1.02140000"], ["1775.52000000", "0.48060000"]], "a": [["1972.81000000", "21.82450000"], ["1972.90000000", "0.47580000"], ["1972.94000000", "6.47920000"], ["1972.96000000", "0.64610000"], ["1972.98000000", "3.47270000"], ["1973.41000000", "0.05000000"], ["1973.61000000", "1.51000000"], ["1974.74000000", "5.06150000"], ["1974.97000000", "0.51300000"], ["1975.10000000", "5.29670000"], ["1976.42000000", "0.59580000"], ["1976.55000000", "1.36700000"], ["1976.97000000", "0.13180000"]], "_local_ts_utc": "2026-06-01T07:49:03.111412+00:00"}
{"e": "depthUpdate", "E": 1780300144315, "s": "ETHUSDT", "U": 76583094344, "u": 76583094504, "b": [["1972.80000000", "22.20140000"], ["1972.79000000", "0.01040000"], ["1972.76000000", "0.00810000"], ["1972.66000000", "0.01080000"], ["1972.64000000", "0.01520000"], ["1972.63000000", "0.03390000"], ["1972.62000000", "0.01640000"], ["1972.61000000", "0.00540000"], ["1972.60000000", "0.02800000"], ["1972.59000000", "10.29120000"], ["1972.58000000", "10.21130000"], ["1972.56000000", "0.00000000"], ["1972.55000000", "0.94820000"], ["1972.54000000", "0.00410000"], ["1972.53000000", "0.00000000"], ["1972.52000000", "0.52860000"], ["1972.51000000", "0.69180000"], ["1972.50000000", "12.41500000"], ["1972.49000000", "22.57370000"], ["1972.48000000", "0.04480000"], ["1972.47000000", "0.63950000"], ["1972.41000000", "14.68350000"], ["1972.40000000", "18.64360000"], ["1972.39000000", "0.00000000"], ["1972.35000000", "13.51710000"], ["1972.33000000", "7.45500000"], ["1972.16000000", "14.22800000"], ["1972.09000000", "31.24000000"], ["1972.01000000", "0.54760000"], ["1971.88000000", "0.01130000"], ["1971.87000000", "7.50920000"], ["1971.82000000", "1.06660000"], ["1971.77000000", "0.44860000"], ["1971.58000000", "1.30260000"], ["1971.48000000", "0.02070000"], ["1971.44000000", "0.00000000"], ["1971.22000000", "0.10000000"], ["1971.18000000", "0.00000000"], ["1968.98000000", "70.41890000"], ["1967.94000000", "0.22000000"], ["1966.98000000", "0.12170000"], ["1963.99000000", "0.00000000"], ["1963.72000000", "0.00000000"], ["1953.67000000", "0.13100000"], ["1947.15000000", "0.12810000"], ["1775.52000000", "0.49300000"]], "a": [["1972.81000000", "55.30190000"], ["1972.85000000", "0.01160000"], ["1972.89000000", "0.63550000"], ["1972.90000000", "1.78510000"], ["1972.91000000", "0.00000000"], ["1972.92000000", "4.45690000"], ["1972.93000000", "0.00000000"], ["1972.94000000", "0.01160000"], ["1972.96000000", "0.63450000"], ["1972.97000000", "0.01020000"], ["1973.08000000", "6.46610000"], ["1973.09000000", "29.83790000"], ["1973.17000000", "1.20550000"], ["1973.84000000", "0.09260000"], ["1974.48000000", "0.03000000"], ["1974.67000000", "13.51730000"], ["1974.69000000", "0.00000000"], ["1977.57000000", "3.73440000"], ["1981.59000000", "0.00000000"], ["1985.44000000", "0.00380000"], ["1987.40000000", "0.44240000"], ["2233.62000000", "0.00660000"]], "_local_ts_utc": "2026-06-01T07:49:03.212305+00:00"}
{"e": "depthUpdate", "E": 1780300144415, "s": "ETHUSDT", "U": 76583094505, "u": 76583094621, "b": [["1972.80000000", "13.10330000"], ["1972.60000000", "0.02260000"], ["1972.59000000", "0.13420000"], ["1972.58000000", "0.00000000"], ["1972.56000000", "0.00540000"], ["1972.54000000", "0.00410000"], ["1972.53000000", "0.00270000"], ["1972.51000000", "0.69180000"], ["1972.50000000", "17.06980000"], ["1972.49000000", "0.00000000"], ["1972.43000000", "0.04410000"], ["1972.42000000", "0.01520000"], ["1972.41000000", "0.49190000"], ["1972.40000000", "12.42700000"], ["1972.38000000", "7.17290000"], ["1972.37000000", "7.15150000"], ["1972.35000000", "0.00000000"], ["1972.33000000", "0.10550000"], ["1972.32000000", "15.64650000"], ["1972.29000000", "6.47300000"], ["1972.24000000", "0.25370000"], ["1972.21000000", "13.60830000"], ["1972.08000000", "0.27760000"], ["1972.05000000", "6.15690000"], ["1971.80000000", "0.00310000"], ["1971.77000000", "0.24860000"], ["1971.76000000", "0.21280000"], ["1970.73000000", "8.53570000"], ["1970.54000000", "7.36640000"], ["1970.53000000", "7.09900000"], ["1970.35000000", "8.36390000"], ["1970.34000000", "0.00000000"], ["1970.33000000", "7.13100000"], ["1967.64000000", "0.05340000"], ["1967.50000000", "10.12370000"], ["1967.28000000", "0.50000000"], ["1966.66000000", "26.83600000"], ["1957.18000000", "0.10210000"], ["1947.15000000", "0.25620000"], ["1941.40000000", "0.12480000"], ["1925.61000000", "0.11350000"], ["1909.83000000", "0.11090000"], ["1894.05000000", "0.10550000"], ["1878.26000000", "0.10640000"], ["1862.48000000", "0.10730000"], ["1846.69000000", "0.36220000"], ["1830.91000000", "0.14360000"], ["1815.13000000", "0.11010000"], ["1799.34000000", "0.11110000"], ["1783.56000000", "0.12390000"], ["1775.52000000", "0.50540000"], ["1767.78000000", "0.11930000"], ["1751.99000000", "0.11410000"], ["1736.21000000", "0.11510000"], ["1720.42000000", "0.11620000"], ["1704.64000000", "0.13430000"], ["1688.86000000", "0.32330000"], ["1673.07000000", "0.11950000"], ["1657.29000000", "0.13620000"], ["1641.51000000", "0.12180000"], ["1625.72000000", "0.12300000"], ["1609.94000000", "0.12420000"], ["1594.15000000", "0.12540000"], ["1578.37000000", "0.12670000"]], "a": [["1972.81000000", "55.35850000"], ["1972.97000000", "14.20300000"], ["1973.02000000", "22.57370000"], ["1973.08000000", "6.36470000"], ["1973.14000000", "14.36740000"], ["1973.35000000", "14.69160000"], ["1973.37000000", "0.84930000"], ["1974.02000000", "0.03990000"], ["1974.39000000", "1.21830000"], ["1974.41000000", "8.61930000"], ["1974.45000000", "0.00000000"], ["1974.83000000", "28.34900000"], ["1974.96000000", "0.03000000"], ["1975.06000000", "0.00000000"], ["1975.62000000", "64.31350000"], ["1976.84000000", "0.00000000"], ["1978.48000000", "0.00000000"], ["1979.48000000", "0.02020000"]], "_local_ts_utc": "2026-06-01T07:49:03.312788+00:00"}
{"e": "depthUpdate", "E": 1780300144515, "s": "ETHUSDT", "U": 76583094622, "u": 76583094744, "b": [["1972.80000000", "37.92740000"], ["1972.76000000", "0.01350000"], ["1972.75000000", "10.16340000"], ["1972.72000000", "0.09260000"], ["1972.71000000", "0.00520000"], ["1972.70000000", "0.05260000"], ["1972.69000000", "0.00000000"], ["1972.68000000", "0.47710000"], ["1972.67000000", "0.00560000"], ["1972.66000000", "0.00540000"], ["1972.65000000", "0.20610000"], ["1972.56000000", "0.00000000"], ["1972.53000000", "0.00000000"], ["1972.51000000", "3.04130000"], ["1972.50000000", "10.58830000"], ["1972.46000000", "2.20830000"], ["1972.45000000", "2.56280000"], ["1972.44000000", "0.12620000"], ["1972.08000000", "0.54760000"], ["1972.05000000", "6.16450000"], ["1971.86000000", "22.59360000"], ["1971.46000000", "0.01150000"], ["1971.42000000", "1.17950000"], ["1970.54000000", "7.36940000"], ["1968.03000000", "0.29790000"], ["1967.46000000", "0.58440000"], ["1966.70000000", "0.02460000"], ["1953.66000000", "0.25540000"], ["1775.52000000", "0.51780000"]], "a": [["1972.81000000", "50.16340000"], ["1972.88000000", "0.00800000"], ["1972.89000000", "0.64090000"], ["1972.91000000", "0.00540000"], ["1972.92000000", "3.82860000"], ["1972.94000000", "0.01430000"], ["1972.96000000", "7.73090000"], ["1972.97000000", "0.01020000"], ["1972.99000000", "0.10140000"], ["1973.01000000", "15.64820000"], ["1973.08000000", "0.00000000"], ["1973.10000000", "11.86450000"], ["1973.14000000", "14.16740000"], ["1973.16000000", "0.20000000"], ["1973.17000000", "0.00000000"], ["1973.26000000", "23.16770000"], ["1973.70000000", "3.73570000"], ["1974.41000000", "13.40840000"], ["1974.45000000", "7.09640000"], ["1974.74000000", "3.68010000"], ["1974.83000000", "0.00300000"], ["1974.94000000", "1.40940000"], ["1975.00000000", "5.00570000"], ["1983.25000000", "0.06120000"]], "_local_ts_utc": "2026-06-01T07:49:03.412389+00:00"}
{"e": "depthUpdate", "E": 1780300144615, "s": "ETHUSDT", "U": 76583094745, "u": 76583094909, "b": [["1972.80000000", "44.42090000"], ["1972.79000000", "0.01040000"], ["1972.77000000", "0.62620000"], ["1972.76000000", "0.00810000"], ["1972.75000000", "0.01260000"], ["1972.72000000", "10.23820000"], ["1972.69000000", "0.00540000"], ["1972.66000000", "0.01080000"], ["1972.56000000", "1.10530000"], ["1972.52000000", "1.81020000"], ["1972.51000000", "7.15940000"], ["1972.50000000", "10.59140000"], ["1972.48000000", "15.82070000"], ["1972.47000000", "23.21320000"], ["1972.46000000", "0.11880000"], ["1972.45000000", "0.02720000"], ["1972.43000000", "1.47410000"], ["1972.42000000", "15.62730000"], ["1972.41000000", "0.49190000"], ["1972.40000000", "15.84180000"], ["1972.35000000", "13.51710000"], ["1972.29000000", "0.00540000"], ["1972.09000000", "31.04000000"], ["1972.04000000", "0.37810000"], ["1972.03000000", "17.23700000"], ["1971.94000000", "0.21380000"], ["1971.87000000", "7.10920000"], ["1971.72000000", "0.40260000"], ["1971.46000000", "0.11150000"], ["1971.22000000", "0.00000000"], ["1968.56000000", "0.12160000"], ["1967.56000000", "37.23030000"], ["1953.66000000", "0.38310000"], ["1950.08000000", "0.77370000"], ["1924.32000000", "0.38850000"], ["1775.52000000", "0.53020000"], ["1192.00000000", "0.00000000"]], "a": [["1972.81000000", "30.89180000"], ["1972.84000000", "0.01160000"], ["1972.85000000", "0.00000000"], ["1972.88000000", "0.00260000"], ["1972.89000000", "0.10800000"], ["1972.90000000", "0.46420000"], ["1972.92000000", "9.62240000"], ["1972.94000000", "0.01700000"], ["1972.96000000", "0.00000000"], ["1972.97000000", "0.01020000"], ["1972.99000000", "0.00000000"], ["1973.01000000", "0.00000000"], ["1973.02000000", "0.00000000"], ["1973.07000000", "4.25110000"], ["1973.08000000", "7.09640000"], ["1973.09000000", "14.22580000"], ["1973.10000000", "8.49550000"], ["1973.11000000", "0.00260000"], ["1973.14000000", "0.65030000"], ["1973.16000000", "0.00000000"], ["1973.28000000", "0.05000000"], ["1973.33000000", "0.20000000"], ["1974.06000000", "0.80300000"], ["1974.17000000", "0.63260000"], ["1974.28000000", "0.00260000"], ["1974.39000000", "8.31470000"], ["1974.48000000", "8.54570000"], ["1974.59000000", "0.00000000"], ["1974.66000000", "0.15110000"], ["1974.69000000", "0.00000000"], ["1975.02000000", "0.90780000"], ["1975.10000000", "12.41530000"], ["1975.19000000", "13.69540000"], ["1975.36000000", "5.43470000"], ["1976.59000000", "0.00000000"], ["1976.90000000", "0.01940000"], ["1977.49000000", "0.02030000"], ["1977.62000000", "0.96550000"], ["1977.95000000", "38.78660000"], ["1977.97000000", "0.00000000"], ["1978.21000000", "0.00000000"], ["1978.37000000", "1.28380000"], ["2246.33000000", "0.01110000"]], "_local_ts_utc": "2026-06-01T07:49:03.511236+00:00"}
{"e": "depthUpdate", "E": 1780300144715, "s": "ETHUSDT", "U": 76583094910, "u": 76583095015, "b": [["1972.80000000", "35.01350000"], ["1972.73000000", "0.00260000"], ["1972.72000000", "0.08720000"], ["1972.67000000", "0.00560000"], ["1972.66000000", "10.16210000"], ["1972.64000000", "0.02060000"], ["1972.63000000", "0.03930000"], ["1972.62000000", "0.01640000"], ["1972.57000000", "0.00000000"], ["1972.56000000", "5.37940000"], ["1972.52000000", "1.81020000"], ["1972.51000000", "0.69180000"], ["1972.49000000", "0.00000000"], ["1972.48000000", "22.91710000"], ["1972.47000000", "0.01020000"], ["1972.38000000", "13.64050000"], ["1972.03000000", "14.19100000"], ["1971.83000000", "0.01020000"], ["1971.54000000", "10.06960000"], ["1971.46000000", "0.01150000"], ["1971.42000000", "1.27950000"], ["1970.73000000", "0.02000000"], ["1970.54000000", "0.27300000"], ["1970.53000000", "0.00260000"], ["1970.35000000", "4.69740000"], ["1970.33000000", "0.03460000"], ["1969.09000000", "0.12610000"], ["1962.15000000", "1.20550000"], ["1947.15000000", "0.38430000"], ["1946.13000000", "0.89430000"], ["1943.21000000", "0.12840000"], ["1934.19000000", "0.76740000"], ["1933.35000000", "0.12900000"], ["1913.63000000", "0.13040000"], ["1775.52000000", "0.54260000"]], "a": [["1972.81000000", "37.21360000"], ["1972.90000000", "0.46960000"], ["1972.91000000", "4.40410000"], ["1972.92000000", "7.68260000"], ["1972.93000000", "0.00270000"], ["1972.94000000", "1.29100000"], ["1973.00000000", "4.95050000"], ["1973.05000000", "13.10550000"], ["1973.06000000", "22.57370000"], ["1973.07000000", "0.00300000"], ["1973.09000000", "22.74150000"], ["1973.17000000", "1.20550000"], ["1973.75000000", "16.99810000"], ["1974.48000000", "0.03000000"], ["1975.18000000", "3.60000000"]], "_local_ts_utc": "2026-06-01T07:49:03.611698+00:00"}
{"e": "depthUpdate", "E": 1780300144815, "s": "ETHUSDT", "U": 76583095016, "u": 76583095180, "b": [["1972.80000000", "31.66190000"], ["1972.79000000", "0.01300000"], ["1972.75000000", "10.16340000"], ["1972.72000000", "0.08720000"], ["1972.71000000", "0.00520000"], ["1972.67000000", "0.00560000"], ["1972.66000000", "0.01080000"], ["1972.64000000", "0.01520000"], ["1972.63000000", "0.03390000"], ["1972.57000000", "0.00000000"], ["1972.56000000", "0.00000000"], ["1972.53000000", "3.70100000"], ["1972.50000000", "22.29710000"], ["1972.49000000", "14.19280000"], ["1972.48000000", "0.04480000"], ["1972.43000000", "17.08620000"], ["1972.42000000", "0.01520000"], ["1972.40000000", "15.83870000"], ["1972.39000000", "14.19280000"], ["1972.38000000", "6.54410000"], ["1972.37000000", "0.05510000"], ["1972.35000000", "0.00000000"], ["1972.33000000", "15.71760000"], ["1972.32000000", "0.03510000"], ["1972.27000000", "14.19920000"], ["1972.21000000", "13.60950000"], ["1972.16000000", "16.76360000"], ["1971.94000000", "0.21380000"], ["1971.87000000", "7.50920000"], ["1971.72000000", "0.00260000"], ["1971.65000000", "3.61520000"], ["1971.54000000", "7.22220000"], ["1971.42000000", "1.27950000"], ["1971.18000000", "0.00000000"], ["1970.73000000", "8.53570000"], ["1970.54000000", "7.36940000"], ["1970.53000000", "0.00260000"], ["1970.34000000", "0.00000000"], ["1970.33000000", "0.03460000"], ["1970.13000000", "0.10760000"], ["1969.61000000", "0.12150000"], ["1969.47000000", "5.13740000"], ["1969.46000000", "13.52880000"], ["1967.46000000", "0.00300000"], ["1966.71000000", "0.58630000"], ["1965.42000000", "0.00000000"], ["1965.17000000", "0.02460000"], ["1963.19000000", "0.00000000"], ["1775.52000000", "0.55500000"], ["1578.48000000", "0.06820000"], ["1578.24000000", "0.07700000"]], "a": [["1972.81000000", "38.72470000"], ["1972.82000000", "0.00510000"], ["1972.89000000", "0.10800000"], ["1972.90000000", "0.46960000"], ["1972.91000000", "4.40410000"], ["1972.93000000", "0.00540000"], ["1973.09000000", "22.74150000"], ["1973.11000000", "0.20260000"], ["1973.33000000", "0.00000000"], ["1973.98000000", "0.00260000"], ["1974.06000000", "1.20300000"], ["1974.20000000", "16.33070000"], ["1974.48000000", "0.03000000"], ["2259.42000000", "0.00380000"], ["2326.08000000", "0.13640000"]], "_local_ts_utc": "2026-06-01T07:49:03.713244+00:00"}
{"e": "depthUpdate", "E": 1780300144915, "s": "ETHUSDT", "U": 76583095181, "u": 76583095228, "b": [["1972.80000000", "31.66190000"], ["1972.79000000", "0.01300000"], ["1972.76000000", "0.01350000"], ["1972.66000000", "0.00540000"], ["1972.44000000", "13.64330000"], ["1971.81000000", "8.35100000"], ["1971.76000000", "0.20760000"], ["1970.43000000", "0.16950000"], ["1970.14000000", "0.12790000"], ["1962.15000000", "0.00000000"], ["1953.66000000", "0.51080000"], ["1933.34000000", "4.28320000"], ["1775.52000000", "0.55500000"]], "a": [["1972.81000000", "43.62400000"], ["1973.17000000", "0.00000000"], ["1973.48000000", "9.25900000"], ["1973.93000000", "0.21920000"], ["1974.28000000", "0.00560000"], ["1976.48000000", "0.00000000"], ["1981.64000000", "1.20550000"], ["2326.08000000", "0.73640000"]], "_local_ts_utc": "2026-06-01T07:49:03.812320+00:00"}
{"e": "depthUpdate", "E": 1780300145015, "s": "ETHUSDT", "U": 76583095229, "u": 76583095318, "b": [["1972.80000000", "45.13050000"], ["1972.79000000", "0.01550000"], ["1972.78000000", "0.01310000"], ["1972.77000000", "0.62620000"], ["1972.76000000", "0.00810000"], ["1972.75000000", "0.01260000"], ["1972.66000000", "0.01080000"], ["1972.53000000", "10.17250000"], ["1972.51000000", "29.73310000"], ["1972.45000000", "0.28090000"], ["1972.44000000", "16.17890000"], ["1972.38000000", "0.08660000"], ["1972.25000000", "2.74840000"], ["1972.24000000", "0.00000000"], ["1972.16000000", "14.22800000"], ["1972.11000000", "0.37400000"], ["1972.05000000", "3.62690000"], ["1971.99000000", "1.01970000"], ["1971.18000000", "2.90340000"], ["1970.04000000", "0.27260000"], ["1967.87000000", "0.00520000"], ["1963.48000000", "0.48860000"], ["1943.21000000", "0.25680000"], ["1923.48000000", "0.12970000"], ["1775.52000000", "0.55500000"]], "a": [["1972.81000000", "38.20490000"], ["1972.84000000", "0.01420000"], ["1972.86000000", "0.00000000"], ["1972.97000000", "0.01020000"], ["1973.04000000", "11.09420000"], ["1973.05000000", "22.57370000"], ["1973.06000000", "0.00000000"], ["1973.08000000", "7.19780000"], ["1973.09000000", "14.22580000"], ["1973.11000000", "0.00260000"], ["1973.21000000", "0.94500000"], ["1973.22000000", "20.63560000"], ["1973.24000000", "0.20000000"], ["1973.42000000", "2.53990000"], ["1973.60000000", "0.00570000"], ["1974.06000000", "0.40300000"], ["1974.20000000", "17.13070000"], ["1974.48000000", "8.54570000"], ["1974.94000000", "2.69540000"], ["1976.90000000", "0.00000000"], ["1977.49000000", "0.00000000"], ["1977.73000000", "0.02520000"], ["1977.74000000", "0.30180000"], ["1978.33000000", "0.02670000"], ["1981.35000000", "0.47660000"]], "_local_ts_utc": "2026-06-01T07:49:03.911772+00:00"}
{"e": "depthUpdate", "E": 1780300145115, "s": "ETHUSDT", "U": 76583095319, "u": 76583096486, "b": [["1972.80000000", "0.00000000"], ["1972.79000000", "0.00000000"], ["1972.78000000", "0.00000000"], ["1972.77000000", "0.00000000"], ["1972.76000000", "0.00000000"], ["1972.75000000", "0.00000000"], ["1972.74000000", "0.00000000"], ["1972.73000000", "0.00000000"], ["1972.72000000", "0.00000000"], ["1972.71000000", "0.00000000"], ["1972.70000000", "0.00000000"], ["1972.69000000", "0.00000000"], ["1972.68000000", "0.00000000"], ["1972.67000000", "0.00000000"], ["1972.66000000", "0.00000000"], ["1972.65000000", "0.00000000"], ["1972.64000000", "0.00000000"], ["1972.63000000", "0.00000000"], ["1972.62000000", "0.00000000"], ["1972.61000000", "0.00000000"], ["1972.60000000", "0.00000000"], ["1972.59000000", "0.00000000"], ["1972.56000000", "0.00000000"], ["1972.55000000", "0.00000000"], ["1972.54000000", "0.00000000"], ["1972.53000000", "0.00000000"], ["1972.52000000", "0.00000000"], ["1972.51000000", "0.00000000"], ["1972.50000000", "0.00000000"], ["1972.49000000", "0.00000000"], ["1972.48000000", "0.00000000"], ["1972.47000000", "0.00000000"], ["1972.46000000", "0.00000000"], ["1972.45000000", "0.00000000"], ["1972.44000000", "0.00000000"], ["1972.43000000", "40.30740000"], ["1972.42000000", "0.01580000"], ["1972.41000000", "1.99330000"], ["1972.40000000", "0.00520000"], ["1972.39000000", "0.00260000"], ["1972.38000000", "0.07910000"], ["1972.37000000", "0.05770000"], ["1972.36000000", "0.11790000"], ["1972.35000000", "0.64170000"], ["1972.34000000", "0.04060000"], ["1972.33000000", "0.01430000"], ["1972.32000000", "0.04310000"], ["1972.31000000", "10.26960000"], ["1972.30000000", "0.34940000"], ["1972.28000000", "0.51290000"], ["1972.27000000", "0.00640000"], ["1972.26000000", "0.01000000"], ["1972.25000000", "0.71820000"], ["1972.23000000", "22.71420000"], ["1972.22000000", "0.05080000"], ["1972.21000000", "0.09780000"], ["1972.18000000", "0.05840000"], ["1972.17000000", "0.16110000"], ["1972.16000000", "0.03580000"], ["1972.15000000", "0.01020000"], ["1972.14000000", "0.00260000"], ["1972.13000000", "29.84840000"], ["1972.12000000", "0.00000000"], ["1972.10000000", "25.81750000"], ["1972.09000000", "29.51750000"], ["1972.08000000", "0.27760000"], ["1972.07000000", "0.01010000"], ["1972.05000000", "0.02690000"], ["1972.03000000", "14.46100000"], ["1972.02000000", "15.61370000"], ["1972.01000000", "1.16260000"], ["1971.99000000", "0.44330000"], ["1971.96000000", "1.87370000"], ["1971.95000000", "3.26440000"], ["1971.94000000", "0.21380000"], ["1971.90000000", "20.65910000"], ["1971.87000000", "7.10920000"], ["1971.82000000", "5.45160000"], ["1971.81000000", "7.14550000"], ["1971.80000000", "0.00570000"], ["1971.79000000", "3.16260000"], ["1971.78000000", "5.38880000"], ["1971.76000000", "0.00760000"], ["1971.75000000", "6.58620000"], ["1971.73000000", "0.01170000"], ["1971.71000000", "0.00000000"], ["1971.70000000", "19.62400000"], ["1971.69000000", "13.88000000"], ["1971.64000000", "0.01270000"], ["1971.62000000", "0.05030000"], ["1971.60000000", "0.00830000"], ["1971.59000000", "2.84750000"], ["1971.58000000", "0.90260000"], ["1971.57000000", "0.22710000"], ["1971.55000000", "17.85170000"], ["1971.54000000", "33.98620000"], ["1971.52000000", "0.08030000"], ["1971.50000000", "20.74610000"], ["1971.48000000", "1.54370000"], ["1971.42000000", "0.96610000"], ["1971.34000000", "8.11910000"], ["1971.26000000", "0.98820000"], ["1971.17000000", "0.00000000"], ["1971.16000000", "0.01270000"], ["1971.13000000", "0.12050000"], ["1971.10000000", "16.75610000"], ["1971.02000000", "0.27000000"], ["1970.74000000", "8.10970000"], ["1970.60000000", "18.28590000"], ["1970.58000000", "1.15120000"], ["1970.53000000", "15.61470000"], ["1970.46000000", "0.00390000"], ["1970.37000000", "0.01350000"], ["1970.35000000", "13.02420000"], ["1970.34000000", "7.09640000"], ["1970.33000000", "22.74310000"], ["1970.20000000", "0.01400000"], ["1970.15000000", "4.35710000"], ["1970.14000000", "7.22430000"], ["1970.13000000", "7.20400000"], ["1970.04000000", "0.00260000"], ["1970.03000000", "0.06860000"], ["1969.92000000", "9.68530000"], ["1969.52000000", "0.00000000"], ["1969.32000000", "4.34280000"], ["1969.31000000", "14.53920000"], ["1968.86000000", "33.65470000"], ["1967.76000000", "0.05310000"], ["1967.60000000", "0.00310000"], ["1967.54000000", "0.00260000"], ["1967.10000000", "0.04460000"], ["1967.01000000", "0.54330000"], ["1966.90000000", "0.00830000"], ["1966.80000000", "0.01290000"], ["1965.78000000", "127.33540000"], ["1965.57000000", "0.11020000"], ["1965.43000000", "1.13170000"], ["1965.05000000", "3.60000000"], ["1963.81000000", "0.20230000"], ["1963.64000000", "0.02110000"], ["1963.60000000", "0.00380000"], ["1963.48000000", "0.00000000"], ["1963.46000000", "1.00000000"], ["1963.34000000", "0.52790000"], ["1963.17000000", "0.00000000"], ["1962.15000000", "1.20550000"], ["1961.49000000", "1.01770000"], ["1956.80000000", "0.00310000"], ["1950.30000000", "0.00000000"], ["1923.48000000", "0.25940000"], ["1775.52000000", "0.40000000"], ["1775.29000000", "0.00000000"], ["1578.48000000", "0.05420000"], ["1578.33000000", "0.00000000"], ["1578.24000000", "0.08400000"], ["1578.04000000", "0.01400000"], ["1472.78000000", "0.00600000"]], "a": [["1972.44000000", "52.81650000"], ["1972.45000000", "5.12940000"], ["1972.46000000", "0.01050000"], ["1972.47000000", "0.00540000"], ["1972.48000000", "0.00000000"], ["1972.49000000", "4.00000000"], ["1972.50000000", "45.90130000"], ["1972.51000000", "3.00000000"], ["1972.52000000", "0.01160000"], ["1972.53000000", "0.00000000"], ["1972.54000000", "0.00000000"], ["1972.55000000", "19.49010000"], ["1972.56000000", "5.87850000"], ["1972.57000000", "0.00000000"], ["1972.60000000", "0.00570000"], ["1972.62000000", "0.01020000"], ["1972.64000000", "0.00000000"], ["1972.65000000", "1.52040000"], ["1972.66000000", "4.97710000"], ["1972.69000000", "0.00000000"], ["1972.70000000", "0.00570000"], ["1972.71000000", "0.00000000"], ["1972.72000000", "7.45260000"], ["1972.73000000", "8.50160000"], ["1972.74000000", "0.00650000"], ["1972.75000000", "0.00000000"], ["1972.76000000", "0.00260000"], ["1972.77000000", "0.00000000"], ["1972.78000000", "1.41830000"], ["1972.79000000", "0.00000000"], ["1972.80000000", "0.00570000"], ["1972.81000000", "0.02170000"], ["1972.82000000", "0.00000000"], ["1972.83000000", "0.00000000"], ["1972.86000000", "0.00260000"], ["1972.87000000", "0.67660000"], ["1972.88000000", "0.50690000"], ["1972.89000000", "0.10000000"], ["1972.90000000", "0.46420000"], ["1972.91000000", "11.49510000"], ["1972.92000000", "1.20340000"], ["1972.93000000", "0.50000000"], ["1972.94000000", "7.10030000"], ["1972.95000000", "0.00000000"], ["1972.96000000", "0.00260000"], ["1973.00000000", "4.31570000"], ["1973.02000000", "15.73900000"], ["1973.03000000", "31.29200000"], ["1973.04000000", "13.51710000"], ["1973.05000000", "0.00000000"], ["1973.07000000", "0.00560000"], ["1973.11000000", "0.00000000"], ["1973.13000000", "2.70150000"], ["1973.15000000", "27.96550000"], ["1973.24000000", "0.00000000"], ["1973.30000000", "0.79410000"], ["1973.31000000", "0.84300000"], ["1973.35000000", "14.19160000"], ["1973.42000000", "0.00260000"], ["1973.44000000", "3.60000000"], ["1973.48000000", "8.31400000"], ["1973.50000000", "10.45980000"], ["1973.54000000", "0.09770000"], ["1973.59000000", "0.00260000"], ["1973.60000000", "0.00310000"], ["1973.61000000", "0.37810000"], ["1973.67000000", "0.74510000"], ["1973.70000000", "3.73310000"], ["1973.78000000", "0.00000000"], ["1973.79000000", "0.00000000"], ["1973.95000000", "15.64540000"], ["1973.98000000", "0.80260000"], ["1974.02000000", "0.00000000"], ["1974.20000000", "16.33070000"], ["1974.37000000", "0.46160000"], ["1974.38000000", "11.60200000"], ["1974.39000000", "1.21830000"], ["1974.41000000", "8.61930000"], ["1974.45000000", "0.94920000"], ["1974.46000000", "0.56700000"], ["1974.47000000", "0.00000000"], ["1974.48000000", "0.03000000"], ["1974.60000000", "0.03610000"], ["1974.74000000", "0.00640000"], ["1974.80000000", "4.57690000"], ["1974.94000000", "0.00680000"], ["1975.02000000", "0.00000000"], ["1975.10000000", "0.00000000"], ["1975.19000000", "0.17830000"], ["1975.26000000", "0.00000000"], ["1975.35000000", "0.00260000"], ["1975.36000000", "0.00000000"], ["1975.53000000", "0.00000000"], ["1975.74000000", "0.44970000"], ["1976.18000000", "1.20550000"], ["1976.68000000", "0.00000000"], ["1976.74000000", "0.00520000"], ["1976.94000000", "0.00000000"], ["1977.14000000", "0.00000000"], ["1977.32000000", "4.24040000"], ["1977.56000000", "0.00000000"], ["1977.62000000", "0.03290000"], ["1977.81000000", "0.00000000"], ["1977.82000000", "0.00000000"], ["1977.89000000", "0.00000000"], ["1977.97000000", "0.00000000"], ["1977.98000000", "0.00000000"], ["1978.01000000", "0.00750000"], ["1978.07000000", "0.00000000"], ["1978.11000000", "0.00260000"], ["1978.59000000", "0.00260000"], ["1978.62000000", "3.60480000"], ["1979.54000000", "0.00000000"], ["1979.92000000", "0.00270000"], ["1979.98000000", "0.01310000"], ["1980.01000000", "7.60260000"], ["1981.70000000", "0.00380000"], ["1981.81000000", "0.02380000"], ["1982.63000000", "0.00590000"], ["1983.05000000", "0.12280000"], ["1983.51000000", "0.00000000"], ["1983.69000000", "0.01480000"], ["1985.06000000", "0.00800000"], ["1985.24000000", "0.00000000"], ["1987.53000000", "0.02270000"], ["1988.21000000", "0.12120000"], ["1988.49000000", "1.51410000"], ["1990.90000000", "0.05230000"], ["1992.93000000", "0.03660000"], ["1995.45000000", "0.68240000"], ["1997.16000000", "0.00990000"], ["1997.33000000", "0.01260000"], ["1998.11000000", "0.12400000"], ["2001.94000000", "21.32490000"], ["2002.45000000", "0.00000000"], ["2002.51000000", "0.00000000"], ["2003.03000000", "0.01330000"], ["2019.70000000", "0.11350000"], ["2027.27000000", "0.13980000"], ["2037.17000000", "0.00280000"], ["2272.90000000", "0.00630000"], ["2472.79000000", "1.08870000"]], "_local_ts_utc": "2026-06-01T07:49:04.013269+00:00"}
{"e": "depthUpdate", "E": 1780300145215, "s": "ETHUSDT", "U": 76583096487, "u": 76583096933, "b": [["1972.43000000", "35.78060000"], ["1972.42000000", "0.01580000"], ["1972.41000000", "1.98010000"], ["1972.36000000", "10.27070000"], ["1972.35000000", "0.00260000"], ["1972.33000000", "0.01170000"], ["1972.32000000", "0.00510000"], ["1972.31000000", "1.38380000"], ["1972.29000000", "0.01080000"], ["1972.28000000", "0.50750000"], ["1972.26000000", "0.64840000"], ["1972.25000000", "0.72360000"], ["1972.24000000", "8.51570000"], ["1972.23000000", "0.00570000"], ["1972.21000000", "21.33130000"], ["1972.20000000", "0.00780000"], ["1972.19000000", "0.00300000"], ["1972.14000000", "22.03540000"], ["1972.13000000", "0.04350000"], ["1972.11000000", "44.18660000"], ["1972.10000000", "0.00830000"], ["1972.08000000", "0.00760000"], ["1972.06000000", "0.02120000"], ["1972.05000000", "0.68860000"], ["1972.04000000", "8.51570000"], ["1972.03000000", "0.27000000"], ["1972.02000000", "0.00550000"], ["1972.01000000", "15.35540000"], ["1971.99000000", "7.09640000"], ["1971.95000000", "0.21810000"], ["1971.94000000", "22.04660000"], ["1971.92000000", "0.01170000"], ["1971.91000000", "0.92230000"], ["1971.90000000", "12.14550000"], ["1971.89000000", "8.36880000"], ["1971.88000000", "0.01130000"], ["1971.87000000", "0.01460000"], ["1971.82000000", "13.91700000"], ["1971.81000000", "7.09520000"], ["1971.80000000", "13.52280000"], ["1971.79000000", "7.36430000"], ["1971.78000000", "0.02460000"], ["1971.75000000", "6.96430000"], ["1971.74000000", "7.21360000"], ["1971.73000000", "0.01170000"], ["1971.69000000", "0.36630000"], ["1971.65000000", "3.61520000"], ["1971.59000000", "1.34750000"], ["1971.58000000", "1.10260000"], ["1971.56000000", "13.79120000"], ["1971.55000000", "18.58890000"], ["1971.52000000", "0.03000000"], ["1971.51000000", "0.01280000"], ["1971.44000000", "0.00000000"], ["1971.42000000", "0.16610000"], ["1971.36000000", "1.28670000"], ["1971.35000000", "11.98320000"], ["1971.33000000", "2.87540000"], ["1971.28000000", "13.52590000"], ["1971.18000000", "0.00000000"], ["1971.16000000", "0.11270000"], ["1971.13000000", "0.02050000"], ["1971.06000000", "8.56230000"], ["1971.05000000", "3.80100000"], ["1971.01000000", "14.10010000"], ["1970.99000000", "1.07670000"], ["1970.97000000", "10.58850000"], ["1970.93000000", "0.01730000"], ["1970.33000000", "14.22740000"], ["1970.22000000", "0.58250000"], ["1970.15000000", "11.45350000"], ["1970.11000000", "0.06070000"], ["1970.03000000", "7.16500000"], ["1969.83000000", "0.00260000"], ["1969.76000000", "0.20180000"], ["1969.58000000", "0.58190000"], ["1969.16000000", "0.00000000"], ["1969.14000000", "0.00000000"], ["1969.03000000", "13.52410000"], ["1968.89000000", "0.00000000"], ["1968.69000000", "1.47180000"], ["1968.58000000", "6.96530000"], ["1968.35000000", "0.91190000"], ["1966.90000000", "0.01090000"], ["1966.81000000", "0.00260000"], ["1966.72000000", "0.04360000"], ["1966.63000000", "0.07690000"], ["1965.17000000", "0.01510000"], ["1963.50000000", "0.02860000"], ["1942.82000000", "0.12840000"], ["1775.19000000", "0.01240000"]], "a": [["1972.44000000", "29.90350000"], ["1972.45000000", "0.14690000"], ["1972.46000000", "0.00510000"], ["1972.47000000", "0.00540000"], ["1972.48000000", "5.54560000"], ["1972.49000000", "0.00000000"], ["1972.50000000", "0.00800000"], ["1972.52000000", "0.00260000"], ["1972.53000000", "6.46760000"], ["1972.54000000", "0.00000000"], ["1972.55000000", "5.63650000"], ["1972.56000000", "0.90150000"], ["1972.61000000", "0.00000000"], ["1972.63000000", "0.01160000"], ["1972.64000000", "0.90670000"], ["1972.65000000", "1.52040000"], ["1972.67000000", "0.00260000"], ["1972.72000000", "0.33000000"], ["1972.73000000", "0.10160000"], ["1972.81000000", "0.01160000"], ["1972.82000000", "12.73440000"], ["1972.83000000", "22.57370000"], ["1972.84000000", "0.00260000"], ["1972.86000000", "0.00260000"], ["1972.87000000", "0.03300000"], ["1972.90000000", "14.63540000"], ["1972.91000000", "7.09640000"], ["1972.98000000", "2.87880000"], ["1973.04000000", "0.00000000"], ["1973.07000000", "13.52270000"], ["1973.08000000", "7.09640000"], ["1973.13000000", "10.09960000"], ["1973.28000000", "0.08000000"], ["1973.56000000", "0.00000000"], ["1973.58000000", "7.09640000"], ["1973.91000000", "3.80000000"], ["1974.13000000", "0.00260000"], ["1974.38000000", "4.50560000"], ["1974.60000000", "14.15300000"], ["1974.85000000", "2.39470000"], ["1974.96000000", "0.00000000"], ["1975.04000000", "0.00000000"], ["1975.19000000", "0.17830000"], ["1975.27000000", "0.00300000"], ["1975.61000000", "9.37810000"], ["1975.98000000", "0.00000000"], ["1976.36000000", "0.00260000"], ["1976.80000000", "0.00570000"], ["1976.89000000", "0.08120000"], ["1977.71000000", "0.00000000"], ["1977.79000000", "0.00000000"], ["1977.86000000", "31.63950000"], ["1977.92000000", "0.00260000"], ["1979.13000000", "0.02710000"], ["1980.05000000", "1.93170000"], ["1981.26000000", "0.55640000"], ["1981.31000000", "0.00280000"], ["1981.70000000", "0.01970000"], ["1981.77000000", "0.00000000"], ["1984.79000000", "0.02300000"], ["1990.57000000", "0.00440000"], ["1993.60000000", "0.01420000"], ["2007.20000000", "0.07290000"], ["2009.09000000", "0.16330000"]], "_local_ts_utc": "2026-06-01T07:49:04.111386+00:00"}
{"e": "depthUpdate", "E": 1780300145315, "s": "ETHUSDT", "U": 76583096934, "u": 76583097153, "b": [["1972.43000000", "18.93520000"], ["1972.42000000", "0.01580000"], ["1972.37000000", "0.00770000"], ["1972.36000000", "0.11790000"], ["1972.35000000", "10.15550000"], ["1972.32000000", "0.01050000"], ["1972.31000000", "1.37840000"], ["1972.29000000", "0.00540000"], ["1972.28000000", "0.00000000"], ["1972.27000000", "0.00640000"], ["1972.26000000", "0.01540000"], ["1972.25000000", "0.71820000"], ["1972.24000000", "0.00000000"], ["1972.21000000", "0.04210000"], ["1972.16000000", "0.05320000"], ["1972.15000000", "6.47780000"], ["1972.14000000", "8.51830000"], ["1972.13000000", "21.25840000"], ["1972.12000000", "0.00000000"], ["1972.11000000", "43.91660000"], ["1972.09000000", "15.88030000"], ["1972.03000000", "0.00000000"], ["1972.01000000", "14.54540000"], ["1971.99000000", "7.53970000"], ["1971.94000000", "22.04660000"], ["1971.91000000", "3.45990000"], ["1971.90000000", "19.43240000"], ["1971.89000000", "8.63880000"], ["1971.83000000", "0.06020000"], ["1971.80000000", "14.12280000"], ["1971.79000000", "6.60150000"], ["1971.73000000", "0.28170000"], ["1971.66000000", "24.41010000"], ["1971.65000000", "3.61520000"], ["1971.58000000", "0.50260000"], ["1971.56000000", "14.32120000"], ["1971.36000000", "0.48670000"], ["1971.35000000", "8.26220000"], ["1971.29000000", "20.49620000"], ["1971.27000000", "0.00320000"], ["1971.24000000", "0.27000000"], ["1971.16000000", "0.01270000"], ["1971.10000000", "16.75610000"], ["1970.98000000", "0.10560000"], ["1970.91000000", "16.09630000"], ["1970.74000000", "8.37970000"], ["1970.67000000", "4.86470000"], ["1970.49000000", "16.03320000"], ["1970.29000000", "12.78530000"], ["1970.28000000", "14.54140000"], ["1970.08000000", "0.08690000"], ["1969.76000000", "0.17180000"], ["1969.06000000", "7.19930000"], ["1964.97000000", "0.00970000"], ["1953.28000000", "0.12770000"], ["1775.19000000", "0.02480000"]], "a": [["1972.44000000", "58.05020000"], ["1972.45000000", "0.00510000"], ["1972.48000000", "3.30020000"], ["1972.50000000", "0.01110000"], ["1972.52000000", "0.00800000"], ["1972.54000000", "0.00000000"], ["1972.55000000", "0.65940000"], ["1972.56000000", "0.91310000"], ["1972.60000000", "0.01730000"], ["1972.63000000", "0.00000000"], ["1972.64000000", "3.24520000"], ["1972.65000000", "1.36130000"], ["1972.72000000", "0.00000000"], ["1972.73000000", "0.11320000"], ["1972.74000000", "0.05950000"], ["1972.78000000", "0.00000000"], ["1972.81000000", "8.31350000"], ["1972.82000000", "21.25010000"], ["1973.04000000", "0.05000000"], ["1973.16000000", "1.67400000"], ["1973.23000000", "8.17840000"], ["1973.28000000", "0.03000000"], ["1973.41000000", "0.00000000"], ["1973.50000000", "0.51610000"], ["1973.77000000", "14.71630000"], ["1973.98000000", "0.00260000"], ["1974.06000000", "0.00300000"], ["1974.20000000", "11.89680000"], ["1974.23000000", "14.19040000"], ["1974.25000000", "0.00000000"], ["1974.57000000", "10.69380000"], ["1974.77000000", "2.30440000"], ["1975.40000000", "5.00420000"], ["1975.61000000", "0.00000000"], ["1976.22000000", "1.50920000"], ["1976.36000000", "9.38070000"], ["1976.37000000", "31.79540000"], ["1976.42000000", "0.00000000"], ["1983.96000000", "0.00000000"], ["2286.79000000", "0.01180000"]], "_local_ts_utc": "2026-06-01T07:49:04.211446+00:00"}
{"e": "depthUpdate", "E": 1780300145415, "s": "ETHUSDT", "U": 76583097154, "u": 76583097875, "b": [["1972.43000000", "0.00000000"], ["1972.42000000", "0.00000000"], ["1972.41000000", "0.00000000"], ["1972.40000000", "0.00000000"], ["1972.39000000", "0.00000000"], ["1972.38000000", "0.00000000"], ["1972.37000000", "0.00000000"], ["1972.36000000", "0.12470000"], ["1972.35000000", "0.01040000"], ["1972.34000000", "0.03300000"], ["1972.33000000", "0.01430000"], ["1972.32000000", "0.01310000"], ["1972.31000000", "1.38100000"], ["1972.30000000", "0.01630000"], ["1972.29000000", "0.00540000"], ["1972.27000000", "0.00900000"], ["1972.26000000", "0.01800000"], ["1972.25000000", "0.83730000"], ["1972.24000000", "0.00000000"], ["1972.23000000", "0.00310000"], ["1972.21000000", "0.04210000"], ["1972.19000000", "0.00300000"], ["1972.16000000", "0.04780000"], ["1972.15000000", "0.01020000"], ["1972.14000000", "0.00260000"], ["1972.13000000", "0.09350000"], ["1972.12000000", "0.00000000"], ["1972.11000000", "0.05370000"], ["1972.10000000", "0.00520000"], ["1972.09000000", "0.00000000"], ["1972.07000000", "0.00000000"], ["1972.06000000", "0.02660000"], ["1972.04000000", "0.00520000"], ["1972.03000000", "0.00000000"], ["1972.02000000", "0.01090000"], ["1972.01000000", "6.07940000"], ["1972.00000000", "32.03660000"], ["1971.99000000", "0.44330000"], ["1971.95000000", "0.21810000"], ["1971.94000000", "0.01380000"], ["1971.92000000", "0.01170000"], ["1971.91000000", "0.92230000"], ["1971.90000000", "14.19020000"], ["1971.89000000", "0.27000000"], ["1971.87000000", "0.01460000"], ["1971.85000000", "0.00770000"], ["1971.84000000", "0.08030000"], ["1971.83000000", "0.06020000"], ["1971.82000000", "12.90330000"], ["1971.81000000", "7.09640000"], ["1971.80000000", "7.10210000"], ["1971.79000000", "16.00720000"], ["1971.78000000", "0.03470000"], ["1971.74000000", "0.11840000"], ["1971.73000000", "0.28170000"], ["1971.72000000", "8.51830000"], ["1971.71000000", "27.90990000"], ["1971.70000000", "14.32410000"], ["1971.68000000", "0.13470000"], ["1971.67000000", "0.02420000"], ["1971.63000000", "0.01370000"], ["1971.62000000", "0.00000000"], ["1971.59000000", "0.00000000"], ["1971.56000000", "13.52120000"], ["1971.55000000", "17.08890000"], ["1971.49000000", "7.09520000"], ["1971.46000000", "0.01150000"], ["1971.44000000", "0.00000000"], ["1971.43000000", "0.00000000"], ["1971.42000000", "0.16610000"], ["1971.40000000", "0.00570000"], ["1971.39000000", "0.00000000"], ["1971.38000000", "0.84430000"], ["1971.36000000", "1.68670000"], ["1971.35000000", "8.56220000"], ["1971.27000000", "0.00320000"], ["1971.25000000", "4.88420000"], ["1971.21000000", "1.01410000"], ["1971.15000000", "8.84010000"], ["1970.98000000", "0.00560000"], ["1970.92000000", "9.99410000"], ["1970.91000000", "15.88080000"], ["1970.80000000", "0.00570000"], ["1970.76000000", "0.12160000"], ["1970.73000000", "9.54980000"], ["1970.71000000", "7.40400000"], ["1970.67000000", "1.78470000"], ["1970.66000000", "0.15440000"], ["1970.51000000", "13.52990000"], ["1970.46000000", "0.22160000"], ["1970.44000000", "0.00000000"], ["1970.41000000", "8.56360000"], ["1970.28000000", "13.54770000"], ["1970.26000000", "0.01180000"], ["1970.21000000", "8.51990000"], ["1970.19000000", "1.08040000"], ["1970.09000000", "0.00260000"], ["1970.04000000", "15.61470000"], ["1970.03000000", "14.26140000"], ["1969.92000000", "20.13780000"], ["1969.86000000", "6.25620000"], ["1969.84000000", "7.09640000"], ["1969.83000000", "14.19540000"], ["1969.77000000", "0.25850000"], ["1969.69000000", "0.24510000"], ["1969.67000000", "21.28920000"], ["1969.57000000", "0.00270000"], ["1968.89000000", "13.51710000"], ["1968.69000000", "5.31840000"], ["1968.61000000", "13.51710000"], ["1968.46000000", "1.31710000"], ["1966.55000000", "0.08470000"], ["1966.46000000", "0.00260000"], ["1964.97000000", "0.00000000"], ["1964.85000000", "3.60290000"], ["1956.60000000", "3.13500000"], ["1952.07000000", "0.10900000"], ["1946.79000000", "0.12810000"], ["1927.56000000", "0.06840000"], ["1775.19000000", "0.00000000"], ["1775.13000000", "0.00620000"], ["1578.24000000", "0.05600000"], ["1577.90000000", "0.01400000"], ["1577.89000000", "0.01400000"]], "a": [["1972.37000000", "98.13240000"], ["1972.38000000", "18.30830000"], ["1972.39000000", "0.41760000"], ["1972.40000000", "0.00570000"], ["1972.41000000", "6.46760000"], ["1972.42000000", "10.39630000"], ["1972.43000000", "17.05160000"], ["1972.44000000", "0.74770000"], ["1972.45000000", "0.00000000"], ["1972.46000000", "0.00000000"], ["1972.47000000", "0.00000000"], ["1972.48000000", "0.01160000"], ["1972.50000000", "0.00570000"], ["1972.51000000", "0.00000000"], ["1972.52000000", "0.00260000"], ["1972.53000000", "0.00000000"], ["1972.56000000", "8.00950000"], ["1972.59000000", "22.57630000"], ["1972.60000000", "0.00570000"], ["1972.61000000", "7.09640000"], ["1972.62000000", "11.03190000"], ["1972.63000000", "7.09640000"], ["1972.64000000", "0.90670000"], ["1972.67000000", "8.51830000"], ["1972.69000000", "7.09640000"], ["1972.70000000", "0.63510000"], ["1972.73000000", "0.00000000"], ["1972.74000000", "7.79220000"], ["1972.75000000", "7.09640000"], ["1972.76000000", "7.09900000"], ["1972.80000000", "13.52540000"], ["1972.81000000", "8.30190000"], ["1972.83000000", "23.43600000"], ["1972.91000000", "7.14690000"], ["1972.96000000", "0.03260000"], ["1973.03000000", "31.09200000"], ["1973.09000000", "14.68480000"], ["1973.14000000", "0.00390000"], ["1973.22000000", "21.01370000"], ["1973.24000000", "3.60000000"], ["1973.25000000", "15.61080000"], ["1973.32000000", "0.00000000"], ["1973.40000000", "16.41880000"], ["1973.49000000", "7.17340000"], ["1973.55000000", "1.67400000"], ["1973.60000000", "0.03310000"], ["1973.61000000", "0.00000000"], ["1973.69000000", "22.77370000"], ["1973.75000000", "9.90350000"], ["1973.77000000", "14.71630000"], ["1973.79000000", "9.65410000"], ["1973.87000000", "4.88340000"], ["1973.88000000", "15.14250000"], ["1973.91000000", "3.60000000"], ["1973.95000000", "8.55020000"], ["1973.97000000", "1.51200000"], ["1973.99000000", "0.00000000"], ["1974.04000000", "0.98580000"], ["1974.05000000", "2.45700000"], ["1974.08000000", "0.03000000"], ["1974.09000000", "0.00000000"], ["1974.10000000", "5.82500000"], ["1974.11000000", "3.60260000"], ["1974.17000000", "0.63260000"], ["1974.19000000", "0.00000000"], ["1974.20000000", "7.66100000"], ["1974.23000000", "0.00000000"], ["1974.56000000", "0.03000000"], ["1974.57000000", "0.82780000"], ["1974.60000000", "9.15780000"], ["1974.61000000", "0.00300000"], ["1974.77000000", "0.00000000"], ["1974.80000000", "4.54690000"], ["1974.85000000", "1.22110000"], ["1974.86000000", "0.00000000"], ["1974.87000000", "31.68750000"], ["1974.88000000", "0.00000000"], ["1975.05000000", "1.46100000"], ["1975.78000000", "0.00260000"], ["1976.14000000", "0.00640000"], ["1977.38000000", "0.00000000"], ["1977.44000000", "0.00000000"], ["1977.64000000", "0.00000000"], ["1981.11000000", "0.20770000"], ["1981.63000000", "64.11370000"], ["1982.51000000", "0.00000000"], ["1983.09000000", "11.87420000"], ["1983.26000000", "0.00000000"], ["1983.67000000", "0.04090000"], ["1984.22000000", "0.00000000"], ["1984.98000000", "0.00830000"], ["1985.60000000", "0.06830000"], ["2001.59000000", "16.67610000"], ["2001.94000000", "0.01590000"]], "_local_ts_utc": "2026-06-01T07:49:04.312714+00:00"}
{"e": "depthUpdate", "E": 1780300145525, "s": "ETHUSDT", "U": 76583097876, "u": 76583099684, "b": [["1972.36000000", "0.00000000"], ["1972.35000000", "0.00000000"], ["1972.34000000", "0.00000000"], ["1972.33000000", "0.00000000"], ["1972.32000000", "0.00000000"], ["1972.31000000", "0.00000000"], ["1972.30000000", "0.00000000"], ["1972.29000000", "0.00000000"], ["1972.27000000", "0.00000000"], ["1972.26000000", "0.00000000"], ["1972.25000000", "0.00000000"], ["1972.23000000", "0.00000000"], ["1972.22000000", "0.00000000"], ["1972.21000000", "0.00000000"], ["1972.20000000", "0.00000000"], ["1972.19000000", "0.00000000"], ["1972.18000000", "0.00000000"], ["1972.17000000", "0.00000000"], ["1972.16000000", "0.00000000"], ["1972.15000000", "0.00000000"], ["1972.14000000", "0.00000000"], ["1972.13000000", "0.00000000"], ["1972.11000000", "0.00000000"], ["1972.10000000", "0.00000000"], ["1972.08000000", "0.00000000"], ["1972.06000000", "0.00000000"], ["1972.05000000", "0.00000000"], ["1972.04000000", "0.00000000"], ["1972.02000000", "0.00000000"], ["1972.01000000", "0.00000000"], ["1972.00000000", "0.00000000"], ["1971.99000000", "0.00000000"], ["1971.97000000", "0.00000000"], ["1971.96000000", "0.00000000"], ["1971.95000000", "0.00000000"], ["1971.94000000", "0.00000000"], ["1971.93000000", "0.00000000"], ["1971.92000000", "0.00000000"], ["1971.91000000", "0.00000000"], ["1971.90000000", "0.00000000"], ["1971.89000000", "0.00000000"], ["1971.88000000", "0.00000000"], ["1971.87000000", "0.00000000"], ["1971.86000000", "0.00000000"], ["1971.85000000", "9.37890000"], ["1971.84000000", "0.00260000"], ["1971.83000000", "0.05260000"], ["1971.82000000", "0.51240000"], ["1971.81000000", "0.00260000"], ["1971.80000000", "0.00260000"], ["1971.79000000", "0.03300000"], ["1971.78000000", "0.03000000"], ["1971.77000000", "0.24600000"], ["1971.76000000", "0.64570000"], ["1971.75000000", "0.00300000"], ["1971.74000000", "0.01700000"], ["1971.73000000", "0.01170000"], ["1971.72000000", "0.00260000"], ["1971.71000000", "0.00540000"], ["1971.70000000", "0.00800000"], ["1971.68000000", "0.01350000"], ["1971.67000000", "0.02420000"], ["1971.66000000", "0.04320000"], ["1971.65000000", "0.06550000"], ["1971.63000000", "0.01370000"], ["1971.60000000", "0.00520000"], ["1971.59000000", "0.00540000"], ["1971.57000000", "0.08300000"], ["1971.56000000", "0.00680000"], ["1971.55000000", "0.51110000"], ["1971.54000000", "0.00700000"], ["1971.52000000", "0.00000000"], ["1971.50000000", "1.01250000"], ["1971.49000000", "0.00000000"], ["1971.48000000", "0.02070000"], ["1971.47000000", "0.00000000"], ["1971.45000000", "0.05310000"], ["1971.42000000", "0.15850000"], ["1971.41000000", "0.00000000"], ["1971.40000000", "0.00260000"], ["1971.38000000", "0.03430000"], ["1971.37000000", "0.00000000"], ["1971.36000000", "0.06560000"], ["1971.35000000", "0.00000000"], ["1971.34000000", "0.00390000"], ["1971.30000000", "0.21960000"], ["1971.29000000", "1.35610000"], ["1971.28000000", "0.00880000"], ["1971.26000000", "0.98820000"], ["1971.25000000", "0.01140000"], ["1971.24000000", "0.10140000"], ["1971.23000000", "0.00000000"], ["1971.21000000", "0.00000000"], ["1971.20000000", "0.85760000"], ["1971.15000000", "0.00260000"], ["1971.14000000", "0.03960000"], ["1971.12000000", "0.20450000"], ["1971.11000000", "0.41690000"], ["1971.10000000", "0.00570000"], ["1971.09000000", "0.00300000"], ["1971.08000000", "0.00270000"], ["1971.06000000", "11.02840000"], ["1971.05000000", "4.20100000"], ["1971.04000000", "8.57290000"], ["1971.02000000", "0.27000000"], ["1971.01000000", "0.58300000"], ["1971.00000000", "8.18440000"], ["1970.99000000", "6.69560000"], ["1970.97000000", "4.38460000"], ["1970.96000000", "14.20030000"], ["1970.95000000", "0.00000000"], ["1970.94000000", "15.61890000"], ["1970.92000000", "0.06570000"], ["1970.91000000", "0.27000000"], ["1970.90000000", "0.00260000"], ["1970.89000000", "0.00390000"], ["1970.88000000", "22.51710000"], ["1970.87000000", "0.02820000"], ["1970.86000000", "0.00390000"], ["1970.85000000", "26.32110000"], ["1970.84000000", "0.00520000"], ["1970.80000000", "5.53100000"], ["1970.79000000", "0.00910000"], ["1970.78000000", "0.00460000"], ["1970.77000000", "8.61980000"], ["1970.76000000", "7.10930000"], ["1970.74000000", "8.86820000"], ["1970.73000000", "7.11820000"], ["1970.72000000", "0.69280000"], ["1970.71000000", "0.30820000"], ["1970.69000000", "0.00310000"], ["1970.67000000", "8.41110000"], ["1970.66000000", "7.25260000"], ["1970.63000000", "8.52050000"], ["1970.62000000", "7.10080000"], ["1970.61000000", "0.00310000"], ["1970.60000000", "12.88000000"], ["1970.58000000", "7.23540000"], ["1970.57000000", "22.57790000"], ["1970.56000000", "14.31060000"], ["1970.55000000", "1.53760000"], ["1970.54000000", "0.27300000"], ["1970.53000000", "0.00260000"], ["1970.52000000", "1.38510000"], ["1970.51000000", "0.01520000"], ["1970.50000000", "0.04450000"], ["1970.49000000", "0.03820000"], ["1970.48000000", "0.00000000"], ["1970.47000000", "10.83600000"], ["1970.46000000", "7.10210000"], ["1970.45000000", "4.74580000"], ["1970.43000000", "8.68740000"], ["1970.42000000", "7.10080000"], ["1970.41000000", "1.02340000"], ["1970.40000000", "11.90330000"], ["1970.39000000", "13.51710000"], ["1970.38000000", "7.10140000"], ["1970.37000000", "1.02920000"], ["1970.35000000", "0.15790000"], ["1970.34000000", "0.00000000"], ["1970.33000000", "0.03460000"], ["1970.32000000", "15.20820000"], ["1970.29000000", "12.56320000"], ["1970.28000000", "0.03300000"], ["1970.26000000", "7.11000000"], ["1970.25000000", "4.11090000"], ["1970.23000000", "8.52810000"], ["1970.22000000", "8.15650000"], ["1970.21000000", "0.00420000"], ["1970.19000000", "7.80340000"], ["1970.18000000", "8.46350000"], ["1970.16000000", "0.10270000"], ["1970.15000000", "0.00760000"], ["1970.14000000", "0.12790000"], ["1970.13000000", "0.10760000"], ["1970.11000000", "13.57780000"], ["1970.06000000", "7.14760000"], ["1970.05000000", "18.30670000"], ["1970.04000000", "0.00260000"], ["1970.03000000", "8.58650000"], ["1970.02000000", "0.13180000"], ["1969.95000000", "1.01420000"], ["1969.92000000", "9.68530000"], ["1969.91000000", "0.01610000"], ["1969.87000000", "0.00000000"], ["1969.86000000", "19.43270000"], ["1969.85000000", "18.08840000"], ["1969.84000000", "0.00000000"], ["1969.83000000", "22.03760000"], ["1969.80000000", "3.04970000"], ["1969.77000000", "0.00500000"], ["1969.75000000", "0.13230000"], ["1969.74000000", "0.02710000"], ["1969.69000000", "24.66850000"], ["1969.68000000", "22.72050000"], ["1969.67000000", "0.00000000"], ["1969.66000000", "0.00390000"], ["1969.65000000", "33.38710000"], ["1969.62000000", "2.73900000"], ["1969.60000000", "25.46260000"], ["1969.58000000", "0.00000000"], ["1969.56000000", "4.41970000"], ["1969.55000000", "13.51710000"], ["1969.54000000", "0.00260000"], ["1969.52000000", "0.50710000"], ["1969.49000000", "10.08350000"], ["1969.48000000", "15.61610000"], ["1969.47000000", "14.21830000"], ["1969.46000000", "0.01170000"], ["1969.44000000", "0.23470000"], ["1969.40000000", "0.00310000"], ["1969.33000000", "12.39370000"], ["1969.32000000", "43.33240000"], ["1969.31000000", "1.02210000"], ["1969.30000000", "17.89680000"], ["1969.28000000", "1.24230000"], ["1969.25000000", "3.60000000"], ["1969.15000000", "0.13490000"], ["1969.13000000", "8.92010000"], ["1969.12000000", "29.84250000"], ["1969.08000000", "0.76000000"], ["1969.06000000", "11.60690000"], ["1969.04000000", "13.51970000"], ["1969.03000000", "0.00700000"], ["1969.01000000", "1.62360000"], ["1969.00000000", "29.20410000"], ["1968.99000000", "20.43760000"], ["1968.98000000", "0.03310000"], ["1968.96000000", "0.03300000"], ["1968.95000000", "0.01280000"], ["1968.90000000", "13.54580000"], ["1968.89000000", "11.25670000"], ["1968.87000000", "0.91790000"], ["1968.86000000", "0.68140000"], ["1968.83000000", "0.00260000"], ["1968.82000000", "0.00000000"], ["1968.79000000", "0.39420000"], ["1968.75000000", "0.06270000"], ["1968.69000000", "0.00000000"], ["1968.66000000", "5.21900000"], ["1968.63000000", "0.01020000"], ["1968.62000000", "13.52010000"], ["1968.61000000", "0.00000000"], ["1968.36000000", "0.00000000"], ["1968.35000000", "15.90960000"], ["1968.34000000", "31.99530000"], ["1968.33000000", "13.55020000"], ["1968.31000000", "0.37600000"], ["1968.23000000", "0.80070000"], ["1968.22000000", "6.74480000"], ["1968.18000000", "0.00320000"], ["1968.05000000", "17.16560000"], ["1968.01000000", "22.54080000"], ["1967.93000000", "31.90050000"], ["1967.77000000", "13.84860000"], ["1967.49000000", "22.57370000"], ["1967.46000000", "0.50300000"], ["1967.27000000", "0.63130000"], ["1967.25000000", "3.63760000"], ["1966.97000000", "0.00930000"], ["1966.89000000", "8.58070000"], ["1966.68000000", "0.70870000"], ["1966.48000000", "0.50000000"], ["1966.34000000", "0.00260000"], ["1966.26000000", "0.02160000"], ["1966.17000000", "0.14770000"], ["1966.08000000", "0.56690000"], ["1965.02000000", "0.00500000"], ["1964.77000000", "0.00500000"], ["1964.45000000", "3.60260000"], ["1964.32000000", "0.02490000"], ["1964.16000000", "0.01290000"], ["1964.05000000", "3.60420000"], ["1963.85000000", "3.60000000"], ["1963.73000000", "0.23660000"], ["1963.31000000", "0.00000000"], ["1963.24000000", "0.00000000"], ["1963.10000000", "0.00000000"], ["1962.82000000", "6.70230000"], ["1962.67000000", "0.00270000"], ["1962.43000000", "0.00260000"], ["1962.05000000", "0.01870000"], ["1962.00000000", "245.37870000"], ["1961.56000000", "1.20550000"], ["1960.97000000", "1.24130000"], ["1960.11000000", "0.19030000"], ["1959.75000000", "0.00770000"], ["1956.60000000", "0.00000000"], ["1956.14000000", "0.01270000"], ["1947.20000000", "0.08440000"], ["1938.91000000", "0.03340000"], ["1775.13000000", "0.00000000"], ["1775.08000000", "0.00000000"], ["1774.70000000", "0.23020000"], ["1588.49000000", "0.04900000"], ["1588.48000000", "0.06300000"], ["1583.52000000", "0.09800000"], ["1582.64000000", "0.01400000"], ["1582.32000000", "0.05600000"], ["1580.86000000", "0.08000000"], ["1578.38000000", "0.01400000"], ["1578.24000000", "0.02100000"], ["1577.59000000", "0.00700000"], ["1577.57000000", "0.03500000"], ["1577.51000000", "0.02100000"], ["1577.49000000", "0.00700000"], ["1384.65000000", "0.01600000"], ["1384.56000000", "0.00000000"], ["1380.31000000", "0.01600000"]], "a": [["1971.86000000", "130.04570000"], ["1971.87000000", "61.34960000"], ["1971.88000000", "70.17410000"], ["1971.89000000", "19.10890000"], ["1971.90000000", "11.45300000"], ["1971.91000000", "0.00000000"], ["1971.92000000", "0.00000000"], ["1971.93000000", "0.00000000"], ["1971.94000000", "0.00000000"], ["1971.95000000", "0.08550000"], ["1971.96000000", "0.00000000"], ["1971.97000000", "22.43000000"], ["1971.98000000", "0.00000000"], ["1971.99000000", "0.00000000"], ["1972.00000000", "9.35060000"], ["1972.01000000", "25.84630000"], ["1972.02000000", "4.97710000"], ["1972.06000000", "0.00000000"], ["1972.07000000", "0.00000000"], ["1972.09000000", "7.43230000"], ["1972.10000000", "0.00570000"], ["1972.11000000", "4.98990000"], ["1972.12000000", "0.00000000"], ["1972.14000000", "13.72100000"], ["1972.15000000", "15.65030000"], ["1972.16000000", "22.60370000"], ["1972.17000000", "29.81510000"], ["1972.18000000", "0.00260000"], ["1972.19000000", "0.00260000"], ["1972.20000000", "0.00570000"], ["1972.21000000", "0.21790000"], ["1972.22000000", "0.03300000"], ["1972.23000000", "0.00000000"], ["1972.24000000", "1.20550000"], ["1972.25000000", "18.14420000"], ["1972.26000000", "27.75020000"], ["1972.27000000", "0.00000000"], ["1972.28000000", "0.00000000"], ["1972.29000000", "0.00000000"], ["1972.30000000", "24.83910000"], ["1972.31000000", "7.09820000"], ["1972.32000000", "0.04680000"], ["1972.33000000", "0.00000000"], ["1972.34000000", "0.00390000"], ["1972.35000000", "0.00000000"], ["1972.36000000", "36.09080000"], ["1972.37000000", "2.17800000"], ["1972.38000000", "12.68160000"], ["1972.39000000", "0.00000000"], ["1972.40000000", "0.50570000"], ["1972.41000000", "7.94960000"], ["1972.43000000", "25.55570000"], ["1972.44000000", "0.80670000"], ["1972.45000000", "0.50700000"], ["1972.48000000", "0.03000000"], ["1972.49000000", "0.00260000"], ["1972.50000000", "0.05620000"], ["1972.54000000", "0.00390000"], ["1972.55000000", "15.81120000"], ["1972.56000000", "7.99790000"], ["1972.57000000", "1.20550000"], ["1972.58000000", "13.84710000"], ["1972.60000000", "9.37400000"], ["1972.62000000", "0.01020000"], ["1972.65000000", "0.18410000"], ["1972.66000000", "0.00000000"], ["1972.70000000", "3.60570000"], ["1972.74000000", "7.78960000"], ["1972.80000000", "13.55540000"], ["1972.81000000", "19.87940000"], ["1972.82000000", "8.51570000"], ["1972.83000000", "22.57370000"], ["1972.88000000", "0.00000000"], ["1972.90000000", "7.10210000"], ["1972.91000000", "7.09640000"], ["1972.93000000", "0.00000000"], ["1972.97000000", "3.61020000"], ["1972.98000000", "0.00000000"], ["1973.00000000", "0.00310000"], ["1973.02000000", "0.00000000"], ["1973.09000000", "14.77070000"], ["1973.10000000", "0.00310000"], ["1973.11000000", "0.60000000"], ["1973.12000000", "0.03000000"], ["1973.13000000", "0.16370000"], ["1973.15000000", "1.20550000"], ["1973.17000000", "0.00260000"], ["1973.20000000", "0.39030000"], ["1973.21000000", "16.09590000"], ["1973.22000000", "7.09580000"], ["1973.23000000", "8.39250000"], ["1973.29000000", "0.06090000"], ["1973.30000000", "0.79150000"], ["1973.32000000", "0.00390000"], ["1973.34000000", "0.00390000"], ["1973.35000000", "7.09580000"], ["1973.40000000", "0.00610000"], ["1973.43000000", "0.00000000"], ["1973.45000000", "0.00000000"], ["1973.49000000", "0.07700000"], ["1973.51000000", "0.00300000"], ["1973.55000000", "1.05300000"], ["1973.58000000", "0.00000000"], ["1973.61000000", "0.99490000"], ["1973.62000000", "0.01320000"], ["1973.63000000", "0.00260000"], ["1973.68000000", "0.00000000"], ["1973.69000000", "22.57370000"], ["1973.73000000", "0.00300000"], ["1973.75000000", "2.80890000"], ["1973.77000000", "13.51630000"], ["1973.80000000", "0.00310000"], ["1973.84000000", "0.00560000"], ["1973.87000000", "0.00260000"], ["1973.88000000", "0.00000000"], ["1973.90000000", "1.21120000"], ["1973.93000000", "0.00260000"], ["1973.94000000", "0.00650000"], ["1973.95000000", "0.03600000"], ["1974.00000000", "22.62950000"], ["1974.04000000", "0.00000000"], ["1974.10000000", "0.00310000"], ["1974.18000000", "0.00000000"], ["1974.20000000", "0.65370000"], ["1974.32000000", "31.69900000"], ["1974.38000000", "0.03300000"], ["1974.40000000", "0.00310000"], ["1974.41000000", "0.03130000"], ["1974.44000000", "0.00000000"], ["1974.47000000", "0.02000000"], ["1974.48000000", "0.00000000"], ["1974.50000000", "0.28020000"], ["1974.56000000", "0.00000000"], ["1974.60000000", "0.03610000"], ["1974.64000000", "0.00000000"], ["1974.67000000", "0.00260000"], ["1974.72000000", "0.00300000"], ["1974.82000000", "0.03300000"], ["1974.85000000", "0.00260000"], ["1974.91000000", "0.00260000"], ["1974.93000000", "0.02000000"], ["1975.05000000", "1.02900000"], ["1975.08000000", "0.00000000"], ["1975.09000000", "0.51370000"], ["1975.11000000", "0.48600000"], ["1975.15000000", "2.54060000"], ["1975.35000000", "0.92820000"], ["1975.47000000", "0.01020000"], ["1975.74000000", "0.00640000"], ["1976.14000000", "0.00260000"], ["1976.22000000", "0.00000000"], ["1976.34000000", "0.00000000"], ["1976.37000000", "0.13190000"], ["1976.54000000", "0.03290000"], ["1976.80000000", "6.30800000"], ["1976.87000000", "0.20050000"], ["1976.90000000", "0.00000000"], ["1976.97000000", "0.13180000"], ["1977.30000000", "0.00270000"], ["1977.31000000", "0.00000000"], ["1977.32000000", "3.60260000"], ["1977.38000000", "0.00000000"], ["1977.42000000", "0.00000000"], ["1977.44000000", "0.00000000"], ["1977.48000000", "0.00000000"], ["1977.55000000", "0.00000000"], ["1977.57000000", "3.73180000"], ["1977.74000000", "0.15070000"], ["1977.82000000", "0.00870000"], ["1977.89000000", "0.00000000"], ["1978.00000000", "0.15980000"], ["1978.93000000", "0.00000000"], ["1979.14000000", "3.63290000"], ["1979.31000000", "0.00000000"], ["1979.33000000", "0.02980000"], ["1979.34000000", "3.60300000"], ["1979.70000000", "0.00000000"], ["1980.00000000", "8.29770000"], ["1980.18000000", "0.00520000"], ["1980.27000000", "0.00000000"], ["1980.39000000", "0.00690000"], ["1980.97000000", "0.00000000"], ["1981.07000000", "0.05420000"], ["1981.10000000", "0.00000000"], ["1981.28000000", "100.60950000"], ["1981.35000000", "0.00000000"], ["1981.39000000", "0.00000000"], ["1982.78000000", "0.07470000"], ["1982.86000000", "0.00000000"], ["1983.06000000", "0.00000000"], ["1983.07000000", "0.01640000"], ["1983.10000000", "0.00890000"], ["1983.31000000", "0.06010000"], ["1983.33000000", "0.06050000"], ["1983.59000000", "0.00280000"], ["1983.91000000", "0.00510000"], ["1984.00000000", "0.08170000"], ["1984.35000000", "13.51750000"], ["1984.44000000", "0.08130000"], ["1984.62000000", "0.00000000"], ["1984.77000000", "0.00580000"], ["1984.80000000", "0.00790000"], ["1985.19000000", "0.20470000"], ["1985.35000000", "1.24480000"], ["1986.13000000", "0.02770000"], ["1986.27000000", "0.00000000"], ["1986.34000000", "0.21650000"], ["1988.00000000", "0.12340000"], ["1988.23000000", "0.00890000"], ["1989.12000000", "0.12620000"], ["1989.35000000", "0.00910000"], ["1989.96000000", "0.10060000"], ["1990.00000000", "6.33470000"], ["1990.07000000", "0.19860000"], ["1990.87000000", "0.00000000"], ["1992.02000000", "2.64880000"], ["1993.00000000", "1.06110000"], ["1994.00000000", "1.09430000"], ["1994.90000000", "14.22370000"], ["1995.60000000", "0.00520000"], ["1995.66000000", "0.01170000"], ["1996.00000000", "1.71170000"], ["1996.21000000", "0.00940000"], ["1996.74000000", "0.00000000"], ["2000.00000000", "262.59960000"], ["2000.37000000", "0.00270000"], ["2001.10000000", "16.09500000"], ["2001.59000000", "0.02000000"], ["2004.00000000", "0.19900000"], ["2005.96000000", "0.00620000"], ["2013.72000000", "0.01320000"], ["2013.89000000", "0.35200000"], ["2015.38000000", "0.03470000"], ["2015.87000000", "0.06440000"], ["2015.93000000", "0.00000000"], ["2040.29000000", "0.15600000"], ["2051.96000000", "0.00000000"]], "_local_ts_utc": "2026-06-01T07:49:04.422398+00:00"}
{"e": "depthUpdate", "E": 1780300145615, "s": "ETHUSDT", "U": 76583099685, "u": 76583100670, "b": [["1971.85000000", "0.01560000"], ["1971.84000000", "0.01040000"], ["1971.83000000", "0.05260000"], ["1971.82000000", "0.00260000"], ["1971.80000000", "0.00520000"], ["1971.79000000", "0.03560000"], ["1971.78000000", "0.03260000"], ["1971.77000000", "0.24860000"], ["1971.76000000", "0.01020000"], ["1971.72000000", "0.00000000"], ["1971.71000000", "0.00000000"], ["1971.67000000", "0.07450000"], ["1971.66000000", "0.03940000"], ["1971.65000000", "0.06550000"], ["1971.64000000", "0.01270000"], ["1971.63000000", "0.01910000"], ["1971.62000000", "0.00000000"], ["1971.61000000", "0.00000000"], ["1971.59000000", "0.00540000"], ["1971.56000000", "0.00410000"], ["1971.55000000", "0.51110000"], ["1971.50000000", "1.01250000"], ["1971.47000000", "0.00000000"], ["1971.41000000", "0.00000000"], ["1971.40000000", "0.00260000"], ["1971.35000000", "10.17410000"], ["1971.34000000", "0.00390000"], ["1971.31000000", "0.28830000"], ["1971.30000000", "14.41630000"], ["1971.29000000", "16.06810000"], ["1971.28000000", "7.10870000"], ["1971.26000000", "0.71820000"], ["1971.25000000", "3.61140000"], ["1971.24000000", "0.00000000"], ["1971.22000000", "0.37810000"], ["1971.21000000", "0.00000000"], ["1971.20000000", "17.56480000"], ["1971.19000000", "7.11270000"], ["1971.18000000", "15.61970000"], ["1971.17000000", "6.58000000"], ["1971.16000000", "0.01270000"], ["1971.15000000", "0.00260000"], ["1971.14000000", "0.03960000"], ["1971.12000000", "0.20450000"], ["1971.11000000", "0.41690000"], ["1971.09000000", "27.49250000"], ["1971.08000000", "15.62240000"], ["1971.07000000", "50.29590000"], ["1971.06000000", "0.00390000"], ["1971.05000000", "3.80100000"], ["1971.04000000", "0.05500000"], ["1971.03000000", "0.60390000"], ["1971.02000000", "0.00000000"], ["1971.01000000", "0.31300000"], ["1971.00000000", "10.29290000"], ["1970.99000000", "0.11560000"], ["1970.97000000", "0.03880000"], ["1970.96000000", "0.00390000"], ["1970.94000000", "0.00280000"], ["1970.93000000", "0.01730000"], ["1970.90000000", "15.35770000"], ["1970.89000000", "43.34050000"], ["1970.88000000", "0.03260000"], ["1970.86000000", "23.17760000"], ["1970.85000000", "3.74740000"], ["1970.80000000", "0.00570000"], ["1970.77000000", "0.10190000"], ["1970.76000000", "0.01110000"], ["1970.74000000", "0.27000000"], ["1970.73000000", "0.02000000"], ["1970.71000000", "1.51370000"], ["1970.70000000", "13.53440000"], ["1970.69000000", "29.82260000"], ["1970.68000000", "13.52080000"], ["1970.67000000", "0.58160000"], ["1970.66000000", "0.15440000"], ["1970.65000000", "4.30570000"], ["1970.64000000", "0.80000000"], ["1970.63000000", "0.00260000"], ["1970.62000000", "0.00260000"], ["1970.59000000", "29.81950000"], ["1970.58000000", "0.13720000"], ["1970.56000000", "0.79350000"], ["1970.49000000", "15.60260000"], ["1970.48000000", "43.33660000"], ["1970.47000000", "0.00000000"], ["1970.46000000", "0.80390000"], ["1970.44000000", "4.38800000"], ["1970.43000000", "1.18980000"], ["1970.42000000", "0.00260000"], ["1970.40000000", "1.13560000"], ["1970.39000000", "0.00000000"], ["1970.38000000", "0.10320000"], ["1970.35000000", "0.15790000"], ["1970.34000000", "16.65010000"], ["1970.33000000", "43.37120000"], ["1970.32000000", "15.47820000"], ["1970.31000000", "0.00000000"], ["1970.29000000", "8.58430000"], ["1970.27000000", "0.03650000"], ["1970.26000000", "0.01180000"], ["1970.25000000", "4.11090000"], ["1970.23000000", "0.01020000"], ["1970.22000000", "0.98260000"], ["1970.19000000", "14.90310000"], ["1970.18000000", "1.36530000"], ["1970.16000000", "0.00270000"], ["1970.15000000", "26.77160000"], ["1970.13000000", "29.92710000"], ["1970.11000000", "0.06070000"], ["1970.08000000", "1.04830000"], ["1970.07000000", "13.51710000"], ["1970.06000000", "0.04940000"], ["1970.05000000", "4.38030000"], ["1970.03000000", "0.06860000"], ["1970.02000000", "29.95130000"], ["1969.97000000", "0.08660000"], ["1969.94000000", "0.21380000"], ["1969.93000000", "0.00400000"], ["1969.92000000", "0.03820000"], ["1969.88000000", "9.76780000"], ["1969.87000000", "29.81950000"], ["1969.86000000", "0.01930000"], ["1969.85000000", "3.89200000"], ["1969.83000000", "0.00260000"], ["1969.79000000", "13.52650000"], ["1969.76000000", "0.20180000"], ["1969.73000000", "17.00800000"], ["1969.72000000", "32.27830000"], ["1969.70000000", "21.36260000"], ["1969.69000000", "16.58590000"], ["1969.68000000", "0.00620000"], ["1969.65000000", "26.28890000"], ["1969.56000000", "10.21580000"], ["1969.55000000", "0.00000000"], ["1969.54000000", "1.01000000"], ["1969.51000000", "13.51710000"], ["1969.50000000", "14.95620000"], ["1969.49000000", "0.01710000"], ["1969.48000000", "0.00000000"], ["1969.47000000", "0.02190000"], ["1969.46000000", "1.19270000"], ["1969.41000000", "0.11870000"], ["1969.35000000", "4.37820000"], ["1969.34000000", "13.53420000"], ["1969.33000000", "0.10820000"], ["1969.32000000", "0.00280000"], ["1969.15000000", "0.13490000"], ["1969.14000000", "0.00000000"], ["1969.13000000", "0.01660000"], ["1969.12000000", "0.03000000"], ["1969.08000000", "9.04880000"], ["1969.07000000", "13.84110000"], ["1969.06000000", "0.00300000"], ["1969.04000000", "0.00260000"], ["1969.01000000", "1.62360000"], ["1969.00000000", "7.90950000"], ["1968.96000000", "0.00300000"], ["1968.94000000", "0.01370000"], ["1968.90000000", "0.02870000"], ["1968.80000000", "4.29030000"], ["1968.79000000", "13.91130000"], ["1968.66000000", "1.18420000"], ["1968.62000000", "0.00300000"], ["1968.58000000", "10.10990000"], ["1968.51000000", "13.82970000"], ["1968.35000000", "9.71140000"], ["1968.33000000", "0.03310000"], ["1968.23000000", "0.00650000"], ["1968.19000000", "0.64980000"], ["1968.18000000", "0.43850000"], ["1968.05000000", "3.64850000"], ["1967.94000000", "0.22000000"], ["1967.93000000", "0.10150000"], ["1967.77000000", "0.33150000"], ["1967.51000000", "0.90420000"], ["1967.44000000", "0.00000000"], ["1966.41000000", "0.00520000"], ["1966.05000000", "6.45500000"], ["1965.96000000", "7.39330000"], ["1965.87000000", "0.00000000"], ["1964.45000000", "3.60550000"], ["1964.16000000", "0.00300000"], ["1963.85000000", "0.00000000"], ["1963.01000000", "0.00000000"], ["1962.94000000", "0.49220000"], ["1962.36000000", "1.40010000"], ["1962.00000000", "8.83820000"], ["1961.65000000", "69.99860000"], ["1961.44000000", "107.12640000"], ["1960.97000000", "0.03580000"], ["1960.25000000", "236.54050000"], ["1959.53000000", "0.02000000"], ["1959.07000000", "0.02000000"], ["1956.08000000", "0.00390000"], ["1955.73000000", "92.37610000"], ["1922.56000000", "0.00000000"], ["1912.69000000", "0.37460000"], ["1774.67000000", "0.01240000"], ["1582.32000000", "0.04900000"], ["1578.38000000", "0.00000000"], ["1578.24000000", "0.00000000"], ["1578.04000000", "0.00000000"], ["1577.90000000", "0.00000000"], ["1577.89000000", "0.00000000"], ["1577.48000000", "0.16800000"]], "a": [["1971.86000000", "59.09290000"], ["1971.87000000", "0.01030000"], ["1971.88000000", "0.00770000"], ["1971.89000000", "0.00260000"], ["1971.90000000", "0.00830000"], ["1971.92000000", "0.00000000"], ["1971.94000000", "5.61040000"], ["1971.95000000", "4.34200000"], ["1971.96000000", "0.01160000"], ["1971.97000000", "0.00260000"], ["1971.98000000", "0.00000000"], ["1971.99000000", "7.09990000"], ["1972.00000000", "0.03830000"], ["1972.01000000", "0.22940000"], ["1972.02000000", "0.00260000"], ["1972.03000000", "0.56480000"], ["1972.06000000", "0.01160000"], ["1972.07000000", "5.95410000"], ["1972.08000000", "8.52280000"], ["1972.09000000", "0.00000000"], ["1972.10000000", "5.94070000"], ["1972.11000000", "0.01280000"], ["1972.13000000", "21.29970000"], ["1972.14000000", "22.57760000"], ["1972.15000000", "0.00000000"], ["1972.16000000", "0.03000000"], ["1972.17000000", "0.00260000"], ["1972.18000000", "0.00000000"], ["1972.21000000", "1.20550000"], ["1972.23000000", "10.73300000"], ["1972.24000000", "22.03690000"], ["1972.25000000", "14.19980000"], ["1972.26000000", "26.76660000"], ["1972.30000000", "7.39620000"], ["1972.31000000", "0.00000000"], ["1972.32000000", "0.04420000"], ["1972.36000000", "22.57370000"], ["1972.37000000", "1.37320000"], ["1972.38000000", "12.03900000"], ["1972.40000000", "0.00570000"], ["1972.44000000", "0.05900000"], ["1972.45000000", "0.00000000"], ["1972.51000000", "0.00000000"], ["1972.52000000", "13.51970000"], ["1972.55000000", "25.74710000"], ["1972.56000000", "7.87080000"], ["1972.58000000", "0.33000000"], ["1972.64000000", "1.41970000"], ["1972.65000000", "0.03300000"], ["1972.66000000", "0.45900000"], ["1972.73000000", "0.25000000"], ["1972.74000000", "10.90030000"], ["1972.76000000", "7.17620000"], ["1972.80000000", "25.36570000"], ["1972.81000000", "8.30190000"], ["1972.84000000", "0.00000000"], ["1972.86000000", "0.00540000"], ["1972.89000000", "0.10000000"], ["1972.90000000", "12.78730000"], ["1972.97000000", "4.21020000"], ["1973.02000000", "19.86070000"], ["1973.11000000", "0.00000000"], ["1973.13000000", "0.96370000"], ["1973.14000000", "8.82880000"], ["1973.20000000", "26.65040000"], ["1973.21000000", "23.19580000"], ["1973.22000000", "0.00000000"], ["1973.23000000", "8.39250000"], ["1973.25000000", "7.09580000"], ["1973.28000000", "0.03000000"], ["1973.30000000", "0.78870000"], ["1973.35000000", "0.00000000"], ["1973.37000000", "4.88380000"], ["1973.39000000", "0.00000000"], ["1973.40000000", "0.23740000"], ["1973.43000000", "15.43120000"], ["1973.44000000", "3.60000000"], ["1973.45000000", "14.19980000"], ["1973.48000000", "1.21820000"], ["1973.49000000", "0.00000000"], ["1973.61000000", "1.03920000"], ["1973.63000000", "0.00260000"], ["1973.66000000", "0.00260000"], ["1973.68000000", "0.00000000"], ["1973.75000000", "0.00260000"], ["1973.79000000", "10.76590000"], ["1973.95000000", "0.03600000"], ["1974.03000000", "0.51790000"], ["1974.29000000", "13.51710000"], ["1974.32000000", "0.00260000"], ["1974.35000000", "1.25900000"], ["1974.48000000", "0.00000000"], ["1974.57000000", "0.13200000"], ["1974.62000000", "0.00000000"], ["1976.26000000", "0.00000000"], ["1976.87000000", "0.20050000"], ["1977.11000000", "1.51780000"], ["1977.17000000", "0.00000000"], ["1977.23000000", "0.00710000"], ["1977.32000000", "3.60000000"], ["1977.36000000", "0.00680000"], ["1977.82000000", "0.39230000"], ["1977.90000000", "0.94180000"], ["1979.79000000", "0.00000000"], ["1979.91000000", "0.47730000"], ["1980.06000000", "126.41810000"], ["1981.98000000", "0.00300000"], ["1982.60000000", "113.37150000"], ["1983.30000000", "0.00000000"], ["1984.42000000", "0.00000000"], ["1986.78000000", "0.00000000"], ["1989.02000000", "0.00820000"], ["1992.71000000", "0.00550000"], ["1993.75000000", "0.00260000"], ["1996.00000000", "1.71440000"], ["2004.75000000", "0.00380000"], ["2301.10000000", "0.02660000"]], "_local_ts_utc": "2026-06-01T07:49:04.511780+00:00"}
{"e": "depthUpdate", "E": 1780300145715, "s": "ETHUSDT", "U": 76583100671, "u": 76583101123, "b": [["1971.85000000", "0.00000000"], ["1971.84000000", "0.00000000"], ["1971.83000000", "1.59850000"], ["1971.82000000", "0.01040000"], ["1971.76000000", "0.06480000"], ["1971.75000000", "0.00560000"], ["1971.67000000", "0.07450000"], ["1971.65000000", "0.06550000"], ["1971.63000000", "0.01110000"], ["1971.62000000", "0.00000000"], ["1971.59000000", "0.00540000"], ["1971.56000000", "0.00950000"], ["1971.52000000", "0.50730000"], ["1971.51000000", "0.01280000"], ["1971.50000000", "2.35060000"], ["1971.46000000", "0.01670000"], ["1971.44000000", "0.64710000"], ["1971.43000000", "2.59220000"], ["1971.42000000", "0.15850000"], ["1971.40000000", "15.07960000"], ["1971.39000000", "6.46760000"], ["1971.36000000", "0.06560000"], ["1971.35000000", "0.00000000"], ["1971.31000000", "52.41150000"], ["1971.30000000", "0.21960000"], ["1971.29000000", "7.04520000"], ["1971.28000000", "0.00880000"], ["1971.26000000", "0.76850000"], ["1971.25000000", "0.01140000"], ["1971.21000000", "22.71960000"], ["1971.20000000", "13.14900000"], ["1971.19000000", "0.01280000"], ["1971.18000000", "0.00000000"], ["1971.12000000", "7.30440000"], ["1971.10000000", "27.72260000"], ["1971.09000000", "13.15460000"], ["1971.08000000", "8.72250000"], ["1971.07000000", "22.57900000"], ["1971.00000000", "8.18440000"], ["1970.93000000", "0.41730000"], ["1970.89000000", "43.48470000"], ["1970.87000000", "0.82820000"], ["1970.86000000", "23.37760000"], ["1970.85000000", "3.94740000"], ["1970.84000000", "0.00260000"], ["1970.74000000", "0.93540000"], ["1970.72000000", "0.69280000"], ["1970.67000000", "0.63190000"], ["1970.65000000", "4.10570000"], ["1970.64000000", "0.00000000"], ["1970.50000000", "0.04450000"], ["1970.46000000", "0.00390000"], ["1970.38000000", "0.00320000"], ["1970.32000000", "0.47820000"], ["1970.22000000", "1.08260000"], ["1969.96000000", "2.85240000"], ["1969.94000000", "1.73530000"], ["1969.74000000", "0.02710000"], ["1969.72000000", "47.27830000"], ["1969.62000000", "2.77680000"], ["1969.50000000", "22.05610000"], ["1969.35000000", "4.37820000"], ["1969.31000000", "8.12200000"], ["1968.79000000", "13.69130000"], ["1968.24000000", "10.77980000"], ["1968.23000000", "13.52360000"], ["1968.22000000", "0.00260000"], ["1967.94000000", "0.00000000"], ["1967.64000000", "0.27340000"], ["1966.73000000", "0.22760000"], ["1966.12000000", "0.02890000"], ["1965.81000000", "0.00260000"], ["1956.02000000", "3.11130000"], ["1946.13000000", "0.76720000"], ["1928.09000000", "0.00850000"], ["1774.67000000", "0.00000000"], ["1774.66000000", "0.00000000"], ["1774.65000000", "0.06860000"], ["1577.59000000", "0.00000000"], ["1577.57000000", "0.01400000"], ["1577.48000000", "0.17500000"], ["1577.47000000", "0.02800000"]], "a": [["1971.84000000", "79.00820000"], ["1971.85000000", "5.70790000"], ["1971.86000000", "4.29610000"], ["1971.87000000", "1.28220000"], ["1971.88000000", "0.00260000"], ["1971.90000000", "0.00830000"], ["1971.94000000", "0.56660000"], ["1971.95000000", "4.33660000"], ["1971.96000000", "0.01420000"], ["1971.97000000", "0.00000000"], ["1971.98000000", "14.19980000"], ["1971.99000000", "0.00000000"], ["1972.00000000", "7.13560000"], ["1972.01000000", "0.22680000"], ["1972.02000000", "0.00000000"], ["1972.03000000", "0.00000000"], ["1972.07000000", "3.86870000"], ["1972.08000000", "0.00300000"], ["1972.09000000", "8.51990000"], ["1972.10000000", "12.36030000"], ["1972.12000000", "21.29970000"], ["1972.13000000", "0.00000000"], ["1972.15000000", "0.50710000"], ["1972.21000000", "1.20550000"], ["1972.22000000", "13.55010000"], ["1972.23000000", "17.45990000"], ["1972.24000000", "8.51980000"], ["1972.25000000", "14.39980000"], ["1972.43000000", "25.55830000"], ["1972.53000000", "0.10140000"], ["1972.89000000", "0.10000000"], ["1972.97000000", "6.51360000"], ["1973.13000000", "0.16370000"], ["1973.14000000", "2.58130000"], ["1973.19000000", "1.40000000"], ["1973.20000000", "8.91010000"], ["1973.42000000", "0.00260000"], ["1973.43000000", "0.00000000"], ["1973.44000000", "3.63000000"], ["1973.67000000", "0.74510000"], ["1973.68000000", "0.00000000"], ["1974.16000000", "0.00000000"], ["1974.24000000", "0.10260000"], ["1974.35000000", "32.95480000"], ["1974.46000000", "15.56700000"], ["1974.62000000", "0.00000000"], ["1975.23000000", "0.04040000"], ["1975.49000000", "100.85850000"], ["1976.87000000", "0.20050000"], ["1977.03000000", "0.00000000"], ["1978.00000000", "0.00980000"], ["1980.06000000", "0.00000000"], ["1986.67000000", "0.00000000"]], "_local_ts_utc": "2026-06-01T07:49:04.612770+00:00"}
{"e": "depthUpdate", "E": 1780300145815, "s": "ETHUSDT", "U": 76583101124, "u": 76583101370, "b": [["1971.83000000", "44.93300000"], ["1971.82000000", "0.00260000"], ["1971.74000000", "0.01960000"], ["1971.66000000", "0.03940000"], ["1971.65000000", "0.06550000"], ["1971.64000000", "0.01810000"], ["1971.63000000", "6.47870000"], ["1971.61000000", "0.00000000"], ["1971.59000000", "0.00000000"], ["1971.56000000", "0.00410000"], ["1971.55000000", "1.82070000"], ["1971.53000000", "0.00300000"], ["1971.52000000", "8.54990000"], ["1971.50000000", "2.35370000"], ["1971.46000000", "0.01410000"], ["1971.44000000", "0.00000000"], ["1971.43000000", "0.00000000"], ["1971.42000000", "9.06140000"], ["1971.41000000", "29.81960000"], ["1971.39000000", "0.00000000"], ["1971.32000000", "13.53730000"], ["1971.26000000", "0.71820000"], ["1971.19000000", "1.61130000"], ["1971.15000000", "0.40260000"], ["1971.08000000", "8.72250000"], ["1970.97000000", "4.38280000"], ["1970.93000000", "0.81730000"], ["1970.86000000", "22.57760000"], ["1970.80000000", "1.07340000"], ["1970.79000000", "0.00910000"], ["1970.74000000", "0.27000000"], ["1970.57000000", "22.67790000"], ["1970.44000000", "0.00000000"], ["1970.36000000", "0.04050000"], ["1970.26000000", "1.02620000"], ["1970.22000000", "0.98260000"], ["1970.16000000", "0.00270000"], ["1969.97000000", "1.78680000"], ["1969.95000000", "2.02850000"], ["1969.87000000", "21.29970000"], ["1969.70000000", "14.26270000"], ["1969.62000000", "2.73900000"], ["1969.56000000", "6.27790000"], ["1969.50000000", "7.85630000"], ["1969.46000000", "5.81910000"], ["1969.42000000", "16.00470000"], ["1969.31000000", "1.02210000"], ["1969.12000000", "0.00000000"], ["1967.91000000", "20.98260000"], ["1967.90000000", "69.94090000"], ["1967.76000000", "106.84200000"], ["1959.75000000", "90.00770000"], ["1955.84000000", "1.64450000"], ["1950.31000000", "0.14100000"], ["1950.08000000", "0.64680000"], ["1946.13000000", "0.64010000"], ["1934.19000000", "0.63950000"], ["1932.39000000", "0.12910000"], ["1922.35000000", "0.52220000"], ["1912.69000000", "0.24530000"], ["1912.68000000", "0.01890000"], ["1774.65000000", "0.08100000"]], "a": [["1971.84000000", "22.62510000"], ["1971.85000000", "0.01310000"], ["1971.86000000", "0.68700000"], ["1971.87000000", "0.00520000"], ["1971.88000000", "0.00260000"], ["1971.91000000", "0.00260000"], ["1971.93000000", "0.00540000"], ["1971.94000000", "0.57200000"], ["1971.95000000", "4.96600000"], ["1971.96000000", "0.00260000"], ["1971.97000000", "0.00000000"], ["1971.98000000", "0.00000000"], ["1972.00000000", "0.03570000"], ["1972.06000000", "7.09990000"], ["1972.08000000", "6.47060000"], ["1972.09000000", "0.00000000"], ["1972.12000000", "0.00000000"], ["1972.13000000", "14.19980000"], ["1972.15000000", "0.01160000"], ["1972.19000000", "0.67650000"], ["1972.21000000", "7.09990000"], ["1972.22000000", "8.55290000"], ["1972.23000000", "10.53300000"], ["1972.24000000", "0.00000000"], ["1972.25000000", "14.19980000"], ["1972.27000000", "0.00000000"], ["1972.31000000", "0.20000000"], ["1972.51000000", "16.77750000"], ["1972.52000000", "13.51710000"], ["1972.55000000", "10.59530000"], ["1972.89000000", "0.47810000"], ["1973.20000000", "28.71000000"], ["1973.43000000", "7.09990000"], ["1973.44000000", "12.14990000"], ["1973.65000000", "0.00000000"], ["1973.67000000", "7.84500000"], ["1973.68000000", "0.00000000"], ["1973.89000000", "0.00000000"], ["1973.92000000", "0.03000000"], ["1974.35000000", "1.25900000"], ["1974.40000000", "0.03310000"], ["1974.62000000", "13.51710000"], ["1974.97000000", "0.00000000"], ["1975.23000000", "0.59870000"], ["1977.00000000", "0.02240000"], ["1977.59000000", "0.02060000"], ["1977.74000000", "0.13130000"], ["1978.33000000", "0.00610000"], ["1980.06000000", "126.41780000"], ["1995.21000000", "0.02400000"], ["2315.84000000", "0.00380000"]], "_local_ts_utc": "2026-06-01T07:49:04.711412+00:00"}
{"e": "depthUpdate", "E": 1780300145915, "s": "ETHUSDT", "U": 76583101371, "u": 76583101779, "b": [["1971.86000000", "102.52740000"], ["1971.85000000", "4.17810000"], ["1971.84000000", "9.31870000"], ["1971.83000000", "4.64120000"], ["1971.80000000", "0.00520000"], ["1971.78000000", "0.02720000"], ["1971.76000000", "0.07020000"], ["1971.75000000", "1.29140000"], ["1971.74000000", "0.01700000"], ["1971.72000000", "0.00540000"], ["1971.71000000", "22.57370000"], ["1971.70000000", "0.00260000"], ["1971.68000000", "0.04350000"], ["1971.66000000", "0.04330000"], ["1971.64000000", "0.01530000"], ["1971.63000000", "21.31080000"], ["1971.62000000", "8.51990000"], ["1971.60000000", "0.00830000"], ["1971.57000000", "0.71750000"], ["1971.55000000", "1.01840000"], ["1971.54000000", "0.00700000"], ["1971.53000000", "21.30270000"], ["1971.51000000", "22.58650000"], ["1971.50000000", "1.01560000"], ["1971.48000000", "13.53780000"], ["1971.35000000", "0.60840000"], ["1971.26000000", "4.31820000"], ["1971.22000000", "0.00000000"], ["1971.15000000", "1.20260000"], ["1971.09000000", "10.02890000"], ["1971.03000000", "0.00000000"], ["1970.98000000", "1.42200000"], ["1970.93000000", "0.01730000"], ["1970.90000000", "27.81750000"], ["1970.87000000", "27.59320000"], ["1970.85000000", "3.74740000"], ["1970.65000000", "3.60570000"], ["1970.19000000", "7.80340000"], ["1970.15000000", "0.00760000"], ["1970.02000000", "21.43150000"], ["1969.88000000", "7.53080000"], ["1969.87000000", "7.09990000"], ["1969.70000000", "0.06290000"], ["1969.50000000", "0.75640000"], ["1969.30000000", "18.45550000"], ["1969.28000000", "1.21230000"], ["1969.09000000", "0.21430000"], ["1968.24000000", "6.74500000"], ["1968.23000000", "0.00650000"], ["1966.90000000", "0.28610000"], ["1966.83000000", "0.00690000"], ["1966.71000000", "0.00470000"], ["1965.96000000", "7.39070000"], ["1965.70000000", "0.58970000"], ["1962.84000000", "0.00680000"], ["1774.68000000", "0.01240000"], ["1774.65000000", "0.06240000"], ["1577.57000000", "0.00700000"], ["1577.49000000", "0.01400000"]], "a": [["1971.84000000", "0.00000000"], ["1971.85000000", "0.00000000"], ["1971.86000000", "0.00000000"], ["1971.87000000", "0.10520000"], ["1971.90000000", "0.00830000"], ["1971.91000000", "0.00520000"], ["1971.93000000", "0.00800000"], ["1971.94000000", "0.56660000"], ["1971.95000000", "0.00260000"], ["1971.96000000", "0.00260000"], ["1972.00000000", "0.00830000"], ["1972.01000000", "0.00000000"], ["1972.02000000", "0.68860000"], ["1972.03000000", "0.00000000"], ["1972.04000000", "0.00000000"], ["1972.05000000", "0.00000000"], ["1972.06000000", "0.00000000"], ["1972.07000000", "0.00000000"], ["1972.08000000", "0.00300000"], ["1972.09000000", "0.00000000"], ["1972.10000000", "0.00570000"], ["1972.13000000", "0.00000000"], ["1972.14000000", "0.00390000"], ["1972.15000000", "0.00000000"], ["1972.18000000", "0.50710000"], ["1972.19000000", "0.66490000"], ["1972.21000000", "0.00000000"], ["1972.22000000", "0.03300000"], ["1972.23000000", "8.37310000"], ["1972.24000000", "7.09990000"], ["1972.25000000", "7.09990000"], ["1972.26000000", "0.00260000"], ["1972.29000000", "7.11150000"], ["1972.30000000", "11.60000000"], ["1972.31000000", "0.00000000"], ["1972.37000000", "0.87320000"], ["1972.41000000", "25.41690000"], ["1972.42000000", "16.86390000"], ["1972.43000000", "25.65830000"], ["1972.50000000", "0.65620000"], ["1972.52000000", "0.00000000"], ["1972.53000000", "0.00000000"], ["1972.54000000", "0.00390000"], ["1972.56000000", "7.97220000"], ["1972.57000000", "0.00000000"], ["1972.60000000", "22.89110000"], ["1972.70000000", "0.00570000"], ["1972.73000000", "0.00000000"], ["1972.79000000", "13.51710000"], ["1972.80000000", "11.84860000"], ["1972.86000000", "0.00800000"], ["1972.89000000", "0.10000000"], ["1972.95000000", "0.00260000"], ["1973.14000000", "1.01820000"], ["1973.19000000", "0.00000000"], ["1973.26000000", "23.76770000"], ["1973.40000000", "1.03740000"], ["1973.43000000", "20.35310000"], ["1973.61000000", "0.00000000"], ["1973.65000000", "7.09990000"], ["1973.68000000", "15.61980000"], ["1973.87000000", "0.00260000"], ["1973.89000000", "7.09990000"], ["1973.92000000", "0.03000000"], ["1974.11000000", "3.60260000"], ["1974.24000000", "0.13260000"], ["1974.62000000", "0.00000000"], ["1974.86000000", "0.00000000"], ["1976.80000000", "6.31060000"], ["1979.91000000", "0.00000000"], ["1980.72000000", "0.00000000"], ["1981.00000000", "0.03000000"], ["1986.85000000", "0.05780000"]], "_local_ts_utc": "2026-06-01T07:49:04.813197+00:00"}
{"e": "depthUpdate", "E": 1780300146015, "s": "ETHUSDT", "U": 76583101780, "u": 76583101898, "b": [["1971.86000000", "100.86320000"], ["1971.85000000", "0.01060000"], ["1971.84000000", "9.32130000"], ["1971.83000000", "3.37340000"], ["1971.76000000", "0.01300000"], ["1971.73000000", "0.01170000"], ["1971.72000000", "0.00540000"], ["1971.66000000", "0.04330000"], ["1971.64000000", "0.01530000"], ["1971.63000000", "0.26490000"], ["1971.54000000", "15.96320000"], ["1971.48000000", "0.02070000"], ["1971.43000000", "2.53850000"], ["1971.34000000", "0.38200000"], ["1971.30000000", "0.41960000"], ["1971.14000000", "1.93970000"], ["1971.08000000", "8.52250000"], ["1970.99000000", "0.38560000"], ["1970.91000000", "0.42110000"], ["1970.13000000", "21.40730000"], ["1970.00000000", "409.63310000"], ["1969.88000000", "5.41140000"], ["1969.39000000", "0.34800000"], ["1968.58000000", "6.96530000"], ["1968.51000000", "0.31260000"], ["1955.84000000", "1.39150000"], ["1774.68000000", "0.02480000"], ["1472.78000000", "0.00000000"]], "a": [["1971.87000000", "2.46670000"], ["1971.93000000", "0.00260000"], ["1971.94000000", "0.00260000"], ["1972.00000000", "0.00830000"], ["1972.01000000", "0.00000000"], ["1972.02000000", "0.00000000"], ["1972.06000000", "0.00260000"], ["1972.15000000", "0.01160000"], ["1972.19000000", "0.66790000"], ["1972.20000000", "0.11880000"], ["1972.25000000", "7.09990000"], ["1972.26000000", "0.01420000"], ["1972.28000000", "8.51990000"], ["1972.32000000", "0.03260000"], ["1972.39000000", "1.20550000"], ["1972.40000000", "18.13580000"], ["1972.41000000", "13.51710000"], ["1972.54000000", "0.00390000"], ["1972.59000000", "23.08930000"], ["1972.62000000", "2.54870000"], ["1972.80000000", "11.84600000"], ["1973.14000000", "3.54820000"], ["1973.50000000", "0.51300000"], ["1973.61000000", "0.00000000"], ["1973.68000000", "7.09990000"], ["1973.70000000", "3.73000000"], ["1973.73000000", "1.02640000"], ["1973.90000000", "1.20810000"], ["1974.10000000", "0.00000000"], ["1974.30000000", "0.00000000"], ["1975.36000000", "9.37810000"], ["1975.92000000", "0.00000000"], ["1976.15000000", "0.00000000"], ["1976.36000000", "0.00260000"], ["1976.46000000", "0.79440000"], ["1976.60000000", "0.00000000"], ["1976.80000000", "6.30800000"], ["1977.00000000", "0.01930000"], ["1978.65000000", "0.15110000"], ["1982.80000000", "0.01670000"], ["1994.40000000", "0.00260000"], ["2472.79000000", "1.08270000"]], "_local_ts_utc": "2026-06-01T07:49:04.911778+00:00"}
