{"e": "depthUpdate", "E": 1780300146614, "s": "BTCUSDT", "U": 94551786748, "u": 94551787270, "b": [["72710.53000000", "4.43626000"], ["72710.52000000", "0.00024000"], ["72710.08000000", "0.03984000"], ["72709.81000000", "0.13591000"], ["72709.80000000", "0.34342000"], ["72709.79000000", "0.00000000"], ["72709.61000000", "0.07482000"], ["72709.25000000", "0.03663000"], ["72709.24000000", "1.43444000"], ["72709.23000000", "1.11210000"], ["72709.22000000", "0.00000000"], ["72709.03000000", "0.00000000"], ["72708.66000000", "0.05942000"], ["72708.60000000", "0.00000000"], ["72708.59000000", "0.00016000"], ["72708.31000000", "0.00000000"], ["72708.30000000", "0.00016000"], ["72707.90000000", "0.00000000"], ["72707.89000000", "0.00000000"], ["72707.88000000", "0.00000000"], ["72707.76000000", "0.02176000"], ["72706.71000000", "0.00000000"], ["72706.70000000", "0.00016000"], ["72706.68000000", "0.00000000"], ["72706.67000000", "0.12999000"], ["72706.46000000", "0.00000000"], ["72706.36000000", "0.17246000"], ["72706.30000000", "0.00000000"], ["72705.83000000", "0.00000000"], ["72705.82000000", "0.12320000"], ["72705.81000000", "1.13346000"], ["72705.76000000", "0.69630000"], ["72705.46000000", "0.00028000"], ["72705.43000000", "0.27342000"], ["72705.35000000", "0.18191000"], ["72705.33000000", "0.34553000"], ["72705.32000000", "0.10313000"], ["72704.02000000", "0.03407000"], ["72703.66000000", "0.01376000"], ["72701.20000000", "0.00000000"], ["72700.03000000", "0.00000000"], ["72700.02000000", "0.00000000"], ["72700.01000000", "0.40497000"], ["72699.23000000", "0.00000000"], ["72698.87000000", "0.01377000"], ["72698.52000000", "0.00000000"], ["72698.51000000", "0.00000000"], ["72698.47000000", "0.17240000"], ["72697.17000000", "0.00000000"], ["72697.13000000", "0.17240000"], ["72696.06000000", "0.17240000"], ["72695.57000000", "0.02000000"], ["72694.50000000", "0.00000000"], ["72694.45000000", "0.17247000"], ["72693.16000000", "0.00000000"], ["72693.15000000", "0.00000000"], ["72693.11000000", "0.17240000"], ["72693.00000000", "0.01383000"], ["72691.81000000", "0.00000000"], ["72691.77000000", "0.17240000"], ["72690.72000000", "0.17248000"], ["72689.14000000", "0.00000000"], ["72689.13000000", "0.00000000"], ["72689.09000000", "0.17240000"], ["72688.26000000", "0.00000000"], ["72687.83000000", "0.17240000"], ["72687.62000000", "0.17248000"], ["72683.73000000", "0.17238000"], ["72682.44000000", "0.00000000"], ["72682.43000000", "0.00000000"], ["72682.40000000", "0.17240000"], ["72682.18000000", "0.17240000"], ["72680.08000000", "0.17238000"], ["72675.73000000", "0.04663000"], ["72673.22000000", "0.49599000"], ["72670.36000000", "0.00000000"], ["72664.48000000", "0.49605000"], ["72643.20000000", "0.00008000"], ["72639.77000000", "0.00000000"], ["72602.08000000", "0.01373000"], ["72549.45000000", "0.00000000"], ["72506.16000000", "0.00000000"], ["71979.60000000", "0.00007000"], ["71976.96000000", "0.00000000"], ["71422.96000000", "0.00349000"], ["71058.56000000", "0.00351000"], ["65438.31000000", "0.00000000"], ["58167.39000000", "0.00000000"]], "a": [["72709.24000000", "0.00000000"], ["72709.25000000", "0.00000000"], ["72709.26000000", "0.00000000"], ["72709.80000000", "0.00000000"], ["72709.81000000", "0.00000000"], ["72709.82000000", "0.00000000"], ["72710.09000000", "0.00000000"], ["72710.53000000", "0.00000000"], ["72710.54000000", "0.15263000"], ["72710.55000000", "0.00016000"], ["72710.64000000", "0.00000000"], ["72710.67000000", "0.00000000"], ["72710.71000000", "0.00000000"], ["72710.76000000", "0.00008000"], ["72710.77000000", "0.00000000"], ["72711.06000000", "0.04013000"], ["72711.24000000", "0.02016000"], ["72711.45000000", "0.00023000"], ["72711.46000000", "0.00000000"], ["72711.49000000", "0.00000000"], ["72711.79000000", "0.00000000"], ["72711.80000000", "0.00032000"], ["72711.81000000", "0.00000000"], ["72711.84000000", "0.00016000"], ["72711.85000000", "0.04000000"], ["72712.00000000", "0.00000000"], ["72712.01000000", "0.00000000"], ["72712.79000000", "0.00000000"], ["72712.80000000", "0.00024000"], ["72712.81000000", "0.00024000"], ["72712.82000000", "0.50016000"], ["72713.01000000", "0.00000000"], ["72713.58000000", "0.05942000"], ["72713.73000000", "0.00000000"], ["72713.74000000", "0.00008000"], ["72713.90000000", "0.00000000"], ["72714.27000000", "0.00031000"], ["72714.30000000", "0.00016000"], ["72714.53000000", "0.00000000"], ["72714.60000000", "0.00000000"], ["72714.61000000", "0.00000000"], ["72714.66000000", "0.00016000"], ["72715.38000000", "0.65965000"], ["72715.42000000", "0.00000000"], ["72715.47000000", "0.01125000"], ["72715.99000000", "0.00000000"], ["72716.41000000", "0.00031000"], ["72717.32000000", "0.00000000"], ["72718.65000000", "0.00000000"], ["72718.90000000", "0.15795000"], ["72718.92000000", "0.00008000"], ["72720.32000000", "0.00007000"], ["72720.64000000", "0.17248000"], ["72720.65000000", "0.56785000"], ["72721.99000000", "0.00000000"], ["72722.79000000", "0.00007000"], ["72724.99000000", "0.17257000"], ["72725.01000000", "0.00000000"], ["72726.62000000", "0.17240000"], ["72727.46000000", "0.00000000"], ["72727.82000000", "0.17240000"], ["72744.27000000", "0.00000000"], ["72771.23000000", "0.20942000"], ["72773.92000000", "0.49530000"], ["73431.06000000", "0.00000000"], ["73433.75000000", "0.00007000"], ["73596.49000000", "0.00010000"]], "_local_ts_utc": "2026-06-01T07:49:05.511366+00:00"}
{"e": "depthUpdate", "E": 1780300146714, "s": "BTCUSDT", "U": 94551787271, "u": 94551787439, "b": [["72710.53000000", "4.43314000"], ["72710.09000000", "0.00016000"], ["72710.08000000", "0.04000000"], ["72709.82000000", "0.00016000"], ["72709.81000000", "0.13607000"], ["72709.80000000", "0.17183000"], ["72709.62000000", "0.00016000"], ["72709.61000000", "0.07498000"], ["72709.25000000", "0.03679000"], ["72709.24000000", "1.31091000"], ["72709.23000000", "1.11202000"], ["72708.66000000", "0.05950000"], ["72708.59000000", "0.00000000"], ["72708.30000000", "0.00000000"], ["72707.78000000", "0.00929000"], ["72707.76000000", "0.02160000"], ["72706.70000000", "0.00000000"], ["72706.69000000", "0.00000000"], ["72705.82000000", "0.12328000"], ["72704.01000000", "0.00008000"], ["72701.46000000", "0.00007000"], ["72700.98000000", "0.00000000"], ["72700.76000000", "0.00000000"], ["72700.02000000", "0.40840000"], ["72700.01000000", "0.17303000"], ["72698.01000000", "0.00008000"], ["72693.81000000", "0.00008000"], ["72693.80000000", "0.30486000"], ["72691.69000000", "0.00000000"], ["72688.76000000", "0.00020000"], ["72687.62000000", "0.00008000"], ["72685.25000000", "0.00000000"], ["72683.73000000", "0.00000000"], ["72682.40000000", "0.00000000"], ["72682.18000000", "0.00000000"], ["72682.12000000", "0.00000000"], ["72681.44000000", "0.01371000"], ["72680.08000000", "0.00000000"], ["72680.01000000", "0.00323000"], ["72675.21000000", "0.35191000"], ["72672.40000000", "0.00000000"], ["72643.21000000", "0.05940000"], ["72635.11000000", "0.00357000"], ["72595.13000000", "0.00031000"], ["72548.45000000", "0.09874000"], ["72544.59000000", "0.10000000"], ["72537.32000000", "0.01498000"], ["72508.24000000", "0.10000000"], ["72505.43000000", "0.00009000"], ["72471.88000000", "0.10000000"], ["72173.63000000", "0.02415000"], ["72001.42000000", "0.00346000"], ["71787.36000000", "0.01041000"], ["71764.01000000", "0.00347000"], ["65439.48000000", "0.00034000"]], "a": [["72710.54000000", "0.15263000"], ["72711.05000000", "0.00016000"], ["72711.06000000", "0.04029000"], ["72711.24000000", "0.02016000"], ["72711.45000000", "0.00007000"], ["72711.80000000", "0.00000000"], ["72711.84000000", "0.00000000"], ["72711.85000000", "0.00016000"], ["72712.74000000", "0.00000000"], ["72712.80000000", "0.00016000"], ["72712.81000000", "0.36875000"], ["72712.82000000", "0.50016000"], ["72713.57000000", "0.00008000"], ["72713.58000000", "0.05958000"], ["72714.27000000", "0.00000000"], ["72714.30000000", "0.00000000"], ["72714.66000000", "0.00000000"], ["72715.16000000", "0.00031000"], ["72715.24000000", "0.00031000"], ["72715.38000000", "0.65965000"], ["72715.40000000", "0.04000000"], ["72715.47000000", "0.01141000"], ["72717.24000000", "0.17238000"], ["72717.44000000", "0.08016000"], ["72718.58000000", "0.16063000"], ["72720.65000000", "1.31630000"], ["72722.00000000", "0.17238000"], ["72722.01000000", "2.75065000"], ["72724.99000000", "0.00017000"], ["72734.95000000", "0.00000000"], ["72739.63000000", "0.01371000"], ["72785.55000000", "0.00000000"], ["78827.63000000", "0.00111000"]], "_local_ts_utc": "2026-06-01T07:49:05.610494+00:00"}
{"e": "depthUpdate", "E": 1780300146814, "s": "BTCUSDT", "U": 94551787440, "u": 94551787591, "b": [["72710.53000000", "4.08451000"], ["72710.52000000", "0.00024000"], ["72710.12000000", "0.00000000"], ["72710.11000000", "0.00000000"], ["72709.81000000", "0.13591000"], ["72709.80000000", "0.00016000"], ["72709.62000000", "0.00000000"], ["72709.61000000", "0.00016000"], ["72709.58000000", "0.00016000"], ["72709.57000000", "0.07033000"], ["72709.26000000", "0.00000000"], ["72709.25000000", "0.00032000"], ["72709.24000000", "0.98882000"], ["72708.66000000", "0.05950000"], ["72706.36000000", "0.00000000"], ["72704.02000000", "0.00000000"], ["72700.04000000", "0.43310000"], ["72700.03000000", "0.65949000"], ["72700.02000000", "0.00000000"], ["72700.01000000", "0.00063000"], ["72698.87000000", "0.00000000"], ["72698.47000000", "0.00000000"], ["72696.94000000", "0.00008000"], ["72694.45000000", "0.00007000"], ["72693.11000000", "0.00000000"], ["72690.96000000", "0.12056000"], ["72687.83000000", "0.00000000"], ["72687.66000000", "0.05022000"], ["72675.42000000", "0.00000000"], ["72624.80000000", "0.00008000"], ["72173.63000000", "0.02070000"], ["72003.95000000", "0.00346000"], ["71982.13000000", "0.00007000"], ["71979.60000000", "0.00000000"], ["71933.12000000", "0.01038000"], ["71619.87000000", "0.00696000"], ["70694.15000000", "0.00714000"], ["65439.48000000", "0.00094000"]], "a": [["72710.54000000", "0.15263000"], ["72711.04000000", "0.00016000"], ["72711.05000000", "0.01832000"], ["72711.24000000", "0.02016000"], ["72711.85000000", "0.00000000"], ["72712.79000000", "0.00016000"], ["72712.80000000", "0.17254000"], ["72712.81000000", "0.36875000"], ["72712.84000000", "0.00000000"], ["72713.57000000", "0.00000000"], ["72714.33000000", "0.00031000"], ["72714.56000000", "0.17238000"], ["72715.24000000", "0.00000000"], ["72715.37000000", "0.17238000"], ["72715.38000000", "0.65965000"], ["72715.39000000", "0.00000000"], ["72715.40000000", "0.00016000"], ["72715.42000000", "0.01183000"], ["72715.47000000", "0.00016000"], ["72716.41000000", "0.00000000"], ["72716.74000000", "0.04000000"], ["72717.44000000", "0.08000000"], ["72727.84000000", "2.75065000"], ["72736.83000000", "0.00200000"], ["72743.17000000", "0.00000000"], ["72753.45000000", "0.00434000"], ["72830.88000000", "0.00000000"], ["73433.75000000", "0.00000000"], ["73436.34000000", "0.00007000"]], "_local_ts_utc": "2026-06-01T07:49:05.710273+00:00"}
{"e": "depthUpdate", "E": 1780300146914, "s": "BTCUSDT", "U": 94551787592, "u": 94551787776, "b": [["72710.53000000", "3.54580000"], ["72710.52000000", "0.00080000"], ["72710.13000000", "0.00000000"], ["72710.12000000", "0.00000000"], ["72709.81000000", "0.13591000"], ["72709.80000000", "0.00000000"], ["72709.61000000", "0.00000000"], ["72709.58000000", "0.00000000"], ["72709.57000000", "0.00016000"], ["72709.26000000", "0.00016000"], ["72709.25000000", "0.00016000"], ["72709.24000000", "0.04723000"], ["72709.23000000", "1.03183000"], ["72708.66000000", "0.00016000"], ["72708.31000000", "0.00031000"], ["72708.13000000", "0.03214000"], ["72707.78000000", "0.00945000"], ["72707.76000000", "0.02168000"], ["72706.67000000", "0.12259000"], ["72705.77000000", "0.00019000"], ["72705.67000000", "0.05942000"], ["72700.72000000", "0.00048000"], ["72700.15000000", "0.00048000"], ["72700.05000000", "0.65949000"], ["72700.04000000", "0.23213000"], ["72700.03000000", "0.00000000"], ["72697.13000000", "0.00000000"], ["72696.07000000", "0.65949000"], ["72696.06000000", "0.00000000"], ["72696.05000000", "0.45636000"], ["72696.04000000", "0.40856000"], ["72695.57000000", "0.00000000"], ["72692.06000000", "0.00000000"], ["72691.77000000", "0.00000000"], ["72690.72000000", "0.00008000"], ["72689.09000000", "0.00000000"], ["72687.46000000", "0.02000000"], ["72683.45000000", "0.00200000"], ["72675.87000000", "0.00000000"], ["72675.21000000", "0.23374000"], ["72673.98000000", "0.02734000"], ["72673.22000000", "0.00000000"], ["72649.46000000", "0.49615000"], ["71983.42000000", "0.00007000"], ["71982.13000000", "0.00000000"], ["65439.48000000", "0.00119000"], ["65439.00000000", "0.00000000"]], "a": [["72710.54000000", "2.50036000"], ["72711.05000000", "0.06766000"], ["72711.24000000", "0.02016000"], ["72711.88000000", "0.17238000"], ["72711.92000000", "0.00031000"], ["72712.79000000", "0.00000000"], ["72712.80000000", "0.17254000"], ["72713.23000000", "0.00031000"], ["72713.58000000", "0.00016000"], ["72714.33000000", "0.00000000"], ["72714.56000000", "0.17254000"], ["72715.16000000", "0.00000000"], ["72715.38000000", "0.65949000"], ["72715.39000000", "0.00000000"], ["72715.40000000", "0.00000000"], ["72715.42000000", "0.00000000"], ["72715.47000000", "0.00000000"], ["72715.56000000", "0.04605000"], ["72716.71000000", "0.04000000"], ["72716.74000000", "0.00000000"], ["72723.49000000", "0.01289000"], ["72734.04000000", "0.00000000"], ["72741.63000000", "0.00200000"], ["72748.41000000", "0.02725000"], ["72751.07000000", "0.10000000"], ["72854.78000000", "0.02154000"], ["72891.65000000", "0.00000000"], ["73436.34000000", "0.00000000"], ["73437.65000000", "0.00007000"], ["73801.20000000", "0.02652000"], ["73971.16000000", "0.00031000"]], "_local_ts_utc": "2026-06-01T07:49:05.810398+00:00"}
{"e": "depthUpdate", "E": 1780300147014, "s": "BTCUSDT", "U": 94551787777, "u": 94551787955, "b": [["72710.53000000", "2.33847000"], ["72710.52000000", "0.00080000"], ["72709.81000000", "0.13591000"], ["72709.57000000", "0.00000000"], ["72709.26000000", "0.00000000"], ["72709.24000000", "0.04731000"], ["72709.23000000", "0.17086000"], ["72708.66000000", "0.00000000"], ["72708.31000000", "0.00000000"], ["72708.14000000", "0.00008000"], ["72708.13000000", "0.03230000"], ["72707.76000000", "0.02176000"], ["72706.88000000", "0.00031000"], ["72706.68000000", "0.00008000"], ["72706.67000000", "0.08267000"], ["72706.50000000", "0.00000000"], ["72705.82000000", "0.00008000"], ["72705.81000000", "0.15889000"], ["72705.77000000", "0.00000000"], ["72705.76000000", "0.65630000"], ["72705.67000000", "0.00000000"], ["72705.46000000", "0.00000000"], ["72705.33000000", "0.00000000"], ["72704.00000000", "0.85914000"], ["72703.25000000", "0.00300000"], ["72702.64000000", "0.00000000"], ["72702.25000000", "0.00020000"], ["72700.95000000", "0.05942000"], ["72700.49000000", "0.00000000"], ["72700.06000000", "0.23213000"], ["72700.05000000", "0.00000000"], ["72700.04000000", "0.00000000"], ["72698.26000000", "0.00000000"], ["72697.44000000", "0.15993000"], ["72696.51000000", "0.00000000"], ["72696.09000000", "0.70357000"], ["72696.08000000", "0.65949000"], ["72696.07000000", "0.00000000"], ["72696.05000000", "0.00008000"], ["72696.04000000", "0.00000000"], ["72691.77000000", "0.17238000"], ["72690.72000000", "0.94476000"], ["72689.09000000", "0.17238000"], ["72687.83000000", "0.17238000"], ["72687.46000000", "0.00000000"], ["72683.45000000", "0.02200000"], ["72682.40000000", "0.17238000"], ["72682.18000000", "0.16721000"], ["72677.50000000", "0.00199000"], ["72672.39000000", "1.26563000"], ["72672.38000000", "0.00000000"], ["72666.39000000", "0.00000000"], ["72656.97000000", "0.02000000"], ["72643.31000000", "0.20764000"], ["72643.30000000", "0.49619000"], ["72643.21000000", "0.00000000"], ["72602.31000000", "0.00000000"], ["72602.13000000", "4.13731000"], ["72599.61000000", "0.00145000"], ["72520.94000000", "0.00822000"], ["72501.01000000", "0.00000000"], ["65439.48000000", "0.00153000"], ["58168.43000000", "0.00034000"]], "a": [["72710.54000000", "3.58449000"], ["72711.04000000", "0.00000000"], ["72711.05000000", "0.06750000"], ["72711.23000000", "0.00000000"], ["72711.24000000", "0.02016000"], ["72711.88000000", "0.17254000"], ["72712.82000000", "0.50016000"], ["72713.57000000", "0.00688000"], ["72713.58000000", "0.00000000"], ["72714.58000000", "0.00000000"], ["72714.94000000", "0.00000000"], ["72715.55000000", "0.00688000"], ["72715.77000000", "0.00754000"], ["72715.85000000", "0.03407000"], ["72716.69000000", "0.04000000"], ["72716.71000000", "0.00000000"], ["72718.71000000", "0.00000000"], ["72723.59000000", "0.56458000"], ["72723.94000000", "0.17238000"], ["72724.99000000", "0.15508000"], ["72726.49000000", "0.08200000"], ["72727.00000000", "0.68852000"], ["72727.81000000", "0.45885000"], ["72732.00000000", "0.00199000"], ["72733.90000000", "0.00000000"], ["72743.41000000", "1.36266000"], ["72748.41000000", "0.03770000"], ["72748.64000000", "0.49547000"], ["72748.97000000", "1.03920000"], ["72771.23000000", "0.07060000"], ["72773.92000000", "0.00000000"], ["72781.94000000", "1.46980000"], ["72783.15000000", "0.00000000"], ["72802.30000000", "0.00021000"], ["72854.78000000", "0.00000000"], ["72862.31000000", "0.02155000"], ["72893.28000000", "0.00000000"], ["72938.82000000", "0.00000000"], ["79155.75000000", "0.00038000"]], "_local_ts_utc": "2026-06-01T07:49:05.911760+00:00"}
{"e": "depthUpdate", "E": 1780300147114, "s": "BTCUSDT", "U": 94551787956, "u": 94551788077, "b": [["72710.53000000", "1.64437000"], ["72710.14000000", "0.00000000"], ["72710.08000000", "0.00016000"], ["72709.81000000", "0.00016000"], ["72709.49000000", "0.00000000"], ["72709.24000000", "0.04731000"], ["72708.66000000", "0.00000000"], ["72708.14000000", "0.00000000"], ["72708.13000000", "0.00016000"], ["72707.23000000", "0.02558000"], ["72706.88000000", "0.00000000"], ["72706.81000000", "0.00031000"], ["72706.67000000", "0.08275000"], ["72705.42000000", "0.00000000"], ["72705.33000000", "0.00000000"], ["72703.66000000", "0.00000000"], ["72703.21000000", "0.00000000"], ["72702.25000000", "0.00000000"], ["72700.95000000", "0.00000000"], ["72700.06000000", "0.00000000"], ["72698.47000000", "0.00000000"], ["72697.44000000", "0.00300000"], ["72697.13000000", "0.00000000"], ["72696.09000000", "0.53119000"], ["72696.08000000", "0.00000000"], ["72694.45000000", "0.00007000"], ["72693.11000000", "0.00000000"], ["72691.78000000", "0.65949000"], ["72691.68000000", "0.00000000"], ["72690.72000000", "0.00008000"], ["72689.09000000", "0.00000000"], ["72687.83000000", "0.00000000"], ["72687.67000000", "0.00000000"], ["72687.61000000", "0.00000000"], ["72682.40000000", "0.00000000"], ["72682.18000000", "0.00000000"], ["72654.58000000", "0.02000000"], ["72653.86000000", "0.02000000"], ["72602.14000000", "2.75063000"], ["65439.48000000", "0.00187000"]], "a": [["72710.54000000", "3.66394000"], ["72711.04000000", "0.00000000"], ["72711.05000000", "0.06750000"], ["72711.23000000", "0.00000000"], ["72711.55000000", "0.00008000"], ["72711.87000000", "0.00000000"], ["72712.79000000", "0.00000000"], ["72712.82000000", "0.50016000"], ["72713.57000000", "0.00704000"], ["72713.73000000", "0.04809000"], ["72714.56000000", "0.17238000"], ["72715.56000000", "0.00000000"], ["72716.69000000", "0.00000000"], ["72716.70000000", "0.04000000"], ["72723.58000000", "0.17238000"], ["72723.94000000", "0.00000000"], ["72724.99000000", "0.16077000"], ["72726.62000000", "0.17238000"], ["72727.80000000", "0.17238000"], ["72727.82000000", "0.00000000"], ["72728.74000000", "0.05400000"], ["72729.49000000", "0.05400000"], ["72731.52000000", "0.00008000"], ["72737.67000000", "0.00200000"], ["72741.76000000", "0.00000000"], ["72743.41000000", "0.00000000"], ["72782.46000000", "0.00000000"], ["72790.78000000", "2.13270000"], ["72790.79000000", "4.12659000"], ["72792.02000000", "0.00000000"], ["72827.20000000", "0.00000000"]], "_local_ts_utc": "2026-06-01T07:49:06.010580+00:00"}
{"e": "depthUpdate", "E": 1780300147214, "s": "BTCUSDT", "U": 94551788078, "u": 94551788499, "b": [["72710.53000000", "0.02831000"], ["72710.43000000", "0.00000000"], ["72710.09000000", "0.00000000"], ["72710.08000000", "0.00000000"], ["72709.82000000", "0.00000000"], ["72709.81000000", "0.00000000"], ["72709.25000000", "0.00000000"], ["72709.24000000", "0.00016000"], ["72709.23000000", "0.00016000"], ["72708.13000000", "0.00000000"], ["72707.77000000", "0.00016000"], ["72707.76000000", "0.02176000"], ["72707.24000000", "0.00016000"], ["72707.23000000", "0.02574000"], ["72706.89000000", "0.00000000"], ["72706.81000000", "0.00000000"], ["72706.68000000", "0.00016000"], ["72706.67000000", "0.03130000"], ["72705.90000000", "0.00000000"], ["72705.82000000", "0.00024000"], ["72705.81000000", "0.10905000"], ["72705.77000000", "0.00008000"], ["72705.76000000", "0.28993000"], ["72705.60000000", "0.00000000"], ["72705.43000000", "0.11045000"], ["72705.35000000", "0.00000000"], ["72705.33000000", "0.00000000"], ["72704.00000000", "0.80914000"], ["72702.82000000", "0.00000000"], ["72702.19000000", "0.00031000"], ["72702.09000000", "0.00000000"], ["72701.15000000", "0.00000000"], ["72700.97000000", "0.00000000"], ["72700.01000000", "0.00063000"], ["72699.81000000", "0.00000000"], ["72699.17000000", "0.00000000"], ["72698.47000000", "0.00000000"], ["72698.36000000", "0.00000000"], ["72698.29000000", "0.00028000"], ["72698.11000000", "0.00000000"], ["72697.74000000", "0.00000000"], ["72697.13000000", "0.00000000"], ["72696.12000000", "0.51903000"], ["72696.11000000", "0.00000000"], ["72696.10000000", "0.00000000"], ["72696.09000000", "0.00000000"], ["72694.68000000", "0.00000000"], ["72694.45000000", "0.00007000"], ["72693.80000000", "0.03219000"], ["72693.37000000", "0.00008000"], ["72693.20000000", "0.00007000"], ["72693.11000000", "0.00000000"], ["72691.79000000", "0.65949000"], ["72691.78000000", "0.00000000"], ["72691.77000000", "0.00000000"], ["72690.96000000", "0.00000000"], ["72690.72000000", "0.00008000"], ["72690.71000000", "0.18637000"], ["72689.09000000", "0.00000000"], ["72689.01000000", "0.00165000"], ["72688.83000000", "0.00000000"], ["72688.76000000", "0.00020000"], ["72688.75000000", "0.00000000"], ["72687.84000000", "0.17238000"], ["72687.83000000", "0.40856000"], ["72687.82000000", "0.00000000"], ["72687.53000000", "0.00000000"], ["72686.56000000", "0.00112000"], ["72686.41000000", "0.17238000"], ["72686.03000000", "0.06000000"], ["72685.97000000", "0.65949000"], ["72685.55000000", "0.00000000"], ["72685.54000000", "0.07828000"], ["72685.53000000", "0.15000000"], ["72685.50000000", "0.00939000"], ["72685.29000000", "0.00000000"], ["72685.24000000", "0.00000000"], ["72684.13000000", "0.17012000"], ["72683.73000000", "0.17238000"], ["72683.59000000", "0.00626000"], ["72683.06000000", "0.00000000"], ["72683.05000000", "0.65949000"], ["72682.86000000", "0.00000000"], ["72682.40000000", "0.00000000"], ["72682.18000000", "0.00000000"], ["72682.17000000", "0.00000000"], ["72682.12000000", "0.17238000"], ["72681.44000000", "0.00686000"], ["72680.17000000", "0.16981000"], ["72680.09000000", "0.17238000"], ["72680.08000000", "3.81868000"], ["72680.07000000", "0.00000000"], ["72680.02000000", "0.00000000"], ["72679.94000000", "0.12057000"], ["72678.99000000", "0.00185000"], ["72678.01000000", "0.32979000"], ["72677.72000000", "0.00000000"], ["72676.01000000", "0.06799000"], ["72675.21000000", "0.00000000"], ["72673.32000000", "0.00000000"], ["72672.41000000", "0.17238000"], ["72672.40000000", "0.65949000"], ["72671.28000000", "0.00000000"], ["72670.33000000", "0.15850000"], ["72669.29000000", "0.17975000"], ["72669.28000000", "3.41012000"], ["72669.27000000", "0.00000000"], ["72669.24000000", "0.00000000"], ["72666.90000000", "0.00685000"], ["72664.56000000", "0.65949000"], ["72664.54000000", "0.00000000"], ["72660.94000000", "0.05399000"], ["72658.27000000", "0.17238000"], ["72657.61000000", "0.17238000"], ["72656.83000000", "0.00000000"], ["72656.43000000", "0.03664000"], ["72654.87000000", "0.00000000"], ["72654.51000000", "0.00018000"], ["72652.62000000", "0.00000000"], ["72634.89000000", "0.45626000"], ["72634.33000000", "1.42743000"], ["72634.31000000", "0.00000000"], ["72633.45000000", "0.02704000"], ["72631.77000000", "0.27575000"], ["72611.04000000", "0.65949000"], ["72610.84000000", "2.03743000"], ["72602.15000000", "2.75063000"], ["72602.14000000", "0.00000000"], ["72599.61000000", "0.00008000"], ["72592.58000000", "0.00137000"], ["72590.51000000", "0.00000000"], ["72581.83000000", "0.00000000"], ["72514.73000000", "0.00007000"], ["72510.53000000", "0.00000000"], ["71933.12000000", "0.00692000"], ["71787.36000000", "0.00694000"], ["70892.77000000", "0.00352000"], ["65439.48000000", "0.00221000"], ["58168.43000000", "0.00000000"]], "a": [["72710.54000000", "4.49407000"], ["72710.62000000", "0.03407000"], ["72710.76000000", "0.00000000"], ["72710.88000000", "0.00000000"], ["72711.04000000", "0.00008000"], ["72711.39000000", "0.00751000"], ["72711.86000000", "0.16981000"], ["72711.87000000", "0.00008000"], ["72712.80000000", "0.00016000"], ["72712.81000000", "1.25277000"], ["72713.57000000", "0.00016000"], ["72713.72000000", "0.00008000"], ["72713.99000000", "0.00000000"], ["72714.50000000", "0.16981000"], ["72714.55000000", "0.00008000"], ["72715.03000000", "0.00750000"], ["72715.36000000", "0.00000000"], ["72715.37000000", "0.00008000"], ["72715.55000000", "0.00000000"], ["72716.70000000", "0.00000000"], ["72717.14000000", "0.16981000"], ["72717.23000000", "0.00008000"], ["72717.44000000", "0.00000000"], ["72717.67000000", "0.00008000"], ["72717.70000000", "0.00000000"], ["72717.88000000", "0.00000000"], ["72718.11000000", "0.04000000"], ["72718.43000000", "0.00000000"], ["72718.57000000", "0.00008000"], ["72718.90000000", "0.15803000"], ["72719.76000000", "0.00000000"], ["72720.63000000", "0.00008000"], ["72720.64000000", "0.86103000"], ["72721.98000000", "0.17246000"], ["72721.99000000", "2.75063000"], ["72722.00000000", "0.00000000"], ["72722.01000000", "0.00000000"], ["72722.07000000", "0.00008000"], ["72722.29000000", "0.00007000"], ["72723.33000000", "0.00008000"], ["72723.58000000", "0.17246000"], ["72723.60000000", "0.00000000"], ["72725.77000000", "0.00008000"], ["72726.38000000", "0.16981000"], ["72726.61000000", "0.00008000"], ["72726.86000000", "0.00000000"], ["72726.99000000", "0.00008000"], ["72727.00000000", "0.00000000"], ["72727.48000000", "0.00000000"], ["72727.80000000", "0.17246000"], ["72727.83000000", "1.71133000"], ["72727.85000000", "0.00000000"], ["72727.99000000", "0.00008000"], ["72728.51000000", "0.00008000"], ["72729.97000000", "0.00000000"], ["72730.39000000", "0.00008000"], ["72731.58000000", "0.00000000"], ["72733.32000000", "0.00000000"], ["72733.35000000", "0.00000000"], ["72733.90000000", "0.00000000"], ["72734.78000000", "0.00008000"], ["72734.81000000", "0.00008000"], ["72736.05000000", "0.23247000"], ["72736.36000000", "0.00000000"], ["72736.99000000", "0.00000000"], ["72737.02000000", "0.00008000"], ["72737.03000000", "2.75057000"], ["72738.28000000", "0.00000000"], ["72738.50000000", "0.60004000"], ["72739.17000000", "0.43387000"], ["72740.99000000", "0.00008000"], ["72741.23000000", "0.00000000"], ["72741.98000000", "0.00000000"], ["72743.08000000", "1.36266000"], ["72745.53000000", "0.18098000"], ["72748.97000000", "0.00000000"], ["72753.81000000", "0.00000000"], ["72754.47000000", "0.00000000"], ["72757.85000000", "0.00000000"], ["72761.64000000", "0.00000000"], ["72761.87000000", "0.00000000"], ["72764.09000000", "0.18453000"], ["72768.69000000", "1.32841000"], ["72790.78000000", "0.07986000"], ["72790.79000000", "0.00000000"], ["72792.03000000", "0.00000000"], ["72803.44000000", "0.00939000"], ["72805.91000000", "0.12028000"], ["72805.92000000", "0.00000000"], ["72836.69000000", "0.00000000"], ["72851.36000000", "0.00185000"], ["72885.25000000", "0.00000000"], ["72937.25000000", "0.00626000"], ["72965.11000000", "0.00000000"]], "_local_ts_utc": "2026-06-01T07:49:06.110582+00:00"}
{"e": "depthUpdate", "E": 1780300147314, "s": "BTCUSDT", "U": 94551788500, "u": 94551788728, "b": [["72710.53000000", "0.23082000"], ["72710.52000000", "0.00080000"], ["72709.24000000", "0.00000000"], ["72709.23000000", "0.00000000"], ["72707.24000000", "0.00000000"], ["72707.23000000", "0.00016000"], ["72706.13000000", "0.01329000"], ["72705.77000000", "0.00016000"], ["72705.59000000", "0.00000000"], ["72705.44000000", "0.00008000"], ["72705.43000000", "0.11061000"], ["72705.32000000", "0.10329000"], ["72705.06000000", "0.00031000"], ["72704.53000000", "0.00031000"], ["72704.01000000", "0.22038000"], ["72704.00000000", "0.62771000"], ["72703.42000000", "0.00000000"], ["72702.85000000", "0.00029000"], ["72702.19000000", "0.00000000"], ["72700.01000000", "0.21421000"], ["72697.83000000", "0.16637000"], ["72697.02000000", "0.00020000"], ["72696.12000000", "0.31600000"], ["72694.78000000", "0.05942000"], ["72693.80000000", "0.03219000"], ["72691.79000000", "0.00000000"], ["72690.73000000", "0.16981000"], ["72690.71000000", "0.26518000"], ["72689.41000000", "0.16981000"], ["72688.09000000", "0.16981000"], ["72685.98000000", "0.37742000"], ["72685.54000000", "0.00000000"], ["72682.11000000", "1.94535000"], ["72676.01000000", "0.24988000"], ["72675.73000000", "0.02000000"], ["72673.99000000", "0.63848000"], ["72670.33000000", "0.00000000"], ["72666.90000000", "0.00000000"], ["72661.36000000", "0.00343000"], ["72660.94000000", "0.09854000"], ["72655.25000000", "0.02000000"], ["72655.12000000", "0.02000000"], ["72654.95000000", "0.02000000"], ["72653.50000000", "0.92230000"], ["72653.49000000", "0.00000000"], ["72652.67000000", "0.02276000"], ["72652.56000000", "0.00000000"], ["72650.77000000", "1.19742000"], ["72649.02000000", "0.00000000"], ["72648.81000000", "0.00000000"], ["72647.11000000", "0.00000000"], ["72647.01000000", "1.32116000"], ["72645.95000000", "0.00000000"], ["72644.47000000", "1.04069000"], ["72610.84000000", "0.00000000"], ["72592.58000000", "0.00000000"], ["72592.25000000", "0.00137000"], ["72588.48000000", "0.00137000"], ["72543.91000000", "0.00000000"], ["72520.94000000", "0.00000000"], ["72511.11000000", "0.00822000"], ["71933.12000000", "0.00346000"], ["71787.36000000", "0.00347000"], ["71618.23000000", "0.00348000"], ["71422.96000000", "0.00000000"], ["71058.56000000", "0.00000000"], ["65439.48000000", "0.00255000"], ["58168.42000000", "0.00000000"]], "a": [["72710.54000000", "4.44643000"], ["72710.62000000", "0.03423000"], ["72711.05000000", "0.11419000"], ["72711.24000000", "0.02016000"], ["72711.39000000", "0.00767000"], ["72711.55000000", "0.00008000"], ["72711.61000000", "0.06429000"], ["72711.86000000", "0.16997000"], ["72711.88000000", "0.17254000"], ["72712.79000000", "0.00688000"], ["72712.80000000", "0.00000000"], ["72712.81000000", "0.36875000"], ["72712.82000000", "0.50000000"], ["72713.57000000", "0.00000000"], ["72713.73000000", "0.00000000"], ["72720.64000000", "0.17248000"], ["72723.33000000", "0.68862000"], ["72723.59000000", "0.40802000"], ["72724.34000000", "0.00008000"], ["72724.70000000", "0.08000000"], ["72725.08000000", "0.08600000"], ["72725.12000000", "0.07400000"], ["72727.72000000", "0.06200000"], ["72736.83000000", "0.00000000"], ["72738.50000000", "0.88810000"], ["72740.48000000", "0.02724000"], ["72740.72000000", "1.03931000"], ["72748.41000000", "0.01045000"], ["72762.99000000", "0.00000000"], ["72767.19000000", "0.00189000"], ["72784.49000000", "0.18446000"], ["72784.50000000", "0.00000000"], ["72784.51000000", "0.00000000"], ["72785.48000000", "0.00000000"], ["72786.98000000", "0.00000000"], ["72789.99000000", "0.03802000"], ["72790.78000000", "0.00000000"], ["72792.04000000", "0.01650000"], ["72795.47000000", "0.00000000"], ["72800.43000000", "0.00000000"], ["72803.08000000", "0.00000000"], ["72835.82000000", "0.00000000"], ["72839.64000000", "0.00075000"], ["72970.33000000", "0.00000000"]], "_local_ts_utc": "2026-06-01T07:49:06.210399+00:00"}
{"e": "depthUpdate", "E": 1780300147414, "s": "BTCUSDT", "U": 94551788729, "u": 94551788907, "b": [["72710.53000000", "0.75781000"], ["72710.52000000", "0.00088000"], ["72708.10000000", "0.00031000"], ["72707.76000000", "0.02176000"], ["72707.62000000", "0.00031000"], ["72707.23000000", "0.00000000"], ["72706.67000000", "0.03130000"], ["72706.21000000", "0.00000000"], ["72706.19000000", "0.01445000"], ["72706.14000000", "0.00016000"], ["72706.13000000", "0.00016000"], ["72705.83000000", "0.00016000"], ["72705.82000000", "0.15248000"], ["72705.77000000", "0.00000000"], ["72705.58000000", "0.00028000"], ["72705.44000000", "0.00000000"], ["72705.32000000", "0.10329000"], ["72705.06000000", "0.00000000"], ["72704.53000000", "0.00000000"], ["72704.01000000", "0.22038000"], ["72698.28000000", "0.01376000"], ["72697.43000000", "0.16853000"], ["72697.33000000", "0.16988000"], ["72697.07000000", "0.05942000"], ["72696.13000000", "0.00000000"], ["72695.99000000", "0.00007000"], ["72694.83000000", "0.16853000"], ["72694.78000000", "0.00000000"], ["72694.69000000", "0.16981000"], ["72693.80000000", "0.12350000"], ["72693.37000000", "0.16989000"], ["72692.05000000", "0.16981000"], ["72690.71000000", "1.13096000"], ["72688.88000000", "0.65949000"], ["72688.72000000", "0.00013000"], ["72687.85000000", "2.75063000"], ["72687.84000000", "0.00000000"], ["72687.61000000", "0.01376000"], ["72686.97000000", "0.00000000"], ["72683.73000000", "0.00000000"], ["72681.45000000", "0.00102000"], ["72680.09000000", "0.00000000"], ["72672.41000000", "0.00000000"], ["72669.29000000", "0.00737000"], ["72666.90000000", "0.00013000"], ["72665.15000000", "0.00000000"], ["72658.27000000", "0.00000000"], ["72657.61000000", "0.00000000"], ["72657.58000000", "0.00000000"], ["72655.14000000", "0.02000000"], ["72645.09000000", "0.00013000"], ["72643.33000000", "0.00000000"], ["72642.77000000", "0.04710000"], ["72623.28000000", "0.00013000"], ["72621.51000000", "0.00011000"], ["72602.15000000", "0.00000000"], ["72601.46000000", "0.00027000"], ["72519.26000000", "0.00080000"], ["72173.63000000", "0.01725000"], ["72072.95000000", "0.00346000"], ["72005.24000000", "0.00346000"], ["65439.48000000", "0.00289000"]], "a": [["72710.54000000", "4.08283000"], ["72711.23000000", "0.05426000"], ["72711.39000000", "0.00767000"], ["72711.61000000", "0.00016000"], ["72711.85000000", "0.16853000"], ["72711.88000000", "0.00016000"], ["72712.79000000", "0.00000000"], ["72712.81000000", "0.36859000"], ["72713.71000000", "0.00688000"], ["72714.47000000", "0.16853000"], ["72714.56000000", "0.00000000"], ["72715.05000000", "0.00688000"], ["72717.09000000", "0.16853000"], ["72717.24000000", "0.00000000"], ["72721.93000000", "0.08600000"], ["72726.62000000", "0.00000000"], ["72732.35000000", "0.00041000"], ["72733.42000000", "0.00200000"], ["72737.67000000", "0.00000000"], ["72739.01000000", "0.00200000"], ["72748.41000000", "0.00000000"], ["72748.64000000", "0.50592000"], ["72752.44000000", "0.00000000"], ["72754.17000000", "0.00013000"], ["72770.62000000", "0.26000000"], ["72774.26000000", "0.00000000"], ["72775.98000000", "0.00013000"], ["72796.08000000", "0.00000000"], ["72797.79000000", "0.00013000"], ["72806.79000000", "0.00000000"], ["72817.90000000", "0.00000000"], ["72819.61000000", "0.00020000"], ["72839.72000000", "0.00000000"], ["72862.31000000", "0.00000000"], ["72945.18000000", "0.00080000"], ["79225.75000000", "0.00139000"]], "_local_ts_utc": "2026-06-01T07:49:06.310385+00:00"}
{"e": "depthUpdate", "E": 1780300147514, "s": "BTCUSDT", "U": 94551788908, "u": 94551789062, "b": [["72710.53000000", "0.28331000"], ["72710.52000000", "0.00080000"], ["72708.10000000", "0.00000000"], ["72707.77000000", "0.00000000"], ["72707.76000000", "0.00023000"], ["72707.62000000", "0.00000000"], ["72706.76000000", "0.00016000"], ["72706.75000000", "0.00000000"], ["72706.67000000", "0.03130000"], ["72706.24000000", "0.01458000"], ["72706.20000000", "0.00000000"], ["72706.19000000", "0.00016000"], ["72706.14000000", "0.00000000"], ["72706.13000000", "0.00000000"], ["72705.82000000", "0.00040000"], ["72705.77000000", "0.00008000"], ["72705.43000000", "0.10297000"], ["72705.32000000", "0.10313000"], ["72704.01000000", "0.00008000"], ["72704.00000000", "0.61422000"], ["72703.60000000", "0.00000000"], ["72702.43000000", "0.01358000"], ["72702.16000000", "0.00031000"], ["72700.05000000", "0.00000000"], ["72698.74000000", "0.00000000"], ["72697.83000000", "0.00000000"], ["72697.43000000", "0.00000000"], ["72697.34000000", "0.42605000"], ["72697.33000000", "0.00007000"], ["72697.07000000", "0.00000000"], ["72697.02000000", "0.00000000"], ["72696.12000000", "0.00000000"], ["72694.83000000", "0.00000000"], ["72694.69000000", "0.00000000"], ["72687.85000000", "0.00000000"], ["72687.83000000", "0.00000000"], ["72686.41000000", "0.00000000"], ["72685.98000000", "0.27528000"], ["72684.13000000", "0.00031000"], ["72683.45000000", "0.02000000"], ["72681.98000000", "0.00200000"], ["72681.44000000", "0.00000000"], ["72680.17000000", "0.00000000"], ["72661.36000000", "0.00000000"], ["72660.94000000", "0.05399000"], ["72602.14000000", "2.75063000"], ["72588.48000000", "0.00000000"], ["72173.63000000", "0.01380000"], ["71933.12000000", "0.00000000"], ["71680.14000000", "0.00000000"], ["65439.48000000", "0.00323000"], ["58168.43000000", "0.00034000"]], "a": [["72710.54000000", "4.09693000"], ["72711.06000000", "0.04029000"], ["72711.15000000", "0.05182000"], ["72711.23000000", "0.00016000"], ["72711.39000000", "0.00767000"], ["72711.61000000", "0.00000000"], ["72711.85000000", "0.16869000"], ["72711.86000000", "0.16997000"], ["72711.88000000", "0.00000000"], ["72713.24000000", "0.00000000"], ["72714.03000000", "0.00165000"], ["72715.05000000", "0.00000000"], ["72717.59000000", "0.00688000"], ["72720.39000000", "0.00011000"], ["72722.02000000", "0.40000000"], ["72723.33000000", "0.00008000"], ["72723.59000000", "0.58158000"], ["72724.95000000", "0.16853000"], ["72725.64000000", "0.00000000"], ["72725.77000000", "0.68859000"], ["72739.63000000", "0.00686000"], ["72740.15000000", "0.00200000"], ["72741.63000000", "0.00000000"], ["72749.07000000", "1.45853000"], ["72759.57000000", "0.06904000"], ["72784.75000000", "0.00000000"], ["72787.74000000", "0.00000000"], ["72805.91000000", "0.07252000"], ["72806.75000000", "0.00000000"], ["73218.23000000", "0.00012000"]], "_local_ts_utc": "2026-06-01T07:49:06.410707+00:00"}
{"e": "depthUpdate", "E": 1780300147614, "s": "BTCUSDT", "U": 94551789063, "u": 94551789193, "b": [["72710.53000000", "0.24613000"], ["72710.52000000", "0.00080000"], ["72708.62000000", "0.00136000"], ["72707.78000000", "0.00945000"], ["72707.76000000", "0.00007000"], ["72706.76000000", "0.00000000"], ["72706.67000000", "0.03130000"], ["72706.25000000", "0.00000000"], ["72706.24000000", "0.00016000"], ["72706.19000000", "0.00000000"], ["72706.16000000", "0.00016000"], ["72706.15000000", "0.01354000"], ["72706.13000000", "0.00031000"], ["72705.90000000", "0.00000000"], ["72705.83000000", "0.00000000"], ["72705.82000000", "0.00024000"], ["72705.77000000", "0.00016000"], ["72705.44000000", "0.00008000"], ["72705.32000000", "0.10329000"], ["72705.26000000", "0.00000000"], ["72704.44000000", "0.00000000"], ["72704.01000000", "0.21815000"], ["72704.00000000", "0.61438000"], ["72702.16000000", "0.00000000"], ["72701.61000000", "0.00165000"], ["72700.01000000", "0.23208000"], ["72695.79000000", "0.01485000"], ["72693.50000000", "0.16853000"], ["72690.72000000", "0.36737000"], ["72690.71000000", "0.00000000"], ["72687.52000000", "0.01377000"], ["72686.04000000", "0.16853000"], ["72684.33000000", "0.16853000"], ["72684.30000000", "0.08789000"], ["72683.06000000", "0.16853000"], ["72681.44000000", "0.00686000"], ["72680.40000000", "0.16853000"], ["72680.09000000", "0.16853000"], ["72661.36000000", "0.00343000"], ["72660.94000000", "0.09389000"], ["72658.13000000", "0.15679000"], ["72657.61000000", "0.16853000"], ["72588.48000000", "0.00137000"], ["71841.75000000", "0.00000000"], ["71787.36000000", "0.00000000"], ["71765.29000000", "0.00347000"], ["65439.48000000", "0.00357000"], ["58168.43000000", "0.00000000"]], "a": [["72710.54000000", "4.09625000"], ["72711.06000000", "0.04029000"], ["72711.15000000", "0.00016000"], ["72711.23000000", "0.00000000"], ["72711.52000000", "0.06101000"], ["72711.66000000", "0.00000000"], ["72712.28000000", "0.00008000"], ["72718.00000000", "0.01000000"], ["72720.00000000", "0.01000000"], ["72722.00000000", "0.01000000"], ["72723.61000000", "0.06200000"], ["72724.00000000", "0.01000000"], ["72724.39000000", "0.05400000"], ["72724.97000000", "0.01300000"], ["72726.00000000", "0.01000000"], ["72728.00000000", "0.66949000"], ["72730.21000000", "0.00007000"], ["72732.68000000", "0.00007000"], ["72739.63000000", "0.00685000"], ["72805.41000000", "0.07732000"], ["72805.91000000", "0.00000000"], ["72806.64000000", "0.00000000"], ["72808.42000000", "0.08771000"], ["72809.40000000", "0.00000000"]], "_local_ts_utc": "2026-06-01T07:49:06.510279+00:00"}
{"e": "depthUpdate", "E": 1780300147714, "s": "BTCUSDT", "U": 94551789194, "u": 94551789357, "b": [["72710.53000000", "2.54453000"], ["72709.56000000", "0.00031000"], ["72709.43000000", "0.00000000"], ["72708.74000000", "0.00000000"], ["72707.16000000", "0.00016000"], ["72707.15000000", "0.02682000"], ["72706.75000000", "0.00000000"], ["72706.67000000", "0.03130000"], ["72706.24000000", "0.00000000"], ["72706.16000000", "0.00000000"], ["72706.15000000", "0.00016000"], ["72706.13000000", "0.00000000"], ["72705.83000000", "0.00000000"], ["72705.82000000", "0.00016000"], ["72705.77000000", "0.00024000"], ["72705.44000000", "0.00008000"], ["72705.32000000", "0.10329000"], ["72704.01000000", "0.00024000"], ["72704.00000000", "0.61422000"], ["72700.05000000", "0.16853000"], ["72700.01000000", "0.00063000"], ["72699.66000000", "0.05942000"], ["72698.74000000", "0.16853000"], ["72698.01000000", "0.00000000"], ["72697.67000000", "0.15306000"], ["72697.43000000", "0.16853000"], ["72697.35000000", "0.00008000"], ["72696.12000000", "0.16853000"], ["72696.05000000", "0.00000000"], ["72696.01000000", "0.00008000"], ["72694.83000000", "0.16853000"], ["72693.81000000", "0.00000000"], ["72693.38000000", "0.00008000"], ["72690.73000000", "0.16989000"], ["72690.72000000", "0.36729000"], ["72688.89000000", "0.00008000"], ["72688.76000000", "0.00012000"], ["72688.65000000", "0.03407000"], ["72687.62000000", "0.00000000"], ["72685.98000000", "0.27536000"], ["72680.09000000", "0.16861000"], ["72680.03000000", "0.00000000"], ["72680.01000000", "0.00315000"], ["72669.94000000", "0.00000000"], ["72669.29000000", "0.00737000"], ["72667.54000000", "0.02673000"], ["72666.90000000", "0.00013000"], ["72661.36000000", "0.00000000"], ["72588.48000000", "0.00000000"], ["72003.95000000", "0.00692000"], ["65439.48000000", "0.00391000"]], "a": [["72710.54000000", "3.44984000"], ["72710.62000000", "0.00016000"], ["72711.04000000", "0.00008000"], ["72711.05000000", "0.11419000"], ["72711.06000000", "0.04029000"], ["72711.15000000", "0.00000000"], ["72711.23000000", "0.00000000"], ["72711.39000000", "0.00767000"], ["72711.52000000", "0.00016000"], ["72711.84000000", "0.00000000"], ["72711.85000000", "0.16869000"], ["72712.31000000", "0.00000000"], ["72713.71000000", "0.00000000"], ["72714.31000000", "0.05006000"], ["72715.54000000", "0.01394000"], ["72716.79000000", "0.00688000"], ["72717.59000000", "0.00000000"], ["72719.91000000", "0.00688000"], ["72723.58000000", "0.00008000"], ["72723.59000000", "0.40802000"], ["72724.95000000", "0.00000000"], ["72724.99000000", "0.00017000"], ["72725.77000000", "0.00008000"], ["72726.38000000", "0.00000000"], ["72727.57000000", "0.16853000"], ["72728.18000000", "0.68850000"], ["72730.00000000", "0.01000000"], ["72732.00000000", "0.01199000"], ["72734.00000000", "0.01080000"], ["72736.00000000", "0.01080000"], ["72738.00000000", "0.01080000"], ["72739.01000000", "0.00000000"], ["72740.00000000", "0.03977000"], ["72740.84000000", "0.00200000"], ["72742.00000000", "0.04780000"], ["72744.00000000", "0.01080000"], ["72805.41000000", "0.05165000"], ["72806.77000000", "0.00000000"], ["72902.00000000", "0.01000000"], ["72904.00000000", "0.01000000"], ["72906.00000000", "0.01000000"]], "_local_ts_utc": "2026-06-01T07:49:06.610586+00:00"}
{"e": "depthUpdate", "E": 1780300147814, "s": "BTCUSDT", "U": 94551789358, "u": 94551789535, "b": [["72710.53000000", "0.06446000"], ["72710.52000000", "0.00088000"], ["72709.56000000", "0.00000000"], ["72708.62000000", "0.00000000"], ["72707.78000000", "0.00945000"], ["72707.15000000", "0.00016000"], ["72706.67000000", "0.03130000"], ["72706.28000000", "0.00000000"], ["72706.15000000", "0.00000000"], ["72705.96000000", "0.01077000"], ["72705.83000000", "0.00000000"], ["72705.82000000", "0.00016000"], ["72705.44000000", "0.00008000"], ["72705.32000000", "0.10329000"], ["72705.25000000", "0.00000000"], ["72704.91000000", "0.00031000"], ["72704.01000000", "0.21815000"], ["72704.00000000", "0.61438000"], ["72701.90000000", "0.00000000"], ["72700.05000000", "0.00000000"], ["72700.01000000", "0.24981000"], ["72699.67000000", "0.05942000"], ["72699.66000000", "0.00000000"], ["72698.74000000", "0.00000000"], ["72697.67000000", "0.00094000"], ["72697.43000000", "0.00000000"], ["72696.94000000", "0.00000000"], ["72696.12000000", "0.00000000"], ["72694.83000000", "0.00000000"], ["72693.80000000", "0.03221000"], ["72693.50000000", "0.00000000"], ["72693.37000000", "0.00008000"], ["72692.05000000", "0.00000000"], ["72688.89000000", "0.65957000"], ["72688.88000000", "0.00000000"], ["72687.52000000", "0.00000000"], ["72682.30000000", "0.00209000"], ["72681.98000000", "0.00000000"], ["72680.10000000", "2.75063000"], ["72680.08000000", "1.06805000"], ["72661.36000000", "0.00343000"], ["72660.94000000", "0.05399000"], ["72658.13000000", "0.00000000"], ["72657.61000000", "0.00000000"], ["72590.50000000", "0.00000000"], ["72588.48000000", "0.00137000"], ["72000.00000000", "104.01930000"], ["71765.29000000", "0.00694000"], ["65439.48000000", "0.00425000"]], "a": [["72710.54000000", "3.92963000"], ["72710.62000000", "0.00000000"], ["72711.39000000", "0.00767000"], ["72711.49000000", "0.03407000"], ["72711.52000000", "0.00000000"], ["72711.87000000", "0.08675000"], ["72712.81000000", "0.36875000"], ["72712.82000000", "0.50016000"], ["72714.31000000", "0.00000000"], ["72719.43000000", "0.00020000"], ["72719.91000000", "0.00000000"], ["72723.58000000", "0.16861000"], ["72724.95000000", "0.16853000"], ["72726.26000000", "0.16853000"], ["72730.77000000", "0.00020000"], ["72731.50000000", "0.16418000"], ["72733.90000000", "0.16853000"], ["72734.78000000", "0.16861000"], ["72738.71000000", "0.00020000"], ["72740.15000000", "0.00000000"], ["72740.48000000", "0.02924000"], ["72742.42000000", "0.49559000"], ["72770.44000000", "0.00000000"], ["72805.41000000", "0.03314000"], ["72805.75000000", "0.00000000"], ["72908.00000000", "0.01000000"], ["72910.00000000", "0.01000000"], ["72912.00000000", "0.01000000"], ["72914.00000000", "0.01000000"], ["72916.00000000", "0.01000000"], ["72918.00000000", "0.01000000"], ["72920.00000000", "0.01333000"], ["72922.00000000", "0.01000000"], ["72924.00000000", "0.01000000"], ["72926.00000000", "0.01000000"], ["72928.00000000", "0.01000000"], ["72930.00000000", "0.01000000"], ["72932.00000000", "0.01000000"], ["72934.00000000", "0.01000000"], ["72936.00000000", "0.01000000"], ["72938.00000000", "0.01000000"], ["73166.60000000", "0.00010000"]], "_local_ts_utc": "2026-06-01T07:49:06.710262+00:00"}
{"e": "depthUpdate", "E": 1780300147914, "s": "BTCUSDT", "U": 94551789536, "u": 94551789654, "b": [["72710.53000000", "0.06298000"], ["72710.52000000", "0.00094000"], ["72710.51000000", "0.00014000"], ["72707.78000000", "0.00945000"], ["72707.16000000", "0.00000000"], ["72707.15000000", "0.00000000"], ["72706.67000000", "0.03130000"], ["72705.97000000", "0.00016000"], ["72705.96000000", "0.01093000"], ["72705.58000000", "0.00000000"], ["72705.44000000", "0.00016000"], ["72705.33000000", "0.00000000"], ["72705.32000000", "0.10329000"], ["72704.91000000", "0.00000000"], ["72704.01000000", "0.00024000"], ["72704.00000000", "0.61422000"], ["72703.22000000", "0.00031000"], ["72699.67000000", "0.00000000"], ["72697.23000000", "0.00000000"], ["72694.69000000", "0.05942000"], ["72692.13000000", "0.00000000"], ["72690.73000000", "0.00008000"], ["72688.65000000", "0.00000000"], ["72681.44000000", "0.00000000"], ["72680.09000000", "0.00008000"], ["72670.32000000", "0.00000000"], ["72072.95000000", "0.00000000"], ["70891.14000000", "0.00352000"], ["65439.48000000", "0.00425000"]], "a": [["72710.54000000", "3.93665000"], ["72710.55000000", "0.00030000"], ["72710.56000000", "0.00014000"], ["72711.05000000", "0.34018000"], ["72711.39000000", "0.00767000"], ["72711.49000000", "0.03423000"], ["72711.84000000", "0.65949000"], ["72711.86000000", "0.16997000"], ["72711.87000000", "0.08691000"], ["72712.81000000", "1.24090000"], ["72712.82000000", "0.50000000"], ["72715.37000000", "2.75071000"], ["72716.79000000", "0.00000000"], ["72720.00000000", "0.02000000"], ["72722.00000000", "0.02000000"], ["72724.00000000", "0.02000000"], ["72730.19000000", "0.00000000"], ["72731.50000000", "0.00000000"], ["72731.58000000", "0.00000000"], ["72733.42000000", "0.00000000"], ["72733.90000000", "0.00000000"], ["72734.78000000", "0.00008000"], ["72739.63000000", "0.00000000"], ["72742.00000000", "0.01080000"], ["72742.01000000", "0.00000000"], ["72754.21000000", "0.00000000"], ["72940.00000000", "0.14627000"], ["72942.00000000", "0.01000000"], ["72944.00000000", "0.01000000"], ["72946.00000000", "0.01000000"], ["72948.00000000", "0.01000000"], ["72950.00000000", "0.01000000"], ["72952.00000000", "0.01000000"], ["72954.00000000", "0.01000000"], ["72956.00000000", "0.01000000"], ["72958.00000000", "0.01000000"], ["72960.00000000", "0.01361000"], ["72962.00000000", "0.01000000"], ["72964.00000000", "0.01000000"], ["72966.00000000", "0.01000000"], ["72968.00000000", "0.01000000"], ["72970.00000000", "0.01011000"], ["73041.96000000", "0.00146000"], ["79666.01000000", "0.00133000"]], "_local_ts_utc": "2026-06-01T07:49:06.810335+00:00"}
{"e": "depthUpdate", "E": 1780300148014, "s": "BTCUSDT", "U": 94551789655, "u": 94551789756, "b": [["72710.53000000", "0.23241000"], ["72705.93000000", "0.00028000"], ["72705.32000000", "0.10329000"], ["72704.01000000", "0.00008000"], ["72704.00000000", "0.61438000"], ["72703.51000000", "0.00031000"], ["72703.22000000", "0.00000000"], ["72694.73000000", "0.14808000"], ["72689.57000000", "0.16853000"], ["72686.05000000", "0.77235000"], ["72681.44000000", "0.00686000"], ["72657.61000000", "0.16853000"], ["72654.41000000", "0.00000000"], ["72653.50000000", "0.00000000"], ["72642.97000000", "1.72206000"], ["72005.24000000", "0.00692000"], ["65439.48000000", "0.00425000"], ["58168.43000000", "0.00034000"]], "a": [["72710.54000000", "4.03547000"], ["72711.04000000", "0.40864000"], ["72711.49000000", "0.03423000"], ["72711.84000000", "0.65965000"], ["72711.87000000", "0.08675000"], ["72716.80000000", "0.01089000"], ["72726.00000000", "0.02000000"], ["72726.03000000", "0.00200000"], ["72728.00000000", "0.67949000"], ["72730.00000000", "0.02000000"], ["72732.00000000", "0.02199000"], ["72733.97000000", "0.00200000"], ["72734.00000000", "0.02080000"], ["72736.00000000", "0.02080000"], ["72738.00000000", "0.02080000"], ["72739.63000000", "0.01371000"], ["72740.00000000", "0.04977000"], ["72740.84000000", "0.00000000"], ["72742.00000000", "0.02080000"], ["72743.05000000", "0.00434000"], ["72743.98000000", "0.00434000"], ["72744.00000000", "0.02080000"], ["72746.00000000", "0.02080000"], ["72748.64000000", "0.49547000"], ["72749.07000000", "1.45835000"], ["72753.45000000", "0.00000000"], ["72972.00000000", "0.01000000"], ["72974.00000000", "0.01009000"], ["72976.00000000", "0.01000000"], ["72978.00000000", "0.01031000"], ["72980.00000000", "0.01826000"], ["72982.00000000", "0.01000000"], ["72984.00000000", "0.01000000"], ["72986.00000000", "0.01000000"], ["72988.00000000", "0.01000000"], ["72990.00000000", "0.01000000"], ["72992.00000000", "0.01000000"], ["72994.00000000", "0.01000000"], ["72996.00000000", "0.01000000"], ["72998.00000000", "0.01000000"], ["73000.00000000", "1.08603000"]], "_local_ts_utc": "2026-06-01T07:49:06.911429+00:00"}
{"e": "depthUpdate", "E": 1780300148114, "s": "BTCUSDT", "U": 94551789757, "u": 94551789853, "b": [["72710.53000000", "0.28849000"], ["72706.23000000", "0.00016000"], ["72706.22000000", "0.01456000"], ["72705.97000000", "0.00000000"], ["72705.96000000", "0.00016000"], ["72705.63000000", "0.00031000"], ["72704.81000000", "0.00000000"], ["72704.76000000", "0.00000000"], ["72704.01000000", "0.21815000"], ["72703.51000000", "0.00000000"], ["72697.42000000", "0.05942000"], ["72695.99000000", "0.00014000"], ["72694.69000000", "0.00000000"], ["72693.80000000", "0.11493000"], ["72692.19000000", "0.16853000"], ["72690.89000000", "0.16853000"], ["72686.06000000", "0.64677000"], ["72685.98000000", "0.00008000"], ["72682.30000000", "0.00009000"], ["72681.44000000", "0.00686000"], ["72677.82000000", "0.00200000"], ["72674.18000000", "0.00102000"], ["72657.60000000", "1.46411000"], ["72653.51000000", "0.51165000"], ["72648.00000000", "0.02023000"], ["72646.00000000", "0.01369000"], ["72644.83000000", "0.76536000"], ["72644.00000000", "0.01280000"], ["72643.31000000", "0.70920000"], ["72642.00000000", "0.01280000"], ["72640.00000000", "0.20023000"], ["72638.00000000", "0.01280000"], ["72636.00000000", "0.01280000"], ["72634.00000000", "0.01280000"], ["72632.00000000", "0.01280000"], ["72630.00000000", "0.02746000"], ["72628.00000000", "0.01786000"], ["72626.00000000", "0.01280000"], ["72624.00000000", "0.01280000"], ["72622.00000000", "0.01309000"], ["72620.00000000", "2.01840000"], ["72618.00000000", "0.01293000"], ["72550.00000000", "2.35134000"], ["70892.77000000", "0.00704000"], ["65439.48000000", "0.00425000"]], "a": [["72710.54000000", "4.02755000"], ["72711.18000000", "0.05266000"], ["72711.86000000", "0.16981000"], ["72711.87000000", "0.00008000"], ["72713.71000000", "0.01376000"], ["72723.58000000", "0.00008000"], ["72724.95000000", "0.00000000"], ["72726.26000000", "0.00000000"], ["72735.99000000", "0.00200000"], ["72740.48000000", "0.02724000"], ["72803.99000000", "0.02655000"], ["72805.41000000", "0.00000000"], ["72806.52000000", "0.00000000"], ["72902.00000000", "0.00000000"], ["72904.00000000", "0.00000000"], ["72906.00000000", "0.00000000"], ["72908.00000000", "0.00000000"], ["72910.00000000", "0.00000000"], ["72912.00000000", "0.00000000"], ["72914.00000000", "0.00000000"], ["72916.00000000", "0.00000000"], ["72918.00000000", "0.00000000"], ["72920.00000000", "0.00333000"], ["73049.52000000", "0.00056000"]], "_local_ts_utc": "2026-06-01T07:49:07.010667+00:00"}
{"e": "depthUpdate", "E": 1780300148214, "s": "BTCUSDT", "U": 94551789854, "u": 94551790052, "b": [["72710.53000000", "2.01947000"], ["72710.52000000", "0.00102000"], ["72708.34000000", "0.00031000"], ["72707.29000000", "0.00016000"], ["72707.28000000", "0.02776000"], ["72706.74000000", "0.00000000"], ["72706.67000000", "0.03130000"], ["72706.23000000", "0.00000000"], ["72706.22000000", "0.00016000"], ["72706.12000000", "0.00000000"], ["72705.96000000", "0.00000000"], ["72705.90000000", "0.00000000"], ["72705.83000000", "0.00016000"], ["72705.82000000", "0.15011000"], ["72705.63000000", "0.00000000"], ["72705.44000000", "0.00000000"], ["72705.32000000", "0.10329000"], ["72704.01000000", "0.20455000"], ["72704.00000000", "0.61422000"], ["72702.43000000", "0.00000000"], ["72701.36000000", "0.16853000"], ["72700.19000000", "0.05942000"], ["72700.06000000", "0.39078000"], ["72700.05000000", "0.16853000"], ["72700.01000000", "0.00063000"], ["72698.92000000", "0.19607000"], ["72698.74000000", "0.16853000"], ["72697.43000000", "0.16228000"], ["72697.42000000", "0.00000000"], ["72696.12000000", "0.16853000"], ["72694.83000000", "0.16853000"], ["72694.73000000", "0.00000000"], ["72693.80000000", "0.16842000"], ["72693.50000000", "0.16853000"], ["72693.20000000", "0.00007000"], ["72680.11000000", "0.16853000"], ["72660.94000000", "0.09739000"], ["72658.13000000", "0.16853000"], ["72616.00000000", "0.01546000"], ["72614.00000000", "0.01280000"], ["72612.00000000", "0.01367000"], ["72610.00000000", "0.04248000"], ["72608.00000000", "0.01280000"], ["72606.00000000", "0.01296000"], ["72604.00000000", "0.01280000"], ["72602.00000000", "0.01280000"], ["72600.00000000", "6.02753000"], ["72598.00000000", "0.01137000"], ["72596.00000000", "0.01000000"], ["72594.00000000", "0.01000000"], ["72592.00000000", "0.01084000"], ["72590.00000000", "0.01522000"], ["72588.00000000", "0.23581000"], ["72586.00000000", "0.01393000"], ["72584.00000000", "0.01000000"], ["72005.24000000", "0.01038000"], ["65439.48000000", "0.00425000"], ["58168.43000000", "0.00000000"]], "a": [["72710.54000000", "3.57524000"], ["72711.03000000", "0.00024000"], ["72711.04000000", "0.40888000"], ["72711.05000000", "0.34034000"], ["72711.06000000", "0.04029000"], ["72711.17000000", "0.00008000"], ["72711.18000000", "0.00016000"], ["72711.83000000", "0.00016000"], ["72711.85000000", "0.16853000"], ["72711.87000000", "0.00000000"], ["72712.80000000", "0.00008000"], ["72712.81000000", "1.24082000"], ["72713.70000000", "0.00008000"], ["72713.71000000", "0.00000000"], ["72713.72000000", "0.00000000"], ["72714.05000000", "0.04825000"], ["72714.49000000", "0.00008000"], ["72714.55000000", "0.00000000"], ["72715.36000000", "0.00008000"], ["72715.37000000", "2.75063000"], ["72715.84000000", "0.00008000"], ["72716.79000000", "0.01376000"], ["72717.09000000", "0.00000000"], ["72717.13000000", "0.00008000"], ["72717.14000000", "0.00000000"], ["72717.23000000", "0.00000000"], ["72718.58000000", "0.00000000"], ["72718.90000000", "0.00008000"], ["72718.92000000", "0.00000000"], ["72719.43000000", "0.00028000"], ["72720.63000000", "0.00000000"], ["72720.64000000", "0.00008000"], ["72721.98000000", "0.00008000"], ["72722.00000000", "0.02200000"], ["72722.29000000", "0.00007000"], ["72723.33000000", "0.00000000"], ["72724.00000000", "0.02200000"], ["72725.07000000", "0.00008000"], ["72726.00000000", "0.02200000"], ["72726.61000000", "0.00000000"], ["72726.99000000", "0.00000000"], ["72727.57000000", "0.00000000"], ["72727.80000000", "0.00000000"], ["72727.99000000", "0.00000000"], ["72728.00000000", "0.68149000"], ["72728.17000000", "0.00008000"], ["72728.41000000", "0.00008000"], ["72728.51000000", "0.00000000"], ["72730.00000000", "0.02200000"], ["72732.00000000", "0.02399000"], ["72733.90000000", "0.00008000"], ["72734.00000000", "0.02280000"], ["72734.81000000", "0.00000000"], ["72738.49000000", "0.00008000"], ["72738.50000000", "0.88802000"], ["72740.71000000", "0.00008000"], ["72740.99000000", "0.00000000"], ["72743.07000000", "0.00008000"], ["72922.00000000", "0.00000000"], ["72924.00000000", "0.00000000"], ["72926.00000000", "0.00000000"], ["72928.00000000", "0.00000000"], ["72930.00000000", "0.00000000"], ["72932.00000000", "0.00000000"], ["72934.00000000", "0.00000000"], ["72936.00000000", "0.00000000"], ["72938.00000000", "0.00000000"], ["72940.00000000", "0.13627000"], ["72942.00000000", "0.00000000"], ["72944.00000000", "0.00000000"], ["80159.53000000", "0.00132000"]], "_local_ts_utc": "2026-06-01T07:49:07.110586+00:00"}
{"e": "depthUpdate", "E": 1780300148314, "s": "BTCUSDT", "U": 94551790053, "u": 94551790249, "b": [["72710.53000000", "2.55707000"], ["72710.52000000", "0.00102000"], ["72708.58000000", "0.00031000"], ["72708.34000000", "0.00000000"], ["72708.17000000", "0.00000000"], ["72707.90000000", "0.00008000"], ["72707.78000000", "0.00945000"], ["72707.43000000", "0.00000000"], ["72707.28000000", "0.02792000"], ["72706.67000000", "0.03130000"], ["72706.22000000", "0.00000000"], ["72705.83000000", "0.16869000"], ["72705.82000000", "0.15027000"], ["72704.02000000", "0.16853000"], ["72704.01000000", "0.20439000"], ["72703.78000000", "0.05942000"], ["72703.56000000", "0.19613000"], ["72702.67000000", "0.16853000"], ["72702.11000000", "0.00000000"], ["72701.37000000", "0.16853000"], ["72701.36000000", "0.00000000"], ["72700.19000000", "0.00000000"], ["72700.07000000", "0.65949000"], ["72698.92000000", "0.00000000"], ["72696.13000000", "0.65949000"], ["72692.20000000", "0.65949000"], ["72688.64000000", "0.03407000"], ["72672.92000000", "0.04307000"], ["72671.59000000", "1.36400000"], ["72669.29000000", "0.17590000"], ["72664.52000000", "0.49605000"], ["72660.94000000", "0.05399000"], ["72658.13000000", "0.16853000"], ["72657.61000000", "0.16853000"], ["72647.01000000", "2.04746000"], ["72644.82000000", "2.21352000"], ["72643.30000000", "0.00000000"], ["72600.54000000", "0.00000000"], ["72591.81000000", "0.00000000"], ["72582.00000000", "0.01007000"], ["72580.00000000", "0.58479000"], ["72578.00000000", "0.01000000"], ["72576.00000000", "0.01000000"], ["72574.00000000", "0.01230000"], ["72572.00000000", "0.01000000"], ["72570.00000000", "0.02502000"], ["72568.00000000", "0.01726000"], ["72566.00000000", "0.31178000"], ["72564.00000000", "0.01027000"], ["72562.00000000", "0.01000000"], ["72560.00000000", "0.12717000"], ["72558.00000000", "0.44146000"], ["72556.00000000", "0.01008000"], ["72554.00000000", "0.01089000"], ["72552.00000000", "0.01000000"], ["72550.00000000", "2.36134000"], ["72520.93000000", "0.00000000"], ["72005.24000000", "0.01384000"], ["71765.29000000", "0.01041000"], ["66932.55000000", "0.00014000"], ["65439.48000000", "0.00408000"], ["58168.42000000", "0.00000000"]], "a": [["72710.54000000", "3.18396000"], ["72711.03000000", "0.00024000"], ["72711.04000000", "0.40888000"], ["72711.05000000", "0.34034000"], ["72711.06000000", "0.04029000"], ["72711.18000000", "0.00000000"], ["72711.34000000", "0.00000000"], ["72711.48000000", "0.00016000"], ["72711.49000000", "0.00016000"], ["72711.83000000", "0.00016000"], ["72711.85000000", "0.00016000"], ["72711.86000000", "0.00000000"], ["72711.92000000", "0.00000000"], ["72712.84000000", "0.08000000"], ["72713.23000000", "0.00000000"], ["72714.47000000", "0.00000000"], ["72714.50000000", "0.00000000"], ["72715.37000000", "0.00000000"], ["72716.03000000", "0.00000000"], ["72716.79000000", "0.01769000"], ["72716.80000000", "0.00008000"], ["72718.90000000", "0.00008000"], ["72720.64000000", "0.00008000"], ["72721.73000000", "0.00688000"], ["72721.99000000", "0.00000000"], ["72728.18000000", "0.00000000"], ["72731.58000000", "0.68852000"], ["72736.00000000", "0.02280000"], ["72738.00000000", "0.02280000"], ["72740.00000000", "0.05177000"], ["72742.00000000", "0.02280000"], ["72743.08000000", "0.00000000"], ["72744.00000000", "0.02280000"], ["72746.00000000", "0.02280000"], ["72748.00000000", "0.02280000"], ["72766.90000000", "0.55338000"], ["72767.19000000", "0.00000000"], ["72791.10000000", "4.12657000"], ["72792.13000000", "2.75063000"], ["72839.64000000", "0.00000000"], ["72946.00000000", "0.00000000"], ["72948.00000000", "0.00000000"], ["72950.00000000", "0.00000000"], ["72952.00000000", "0.00000000"], ["72954.00000000", "0.00000000"], ["72956.00000000", "0.00000000"], ["72958.00000000", "0.00000000"], ["72960.00000000", "0.00361000"], ["72962.00000000", "0.00000000"], ["72964.00000000", "0.00000000"], ["72966.00000000", "0.00000000"], ["72968.00000000", "0.00000000"]], "_local_ts_utc": "2026-06-01T07:49:07.210585+00:00"}
{"e": "depthUpdate", "E": 1780300148414, "s": "BTCUSDT", "U": 94551790250, "u": 94551790512, "b": [["72710.53000000", "2.80119000"], ["72710.52000000", "0.00110000"], ["72708.58000000", "0.00000000"], ["72707.39000000", "0.00016000"], ["72707.38000000", "0.05942000"], ["72706.67000000", "0.03120000"], ["72705.85000000", "0.22332000"], ["72705.84000000", "0.00000000"], ["72705.83000000", "0.00016000"], ["72705.82000000", "0.00024000"], ["72705.77000000", "0.00008000"], ["72705.32000000", "0.10313000"], ["72704.80000000", "0.04000000"], ["72704.01000000", "0.31452000"], ["72703.78000000", "0.00000000"], ["72702.84000000", "0.00000000"], ["72702.82000000", "0.00009000"], ["72702.67000000", "0.00000000"], ["72701.88000000", "0.01349000"], ["72697.34000000", "0.60538000"], ["72694.83000000", "0.00000000"], ["72693.80000000", "0.35844000"], ["72687.61000000", "0.00000000"], ["72687.47000000", "2.75063000"], ["72682.70000000", "0.00200000"], ["72681.44000000", "0.01371000"], ["72680.40000000", "0.00000000"], ["72680.11000000", "0.00000000"], ["72677.82000000", "0.00000000"], ["72671.23000000", "0.02740000"], ["72671.08000000", "0.49600000"], ["72669.29000000", "0.00737000"], ["72667.54000000", "0.00000000"], ["72660.94000000", "0.05399000"], ["72658.13000000", "0.00000000"], ["72657.61000000", "0.00000000"], ["72647.00000000", "0.00000000"], ["72644.47000000", "0.00000000"], ["72605.61000000", "0.00137000"], ["72602.15000000", "0.00000000"], ["72602.14000000", "0.00000000"], ["72577.56000000", "0.00000000"], ["72005.24000000", "0.01730000"], ["71765.29000000", "0.01735000"], ["71619.87000000", "0.01044000"], ["71256.32000000", "0.00350000"], ["70529.21000000", "0.00353000"], ["65439.48000000", "0.00408000"]], "a": [["72710.54000000", "3.50808000"], ["72710.73000000", "0.00031000"], ["72711.02000000", "0.00016000"], ["72711.03000000", "0.14279000"], ["72711.04000000", "0.40872000"], ["72711.05000000", "0.00032000"], ["72711.39000000", "0.00767000"], ["72711.44000000", "0.00031000"], ["72711.48000000", "0.00000000"], ["72711.49000000", "0.00000000"], ["72711.83000000", "0.00008000"], ["72711.84000000", "0.00016000"], ["72711.85000000", "0.00000000"], ["72712.44000000", "0.00000000"], ["72712.78000000", "0.15869000"], ["72712.79000000", "0.39421000"], ["72712.80000000", "0.65957000"], ["72712.81000000", "0.00016000"], ["72712.82000000", "0.50016000"], ["72712.84000000", "0.00000000"], ["72713.22000000", "0.00000000"], ["72713.33000000", "0.00000000"], ["72714.52000000", "0.03407000"], ["72714.54000000", "0.08000000"], ["72715.38000000", "0.00000000"], ["72715.78000000", "0.16853000"], ["72715.85000000", "0.00000000"], ["72716.13000000", "0.00028000"], ["72716.62000000", "0.69828000"], ["72716.63000000", "0.65949000"], ["72716.79000000", "0.01081000"], ["72717.09000000", "0.16045000"], ["72717.68000000", "0.00000000"], ["72718.40000000", "0.16853000"], ["72718.91000000", "0.00000000"], ["72719.58000000", "0.65949000"], ["72719.71000000", "0.16853000"], ["72720.38000000", "0.00688000"], ["72720.64000000", "0.16861000"], ["72720.65000000", "1.39599000"], ["72721.92000000", "2.90447000"], ["72722.08000000", "0.00000000"], ["72722.97000000", "0.65949000"], ["72723.58000000", "0.00008000"], ["72723.59000000", "0.28507000"], ["72724.95000000", "0.00000000"], ["72725.00000000", "0.00000000"], ["72726.26000000", "0.00000000"], ["72727.57000000", "0.16853000"], ["72727.79000000", "1.81615000"], ["72727.80000000", "2.75063000"], ["72727.83000000", "0.00008000"], ["72727.84000000", "0.00008000"], ["72731.50000000", "0.00000000"], ["72731.57000000", "0.00000000"], ["72733.90000000", "0.00008000"], ["72735.99000000", "0.00000000"], ["72738.50000000", "0.65847000"], ["72740.48000000", "0.00000000"], ["72740.72000000", "0.00000000"], ["72740.87000000", "0.00200000"], ["72741.45000000", "0.00000000"], ["72742.42000000", "0.00007000"], ["72744.12000000", "0.02745000"], ["72763.78000000", "0.00000000"], ["72765.81000000", "0.00000000"], ["72766.89000000", "0.00189000"], ["72768.46000000", "0.00000000"], ["72768.60000000", "0.49534000"], ["72789.99000000", "2.08600000"], ["72802.31000000", "0.00000000"], ["72839.64000000", "0.00075000"], ["72872.76000000", "0.00686000"], ["72882.09000000", "0.01373000"], ["72889.14000000", "0.00686000"], ["72905.53000000", "0.00686000"], ["72970.00000000", "0.00011000"], ["72972.00000000", "0.00000000"], ["72974.00000000", "0.00009000"], ["72976.00000000", "0.00000000"], ["72978.00000000", "0.00031000"], ["72980.00000000", "0.00826000"], ["72982.00000000", "0.00000000"], ["72984.00000000", "0.00000000"], ["72986.00000000", "0.00000000"], ["72988.00000000", "0.00000000"], ["72990.00000000", "0.00000000"], ["72992.00000000", "0.00000000"], ["72994.00000000", "0.00000000"], ["73361.03000000", "0.00000000"], ["81350.56000000", "0.00087000"]], "_local_ts_utc": "2026-06-01T07:49:07.311153+00:00"}
{"e": "depthUpdate", "E": 1780300148514, "s": "BTCUSDT", "U": 94551790513, "u": 94551790627, "b": [["72707.78000000", "0.00945000"], ["72707.38000000", "0.05958000"], ["72706.67000000", "0.03120000"], ["72705.86000000", "0.00016000"], ["72705.85000000", "0.14838000"], ["72705.83000000", "0.00000000"], ["72705.82000000", "0.00008000"], ["72690.72000000", "1.19774000"], ["72687.48000000", "0.40856000"], ["72686.04000000", "0.00000000"], ["72684.33000000", "0.00000000"], ["72683.06000000", "0.00000000"], ["72682.12000000", "0.00000000"], ["72672.41000000", "0.40856000"], ["72653.51000000", "0.75686000"], ["72651.31000000", "1.04059000"], ["72648.00000000", "0.03023000"], ["72646.00000000", "0.02369000"], ["72644.00000000", "0.02280000"], ["72642.00000000", "0.02280000"], ["72640.00000000", "0.21023000"], ["72638.00000000", "0.02280000"], ["72636.00000000", "0.02280000"], ["72550.00000000", "1.86134000"], ["72511.11000000", "0.00000000"], ["72506.81000000", "0.00822000"], ["65439.48000000", "0.00408000"], ["65439.00000000", "0.00020000"], ["58168.43000000", "0.00034000"]], "a": [["72710.54000000", "3.23063000"], ["72710.73000000", "0.00000000"], ["72711.03000000", "0.14295000"], ["72711.04000000", "0.40872000"], ["72711.05000000", "0.00016000"], ["72711.11000000", "0.00031000"], ["72711.39000000", "0.00798000"], ["72711.83000000", "0.05950000"], ["72711.84000000", "0.00000000"], ["72712.00000000", "0.00320000"], ["72712.77000000", "0.00016000"], ["72712.78000000", "0.76738000"], ["72712.79000000", "0.00024000"], ["72712.80000000", "0.65973000"], ["72712.81000000", "0.00000000"], ["72712.82000000", "0.50000000"], ["72714.00000000", "0.00080000"], ["72714.65000000", "0.12085000"], ["72716.00000000", "0.00080000"], ["72716.62000000", "0.70927000"], ["72716.79000000", "0.00000000"], ["72718.00000000", "0.01080000"], ["72720.00000000", "0.02080000"], ["72722.00000000", "0.02280000"], ["72723.59000000", "0.18446000"], ["72724.00000000", "0.02280000"], ["72726.00000000", "0.02280000"], ["72728.00000000", "0.68229000"], ["72730.00000000", "0.02280000"], ["72732.00000000", "0.02479000"], ["72745.53000000", "0.46490000"], ["72747.54000000", "1.03922000"], ["72996.00000000", "0.00000000"], ["72998.00000000", "0.00000000"], ["73000.00000000", "1.57603000"]], "_local_ts_utc": "2026-06-01T07:49:07.410342+00:00"}
{"e": "depthUpdate", "E": 1780300148614, "s": "BTCUSDT", "U": 94551790628, "u": 94551790714, "b": [["72710.53000000", "2.78180000"], ["72710.52000000", "0.00102000"], ["72690.27000000", "0.01377000"], ["72689.21000000", "0.01384000"], ["72653.51000000", "0.51165000"], ["72650.77000000", "0.00000000"], ["72634.00000000", "0.02280000"], ["72632.00000000", "0.02280000"], ["72630.00000000", "0.03746000"], ["72628.00000000", "0.02786000"], ["72626.00000000", "0.02280000"], ["72624.00000000", "0.02280000"], ["72622.00000000", "0.02309000"], ["72620.00000000", "2.02840000"], ["72618.00000000", "0.02293000"], ["72616.00000000", "0.02546000"], ["72614.00000000", "0.02280000"], ["72612.00000000", "0.02367000"], ["71764.01000000", "0.00694000"], ["65439.48000000", "0.00425000"], ["58168.43000000", "0.00000000"], ["58168.00000000", "0.03426000"]], "a": [["72710.54000000", "2.29258000"], ["72710.55000000", "0.00062000"], ["72711.05000000", "0.00016000"], ["72711.11000000", "0.00000000"], ["72711.39000000", "0.00767000"], ["72711.44000000", "0.00000000"], ["72711.45000000", "0.00076000"], ["72711.82000000", "0.00000000"], ["72711.83000000", "0.00024000"], ["72711.86000000", "0.00031000"], ["72712.78000000", "0.76738000"], ["72712.79000000", "0.00008000"], ["72713.46000000", "0.00031000"], ["72717.85000000", "0.00007000"], ["72721.92000000", "0.00000000"], ["72726.03000000", "0.00000000"], ["72727.57000000", "0.00000000"], ["72733.60000000", "0.00200000"], ["72784.63000000", "0.00007000"], ["72835.83000000", "0.00000000"], ["72870.62000000", "0.00000000"]], "_local_ts_utc": "2026-06-01T07:49:07.510190+00:00"}
{"e": "depthUpdate", "E": 1780300148714, "s": "BTCUSDT", "U": 94551790715, "u": 94551792708, "b": [["72719.28000000", "3.15400000"], ["72719.27000000", "0.00022000"], ["72719.26000000", "0.00014000"], ["72718.94000000", "2.37712000"], ["72718.93000000", "0.25396000"], ["72718.92000000", "0.63396000"], ["72718.91000000", "0.00000000"], ["72718.84000000", "0.00016000"], ["72718.83000000", "0.00023000"], ["72718.80000000", "0.00000000"], ["72718.67000000", "0.00000000"], ["72718.66000000", "0.05958000"], ["72718.10000000", "0.00000000"], ["72718.09000000", "0.00000000"], ["72717.99000000", "0.00016000"], ["72717.61000000", "0.00000000"], ["72717.08000000", "0.00000000"], ["72716.66000000", "0.00000000"], ["72716.62000000", "0.00000000"], ["72716.61000000", "0.00000000"], ["72716.30000000", "0.00000000"], ["72715.77000000", "0.00000000"], ["72715.76000000", "0.00000000"], ["72715.53000000", "0.00000000"], ["72715.33000000", "0.16935000"], ["72715.20000000", "0.00000000"], ["72715.14000000", "0.01392000"], ["72715.13000000", "0.00000000"], ["72715.05000000", "0.00000000"], ["72715.02000000", "0.00000000"], ["72714.99000000", "0.00000000"], ["72714.65000000", "0.88910000"], ["72714.64000000", "0.00000000"], ["72714.63000000", "0.00000000"], ["72714.54000000", "0.00000000"], ["72714.53000000", "0.16275000"], ["72714.52000000", "0.00000000"], ["72714.51000000", "0.00016000"], ["72714.48000000", "0.00000000"], ["72714.04000000", "0.00031000"], ["72714.02000000", "0.00000000"], ["72713.99000000", "0.00000000"], ["72713.73000000", "0.00000000"], ["72713.69000000", "0.00000000"], ["72713.46000000", "0.00000000"], ["72713.45000000", "0.00000000"], ["72713.32000000", "0.00751000"], ["72713.22000000", "0.00000000"], ["72713.21000000", "0.00028000"], ["72713.10000000", "0.13752000"], ["72713.02000000", "0.00000000"], ["72712.99000000", "0.00000000"], ["72712.98000000", "0.00000000"], ["72712.97000000", "0.00008000"], ["72712.96000000", "0.00000000"], ["72712.85000000", "0.00000000"], ["72712.83000000", "0.00000000"], ["72712.82000000", "0.00000000"], ["72712.81000000", "0.35191000"], ["72712.80000000", "0.00000000"], ["72712.79000000", "0.00000000"], ["72712.78000000", "0.00000000"], ["72712.77000000", "0.00000000"], ["72712.76000000", "0.00000000"], ["72712.27000000", "0.00000000"], ["72712.04000000", "1.44041000"], ["72712.03000000", "1.51084000"], ["72712.02000000", "0.00000000"], ["72712.01000000", "0.00000000"], ["72711.99000000", "0.00000000"], ["72711.89000000", "0.00000000"], ["72711.85000000", "0.00000000"], ["72711.82000000", "0.00000000"], ["72711.71000000", "0.00000000"], ["72711.70000000", "0.48725000"], ["72711.54000000", "0.00000000"], ["72711.45000000", "0.00007000"], ["72711.44000000", "0.00000000"], ["72711.39000000", "0.00000000"], ["72711.38000000", "0.00008000"], ["72711.37000000", "0.00000000"], ["72711.32000000", "0.00748000"], ["72711.24000000", "0.65949000"], ["72711.23000000", "0.00530000"], ["72711.16000000", "0.00000000"], ["72711.06000000", "0.00000000"], ["72711.05000000", "0.00060000"], ["72711.04000000", "0.15567000"], ["72711.03000000", "0.30553000"], ["72711.02000000", "1.00395000"], ["72711.01000000", "0.00000000"], ["72711.00000000", "0.00000000"], ["72710.65000000", "0.00000000"], ["72710.55000000", "0.25799000"], ["72710.54000000", "1.25116000"], ["72710.53000000", "0.28461000"], ["72710.52000000", "0.00000000"], ["72710.51000000", "0.00000000"], ["72710.41000000", "0.00000000"], ["72710.21000000", "0.00009000"], ["72710.10000000", "0.01405000"], ["72709.22000000", "0.00000000"], ["72708.29000000", "0.00766000"], ["72707.93000000", "0.15892000"], ["72707.92000000", "0.00000000"], ["72707.91000000", "0.00000000"], ["72707.78000000", "0.00929000"], ["72707.63000000", "0.00000000"], ["72707.62000000", "0.00028000"], ["72707.39000000", "0.00000000"], ["72707.38000000", "0.00000000"], ["72707.29000000", "0.00000000"], ["72707.28000000", "0.00000000"], ["72706.68000000", "0.00000000"], ["72706.67000000", "0.00000000"], ["72706.60000000", "0.00000000"], ["72706.31000000", "0.00755000"], ["72705.98000000", "0.01342000"], ["72705.86000000", "0.00000000"], ["72705.85000000", "0.00000000"], ["72705.82000000", "0.00000000"], ["72705.81000000", "0.10889000"], ["72705.76000000", "0.28985000"], ["72705.46000000", "0.00007000"], ["72705.43000000", "0.10281000"], ["72705.12000000", "0.40856000"], ["72704.78000000", "0.00011000"], ["72704.68000000", "0.00000000"], ["72704.53000000", "0.00000000"], ["72704.47000000", "0.00000000"], ["72704.16000000", "0.00766000"], ["72704.05000000", "0.00000000"], ["72704.04000000", "0.51783000"], ["72704.03000000", "0.65949000"], ["72704.02000000", "0.00000000"], ["72704.01000000", "0.00008000"], ["72703.56000000", "0.00008000"], ["72702.67000000", "0.00000000"], ["72702.06000000", "0.00000000"], ["72701.96000000", "0.00766000"], ["72701.94000000", "0.00007000"], ["72701.38000000", "0.00000000"], ["72701.37000000", "0.00000000"], ["72701.03000000", "0.00000000"], ["72700.93000000", "0.15000000"], ["72700.76000000", "0.00000000"], ["72700.75000000", "0.00000000"], ["72700.72000000", "0.00000000"], ["72700.54000000", "0.02000000"], ["72700.53000000", "0.00000000"], ["72700.15000000", "0.00000000"], ["72700.11000000", "0.03407000"], ["72700.08000000", "0.42857000"], ["72700.06000000", "0.00000000"], ["72700.05000000", "0.00000000"], ["72699.96000000", "0.00000000"], ["72699.05000000", "0.00000000"], ["72698.74000000", "0.00000000"], ["72698.13000000", "0.00000000"], ["72698.00000000", "0.06445000"], ["72697.93000000", "0.00000000"], ["72697.46000000", "0.00158000"], ["72697.43000000", "0.00000000"], ["72697.35000000", "0.00000000"], ["72697.34000000", "1.42486000"], ["72696.32000000", "0.00000000"], ["72696.15000000", "0.00000000"], ["72696.14000000", "3.15919000"], ["72696.12000000", "0.00000000"], ["72695.37000000", "0.00360000"], ["72694.83000000", "0.00000000"], ["72693.80000000", "0.16842000"], ["72693.50000000", "0.00000000"], ["72693.38000000", "0.00000000"], ["72693.32000000", "0.04000000"], ["72693.20000000", "0.00000000"], ["72693.03000000", "0.00000000"], ["72693.00000000", "0.00007000"], ["72692.94000000", "0.00000000"], ["72692.21000000", "0.00008000"], ["72692.19000000", "0.00000000"], ["72690.89000000", "0.00000000"], ["72690.83000000", "0.00000000"], ["72690.27000000", "0.00000000"], ["72689.57000000", "0.00000000"], ["72689.41000000", "0.00000000"], ["72689.21000000", "0.00008000"], ["72689.01000000", "0.00000000"], ["72688.90000000", "0.00008000"], ["72688.89000000", "0.65949000"], ["72688.09000000", "0.00000000"], ["72687.48000000", "0.40864000"], ["72687.16000000", "0.00000000"], ["72687.10000000", "0.00200000"], ["72686.70000000", "0.97041000"], ["72686.67000000", "1.36372000"], ["72686.13000000", "0.00000000"], ["72686.07000000", "0.00000000"], ["72686.03000000", "0.02000000"], ["72685.98000000", "0.00000000"], ["72685.53000000", "0.00000000"], ["72685.34000000", "0.00000000"], ["72684.33000000", "0.00000000"], ["72683.52000000", "0.00000000"], ["72683.45000000", "0.00000000"], ["72683.06000000", "0.00000000"], ["72682.70000000", "0.00000000"], ["72682.19000000", "0.00000000"], ["72682.12000000", "0.00000000"], ["72681.93000000", "0.00000000"], ["72681.70000000", "0.00000000"], ["72681.44000000", "0.00000000"], ["72680.40000000", "0.00000000"], ["72680.11000000", "0.00008000"], ["72680.09000000", "0.00000000"], ["72679.36000000", "0.75312000"], ["72679.35000000", "1.36386000"], ["72678.24000000", "0.00000000"], ["72678.01000000", "0.00000000"], ["72677.63000000", "0.49596000"], ["72677.50000000", "0.00000000"], ["72674.55000000", "0.00000000"], ["72671.20000000", "0.00000000"], ["72665.41000000", "0.00000000"], ["72662.84000000", "0.45626000"], ["72660.94000000", "0.12470000"], ["72660.25000000", "0.26000000"], ["72659.32000000", "0.00342000"], ["72658.94000000", "0.00000000"], ["72657.29000000", "0.27575000"], ["72655.81000000", "0.00000000"], ["72653.77000000", "0.00000000"], ["72653.51000000", "0.15422000"], ["72651.31000000", "0.00000000"], ["72650.03000000", "0.40931000"], ["72650.01000000", "0.00000000"], ["72649.46000000", "0.00000000"], ["72647.60000000", "0.00000000"], ["72647.15000000", "0.00000000"], ["72646.20000000", "0.00008000"], ["72638.17000000", "0.00000000"], ["72634.89000000", "0.00000000"], ["72631.77000000", "0.00000000"], ["72630.21000000", "0.00282000"], ["72624.80000000", "0.09647000"], ["72622.01000000", "0.00000000"], ["72611.04000000", "0.00000000"], ["72611.03000000", "0.00000000"], ["72611.02000000", "0.00000000"], ["72610.03000000", "0.00000000"], ["72610.00000000", "0.05248000"], ["72608.00000000", "0.02280000"], ["72607.54000000", "0.00000000"], ["72606.00000000", "0.02296000"], ["72604.00000000", "0.02280000"], ["72602.00000000", "0.02280000"], ["72600.00000000", "6.03753000"], ["72598.00000000", "0.02137000"], ["72596.00000000", "0.02000000"], ["72594.00000000", "0.02000000"], ["72592.00000000", "0.02084000"], ["72590.00000000", "0.02522000"], ["72573.48000000", "0.00008000"], ["72565.46000000", "0.00000000"], ["72560.54000000", "2.84261000"], ["72538.46000000", "0.00037000"], ["72531.94000000", "0.00000000"], ["72514.73000000", "0.00000000"], ["72512.90000000", "0.00000000"], ["72500.76000000", "0.00008000"], ["72492.75000000", "0.00000000"], ["72428.04000000", "0.00008000"], ["72420.04000000", "0.00000000"], ["72355.33000000", "0.00008000"], ["72350.29000000", "0.00000000"], ["72347.33000000", "0.00000000"], ["72282.61000000", "0.00008000"], ["72274.61000000", "0.00000000"], ["72209.89000000", "0.00008000"], ["72201.90000000", "0.00000000"], ["72137.17000000", "0.00008000"], ["72129.19000000", "0.00000000"], ["71619.87000000", "0.01392000"], ["65447.36000000", "0.00052000"], ["65439.93000000", "0.00098000"], ["65439.48000000", "0.00000000"], ["65439.00000000", "0.00000000"], ["58168.00000000", "0.02826000"]], "a": [["72710.54000000", "0.00000000"], ["72710.55000000", "0.00000000"], ["72710.56000000", "0.00000000"], ["72711.02000000", "0.00000000"], ["72711.03000000", "0.00000000"], ["72711.04000000", "0.00000000"], ["72711.05000000", "0.00000000"], ["72711.06000000", "0.00000000"], ["72711.17000000", "0.00000000"], ["72711.23000000", "0.00000000"], ["72711.24000000", "0.00000000"], ["72711.39000000", "0.00000000"], ["72711.45000000", "0.00000000"], ["72711.55000000", "0.00000000"], ["72711.83000000", "0.00000000"], ["72711.86000000", "0.00000000"], ["72712.00000000", "0.00000000"], ["72712.28000000", "0.00000000"], ["72712.77000000", "0.00000000"], ["72712.78000000", "0.00000000"], ["72712.79000000", "0.00000000"], ["72712.80000000", "0.00000000"], ["72712.81000000", "0.00000000"], ["72712.82000000", "0.00000000"], ["72712.83000000", "0.00000000"], ["72713.00000000", "0.00000000"], ["72713.46000000", "0.00000000"], ["72713.70000000", "0.00000000"], ["72713.74000000", "0.00000000"], ["72713.79000000", "0.00000000"], ["72714.00000000", "0.00000000"], ["72714.03000000", "0.00000000"], ["72714.04000000", "0.00000000"], ["72714.05000000", "0.00000000"], ["72714.49000000", "0.00000000"], ["72714.52000000", "0.00000000"], ["72714.53000000", "0.00000000"], ["72714.54000000", "0.00000000"], ["72714.55000000", "0.00000000"], ["72714.64000000", "0.00000000"], ["72714.65000000", "0.00000000"], ["72715.03000000", "0.00000000"], ["72715.06000000", "0.00000000"], ["72715.14000000", "0.00000000"], ["72715.21000000", "0.00000000"], ["72715.34000000", "0.00000000"], ["72715.36000000", "0.00000000"], ["72715.54000000", "0.00000000"], ["72715.76000000", "0.00000000"], ["72715.77000000", "0.00000000"], ["72715.78000000", "0.00000000"], ["72715.84000000", "0.00000000"], ["72716.00000000", "0.00000000"], ["72716.04000000", "0.00000000"], ["72716.13000000", "0.00000000"], ["72716.34000000", "0.00000000"], ["72716.62000000", "0.00000000"], ["72716.63000000", "0.00000000"], ["72716.80000000", "0.00000000"], ["72716.81000000", "0.00000000"], ["72717.09000000", "0.00000000"], ["72717.13000000", "0.00000000"], ["72717.46000000", "0.00000000"], ["72717.60000000", "0.00000000"], ["72717.67000000", "0.00000000"], ["72717.85000000", "0.00000000"], ["72718.00000000", "0.00000000"], ["72718.10000000", "0.00000000"], ["72718.11000000", "0.00000000"], ["72718.40000000", "0.00000000"], ["72718.57000000", "0.00000000"], ["72718.66000000", "0.00000000"], ["72718.67000000", "0.00000000"], ["72718.79000000", "0.00000000"], ["72718.81000000", "0.00000000"], ["72718.83000000", "0.00000000"], ["72718.84000000", "0.00000000"], ["72718.90000000", "0.00000000"], ["72718.92000000", "0.00000000"], ["72718.93000000", "0.00000000"], ["72719.17000000", "0.00000000"], ["72719.29000000", "0.00410000"], ["72719.30000000", "0.00048000"], ["72719.43000000", "0.00008000"], ["72719.44000000", "0.00000000"], ["72719.58000000", "0.00000000"], ["72719.71000000", "0.00000000"], ["72719.74000000", "0.00000000"], ["72719.79000000", "0.00312000"], ["72719.92000000", "0.00000000"], ["72719.99000000", "0.00016000"], ["72720.00000000", "0.02080000"], ["72720.32000000", "0.00015000"], ["72720.38000000", "0.00000000"], ["72720.47000000", "0.00000000"], ["72720.64000000", "0.00008000"], ["72720.65000000", "0.00016000"], ["72720.99000000", "0.00000000"], ["72721.09000000", "0.00000000"], ["72721.24000000", "0.00000000"], ["72721.62000000", "0.00000000"], ["72721.73000000", "0.00000000"], ["72721.91000000", "0.00000000"], ["72721.92000000", "0.00016000"], ["72722.01000000", "0.00016000"], ["72722.29000000", "0.01388000"], ["72722.58000000", "0.00192000"], ["72722.96000000", "0.00008000"], ["72723.33000000", "0.00000000"], ["72723.34000000", "0.00000000"], ["72723.40000000", "0.00000000"], ["72723.41000000", "0.00000000"], ["72723.49000000", "0.00000000"], ["72723.57000000", "0.00000000"], ["72723.59000000", "0.00000000"], ["72723.61000000", "0.00000000"], ["72724.06000000", "0.12588000"], ["72724.07000000", "0.10000000"], ["72724.09000000", "0.00762000"], ["72724.32000000", "0.02000000"], ["72724.38000000", "0.00000000"], ["72724.39000000", "0.00000000"], ["72724.70000000", "0.00000000"], ["72725.06000000", "0.00028000"], ["72725.78000000", "0.00000000"], ["72725.82000000", "0.00000000"], ["72726.26000000", "0.00000000"], ["72726.49000000", "0.00000000"], ["72726.83000000", "0.00031000"], ["72727.41000000", "0.00000000"], ["72727.57000000", "0.00000000"], ["72727.70000000", "0.16851000"], ["72727.71000000", "0.40856000"], ["72727.72000000", "0.00000000"], ["72727.73000000", "0.00742000"], ["72727.78000000", "0.00011000"], ["72727.79000000", "0.33539000"], ["72727.80000000", "0.00000000"], ["72727.81000000", "0.00000000"], ["72727.87000000", "0.00000000"], ["72727.91000000", "0.00000000"], ["72728.01000000", "0.00000000"], ["72728.16000000", "0.00000000"], ["72728.40000000", "0.00155000"], ["72728.42000000", "0.00000000"], ["72728.43000000", "0.00000000"], ["72728.52000000", "0.00000000"], ["72728.74000000", "0.00000000"], ["72729.49000000", "0.00000000"], ["72729.57000000", "0.00000000"], ["72731.04000000", "0.00072000"], ["72731.08000000", "0.16851000"], ["72731.37000000", "0.00742000"], ["72731.51000000", "0.00000000"], ["72731.58000000", "0.16851000"], ["72732.00000000", "0.02280000"], ["72733.31000000", "0.00000000"], ["72733.70000000", "0.15207000"], ["72733.88000000", "0.16851000"], ["72733.89000000", "0.00000000"], ["72733.90000000", "0.00008000"], ["72733.91000000", "0.00000000"], ["72733.97000000", "0.00000000"], ["72734.78000000", "0.00008000"], ["72735.01000000", "0.00767000"], ["72736.05000000", "0.00000000"], ["72736.32000000", "0.15802000"], ["72736.99000000", "0.16851000"], ["72738.15000000", "0.58536000"], ["72738.65000000", "0.00760000"], ["72738.66000000", "0.00275000"], ["72739.16000000", "0.00000000"], ["72739.17000000", "0.00000000"], ["72739.63000000", "0.00000000"], ["72740.12000000", "0.00000000"], ["72740.87000000", "0.00000000"], ["72741.11000000", "0.00137000"], ["72743.05000000", "0.00000000"], ["72743.98000000", "0.00000000"], ["72745.07000000", "0.00200000"], ["72745.52000000", "0.45885000"], ["72745.53000000", "0.03055000"], ["72747.28000000", "0.00200000"], ["72747.54000000", "0.00000000"], ["72748.35000000", "0.00007000"], ["72748.64000000", "0.00000000"], ["72750.72000000", "0.00000000"], ["72751.07000000", "0.00000000"], ["72752.04000000", "0.00007000"], ["72752.91000000", "0.23247000"], ["72753.49000000", "0.00000000"], ["72753.82000000", "1.13006000"], ["72754.66000000", "0.00000000"], ["72755.80000000", "0.00000000"], ["72756.03000000", "0.43387000"], ["72757.45000000", "0.03185000"], ["72759.57000000", "0.00000000"], ["72761.27000000", "0.00000000"], ["72762.88000000", "0.00000000"], ["72764.09000000", "0.00007000"], ["72766.89000000", "0.00000000"], ["72766.90000000", "0.00000000"], ["72771.23000000", "0.20938000"], ["72773.22000000", "0.49531000"], ["72774.91000000", "0.00000000"], ["72775.16000000", "0.00000000"], ["72775.74000000", "0.00000000"], ["72776.71000000", "0.00000000"], ["72777.17000000", "0.18446000"], ["72779.74000000", "0.59811000"], ["72781.44000000", "1.36195000"], ["72782.00000000", "0.57618000"], ["72782.18000000", "0.00343000"], ["72784.71000000", "0.00000000"], ["72789.99000000", "0.85425000"], ["72791.10000000", "0.00000000"], ["72792.01000000", "0.00008000"], ["72800.42000000", "1.64369000"], ["72802.31000000", "2.75063000"], ["72833.93000000", "0.02122000"], ["72839.64000000", "0.00000000"], ["72848.31000000", "0.00000000"], ["72849.42000000", "0.00000000"], ["72855.42000000", "0.00000000"], ["72857.42000000", "0.00000000"], ["72861.17000000", "0.09607000"], ["72864.37000000", "0.00010000"], ["72864.73000000", "0.00008000"], ["72876.11000000", "2.06252000"], ["72902.16000000", "4.12028000"], ["72994.83000000", "0.00016000"], ["73002.85000000", "0.00000000"], ["73010.17000000", "0.00015000"], ["73067.53000000", "0.00000000"], ["73075.56000000", "0.00000000"], ["73082.89000000", "0.00008000"], ["73201.71000000", "0.00000000"], ["73212.94000000", "0.00000000"], ["73220.98000000", "0.00000000"], ["73228.33000000", "0.00008000"], ["81514.80000000", "0.00052000"]], "_local_ts_utc": "2026-06-01T07:49:07.610760+00:00"}
{"e": "depthUpdate", "E": 1780300148814, "s": "BTCUSDT", "U": 94551792709, "u": 94551793009, "b": [["72719.28000000", "3.15016000"], ["72718.95000000", "0.00024000"], ["72718.94000000", "0.28331000"], ["72718.93000000", "0.25388000"], ["72718.92000000", "0.29692000"], ["72718.84000000", "0.00000000"], ["72718.83000000", "0.00007000"], ["72718.67000000", "0.00016000"], ["72718.66000000", "0.05958000"], ["72718.26000000", "0.00008000"], ["72718.25000000", "0.06645000"], ["72718.24000000", "0.00000000"], ["72718.23000000", "0.00000000"], ["72717.99000000", "0.00000000"], ["72716.28000000", "0.04051000"], ["72715.33000000", "0.16951000"], ["72715.14000000", "0.01408000"], ["72714.67000000", "0.25660000"], ["72714.66000000", "0.16851000"], ["72714.65000000", "0.00016000"], ["72714.53000000", "0.16267000"], ["72714.51000000", "0.00000000"], ["72714.04000000", "0.00015000"], ["72713.10000000", "0.00000000"], ["72712.97000000", "0.00000000"], ["72712.82000000", "0.16851000"], ["72712.81000000", "0.35183000"], ["72712.05000000", "0.65949000"], ["72712.04000000", "1.44049000"], ["72712.03000000", "1.46076000"], ["72711.38000000", "0.00000000"], ["72711.24000000", "0.00000000"], ["72711.03000000", "0.30545000"], ["72711.02000000", "1.00387000"], ["72710.53000000", "0.28453000"], ["72710.21000000", "0.00016000"], ["72708.51000000", "0.01376000"], ["72708.20000000", "0.00573000"], ["72707.93000000", "0.33618000"], ["72707.16000000", "0.00165000"], ["72707.02000000", "0.65949000"], ["72705.64000000", "0.00048000"], ["72705.08000000", "0.00191000"], ["72704.05000000", "0.00000000"], ["72704.04000000", "0.51791000"], ["72704.01000000", "0.00000000"], ["72704.00000000", "0.60569000"], ["72703.17000000", "0.00000000"], ["72701.14000000", "0.04000000"], ["72700.94000000", "0.00000000"], ["72700.73000000", "0.00000000"], ["72700.12000000", "0.16851000"], ["72700.08000000", "0.42849000"], ["72698.32000000", "0.00000000"], ["72698.28000000", "0.00000000"], ["72698.00000000", "0.06280000"], ["72697.35000000", "0.16851000"], ["72697.15000000", "0.12061000"], ["72696.15000000", "0.00008000"], ["72695.43000000", "0.00009000"], ["72693.79000000", "0.00000000"], ["72693.32000000", "0.00000000"], ["72689.83000000", "0.00685000"], ["72688.98000000", "0.00000000"], ["72688.90000000", "0.00000000"], ["72686.71000000", "1.19798000"], ["72686.06000000", "0.00000000"], ["72679.94000000", "0.00000000"], ["72674.90000000", "0.02702000"], ["72671.23000000", "0.00000000"], ["72668.61000000", "0.38828000"], ["72660.94000000", "0.42720000"], ["72659.74000000", "1.04047000"], ["72642.77000000", "0.00000000"], ["72639.80000000", "0.04710000"], ["72629.40000000", "0.00137000"], ["72616.28000000", "0.00000000"], ["72616.27000000", "0.00000000"], ["72601.16000000", "0.00000000"], ["72592.25000000", "0.00000000"], ["72588.00000000", "0.24581000"], ["72586.00000000", "0.02393000"], ["72584.00000000", "0.02000000"], ["72582.00000000", "0.02007000"], ["72580.00000000", "0.59479000"], ["72578.00000000", "0.02000000"], ["72576.00000000", "0.02000000"], ["72574.00000000", "0.02230000"], ["72572.00000000", "0.02000000"], ["72570.00000000", "0.03502000"], ["72568.00000000", "0.02726000"], ["72566.00000000", "0.32178000"], ["72516.58000000", "0.00000000"], ["72511.11000000", "0.00822000"], ["72506.81000000", "0.00000000"], ["71777.00000000", "0.16325000"], ["65447.36000000", "0.00086000"]], "a": [["72719.29000000", "0.13291000"], ["72719.30000000", "0.00064000"], ["72719.79000000", "0.00000000"], ["72720.00000000", "0.02096000"], ["72720.39000000", "0.00000000"], ["72720.59000000", "0.00016000"], ["72720.60000000", "0.16851000"], ["72720.64000000", "0.00024000"], ["72720.65000000", "0.50406000"], ["72720.66000000", "0.50016000"], ["72721.74000000", "0.00000000"], ["72721.90000000", "0.00016000"], ["72721.91000000", "0.16851000"], ["72721.92000000", "0.00000000"], ["72721.93000000", "0.00016000"], ["72722.00000000", "0.02296000"], ["72722.01000000", "0.00000000"], ["72722.02000000", "0.40016000"], ["72722.29000000", "0.01404000"], ["72722.46000000", "0.00031000"], ["72722.58000000", "0.00000000"], ["72722.96000000", "0.00000000"], ["72722.97000000", "0.65965000"], ["72723.56000000", "0.00000000"], ["72724.00000000", "0.02296000"], ["72724.06000000", "0.20830000"], ["72724.09000000", "0.01882000"], ["72724.18000000", "0.00031000"], ["72724.42000000", "0.00000000"], ["72724.53000000", "0.15229000"], ["72724.97000000", "0.00000000"], ["72725.08000000", "0.00000000"], ["72725.12000000", "0.00000000"], ["72725.84000000", "0.16851000"], ["72726.59000000", "0.00031000"], ["72726.83000000", "0.00000000"], ["72726.84000000", "0.12084000"], ["72727.15000000", "0.16851000"], ["72727.42000000", "0.00000000"], ["72727.70000000", "0.00000000"], ["72728.19000000", "0.00000000"], ["72729.61000000", "0.16602000"], ["72729.77000000", "0.16851000"], ["72731.58000000", "0.00000000"], ["72731.59000000", "0.29786000"], ["72731.86000000", "0.00192000"], ["72731.91000000", "0.00000000"], ["72733.48000000", "0.16602000"], ["72734.78000000", "0.16610000"], ["72740.36000000", "0.96870000"], ["72743.09000000", "0.00119000"], ["72743.31000000", "0.38333000"], ["72743.93000000", "0.68836000"], ["72744.12000000", "0.00000000"], ["72745.51000000", "0.16752000"], ["72745.53000000", "0.00000000"], ["72747.76000000", "0.02647000"], ["72752.98000000", "0.00000000"], ["72756.62000000", "1.03909000"], ["72757.22000000", "0.00435000"], ["72759.97000000", "0.00343000"], ["72760.47000000", "0.00000000"], ["72761.09000000", "0.00000000"], ["72763.00000000", "0.00000000"], ["72770.02000000", "0.00000000"], ["72770.62000000", "0.00000000"], ["72774.40000000", "0.09360000"], ["72774.92000000", "0.18446000"], ["72775.30000000", "0.00112000"], ["72775.71000000", "0.01731000"], ["72775.74000000", "0.00000000"], ["72775.92000000", "0.00189000"], ["72787.08000000", "1.73076000"], ["72822.75000000", "0.06161000"], ["72824.06000000", "0.00000000"], ["72825.80000000", "0.00000000"], ["72833.21000000", "0.00137000"], ["72848.44000000", "0.00075000"], ["72906.89000000", "0.00007000"], ["72910.52000000", "0.00007000"], ["72914.02000000", "0.00007000"], ["72917.65000000", "0.00000000"]], "_local_ts_utc": "2026-06-01T07:49:07.710738+00:00"}
{"e": "depthUpdate", "E": 1780300148915, "s": "BTCUSDT", "U": 94551793010, "u": 94551793770, "b": [["72721.97000000", "0.19250000"], ["72721.92000000", "0.14250000"], ["72721.90000000", "3.66936000"], ["72721.89000000", "0.00022000"], ["72721.88000000", "0.00014000"], ["72720.67000000", "0.00000000"], ["72720.66000000", "1.34389000"], ["72720.65000000", "3.61960000"], ["72720.64000000", "0.00000000"], ["72720.63000000", "0.00000000"], ["72720.60000000", "1.55885000"], ["72720.59000000", "0.52078000"], ["72720.58000000", "0.00000000"], ["72720.47000000", "0.00000000"], ["72720.31000000", "0.00000000"], ["72720.24000000", "0.00000000"], ["72720.23000000", "0.00000000"], ["72720.00000000", "0.86194000"], ["72719.99000000", "0.62754000"], ["72719.98000000", "0.00000000"], ["72719.97000000", "0.00000000"], ["72719.42000000", "0.00000000"], ["72719.30000000", "0.00008000"], ["72719.29000000", "0.00000000"], ["72719.28000000", "0.57852000"], ["72719.27000000", "0.00000000"], ["72719.26000000", "0.00000000"], ["72719.10000000", "0.13751000"], ["72718.95000000", "0.00000000"], ["72718.94000000", "0.00016000"], ["72718.93000000", "0.16466000"], ["72718.92000000", "0.20160000"], ["72718.67000000", "0.00000000"], ["72718.66000000", "0.00016000"], ["72718.31000000", "0.00000000"], ["72718.26000000", "0.00000000"], ["72718.25000000", "0.00000000"], ["72717.60000000", "0.00009000"], ["72717.41000000", "0.16602000"], ["72716.75000000", "0.00000000"], ["72716.70000000", "0.16602000"], ["72716.28000000", "0.04051000"], ["72715.41000000", "0.16602000"], ["72715.33000000", "0.16935000"], ["72715.14000000", "0.01392000"], ["72714.66000000", "0.00000000"], ["72714.65000000", "0.00000000"], ["72714.53000000", "0.16203000"], ["72712.91000000", "0.16602000"], ["72712.85000000", "0.16602000"], ["72712.83000000", "0.00000000"], ["72712.81000000", "0.18034000"], ["72712.16000000", "0.00011000"], ["72712.06000000", "0.00000000"], ["72711.23000000", "0.00000000"], ["72711.05000000", "0.16662000"], ["72711.04000000", "0.02610000"], ["72711.03000000", "0.12795000"], ["72711.02000000", "0.66065000"], ["72710.55000000", "0.07006000"], ["72708.96000000", "0.00000000"], ["72708.93000000", "0.03000000"], ["72708.92000000", "0.00000000"], ["72707.94000000", "0.16602000"], ["72707.90000000", "0.00000000"], ["72707.85000000", "0.02000000"], ["72707.28000000", "0.00007000"], ["72707.03000000", "0.16610000"], ["72705.77000000", "0.00000000"], ["72705.64000000", "0.00000000"], ["72705.13000000", "0.16602000"], ["72704.06000000", "1.29733000"], ["72704.05000000", "2.75063000"], ["72704.04000000", "0.00000000"], ["72702.81000000", "0.00000000"], ["72702.51000000", "0.00000000"], ["72701.86000000", "0.04000000"], ["72701.85000000", "0.04000000"], ["72701.22000000", "0.00000000"], ["72701.14000000", "0.00000000"], ["72701.10000000", "0.00000000"], ["72700.93000000", "0.12000000"], ["72700.54000000", "0.00000000"], ["72700.12000000", "0.00000000"], ["72698.64000000", "0.00011000"], ["72697.35000000", "0.16859000"], ["72696.15000000", "0.00008000"], ["72696.01000000", "0.00000000"], ["72694.98000000", "1.36357000"], ["72692.21000000", "0.00000000"], ["72690.80000000", "0.00000000"], ["72689.83000000", "0.00000000"], ["72688.90000000", "0.00000000"], ["72687.49000000", "0.00000000"], ["72684.72000000", "0.49591000"], ["72684.31000000", "0.00412000"], ["72678.81000000", "0.02678000"], ["72678.64000000", "0.00000000"], ["72678.00000000", "1.05330000"], ["72674.90000000", "0.00000000"], ["72664.48000000", "0.00000000"], ["72662.47000000", "0.00428000"], ["72659.74000000", "0.00000000"], ["72647.92000000", "0.00000000"], ["72641.09000000", "0.00111000"], ["72640.00000000", "0.21030000"], ["72624.96000000", "0.00000000"], ["72622.68000000", "0.20437000"], ["72622.67000000", "0.00000000"], ["72622.66000000", "0.00000000"], ["72606.70000000", "0.00000000"], ["72564.00000000", "0.02027000"], ["72562.00000000", "0.02000000"], ["72560.00000000", "0.13717000"], ["72558.00000000", "0.45146000"], ["72556.00000000", "0.02008000"], ["72554.00000000", "0.02089000"], ["72552.00000000", "0.02000000"], ["72550.00000000", "1.87134000"], ["72519.85000000", "0.00000000"], ["72511.10000000", "0.00000000"], ["72160.00000000", "0.02324000"], ["65448.00000000", "0.00000000"], ["65447.36000000", "0.00035000"]], "a": [["72719.29000000", "0.00000000"], ["72719.30000000", "0.00000000"], ["72719.43000000", "0.00000000"], ["72719.99000000", "0.00000000"], ["72720.00000000", "0.00000000"], ["72720.01000000", "0.00000000"], ["72720.32000000", "0.00000000"], ["72720.48000000", "0.00000000"], ["72720.59000000", "0.00000000"], ["72720.60000000", "0.00000000"], ["72720.64000000", "0.00000000"], ["72720.65000000", "0.00000000"], ["72720.66000000", "0.00000000"], ["72721.90000000", "0.00000000"], ["72721.91000000", "0.00000000"], ["72721.93000000", "0.00000000"], ["72721.99000000", "0.00016000"], ["72722.01000000", "0.00016000"], ["72722.29000000", "0.00016000"], ["72722.39000000", "0.00000000"], ["72722.46000000", "0.00000000"], ["72722.52000000", "0.00015000"], ["72722.79000000", "0.00000000"], ["72722.96000000", "0.00000000"], ["72722.97000000", "0.00016000"], ["72723.99000000", "0.00016000"], ["72724.00000000", "0.02296000"], ["72724.05000000", "0.00000000"], ["72724.06000000", "0.00016000"], ["72724.07000000", "0.00016000"], ["72724.09000000", "0.00008000"], ["72724.18000000", "0.00000000"], ["72724.21000000", "0.00000000"], ["72724.32000000", "0.00008000"], ["72724.34000000", "0.00000000"], ["72724.53000000", "0.00000000"], ["72724.60000000", "0.00000000"], ["72724.99000000", "0.00008000"], ["72725.06000000", "0.00000000"], ["72725.17000000", "0.00560000"], ["72725.38000000", "0.00000000"], ["72725.84000000", "0.00000000"], ["72725.89000000", "0.00000000"], ["72725.99000000", "0.00016000"], ["72726.59000000", "0.00000000"], ["72726.84000000", "0.00000000"], ["72727.01000000", "0.00000000"], ["72727.15000000", "0.00000000"], ["72727.43000000", "0.00016000"], ["72727.44000000", "0.00000000"], ["72727.69000000", "0.00000000"], ["72727.70000000", "0.00000000"], ["72727.71000000", "0.00000000"], ["72727.73000000", "0.00000000"], ["72727.79000000", "0.00000000"], ["72727.88000000", "0.00000000"], ["72728.00000000", "0.02280000"], ["72728.63000000", "0.00000000"], ["72729.60000000", "0.40856000"], ["72729.61000000", "0.00000000"], ["72729.77000000", "0.00000000"], ["72729.83000000", "0.00008000"], ["72730.40000000", "0.00000000"], ["72730.48000000", "0.00000000"], ["72730.53000000", "0.02000000"], ["72731.06000000", "0.25025000"], ["72731.07000000", "0.00000000"], ["72731.08000000", "0.00000000"], ["72731.28000000", "0.00031000"], ["72731.58000000", "0.10000000"], ["72731.59000000", "0.00000000"], ["72733.48000000", "0.00000000"], ["72733.60000000", "0.00000000"], ["72733.70000000", "0.00000000"], ["72733.88000000", "0.00000000"], ["72734.19000000", "0.00000000"], ["72734.78000000", "0.00008000"], ["72734.79000000", "0.40842000"], ["72736.32000000", "0.00000000"], ["72736.99000000", "0.00000000"], ["72737.03000000", "0.00000000"], ["72737.99000000", "0.00000000"], ["72738.14000000", "0.00000000"], ["72740.35000000", "0.00000000"], ["72743.93000000", "0.00000000"], ["72745.51000000", "0.35098000"], ["72747.28000000", "0.00000000"], ["72747.75000000", "0.68838000"], ["72747.76000000", "0.00000000"], ["72748.15000000", "0.00200000"], ["72754.69000000", "0.00200000"], ["72755.73000000", "0.00007000"], ["72756.62000000", "0.00000000"], ["72756.96000000", "0.00000000"], ["72757.72000000", "0.33596000"], ["72757.86000000", "0.00000000"], ["72762.56000000", "0.00000000"], ["72770.02000000", "0.00000000"], ["72770.40000000", "0.00000000"], ["72774.92000000", "0.00000000"], ["72775.92000000", "0.00000000"], ["72777.95000000", "0.49527000"], ["72779.83000000", "0.00000000"], ["72783.58000000", "0.07046000"], ["72785.97000000", "0.98741000"], ["72787.04000000", "1.36184000"], ["72789.98000000", "0.18446000"], ["72800.00000000", "0.02613000"], ["72812.36000000", "0.96906000"], ["72812.37000000", "2.75063000"], ["72812.38000000", "0.00000000"], ["72822.75000000", "0.02604000"], ["72827.00000000", "0.04268000"], ["72839.64000000", "0.12980000"], ["72841.09000000", "0.11495000"], ["72844.27000000", "0.06819000"], ["72848.44000000", "0.00000000"], ["73280.00000000", "0.00716000"], ["85045.16000000", "0.00057000"]], "_local_ts_utc": "2026-06-01T07:49:07.811751+00:00"}
{"e": "depthUpdate", "E": 1780300149014, "s": "BTCUSDT", "U": 94551793771, "u": 94551795252, "b": [["72731.05000000", "3.61504000"], ["72731.04000000", "0.00038000"], ["72731.03000000", "0.00014000"], ["72730.02000000", "0.05583000"], ["72730.01000000", "0.00000000"], ["72730.00000000", "0.00000000"], ["72729.99000000", "0.00016000"], ["72729.90000000", "0.00007000"], ["72729.89000000", "0.00000000"], ["72729.76000000", "0.00000000"], ["72729.59000000", "0.00016000"], ["72729.58000000", "0.00000000"], ["72729.15000000", "0.00000000"], ["72729.14000000", "0.00016000"], ["72729.01000000", "0.00000000"], ["72728.93000000", "0.00016000"], ["72728.92000000", "0.03457000"], ["72728.47000000", "0.00000000"], ["72727.99000000", "0.00000000"], ["72727.84000000", "0.00016000"], ["72727.83000000", "0.04051000"], ["72727.82000000", "0.00000000"], ["72727.18000000", "0.00000000"], ["72727.08000000", "0.00000000"], ["72726.60000000", "0.00016000"], ["72726.59000000", "0.05942000"], ["72726.21000000", "0.00007000"], ["72726.00000000", "0.00016000"], ["72725.99000000", "0.16535000"], ["72725.89000000", "0.00000000"], ["72725.16000000", "0.00000000"], ["72724.71000000", "0.00000000"], ["72724.61000000", "0.00000000"], ["72724.60000000", "0.16600000"], ["72724.15000000", "0.00000000"], ["72724.08000000", "0.00000000"], ["72724.06000000", "0.00000000"], ["72724.05000000", "0.00000000"], ["72724.01000000", "0.00000000"], ["72724.00000000", "0.46624000"], ["72723.99000000", "0.00016000"], ["72723.59000000", "0.00008000"], ["72723.58000000", "0.65949000"], ["72723.57000000", "0.56935000"], ["72723.56000000", "0.00000000"], ["72723.55000000", "0.00000000"], ["72722.96000000", "0.00000000"], ["72722.52000000", "0.00007000"], ["72722.51000000", "0.27655000"], ["72722.50000000", "0.00811000"], ["72722.49000000", "0.00530000"], ["72722.29000000", "0.00000000"], ["72722.28000000", "0.00016000"], ["72722.27000000", "0.00000000"], ["72722.26000000", "0.00016000"], ["72722.08000000", "0.00000000"], ["72722.06000000", "0.00000000"], ["72722.04000000", "0.95867000"], ["72722.03000000", "0.00008000"], ["72722.02000000", "0.06762000"], ["72722.01000000", "0.12672000"], ["72722.00000000", "0.00000000"], ["72721.99000000", "0.10460000"], ["72721.98000000", "0.00000000"], ["72721.97000000", "0.05000000"], ["72721.96000000", "0.00000000"], ["72721.92000000", "0.00000000"], ["72721.91000000", "0.00000000"], ["72721.90000000", "0.08000000"], ["72721.89000000", "0.00000000"], ["72721.88000000", "0.00000000"], ["72720.67000000", "0.40856000"], ["72720.66000000", "0.00000000"], ["72720.65000000", "0.21715000"], ["72720.64000000", "0.00000000"], ["72720.62000000", "0.00028000"], ["72720.60000000", "0.00000000"], ["72720.59000000", "0.19001000"], ["72720.47000000", "0.00000000"], ["72720.32000000", "0.00765000"], ["72720.14000000", "0.01352000"], ["72720.01000000", "0.00000000"], ["72720.00000000", "0.86194000"], ["72719.99000000", "0.27972000"], ["72719.54000000", "0.00011000"], ["72719.30000000", "0.00008000"], ["72719.29000000", "0.04642000"], ["72719.28000000", "0.04896000"], ["72719.10000000", "0.00000000"], ["72719.03000000", "0.00000000"], ["72718.94000000", "0.00000000"], ["72718.93000000", "0.00000000"], ["72718.92000000", "0.09000000"], ["72718.66000000", "0.00000000"], ["72718.34000000", "0.00007000"], ["72718.33000000", "0.00740000"], ["72717.42000000", "0.77202000"], ["72717.41000000", "0.00000000"], ["72717.35000000", "0.00000000"], ["72717.33000000", "0.00000000"], ["72716.85000000", "0.00000000"], ["72716.70000000", "0.00000000"], ["72716.36000000", "0.00773000"], ["72716.28000000", "0.00000000"], ["72715.83000000", "0.00000000"], ["72715.79000000", "0.00047000"], ["72715.69000000", "0.16485000"], ["72715.57000000", "0.15770000"], ["72715.56000000", "0.00000000"], ["72715.50000000", "0.00191000"], ["72715.41000000", "0.00000000"], ["72715.34000000", "0.17601000"], ["72715.33000000", "0.00000000"], ["72715.06000000", "0.00028000"], ["72714.69000000", "0.00300000"], ["72714.68000000", "0.00000000"], ["72714.67000000", "0.00000000"], ["72714.53000000", "0.05014000"], ["72714.33000000", "0.00007000"], ["72714.32000000", "0.01376000"], ["72714.28000000", "0.16599000"], ["72714.04000000", "0.00000000"], ["72713.57000000", "0.00000000"], ["72713.25000000", "0.00000000"], ["72712.99000000", "0.16599000"], ["72712.98000000", "0.00000000"], ["72712.94000000", "0.00000000"], ["72712.91000000", "0.00000000"], ["72712.85000000", "0.00000000"], ["72712.82000000", "0.00000000"], ["72712.81000000", "0.18007000"], ["72712.41000000", "0.00000000"], ["72712.40000000", "0.40856000"], ["72712.07000000", "2.06845000"], ["72712.06000000", "2.75063000"], ["72712.04000000", "0.00000000"], ["72711.97000000", "0.00000000"], ["72711.70000000", "0.37025000"], ["72711.62000000", "0.03407000"], ["72711.05000000", "0.00011000"], ["72710.88000000", "0.00021000"], ["72710.56000000", "0.00000000"], ["72710.55000000", "0.06998000"], ["72709.88000000", "0.00008000"], ["72708.51000000", "0.00000000"], ["72708.30000000", "0.00000000"], ["72708.29000000", "0.00000000"], ["72707.94000000", "0.00000000"], ["72707.03000000", "0.00008000"], ["72706.31000000", "0.00000000"], ["72705.82000000", "0.00000000"], ["72705.13000000", "0.00000000"], ["72705.12000000", "0.40856000"], ["72705.08000000", "0.00000000"], ["72704.53000000", "0.00000000"], ["72704.43000000", "0.00000000"], ["72704.35000000", "0.04000000"], ["72704.32000000", "0.00000000"], ["72704.16000000", "0.00000000"], ["72704.07000000", "0.00007000"], ["72703.56000000", "0.00208000"], ["72702.98000000", "0.00000000"], ["72702.70000000", "0.02260000"], ["72702.55000000", "0.02466000"], ["72701.96000000", "0.00000000"], ["72701.94000000", "0.00000000"], ["72701.86000000", "0.00000000"], ["72701.85000000", "0.00000000"], ["72698.08000000", "0.00007000"], ["72697.70000000", "0.00000000"], ["72697.46000000", "0.00137000"], ["72697.44000000", "0.00000000"], ["72697.35000000", "0.00008000"], ["72695.99000000", "0.00007000"], ["72695.71000000", "0.00686000"], ["72695.06000000", "0.00190000"], ["72694.51000000", "0.00000000"], ["72694.44000000", "0.00000000"], ["72693.97000000", "0.00117000"], ["72693.80000000", "0.38827000"], ["72693.62000000", "0.00012000"], ["72693.00000000", "0.00000000"], ["72692.80000000", "0.64273000"], ["72692.62000000", "0.00000000"], ["72690.88000000", "0.00000000"], ["72690.84000000", "0.49587000"], ["72690.19000000", "0.00000000"], ["72689.31000000", "0.00000000"], ["72687.10000000", "0.00000000"], ["72686.68000000", "0.00008000"], ["72686.56000000", "0.00010000"], ["72686.05000000", "0.00000000"], ["72685.62000000", "0.00000000"], ["72683.02000000", "0.00007000"], ["72680.66000000", "0.00000000"], ["72680.11000000", "0.00000000"], ["72679.89000000", "0.00000000"], ["72679.28000000", "0.00000000"], ["72677.45000000", "0.00000000"], ["72674.18000000", "0.00000000"], ["72667.16000000", "0.00434000"], ["72665.43000000", "0.00000000"], ["72661.79000000", "0.00000000"], ["72660.95000000", "0.13256000"], ["72660.94000000", "0.00000000"], ["72658.32000000", "0.00008000"], ["72654.86000000", "0.00000000"], ["72651.61000000", "0.00137000"], ["72651.02000000", "0.00000000"], ["72650.04000000", "0.00000000"], ["72650.03000000", "0.42000000"], ["72649.29000000", "0.00282000"], ["72646.54000000", "0.01735000"], ["72646.20000000", "0.00000000"], ["72634.33000000", "0.62064000"], ["72634.30000000", "0.00000000"], ["72630.21000000", "0.00000000"], ["72630.20000000", "0.00000000"], ["72630.01000000", "0.08751000"], ["72629.62000000", "0.00000000"], ["72629.61000000", "0.00000000"], ["72629.58000000", "0.00000000"], ["72624.81000000", "0.04676000"], ["72622.68000000", "0.00000000"], ["72605.61000000", "0.00000000"], ["72585.59000000", "0.00008000"], ["72573.48000000", "0.00000000"], ["72548.51000000", "0.00000000"], ["72548.45000000", "0.00000000"], ["72546.22000000", "0.02154000"], ["72523.84000000", "0.00000000"], ["72521.90000000", "0.00000000"], ["72512.86000000", "0.00008000"], ["72500.76000000", "0.00000000"], ["72488.61000000", "0.28066000"], ["72451.98000000", "0.00000000"], ["72440.13000000", "0.00008000"], ["72428.04000000", "0.00000000"], ["72367.39000000", "0.00008000"], ["72355.33000000", "0.00000000"], ["72294.66000000", "0.00111000"], ["72282.61000000", "0.00000000"], ["72221.93000000", "0.00008000"], ["72209.89000000", "0.00000000"], ["72149.20000000", "0.00008000"], ["72137.17000000", "0.00000000"], ["71992.08000000", "0.00007000"], ["71983.42000000", "0.00000000"], ["65457.95000000", "0.00034000"], ["58184.84000000", "0.00034000"]], "a": [["72721.98000000", "0.00000000"], ["72721.99000000", "0.00000000"], ["72722.00000000", "0.00000000"], ["72722.01000000", "0.00000000"], ["72722.02000000", "0.00000000"], ["72722.03000000", "0.00000000"], ["72722.07000000", "0.00000000"], ["72722.29000000", "0.00000000"], ["72722.50000000", "0.00000000"], ["72722.52000000", "0.00000000"], ["72722.97000000", "0.00000000"], ["72723.58000000", "0.00000000"], ["72723.99000000", "0.00000000"], ["72724.00000000", "0.00000000"], ["72724.06000000", "0.00000000"], ["72724.07000000", "0.00000000"], ["72724.09000000", "0.00000000"], ["72724.16000000", "0.00000000"], ["72724.32000000", "0.00000000"], ["72724.72000000", "0.00000000"], ["72724.99000000", "0.00000000"], ["72725.07000000", "0.00000000"], ["72725.16000000", "0.00000000"], ["72725.17000000", "0.00000000"], ["72725.26000000", "0.00000000"], ["72725.77000000", "0.00000000"], ["72725.99000000", "0.00000000"], ["72726.00000000", "0.00000000"], ["72726.21000000", "0.00000000"], ["72726.55000000", "0.00000000"], ["72726.57000000", "0.00000000"], ["72726.60000000", "0.00000000"], ["72727.09000000", "0.00000000"], ["72727.20000000", "0.00000000"], ["72727.43000000", "0.00000000"], ["72727.74000000", "0.00000000"], ["72727.78000000", "0.00000000"], ["72727.82000000", "0.00000000"], ["72727.83000000", "0.00000000"], ["72727.84000000", "0.00000000"], ["72727.99000000", "0.00000000"], ["72728.00000000", "0.00000000"], ["72728.17000000", "0.00000000"], ["72728.40000000", "0.00000000"], ["72728.41000000", "0.00000000"], ["72729.01000000", "0.00000000"], ["72729.02000000", "0.00000000"], ["72729.09000000", "0.00000000"], ["72729.15000000", "0.00000000"], ["72729.59000000", "0.00000000"], ["72729.60000000", "0.00000000"], ["72729.83000000", "0.00000000"], ["72729.90000000", "0.00000000"], ["72729.94000000", "0.00000000"], ["72730.00000000", "0.00000000"], ["72730.21000000", "0.00000000"], ["72730.39000000", "0.00000000"], ["72730.53000000", "0.00000000"], ["72730.62000000", "0.00000000"], ["72730.63000000", "0.00000000"], ["72730.77000000", "0.00000000"], ["72730.84000000", "0.00000000"], ["72731.04000000", "0.00000000"], ["72731.06000000", "1.17917000"], ["72731.07000000", "0.00048000"], ["72731.28000000", "0.00000000"], ["72731.37000000", "0.00000000"], ["72731.58000000", "0.00000000"], ["72731.65000000", "0.00000000"], ["72731.72000000", "0.00000000"], ["72731.86000000", "0.00000000"], ["72731.98000000", "0.00016000"], ["72731.99000000", "0.06831000"], ["72732.11000000", "0.00763000"], ["72732.30000000", "0.00028000"], ["72732.35000000", "0.00013000"], ["72732.49000000", "0.00000000"], ["72732.60000000", "0.00016000"], ["72732.66000000", "0.00000000"], ["72733.03000000", "0.00000000"], ["72733.04000000", "0.00000000"], ["72733.35000000", "0.00031000"], ["72733.62000000", "0.16485000"], ["72733.63000000", "0.00016000"], ["72733.64000000", "0.16599000"], ["72733.85000000", "0.00000000"], ["72733.99000000", "0.00008000"], ["72734.08000000", "0.00000000"], ["72734.76000000", "0.51446000"], ["72734.77000000", "0.00000000"], ["72734.78000000", "0.65957000"], ["72734.79000000", "0.00000000"], ["72734.82000000", "0.00000000"], ["72735.50000000", "0.00000000"], ["72735.99000000", "0.16485000"], ["72736.01000000", "0.12085000"], ["72736.02000000", "0.03888000"], ["72736.22000000", "0.16599000"], ["72736.53000000", "0.00300000"], ["72736.87000000", "0.03407000"], ["72737.00000000", "0.00000000"], ["72737.03000000", "0.00000000"], ["72737.04000000", "0.00000000"], ["72737.22000000", "0.00031000"], ["72737.29000000", "0.00031000"], ["72737.94000000", "0.00155000"], ["72738.04000000", "0.02000000"], ["72738.14000000", "0.82550000"], ["72738.15000000", "0.00000000"], ["72738.34000000", "0.00185000"], ["72738.51000000", "0.00000000"], ["72738.66000000", "0.00000000"], ["72739.17000000", "0.00000000"], ["72739.99000000", "0.15330000"], ["72740.06000000", "0.15852000"], ["72740.34000000", "0.16599000"], ["72740.35000000", "0.00000000"], ["72740.63000000", "0.00000000"], ["72741.00000000", "0.00000000"], ["72741.26000000", "0.16309000"], ["72741.36000000", "0.07000000"], ["72741.90000000", "0.00000000"], ["72741.98000000", "0.15170000"], ["72741.99000000", "1.36977000"], ["72742.66000000", "0.00191000"], ["72743.20000000", "2.75071000"], ["72743.21000000", "0.00000000"], ["72743.31000000", "0.00000000"], ["72743.43000000", "0.00007000"], ["72745.07000000", "0.00000000"], ["72745.50000000", "0.01300000"], ["72745.51000000", "0.10480000"], ["72745.52000000", "0.00000000"], ["72745.76000000", "0.00000000"], ["72747.75000000", "0.00000000"], ["72747.83000000", "0.16599000"], ["72748.16000000", "0.08000000"], ["72748.43000000", "0.00275000"], ["72749.06000000", "0.16789000"], ["72751.29000000", "0.00012000"], ["72751.64000000", "0.02728000"], ["72751.99000000", "0.68828000"], ["72752.91000000", "0.00000000"], ["72753.04000000", "0.58536000"], ["72754.97000000", "0.45893000"], ["72756.03000000", "0.00000000"], ["72757.22000000", "0.00000000"], ["72757.45000000", "0.00000000"], ["72759.42000000", "0.00007000"], ["72759.80000000", "0.00199000"], ["72759.97000000", "0.00000000"], ["72760.56000000", "0.00000000"], ["72761.77000000", "0.00200000"], ["72763.11000000", "0.00007000"], ["72763.62000000", "0.00000000"], ["72764.09000000", "0.00007000"], ["72764.10000000", "0.07168000"], ["72764.11000000", "0.00000000"], ["72765.99000000", "0.10000000"], ["72766.80000000", "0.00007000"], ["72766.81000000", "0.00000000"], ["72768.60000000", "0.00000000"], ["72769.29000000", "0.00434000"], ["72770.42000000", "0.00433000"], ["72771.23000000", "0.69557000"], ["72771.41000000", "0.23247000"], ["72771.46000000", "1.36213000"], ["72771.56000000", "0.00344000"], ["72774.53000000", "0.43387000"], ["72777.17000000", "0.00000000"], ["72782.00000000", "0.02280000"], ["72782.18000000", "0.00000000"], ["72782.19000000", "0.18721000"], ["72782.63000000", "0.01084000"], ["72784.49000000", "0.00000000"], ["72785.53000000", "0.08200000"], ["72787.03000000", "0.00000000"], ["72787.32000000", "0.02752000"], ["72787.65000000", "0.00000000"], ["72792.01000000", "0.00000000"], ["72792.03000000", "0.65949000"], ["72792.12000000", "0.20096000"], ["72793.34000000", "0.45968000"], ["72793.37000000", "0.73784000"], ["72794.76000000", "0.00342000"], ["72795.33000000", "0.18446000"], ["72800.42000000", "1.01765000"], ["72802.88000000", "0.00000000"], ["72803.35000000", "0.00008000"], ["72820.66000000", "2.25630000"], ["72820.67000000", "2.75063000"], ["72821.06000000", "0.00009000"], ["72833.21000000", "0.00000000"], ["72833.92000000", "0.00412000"], ["72844.27000000", "0.06956000"], ["72847.98000000", "0.00000000"], ["72848.44000000", "1.37171000"], ["72857.99000000", "0.00137000"], ["72861.16000000", "0.00000000"], ["72864.37000000", "0.00000000"], ["72864.73000000", "0.00000000"], ["72876.08000000", "0.00008000"], ["72876.52000000", "0.00010000"], ["72918.01000000", "0.00007000"], ["72921.64000000", "0.00007000"], ["73010.17000000", "0.00007000"], ["73021.54000000", "0.00008000"], ["73082.89000000", "0.00000000"], ["73089.69000000", "0.00007000"], ["73094.27000000", "0.00008000"], ["73228.33000000", "0.00000000"], ["73239.73000000", "0.00008000"], ["73298.39000000", "0.00000000"], ["73437.65000000", "0.00000000"], ["73446.49000000", "0.00007000"]], "_local_ts_utc": "2026-06-01T07:49:07.912768+00:00"}
{"e": "depthUpdate", "E": 1780300149114, "s": "BTCUSDT", "U": 94551795253, "u": 94551795581, "b": [["72731.05000000", "0.18585000"], ["72730.03000000", "0.00000000"], ["72730.02000000", "0.00016000"], ["72729.99000000", "0.00000000"], ["72729.59000000", "0.00000000"], ["72729.14000000", "0.00000000"], ["72728.93000000", "0.00000000"], ["72728.92000000", "0.00016000"], ["72728.73000000", "0.00000000"], ["72728.72000000", "0.00000000"], ["72728.09000000", "0.00016000"], ["72728.08000000", "0.00000000"], ["72727.83000000", "0.04067000"], ["72726.60000000", "0.00000000"], ["72726.59000000", "0.00016000"], ["72726.06000000", "0.00450000"], ["72726.00000000", "0.00000000"], ["72725.99000000", "0.00016000"], ["72725.76000000", "0.00000000"], ["72725.60000000", "0.00000000"], ["72724.60000000", "0.00047000"], ["72724.01000000", "0.00016000"], ["72724.00000000", "0.06391000"], ["72723.99000000", "0.00000000"], ["72723.58000000", "0.00032000"], ["72723.57000000", "0.06329000"], ["72723.29000000", "0.05942000"], ["72722.51000000", "0.00000000"], ["72722.50000000", "0.00054000"], ["72722.33000000", "0.00000000"], ["72722.28000000", "0.00000000"], ["72722.26000000", "0.00000000"], ["72722.05000000", "0.00008000"], ["72722.04000000", "0.18963000"], ["72721.97000000", "0.00000000"], ["72721.90000000", "0.00000000"], ["72720.67000000", "0.00000000"], ["72720.65000000", "0.16743000"], ["72720.62000000", "0.00000000"], ["72720.59000000", "0.00000000"], ["72720.48000000", "0.00008000"], ["72720.32000000", "0.00000000"], ["72720.00000000", "0.20245000"], ["72719.99000000", "0.18972000"], ["72719.29000000", "0.02218000"], ["72719.28000000", "0.00896000"], ["72718.92000000", "0.05000000"], ["72718.68000000", "0.00573000"], ["72717.42000000", "0.00000000"], ["72715.69000000", "0.00000000"], ["72715.57000000", "0.00000000"], ["72715.34000000", "0.07691000"], ["72714.98000000", "0.65949000"], ["72714.28000000", "0.00000000"], ["72713.13000000", "0.16485000"], ["72712.99000000", "0.00000000"], ["72712.41000000", "0.16485000"], ["72712.07000000", "1.48276000"], ["72712.06000000", "0.00000000"], ["72711.71000000", "0.77208000"], ["72711.62000000", "0.00000000"], ["72707.85000000", "0.00000000"], ["72706.06000000", "0.04000000"], ["72705.58000000", "0.00000000"], ["72705.44000000", "0.00008000"], ["72705.15000000", "0.02000000"], ["72704.42000000", "0.02000000"], ["72704.35000000", "0.00000000"], ["72704.16000000", "0.00000000"], ["72701.95000000", "0.00000000"], ["72700.27000000", "0.02000000"], ["72694.98000000", "0.00000000"], ["72694.32000000", "0.00000000"], ["72693.42000000", "0.00072000"], ["72690.84000000", "0.00000000"], ["72682.89000000", "0.02741000"], ["72681.73000000", "0.00343000"], ["72678.81000000", "0.00000000"], ["72676.00000000", "0.03429000"], ["72668.61000000", "0.76155000"], ["72666.29000000", "0.49603000"], ["72666.18000000", "1.04449000"], ["72661.36000000", "0.00000000"], ["72658.31000000", "0.00685000"], ["72651.61000000", "0.00000000"], ["72650.27000000", "0.00711000"], ["72634.35000000", "1.44147000"], ["72634.34000000", "2.74985000"], ["72634.33000000", "0.00000000"], ["72618.05000000", "0.04479000"], ["72608.76000000", "0.00137000"], ["72607.60000000", "0.00000000"], ["72588.48000000", "0.00000000"], ["72548.45000000", "0.09872000"], ["72546.22000000", "0.00000000"], ["72443.99000000", "4.14634000"], ["65457.95000000", "0.00068000"]], "a": [["72731.06000000", "3.80933000"], ["72731.07000000", "0.00016000"], ["72731.66000000", "0.00031000"], ["72731.83000000", "0.03407000"], ["72731.98000000", "0.00000000"], ["72731.99000000", "0.15494000"], ["72732.00000000", "0.02296000"], ["72732.11000000", "0.00779000"], ["72732.12000000", "0.13749000"], ["72732.34000000", "0.16485000"], ["72732.60000000", "0.00000000"], ["72732.61000000", "0.01410000"], ["72732.95000000", "0.05942000"], ["72733.61000000", "0.00000000"], ["72733.62000000", "0.16501000"], ["72733.63000000", "0.00000000"], ["72733.64000000", "0.16615000"], ["72733.99000000", "0.00000000"], ["72734.00000000", "0.02296000"], ["72734.22000000", "0.00000000"], ["72734.76000000", "0.51462000"], ["72736.02000000", "0.00000000"], ["72737.22000000", "0.00000000"], ["72737.29000000", "0.00000000"], ["72738.04000000", "0.00000000"], ["72738.34000000", "0.00000000"], ["72742.66000000", "0.00000000"], ["72743.19000000", "0.16348000"], ["72745.11000000", "0.16485000"], ["72745.51000000", "0.18521000"], ["72745.60000000", "0.05408000"], ["72746.42000000", "0.14942000"], ["72747.70000000", "0.16485000"], ["72748.15000000", "0.00000000"], ["72751.54000000", "0.16485000"], ["72751.64000000", "0.00000000"], ["72752.82000000", "0.16485000"], ["72753.77000000", "0.16485000"], ["72755.45000000", "0.38333000"], ["72755.62000000", "0.02714000"], ["72760.16000000", "0.00686000"], ["72763.91000000", "0.68834000"], ["72763.92000000", "1.36227000"], ["72764.10000000", "0.00000000"], ["72766.67000000", "0.49535000"], ["72766.90000000", "0.00000000"], ["72768.07000000", "0.00000000"], ["72769.23000000", "1.03891000"], ["72781.16000000", "0.49525000"], ["72785.97000000", "0.69720000"], ["72787.08000000", "0.36892000"], ["72787.65000000", "0.00189000"], ["72787.83000000", "0.05400000"], ["72788.55000000", "0.05400000"], ["72822.75000000", "0.74771000"], ["72824.89000000", "2.43956000"], ["72827.00000000", "0.00000000"], ["72836.24000000", "0.04267000"], ["72861.16000000", "0.00075000"], ["72925.27000000", "0.00007000"], ["72928.90000000", "0.00007000"]], "_local_ts_utc": "2026-06-01T07:49:08.010446+00:00"}
{"e": "depthUpdate", "E": 1780300149214, "s": "BTCUSDT", "U": 94551795582, "u": 94551796353, "b": [["72731.05000000", "0.00000000"], ["72731.04000000", "0.00000000"], ["72731.03000000", "0.00000000"], ["72730.02000000", "0.00000000"], ["72729.90000000", "0.00000000"], ["72728.92000000", "0.00000000"], ["72728.09000000", "0.00000000"], ["72727.84000000", "0.00000000"], ["72727.83000000", "0.00000000"], ["72726.65000000", "0.00000000"], ["72726.59000000", "0.00000000"], ["72726.21000000", "0.00000000"], ["72726.06000000", "0.00000000"], ["72725.99000000", "0.00000000"], ["72725.72000000", "0.00000000"], ["72724.60000000", "0.00000000"], ["72724.01000000", "0.22744000"], ["72724.00000000", "0.05032000"], ["72723.58000000", "0.00016000"], ["72723.57000000", "0.06331000"], ["72723.30000000", "0.00000000"], ["72723.29000000", "0.00016000"], ["72722.49000000", "0.00016000"], ["72722.05000000", "0.00000000"], ["72722.04000000", "0.00016000"], ["72722.03000000", "0.00008000"], ["72722.02000000", "0.00032000"], ["72722.01000000", "0.07805000"], ["72722.00000000", "0.00016000"], ["72721.99000000", "0.10476000"], ["72720.66000000", "0.00008000"], ["72720.65000000", "0.16715000"], ["72720.42000000", "0.00000000"], ["72720.00000000", "0.00000000"], ["72719.99000000", "0.00000000"], ["72719.29000000", "0.00000000"], ["72719.07000000", "0.01357000"], ["72718.92000000", "0.00000000"], ["72718.59000000", "0.00000000"], ["72716.90000000", "0.00000000"], ["72716.51000000", "0.00014000"], ["72715.34000000", "0.07691000"], ["72714.98000000", "0.00000000"], ["72714.55000000", "0.04000000"], ["72714.54000000", "0.00000000"], ["72714.32000000", "0.00000000"], ["72713.13000000", "0.00000000"], ["72712.49000000", "0.15049000"], ["72712.41000000", "0.00000000"], ["72712.40000000", "0.00000000"], ["72712.09000000", "1.03245000"], ["72712.08000000", "0.65949000"], ["72712.07000000", "0.00008000"], ["72712.05000000", "0.00000000"], ["72712.03000000", "0.02103000"], ["72711.72000000", "0.00000000"], ["72711.71000000", "0.00000000"], ["72711.70000000", "0.00000000"], ["72711.02000000", "0.31552000"], ["72710.73000000", "0.01376000"], ["72710.42000000", "0.00048000"], ["72709.41000000", "0.12062000"], ["72708.93000000", "0.00000000"], ["72707.93000000", "0.15892000"], ["72707.02000000", "0.00000000"], ["72706.09000000", "0.16486000"], ["72706.06000000", "0.00000000"], ["72705.40000000", "0.01376000"], ["72705.12000000", "0.00000000"], ["72704.81000000", "0.16486000"], ["72704.09000000", "0.00000000"], ["72704.08000000", "0.94447000"], ["72704.07000000", "3.81797000"], ["72704.06000000", "0.00008000"], ["72704.05000000", "0.00000000"], ["72704.03000000", "0.00000000"], ["72703.53000000", "0.01000000"], ["72703.43000000", "0.02000000"], ["72700.42000000", "0.66001000"], ["72700.41000000", "0.66774000"], ["72700.27000000", "0.00000000"], ["72700.11000000", "0.00000000"], ["72700.08000000", "0.00000000"], ["72700.07000000", "0.00000000"], ["72700.01000000", "0.77284000"], ["72698.77000000", "0.02000000"], ["72697.35000000", "0.65957000"], ["72697.15000000", "0.00000000"], ["72696.15000000", "2.74993000"], ["72696.14000000", "0.40856000"], ["72696.13000000", "0.00000000"], ["72693.80000000", "0.16842000"], ["72693.00000000", "0.00007000"], ["72692.80000000", "0.00000000"], ["72691.03000000", "0.00000000"], ["72690.31000000", "0.00000000"], ["72689.31000000", "0.00007000"], ["72686.71000000", "0.56129000"], ["72686.67000000", "0.00000000"], ["72684.72000000", "0.00000000"], ["72683.78000000", "0.00102000"], ["72681.73000000", "0.00000000"], ["72676.01000000", "0.06799000"], ["72673.99000000", "0.00000000"], ["72668.61000000", "0.38828000"], ["72666.18000000", "0.00411000"], ["72660.95000000", "0.05497000"], ["72660.25000000", "0.00000000"], ["72658.31000000", "0.00000000"], ["72650.27000000", "0.00574000"], ["72649.29000000", "0.00000000"], ["72642.01000000", "0.00330000"], ["72639.38000000", "1.55248000"], ["72637.12000000", "4.13532000"], ["72635.11000000", "0.00000000"], ["72625.01000000", "0.02881000"], ["72624.81000000", "0.00000000"], ["72624.80000000", "0.00008000"], ["72622.70000000", "0.00000000"], ["72608.76000000", "0.00000000"], ["72522.54000000", "0.00007000"], ["72518.91000000", "0.00000000"], ["72405.71000000", "0.09668000"], ["71992.08000000", "0.00000000"], ["65457.95000000", "0.00000000"], ["65451.61000000", "0.00034000"], ["58184.84000000", "0.00000000"]], "a": [["72724.02000000", "9.71381000"], ["72724.03000000", "0.00024000"], ["72724.60000000", "0.59086000"], ["72724.61000000", "0.85132000"], ["72724.62000000", "0.00000000"], ["72724.73000000", "0.00000000"], ["72724.97000000", "0.00000000"], ["72725.05000000", "0.10485000"], ["72725.30000000", "0.00000000"], ["72725.61000000", "0.05942000"], ["72725.73000000", "0.00000000"], ["72726.00000000", "0.00000000"], ["72726.06000000", "0.00000000"], ["72726.07000000", "0.57661000"], ["72726.21000000", "0.00007000"], ["72726.22000000", "0.00000000"], ["72726.58000000", "0.16486000"], ["72726.59000000", "0.00008000"], ["72726.60000000", "0.71722000"], ["72726.64000000", "0.00000000"], ["72726.66000000", "0.00000000"], ["72727.18000000", "0.00270000"], ["72727.82000000", "0.00000000"], ["72727.83000000", "0.58679000"], ["72727.84000000", "1.48581000"], ["72727.85000000", "0.00000000"], ["72728.93000000", "0.00000000"], ["72729.12000000", "0.00000000"], ["72729.90000000", "0.00007000"], ["72729.91000000", "0.00000000"], ["72730.03000000", "0.00000000"], ["72730.40000000", "0.00000000"], ["72730.75000000", "0.65949000"], ["72731.04000000", "0.00000000"], ["72731.05000000", "0.00008000"], ["72731.06000000", "1.05548000"], ["72731.07000000", "0.00000000"], ["72731.64000000", "0.00000000"], ["72731.83000000", "0.00016000"], ["72731.98000000", "0.00008000"], ["72732.11000000", "0.00763000"], ["72732.12000000", "0.00000000"], ["72732.25000000", "0.00000000"], ["72732.34000000", "0.00000000"], ["72732.61000000", "0.01394000"], ["72732.95000000", "0.00000000"], ["72733.10000000", "0.00007000"], ["72733.24000000", "0.00008000"], ["72733.25000000", "0.11000000"], ["72733.62000000", "0.16485000"], ["72733.64000000", "0.00000000"], ["72733.90000000", "0.00000000"], ["72734.00000000", "0.02280000"], ["72734.26000000", "0.06076000"], ["72734.75000000", "0.16493000"], ["72734.76000000", "1.29931000"], ["72734.77000000", "0.00008000"], ["72734.78000000", "0.65949000"], ["72735.98000000", "0.00008000"], ["72735.99000000", "0.00000000"], ["72736.22000000", "0.00000000"], ["72737.02000000", "0.00000000"], ["72737.03000000", "0.00008000"], ["72737.04000000", "2.74985000"], ["72738.08000000", "0.00000000"], ["72738.13000000", "0.00008000"], ["72738.14000000", "0.65949000"], ["72738.50000000", "0.45057000"], ["72739.46000000", "0.00000000"], ["72739.98000000", "0.00008000"], ["72739.99000000", "0.00000000"], ["72740.06000000", "0.00000000"], ["72740.34000000", "0.00000000"], ["72740.35000000", "0.00008000"], ["72740.71000000", "0.00000000"], ["72741.12000000", "0.50000000"], ["72741.25000000", "0.00008000"], ["72741.36000000", "0.04000000"], ["72741.92000000", "0.00000000"], ["72741.98000000", "0.00000000"], ["72742.55000000", "0.00008000"], ["72742.59000000", "0.08008000"], ["72743.07000000", "0.00000000"], ["72743.18000000", "0.68835000"], ["72743.19000000", "0.00008000"], ["72743.20000000", "2.75063000"], ["72744.41000000", "0.00008000"], ["72745.11000000", "0.00000000"], ["72745.13000000", "0.00008000"], ["72745.50000000", "0.01308000"], ["72745.51000000", "0.00000000"], ["72745.59000000", "0.14128000"], ["72746.42000000", "0.00000000"], ["72747.70000000", "0.00000000"], ["72747.83000000", "0.00000000"], ["72748.16000000", "0.00000000"], ["72748.52000000", "0.58485000"], ["72748.69000000", "0.38333000"], ["72749.06000000", "0.00190000"], ["72750.67000000", "0.00200000"], ["72750.88000000", "0.00000000"], ["72751.54000000", "0.00000000"], ["72751.72000000", "0.23247000"], ["72751.99000000", "0.00000000"], ["72752.82000000", "0.00000000"], ["72753.03000000", "0.00008000"], ["72753.70000000", "0.00685000"], ["72753.77000000", "0.00000000"], ["72753.81000000", "0.00008000"], ["72753.82000000", "1.75282000"], ["72754.84000000", "0.43387000"], ["72754.96000000", "0.00000000"], ["72755.05000000", "1.36244000"], ["72756.66000000", "0.00000000"], ["72757.71000000", "0.00000000"], ["72757.72000000", "0.33604000"], ["72759.22000000", "0.00000000"], ["72759.80000000", "0.00000000"], ["72759.97000000", "0.00008000"], ["72760.16000000", "0.00000000"], ["72760.32000000", "0.49539000"], ["72761.39000000", "0.00000000"], ["72761.87000000", "0.00008000"], ["72763.11000000", "0.00000000"], ["72763.90000000", "0.00000000"], ["72763.91000000", "0.68842000"], ["72766.66000000", "0.00000000"], ["72766.80000000", "0.00000000"], ["72768.07000000", "0.00000000"], ["72768.69000000", "1.32849000"], ["72769.23000000", "0.00000000"], ["72771.41000000", "0.00000000"], ["72771.45000000", "0.00008000"], ["72774.53000000", "0.00000000"], ["72774.99000000", "1.33939000"], ["72781.94000000", "1.46988000"], ["72787.65000000", "0.00000000"], ["72820.66000000", "1.43521000"], ["72820.67000000", "0.00000000"], ["72861.16000000", "0.00000000"], ["72861.17000000", "0.00000000"], ["72902.16000000", "0.00000000"], ["72928.90000000", "0.00000000"], ["73089.69000000", "0.00000000"], ["73148.31000000", "0.01330000"], ["73446.49000000", "0.00000000"], ["85780.87000000", "0.00028000"]], "_local_ts_utc": "2026-06-01T07:49:08.110471+00:00"}
{"e": "depthUpdate", "E": 1780300149314, "s": "BTCUSDT", "U": 94551796354, "u": 94551797088, "b": [["72724.01000000", "0.00000000"], ["72724.00000000", "0.00000000"], ["72723.59000000", "0.00000000"], ["72723.58000000", "0.00000000"], ["72723.57000000", "0.00000000"], ["72723.29000000", "0.00000000"], ["72722.52000000", "0.00000000"], ["72722.50000000", "0.00000000"], ["72722.49000000", "0.00000000"], ["72722.04000000", "0.00000000"], ["72722.03000000", "0.00000000"], ["72722.02000000", "0.00000000"], ["72722.01000000", "0.00000000"], ["72722.00000000", "0.00000000"], ["72721.99000000", "0.00000000"], ["72720.66000000", "0.00000000"], ["72720.65000000", "0.00000000"], ["72720.48000000", "0.22294000"], ["72720.47000000", "0.00072000"], ["72720.15000000", "0.00016000"], ["72720.14000000", "0.00016000"], ["72719.28000000", "0.00912000"], ["72719.07000000", "0.00016000"], ["72718.68000000", "0.00589000"], ["72718.43000000", "0.00000000"], ["72718.34000000", "0.00000000"], ["72718.33000000", "0.00016000"], ["72717.60000000", "0.00000000"], ["72716.51000000", "0.00021000"], ["72716.43000000", "0.04020000"], ["72716.36000000", "0.00016000"], ["72715.79000000", "0.00000000"], ["72715.50000000", "0.00000000"], ["72715.35000000", "0.00000000"], ["72715.34000000", "0.00016000"], ["72715.15000000", "0.00016000"], ["72715.14000000", "0.00023000"], ["72715.11000000", "0.00300000"], ["72714.70000000", "0.00016000"], ["72714.69000000", "0.06300000"], ["72714.56000000", "0.00016000"], ["72714.55000000", "0.00000000"], ["72714.54000000", "0.00000000"], ["72714.53000000", "0.00000000"], ["72714.52000000", "0.00008000"], ["72714.51000000", "0.00000000"], ["72714.33000000", "0.00000000"], ["72714.21000000", "0.00000000"], ["72714.01000000", "0.04000000"], ["72713.32000000", "0.00000000"], ["72713.21000000", "0.00000000"], ["72712.81000000", "0.00007000"], ["72712.49000000", "0.00000000"], ["72712.10000000", "0.00000000"], ["72712.09000000", "0.00000000"], ["72712.08000000", "0.00000000"], ["72711.67000000", "0.00000000"], ["72711.05000000", "0.00000000"], ["72711.04000000", "0.00000000"], ["72711.03000000", "0.08795000"], ["72710.55000000", "0.00000000"], ["72710.54000000", "0.00000000"], ["72710.53000000", "0.24453000"], ["72709.30000000", "0.00000000"], ["72709.24000000", "0.00102000"], ["72709.14000000", "0.02000000"], ["72707.94000000", "0.16137000"], ["72707.93000000", "0.00000000"], ["72706.09000000", "0.00000000"], ["72704.81000000", "0.00000000"], ["72704.74000000", "0.00188000"], ["72704.09000000", "0.42573000"], ["72704.08000000", "0.65949000"], ["72704.07000000", "0.00007000"], ["72703.76000000", "0.00007000"], ["72703.56000000", "0.00008000"], ["72703.53000000", "0.00000000"], ["72703.43000000", "0.00000000"], ["72702.92000000", "0.02000000"], ["72700.93000000", "0.00000000"], ["72700.44000000", "0.42354000"], ["72700.43000000", "0.65949000"], ["72700.42000000", "0.00000000"], ["72700.41000000", "0.00825000"], ["72700.01000000", "0.00063000"], ["72699.73000000", "0.00000000"], ["72698.77000000", "0.00000000"], ["72698.67000000", "0.02000000"], ["72698.43000000", "0.00000000"], ["72698.13000000", "0.00000000"], ["72697.37000000", "1.54197000"], ["72697.36000000", "2.74985000"], ["72697.35000000", "0.00008000"], ["72697.34000000", "0.00000000"], ["72697.33000000", "0.15007000"], ["72696.87000000", "0.00000000"], ["72696.41000000", "0.00000000"], ["72696.16000000", "0.65949000"], ["72696.15000000", "0.00008000"], ["72695.90000000", "0.00200000"], ["72694.69000000", "0.00102000"], ["72693.80000000", "0.16842000"], ["72692.21000000", "0.64177000"], ["72692.20000000", "0.00000000"], ["72690.26000000", "0.00000000"], ["72690.06000000", "0.00000000"], ["72685.62000000", "0.00007000"], ["72683.02000000", "0.00000000"], ["72682.89000000", "0.00000000"], ["72679.36000000", "0.34463000"], ["72679.35000000", "0.00000000"], ["72677.63000000", "0.00000000"], ["72672.39000000", "1.90778000"], ["72668.99000000", "1.24114000"], ["72667.16000000", "0.00000000"], ["72660.95000000", "0.20321000"], ["72659.33000000", "0.52023000"], ["72658.32000000", "0.00000000"], ["72656.82000000", "1.36428000"], ["72650.86000000", "0.00008000"], ["72643.31000000", "0.20764000"], ["72642.97000000", "0.76536000"], ["72625.01000000", "0.84596000"], ["72622.70000000", "2.74985000"], ["72615.72000000", "0.16252000"], ["72611.06000000", "0.00000000"], ["72598.04000000", "0.08264000"], ["72585.59000000", "0.00000000"], ["72578.13000000", "0.00008000"], ["72519.41000000", "0.00007000"], ["72515.78000000", "0.00007000"], ["72512.86000000", "0.00000000"], ["72505.41000000", "0.00008000"], ["72440.13000000", "0.00000000"], ["72432.69000000", "0.00008000"], ["72367.39000000", "0.00000000"], ["72359.96000000", "0.00008000"], ["72294.66000000", "0.00103000"], ["72287.24000000", "0.00048000"], ["72221.93000000", "0.00000000"], ["72214.51000000", "0.00464000"], ["72149.20000000", "0.00000000"], ["72141.79000000", "0.00008000"], ["71778.60000000", "0.00347000"], ["71619.87000000", "0.01740000"], ["65451.61000000", "0.00000000"], ["65448.44000000", "0.00017000"], ["58179.21000000", "0.00000000"]], "a": [["72720.49000000", "7.46410000"], ["72720.50000000", "0.00041000"], ["72720.51000000", "0.00014000"], ["72720.64000000", "0.40221000"], ["72720.65000000", "0.65949000"], ["72720.66000000", "0.37555000"], ["72720.67000000", "0.00016000"], ["72720.68000000", "0.00000000"], ["72721.86000000", "0.13751000"], ["72721.93000000", "0.16364000"], ["72722.00000000", "0.00000000"], ["72722.02000000", "0.00000000"], ["72722.52000000", "0.00007000"], ["72723.20000000", "0.16364000"], ["72723.30000000", "0.00000000"], ["72723.58000000", "0.00000000"], ["72723.59000000", "0.00000000"], ["72723.60000000", "0.00000000"], ["72724.01000000", "2.42927000"], ["72724.02000000", "5.21586000"], ["72724.03000000", "0.00000000"], ["72724.59000000", "0.00000000"], ["72724.60000000", "0.00024000"], ["72724.61000000", "0.85132000"], ["72724.95000000", "0.00028000"], ["72724.99000000", "0.00009000"], ["72725.05000000", "0.00016000"], ["72725.11000000", "0.00000000"], ["72725.44000000", "0.00008000"], ["72725.61000000", "0.00016000"], ["72726.06000000", "0.00008000"], ["72726.07000000", "0.57661000"], ["72726.58000000", "0.00016000"], ["72726.59000000", "0.00000000"], ["72726.60000000", "0.71706000"], ["72727.18000000", "0.00000000"], ["72727.82000000", "0.00000000"], ["72727.83000000", "1.23468000"], ["72727.84000000", "1.48565000"], ["72728.54000000", "0.00155000"], ["72729.10000000", "0.00000000"], ["72729.74000000", "0.00007000"], ["72729.94000000", "0.00028000"], ["72730.37000000", "0.00000000"], ["72730.73000000", "0.00008000"], ["72730.74000000", "2.74985000"], ["72731.04000000", "0.00000000"], ["72731.05000000", "0.38200000"], ["72731.06000000", "1.05532000"], ["72731.66000000", "0.00000000"], ["72731.83000000", "0.00000000"], ["72731.98000000", "0.00000000"], ["72731.99000000", "0.00000000"], ["72732.00000000", "0.02280000"], ["72732.07000000", "0.00000000"], ["72732.86000000", "0.00007000"], ["72732.91000000", "0.00000000"], ["72733.35000000", "0.00000000"], ["72733.62000000", "0.00000000"], ["72734.00000000", "0.02280000"], ["72734.61000000", "0.00000000"], ["72734.74000000", "0.68843000"], ["72734.75000000", "0.00008000"], ["72735.98000000", "0.00000000"], ["72736.00000000", "0.02288000"], ["72736.60000000", "0.00000000"], ["72737.03000000", "0.00008000"], ["72737.84000000", "0.00000000"], ["72737.94000000", "0.00000000"], ["72738.12000000", "0.00008000"], ["72738.13000000", "0.79670000"], ["72738.49000000", "0.00000000"], ["72738.50000000", "0.00000000"], ["72739.71000000", "0.00000000"], ["72739.98000000", "0.00000000"], ["72740.35000000", "0.00008000"], ["72741.06000000", "0.00000000"], ["72741.11000000", "0.00145000"], ["72741.25000000", "0.00000000"], ["72741.90000000", "0.00300000"], ["72741.98000000", "0.00000000"], ["72743.18000000", "0.00000000"], ["72743.43000000", "0.00000000"], ["72744.26000000", "0.00007000"], ["72745.13000000", "0.00000000"], ["72745.50000000", "0.01300000"], ["72745.58000000", "0.00008000"], ["72745.59000000", "0.57353000"], ["72747.66000000", "0.00008000"], ["72747.67000000", "1.36258000"], ["72748.69000000", "0.00000000"], ["72749.06000000", "0.00198000"], ["72753.03000000", "0.00000000"], ["72753.04000000", "0.00000000"], ["72753.56000000", "0.49544000"], ["72753.70000000", "0.00000000"], ["72754.08000000", "0.00200000"], ["72755.04000000", "0.00008000"], ["72755.45000000", "0.00000000"], ["72755.62000000", "0.00000000"], ["72759.42000000", "0.00000000"], ["72759.95000000", "0.02682000"], ["72761.77000000", "0.00000000"], ["72769.29000000", "0.00000000"], ["72770.42000000", "0.00000000"], ["72771.45000000", "0.00000000"], ["72779.74000000", "0.21776000"], ["72781.16000000", "0.00000000"], ["72781.44000000", "0.00000000"], ["72783.33000000", "0.19134000"], ["72785.51000000", "0.08000000"], ["72785.62000000", "0.08600000"], ["72785.66000000", "0.07400000"], ["72788.27000000", "0.06200000"], ["72793.38000000", "0.00008000"], ["72803.35000000", "0.00000000"], ["72812.36000000", "0.00000000"], ["72812.37000000", "0.00000000"], ["72812.57000000", "0.14331000"], ["72820.66000000", "0.00000000"], ["72821.06000000", "0.20002000"], ["72822.75000000", "0.02604000"], ["72839.64000000", "0.00000000"], ["72841.09000000", "0.00000000"], ["72844.27000000", "0.00137000"], ["72848.44000000", "0.00000000"], ["72866.10000000", "0.00018000"], ["72876.08000000", "0.00000000"], ["72876.52000000", "0.00000000"], ["72921.64000000", "0.00000000"], ["72925.27000000", "0.00000000"], ["73011.54000000", "0.00008000"], ["73021.54000000", "0.00000000"], ["73084.26000000", "0.00008000"], ["73094.27000000", "0.00000000"], ["73229.70000000", "0.00008000"], ["73239.73000000", "0.00000000"], ["73286.46000000", "0.02128000"]], "_local_ts_utc": "2026-06-01T07:49:08.210739+00:00"}
{"e": "depthUpdate", "E": 1780300149414, "s": "BTCUSDT", "U": 94551797089, "u": 94551797313, "b": [["72720.48000000", "0.21892000"], ["72720.47000000", "0.00064000"], ["72720.15000000", "0.00000000"], ["72720.14000000", "0.00000000"], ["72719.54000000", "0.00000000"], ["72719.28000000", "0.00912000"], ["72719.07000000", "0.00000000"], ["72718.68000000", "0.00589000"], ["72718.33000000", "0.00000000"], ["72718.14000000", "0.00008000"], ["72716.44000000", "0.00000000"], ["72716.43000000", "0.00016000"], ["72716.36000000", "0.00000000"], ["72715.64000000", "0.00016000"], ["72715.63000000", "0.01110000"], ["72715.61000000", "0.00000000"], ["72715.34000000", "0.00000000"], ["72715.15000000", "0.00000000"], ["72715.14000000", "0.00007000"], ["72715.11000000", "0.00000000"], ["72714.92000000", "0.00016000"], ["72714.91000000", "0.01376000"], ["72714.69000000", "0.06316000"], ["72714.56000000", "0.00000000"], ["72714.52000000", "0.00000000"], ["72714.02000000", "0.00000000"], ["72714.01000000", "0.00016000"], ["72713.39000000", "0.00008000"], ["72713.31000000", "0.00028000"], ["72713.12000000", "0.00008000"], ["72712.04000000", "0.00016000"], ["72712.03000000", "0.02119000"], ["72711.32000000", "0.00016000"], ["72711.04000000", "0.27471000"], ["72711.03000000", "0.08811000"], ["72710.79000000", "0.00000000"], ["72709.47000000", "0.00007000"], ["72709.41000000", "0.00000000"], ["72707.16000000", "0.00000000"], ["72706.96000000", "0.04000000"], ["72704.10000000", "0.16364000"], ["72704.09000000", "0.41197000"], ["72703.00000000", "0.00047000"], ["72701.43000000", "0.16364000"], ["72700.45000000", "0.16364000"], ["72698.56000000", "0.00102000"], ["72697.98000000", "0.12063000"], ["72697.62000000", "0.16364000"], ["72697.38000000", "0.16364000"], ["72695.69000000", "0.00165000"], ["72695.06000000", "0.00000000"], ["72694.82000000", "0.00000000"], ["72681.85000000", "0.00192000"], ["72652.73000000", "0.00427000"], ["72650.40000000", "0.71934000"], ["72650.39000000", "1.04061000"], ["72650.03000000", "0.00000000"], ["72633.97000000", "0.01078000"], ["72618.05000000", "0.00000000"], ["71775.11000000", "0.00347000"], ["71765.29000000", "0.02082000"], ["70539.04000000", "0.00353000"], ["65448.44000000", "0.00051000"]], "a": [["72720.49000000", "7.83246000"], ["72720.50000000", "0.00057000"], ["72720.64000000", "0.40237000"], ["72720.65000000", "0.65965000"], ["72720.66000000", "0.37555000"], ["72720.67000000", "0.00000000"], ["72721.57000000", "0.09092000"], ["72721.86000000", "0.00016000"], ["72721.93000000", "0.16380000"], ["72723.20000000", "0.16380000"], ["72723.82000000", "0.12085000"], ["72724.01000000", "2.26650000"], ["72724.02000000", "5.21586000"], ["72724.60000000", "0.00008000"], ["72724.61000000", "0.85116000"], ["72725.05000000", "0.00000000"], ["72725.61000000", "0.00000000"], ["72725.84000000", "0.00763000"], ["72726.07000000", "0.57645000"], ["72726.58000000", "0.00000000"], ["72727.84000000", "1.50711000"], ["72728.54000000", "0.00000000"], ["72735.91000000", "0.00193000"], ["72736.01000000", "0.00000000"], ["72736.67000000", "0.00012000"], ["72744.92000000", "0.38333000"], ["72749.06000000", "0.00008000"], ["72751.29000000", "0.00000000"], ["72754.87000000", "0.00427000"], ["72755.19000000", "0.00431000"], ["72756.19000000", "1.03909000"], ["72759.95000000", "0.00000000"], ["72766.08000000", "0.02688000"], ["72785.63000000", "0.08600000"], ["72836.24000000", "0.00000000"], ["73374.96000000", "0.00010000"]], "_local_ts_utc": "2026-06-01T07:49:08.309928+00:00"}
{"e": "depthUpdate", "E": 1780300149514, "s": "BTCUSDT", "U": 94551797314, "u": 94551797436, "b": [["72720.48000000", "0.00096000"], ["72718.68000000", "0.00589000"], ["72716.43000000", "0.00000000"], ["72715.64000000", "0.00000000"], ["72715.63000000", "0.00016000"], ["72715.04000000", "0.00302000"], ["72715.03000000", "0.00000000"], ["72714.93000000", "0.00016000"], ["72714.92000000", "0.02321000"], ["72714.91000000", "0.00016000"], ["72714.69000000", "0.06316000"], ["72714.01000000", "0.00000000"], ["72712.03000000", "0.02119000"], ["72711.32000000", "0.00000000"], ["72711.05000000", "0.00016000"], ["72711.04000000", "0.20262000"], ["72709.14000000", "0.00000000"], ["72708.16000000", "0.05942000"], ["72706.96000000", "0.00000000"], ["72705.54000000", "0.19162000"], ["72702.79000000", "0.04013000"], ["72698.67000000", "0.00000000"], ["72698.66000000", "0.00013000"], ["72691.63000000", "0.02000000"], ["72688.72000000", "0.00000000"], ["72677.01000000", "0.00686000"], ["72676.85000000", "0.00013000"], ["72666.90000000", "0.00000000"], ["72655.03000000", "0.00013000"], ["72645.09000000", "0.00000000"], ["72633.22000000", "0.00013000"], ["72632.69000000", "0.00370000"], ["72623.28000000", "0.00000000"], ["72620.56000000", "2.03689000"], ["72611.40000000", "0.00013000"], ["72608.22000000", "0.04644000"], ["72601.46000000", "0.00014000"], ["71619.87000000", "0.02088000"], ["71256.32000000", "0.00700000"], ["65448.44000000", "0.00085000"], ["58176.39000000", "0.00034000"]], "a": [["72720.49000000", "7.27357000"], ["72720.50000000", "0.00064000"], ["72720.64000000", "0.00024000"], ["72720.66000000", "0.87555000"], ["72721.57000000", "0.00016000"], ["72721.70000000", "0.13751000"], ["72721.86000000", "0.00000000"], ["72723.20000000", "0.16380000"], ["72723.82000000", "0.12101000"], ["72724.02000000", "5.21552000"], ["72732.35000000", "0.00000000"], ["72735.21000000", "0.00000000"], ["72742.31000000", "0.00013000"], ["72746.54000000", "0.00200000"], ["72749.75000000", "0.00686000"], ["72754.17000000", "0.00000000"], ["72754.69000000", "0.00000000"], ["72758.12000000", "0.02669000"], ["72764.12000000", "0.00013000"], ["72766.08000000", "0.00000000"], ["72775.98000000", "0.00000000"], ["72779.76000000", "0.19134000"], ["72782.63000000", "0.00000000"], ["72785.94000000", "0.00013000"], ["72797.79000000", "0.00000000"], ["72807.75000000", "0.00013000"], ["72819.61000000", "0.00007000"], ["72821.06000000", "1.01809000"], ["72826.38000000", "0.04268000"], ["72829.57000000", "0.17660000"], ["86269.38000000", "0.00020000"]], "_local_ts_utc": "2026-06-01T07:49:08.410413+00:00"}
{"e": "depthUpdate", "E": 1780300149614, "s": "BTCUSDT", "U": 94551797437, "u": 94551798042, "b": [["72720.48000000", "0.00000000"], ["72720.47000000", "0.00000000"], ["72720.46000000", "0.00000000"], ["72719.30000000", "0.00000000"], ["72719.28000000", "0.00000000"], ["72718.83000000", "0.00000000"], ["72718.68000000", "0.00000000"], ["72718.14000000", "0.00000000"], ["72716.51000000", "0.00000000"], ["72715.63000000", "0.00000000"], ["72715.14000000", "0.00000000"], ["72715.06000000", "0.00000000"], ["72715.04000000", "1.99319000"], ["72715.03000000", "0.00072000"], ["72714.97000000", "0.00303000"], ["72714.93000000", "0.00000000"], ["72714.92000000", "0.00016000"], ["72714.91000000", "0.00000000"], ["72714.69000000", "0.00316000"], ["72713.32000000", "0.00028000"], ["72713.31000000", "0.00000000"], ["72712.81000000", "0.00000000"], ["72712.03000000", "0.00016000"], ["72711.29000000", "0.00759000"], ["72711.04000000", "0.00032000"], ["72711.03000000", "0.00024000"], ["72711.02000000", "0.00016000"], ["72710.89000000", "0.00165000"], ["72710.73000000", "0.00016000"], ["72710.53000000", "0.03087000"], ["72710.42000000", "0.00000000"], ["72708.16000000", "0.00000000"], ["72707.94000000", "0.00000000"], ["72707.65000000", "0.00759000"], ["72706.45000000", "0.01485000"], ["72705.54000000", "0.00000000"], ["72705.51000000", "0.05942000"], ["72704.80000000", "0.00000000"], ["72704.10000000", "0.16329000"], ["72704.08000000", "0.00000000"], ["72704.01000000", "0.00752000"], ["72702.79000000", "0.00013000"], ["72702.76000000", "0.04000000"], ["72701.61000000", "0.00000000"], ["72701.43000000", "0.00000000"], ["72701.07000000", "0.16329000"], ["72700.45000000", "0.16329000"], ["72700.44000000", "0.42402000"], ["72700.43000000", "0.00000000"], ["72700.37000000", "0.00761000"], ["72699.96000000", "0.01376000"], ["72698.59000000", "0.02000000"], ["72698.53000000", "0.16329000"], ["72697.92000000", "0.02000000"], ["72697.62000000", "0.00000000"], ["72697.38000000", "0.16329000"], ["72697.36000000", "0.00000000"], ["72697.33000000", "0.03007000"], ["72696.73000000", "0.00742000"], ["72696.29000000", "0.01376000"], ["72695.79000000", "0.00000000"], ["72695.71000000", "0.00000000"], ["72693.97000000", "0.00000000"], ["72693.62000000", "0.00000000"], ["72691.63000000", "0.00000000"], ["72691.23000000", "0.12000000"], ["72689.63000000", "0.02000000"], ["72686.03000000", "0.00000000"], ["72681.93000000", "0.00007000"], ["72680.90000000", "0.00119000"], ["72680.01000000", "0.00327000"], ["72677.01000000", "0.00000000"], ["72671.08000000", "0.00000000"], ["72661.01000000", "0.00007000"], ["72658.54000000", "0.00030000"], ["72656.03000000", "0.00686000"], ["72653.61000000", "0.30831000"], ["72653.60000000", "0.49612000"], ["72653.51000000", "0.00000000"], ["72650.86000000", "0.00000000"], ["72646.54000000", "0.00000000"], ["72642.34000000", "0.00008000"], ["72642.01000000", "0.00048000"], ["72640.00000000", "0.21023000"], ["72633.15000000", "0.00282000"], ["72611.06000000", "2.74985000"], ["72578.13000000", "0.00000000"], ["72569.63000000", "0.00008000"], ["72505.41000000", "0.00000000"], ["72496.91000000", "0.00008000"], ["72432.69000000", "0.00000000"], ["72424.20000000", "0.00041000"], ["72359.96000000", "0.00000000"], ["72351.48000000", "0.00008000"], ["72287.24000000", "0.00040000"], ["72278.77000000", "0.00008000"], ["72214.51000000", "0.00456000"], ["72206.05000000", "0.00008000"], ["72160.00000000", "0.02331000"], ["72141.79000000", "0.00000000"], ["72133.34000000", "0.00008000"], ["71629.67000000", "0.00348000"], ["65448.44000000", "0.00000000"], ["58176.39000000", "0.00000000"]], "a": [["72715.05000000", "5.97391000"], ["72715.06000000", "0.00038000"], ["72715.07000000", "0.00014000"], ["72715.14000000", "0.00007000"], ["72715.15000000", "0.00000000"], ["72715.63000000", "0.64818000"], ["72715.64000000", "0.00024000"], ["72715.65000000", "0.00000000"], ["72716.32000000", "0.16328000"], ["72716.52000000", "0.00000000"], ["72717.11000000", "0.00000000"], ["72717.59000000", "0.16328000"], ["72718.15000000", "0.00000000"], ["72718.69000000", "0.00016000"], ["72718.83000000", "0.00007000"], ["72718.84000000", "0.00000000"], ["72718.86000000", "0.16328000"], ["72719.29000000", "0.00016000"], ["72719.31000000", "0.00000000"], ["72720.13000000", "0.16328000"], ["72720.47000000", "0.00000000"], ["72720.48000000", "1.70341000"], ["72720.49000000", "1.97566000"], ["72720.50000000", "0.00000000"], ["72720.51000000", "0.00000000"], ["72720.64000000", "0.00008000"], ["72720.66000000", "0.50047000"], ["72721.35000000", "0.00766000"], ["72721.57000000", "0.00000000"], ["72721.67000000", "0.13751000"], ["72721.70000000", "0.00016000"], ["72721.93000000", "0.00000000"], ["72723.20000000", "0.00000000"], ["72723.82000000", "0.12085000"], ["72724.01000000", "2.26634000"], ["72724.02000000", "5.22185000"], ["72724.03000000", "0.01409000"], ["72725.56000000", "0.00000000"], ["72725.57000000", "0.00000000"], ["72726.06000000", "0.00008000"], ["72727.78000000", "0.00011000"], ["72727.82000000", "0.00000000"], ["72727.84000000", "1.39599000"], ["72729.15000000", "0.00573000"], ["72730.48000000", "0.00000000"], ["72730.49000000", "0.00000000"], ["72730.64000000", "0.00000000"], ["72730.73000000", "0.00008000"], ["72731.06000000", "1.05501000"], ["72731.55000000", "0.06200000"], ["72732.33000000", "0.05400000"], ["72734.61000000", "0.00000000"], ["72738.65000000", "0.00000000"], ["72744.11000000", "0.00000000"], ["72744.88000000", "0.63885000"], ["72746.67000000", "0.49549000"], ["72748.43000000", "0.00000000"], ["72749.75000000", "0.00000000"], ["72752.04000000", "0.00000000"], ["72753.15000000", "0.02687000"], ["72755.73000000", "0.00000000"], ["72756.96000000", "0.00007000"], ["72758.12000000", "0.00000000"], ["72765.99000000", "0.00000000"], ["72768.50000000", "0.01083000"], ["72777.95000000", "0.00000000"], ["72778.73000000", "0.00342000"], ["72787.39000000", "0.06200000"], ["72788.16000000", "0.05400000"], ["72793.95000000", "0.08158000"], ["72794.76000000", "0.00000000"], ["72800.00000000", "0.02620000"], ["72829.57000000", "0.00013000"], ["72918.01000000", "0.00000000"], ["73280.00000000", "0.00709000"]], "_local_ts_utc": "2026-06-01T07:49:08.510449+00:00"}
{"e": "depthUpdate", "E": 1780300149714, "s": "BTCUSDT", "U": 94551798043, "u": 94551798384, "b": [["72715.04000000", "2.05986000"], ["72715.03000000", "0.00064000"], ["72714.97000000", "0.00000000"], ["72714.92000000", "0.00000000"], ["72714.70000000", "0.00000000"], ["72714.69000000", "0.00300000"], ["72712.16000000", "0.00000000"], ["72712.04000000", "0.00000000"], ["72712.03000000", "0.00000000"], ["72711.29000000", "0.00775000"], ["72711.05000000", "0.00000000"], ["72711.04000000", "0.00000000"], ["72711.03000000", "0.00000000"], ["72711.02000000", "0.00000000"], ["72710.74000000", "0.00000000"], ["72710.73000000", "0.00000000"], ["72710.54000000", "0.00016000"], ["72710.52000000", "0.00000000"], ["72710.51000000", "0.00000000"], ["72710.11000000", "0.00016000"], ["72710.10000000", "0.04917000"], ["72709.47000000", "0.00000000"], ["72709.24000000", "0.00000000"], ["72708.20000000", "0.00589000"], ["72708.17000000", "0.00000000"], ["72707.95000000", "0.00000000"], ["72707.78000000", "0.00945000"], ["72707.65000000", "0.00775000"], ["72707.43000000", "0.00016000"], ["72707.42000000", "0.16329000"], ["72706.46000000", "0.00000000"], ["72706.45000000", "0.01501000"], ["72706.17000000", "0.00016000"], ["72706.16000000", "0.27372000"], ["72706.15000000", "0.15623000"], ["72705.99000000", "0.00000000"], ["72705.98000000", "0.01358000"], ["72705.94000000", "0.00007000"], ["72705.83000000", "0.00000000"], ["72705.82000000", "0.00000000"], ["72705.51000000", "0.00000000"], ["72704.89000000", "0.39004000"], ["72704.88000000", "0.16329000"], ["72704.09000000", "0.00000000"], ["72704.02000000", "0.65949000"], ["72702.76000000", "0.00000000"], ["72702.34000000", "0.16329000"], ["72700.47000000", "0.53372000"], ["72700.46000000", "0.65949000"], ["72700.44000000", "0.00048000"], ["72698.56000000", "0.00000000"], ["72697.51000000", "0.00000000"], ["72697.37000000", "1.51814000"], ["72697.10000000", "0.04000000"], ["72697.08000000", "0.00000000"], ["72696.29000000", "0.00000000"], ["72696.19000000", "0.16329000"], ["72696.17000000", "2.74985000"], ["72694.72000000", "0.00008000"], ["72694.69000000", "0.00000000"], ["72693.80000000", "0.36717000"], ["72693.45000000", "0.00000000"], ["72693.34000000", "0.00000000"], ["72692.22000000", "0.00000000"], ["72692.19000000", "0.01289000"], ["72690.91000000", "0.00000000"], ["72690.73000000", "0.00008000"], ["72689.63000000", "0.00000000"], ["72688.90000000", "0.00000000"], ["72687.76000000", "0.00102000"], ["72687.49000000", "0.00000000"], ["72687.13000000", "0.02000000"], ["72685.35000000", "0.00000000"], ["72685.13000000", "0.00000000"], ["72683.78000000", "0.00000000"], ["72679.33000000", "0.02705000"], ["72662.47000000", "0.00000000"], ["72650.74000000", "0.00426000"], ["72647.90000000", "0.00137000"], ["72630.86000000", "0.01710000"], ["72611.07000000", "0.00000000"], ["72611.06000000", "0.00000000"], ["72405.71000000", "0.00000000"], ["72206.37000000", "0.09694000"], ["65443.54000000", "0.00034000"]], "a": [["72715.05000000", "4.82372000"], ["72715.06000000", "0.00062000"], ["72715.61000000", "0.00016000"], ["72715.62000000", "0.12583000"], ["72715.63000000", "0.04068000"], ["72715.64000000", "0.00000000"], ["72715.77000000", "0.00000000"], ["72715.78000000", "0.00000000"], ["72716.31000000", "0.00000000"], ["72716.32000000", "0.00016000"], ["72717.51000000", "0.00000000"], ["72717.58000000", "0.00000000"], ["72717.59000000", "0.16380000"], ["72718.14000000", "0.00000000"], ["72718.15000000", "0.05212000"], ["72718.17000000", "0.03407000"], ["72718.69000000", "0.00000000"], ["72718.85000000", "0.00008000"], ["72718.86000000", "0.16344000"], ["72719.29000000", "0.00000000"], ["72720.13000000", "0.16344000"], ["72720.47000000", "1.35292000"], ["72720.48000000", "1.59964000"], ["72720.49000000", "1.52116000"], ["72720.66000000", "0.50031000"], ["72721.67000000", "0.00000000"], ["72721.70000000", "0.00000000"], ["72722.50000000", "0.00028000"], ["72724.13000000", "0.00007000"], ["72726.06000000", "0.00000000"], ["72727.76000000", "0.00007000"], ["72730.74000000", "2.74985000"], ["72734.77000000", "0.00000000"], ["72736.00000000", "0.02280000"], ["72736.09000000", "0.00007000"], ["72736.60000000", "0.00008000"], ["72739.52000000", "0.58485000"], ["72739.54000000", "0.00275000"], ["72739.94000000", "0.38398000"], ["72742.59000000", "0.08000000"], ["72744.87000000", "0.00008000"], ["72744.88000000", "0.58485000"], ["72744.92000000", "0.00000000"], ["72746.66000000", "0.00008000"], ["72748.52000000", "0.00000000"], ["72749.06000000", "0.00000000"], ["72750.67000000", "0.00000000"], ["72753.77000000", "0.00008000"], ["72754.96000000", "0.00008000"], ["72755.04000000", "0.00000000"], ["72757.72000000", "0.33596000"], ["72759.97000000", "0.00000000"], ["72781.94000000", "1.46980000"], ["72821.06000000", "0.20002000"], ["72910.52000000", "0.00000000"], ["72914.02000000", "0.00000000"], ["86757.89000000", "0.00019000"]], "_local_ts_utc": "2026-06-01T07:49:08.610464+00:00"}
{"e": "depthUpdate", "E": 1780300149814, "s": "BTCUSDT", "U": 94551798385, "u": 94551798596, "b": [["72715.04000000", "0.99493000"], ["72715.03000000", "0.00064000"], ["72713.32000000", "0.00000000"], ["72711.14000000", "0.02157000"], ["72710.55000000", "0.00000000"], ["72710.54000000", "0.00016000"], ["72710.21000000", "0.00007000"], ["72710.10000000", "0.01421000"], ["72709.47000000", "0.00000000"], ["72709.46000000", "0.00000000"], ["72708.20000000", "0.06589000"], ["72707.65000000", "0.00775000"], ["72707.43000000", "0.00000000"], ["72707.42000000", "0.00016000"], ["72706.46000000", "0.00016000"], ["72706.45000000", "0.01501000"], ["72706.17000000", "0.00016000"], ["72706.16000000", "0.20466000"], ["72706.15000000", "0.00000000"], ["72705.98000000", "0.01342000"], ["72705.82000000", "0.00008000"], ["72705.15000000", "0.00000000"], ["72704.88000000", "0.00000000"], ["72704.68000000", "0.00048000"], ["72704.42000000", "0.00000000"], ["72704.10000000", "0.00000000"], ["72704.02000000", "0.00000000"], ["72703.00000000", "0.00000000"], ["72702.34000000", "0.00000000"], ["72701.07000000", "0.00000000"], ["72700.48000000", "0.65949000"], ["72700.46000000", "0.00000000"], ["72700.45000000", "0.00000000"], ["72698.70000000", "0.16092000"], ["72698.53000000", "0.00000000"], ["72697.98000000", "0.00000000"], ["72697.39000000", "0.65949000"], ["72697.38000000", "0.00000000"], ["72697.33000000", "0.00007000"], ["72696.20000000", "0.40856000"], ["72696.19000000", "0.00000000"], ["72696.17000000", "0.00000000"], ["72696.16000000", "0.00000000"], ["72696.14000000", "0.00000000"], ["72695.43000000", "0.00009000"], ["72695.37000000", "0.00000000"], ["72694.23000000", "0.01000000"], ["72693.80000000", "0.16842000"], ["72692.21000000", "0.00000000"], ["72691.95000000", "0.65949000"], ["72691.83000000", "0.02000000"], ["72688.89000000", "0.00000000"], ["72687.49000000", "2.74985000"], ["72687.47000000", "0.00000000"], ["72677.87000000", "0.12064000"], ["72672.35000000", "0.49599000"], ["72668.99000000", "0.00000000"], ["72653.61000000", "0.16020000"], ["72653.60000000", "0.00000000"], ["72650.54000000", "0.49614000"], ["72647.90000000", "0.00000000"], ["72635.61000000", "0.05455000"], ["72611.06000000", "2.74985000"], ["65443.54000000", "0.00068000"]], "a": [["72715.05000000", "4.82348000"], ["72715.06000000", "0.00038000"], ["72715.61000000", "0.00000000"], ["72715.62000000", "0.12583000"], ["72715.63000000", "0.04068000"], ["72715.94000000", "0.00008000"], ["72716.32000000", "0.16329000"], ["72717.42000000", "0.00028000"], ["72717.59000000", "0.16380000"], ["72717.64000000", "0.05493000"], ["72718.15000000", "0.00016000"], ["72718.17000000", "0.03423000"], ["72720.13000000", "0.16344000"], ["72720.47000000", "1.35308000"], ["72720.48000000", "1.59948000"], ["72720.49000000", "1.52100000"], ["72720.65000000", "0.65949000"], ["72722.67000000", "0.15382000"], ["72723.81000000", "0.15153000"], ["72724.00000000", "0.16329000"], ["72724.60000000", "2.74993000"], ["72725.25000000", "0.07000000"], ["72725.44000000", "0.00000000"], ["72727.76000000", "0.04007000"], ["72733.25000000", "0.08000000"], ["72738.29000000", "0.00200000"], ["72741.36000000", "0.00000000"], ["72743.41000000", "0.00200000"], ["72744.88000000", "0.00000000"], ["72746.54000000", "0.00000000"], ["72802.31000000", "0.00000000"]], "_local_ts_utc": "2026-06-01T07:49:08.710290+00:00"}
{"e": "depthUpdate", "E": 1780300149914, "s": "BTCUSDT", "U": 94551798597, "u": 94551798697, "b": [["72715.04000000", "1.04493000"], ["72711.29000000", "0.00775000"], ["72711.15000000", "0.02080000"], ["72711.14000000", "0.02173000"], ["72708.21000000", "0.00000000"], ["72708.20000000", "0.00589000"], ["72707.65000000", "0.00775000"], ["72707.42000000", "0.00000000"], ["72706.17000000", "0.00008000"], ["72705.82000000", "0.00000000"], ["72704.89000000", "0.46075000"], ["72704.45000000", "0.18911000"], ["72704.12000000", "0.05942000"], ["72704.02000000", "0.65949000"], ["72702.34000000", "0.16330000"], ["72701.07000000", "0.16330000"], ["72700.50000000", "0.16337000"], ["72700.49000000", "0.48396000"], ["72700.47000000", "0.00000000"], ["72698.71000000", "0.16330000"], ["72698.70000000", "0.00000000"], ["72697.40000000", "0.16341000"], ["72697.37000000", "1.28619000"], ["72696.21000000", "2.90910000"], ["72695.90000000", "0.00000000"], ["72693.80000000", "0.32757000"], ["72693.45000000", "0.00000000"], ["72692.18000000", "0.00000000"], ["72691.21000000", "0.00200000"], ["72690.91000000", "0.00000000"], ["72690.73000000", "0.00008000"], ["72689.59000000", "0.00102000"], ["72688.37000000", "0.16330000"], ["72687.50000000", "0.16398000"], ["72685.95000000", "0.00686000"], ["72684.73000000", "0.66220000"], ["72676.00000000", "0.02280000"], ["72661.51000000", "1.26620000"], ["72654.87000000", "0.01146000"], ["72639.80000000", "0.00000000"], ["72636.83000000", "0.04710000"], ["72611.07000000", "0.00000000"], ["72611.06000000", "0.00000000"], ["65443.54000000", "0.00102000"]], "a": [["72715.05000000", "4.81661000"], ["72715.63000000", "0.04068000"], ["72716.32000000", "0.16345000"], ["72717.42000000", "0.00036000"], ["72717.59000000", "0.16344000"], ["72717.64000000", "0.05509000"], ["72718.15000000", "0.00000000"], ["72720.47000000", "1.35292000"], ["72724.60000000", "0.00008000"], ["72729.59000000", "0.00008000"], ["72744.73000000", "0.01371000"], ["72745.60000000", "0.05400000"], ["72749.02000000", "0.02677000"], ["72749.40000000", "0.00200000"], ["72753.15000000", "0.00000000"], ["72754.08000000", "0.00000000"], ["72800.42000000", "0.12691000"]], "_local_ts_utc": "2026-06-01T07:49:08.810230+00:00"}
{"e": "depthUpdate", "E": 1780300150014, "s": "BTCUSDT", "U": 94551798698, "u": 94551798843, "b": [["72715.04000000", "2.05204000"], ["72715.03000000", "0.00048000"], ["72714.69000000", "0.00000000"], ["72713.39000000", "0.00000000"], ["72712.07000000", "0.00000000"], ["72711.29000000", "0.00016000"], ["72711.16000000", "0.00016000"], ["72711.15000000", "0.01436000"], ["72711.14000000", "0.00016000"], ["72711.02000000", "0.00016000"], ["72711.01000000", "0.02866000"], ["72710.54000000", "0.00024000"], ["72710.11000000", "0.00000000"], ["72710.10000000", "0.00016000"], ["72708.70000000", "0.00016000"], ["72708.69000000", "0.16330000"], ["72707.90000000", "0.00008000"], ["72707.43000000", "0.00016000"], ["72707.42000000", "0.16330000"], ["72707.03000000", "0.00000000"], ["72706.68000000", "0.00000000"], ["72706.67000000", "0.00000000"], ["72706.46000000", "0.00000000"], ["72706.45000000", "0.01485000"], ["72706.18000000", "0.00000000"], ["72706.17000000", "0.16338000"], ["72705.40000000", "0.00000000"], ["72704.90000000", "0.14889000"], ["72704.12000000", "0.00000000"], ["72704.06000000", "0.00000000"], ["72704.03000000", "0.14694000"], ["72702.92000000", "0.00000000"], ["72702.70000000", "0.00260000"], ["72702.63000000", "0.01376000"], ["72702.35000000", "0.00008000"], ["72700.50000000", "0.16351000"], ["72700.49000000", "0.48704000"], ["72697.35000000", "0.00000000"], ["72696.22000000", "0.00008000"], ["72696.15000000", "0.00000000"], ["72696.01000000", "0.00008000"], ["72693.81000000", "0.77227000"], ["72693.23000000", "0.00102000"], ["72691.96000000", "0.00008000"], ["72687.50000000", "0.16406000"], ["72687.48000000", "0.40856000"], ["72686.68000000", "0.00000000"], ["72685.95000000", "0.01371000"], ["72681.43000000", "0.00400000"], ["72678.69000000", "0.00102000"], ["72667.78000000", "0.00102000"], ["72661.52000000", "0.59031000"], ["72660.95000000", "0.00000000"], ["66912.16000000", "0.00015000"], ["65443.54000000", "0.00136000"], ["58172.04000000", "0.00034000"]], "a": [["72715.05000000", "4.80576000"], ["72715.06000000", "0.00078000"], ["72715.61000000", "0.00016000"], ["72715.62000000", "0.17392000"], ["72716.31000000", "0.00000000"], ["72716.32000000", "0.00016000"], ["72716.42000000", "0.01401000"], ["72717.05000000", "0.00744000"], ["72717.42000000", "0.00000000"], ["72717.58000000", "0.00016000"], ["72717.59000000", "0.16398000"], ["72717.64000000", "0.00016000"], ["72718.02000000", "0.00016000"], ["72718.03000000", "0.04975000"], ["72718.13000000", "0.00008000"], ["72718.16000000", "0.00008000"], ["72721.91000000", "0.20000000"], ["72722.33000000", "0.00300000"], ["72722.67000000", "0.00000000"], ["72723.81000000", "0.00000000"], ["72724.00000000", "0.00000000"], ["72724.16000000", "0.00008000"], ["72727.84000000", "1.39531000"], ["72729.61000000", "0.09700000"], ["72731.42000000", "0.00400000"], ["72735.01000000", "0.00000000"], ["72736.53000000", "0.00000000"], ["72745.96000000", "0.00400000"], ["72747.51000000", "0.00349000"], ["72787.30000000", "0.09400000"]], "_local_ts_utc": "2026-06-01T07:49:08.911755+00:00"}
{"e": "depthUpdate", "E": 1780300150114, "s": "BTCUSDT", "U": 94551798844, "u": 94551798975, "b": [["72715.04000000", "2.21982000"], ["72715.03000000", "0.00048000"], ["72711.29000000", "0.00000000"], ["72711.15000000", "0.00016000"], ["72711.14000000", "0.00000000"], ["72711.02000000", "0.01392000"], ["72711.01000000", "0.02882000"], ["72710.53000000", "0.03087000"], ["72710.10000000", "0.00000000"], ["72709.06000000", "0.01100000"], ["72708.69000000", "0.16346000"], ["72707.65000000", "0.00775000"], ["72707.42000000", "0.16346000"], ["72707.18000000", "0.00400000"], ["72705.36000000", "0.00400000"], ["72704.14000000", "0.00070000"], ["72703.54000000", "0.00400000"], ["72702.63000000", "0.00000000"], ["72701.72000000", "0.00400000"], ["72700.50000000", "0.16358000"], ["72699.90000000", "0.00400000"], ["72698.67000000", "0.00023000"], ["72698.08000000", "0.00407000"], ["72696.26000000", "0.00400000"], ["72694.44000000", "0.00400000"], ["72692.62000000", "0.00400000"], ["72690.80000000", "0.00400000"], ["72688.98000000", "0.00400000"], ["72687.16000000", "0.00400000"], ["72685.34000000", "0.00400000"], ["72683.52000000", "0.00400000"], ["72681.70000000", "0.00400000"], ["72679.88000000", "0.00400000"], ["72678.06000000", "0.00000000"], ["72654.67000000", "0.00424000"], ["72654.60000000", "0.00629000"], ["72645.69000000", "0.00315000"], ["72639.19000000", "0.82632000"], ["72548.45000000", "0.00000000"], ["72417.86000000", "0.00033000"], ["72391.34000000", "0.01883000"], ["72391.32000000", "0.02795000"], ["65443.54000000", "0.00170000"], ["58172.00000000", "0.00000000"]], "a": [["72715.05000000", "4.81746000"], ["72715.06000000", "0.00078000"], ["72715.63000000", "0.04068000"], ["72716.32000000", "0.00000000"], ["72716.42000000", "0.01471000"], ["72717.05000000", "0.00760000"], ["72717.59000000", "0.16344000"], ["72717.64000000", "0.00000000"], ["72718.02000000", "0.00000000"], ["72718.03000000", "0.04991000"], ["72718.10000000", "0.00400000"], ["72718.16000000", "0.00000000"], ["72719.92000000", "0.00400000"], ["72720.13000000", "0.16328000"], ["72721.74000000", "0.00400000"], ["72723.56000000", "0.00400000"], ["72725.38000000", "0.00400000"], ["72727.20000000", "0.00400000"], ["72728.49000000", "0.00903000"], ["72729.02000000", "0.00400000"], ["72730.84000000", "0.00400000"], ["72731.05000000", "0.84085000"], ["72731.75000000", "0.06600000"], ["72732.66000000", "0.00400000"], ["72734.48000000", "0.00400000"], ["72736.30000000", "0.00400000"], ["72738.12000000", "0.00408000"], ["72739.94000000", "0.38798000"], ["72741.76000000", "0.00400000"], ["72742.15000000", "0.00000000"], ["72743.41000000", "0.00000000"], ["72743.58000000", "0.00400000"], ["72745.10000000", "0.00200000"], ["72745.40000000", "0.00400000"], ["72748.47000000", "0.00629000"], ["72748.53000000", "0.00424000"], ["72754.97000000", "0.00008000"], ["72784.60000000", "0.82632000"], ["72789.47000000", "0.06600000"]], "_local_ts_utc": "2026-06-01T07:49:09.010582+00:00"}
{"e": "depthUpdate", "E": 1780300150214, "s": "BTCUSDT", "U": 94551798976, "u": 94551799039, "b": [["72715.04000000", "2.21582000"], ["72715.03000000", "0.00048000"], ["72711.16000000", "0.00000000"], ["72711.15000000", "0.00000000"], ["72711.03000000", "0.00016000"], ["72711.02000000", "0.03817000"], ["72710.53000000", "0.03087000"], ["72709.07000000", "0.00016000"], ["72709.06000000", "0.07058000"], ["72707.43000000", "0.00000000"], ["72707.42000000", "0.16330000"], ["72702.96000000", "0.01376000"], ["72691.21000000", "0.00000000"], ["72682.13000000", "0.00200000"], ["72598.04000000", "0.00000000"], ["72551.44000000", "0.09874000"], ["72321.70000000", "0.09679000"], ["72206.37000000", "0.00000000"], ["71256.32000000", "0.01050000"], ["65443.54000000", "0.00204000"], ["58172.04000000", "0.00000000"]], "a": [["72715.05000000", "4.81754000"], ["72715.06000000", "0.00086000"], ["72718.02000000", "0.00016000"], ["72718.16000000", "0.00008000"], ["72724.02000000", "4.92185000"], ["72740.31000000", "0.00200000"], ["72744.30000000", "0.00000000"], ["72745.59000000", "0.19127000"], ["72747.67000000", "0.00000000"], ["72749.40000000", "0.00000000"], ["72793.95000000", "0.00000000"], ["72800.42000000", "0.20808000"], ["72890.32000000", "4.12095000"]], "_local_ts_utc": "2026-06-01T07:49:09.110542+00:00"}
{"e": "depthUpdate", "E": 1780300150314, "s": "BTCUSDT", "U": 94551799040, "u": 94551799328, "b": [["72715.04000000", "2.88634000"], ["72715.03000000", "0.00016000"], ["72713.79000000", "0.00016000"], ["72713.78000000", "0.04900000"], ["72713.77000000", "0.16326000"], ["72713.27000000", "0.00028000"], ["72712.64000000", "0.00400000"], ["72712.58000000", "0.00016000"], ["72712.57000000", "0.02829000"], ["72712.52000000", "0.00016000"], ["72712.51000000", "0.16510000"], ["72712.50000000", "0.16326000"], ["72712.07000000", "0.06492000"], ["72711.25000000", "0.00550000"], ["72711.24000000", "0.00000000"], ["72711.23000000", "0.16326000"], ["72711.03000000", "0.00000000"], ["72711.02000000", "0.00016000"], ["72711.01000000", "0.00016000"], ["72710.82000000", "0.00400000"], ["72710.54000000", "0.00008000"], ["72710.21000000", "0.00016000"], ["72709.97000000", "0.00000000"], ["72709.96000000", "0.16326000"], ["72709.07000000", "0.00000000"], ["72709.06000000", "0.00016000"], ["72709.00000000", "0.00400000"], ["72708.70000000", "0.00000000"], ["72708.31000000", "0.31938000"], ["72708.30000000", "0.18135000"], ["72706.16000000", "0.00000000"], ["72704.45000000", "0.00000000"], ["72704.14000000", "0.00000000"], ["72704.04000000", "0.65949000"], ["72704.02000000", "0.00000000"], ["72703.76000000", "0.00000000"], ["72702.96000000", "0.00000000"], ["72698.67000000", "0.00000000"], ["72696.22000000", "0.40864000"], ["72696.20000000", "0.00000000"], ["72695.44000000", "0.02202000"], ["72693.82000000", "0.74558000"], ["72693.80000000", "0.00000000"], ["72692.18000000", "0.00000000"], ["72690.91000000", "0.00000000"], ["72690.73000000", "0.00008000"], ["72687.13000000", "0.00000000"], ["72684.73000000", "0.00000000"], ["72683.52000000", "0.00000000"], ["72681.70000000", "0.00000000"], ["72679.88000000", "0.00000000"], ["72679.58000000", "0.79754000"], ["72679.57000000", "1.36385000"], ["72679.36000000", "0.00000000"], ["72661.52000000", "0.21235000"], ["72661.51000000", "0.00000000"], ["72656.00000000", "0.94738000"], ["72634.35000000", "1.03930000"], ["72633.14000000", "0.00000000"], ["71624.31000000", "0.00348000"], ["70897.16000000", "0.00352000"], ["65443.54000000", "0.00238000"], ["58172.03000000", "0.00000000"]], "a": [["72715.05000000", "1.11379000"], ["72715.61000000", "0.00000000"], ["72715.62000000", "0.00040000"], ["72716.41000000", "0.00000000"], ["72716.42000000", "0.00070000"], ["72717.05000000", "0.00016000"], ["72717.25000000", "0.00000000"], ["72717.57000000", "0.00000000"], ["72717.58000000", "0.65949000"], ["72717.59000000", "0.00016000"], ["72717.96000000", "0.00000000"], ["72718.02000000", "0.00000000"], ["72718.03000000", "0.00016000"], ["72718.16000000", "0.00000000"], ["72718.17000000", "0.00016000"], ["72718.85000000", "0.00008000"], ["72718.86000000", "0.16342000"], ["72719.20000000", "0.00016000"], ["72719.21000000", "0.04254000"], ["72719.26000000", "0.00031000"], ["72719.32000000", "0.00000000"], ["72719.76000000", "0.00016000"], ["72719.77000000", "0.01370000"], ["72720.12000000", "0.00016000"], ["72720.45000000", "0.00008000"], ["72720.46000000", "0.16326000"], ["72720.48000000", "0.93482000"], ["72720.49000000", "0.99432000"], ["72721.32000000", "0.02000000"], ["72721.35000000", "0.00000000"], ["72721.59000000", "0.00739000"], ["72724.02000000", "4.84154000"], ["72725.25000000", "0.00000000"], ["72726.62000000", "0.00191000"], ["72727.05000000", "0.01000000"], ["72727.15000000", "0.02000000"], ["72727.35000000", "0.04000000"], ["72727.83000000", "0.58679000"], ["72730.74000000", "0.00000000"], ["72731.03000000", "1.25652000"], ["72731.04000000", "2.75046000"], ["72731.05000000", "0.00008000"], ["72731.42000000", "0.00000000"], ["72732.86000000", "0.00000000"], ["72736.26000000", "0.00400000"], ["72736.60000000", "0.45893000"], ["72745.59000000", "0.04337000"], ["72746.67000000", "0.00000000"], ["72770.62000000", "0.26000000"], ["72771.67000000", "0.49532000"], ["72800.42000000", "1.01871000"], ["72802.32000000", "2.75046000"], ["87246.40000000", "0.00020000"]], "_local_ts_utc": "2026-06-01T07:49:09.210250+00:00"}
{"e": "depthUpdate", "E": 1780300150414, "s": "BTCUSDT", "U": 94551799329, "u": 94551799544, "b": [["72715.04000000", "3.18971000"], ["72714.80000000", "0.04229000"], ["72714.46000000", "0.00400000"], ["72713.78000000", "0.04916000"], ["72713.77000000", "0.16342000"], ["72713.75000000", "0.00008000"], ["72713.23000000", "0.01100000"], ["72712.90000000", "0.00000000"], ["72712.58000000", "0.00000000"], ["72712.57000000", "0.00016000"], ["72712.52000000", "0.00000000"], ["72712.51000000", "0.16510000"], ["72712.50000000", "0.16342000"], ["72712.29000000", "0.19013000"], ["72712.07000000", "0.05958000"], ["72711.25000000", "0.00016000"], ["72711.23000000", "0.16342000"], ["72711.02000000", "0.00000000"], ["72711.01000000", "0.00000000"], ["72710.53000000", "0.03071000"], ["72709.06000000", "0.00000000"], ["72708.69000000", "0.16330000"], ["72708.30000000", "0.00000000"], ["72708.20000000", "0.00573000"], ["72707.78000000", "0.00929000"], ["72707.65000000", "0.00759000"], ["72705.07000000", "0.00000000"], ["72704.68000000", "0.00000000"], ["72704.05000000", "0.40856000"], ["72703.54000000", "0.00400000"], ["72701.94000000", "0.03407000"], ["72698.32000000", "0.00007000"], ["72694.25000000", "0.00349000"], ["72693.82000000", "0.58232000"], ["72693.67000000", "0.12065000"], ["72690.73000000", "0.15948000"], ["72685.34000000", "0.00000000"], ["72680.42000000", "0.49594000"], ["72677.87000000", "0.00000000"], ["72650.54000000", "0.00000000"], ["65443.54000000", "0.00289000"]], "a": [["72715.05000000", "0.16767000"], ["72715.06000000", "0.00078000"], ["72715.62000000", "0.00024000"], ["72715.63000000", "0.04068000"], ["72716.42000000", "0.00054000"], ["72717.05000000", "0.00000000"], ["72717.56000000", "0.25923000"], ["72717.57000000", "0.65949000"], ["72717.58000000", "0.00016000"], ["72717.59000000", "0.00000000"], ["72718.03000000", "0.00000000"], ["72718.10000000", "0.00000000"], ["72718.17000000", "0.00000000"], ["72718.23000000", "0.00000000"], ["72718.60000000", "0.00000000"], ["72718.85000000", "0.00024000"], ["72718.86000000", "0.00016000"], ["72719.02000000", "0.00000000"], ["72719.20000000", "0.00000000"], ["72719.21000000", "0.00016000"], ["72719.26000000", "0.00000000"], ["72719.60000000", "0.00000000"], ["72719.71000000", "0.00031000"], ["72719.74000000", "0.01475000"], ["72719.76000000", "0.00000000"], ["72719.77000000", "0.01386000"], ["72719.92000000", "0.00000000"], ["72720.13000000", "0.16344000"], ["72720.45000000", "0.00008000"], ["72720.46000000", "0.16342000"], ["72720.47000000", "0.99350000"], ["72720.48000000", "0.66482000"], ["72720.49000000", "0.95397000"], ["72720.53000000", "0.00031000"], ["72720.66000000", "0.50000000"], ["72721.32000000", "0.02031000"], ["72722.33000000", "0.27300000"], ["72724.02000000", "4.00545000"], ["72727.42000000", "0.00007000"], ["72729.61000000", "0.36700000"], ["72731.25000000", "0.07400000"], ["72734.74000000", "0.00000000"], ["72736.26000000", "0.00000000"], ["72738.13000000", "1.17968000"], ["72738.67000000", "0.00400000"], ["72739.51000000", "0.68842000"], ["72744.14000000", "0.00685000"], ["72744.73000000", "0.00686000"], ["72745.10000000", "0.00000000"], ["72746.27000000", "0.00200000"], ["72749.04000000", "0.00400000"], ["72750.86000000", "0.00400000"], ["72787.19000000", "0.00000000"], ["73207.00000000", "0.00009000"], ["73374.96000000", "0.00000000"]], "_local_ts_utc": "2026-06-01T07:49:09.312756+00:00"}
{"e": "depthUpdate", "E": 1780300150514, "s": "BTCUSDT", "U": 94551799545, "u": 94551799730, "b": [["72715.04000000", "2.88295000"], ["72714.97000000", "0.00016000"], ["72714.96000000", "0.05942000"], ["72714.82000000", "0.00016000"], ["72714.81000000", "0.08202000"], ["72714.80000000", "0.00016000"], ["72714.67000000", "0.03500000"], ["72714.41000000", "0.00016000"], ["72714.40000000", "0.00000000"], ["72713.79000000", "0.00000000"], ["72713.78000000", "0.00032000"], ["72713.77000000", "0.00016000"], ["72713.27000000", "0.00000000"], ["72713.23000000", "0.01116000"], ["72712.80000000", "0.00275000"], ["72712.57000000", "0.00000000"], ["72712.52000000", "0.00016000"], ["72712.51000000", "0.16510000"], ["72712.50000000", "0.16342000"], ["72712.29000000", "0.00016000"], ["72712.07000000", "0.00016000"], ["72711.25000000", "0.00753000"], ["72711.23000000", "0.16326000"], ["72710.01000000", "0.01351000"], ["72700.50000000", "0.16365000"], ["72700.44000000", "0.00000000"], ["72699.23000000", "0.02000000"], ["72690.73000000", "0.00008000"], ["72690.49000000", "0.00200000"], ["72689.67000000", "0.00011000"], ["72682.13000000", "0.00000000"], ["72673.62000000", "0.00000000"], ["72671.42000000", "0.00102000"], ["72660.57000000", "0.00010000"], ["72647.55000000", "0.82626000"], ["72639.19000000", "0.00000000"], ["66912.16000000", "0.00000000"], ["65443.54000000", "0.00323000"], ["65443.00000000", "0.00020000"], ["58172.04000000", "0.00034000"]], "a": [["72715.05000000", "0.37285000"], ["72715.06000000", "0.00054000"], ["72715.63000000", "0.04068000"], ["72716.42000000", "0.00000000"], ["72717.29000000", "0.00031000"], ["72717.53000000", "0.16418000"], ["72717.54000000", "0.20565000"], ["72717.55000000", "0.65949000"], ["72717.56000000", "0.00088000"], ["72717.57000000", "0.00016000"], ["72717.58000000", "0.00000000"], ["72718.85000000", "0.00008000"], ["72718.86000000", "0.00000000"], ["72718.89000000", "0.16402000"], ["72718.98000000", "0.00031000"], ["72719.21000000", "0.00000000"], ["72719.49000000", "0.07042000"], ["72719.57000000", "0.00031000"], ["72719.69000000", "0.01920000"], ["72719.71000000", "0.00000000"], ["72719.74000000", "0.00016000"], ["72719.80000000", "0.00000000"], ["72720.31000000", "0.00000000"], ["72720.37000000", "0.00000000"], ["72720.38000000", "0.00000000"], ["72720.53000000", "0.00000000"], ["72721.32000000", "0.02000000"], ["72723.04000000", "0.00000000"], ["72732.68000000", "0.04607000"], ["72740.31000000", "0.00000000"], ["72743.94000000", "0.00000000"], ["72748.69000000", "0.00200000"], ["72755.24000000", "0.00105000"], ["72779.63000000", "0.04600000"], ["72784.60000000", "0.00000000"], ["72788.63000000", "0.82626000"], ["72862.83000000", "0.02154000"], ["72900.00000000", "0.04039000"], ["73594.17000000", "0.00000000"], ["87734.91000000", "0.00012000"]], "_local_ts_utc": "2026-06-01T07:49:09.410417+00:00"}
{"e": "depthUpdate", "E": 1780300150614, "s": "BTCUSDT", "U": 94551799731, "u": 94551799922, "b": [["72715.04000000", "3.25465000"], ["72714.98000000", "0.00016000"], ["72714.97000000", "0.05970000"], ["72714.96000000", "0.00016000"], ["72714.82000000", "0.00000000"], ["72714.81000000", "0.00016000"], ["72714.80000000", "0.00000000"], ["72714.77000000", "0.00000000"], ["72714.76000000", "0.00000000"], ["72714.71000000", "0.04115000"], ["72714.68000000", "0.00000000"], ["72714.67000000", "0.00016000"], ["72714.45000000", "0.00000000"], ["72714.41000000", "0.00000000"], ["72713.78000000", "0.00000000"], ["72713.77000000", "0.00152000"], ["72713.76000000", "0.16402000"], ["72712.55000000", "0.05942000"], ["72712.52000000", "0.00016000"], ["72712.51000000", "0.16518000"], ["72712.50000000", "0.16342000"], ["72712.29000000", "0.00008000"], ["72712.07000000", "0.00000000"], ["72711.25000000", "0.00769000"], ["72711.23000000", "0.16342000"], ["72707.87000000", "0.01376000"], ["72705.29000000", "0.00048000"], ["72705.16000000", "0.00047000"], ["72703.51000000", "0.01377000"], ["72697.20000000", "0.01376000"], ["72696.94000000", "0.00008000"], ["72688.16000000", "0.00000000"], ["72682.29000000", "0.63390000"], ["72661.52000000", "0.55211000"], ["72659.07000000", "1.22909000"], ["72475.56000000", "0.00261000"], ["65443.54000000", "0.00357000"], ["58172.04000000", "0.00000000"]], "a": [["72715.05000000", "0.29566000"], ["72715.06000000", "0.00078000"], ["72715.63000000", "0.04068000"], ["72717.29000000", "0.00072000"], ["72717.52000000", "0.37290000"], ["72717.53000000", "0.00016000"], ["72717.54000000", "0.00032000"], ["72717.55000000", "0.65965000"], ["72717.56000000", "0.00000000"], ["72717.57000000", "0.00000000"], ["72718.75000000", "0.00031000"], ["72718.88000000", "0.00000000"], ["72718.89000000", "0.00016000"], ["72719.48000000", "0.00016000"], ["72719.49000000", "0.07058000"], ["72719.69000000", "0.00016000"], ["72719.74000000", "0.00000000"], ["72719.75000000", "0.00000000"], ["72719.78000000", "0.01662000"], ["72719.83000000", "0.00000000"], ["72720.12000000", "0.00008000"], ["72720.13000000", "0.16328000"], ["72720.45000000", "0.00000000"], ["72720.46000000", "0.16326000"], ["72720.47000000", "0.99334000"], ["72725.26000000", "0.00007000"], ["72727.74000000", "0.00007000"], ["72738.29000000", "0.00000000"], ["72744.14000000", "0.00685000"], ["72745.22000000", "0.00000000"], ["73369.28000000", "0.00250000"], ["73517.38000000", "0.00275000"]], "_local_ts_utc": "2026-06-01T07:49:09.510412+00:00"}
{"e": "depthUpdate", "E": 1780300150714, "s": "BTCUSDT", "U": 94551799923, "u": 94551800107, "b": [["72715.04000000", "3.35120000"], ["72714.97000000", "0.05970000"], ["72714.96000000", "0.00000000"], ["72714.81000000", "0.00000000"], ["72714.72000000", "0.00000000"], ["72714.71000000", "0.00016000"], ["72714.67000000", "0.00000000"], ["72714.14000000", "0.00000000"], ["72714.13000000", "0.06724000"], ["72713.77000000", "0.00136000"], ["72713.76000000", "0.16418000"], ["72713.40000000", "0.00028000"], ["72713.23000000", "0.01116000"], ["72712.56000000", "0.00000000"], ["72712.55000000", "0.05958000"], ["72712.52000000", "0.00000000"], ["72712.51000000", "0.16510000"], ["72711.25000000", "0.16338000"], ["72711.23000000", "0.16326000"], ["72705.29000000", "0.00000000"], ["72704.06000000", "0.40856000"], ["72704.05000000", "0.00000000"], ["72699.96000000", "0.00000000"], ["72696.23000000", "0.40856000"], ["72696.22000000", "0.00008000"], ["72693.83000000", "0.16402000"], ["72692.01000000", "0.16402000"], ["72690.73000000", "0.16410000"], ["72622.71000000", "2.75046000"], ["72622.70000000", "0.00000000"], ["72461.55000000", "0.09660000"], ["72321.70000000", "0.00000000"], ["65443.54000000", "0.00391000"], ["65443.00000000", "0.00000000"]], "a": [["72715.05000000", "0.10576000"], ["72715.63000000", "0.04068000"], ["72717.29000000", "0.00000000"], ["72717.51000000", "0.00024000"], ["72717.52000000", "0.00088000"], ["72717.53000000", "0.00000000"], ["72717.54000000", "0.00024000"], ["72717.55000000", "0.00016000"], ["72718.03000000", "0.00000000"], ["72718.26000000", "0.01485000"], ["72718.75000000", "0.00000000"], ["72718.85000000", "0.00000000"], ["72718.89000000", "0.00000000"], ["72718.93000000", "0.00165000"], ["72718.98000000", "0.00000000"], ["72719.48000000", "0.00024000"], ["72719.49000000", "0.07058000"], ["72719.57000000", "0.00000000"], ["72719.69000000", "0.00000000"], ["72719.77000000", "0.01386000"], ["72719.78000000", "0.00016000"], ["72719.84000000", "0.01075000"], ["72720.12000000", "0.00016000"], ["72720.13000000", "0.00016000"], ["72720.46000000", "0.40880000"], ["72720.48000000", "0.25618000"], ["72721.95000000", "0.00031000"], ["72722.32000000", "0.00008000"], ["72722.33000000", "0.00300000"], ["72727.05000000", "0.00000000"], ["72727.15000000", "0.00000000"], ["72727.35000000", "0.00000000"], ["72727.75000000", "0.00008000"], ["72729.60000000", "0.00008000"], ["72730.73000000", "0.00000000"], ["72731.03000000", "1.25660000"], ["72731.04000000", "0.00000000"], ["72731.65000000", "0.07000000"], ["72731.74000000", "0.00008000"], ["72733.24000000", "0.00000000"], ["72736.59000000", "0.00008000"], ["72736.60000000", "0.45885000"], ["72739.50000000", "0.00008000"], ["72739.93000000", "0.00008000"], ["72741.77000000", "0.00200000"], ["72744.14000000", "0.00000000"], ["72744.41000000", "0.00000000"], ["72744.87000000", "0.00000000"], ["72745.58000000", "0.00000000"], ["72746.27000000", "0.00000000"], ["72746.66000000", "0.00000000"], ["72747.66000000", "0.00000000"], ["72748.93000000", "0.00200000"], ["72753.77000000", "0.00000000"], ["72754.96000000", "0.00000000"], ["72763.91000000", "0.68834000"], ["72768.69000000", "1.32841000"], ["72774.99000000", "1.33931000"], ["72853.85000000", "0.44999000"], ["72859.91000000", "0.00000000"], ["72916.72000000", "0.01375000"]], "_local_ts_utc": "2026-06-01T07:49:09.610314+00:00"}
{"e": "depthUpdate", "E": 1780300150814, "s": "BTCUSDT", "U": 94551800108, "u": 94551800260, "b": [["72715.04000000", "3.53600000"], ["72714.98000000", "0.00000000"], ["72714.97000000", "0.07051000"], ["72714.82000000", "0.05942000"], ["72714.71000000", "0.00000000"], ["72714.33000000", "0.00000000"], ["72714.13000000", "0.00016000"], ["72714.00000000", "0.00000000"], ["72713.40000000", "0.00000000"], ["72713.24000000", "0.00028000"], ["72713.23000000", "0.00016000"], ["72712.55000000", "0.00016000"], ["72711.25000000", "0.00769000"], ["72705.16000000", "0.00000000"], ["72704.07000000", "2.75053000"], ["72703.58000000", "0.01376000"], ["72700.03000000", "0.02000000"], ["72694.56000000", "0.16402000"], ["72691.83000000", "0.00000000"], ["72689.44000000", "0.16402000"], ["72669.06000000", "0.00137000"], ["72657.50000000", "0.00137000"], ["72645.69000000", "0.00178000"], ["72629.40000000", "0.00000000"], ["72622.71000000", "0.00000000"], ["72511.11000000", "0.00000000"], ["72508.25000000", "0.00822000"], ["65443.54000000", "0.00425000"]], "a": [["72715.05000000", "0.05145000"], ["72715.06000000", "0.00094000"], ["72715.63000000", "0.04068000"], ["72717.51000000", "0.00080000"], ["72717.52000000", "0.00000000"], ["72717.54000000", "0.00008000"], ["72717.55000000", "0.00000000"], ["72718.25000000", "0.00016000"], ["72718.26000000", "0.01501000"], ["72719.49000000", "0.00016000"], ["72719.76000000", "0.00016000"], ["72719.77000000", "0.01386000"], ["72719.78000000", "0.00000000"], ["72719.83000000", "0.00000000"], ["72719.84000000", "0.00016000"], ["72719.95000000", "0.00000000"], ["72720.12000000", "0.00008000"], ["72720.13000000", "0.00000000"], ["72720.45000000", "0.00008000"], ["72720.46000000", "0.00024000"], ["72720.47000000", "0.00016000"], ["72720.48000000", "0.17849000"], ["72720.49000000", "0.56121000"], ["72721.08000000", "0.00000000"], ["72721.79000000", "0.00000000"], ["72721.95000000", "0.00000000"], ["72722.33000000", "0.00300000"], ["72724.02000000", "3.90920000"], ["72724.51000000", "0.00031000"], ["72726.07000000", "0.19288000"], ["72726.60000000", "0.16875000"], ["72727.84000000", "1.22586000"], ["72730.28000000", "0.00155000"], ["72731.03000000", "0.49109000"], ["72744.14000000", "0.00000000"], ["72747.51000000", "0.00000000"], ["72749.02000000", "0.00000000"], ["72784.81000000", "0.09617000"], ["72821.06000000", "1.00453000"], ["72911.46000000", "0.00007000"], ["72915.09000000", "0.00007000"], ["87997.75000000", "0.00197000"]], "_local_ts_utc": "2026-06-01T07:49:09.712754+00:00"}
{"e": "depthUpdate", "E": 1780300150914, "s": "BTCUSDT", "U": 94551800261, "u": 94551800422, "b": [["72715.04000000", "3.69526000"], ["72715.03000000", "0.00030000"], ["72715.02000000", "0.00014000"], ["72714.97000000", "0.07051000"], ["72714.82000000", "0.05958000"], ["72714.77000000", "0.01401000"], ["72714.32000000", "0.09173000"], ["72714.13000000", "0.00000000"], ["72713.76000000", "0.16418000"], ["72713.23000000", "0.00000000"], ["72713.02000000", "0.00008000"], ["72712.55000000", "0.00000000"], ["72711.23000000", "0.16342000"], ["72710.53000000", "0.03087000"], ["72706.95000000", "0.65949000"], ["72705.69000000", "0.00165000"], ["72704.89000000", "1.42005000"], ["72704.08000000", "0.40856000"], ["72704.06000000", "0.00000000"], ["72703.51000000", "0.00000000"], ["72695.69000000", "0.00000000"], ["72694.56000000", "0.00000000"], ["72693.83000000", "0.00000000"], ["72692.01000000", "0.00000000"], ["72690.73000000", "0.00008000"], ["72690.30000000", "0.00400000"], ["72689.44000000", "0.00000000"], ["72688.37000000", "0.00000000"], ["72683.17000000", "0.02739000"], ["72681.43000000", "0.00000000"], ["72679.33000000", "0.00000000"], ["72660.25000000", "0.26000000"], ["72625.01000000", "0.02881000"], ["72417.86000000", "0.00000000"], ["70897.16000000", "0.00704000"], ["65443.54000000", "0.00425000"]], "a": [["72715.05000000", "0.15896000"], ["72715.06000000", "0.00094000"], ["72718.26000000", "0.01501000"], ["72719.48000000", "0.00008000"], ["72719.49000000", "0.00000000"], ["72719.77000000", "0.01386000"], ["72719.84000000", "0.00000000"], ["72719.95000000", "0.00755000"], ["72720.45000000", "0.00000000"], ["72720.46000000", "0.00024000"], ["72720.47000000", "0.46872000"], ["72720.48000000", "0.76343000"], ["72720.49000000", "0.56137000"], ["72720.65000000", "0.65965000"], ["72720.66000000", "0.50016000"], ["72721.32000000", "0.02016000"], ["72721.61000000", "0.00031000"], ["72721.74000000", "0.00000000"], ["72722.20000000", "0.00031000"], ["72722.72000000", "0.00031000"], ["72724.01000000", "1.53875000"], ["72724.69000000", "0.00070000"], ["72724.74000000", "0.00047000"], ["72731.65000000", "0.01000000"], ["72733.25000000", "0.00000000"], ["72734.35000000", "0.02000000"], ["72734.45000000", "0.00000000"], ["72737.05000000", "0.52856000"], ["72741.77000000", "0.00000000"], ["72745.96000000", "0.00000000"], ["72754.50000000", "0.00400000"], ["72754.70000000", "0.00400000"], ["72756.64000000", "0.00349000"], ["72822.75000000", "0.74771000"], ["72829.57000000", "0.17658000"], ["72915.09000000", "0.00000000"]], "_local_ts_utc": "2026-06-01T07:49:09.810562+00:00"}
