{"e": "depthUpdate", "E": 1780300151014, "s": "BTCUSDT", "U": 94551800423, "u": 94551800532, "b": [["72715.04000000", "3.69344000"], ["72715.03000000", "0.00083000"], ["72714.82000000", "0.05958000"], ["72714.77000000", "0.01417000"], ["72714.32000000", "0.00016000"], ["72714.29000000", "0.10329000"], ["72714.06000000", "0.00000000"], ["72713.24000000", "0.00000000"], ["72712.52000000", "0.00008000"], ["72711.23000000", "0.16326000"], ["72710.54000000", "0.00000000"], ["72710.53000000", "0.03071000"], ["72708.32000000", "0.00008000"], ["72706.96000000", "0.00008000"], ["72706.17000000", "0.16330000"], ["72704.08000000", "0.40864000"], ["72704.03000000", "0.14686000"], ["72702.79000000", "0.02013000"], ["72697.38000000", "0.00008000"], ["72696.01000000", "0.00000000"], ["72691.96000000", "0.00000000"], ["72638.74000000", "0.02000000"], ["72425.43000000", "0.00030000"], ["71987.89000000", "0.00007000"], ["71260.74000000", "0.00350000"], ["65443.54000000", "0.00425000"], ["58172.04000000", "0.00034000"]], "a": [["72715.05000000", "0.04624000"], ["72715.06000000", "0.00102000"], ["72717.51000000", "0.00072000"], ["72717.54000000", "0.00018000"], ["72718.25000000", "0.00024000"], ["72719.48000000", "0.00000000"], ["72719.77000000", "0.01386000"], ["72719.86000000", "0.00000000"], ["72719.87000000", "0.00000000"], ["72719.95000000", "0.00016000"], ["72720.02000000", "0.00711000"], ["72720.12000000", "0.00000000"], ["72720.45000000", "0.00016000"], ["72720.46000000", "0.06008000"], ["72720.47000000", "0.00032000"], ["72720.64000000", "0.00000000"], ["72720.66000000", "0.50000000"], ["72721.32000000", "0.02000000"], ["72721.37000000", "0.00000000"], ["72721.61000000", "0.00000000"], ["72721.90000000", "0.00039000"], ["72722.32000000", "0.00000000"], ["72722.80000000", "0.01100000"], ["72722.84000000", "0.05942000"], ["72724.51000000", "0.00000000"], ["72727.75000000", "0.00000000"], ["72730.74000000", "0.00008000"], ["72731.03000000", "0.49101000"], ["72732.32000000", "0.00008000"], ["72732.67000000", "0.00008000"], ["72733.78000000", "0.08200000"], ["72734.25000000", "0.00008000"], ["72743.10000000", "0.00200000"], ["72744.14000000", "0.00686000"], ["72744.73000000", "0.00000000"], ["72748.93000000", "0.00000000"], ["72749.06000000", "0.00008000"], ["72752.62000000", "0.00200000"], ["72758.68000000", "0.00685000"], ["73442.19000000", "0.00007000"], ["87997.80000000", "0.00040000"]], "_local_ts_utc": "2026-06-01T07:49:09.910732+00:00"}
{"e": "depthUpdate", "E": 1780300151114, "s": "BTCUSDT", "U": 94551800533, "u": 94551800609, "b": [["72715.04000000", "3.69714000"], ["72714.77000000", "0.01417000"], ["72714.32000000", "0.00000000"], ["72714.29000000", "0.00016000"], ["72714.06000000", "0.06521000"], ["72713.13000000", "0.00738000"], ["72712.29000000", "0.00000000"], ["72707.90000000", "0.00000000"], ["72700.72000000", "0.02000000"], ["72699.98000000", "0.02000000"], ["72696.73000000", "0.00000000"], ["72696.21000000", "2.74985000"], ["72694.37000000", "0.00200000"], ["72690.49000000", "0.00000000"], ["72687.50000000", "0.00076000"], ["72686.90000000", "0.00199000"], ["72664.57000000", "0.00340000"], ["72638.74000000", "0.00000000"], ["72636.35000000", "0.02000000"], ["72635.63000000", "0.02000000"], ["72592.99000000", "0.00137000"], ["71987.88000000", "0.00007000"], ["65443.54000000", "0.00425000"]], "a": [["72715.05000000", "0.03936000"], ["72715.06000000", "0.00102000"], ["72717.51000000", "0.00000000"], ["72717.54000000", "0.00000000"], ["72718.13000000", "0.00098000"], ["72719.77000000", "0.01386000"], ["72719.86000000", "0.00016000"], ["72719.87000000", "0.00000000"], ["72719.95000000", "0.00000000"], ["72720.02000000", "0.00016000"], ["72720.46000000", "0.06024000"], ["72720.47000000", "0.00008000"], ["72720.93000000", "0.00000000"], ["72729.41000000", "0.00904000"], ["72736.08000000", "0.05400000"], ["72736.80000000", "0.05400000"], ["72742.60000000", "0.00000000"], ["72743.20000000", "2.75262000"], ["72748.69000000", "0.00000000"], ["72752.56000000", "0.00200000"], ["72758.68000000", "0.00000000"], ["72771.45000000", "0.00189000"], ["72844.26000000", "0.00075000"], ["73442.21000000", "0.00007000"]], "_local_ts_utc": "2026-06-01T07:49:10.010431+00:00"}
{"e": "depthUpdate", "E": 1780300151214, "s": "BTCUSDT", "U": 94551800610, "u": 94551800680, "b": [["72715.04000000", "3.53082000"], ["72714.97000000", "0.10144000"], ["72714.77000000", "0.01417000"], ["72714.29000000", "0.00000000"], ["72714.08000000", "0.06615000"], ["72714.06000000", "0.00016000"], ["72713.76000000", "0.16418000"], ["72713.13000000", "0.00754000"], ["72711.25000000", "0.00753000"], ["72704.89000000", "1.40629000"], ["72702.35000000", "0.77226000"], ["72693.82000000", "0.28435000"], ["72693.81000000", "0.00000000"], ["65443.54000000", "0.00425000"], ["58172.04000000", "0.00000000"]], "a": [["72715.05000000", "0.15208000"], ["72715.06000000", "0.00094000"], ["72719.22000000", "0.00031000"], ["72719.77000000", "0.01386000"], ["72719.86000000", "0.00000000"], ["72719.87000000", "0.00016000"], ["72719.88000000", "0.01175000"], ["72720.02000000", "0.00000000"], ["72720.04000000", "0.00000000"], ["72720.47000000", "0.00008000"], ["72720.66000000", "0.50016000"], ["72721.90000000", "0.00008000"], ["72722.20000000", "0.00000000"], ["72722.33000000", "0.27331000"], ["72726.60000000", "0.00000000"], ["72744.14000000", "0.00686000"], ["72744.86000000", "0.00000000"], ["72745.59000000", "0.01817000"], ["72745.60000000", "0.00000000"]], "_local_ts_utc": "2026-06-01T07:49:10.110239+00:00"}
{"e": "depthUpdate", "E": 1780300151314, "s": "BTCUSDT", "U": 94551800681, "u": 94551800775, "b": [["72715.04000000", "3.58492000"], ["72714.82000000", "0.00016000"], ["72714.77000000", "0.01417000"], ["72714.31000000", "0.00000000"], ["72714.08000000", "0.00016000"], ["72714.06000000", "0.00000000"], ["72714.05000000", "0.06470000"], ["72714.00000000", "0.02000000"], ["72712.00000000", "0.01200000"], ["72710.00000000", "0.01200000"], ["72708.00000000", "0.00200000"], ["72706.00000000", "0.00200000"], ["72702.89000000", "0.02000000"], ["72702.86000000", "0.02000000"], ["72661.52000000", "0.21235000"], ["72659.07000000", "0.00000000"], ["72656.83000000", "0.18859000"], ["72655.32000000", "0.56577000"], ["72637.02000000", "0.02000000"], ["72636.89000000", "0.02000000"], ["72635.63000000", "0.00000000"], ["72601.85000000", "0.09642000"], ["72523.50000000", "0.00822000"], ["72508.25000000", "0.00000000"], ["72461.55000000", "0.00000000"], ["65443.54000000", "0.00408000"], ["58172.03000000", "0.00010000"], ["58172.00000000", "0.00000000"]], "a": [["72715.05000000", "0.03795000"], ["72715.06000000", "0.00102000"], ["72719.22000000", "0.00000000"], ["72719.77000000", "0.01386000"], ["72719.85000000", "0.01193000"], ["72719.87000000", "0.00000000"], ["72719.88000000", "0.00016000"], ["72720.02000000", "0.00000000"], ["72720.47000000", "0.00016000"], ["72720.64000000", "0.00031000"], ["72720.66000000", "0.50000000"], ["72721.79000000", "0.01100000"], ["72722.33000000", "0.00331000"], ["72722.80000000", "0.00000000"], ["72733.77000000", "0.08000000"], ["72733.92000000", "0.08600000"], ["72733.97000000", "0.07400000"], ["72736.56000000", "0.06200000"], ["72738.12000000", "0.00808000"], ["72738.67000000", "0.00000000"], ["72742.67000000", "0.00000000"], ["72743.10000000", "0.00000000"], ["72744.14000000", "0.00886000"], ["72745.14000000", "0.00000000"], ["72752.25000000", "0.00200000"], ["72752.62000000", "0.00000000"], ["72784.81000000", "0.00000000"], ["72872.51000000", "0.09606000"], ["88223.42000000", "0.00022000"]], "_local_ts_utc": "2026-06-01T07:49:10.210329+00:00"}
{"e": "depthUpdate", "E": 1780300151414, "s": "BTCUSDT", "U": 94551800776, "u": 94551800860, "b": [["72715.04000000", "3.42337000"], ["72714.97000000", "0.10144000"], ["72714.82000000", "0.00000000"], ["72714.77000000", "0.01417000"], ["72714.30000000", "0.00000000"], ["72714.08000000", "0.00000000"], ["72714.07000000", "0.06549000"], ["72714.05000000", "0.00016000"], ["72714.00000000", "0.02016000"], ["72712.55000000", "0.18913000"], ["72712.50000000", "0.16342000"], ["72708.00000000", "0.01200000"], ["72706.00000000", "0.01200000"], ["72704.00000000", "0.61769000"], ["72698.32000000", "0.00007000"], ["72694.37000000", "0.00000000"], ["72694.36000000", "0.00200000"], ["72664.14000000", "0.00041000"], ["72637.02000000", "0.00000000"], ["65443.54000000", "0.00408000"], ["58172.03000000", "0.00000000"]], "a": [["72715.05000000", "0.15417000"], ["72715.06000000", "0.00094000"], ["72719.77000000", "0.01386000"], ["72719.84000000", "0.00000000"], ["72719.85000000", "0.00032000"], ["72719.86000000", "0.01181000"], ["72719.88000000", "0.00031000"], ["72720.04000000", "0.00000000"], ["72720.47000000", "0.00008000"], ["72720.64000000", "0.00000000"], ["72720.65000000", "0.65996000"], ["72722.33000000", "0.27331000"], ["72727.42000000", "0.00007000"], ["72733.87000000", "0.08600000"], ["72742.54000000", "0.00000000"], ["72744.14000000", "0.01571000"], ["72752.55000000", "0.00200000"], ["72752.56000000", "0.00000000"], ["73369.48000000", "0.00010000"]], "_local_ts_utc": "2026-06-01T07:49:10.312753+00:00"}
{"e": "depthUpdate", "E": 1780300151514, "s": "BTCUSDT", "U": 94551800861, "u": 94551800951, "b": [["72715.04000000", "3.41937000"], ["72714.77000000", "0.01417000"], ["72714.07000000", "0.06565000"], ["72714.05000000", "0.00000000"], ["72713.13000000", "0.00754000"], ["72712.55000000", "0.00016000"], ["72712.50000000", "0.16326000"], ["72702.36000000", "0.16402000"], ["72702.34000000", "0.00000000"], ["72698.71000000", "0.00000000"], ["72636.35000000", "0.00000000"], ["65443.54000000", "0.00408000"], ["58172.04000000", "0.00034000"], ["50900.53000000", "0.00000000"]], "a": [["72715.05000000", "0.14247000"], ["72715.06000000", "0.00102000"], ["72715.61000000", "0.00000000"], ["72715.62000000", "0.00024000"], ["72718.25000000", "0.00042000"], ["72718.61000000", "0.00000000"], ["72719.34000000", "0.00031000"], ["72719.77000000", "0.01386000"], ["72719.85000000", "0.00016000"], ["72719.86000000", "0.01197000"], ["72720.45000000", "0.00000000"], ["72720.46000000", "0.00024000"], ["72720.47000000", "0.00016000"], ["72722.33000000", "0.27300000"], ["72722.72000000", "0.00000000"], ["72724.69000000", "0.00000000"], ["72724.74000000", "0.00000000"], ["72742.59000000", "0.00000000"], ["72744.14000000", "0.01371000"], ["72785.63000000", "0.00000000"], ["77854.65000000", "0.00019000"]], "_local_ts_utc": "2026-06-01T07:49:10.410195+00:00"}
{"e": "depthUpdate", "E": 1780300151614, "s": "BTCUSDT", "U": 94551800952, "u": 94551801010, "b": [["72714.00000000", "0.02656000"], ["72713.13000000", "0.00754000"], ["72712.55000000", "0.00000000"], ["72712.50000000", "0.16342000"], ["72712.00000000", "0.01280000"], ["72710.00000000", "0.01280000"], ["72708.00000000", "0.01280000"], ["72693.70000000", "0.66113000"], ["72648.66000000", "0.00014000"], ["72646.19000000", "0.00007000"], ["70533.59000000", "0.00353000"], ["65443.54000000", "0.00408000"], ["58172.04000000", "0.00000000"]], "a": [["72715.05000000", "0.14342000"], ["72715.06000000", "0.00094000"], ["72719.34000000", "0.00000000"], ["72719.86000000", "0.01197000"], ["72719.88000000", "0.00000000"], ["72720.46000000", "0.00039000"], ["72720.47000000", "0.00016000"], ["72720.66000000", "0.50016000"], ["72722.33000000", "0.00300000"], ["72737.88000000", "0.00400000"], ["72738.12000000", "0.00408000"], ["72742.47000000", "0.00000000"], ["72744.19000000", "0.00200000"], ["88228.57000000", "0.00371000"]], "_local_ts_utc": "2026-06-01T07:49:10.510341+00:00"}
{"e": "depthUpdate", "E": 1780300151714, "s": "BTCUSDT", "U": 94551801011, "u": 94551801117, "b": [["72715.04000000", "3.34495000"], ["72714.98000000", "0.00016000"], ["72714.78000000", "0.00016000"], ["72714.08000000", "0.00000000"], ["72714.01000000", "0.00000000"], ["72713.77000000", "0.00136000"], ["72711.37000000", "0.15768000"], ["72706.00000000", "0.01280000"], ["72705.91000000", "0.01377000"], ["72704.09000000", "0.16402000"], ["72704.03000000", "0.00000000"], ["72704.00000000", "0.61849000"], ["72702.36000000", "0.00000000"], ["72701.07000000", "0.00000000"], ["72700.96000000", "0.16402000"], ["72700.50000000", "0.16437000"], ["72694.36000000", "0.00000000"], ["72693.82000000", "0.44534000"], ["72693.64000000", "0.00200000"], ["72664.58000000", "0.00340000"], ["72664.57000000", "0.00000000"], ["72636.89000000", "0.00000000"], ["72593.00000000", "0.25440000"], ["72592.99000000", "0.00000000"], ["70897.16000000", "0.01056000"], ["65443.54000000", "0.00408000"]], "a": [["72715.05000000", "0.14344000"], ["72715.06000000", "0.00102000"], ["72715.61000000", "0.00016000"], ["72715.62000000", "0.00024000"], ["72719.23000000", "0.00031000"], ["72719.61000000", "0.00031000"], ["72719.76000000", "0.00000000"], ["72719.77000000", "0.00032000"], ["72719.78000000", "0.01413000"], ["72719.85000000", "0.00000000"], ["72720.16000000", "0.00008000"], ["72720.17000000", "0.15466000"], ["72720.47000000", "0.16410000"], ["72720.65000000", "0.65965000"], ["72721.79000000", "0.00000000"], ["72722.33000000", "0.27300000"], ["72723.29000000", "0.01100000"], ["72724.00000000", "0.00000000"], ["72751.83000000", "0.00200000"], ["72752.55000000", "0.00000000"], ["72810.08000000", "0.44458000"]], "_local_ts_utc": "2026-06-01T07:49:10.610438+00:00"}
{"e": "depthUpdate", "E": 1780300151814, "s": "BTCUSDT", "U": 94551801118, "u": 94551801185, "b": [["72715.04000000", "3.41529000"], ["72714.78000000", "0.00000000"], ["72713.59000000", "0.01859000"], ["72712.02000000", "0.00707000"], ["72707.78000000", "0.00000000"], ["72690.30000000", "0.00000000"], ["72688.40000000", "0.00400000"], ["65443.54000000", "0.00408000"]], "a": [["72715.05000000", "0.14247000"], ["72715.06000000", "0.00110000"], ["72715.61000000", "0.00016000"], ["72715.62000000", "0.02589000"], ["72718.26000000", "0.01501000"], ["72718.96000000", "0.00000000"], ["72718.99000000", "0.00000000"], ["72719.23000000", "0.00000000"], ["72719.61000000", "0.00000000"], ["72719.77000000", "0.00016000"], ["72719.78000000", "0.01398000"], ["72719.85000000", "0.00000000"], ["72719.86000000", "0.01197000"], ["72720.17000000", "0.15482000"], ["72720.46000000", "0.00008000"], ["72720.47000000", "0.16426000"], ["72720.50000000", "0.00031000"], ["72720.65000000", "0.65949000"], ["72720.66000000", "0.50000000"], ["72744.19000000", "0.00000000"], ["72752.62000000", "0.00400000"], ["72754.70000000", "0.00000000"], ["72808.42000000", "0.20920000"], ["79986.55000000", "0.00007000"], ["88789.71000000", "0.00022000"]], "_local_ts_utc": "2026-06-01T07:49:10.710232+00:00"}
{"e": "depthUpdate", "E": 1780300151914, "s": "BTCUSDT", "U": 94551801186, "u": 94551801225, "b": [["72715.04000000", "3.41137000"], ["72714.00000000", "0.03656000"], ["72713.76000000", "0.16418000"], ["72713.59000000", "0.01875000"], ["72712.50000000", "0.16326000"], ["72712.00000000", "0.02280000"], ["72710.00000000", "0.02280000"], ["72708.00000000", "0.02280000"], ["65443.54000000", "0.00391000"]], "a": [["72715.05000000", "0.15807000"], ["72715.62000000", "0.02605000"], ["72719.44000000", "0.00031000"], ["72720.49000000", "0.56121000"], ["72745.65000000", "0.00200000"], ["72751.94000000", "0.00200000"], ["72752.25000000", "0.00000000"], ["72870.56000000", "0.44999000"], ["72888.29000000", "0.00000000"], ["79986.55000000", "0.00000000"]], "_local_ts_utc": "2026-06-01T07:49:10.810204+00:00"}
{"e": "depthUpdate", "E": 1780300152014, "s": "BTCUSDT", "U": 94551801226, "u": 94551801271, "b": [["72715.04000000", "3.40951000"], ["72713.77000000", "0.00144000"], ["72708.32000000", "0.00000000"], ["72706.00000000", "0.02280000"], ["72704.90000000", "0.14897000"], ["72704.00000000", "0.62849000"], ["72702.36000000", "0.00008000"], ["72702.35000000", "0.77218000"], ["72700.49000000", "0.48696000"], ["72697.40000000", "0.16349000"], ["72697.38000000", "0.00000000"], ["72693.92000000", "0.00200000"], ["72693.71000000", "0.00008000"], ["72693.64000000", "0.00000000"], ["72690.73000000", "0.00000000"], ["65443.54000000", "0.00391000"], ["58172.04000000", "0.00034000"], ["58172.00000000", "0.00200000"]], "a": [["72715.05000000", "0.15807000"], ["72715.61000000", "0.00024000"], ["72718.25000000", "0.00034000"], ["72718.26000000", "0.01519000"], ["72718.64000000", "0.00000000"], ["72719.77000000", "0.00024000"], ["72719.78000000", "0.00016000"], ["72721.59000000", "0.00000000"], ["72721.90000000", "0.00000000"], ["72722.83000000", "0.00008000"], ["72724.02000000", "3.90155000"], ["72730.74000000", "0.00000000"], ["72731.24000000", "0.00008000"], ["72732.32000000", "0.00000000"], ["72732.67000000", "0.00000000"], ["72733.91000000", "0.00008000"], ["72737.04000000", "2.74993000"], ["72739.51000000", "0.68850000"], ["72749.06000000", "0.00000000"], ["72751.83000000", "0.00000000"], ["72752.11000000", "0.00200000"], ["72761.87000000", "0.00000000"], ["89169.94000000", "0.00007000"]], "_local_ts_utc": "2026-06-01T07:49:10.910619+00:00"}
{"e": "depthUpdate", "E": 1780300152114, "s": "BTCUSDT", "U": 94551801272, "u": 94551801310, "b": [["72715.04000000", "3.33509000"], ["65443.54000000", "0.00391000"], ["58172.00000000", "0.00000000"]], "a": [["72715.05000000", "0.15791000"], ["72715.06000000", "0.00102000"], ["72718.26000000", "0.01519000"], ["72718.55000000", "0.00031000"], ["72719.77000000", "0.00008000"], ["72719.78000000", "0.00000000"], ["72719.85000000", "0.00016000"], ["72720.49000000", "0.56137000"], ["72721.84000000", "0.01100000"], ["72722.33000000", "0.27300000"], ["72723.21000000", "0.00774000"], ["72723.29000000", "0.00000000"]], "_local_ts_utc": "2026-06-01T07:49:11.010306+00:00"}
{"e": "depthUpdate", "E": 1780300152214, "s": "BTCUSDT", "U": 94551801311, "u": 94551801411, "b": [["72715.04000000", "3.33701000"], ["72714.78000000", "0.00000000"], ["72714.77000000", "0.00016000"], ["72714.70000000", "0.00000000"], ["72714.67000000", "0.00000000"], ["72714.08000000", "0.06627000"], ["72714.07000000", "0.00016000"], ["72714.01000000", "0.00016000"], ["72714.00000000", "0.03672000"], ["72713.99000000", "0.00000000"], ["72713.94000000", "0.01399000"], ["72713.77000000", "0.00160000"], ["72713.13000000", "0.00016000"], ["72712.52000000", "0.00016000"], ["72711.37000000", "0.00000000"], ["72705.91000000", "0.00000000"], ["72700.96000000", "0.00000000"], ["72700.50000000", "0.00035000"], ["65443.54000000", "0.00408000"], ["58172.04000000", "0.00000000"]], "a": [["72715.05000000", "0.13164000"], ["72715.06000000", "0.00102000"], ["72717.14000000", "0.00000000"], ["72717.51000000", "0.00028000"], ["72718.18000000", "0.00031000"], ["72718.48000000", "0.00031000"], ["72719.79000000", "0.00000000"], ["72719.82000000", "0.00016000"], ["72719.83000000", "0.00000000"], ["72719.85000000", "0.01135000"], ["72719.86000000", "0.00016000"], ["72720.50000000", "0.00000000"], ["72724.00000000", "0.16402000"], ["72724.47000000", "0.00000000"], ["72736.99000000", "0.00400000"], ["72737.88000000", "0.00000000"], ["72749.69000000", "0.00200000"], ["72751.94000000", "0.00000000"], ["72909.26000000", "0.00007000"], ["72911.46000000", "0.00000000"]], "_local_ts_utc": "2026-06-01T07:49:11.110144+00:00"}
{"e": "depthUpdate", "E": 1780300152314, "s": "BTCUSDT", "U": 94551801412, "u": 94551802099, "b": [["72720.47000000", "6.01773000"], ["72720.46000000", "0.00038000"], ["72720.45000000", "0.00014000"], ["72720.20000000", "0.00000000"], ["72720.16000000", "0.00000000"], ["72719.92000000", "0.00400000"], ["72719.84000000", "0.00000000"], ["72719.53000000", "0.07604000"], ["72719.31000000", "0.01100000"], ["72719.19000000", "0.16401000"], ["72718.93000000", "0.40990000"], ["72718.92000000", "0.23408000"], ["72718.83000000", "0.00007000"], ["72718.25000000", "0.27407000"], ["72718.24000000", "0.47755000"], ["72718.11000000", "0.21913000"], ["72718.10000000", "0.00400000"], ["72717.77000000", "0.05942000"], ["72717.60000000", "0.00009000"], ["72716.76000000", "0.00028000"], ["72716.74000000", "0.04055000"], ["72716.63000000", "0.16401000"], ["72716.28000000", "0.00400000"], ["72715.93000000", "0.00000000"], ["72715.63000000", "0.69160000"], ["72715.62000000", "0.32544000"], ["72715.61000000", "0.00000000"], ["72715.60000000", "0.00000000"], ["72715.51000000", "0.00000000"], ["72715.14000000", "0.00007000"], ["72715.13000000", "0.00000000"], ["72715.06000000", "0.00000000"], ["72715.05000000", "0.26500000"], ["72715.04000000", "0.67928000"], ["72715.03000000", "0.00053000"], ["72715.02000000", "0.00000000"], ["72714.98000000", "0.00000000"], ["72714.97000000", "0.00016000"], ["72714.77000000", "0.00000000"], ["72714.68000000", "0.01485000"], ["72714.08000000", "0.00016000"], ["72714.07000000", "0.00000000"], ["72714.01000000", "0.00000000"], ["72714.00000000", "0.03656000"], ["72713.96000000", "0.00000000"], ["72713.94000000", "0.01415000"], ["72713.93000000", "0.00000000"], ["72713.77000000", "0.00136000"], ["72713.76000000", "0.00016000"], ["72713.59000000", "0.01875000"], ["72713.13000000", "0.00000000"], ["72712.79000000", "0.16401000"], ["72712.52000000", "0.00008000"], ["72712.50000000", "0.00000000"], ["72712.16000000", "0.00011000"], ["72712.07000000", "0.00000000"], ["72711.52000000", "0.00008000"], ["72711.51000000", "0.16401000"], ["72710.43000000", "0.00020000"], ["72709.44000000", "0.00008000"], ["72706.63000000", "0.12000000"], ["72706.45000000", "0.00000000"], ["72705.04000000", "0.00000000"], ["72703.75000000", "0.00805000"], ["72703.32000000", "0.00000000"], ["72702.36000000", "0.00008000"], ["72701.93000000", "0.01033000"], ["72701.62000000", "0.02000000"], ["72701.57000000", "0.00349000"], ["72700.96000000", "0.00000000"], ["72700.50000000", "0.00035000"], ["72698.40000000", "0.00008000"], ["72698.32000000", "0.00000000"], ["72697.40000000", "0.00019000"], ["72697.20000000", "0.00000000"], ["72695.44000000", "0.00202000"], ["72695.37000000", "0.00400000"], ["72694.23000000", "0.00000000"], ["72693.71000000", "0.00000000"], ["72693.30000000", "0.00020000"], ["72691.38000000", "0.00686000"], ["72691.23000000", "0.00000000"], ["72690.80000000", "0.00000000"], ["72688.98000000", "0.00000000"], ["72687.16000000", "0.00000000"], ["72686.90000000", "0.00008000"], ["72686.89000000", "1.36372000"], ["72686.38000000", "0.49590000"], ["72685.95000000", "0.00000000"], ["72683.59000000", "0.00000000"], ["72682.86000000", "0.00626000"], ["72682.25000000", "0.00000000"], ["72681.93000000", "0.00000000"], ["72678.99000000", "0.00000000"], ["72678.26000000", "0.00185000"], ["72677.43000000", "0.00020000"], ["72669.24000000", "0.00020000"], ["72669.06000000", "0.00000000"], ["72661.52000000", "0.14191000"], ["72659.33000000", "0.02415000"], ["72656.82000000", "0.00000000"], ["72656.00000000", "0.94716000"], ["72650.39000000", "0.00000000"], ["72643.31000000", "0.00013000"], ["72642.97000000", "0.00000000"], ["72640.00000000", "0.21030000"], ["72601.85000000", "0.00000000"], ["72446.20000000", "0.09662000"], ["72160.00000000", "0.02324000"], ["65448.43000000", "0.00017000"], ["65443.54000000", "0.00000000"]], "a": [["72715.05000000", "0.00000000"], ["72715.06000000", "0.00000000"], ["72715.07000000", "0.00000000"], ["72715.14000000", "0.00000000"], ["72715.61000000", "0.00000000"], ["72715.62000000", "0.00000000"], ["72715.63000000", "0.00000000"], ["72715.94000000", "0.00000000"], ["72717.51000000", "0.00000000"], ["72718.12000000", "0.00000000"], ["72718.13000000", "0.00000000"], ["72718.18000000", "0.00000000"], ["72718.25000000", "0.00000000"], ["72718.26000000", "0.00000000"], ["72718.48000000", "0.00000000"], ["72718.55000000", "0.00000000"], ["72718.83000000", "0.00000000"], ["72718.93000000", "0.00000000"], ["72719.44000000", "0.00000000"], ["72719.77000000", "0.00000000"], ["72719.82000000", "0.00000000"], ["72719.85000000", "0.00000000"], ["72719.86000000", "0.00000000"], ["72720.16000000", "0.00000000"], ["72720.17000000", "0.00000000"], ["72720.21000000", "0.00000000"], ["72720.46000000", "0.00000000"], ["72720.47000000", "0.00000000"], ["72720.48000000", "0.24126000"], ["72720.49000000", "0.00080000"], ["72720.64000000", "0.00000000"], ["72720.65000000", "0.00032000"], ["72720.66000000", "0.50016000"], ["72721.11000000", "0.00000000"], ["72721.15000000", "0.00165000"], ["72721.32000000", "0.00016000"], ["72721.48000000", "0.00024000"], ["72721.84000000", "0.00016000"], ["72721.90000000", "0.00016000"], ["72721.91000000", "0.20016000"], ["72722.03000000", "0.01485000"], ["72722.33000000", "0.00316000"], ["72722.83000000", "0.00024000"], ["72722.84000000", "0.00016000"], ["72723.10000000", "0.00000000"], ["72723.21000000", "0.00000000"], ["72723.56000000", "0.00000000"], ["72723.81000000", "0.00016000"], ["72723.82000000", "0.00000000"], ["72723.90000000", "0.00000000"], ["72723.99000000", "0.40856000"], ["72724.00000000", "0.00000000"], ["72724.01000000", "0.00016000"], ["72724.02000000", "3.55803000"], ["72724.03000000", "0.00000000"], ["72724.60000000", "0.00008000"], ["72724.61000000", "0.65319000"], ["72725.20000000", "0.00000000"], ["72725.35000000", "0.00000000"], ["72725.38000000", "0.00000000"], ["72725.54000000", "0.01187000"], ["72725.84000000", "0.00000000"], ["72725.94000000", "0.00000000"], ["72726.07000000", "0.00000000"], ["72726.62000000", "0.00000000"], ["72726.70000000", "0.02000000"], ["72727.34000000", "0.00031000"], ["72727.42000000", "0.00000000"], ["72727.84000000", "0.67359000"], ["72728.49000000", "0.00000000"], ["72728.88000000", "0.00754000"], ["72729.41000000", "0.00000000"], ["72729.61000000", "0.27300000"], ["72731.25000000", "0.00000000"], ["72731.55000000", "0.00000000"], ["72731.65000000", "0.00000000"], ["72731.75000000", "0.00000000"], ["72732.33000000", "0.00000000"], ["72732.68000000", "0.00007000"], ["72732.85000000", "0.00007000"], ["72734.35000000", "0.00000000"], ["72734.71000000", "0.12085000"], ["72734.76000000", "0.51446000"], ["72736.55000000", "0.03000000"], ["72736.60000000", "0.00000000"], ["72736.99000000", "0.00000000"], ["72737.04000000", "0.00008000"], ["72737.81000000", "0.00903000"], ["72739.51000000", "0.00008000"], ["72741.98000000", "0.00000000"], ["72742.54000000", "0.00400000"], ["72743.99000000", "0.68841000"], ["72744.14000000", "0.00000000"], ["72748.86000000", "0.00000000"], ["72749.06000000", "0.45885000"], ["72749.57000000", "0.01371000"], ["72752.04000000", "0.00007000"], ["72753.56000000", "0.00000000"], ["72755.05000000", "0.00000000"], ["72755.24000000", "0.00000000"], ["72755.73000000", "0.00007000"], ["72756.19000000", "0.00000000"], ["72756.32000000", "0.00400000"], ["72756.96000000", "0.00000000"], ["72758.14000000", "0.00454000"], ["72770.62000000", "0.00000000"], ["72771.45000000", "0.00000000"], ["72777.75000000", "0.49527000"], ["72784.28000000", "1.36189000"], ["72792.14000000", "0.00105000"], ["72800.00000000", "0.02613000"], ["72802.71000000", "0.00939000"], ["72803.44000000", "0.00000000"], ["72808.42000000", "0.08771000"], ["72810.08000000", "0.00000000"], ["72812.51000000", "2.76609000"], ["72844.26000000", "0.00000000"], ["72872.51000000", "0.00000000"], ["72936.52000000", "0.00626000"], ["72937.25000000", "0.00000000"], ["73280.00000000", "0.00716000"]], "_local_ts_utc": "2026-06-01T07:49:11.210201+00:00"}
{"e": "depthUpdate", "E": 1780300152414, "s": "BTCUSDT", "U": 94551802100, "u": 94551802345, "b": [["72720.47000000", "6.60320000"], ["72719.53000000", "0.07620000"], ["72719.31000000", "0.01116000"], ["72719.19000000", "0.16417000"], ["72718.93000000", "0.41006000"], ["72718.92000000", "0.23424000"], ["72718.25000000", "0.27423000"], ["72718.24000000", "0.47771000"], ["72717.81000000", "0.01381000"], ["72717.77000000", "0.00000000"], ["72717.02000000", "0.15317000"], ["72715.99000000", "0.00743000"], ["72715.63000000", "0.45718000"], ["72715.62000000", "0.16272000"], ["72715.05000000", "0.11120000"], ["72715.04000000", "0.67817000"], ["72714.97000000", "0.00000000"], ["72714.18000000", "0.00024000"], ["72714.09000000", "0.03407000"], ["72714.08000000", "0.00000000"], ["72714.07000000", "0.16401000"], ["72714.00000000", "0.03640000"], ["72713.94000000", "0.01399000"], ["72713.76000000", "0.00000000"], ["72713.59000000", "0.01859000"], ["72713.19000000", "0.65949000"], ["72712.51000000", "0.36180000"], ["72712.35000000", "0.00763000"], ["72711.43000000", "0.40856000"], ["72710.18000000", "0.65949000"], ["72709.83000000", "0.01000000"], ["72709.33000000", "0.02000000"], ["72708.31000000", "0.46793000"], ["72707.43000000", "0.02000000"], ["72705.45000000", "0.02000000"], ["72701.93000000", "0.00033000"], ["72701.62000000", "0.00000000"], ["72700.03000000", "0.00000000"], ["72697.15000000", "0.00011000"], ["72694.25000000", "0.00000000"], ["72688.58000000", "0.02770000"], ["72683.17000000", "0.00000000"], ["72675.46000000", "0.00137000"], ["72667.93000000", "0.00432000"], ["72667.64000000", "0.00617000"], ["72660.57000000", "0.00000000"], ["72654.67000000", "0.00000000"], ["72654.60000000", "0.00000000"], ["72653.56000000", "0.00000000"], ["72650.74000000", "0.00000000"], ["72515.78000000", "0.00000000"], ["72425.43000000", "0.00000000"], ["70533.59000000", "0.00706000"], ["65448.43000000", "0.00051000"], ["58176.38000000", "0.00000000"]], "a": [["72720.48000000", "0.13470000"], ["72720.49000000", "0.00048000"], ["72720.65000000", "0.00016000"], ["72720.66000000", "0.50016000"], ["72721.15000000", "0.00000000"], ["72721.32000000", "0.00000000"], ["72721.48000000", "0.00000000"], ["72721.84000000", "0.00000000"], ["72721.91000000", "0.20016000"], ["72722.03000000", "0.00016000"], ["72722.33000000", "0.00300000"], ["72722.83000000", "0.00008000"], ["72722.84000000", "0.00000000"], ["72723.81000000", "0.00000000"], ["72723.98000000", "0.00000000"], ["72723.99000000", "0.00016000"], ["72724.01000000", "0.00024000"], ["72724.02000000", "1.59766000"], ["72724.13000000", "0.00000000"], ["72724.60000000", "0.00024000"], ["72724.61000000", "0.33078000"], ["72724.95000000", "0.00000000"], ["72724.99000000", "0.00000000"], ["72725.54000000", "0.01203000"], ["72726.60000000", "0.00000000"], ["72726.70000000", "0.02016000"], ["72727.20000000", "0.00000000"], ["72727.34000000", "0.00000000"], ["72727.82000000", "0.00008000"], ["72727.83000000", "0.23369000"], ["72727.84000000", "0.01410000"], ["72729.02000000", "0.00000000"], ["72729.03000000", "0.00164000"], ["72729.19000000", "0.00550000"], ["72729.61000000", "0.00300000"], ["72729.72000000", "0.01484000"], ["72729.78000000", "0.00031000"], ["72730.03000000", "0.06492000"], ["72730.41000000", "0.00069000"], ["72730.74000000", "0.65949000"], ["72730.75000000", "0.00000000"], ["72731.08000000", "0.00031000"], ["72731.67000000", "0.00189000"], ["72733.77000000", "0.00000000"], ["72733.78000000", "0.00000000"], ["72733.92000000", "0.00000000"], ["72733.97000000", "0.00000000"], ["72736.08000000", "0.00000000"], ["72736.55000000", "0.00000000"], ["72736.56000000", "0.00000000"], ["72736.80000000", "0.00000000"], ["72737.04000000", "0.16408000"], ["72737.05000000", "0.40856000"], ["72738.12000000", "0.16809000"], ["72739.76000000", "0.15000000"], ["72743.57000000", "0.07400000"], ["72743.99000000", "0.00000000"], ["72745.99000000", "0.68832000"], ["72748.47000000", "0.00000000"], ["72748.53000000", "0.00000000"], ["72751.72000000", "0.00000000"], ["72753.82000000", "0.00000000"], ["72754.84000000", "0.00000000"], ["72754.87000000", "0.00000000"], ["72756.64000000", "0.00000000"], ["72759.36000000", "0.00426000"], ["72759.75000000", "0.00620000"], ["72759.96000000", "0.00400000"], ["72761.78000000", "0.00400000"], ["72765.88000000", "0.00432000"], ["72770.89000000", "0.23247000"], ["72774.01000000", "0.43387000"], ["72776.99000000", "0.00189000"], ["72788.63000000", "0.00000000"], ["72789.28000000", "0.00097000"], ["72790.80000000", "0.00000000"], ["72791.62000000", "0.00000000"], ["72792.28000000", "0.82619000"], ["72849.99000000", "0.00075000"], ["72911.12000000", "0.00007000"], ["72914.75000000", "0.00007000"]], "_local_ts_utc": "2026-06-01T07:49:11.310918+00:00"}
{"e": "depthUpdate", "E": 1780300152514, "s": "BTCUSDT", "U": 94551802346, "u": 94551802424, "b": [["72720.47000000", "6.61474000"], ["72719.31000000", "0.00016000"], ["72718.25000000", "0.11136000"], ["72715.62000000", "0.00000000"], ["72714.12000000", "0.16272000"], ["72711.23000000", "0.00000000"], ["72704.74000000", "0.00000000"], ["72704.09000000", "0.00000000"], ["72693.98000000", "0.00118000"], ["72693.66000000", "0.00012000"], ["72680.90000000", "0.00000000"], ["72680.01000000", "0.00315000"], ["72664.19000000", "1.04041000"], ["72663.62000000", "0.00435000"], ["72551.44000000", "0.09873000"], ["72433.90000000", "0.00034000"], ["65448.43000000", "0.00085000"], ["65448.00000000", "0.00000000"], ["58176.38000000", "0.00034000"]], "a": [["72720.48000000", "0.13459000"], ["72721.91000000", "0.20016000"], ["72722.03000000", "0.00000000"], ["72723.99000000", "0.00000000"], ["72724.00000000", "0.00016000"], ["72724.01000000", "0.58571000"], ["72724.99000000", "0.00028000"], ["72727.76000000", "0.04023000"], ["72727.82000000", "0.00000000"], ["72727.83000000", "0.23385000"], ["72727.84000000", "0.00008000"], ["72728.34000000", "0.00031000"], ["72728.88000000", "0.00000000"], ["72728.90000000", "0.00024000"], ["72728.96000000", "0.01381000"], ["72729.19000000", "0.00000000"], ["72729.47000000", "0.00750000"], ["72729.49000000", "0.00031000"], ["72729.66000000", "0.00031000"], ["72729.94000000", "0.00578000"], ["72729.97000000", "0.00550000"], ["72730.03000000", "0.00000000"], ["72731.03000000", "0.35698000"], ["72731.08000000", "0.00000000"], ["72731.35000000", "0.00047000"], ["72733.87000000", "0.00000000"], ["72734.45000000", "0.16272000"], ["72734.70000000", "0.15580000"], ["72736.99000000", "0.16272000"], ["72738.12000000", "0.00408000"], ["72745.16000000", "0.04600000"], ["72749.69000000", "0.00000000"], ["72755.16000000", "0.00200000"], ["72755.19000000", "0.00000000"], ["72765.75000000", "0.00425000"], ["72767.72000000", "1.03893000"], ["72792.28000000", "0.00000000"], ["72792.32000000", "0.00000000"], ["72792.68000000", "0.82614000"], ["72797.86000000", "0.04600000"], ["72914.75000000", "0.00000000"]], "_local_ts_utc": "2026-06-01T07:49:11.410244+00:00"}
{"e": "depthUpdate", "E": 1780300152614, "s": "BTCUSDT", "U": 94551802425, "u": 94551802488, "b": [["72720.47000000", "6.59202000"], ["72720.18000000", "0.00752000"], ["72719.60000000", "0.00008000"], ["72719.53000000", "0.07620000"], ["72719.31000000", "0.00000000"], ["72719.20000000", "0.16272000"], ["72718.94000000", "0.40856000"], ["72718.11000000", "0.21929000"], ["72718.09000000", "0.00753000"], ["72714.89000000", "0.01376000"], ["72714.09000000", "0.00000000"], ["72713.75000000", "0.00000000"], ["72713.02000000", "0.00000000"], ["72711.52000000", "2.75054000"], ["72704.01000000", "0.00000000"], ["72700.37000000", "0.00000000"], ["72698.26000000", "0.00200000"], ["72693.92000000", "0.00000000"], ["72670.90000000", "0.00007000"], ["72665.95000000", "0.00007000"], ["72665.66000000", "0.00425000"], ["72664.58000000", "0.00000000"], ["72655.45000000", "0.82614000"], ["72652.73000000", "0.00000000"], ["72650.40000000", "0.00000000"], ["72647.55000000", "0.00000000"], ["72634.34000000", "0.00000000"], ["72593.00000000", "0.25303000"], ["72528.57000000", "0.00822000"], ["72523.50000000", "0.00000000"], ["71987.88000000", "0.00000000"], ["65448.43000000", "0.00119000"], ["58176.38000000", "0.00000000"]], "a": [["72720.48000000", "0.13467000"], ["72720.49000000", "0.00056000"], ["72721.91000000", "0.20016000"], ["72724.00000000", "0.00000000"], ["72724.01000000", "0.00040000"], ["72727.82000000", "0.00008000"], ["72727.83000000", "0.23369000"], ["72728.34000000", "0.00000000"], ["72729.49000000", "0.00000000"], ["72730.89000000", "0.05942000"], ["72752.11000000", "0.00000000"], ["72756.47000000", "0.00200000"], ["72768.50000000", "0.00000000"], ["72782.63000000", "0.01088000"], ["72792.68000000", "0.00000000"], ["72796.54000000", "0.82614000"], ["73442.21000000", "0.00000000"], ["89317.29000000", "0.00009000"]], "_local_ts_utc": "2026-06-01T07:49:11.510344+00:00"}
{"e": "depthUpdate", "E": 1780300152714, "s": "BTCUSDT", "U": 94551802489, "u": 94551803771, "b": [["72725.53000000", "2.79472000"], ["72725.52000000", "0.14378000"], ["72725.51000000", "0.00014000"], ["72725.38000000", "0.00400000"], ["72725.25000000", "0.14895000"], ["72724.99000000", "0.00009000"], ["72724.98000000", "0.00000000"], ["72724.61000000", "0.00008000"], ["72724.60000000", "0.16287000"], ["72724.59000000", "0.34829000"], ["72724.58000000", "0.00000000"], ["72724.57000000", "0.00000000"], ["72724.27000000", "0.13750000"], ["72724.15000000", "0.00000000"], ["72724.02000000", "0.82239000"], ["72724.01000000", "0.74248000"], ["72724.00000000", "0.00000000"], ["72723.99000000", "0.00000000"], ["72723.83000000", "0.01357000"], ["72723.56000000", "0.00400000"], ["72722.82000000", "0.00000000"], ["72722.73000000", "0.00000000"], ["72722.52000000", "0.16277000"], ["72722.51000000", "0.00000000"], ["72722.49000000", "0.00000000"], ["72722.33000000", "0.00000000"], ["72722.32000000", "0.47260000"], ["72722.09000000", "0.00000000"], ["72721.93000000", "0.04055000"], ["72721.91000000", "0.75638000"], ["72721.90000000", "0.00000000"], ["72721.89000000", "0.00000000"], ["72721.74000000", "0.00400000"], ["72721.51000000", "0.00000000"], ["72721.37000000", "0.00020000"], ["72721.36000000", "0.00016000"], ["72721.35000000", "0.00000000"], ["72720.66000000", "0.40856000"], ["72720.65000000", "0.16286000"], ["72720.64000000", "0.80140000"], ["72720.58000000", "0.00000000"], ["72720.52000000", "0.00000000"], ["72720.51000000", "0.00016000"], ["72720.48000000", "0.56175000"], ["72720.47000000", "1.69320000"], ["72720.46000000", "0.00000000"], ["72720.45000000", "0.00000000"], ["72720.18000000", "0.00752000"], ["72719.53000000", "0.00000000"], ["72719.21000000", "0.00000000"], ["72719.20000000", "0.00000000"], ["72719.19000000", "0.00000000"], ["72719.18000000", "0.14644000"], ["72718.96000000", "0.16270000"], ["72718.95000000", "0.36626000"], ["72718.94000000", "0.00000000"], ["72718.93000000", "0.00000000"], ["72718.92000000", "0.18284000"], ["72718.41000000", "0.00165000"], ["72718.25000000", "0.00000000"], ["72718.24000000", "0.38164000"], ["72718.11000000", "0.16814000"], ["72717.84000000", "0.00000000"], ["72717.24000000", "0.00000000"], ["72717.02000000", "0.00000000"], ["72716.83000000", "0.00000000"], ["72716.80000000", "0.00008000"], ["72716.64000000", "0.16270000"], ["72716.63000000", "0.00000000"], ["72715.64000000", "0.16270000"], ["72715.63000000", "0.45710000"], ["72715.58000000", "0.00165000"], ["72715.06000000", "0.00028000"], ["72715.05000000", "0.00008000"], ["72715.04000000", "0.67087000"], ["72714.59000000", "0.00000000"], ["72714.12000000", "0.00000000"], ["72714.10000000", "0.16270000"], ["72714.07000000", "0.00000000"], ["72713.43000000", "0.00000000"], ["72713.20000000", "0.16270000"], ["72712.83000000", "0.00007000"], ["72712.79000000", "0.00000000"], ["72712.52000000", "0.16278000"], ["72712.51000000", "1.23684000"], ["72711.94000000", "0.03407000"], ["72711.75000000", "0.00000000"], ["72711.58000000", "0.00000000"], ["72711.53000000", "0.14941000"], ["72711.52000000", "2.75046000"], ["72711.51000000", "0.00000000"], ["72710.89000000", "0.00000000"], ["72710.47000000", "0.00000000"], ["72709.96000000", "0.00000000"], ["72708.87000000", "0.00349000"], ["72708.69000000", "0.00000000"], ["72708.31000000", "0.31938000"], ["72707.87000000", "0.00000000"], ["72707.81000000", "0.01100000"], ["72707.71000000", "0.01289000"], ["72707.65000000", "0.00000000"], ["72707.42000000", "0.00000000"], ["72706.17000000", "0.00000000"], ["72705.81000000", "0.00000000"], ["72705.76000000", "0.00008000"], ["72705.69000000", "0.00000000"], ["72705.43000000", "0.00000000"], ["72705.32000000", "0.00000000"], ["72705.21000000", "0.16270000"], ["72705.16000000", "0.00011000"], ["72705.04000000", "0.00000000"], ["72704.90000000", "0.16270000"], ["72704.00000000", "0.02280000"], ["72703.58000000", "0.00000000"], ["72703.53000000", "0.00007000"], ["72700.30000000", "0.00400000"], ["72699.37000000", "0.49581000"], ["72698.16000000", "0.00000000"], ["72697.40000000", "0.00011000"], ["72697.15000000", "0.00000000"], ["72697.14000000", "0.00192000"], ["72696.43000000", "0.01371000"], ["72696.26000000", "0.00000000"], ["72694.72000000", "1.36365000"], ["72694.44000000", "0.00000000"], ["72694.07000000", "0.02698000"], ["72692.62000000", "0.00000000"], ["72691.38000000", "0.00000000"], ["72688.58000000", "0.00051000"], ["72688.40000000", "0.00000000"], ["72686.90000000", "1.10296000"], ["72686.71000000", "0.00000000"], ["72685.62000000", "0.00000000"], ["72683.02000000", "0.00007000"], ["72681.85000000", "0.00000000"], ["72680.11000000", "0.00008000"], ["72677.43000000", "0.00000000"], ["72672.42000000", "0.00000000"], ["72669.24000000", "0.00000000"], ["72666.29000000", "0.00000000"], ["72664.52000000", "0.00000000"], ["72663.74000000", "0.00000000"], ["72655.45000000", "0.00000000"], ["72651.29000000", "0.00008000"], ["72650.67000000", "0.01077000"], ["72648.64000000", "0.01724000"], ["72646.19000000", "0.00000000"], ["72645.47000000", "0.00000000"], ["72642.34000000", "0.00000000"], ["72634.35000000", "0.21847000"], ["72633.97000000", "0.00000000"], ["72630.86000000", "0.00000000"], ["72598.82000000", "0.00000000"], ["72578.56000000", "0.00008000"], ["72569.63000000", "0.00000000"], ["72559.89000000", "4.13971000"], ["72505.84000000", "0.00008000"], ["72496.91000000", "0.00000000"], ["72446.73000000", "4.14617000"], ["72443.99000000", "0.00000000"], ["72433.11000000", "0.00008000"], ["72432.36000000", "0.00028000"], ["72424.20000000", "0.00033000"], ["72360.39000000", "0.00008000"], ["72351.48000000", "0.00000000"], ["72287.67000000", "0.00008000"], ["72278.77000000", "0.00000000"], ["72214.94000000", "0.00008000"], ["72206.05000000", "0.00000000"], ["72142.22000000", "0.00008000"], ["72133.34000000", "0.00000000"], ["65452.98000000", "0.00017000"], ["65452.14000000", "0.00000000"], ["65448.43000000", "0.00000000"]], "a": [["72720.48000000", "0.00000000"], ["72720.49000000", "0.00000000"], ["72720.65000000", "0.00000000"], ["72720.66000000", "0.00000000"], ["72721.90000000", "0.00000000"], ["72721.91000000", "0.00000000"], ["72722.33000000", "0.00000000"], ["72722.50000000", "0.00000000"], ["72722.52000000", "0.00000000"], ["72722.83000000", "0.00000000"], ["72724.01000000", "0.00000000"], ["72724.02000000", "0.00000000"], ["72724.16000000", "0.00000000"], ["72724.60000000", "0.00000000"], ["72724.61000000", "0.00000000"], ["72724.99000000", "0.00000000"], ["72725.26000000", "0.00000000"], ["72725.53000000", "0.00000000"], ["72725.54000000", "0.00307000"], ["72725.55000000", "0.00064000"], ["72726.69000000", "0.00000000"], ["72726.70000000", "0.00016000"], ["72727.74000000", "0.00000000"], ["72727.75000000", "0.00016000"], ["72727.82000000", "0.00000000"], ["72727.83000000", "0.00016000"], ["72728.96000000", "0.00016000"], ["72729.03000000", "0.00000000"], ["72729.15000000", "0.00589000"], ["72729.37000000", "0.00000000"], ["72729.47000000", "0.00016000"], ["72729.48000000", "0.00000000"], ["72729.66000000", "0.00000000"], ["72729.72000000", "0.00016000"], ["72729.74000000", "0.00000000"], ["72729.78000000", "0.00000000"], ["72729.94000000", "0.00044000"], ["72729.97000000", "0.00016000"], ["72730.28000000", "0.00000000"], ["72730.41000000", "0.00000000"], ["72730.64000000", "0.00000000"], ["72730.73000000", "0.00000000"], ["72730.74000000", "0.00308000"], ["72730.84000000", "0.00000000"], ["72730.89000000", "0.00000000"], ["72731.02000000", "0.00016000"], ["72731.03000000", "0.04798000"], ["72731.06000000", "0.00000000"], ["72731.35000000", "0.00000000"], ["72731.67000000", "0.00000000"], ["72731.95000000", "0.00000000"], ["72731.99000000", "0.00016000"], ["72732.11000000", "0.00000000"], ["72732.30000000", "0.00016000"], ["72732.31000000", "0.02000000"], ["72732.61000000", "0.00000000"], ["72732.66000000", "0.00000000"], ["72733.17000000", "0.00000000"], ["72733.18000000", "0.00108000"], ["72733.99000000", "0.00008000"], ["72734.25000000", "0.00016000"], ["72734.43000000", "0.14952000"], ["72734.45000000", "0.00000000"], ["72734.48000000", "0.00000000"], ["72734.64000000", "0.00000000"], ["72734.70000000", "0.00000000"], ["72734.78000000", "0.00000000"], ["72734.79000000", "0.00000000"], ["72735.38000000", "0.00048000"], ["72735.49000000", "0.00031000"], ["72735.58000000", "0.00070000"], ["72735.70000000", "0.16270000"], ["72735.91000000", "0.00000000"], ["72736.32000000", "0.00164000"], ["72736.59000000", "0.16278000"], ["72736.60000000", "0.65949000"], ["72736.67000000", "0.00000000"], ["72736.82000000", "0.00749000"], ["72736.87000000", "0.00000000"], ["72736.99000000", "0.00000000"], ["72737.04000000", "0.00008000"], ["72738.12000000", "0.16678000"], ["72738.13000000", "0.79670000"], ["72738.14000000", "0.00000000"], ["72738.33000000", "0.01484000"], ["72738.77000000", "0.05942000"], ["72738.78000000", "0.01100000"], ["72739.50000000", "0.15014000"], ["72739.51000000", "0.65957000"], ["72739.52000000", "0.00000000"], ["72739.54000000", "0.00000000"], ["72739.76000000", "0.00000000"], ["72739.94000000", "0.00400000"], ["72740.35000000", "0.15017000"], ["72740.46000000", "0.00760000"], ["72740.48000000", "0.00155000"], ["72741.90000000", "0.00000000"], ["72741.99000000", "0.38468000"], ["72742.54000000", "0.00000000"], ["72743.20000000", "0.00000000"], ["72743.26000000", "0.15000000"], ["72744.10000000", "0.00749000"], ["72744.41000000", "0.16270000"], ["72745.59000000", "0.06187000"], ["72745.65000000", "0.00000000"], ["72745.86000000", "0.16270000"], ["72745.99000000", "0.00000000"], ["72747.13000000", "0.16270000"], ["72747.74000000", "0.00749000"], ["72748.40000000", "0.16270000"], ["72748.73000000", "0.16271000"], ["72749.04000000", "1.58075000"], ["72749.05000000", "2.75046000"], ["72749.07000000", "0.00008000"], ["72749.08000000", "0.65949000"], ["72749.15000000", "0.00000000"], ["72749.57000000", "0.00000000"], ["72749.73000000", "0.00275000"], ["72749.86000000", "0.00000000"], ["72749.88000000", "0.00000000"], ["72749.94000000", "0.96719000"], ["72750.29000000", "0.00000000"], ["72750.32000000", "0.00000000"], ["72750.35000000", "0.00000000"], ["72750.50000000", "0.00000000"], ["72750.53000000", "0.00000000"], ["72750.79000000", "0.00000000"], ["72750.84000000", "0.00400000"], ["72751.07000000", "0.00000000"], ["72751.14000000", "0.00000000"], ["72751.17000000", "0.00000000"], ["72751.22000000", "0.00192000"], ["72751.38000000", "0.00767000"], ["72751.99000000", "0.68829000"], ["72752.62000000", "0.00000000"], ["72753.77000000", "0.16270000"], ["72754.64000000", "0.00686000"], ["72759.42000000", "0.00007000"], ["72759.83000000", "0.14695000"], ["72759.97000000", "0.15403000"], ["72760.32000000", "0.00000000"], ["72763.60000000", "0.00400000"], ["72763.70000000", "0.00000000"], ["72763.91000000", "0.00000000"], ["72763.92000000", "0.00000000"], ["72764.41000000", "0.00000000"], ["72764.43000000", "0.00000000"], ["72764.83000000", "0.00000000"], ["72764.87000000", "0.00000000"], ["72764.90000000", "0.00000000"], ["72764.91000000", "0.02650000"], ["72765.05000000", "0.00000000"], ["72765.07000000", "0.00000000"], ["72765.34000000", "0.00000000"], ["72765.39000000", "0.00400000"], ["72765.42000000", "0.00400000"], ["72765.50000000", "0.00000000"], ["72765.61000000", "0.00000000"], ["72765.69000000", "0.00000000"], ["72765.72000000", "0.00000000"], ["72766.67000000", "0.00000000"], ["72767.19000000", "0.16270000"], ["72769.06000000", "0.00400000"], ["72769.18000000", "0.00685000"], ["72771.21000000", "1.12942000"], ["72771.22000000", "0.66361000"], ["72771.23000000", "0.00000000"], ["72776.99000000", "0.00000000"], ["72778.73000000", "0.00000000"], ["72779.76000000", "0.00000000"], ["72781.93000000", "0.00189000"], ["72783.13000000", "0.49524000"], ["72783.33000000", "0.00000000"], ["72787.65000000", "0.00343000"], ["72792.10000000", "0.18446000"], ["72793.26000000", "1.36172000"], ["72796.54000000", "0.00000000"], ["72797.86000000", "0.00000000"], ["72797.89000000", "0.00000000"], ["72798.55000000", "0.00000000"], ["72799.64000000", "0.00000000"], ["72799.91000000", "0.00000000"], ["72800.41000000", "0.65949000"], ["72820.67000000", "2.75046000"], ["72829.57000000", "0.97503000"], ["72830.86000000", "2.75046000"], ["72849.99000000", "0.00000000"], ["72854.63000000", "0.00075000"], ["72914.82000000", "0.00007000"], ["72918.45000000", "0.00007000"], ["73000.00000000", "1.54603000"]], "_local_ts_utc": "2026-06-01T07:49:11.610403+00:00"}
{"e": "depthUpdate", "E": 1780300152814, "s": "BTCUSDT", "U": 94551803772, "u": 94551805109, "b": [["72734.25000000", "3.59681000"], ["72734.24000000", "0.00424000"], ["72734.23000000", "0.00014000"], ["72734.02000000", "0.22722000"], ["72734.01000000", "0.16268000"], ["72734.00000000", "0.00008000"], ["72733.99000000", "0.28441000"], ["72733.98000000", "0.00000000"], ["72733.59000000", "0.00007000"], ["72733.36000000", "0.00000000"], ["72733.17000000", "0.00000000"], ["72733.09000000", "0.24868000"], ["72732.71000000", "0.04055000"], ["72732.66000000", "0.00400000"], ["72732.38000000", "0.00009000"], ["72732.31000000", "0.00000000"], ["72732.30000000", "0.15306000"], ["72732.00000000", "0.00000000"], ["72731.99000000", "0.00016000"], ["72731.71000000", "0.14766000"], ["72731.03000000", "0.00000000"], ["72731.02000000", "0.00016000"], ["72731.01000000", "0.00000000"], ["72730.84000000", "0.00400000"], ["72730.73000000", "0.00000000"], ["72730.45000000", "0.14790000"], ["72730.44000000", "0.16268000"], ["72729.93000000", "0.00000000"], ["72729.90000000", "0.00007000"], ["72729.71000000", "0.00000000"], ["72729.60000000", "0.00000000"], ["72729.59000000", "0.00000000"], ["72729.58000000", "0.00000000"], ["72729.46000000", "0.00000000"], ["72729.17000000", "0.16268000"], ["72729.14000000", "0.00000000"], ["72729.02000000", "0.00400000"], ["72728.95000000", "0.00000000"], ["72728.90000000", "0.00000000"], ["72728.89000000", "0.16205000"], ["72728.88000000", "0.00000000"], ["72728.84000000", "0.00000000"], ["72728.23000000", "0.00739000"], ["72727.83000000", "0.00000000"], ["72727.82000000", "0.00000000"], ["72727.77000000", "0.00000000"], ["72727.75000000", "0.00000000"], ["72727.74000000", "0.00000000"], ["72727.24000000", "0.00000000"], ["72727.20000000", "0.00400000"], ["72726.95000000", "0.00000000"], ["72726.69000000", "0.00000000"], ["72726.68000000", "0.00000000"], ["72726.63000000", "0.16268000"], ["72726.35000000", "0.16270000"], ["72726.21000000", "0.93852000"], ["72726.20000000", "0.31657000"], ["72725.94000000", "0.00000000"], ["72725.86000000", "0.00000000"], ["72725.83000000", "0.00000000"], ["72725.78000000", "0.00016000"], ["72725.54000000", "0.05007000"], ["72725.53000000", "0.70498000"], ["72725.52000000", "0.00016000"], ["72725.51000000", "0.00000000"], ["72725.31000000", "0.00165000"], ["72725.25000000", "0.00000000"], ["72724.61000000", "0.00000000"], ["72724.60000000", "0.00000000"], ["72724.59000000", "0.27771000"], ["72724.52000000", "0.00000000"], ["72724.27000000", "0.00000000"], ["72724.24000000", "0.00022000"], ["72724.09000000", "0.16268000"], ["72724.04000000", "0.15922000"], ["72724.03000000", "0.00000000"], ["72724.02000000", "0.65969000"], ["72724.01000000", "0.74982000"], ["72723.67000000", "0.00000000"], ["72722.73000000", "0.16377000"], ["72722.54000000", "0.00000000"], ["72722.53000000", "0.00008000"], ["72722.52000000", "0.00007000"], ["72722.50000000", "0.00028000"], ["72722.32000000", "0.19942000"], ["72721.94000000", "0.16268000"], ["72721.93000000", "0.00000000"], ["72721.91000000", "0.75622000"], ["72721.36000000", "0.00000000"], ["72721.17000000", "0.04000000"], ["72721.16000000", "0.04000000"], ["72721.15000000", "0.00000000"], ["72720.67000000", "0.16268000"], ["72720.65000000", "0.00000000"], ["72720.51000000", "0.00000000"], ["72720.48000000", "0.56182000"], ["72720.47000000", "1.69116000"], ["72719.54000000", "0.00011000"], ["72719.29000000", "0.01376000"], ["72719.18000000", "0.00000000"], ["72719.01000000", "0.16268000"], ["72718.99000000", "0.16268000"], ["72718.98000000", "1.07027000"], ["72718.97000000", "2.75046000"], ["72718.96000000", "0.00000000"], ["72718.95000000", "0.00000000"], ["72718.74000000", "0.00000000"], ["72718.68000000", "0.00573000"], ["72718.23000000", "0.01000000"], ["72718.14000000", "0.00007000"], ["72717.91000000", "0.00007000"], ["72717.73000000", "0.02000000"], ["72717.52000000", "0.00008000"], ["72717.46000000", "0.00000000"], ["72717.31000000", "0.00000000"], ["72717.27000000", "0.00349000"], ["72716.64000000", "0.00000000"], ["72715.93000000", "0.00191000"], ["72715.64000000", "0.00000000"], ["72715.58000000", "0.00000000"], ["72715.53000000", "0.00000000"], ["72715.04000000", "0.57611000"], ["72714.89000000", "0.00000000"], ["72714.53000000", "0.02000000"], ["72714.18000000", "0.00000000"], ["72714.10000000", "0.00000000"], ["72714.08000000", "0.12070000"], ["72713.20000000", "0.00000000"], ["72712.83000000", "0.00000000"], ["72712.52000000", "0.00008000"], ["72712.43000000", "0.00137000"], ["72712.28000000", "0.00000000"], ["72711.53000000", "0.00008000"], ["72711.36000000", "0.00000000"], ["72711.25000000", "0.00000000"], ["72710.88000000", "0.00401000"], ["72710.47000000", "0.00000000"], ["72710.19000000", "0.00000000"], ["72709.83000000", "0.00000000"], ["72709.33000000", "0.00000000"], ["72709.02000000", "0.00000000"], ["72708.62000000", "0.00000000"], ["72708.31000000", "0.66621000"], ["72707.90000000", "0.00008000"], ["72707.83000000", "0.96881000"], ["72707.75000000", "0.00000000"], ["72707.68000000", "0.00686000"], ["72707.43000000", "0.00000000"], ["72706.96000000", "0.00000000"], ["72706.36000000", "0.49576000"], ["72705.21000000", "0.00000000"], ["72704.90000000", "0.00000000"], ["72704.09000000", "0.00000000"], ["72703.75000000", "0.00798000"], ["72703.54000000", "0.00000000"], ["72702.96000000", "1.36341000"], ["72702.36000000", "0.00000000"], ["72702.01000000", "0.00000000"], ["72701.88000000", "0.00000000"], ["72701.72000000", "0.00000000"], ["72701.57000000", "0.00000000"], ["72699.90000000", "0.00000000"], ["72698.08000000", "0.00007000"], ["72697.46000000", "0.00000000"], ["72697.10000000", "0.00000000"], ["72696.94000000", "0.00000000"], ["72696.69000000", "0.00000000"], ["72696.43000000", "0.00000000"], ["72695.99000000", "0.00000000"], ["72695.38000000", "0.00412000"], ["72693.67000000", "0.00000000"], ["72693.66000000", "0.00000000"], ["72693.00000000", "0.00000000"], ["72692.19000000", "0.00000000"], ["72691.32000000", "0.00686000"], ["72689.31000000", "0.00000000"], ["72686.98000000", "0.00137000"], ["72686.90000000", "0.00000000"], ["72686.70000000", "0.00171000"], ["72684.56000000", "0.00342000"], ["72683.41000000", "0.01159000"], ["72683.24000000", "0.03456000"], ["72681.45000000", "0.00000000"], ["72680.51000000", "0.00011000"], ["72680.11000000", "0.00000000"], ["72676.38000000", "0.01131000"], ["72672.35000000", "0.00000000"], ["72669.94000000", "0.00137000"], ["72667.93000000", "0.00000000"], ["72667.64000000", "0.00000000"], ["72665.77000000", "0.00000000"], ["72664.55000000", "0.33678000"], ["72664.19000000", "0.00000000"], ["72663.62000000", "0.00000000"], ["72662.33000000", "0.09634000"], ["72661.35000000", "0.00000000"], ["72661.26000000", "0.00008000"], ["72657.85000000", "0.00000000"], ["72657.50000000", "0.00000000"], ["72656.03000000", "0.00000000"], ["72654.87000000", "0.00000000"], ["72652.49000000", "0.00282000"], ["72651.29000000", "0.00000000"], ["72647.01000000", "0.72630000"], ["72645.94000000", "0.00000000"], ["72641.09000000", "0.00000000"], ["72635.29000000", "0.04632000"], ["72634.35000000", "0.00000000"], ["72634.32000000", "0.00033000"], ["72633.15000000", "0.00000000"], ["72629.66000000", "0.02563000"], ["72612.01000000", "0.00137000"], ["72608.75000000", "0.00000000"], ["72608.22000000", "0.00000000"], ["72607.12000000", "0.00000000"], ["72602.92000000", "0.00000000"], ["72588.52000000", "0.00008000"], ["72578.56000000", "0.00000000"], ["72574.24000000", "1.20000000"], ["72558.03000000", "0.00000000"], ["72552.58000000", "0.00000000"], ["72522.54000000", "0.00000000"], ["72519.41000000", "0.00000000"], ["72515.79000000", "0.00008000"], ["72505.84000000", "0.00000000"], ["72446.20000000", "0.00000000"], ["72443.05000000", "0.00008000"], ["72433.90000000", "0.00000000"], ["72433.11000000", "0.00000000"], ["72370.32000000", "0.00008000"], ["72360.39000000", "0.00000000"], ["72297.59000000", "0.00008000"], ["72287.67000000", "0.00000000"], ["72224.85000000", "0.00008000"], ["72214.94000000", "0.00000000"], ["72152.12000000", "0.00008000"], ["72142.22000000", "0.00000000"], ["71993.26000000", "0.00007000"], ["65592.51000000", "0.00234000"], ["65460.83000000", "0.00034000"], ["65460.82000000", "0.00018000"], ["65452.98000000", "0.00000000"]], "a": [["72725.54000000", "0.00000000"], ["72725.55000000", "0.00000000"], ["72726.21000000", "0.00000000"], ["72726.70000000", "0.00000000"], ["72727.75000000", "0.00000000"], ["72727.76000000", "0.00000000"], ["72727.78000000", "0.00000000"], ["72727.83000000", "0.00000000"], ["72727.84000000", "0.00000000"], ["72728.90000000", "0.00000000"], ["72728.96000000", "0.00000000"], ["72729.15000000", "0.00000000"], ["72729.47000000", "0.00000000"], ["72729.59000000", "0.00000000"], ["72729.60000000", "0.00000000"], ["72729.61000000", "0.00000000"], ["72729.72000000", "0.00000000"], ["72729.90000000", "0.00000000"], ["72729.94000000", "0.00000000"], ["72729.97000000", "0.00000000"], ["72730.74000000", "0.00000000"], ["72731.02000000", "0.00000000"], ["72731.03000000", "0.00000000"], ["72731.05000000", "0.00000000"], ["72731.24000000", "0.00000000"], ["72731.52000000", "0.00000000"], ["72731.74000000", "0.00000000"], ["72731.99000000", "0.00000000"], ["72732.00000000", "0.00000000"], ["72732.30000000", "0.00000000"], ["72732.31000000", "0.00000000"], ["72732.38000000", "0.00000000"], ["72732.45000000", "0.00000000"], ["72732.68000000", "0.00000000"], ["72732.80000000", "0.00000000"], ["72732.85000000", "0.00000000"], ["72733.10000000", "0.00000000"], ["72733.18000000", "0.00000000"], ["72733.59000000", "0.00000000"], ["72733.91000000", "0.00000000"], ["72733.99000000", "0.00000000"], ["72734.00000000", "0.00000000"], ["72734.25000000", "0.00000000"], ["72734.26000000", "0.12770000"], ["72734.27000000", "0.00072000"], ["72734.42000000", "0.00000000"], ["72734.43000000", "0.00016000"], ["72734.70000000", "0.00000000"], ["72734.71000000", "0.00016000"], ["72734.75000000", "0.00008000"], ["72734.76000000", "0.00000000"], ["72735.38000000", "0.00000000"], ["72735.49000000", "0.00000000"], ["72735.58000000", "0.00000000"], ["72735.69000000", "0.00000000"], ["72735.70000000", "0.00000000"], ["72735.99000000", "0.00016000"], ["72736.09000000", "0.00000000"], ["72736.30000000", "0.00000000"], ["72736.32000000", "0.00000000"], ["72736.58000000", "0.00000000"], ["72736.59000000", "0.00008000"], ["72736.60000000", "0.00000000"], ["72736.61000000", "0.00000000"], ["72736.82000000", "0.00000000"], ["72737.05000000", "0.00000000"], ["72737.22000000", "0.00000000"], ["72737.81000000", "0.00000000"], ["72737.98000000", "0.00000000"], ["72737.99000000", "0.00016000"], ["72738.01000000", "0.00016000"], ["72738.10000000", "0.00024000"], ["72738.12000000", "0.00024000"], ["72738.13000000", "0.06863000"], ["72738.33000000", "0.00000000"], ["72738.71000000", "0.00000000"], ["72738.77000000", "0.00000000"], ["72738.78000000", "0.00000000"], ["72738.91000000", "0.00008000"], ["72738.92000000", "0.02000000"], ["72739.43000000", "0.00000000"], ["72739.50000000", "0.00008000"], ["72739.51000000", "0.00008000"], ["72739.61000000", "0.00332000"], ["72739.77000000", "0.00000000"], ["72739.93000000", "0.00008000"], ["72739.94000000", "0.00000000"], ["72740.35000000", "0.00008000"], ["72740.36000000", "0.00000000"], ["72740.40000000", "0.01360000"], ["72740.46000000", "0.00000000"], ["72740.47000000", "0.00000000"], ["72740.48000000", "0.00000000"], ["72740.91000000", "0.00031000"], ["72741.11000000", "0.00008000"], ["72741.12000000", "0.00000000"], ["72741.52000000", "0.00000000"], ["72741.54000000", "0.00000000"], ["72741.71000000", "0.00000000"], ["72741.76000000", "0.00000000"], ["72741.88000000", "0.00000000"], ["72741.94000000", "0.16377000"], ["72741.99000000", "0.11423000"], ["72742.15000000", "0.00000000"], ["72742.17000000", "0.00745000"], ["72742.42000000", "0.00038000"], ["72742.46000000", "0.00000000"], ["72742.56000000", "0.00019000"], ["72743.09000000", "0.00000000"], ["72743.15000000", "0.16268000"], ["72743.26000000", "0.00000000"], ["72743.57000000", "0.00000000"], ["72744.41000000", "0.00000000"], ["72744.42000000", "0.16268000"], ["72744.91000000", "0.00164000"], ["72745.12000000", "0.00000000"], ["72745.16000000", "0.00000000"], ["72745.58000000", "0.16268000"], ["72745.59000000", "0.48499000"], ["72745.86000000", "0.00000000"], ["72745.91000000", "0.00000000"], ["72746.50000000", "0.16268000"], ["72746.51000000", "0.01484000"], ["72746.52000000", "0.40856000"], ["72747.13000000", "0.00000000"], ["72747.21000000", "0.01369000"], ["72747.25000000", "0.00007000"], ["72747.31000000", "0.00000000"], ["72747.56000000", "0.00000000"], ["72748.10000000", "0.12085000"], ["72748.23000000", "0.16268000"], ["72748.31000000", "0.00191000"], ["72748.40000000", "0.00000000"], ["72748.73000000", "0.00000000"], ["72748.80000000", "0.00008000"], ["72748.82000000", "0.00000000"], ["72748.92000000", "0.65949000"], ["72749.03000000", "0.16268000"], ["72749.04000000", "0.62426000"], ["72749.05000000", "0.00000000"], ["72749.06000000", "0.00000000"], ["72749.08000000", "0.00000000"], ["72749.93000000", "0.16268000"], ["72750.16000000", "0.00000000"], ["72750.26000000", "0.00000000"], ["72750.36000000", "0.00000000"], ["72750.64000000", "0.00000000"], ["72750.70000000", "0.00000000"], ["72750.74000000", "0.00155000"], ["72750.84000000", "0.00000000"], ["72751.52000000", "0.00012000"], ["72751.86000000", "0.16268000"], ["72751.87000000", "0.65949000"], ["72751.99000000", "0.00000000"], ["72753.31000000", "0.16268000"], ["72753.77000000", "0.00000000"], ["72753.78000000", "0.00000000"], ["72753.82000000", "1.16311000"], ["72754.49000000", "0.01372000"], ["72754.55000000", "0.00209000"], ["72754.58000000", "0.16268000"], ["72754.64000000", "0.00000000"], ["72754.96000000", "0.16268000"], ["72754.97000000", "3.41003000"], ["72754.98000000", "0.00000000"], ["72755.16000000", "0.00000000"], ["72755.92000000", "0.00000000"], ["72756.08000000", "0.00137000"], ["72756.87000000", "0.15000000"], ["72756.96000000", "0.00000000"], ["72757.12000000", "0.16268000"], ["72757.28000000", "0.00008000"], ["72757.70000000", "0.16268000"], ["72757.71000000", "0.45885000"], ["72757.72000000", "0.00000000"], ["72757.73000000", "0.00000000"], ["72759.36000000", "0.00000000"], ["72759.51000000", "0.00000000"], ["72759.52000000", "0.00400000"], ["72759.66000000", "0.16268000"], ["72759.68000000", "0.00000000"], ["72759.75000000", "0.00000000"], ["72759.83000000", "0.00000000"], ["72759.97000000", "0.16268000"], ["72760.04000000", "0.00000000"], ["72760.08000000", "0.00000000"], ["72760.14000000", "0.00120000"], ["72760.20000000", "0.00000000"], ["72760.25000000", "0.00000000"], ["72760.28000000", "0.00000000"], ["72760.34000000", "0.00000000"], ["72760.40000000", "0.00000000"], ["72760.53000000", "0.00000000"], ["72760.58000000", "0.00000000"], ["72760.62000000", "0.00000000"], ["72760.63000000", "0.00000000"], ["72760.70000000", "0.00000000"], ["72760.72000000", "0.00000000"], ["72760.87000000", "0.00000000"], ["72761.01000000", "0.16268000"], ["72761.02000000", "0.96881000"], ["72761.39000000", "0.68820000"], ["72761.77000000", "0.01364000"], ["72763.11000000", "0.00007000"], ["72765.19000000", "0.00000000"], ["72765.24000000", "0.00000000"], ["72765.39000000", "0.00000000"], ["72765.75000000", "0.00000000"], ["72765.88000000", "0.00000000"], ["72766.80000000", "0.00007000"], ["72767.19000000", "0.16268000"], ["72767.24000000", "0.00400000"], ["72767.72000000", "0.00000000"], ["72768.07000000", "0.16268000"], ["72768.67000000", "0.00000000"], ["72768.68000000", "0.00000000"], ["72768.88000000", "0.00200000"], ["72769.05000000", "0.01393000"], ["72769.18000000", "0.00000000"], ["72770.49000000", "0.00007000"], ["72770.88000000", "0.00400000"], ["72770.94000000", "0.00000000"], ["72771.21000000", "0.00000000"], ["72771.22000000", "0.65949000"], ["72771.46000000", "0.00000000"], ["72771.67000000", "0.00000000"], ["72772.70000000", "0.00400000"], ["72773.22000000", "0.00000000"], ["72773.58000000", "0.00429000"], ["72773.99000000", "0.00633000"], ["72774.04000000", "0.00000000"], ["72774.06000000", "0.00400000"], ["72774.38000000", "0.00000000"], ["72774.40000000", "0.00000000"], ["72774.52000000", "0.00400000"], ["72774.59000000", "0.00000000"], ["72774.63000000", "0.00000000"], ["72774.80000000", "0.00000000"], ["72774.83000000", "0.00000000"], ["72774.84000000", "0.00000000"], ["72774.90000000", "0.00000000"], ["72774.95000000", "0.00000000"], ["72775.12000000", "0.00000000"], ["72775.13000000", "0.00000000"], ["72775.17000000", "0.00573000"], ["72775.20000000", "0.00000000"], ["72775.25000000", "0.00000000"], ["72775.27000000", "0.00000000"], ["72775.30000000", "0.00000000"], ["72775.42000000", "0.00000000"], ["72775.71000000", "0.00000000"], ["72776.28000000", "1.36204000"], ["72778.21000000", "0.00425000"], ["72778.74000000", "0.00000000"], ["72781.30000000", "0.01143000"], ["72781.93000000", "0.00000000"], ["72782.19000000", "0.00000000"], ["72785.97000000", "0.00000000"], ["72786.26000000", "0.49522000"], ["72787.04000000", "0.00000000"], ["72787.08000000", "0.00000000"], ["72787.65000000", "0.00000000"], ["72787.94000000", "0.09343000"], ["72792.04000000", "0.00000000"], ["72792.10000000", "0.00000000"], ["72792.12000000", "0.00000000"], ["72793.09000000", "0.01691000"], ["72793.38000000", "0.00000000"], ["72794.16000000", "0.00109000"], ["72797.97000000", "0.55338000"], ["72797.98000000", "0.00342000"], ["72800.15000000", "0.00573000"], ["72800.42000000", "1.43822000"], ["72801.22000000", "1.36157000"], ["72801.63000000", "0.00008000"], ["72803.24000000", "0.39642000"], ["72809.14000000", "0.65949000"], ["72810.34000000", "0.00105000"], ["72812.51000000", "2.75046000"], ["72817.87000000", "0.69356000"], ["72818.15000000", "0.00000000"], ["72826.38000000", "0.00000000"], ["72841.05000000", "2.75046000"], ["72848.44000000", "0.00000000"], ["72853.28000000", "0.22285000"], ["72853.84000000", "0.00412000"], ["72854.63000000", "0.00000000"], ["72862.83000000", "0.00000000"], ["72866.10000000", "0.00000000"], ["72874.36000000", "0.00018000"], ["72876.11000000", "0.00000000"], ["72878.10000000", "0.00000000"], ["72879.41000000", "0.00000000"], ["72880.19000000", "0.02154000"], ["72880.37000000", "2.06252000"], ["72894.32000000", "0.00000000"], ["72895.15000000", "0.27000000"], ["72917.58000000", "0.00007000"], ["72918.45000000", "0.00000000"], ["72921.21000000", "0.00007000"], ["72923.03000000", "0.00007000"], ["72926.66000000", "0.00007000"], ["73011.54000000", "0.00000000"], ["73019.82000000", "0.00008000"], ["73084.26000000", "0.00000000"], ["73089.69000000", "0.00007000"], ["73092.54000000", "0.00008000"], ["73229.70000000", "0.00000000"], ["73238.00000000", "0.00008000"], ["73447.69000000", "0.00007000"], ["89497.83000000", "0.00037000"]], "_local_ts_utc": "2026-06-01T07:49:11.710709+00:00"}
{"e": "depthUpdate", "E": 1780300152914, "s": "BTCUSDT", "U": 94551805110, "u": 94551805291, "b": [["72734.25000000", "3.59281000"], ["72734.02000000", "0.22738000"], ["72734.01000000", "0.16284000"], ["72733.99000000", "0.28441000"], ["72733.37000000", "0.06823000"], ["72733.09000000", "0.11136000"], ["72732.71000000", "0.04071000"], ["72732.30000000", "0.15306000"], ["72731.99000000", "0.00000000"], ["72731.71000000", "0.14782000"], ["72731.29000000", "0.00775000"], ["72731.02000000", "0.00000000"], ["72729.63000000", "0.01397000"], ["72728.89000000", "0.16189000"], ["72725.78000000", "0.00000000"], ["72725.53000000", "0.69627000"], ["72725.52000000", "0.00000000"], ["72724.24000000", "0.00000000"], ["72721.16000000", "0.00000000"], ["72718.99000000", "0.00000000"], ["72715.93000000", "0.00000000"], ["72712.35000000", "0.00000000"], ["72708.95000000", "0.00118000"], ["72708.87000000", "0.00000000"], ["72707.22000000", "0.00013000"], ["72700.50000000", "0.00007000"], ["72698.57000000", "0.00137000"], ["72693.98000000", "0.00000000"], ["72693.23000000", "0.00000000"], ["72689.59000000", "0.00000000"], ["72681.54000000", "0.00631000"], ["72680.58000000", "0.00563000"], ["72678.69000000", "0.00000000"], ["72677.64000000", "0.00426000"], ["72675.46000000", "0.00000000"], ["72667.78000000", "0.00000000"], ["72658.70000000", "0.00111000"], ["72634.90000000", "0.04564000"], ["72625.39000000", "0.04479000"], ["72610.80000000", "0.00000000"], ["72586.40000000", "0.00000000"], ["72586.16000000", "2.84261000"], ["72560.54000000", "0.00000000"], ["72555.78000000", "0.00080000"], ["72551.44000000", "0.09872000"], ["72531.38000000", "0.00000000"], ["72529.23000000", "0.00011000"], ["72526.01000000", "0.00000000"], ["72519.26000000", "0.00000000"], ["72477.64000000", "0.00000000"], ["72444.66000000", "0.00031000"], ["72329.14000000", "2.50000000"], ["72246.09000000", "0.00250000"], ["72221.87000000", "0.00250000"], ["65460.83000000", "0.00068000"], ["58172.00000000", "0.00000000"]], "a": [["72734.26000000", "0.15575000"], ["72734.27000000", "0.00072000"], ["72734.43000000", "0.00000000"], ["72734.71000000", "0.00000000"], ["72735.17000000", "0.00000000"], ["72736.00000000", "0.02296000"], ["72738.00000000", "0.02296000"], ["72738.02000000", "0.05862000"], ["72738.13000000", "0.19005000"], ["72738.92000000", "0.02016000"], ["72739.08000000", "0.01077000"], ["72739.46000000", "0.00031000"], ["72739.61000000", "0.00000000"], ["72739.62000000", "0.00589000"], ["72740.00000000", "0.05193000"], ["72740.40000000", "0.00016000"], ["72740.48000000", "0.00000000"], ["72740.66000000", "0.16377000"], ["72741.54000000", "0.00000000"], ["72742.17000000", "0.00000000"], ["72744.79000000", "0.00069000"], ["72745.50000000", "0.00000000"], ["72745.59000000", "0.68178000"], ["72745.98000000", "0.65949000"], ["72746.33000000", "0.00048000"], ["72747.18000000", "0.00550000"], ["72747.30000000", "0.00550000"], ["72749.02000000", "0.05942000"], ["72757.12000000", "0.00000000"], ["72758.44000000", "0.00000000"], ["72758.99000000", "0.00400000"], ["72759.10000000", "0.00000000"], ["72759.14000000", "0.00000000"], ["72759.27000000", "0.00000000"], ["72759.52000000", "0.00000000"], ["72761.01000000", "0.00000000"], ["72767.19000000", "0.00000000"], ["72768.07000000", "0.00000000"], ["72772.99000000", "0.00000000"], ["72773.54000000", "0.00400000"], ["72773.65000000", "0.00000000"], ["72773.69000000", "0.00000000"], ["72773.72000000", "0.00000000"], ["72773.81000000", "0.00000000"], ["72774.06000000", "0.00000000"], ["72779.24000000", "0.00426000"], ["72805.71000000", "0.01147000"], ["72828.52000000", "0.04564000"], ["72843.61000000", "0.04431000"], ["72845.14000000", "0.04540000"], ["72880.37000000", "0.00000000"], ["72880.42000000", "0.00000000"], ["72901.88000000", "2.06252000"], ["72945.18000000", "0.00000000"], ["75376.16000000", "0.00000000"]], "_local_ts_utc": "2026-06-01T07:49:11.810322+00:00"}
{"e": "depthUpdate", "E": 1780300153014, "s": "BTCUSDT", "U": 94551805292, "u": 94551805439, "b": [["72734.25000000", "3.59976000"], ["72734.03000000", "0.00016000"], ["72734.02000000", "0.16382000"], ["72734.00000000", "0.00024000"], ["72733.99000000", "0.28441000"], ["72733.38000000", "0.00040000"], ["72733.37000000", "0.06839000"], ["72733.10000000", "0.00008000"], ["72732.30000000", "0.00016000"], ["72731.71000000", "0.14766000"], ["72726.97000000", "0.00300000"], ["72724.16000000", "0.00008000"], ["72723.90000000", "0.00000000"], ["72723.81000000", "0.00187000"], ["72721.17000000", "0.00000000"], ["72721.16000000", "0.04000000"], ["72719.69000000", "0.00300000"], ["72719.29000000", "0.00000000"], ["72719.01000000", "0.00000000"], ["72716.14000000", "0.01376000"], ["72715.13000000", "0.02000000"], ["72703.25000000", "0.00000000"], ["72702.35000000", "0.00000000"], ["72700.49000000", "0.48396000"], ["72699.35000000", "0.02702000"], ["72694.07000000", "0.00000000"], ["72682.29000000", "0.00000000"], ["72551.44000000", "0.09871000"], ["71998.27000000", "0.00025000"], ["71993.26000000", "0.00000000"], ["65460.83000000", "0.00102000"], ["58187.40000000", "0.00034000"]], "a": [["72734.26000000", "0.17143000"], ["72734.27000000", "0.00080000"], ["72735.98000000", "0.00000000"], ["72735.99000000", "0.00016000"], ["72737.57000000", "0.00031000"], ["72738.13000000", "0.18954000"], ["72738.91000000", "0.00008000"], ["72738.92000000", "0.02016000"], ["72739.08000000", "0.01093000"], ["72739.24000000", "0.00031000"], ["72739.38000000", "0.15704000"], ["72740.00000000", "0.05193000"], ["72740.40000000", "0.00000000"], ["72741.54000000", "0.27300000"], ["72741.81000000", "0.00000000"], ["72741.93000000", "0.17244000"], ["72741.99000000", "0.00000000"], ["72742.42000000", "0.00007000"], ["72742.81000000", "0.01385000"], ["72743.00000000", "0.65949000"], ["72745.27000000", "0.00550000"], ["72746.12000000", "0.05942000"], ["72746.27000000", "0.00550000"], ["72747.18000000", "0.00000000"], ["72747.30000000", "0.00000000"], ["72748.10000000", "0.12085000"], ["72748.82000000", "0.00300000"], ["72748.90000000", "0.00000000"], ["72749.02000000", "0.00000000"], ["72753.17000000", "0.08200000"], ["72757.22000000", "0.00400000"], ["72757.24000000", "0.00000000"], ["72757.25000000", "0.00000000"], ["72757.27000000", "0.00000000"], ["72757.70000000", "0.16268000"], ["72757.89000000", "0.00000000"], ["72757.93000000", "0.00000000"], ["72758.99000000", "0.00000000"], ["72764.91000000", "0.00000000"], ["72771.77000000", "0.00400000"], ["72771.79000000", "0.00000000"], ["72771.80000000", "0.00000000"], ["72771.82000000", "0.00000000"], ["72772.25000000", "0.00000000"], ["72772.44000000", "0.00007000"], ["72772.48000000", "0.00000000"], ["72773.54000000", "0.00000000"], ["72776.22000000", "0.00114000"], ["72777.46000000", "0.00000000"], ["72783.58000000", "0.06932000"], ["72791.22000000", "0.00189000"], ["72803.76000000", "0.08200000"], ["72815.93000000", "0.02836000"], ["72863.85000000", "0.00076000"], ["72977.84000000", "0.00080000"], ["73447.69000000", "0.00000000"], ["73452.80000000", "0.00007000"], ["73559.67000000", "0.00000000"]], "_local_ts_utc": "2026-06-01T07:49:11.912421+00:00"}
{"e": "depthUpdate", "E": 1780300153114, "s": "BTCUSDT", "U": 94551805440, "u": 94551805641, "b": [["72734.25000000", "3.59765000"], ["72734.03000000", "0.00000000"], ["72734.02000000", "0.22766000"], ["72734.00000000", "0.00008000"], ["72733.52000000", "0.00000000"], ["72733.38000000", "0.00024000"], ["72733.37000000", "0.00016000"], ["72733.17000000", "0.13748000"], ["72733.10000000", "0.00000000"], ["72732.71000000", "0.04071000"], ["72732.30000000", "0.00000000"], ["72731.71000000", "0.14782000"], ["72723.81000000", "0.00000000"], ["72719.71000000", "0.00007000"], ["72718.99000000", "0.16377000"], ["72718.92000000", "0.20284000"], ["72718.19000000", "0.02000000"], ["72715.04000000", "0.47611000"], ["72712.64000000", "0.00411000"], ["72705.16000000", "0.00113000"], ["72704.89000000", "1.41315000"], ["72702.79000000", "0.00013000"], ["72701.80000000", "0.00199000"], ["72690.34000000", "0.00685000"], ["72680.51000000", "0.00000000"], ["72678.27000000", "0.00436000"], ["72673.64000000", "1.04027000"], ["72665.66000000", "0.00000000"], ["72041.72000000", "0.00000000"], ["72006.90000000", "0.00007000"], ["71998.27000000", "0.00018000"], ["65460.83000000", "0.00136000"]], "a": [["72734.26000000", "0.00267000"], ["72734.27000000", "0.00072000"], ["72734.75000000", "0.00000000"], ["72735.98000000", "0.00024000"], ["72735.99000000", "0.03189000"], ["72736.59000000", "0.00000000"], ["72737.03000000", "0.00000000"], ["72737.04000000", "0.00000000"], ["72737.14000000", "0.00000000"], ["72737.57000000", "0.00000000"], ["72738.01000000", "0.00024000"], ["72738.13000000", "0.12479000"], ["72738.91000000", "0.00000000"], ["72739.08000000", "0.00016000"], ["72739.22000000", "0.00000000"], ["72739.24000000", "0.00000000"], ["72739.37000000", "0.00008000"], ["72739.38000000", "0.00016000"], ["72739.46000000", "0.00338000"], ["72739.50000000", "0.00000000"], ["72739.51000000", "0.00000000"], ["72739.93000000", "0.00000000"], ["72739.99000000", "0.00008000"], ["72740.00000000", "0.05193000"], ["72740.35000000", "0.00000000"], ["72740.65000000", "0.00008000"], ["72740.85000000", "0.00031000"], ["72740.91000000", "0.00000000"], ["72740.92000000", "0.00031000"], ["72741.11000000", "0.00000000"], ["72741.54000000", "0.00300000"], ["72741.92000000", "0.00008000"], ["72741.93000000", "0.34726000"], ["72742.23000000", "0.05942000"], ["72742.26000000", "0.00550000"], ["72742.29000000", "0.00550000"], ["72742.55000000", "0.00000000"], ["72742.80000000", "0.00008000"], ["72742.95000000", "0.03407000"], ["72742.99000000", "0.00008000"], ["72743.15000000", "0.00000000"], ["72743.19000000", "0.00000000"], ["72744.41000000", "0.00008000"], ["72745.27000000", "0.00000000"], ["72745.58000000", "0.16276000"], ["72745.97000000", "0.00008000"], ["72746.12000000", "0.00000000"], ["72746.27000000", "0.00000000"], ["72746.51000000", "0.01492000"], ["72747.99000000", "0.00008000"], ["72748.22000000", "0.00008000"], ["72748.91000000", "0.00008000"], ["72749.07000000", "0.00000000"], ["72749.93000000", "0.00008000"], ["72749.99000000", "0.00015000"], ["72751.86000000", "0.16276000"], ["72753.30000000", "0.00008000"], ["72753.50000000", "0.00903000"], ["72754.57000000", "0.00008000"], ["72754.58000000", "0.00000000"], ["72754.96000000", "0.00008000"], ["72754.97000000", "3.40995000"], ["72755.42000000", "0.05400000"], ["72756.17000000", "0.05400000"], ["72756.86000000", "0.00008000"], ["72757.22000000", "0.00000000"], ["72757.40000000", "0.00000000"], ["72757.41000000", "0.00397000"], ["72757.45000000", "0.00000000"], ["72757.70000000", "0.00008000"], ["72757.85000000", "0.00000000"], ["72758.13000000", "0.00400000"], ["72758.18000000", "0.00000000"], ["72758.22000000", "0.00000000"], ["72758.26000000", "0.00000000"], ["72758.28000000", "0.00008000"], ["72759.66000000", "0.00000000"], ["72759.97000000", "0.00008000"], ["72761.01000000", "0.00008000"], ["72762.00000000", "0.02479000"], ["72763.10000000", "0.00686000"], ["72767.30000000", "0.00000000"], ["72768.07000000", "0.00008000"], ["72768.69000000", "1.32849000"], ["72768.88000000", "0.00000000"], ["72769.46000000", "0.00200000"], ["72771.77000000", "0.00000000"], ["72771.94000000", "0.00000000"], ["72771.96000000", "0.00000000"], ["72772.00000000", "0.02288000"], ["72772.40000000", "0.00000000"], ["72772.68000000", "0.00400000"], ["72772.70000000", "0.00400000"], ["72772.73000000", "0.00000000"], ["72772.77000000", "0.00000000"], ["72774.99000000", "1.33939000"], ["72780.03000000", "1.03875000"], ["72781.94000000", "1.46988000"], ["72786.47000000", "0.00122000"], ["72791.21000000", "0.00189000"], ["72791.22000000", "0.00000000"], ["72792.19000000", "0.00685000"], ["72806.06000000", "0.05400000"], ["72806.79000000", "0.05400000"], ["72863.84000000", "0.00076000"], ["72863.85000000", "0.00000000"], ["73452.80000000", "0.00000000"], ["73461.61000000", "0.00007000"], ["89513.33000000", "0.00059000"]], "_local_ts_utc": "2026-06-01T07:49:12.010643+00:00"}
{"e": "depthUpdate", "E": 1780300153214, "s": "BTCUSDT", "U": 94551805642, "u": 94551806150, "b": [["72735.99000000", "4.92773000"], ["72735.98000000", "0.73245000"], ["72735.97000000", "0.00014000"], ["72735.96000000", "0.00000000"], ["72735.19000000", "0.00016000"], ["72735.15000000", "0.00000000"], ["72735.14000000", "0.00016000"], ["72735.11000000", "0.00000000"], ["72735.06000000", "0.13748000"], ["72734.96000000", "0.00008000"], ["72734.94000000", "0.00000000"], ["72734.70000000", "0.16377000"], ["72734.48000000", "0.00400000"], ["72734.27000000", "0.82659000"], ["72734.26000000", "0.00016000"], ["72734.25000000", "0.55693000"], ["72734.24000000", "0.00000000"], ["72734.23000000", "0.00000000"], ["72734.02000000", "0.00016000"], ["72734.01000000", "0.00016000"], ["72733.99000000", "0.00016000"], ["72733.37000000", "0.00000000"], ["72733.17000000", "0.00000000"], ["72733.09000000", "0.11120000"], ["72732.71000000", "0.04055000"], ["72732.15000000", "0.16377000"], ["72732.14000000", "0.16377000"], ["72731.71000000", "0.14766000"], ["72728.67000000", "0.01375000"], ["72727.03000000", "0.16377000"], ["72727.02000000", "0.16377000"], ["72726.97000000", "0.66249000"], ["72726.92000000", "0.00011000"], ["72726.63000000", "0.00000000"], ["72726.35000000", "0.00000000"], ["72725.55000000", "0.16377000"], ["72725.54000000", "0.25007000"], ["72725.53000000", "0.89627000"], ["72724.25000000", "0.00000000"], ["72723.99000000", "0.00000000"], ["72723.33000000", "0.01376000"], ["72723.27000000", "0.00007000"], ["72722.73000000", "0.00000000"], ["72722.44000000", "0.02000000"], ["72721.94000000", "0.00000000"], ["72721.84000000", "0.12000000"], ["72721.40000000", "0.04000000"], ["72721.31000000", "0.04000000"], ["72721.16000000", "0.00000000"], ["72720.68000000", "0.40856000"], ["72720.66000000", "0.00000000"], ["72720.49000000", "0.00000000"], ["72720.47000000", "1.14109000"], ["72720.00000000", "0.00008000"], ["72719.60000000", "0.00000000"], ["72719.36000000", "0.00000000"], ["72718.99000000", "0.00000000"], ["72716.14000000", "0.00000000"], ["72715.53000000", "0.00000000"], ["72715.04000000", "0.27805000"], ["72714.53000000", "0.00000000"], ["72714.22000000", "0.00000000"], ["72713.20000000", "0.00000000"], ["72712.52000000", "0.00008000"], ["72712.38000000", "0.00007000"], ["72712.32000000", "0.00200000"], ["72706.63000000", "0.00000000"], ["72705.98000000", "0.00000000"], ["72705.36000000", "0.00000000"], ["72704.89000000", "1.40629000"], ["72701.80000000", "0.00000000"], ["72698.26000000", "0.00000000"], ["72690.34000000", "0.00000000"], ["72686.90000000", "0.81482000"], ["72684.57000000", "0.00342000"], ["72684.56000000", "0.00000000"], ["72676.01000000", "0.37467000"], ["72657.67000000", "0.00000000"], ["72650.03000000", "0.41217000"], ["72640.01000000", "0.06277000"], ["72632.69000000", "0.00007000"], ["72612.02000000", "0.00137000"], ["72612.01000000", "0.00000000"], ["72578.29000000", "0.02154000"], ["71538.81000000", "0.00000000"], ["65462.39000000", "0.00000000"], ["65460.83000000", "0.00000000"], ["58187.40000000", "0.00000000"]], "a": [["72734.26000000", "0.00000000"], ["72734.27000000", "0.00000000"], ["72735.15000000", "0.00000000"], ["72735.20000000", "0.00000000"], ["72735.98000000", "0.00000000"], ["72735.99000000", "0.00000000"], ["72736.00000000", "0.02566000"], ["72736.01000000", "0.00078000"], ["72738.01000000", "0.00008000"], ["72738.02000000", "0.00016000"], ["72738.12000000", "0.00008000"], ["72738.13000000", "0.00016000"], ["72738.91000000", "0.00016000"], ["72738.92000000", "0.00016000"], ["72739.08000000", "0.00000000"], ["72739.38000000", "0.00000000"], ["72739.46000000", "0.00000000"], ["72739.98000000", "0.00016000"], ["72739.99000000", "0.00024000"], ["72740.14000000", "0.00000000"], ["72740.30000000", "0.00008000"], ["72740.31000000", "0.00000000"], ["72740.66000000", "0.00016000"], ["72740.85000000", "0.00000000"], ["72740.92000000", "0.00000000"], ["72741.08000000", "0.00000000"], ["72741.26000000", "0.16325000"], ["72741.54000000", "0.00300000"], ["72741.93000000", "0.17244000"], ["72741.94000000", "0.00000000"], ["72742.23000000", "0.00000000"], ["72742.26000000", "0.00000000"], ["72742.29000000", "0.00000000"], ["72742.43000000", "0.00000000"], ["72742.54000000", "0.00000000"], ["72742.81000000", "0.00000000"], ["72742.95000000", "0.00000000"], ["72743.12000000", "0.00000000"], ["72744.10000000", "0.00000000"], ["72744.42000000", "0.00000000"], ["72744.99000000", "0.05942000"], ["72745.28000000", "0.00031000"], ["72745.43000000", "0.02000000"], ["72745.58000000", "0.00008000"], ["72746.50000000", "0.00000000"], ["72747.74000000", "0.00000000"], ["72748.01000000", "0.00000000"], ["72748.23000000", "0.00000000"], ["72749.03000000", "0.00000000"], ["72751.86000000", "0.00008000"], ["72753.31000000", "0.00000000"], ["72753.99000000", "0.00000000"], ["72756.47000000", "0.00000000"], ["72757.70000000", "0.45977000"], ["72758.74000000", "0.68823000"], ["72761.39000000", "0.00000000"], ["72763.10000000", "0.00000000"], ["72764.24000000", "0.05035000"], ["72769.59000000", "0.00000000"], ["72770.32000000", "0.00000000"], ["72770.52000000", "0.00200000"], ["72771.21000000", "0.40470000"], ["72779.74000000", "0.50340000"], ["72782.63000000", "0.00000000"], ["72785.97000000", "0.43728000"], ["72789.98000000", "0.00000000"], ["72792.19000000", "0.00000000"], ["72793.25000000", "0.90194000"], ["72793.34000000", "0.00000000"], ["72793.37000000", "0.55338000"], ["72795.33000000", "0.00000000"], ["72797.22000000", "0.01063000"], ["72802.33000000", "0.18446000"], ["72803.28000000", "0.00550000"], ["72803.99000000", "0.05882000"], ["72807.14000000", "0.36892000"], ["72808.42000000", "0.27366000"], ["72812.50000000", "0.96432000"], ["72812.57000000", "0.00000000"], ["72815.99000000", "0.21603000"], ["72820.66000000", "2.25625000"], ["72821.06000000", "0.00009000"], ["72827.20000000", "0.00008000"], ["72839.64000000", "0.12980000"], ["72841.04000000", "0.94919000"], ["72844.27000000", "0.08311000"], ["72848.44000000", "1.37226000"], ["72850.63000000", "0.00185000"], ["72851.36000000", "0.00000000"], ["72856.90000000", "0.13104000"], ["72857.99000000", "0.00000000"], ["72871.99000000", "0.00137000"], ["72883.67000000", "0.00000000"], ["72919.56000000", "0.19177000"], ["72930.87000000", "0.00007000"], ["72934.50000000", "0.00007000"], ["73020.00000000", "0.00508000"]], "_local_ts_utc": "2026-06-01T07:49:12.110562+00:00"}
{"e": "depthUpdate", "E": 1780300153314, "s": "BTCUSDT", "U": 94551806151, "u": 94551806760, "b": [["72741.25000000", "4.19179000"], ["72741.24000000", "0.00038000"], ["72741.23000000", "0.00014000"], ["72740.97000000", "0.00007000"], ["72740.96000000", "0.11999000"], ["72740.01000000", "0.04055000"], ["72739.99000000", "0.32514000"], ["72739.80000000", "0.16555000"], ["72739.61000000", "0.00000000"], ["72738.69000000", "0.16380000"], ["72738.60000000", "0.00000000"], ["72738.00000000", "0.00000000"], ["72737.99000000", "0.84776000"], ["72737.98000000", "0.00000000"], ["72737.62000000", "0.00000000"], ["72737.37000000", "0.00000000"], ["72737.28000000", "0.00007000"], ["72737.27000000", "0.00000000"], ["72736.13000000", "0.16380000"], ["72736.00000000", "0.40856000"], ["72735.99000000", "1.63448000"], ["72735.98000000", "0.23101000"], ["72735.97000000", "0.00000000"], ["72735.45000000", "0.00771000"], ["72735.19000000", "0.00000000"], ["72735.14000000", "0.00000000"], ["72735.06000000", "0.00016000"], ["72734.88000000", "0.00000000"], ["72734.70000000", "0.00016000"], ["72734.29000000", "0.36025000"], ["72734.28000000", "0.00008000"], ["72734.27000000", "0.00016000"], ["72734.26000000", "0.00000000"], ["72734.25000000", "0.33263000"], ["72734.02000000", "0.00000000"], ["72734.01000000", "0.00000000"], ["72734.00000000", "0.00000000"], ["72733.99000000", "0.00000000"], ["72733.96000000", "0.01363000"], ["72733.29000000", "0.00028000"], ["72733.09000000", "0.11136000"], ["72732.71000000", "0.00016000"], ["72732.16000000", "0.00008000"], ["72732.15000000", "0.00000000"], ["72732.14000000", "0.00000000"], ["72731.71000000", "0.00000000"], ["72731.52000000", "0.00008000"], ["72730.45000000", "0.26138000"], ["72730.44000000", "0.00000000"], ["72729.94000000", "0.00028000"], ["72729.17000000", "0.00000000"], ["72729.15000000", "0.00573000"], ["72728.89000000", "0.00007000"], ["72728.14000000", "0.00000000"], ["72728.11000000", "0.40856000"], ["72727.89000000", "0.04000000"], ["72727.06000000", "0.16381000"], ["72727.05000000", "2.22779000"], ["72727.04000000", "2.74973000"], ["72727.03000000", "0.00000000"], ["72727.02000000", "0.00000000"], ["72726.64000000", "0.03000000"], ["72726.22000000", "0.00008000"], ["72726.21000000", "0.00007000"], ["72726.20000000", "0.33127000"], ["72726.02000000", "0.02000000"], ["72725.98000000", "0.00000000"], ["72725.75000000", "0.00000000"], ["72725.55000000", "0.00000000"], ["72725.33000000", "0.03407000"], ["72725.16000000", "0.00008000"], ["72724.25000000", "0.00000000"], ["72724.09000000", "0.00000000"], ["72724.04000000", "0.00000000"], ["72723.74000000", "0.02000000"], ["72722.53000000", "0.00000000"], ["72721.92000000", "0.00008000"], ["72721.55000000", "0.00000000"], ["72721.40000000", "0.00000000"], ["72721.31000000", "0.00000000"], ["72721.19000000", "0.02000000"], ["72720.67000000", "0.00000000"], ["72720.48000000", "0.42057000"], ["72720.47000000", "0.78190000"], ["72719.71000000", "0.00021000"], ["72719.26000000", "0.01288000"], ["72718.23000000", "0.00000000"], ["72718.14000000", "0.00000000"], ["72717.73000000", "0.00000000"], ["72715.99000000", "0.00000000"], ["72715.64000000", "0.00008000"], ["72715.05000000", "0.00000000"], ["72714.17000000", "0.00013000"], ["72712.38000000", "0.00000000"], ["72711.46000000", "0.63036000"], ["72711.35000000", "0.00191000"], ["72708.80000000", "0.00102000"], ["72707.90000000", "0.00000000"], ["72707.84000000", "0.00008000"], ["72707.71000000", "0.00000000"], ["72704.07000000", "2.75046000"], ["72700.38000000", "0.00000000"], ["72700.01000000", "0.00055000"], ["72698.66000000", "0.00000000"], ["72697.14000000", "0.00000000"], ["72692.35000000", "0.00013000"], ["72687.50000000", "0.00068000"], ["72686.98000000", "0.00239000"], ["72682.38000000", "0.18446000"], ["72682.12000000", "0.00343000"], ["72681.67000000", "0.36992000"], ["72677.45000000", "0.27557000"], ["72676.85000000", "0.00000000"], ["72670.53000000", "0.00013000"], ["72662.33000000", "0.00000000"], ["72659.32000000", "0.00000000"], ["72658.54000000", "0.00023000"], ["72657.60000000", "0.85310000"], ["72657.59000000", "0.00000000"], ["72657.29000000", "0.00000000"], ["72655.03000000", "0.00000000"], ["72653.86000000", "0.00000000"], ["72648.71000000", "0.00013000"], ["72633.22000000", "0.00000000"], ["72632.48000000", "1.83832000"], ["72630.00000000", "0.03738000"], ["72626.89000000", "0.00013000"], ["72625.39000000", "0.00000000"], ["72611.40000000", "0.00000000"], ["72598.75000000", "0.00000000"], ["72596.31000000", "0.00000000"], ["72541.81000000", "0.00007000"], ["72536.90000000", "0.00000000"], ["72535.01000000", "0.00000000"], ["72428.47000000", "1.87700000"], ["72395.16000000", "0.00000000"], ["65462.40000000", "0.00000000"]], "a": [["72736.00000000", "0.00000000"], ["72736.01000000", "0.00000000"], ["72737.28000000", "0.00000000"], ["72737.38000000", "0.00000000"], ["72737.63000000", "0.00000000"], ["72737.99000000", "0.00000000"], ["72738.00000000", "0.00000000"], ["72738.01000000", "0.00000000"], ["72738.02000000", "0.00000000"], ["72738.10000000", "0.00000000"], ["72738.12000000", "0.00000000"], ["72738.13000000", "0.00000000"], ["72738.88000000", "0.00000000"], ["72738.91000000", "0.00000000"], ["72738.92000000", "0.00000000"], ["72739.37000000", "0.00000000"], ["72739.62000000", "0.00000000"], ["72739.75000000", "0.00000000"], ["72739.98000000", "0.00000000"], ["72739.99000000", "0.00000000"], ["72740.00000000", "0.00000000"], ["72740.10000000", "0.00000000"], ["72740.30000000", "0.00000000"], ["72740.44000000", "0.00000000"], ["72740.65000000", "0.00000000"], ["72740.66000000", "0.00000000"], ["72740.79000000", "0.00000000"], ["72740.97000000", "0.00000000"], ["72741.24000000", "0.00000000"], ["72741.25000000", "0.00000000"], ["72741.26000000", "0.28205000"], ["72741.27000000", "0.00064000"], ["72741.35000000", "0.00000000"], ["72741.92000000", "0.00008000"], ["72741.93000000", "0.00016000"], ["72741.99000000", "0.00016000"], ["72742.00000000", "0.02296000"], ["72742.31000000", "0.00000000"], ["72742.42000000", "0.00000000"], ["72742.98000000", "0.00016000"], ["72742.99000000", "0.20496000"], ["72743.00000000", "0.65965000"], ["72743.58000000", "0.00000000"], ["72744.00000000", "0.02296000"], ["72744.26000000", "0.00000000"], ["72744.45000000", "0.00008000"], ["72744.91000000", "0.00000000"], ["72744.99000000", "0.00000000"], ["72745.01000000", "0.00000000"], ["72745.28000000", "0.00000000"], ["72745.32000000", "0.00000000"], ["72745.38000000", "0.00000000"], ["72745.40000000", "0.00000000"], ["72745.58000000", "0.00024000"], ["72745.96000000", "0.00008000"], ["72745.97000000", "0.00008000"], ["72746.51000000", "0.00008000"], ["72746.52000000", "0.00000000"], ["72747.16000000", "0.00000000"], ["72747.25000000", "0.00000000"], ["72747.72000000", "0.05942000"], ["72748.05000000", "0.00744000"], ["72748.25000000", "0.00027000"], ["72749.04000000", "0.41638000"], ["72749.73000000", "0.00000000"], ["72749.94000000", "0.00000000"], ["72750.00000000", "0.02280000"], ["72751.22000000", "0.00000000"], ["72751.35000000", "0.16380000"], ["72751.36000000", "0.00000000"], ["72751.52000000", "0.00000000"], ["72752.63000000", "0.16380000"], ["72752.64000000", "0.00000000"], ["72753.16000000", "0.00164000"], ["72753.50000000", "0.00000000"], ["72753.81000000", "0.16389000"], ["72754.55000000", "0.00009000"], ["72755.34000000", "0.01484000"], ["72756.87000000", "0.07000000"], ["72757.70000000", "0.16218000"], ["72757.71000000", "0.00000000"], ["72757.82000000", "0.00013000"], ["72758.13000000", "0.00000000"], ["72758.74000000", "0.00000000"], ["72758.87000000", "0.08000000"], ["72758.89000000", "0.07400000"], ["72759.35000000", "0.08000000"], ["72759.52000000", "0.08600000"], ["72759.98000000", "1.88417000"], ["72760.12000000", "0.00000000"], ["72760.33000000", "0.50000000"], ["72760.43000000", "0.00275000"], ["72760.44000000", "0.58277000"], ["72761.87000000", "0.00000000"], ["72762.00000000", "0.02280000"], ["72762.17000000", "0.06200000"], ["72763.16000000", "0.00400000"], ["72764.12000000", "0.00000000"], ["72764.24000000", "0.18148000"], ["72765.61000000", "0.00190000"], ["72765.78000000", "0.00012000"], ["72765.99000000", "0.68818000"], ["72767.19000000", "0.45885000"], ["72767.43000000", "0.00000000"], ["72769.23000000", "0.00000000"], ["72771.56000000", "0.00000000"], ["72774.18000000", "0.00007000"], ["72774.78000000", "0.04048000"], ["72776.22000000", "0.00000000"], ["72776.28000000", "0.00000000"], ["72776.34000000", "0.00400000"], ["72779.64000000", "0.00013000"], ["72779.98000000", "0.00407000"], ["72781.93000000", "0.00343000"], ["72783.79000000", "0.00105000"], ["72785.94000000", "0.00000000"], ["72793.25000000", "0.62664000"], ["72793.37000000", "0.00000000"], ["72797.98000000", "0.00000000"], ["72801.46000000", "0.00013000"], ["72801.63000000", "0.00000000"], ["72803.74000000", "0.08000000"], ["72803.85000000", "0.08600000"], ["72803.89000000", "0.07400000"], ["72803.99000000", "0.61273000"], ["72805.28000000", "0.00341000"], ["72805.80000000", "0.18446000"], ["72806.15000000", "1.36148000"], ["72806.50000000", "0.06200000"], ["72807.13000000", "0.36892000"], ["72807.75000000", "0.00000000"], ["72812.36000000", "0.00008000"], ["72812.89000000", "0.00000000"], ["72823.28000000", "0.00013000"], ["72829.57000000", "0.97490000"], ["72843.61000000", "0.00000000"], ["72845.10000000", "0.00013000"], ["72847.40000000", "0.00008000"], ["72874.36000000", "0.00000000"], ["72880.19000000", "0.00000000"], ["72885.10000000", "0.00008000"], ["72928.80000000", "0.00007000"], ["72934.50000000", "0.00000000"], ["72988.31000000", "0.00000000"], ["73017.67000000", "1.19998000"], ["73019.82000000", "0.00000000"], ["73030.58000000", "0.00008000"], ["73092.54000000", "0.00000000"], ["73103.32000000", "0.27008000"], ["73238.00000000", "0.00000000"], ["73248.80000000", "0.00008000"], ["82071.40000000", "0.00000000"]], "_local_ts_utc": "2026-06-01T07:49:12.210609+00:00"}
{"e": "depthUpdate", "E": 1780300153414, "s": "BTCUSDT", "U": 94551806761, "u": 94551807690, "b": [["72745.58000000", "4.79732000"], ["72745.57000000", "0.00038000"], ["72745.56000000", "0.00014000"], ["72745.42000000", "0.00000000"], ["72745.40000000", "0.00400000"], ["72745.02000000", "0.00016000"], ["72745.01000000", "0.00000000"], ["72744.66000000", "0.00007000"], ["72744.30000000", "0.00000000"], ["72744.10000000", "0.00016000"], ["72744.09000000", "0.05942000"], ["72744.02000000", "0.15039000"], ["72744.01000000", "0.17408000"], ["72743.99000000", "0.00000000"], ["72743.58000000", "0.00400000"], ["72743.02000000", "0.16234000"], ["72743.00000000", "0.00016000"], ["72742.99000000", "0.00000000"], ["72742.98000000", "0.00000000"], ["72742.79000000", "0.00000000"], ["72742.32000000", "0.00000000"], ["72741.99000000", "0.00000000"], ["72741.98000000", "0.00000000"], ["72741.92000000", "0.00000000"], ["72741.91000000", "0.00000000"], ["72741.76000000", "0.00400000"], ["72741.74000000", "0.16379000"], ["72741.55000000", "0.71101000"], ["72741.54000000", "0.00000000"], ["72741.53000000", "0.19881000"], ["72741.52000000", "0.00000000"], ["72741.51000000", "0.00000000"], ["72741.26000000", "0.11650000"], ["72741.25000000", "0.25514000"], ["72741.24000000", "0.00000000"], ["72741.23000000", "0.00000000"], ["72740.97000000", "0.00007000"], ["72740.96000000", "0.07023000"], ["72740.94000000", "0.00000000"], ["72740.93000000", "0.00000000"], ["72740.68000000", "0.00000000"], ["72740.58000000", "0.00028000"], ["72740.17000000", "0.00000000"], ["72740.01000000", "0.04071000"], ["72740.00000000", "0.00000000"], ["72739.99000000", "0.00016000"], ["72739.94000000", "0.00400000"], ["72739.80000000", "0.00016000"], ["72739.77000000", "0.00009000"], ["72738.88000000", "0.01373000"], ["72738.69000000", "0.00016000"], ["72738.12000000", "0.00400000"], ["72738.00000000", "0.55011000"], ["72737.99000000", "0.00016000"], ["72737.38000000", "0.00028000"], ["72736.62000000", "0.16379000"], ["72736.41000000", "0.00000000"], ["72736.30000000", "0.00400000"], ["72736.14000000", "0.00000000"], ["72736.13000000", "0.00000000"], ["72736.01000000", "0.40856000"], ["72736.00000000", "0.00008000"], ["72735.99000000", "0.99622000"], ["72735.98000000", "0.23085000"], ["72735.06000000", "0.00000000"], ["72735.00000000", "0.00000000"], ["72734.70000000", "0.00000000"], ["72734.32000000", "0.16379000"], ["72734.31000000", "0.14151000"], ["72734.30000000", "0.00011000"], ["72734.29000000", "0.00000000"], ["72734.28000000", "0.00000000"], ["72734.27000000", "0.00000000"], ["72734.25000000", "0.33247000"], ["72733.38000000", "0.00000000"], ["72733.33000000", "0.65949000"], ["72733.09000000", "0.11120000"], ["72732.88000000", "0.16235000"], ["72732.78000000", "0.16379000"], ["72732.73000000", "0.04000000"], ["72732.71000000", "0.00000000"], ["72732.57000000", "0.00000000"], ["72732.29000000", "0.00000000"], ["72732.17000000", "0.00007000"], ["72732.16000000", "0.00000000"], ["72731.50000000", "0.16379000"], ["72731.25000000", "0.00000000"], ["72731.01000000", "0.00000000"], ["72730.46000000", "0.00008000"], ["72730.45000000", "0.41418000"], ["72730.38000000", "0.65949000"], ["72729.73000000", "0.00000000"], ["72729.07000000", "0.16235000"], ["72728.94000000", "0.16379000"], ["72728.45000000", "0.00000000"], ["72728.18000000", "0.00000000"], ["72728.12000000", "0.00000000"], ["72727.89000000", "0.00000000"], ["72727.80000000", "0.00000000"], ["72727.17000000", "0.16380000"], ["72727.06000000", "0.00008000"], ["72727.05000000", "2.22787000"], ["72726.61000000", "0.00458000"], ["72726.31000000", "0.02000000"], ["72726.22000000", "0.00000000"], ["72725.98000000", "0.00000000"], ["72725.14000000", "0.00007000"], ["72724.77000000", "0.00349000"], ["72724.25000000", "0.00000000"], ["72721.45000000", "0.00007000"], ["72720.64000000", "0.79645000"], ["72720.58000000", "0.00011000"], ["72720.48000000", "0.24864000"], ["72719.71000000", "0.00028000"], ["72718.99000000", "0.00008000"], ["72718.25000000", "0.00000000"], ["72716.74000000", "0.00000000"], ["72716.28000000", "0.00000000"], ["72715.64000000", "0.00000000"], ["72715.04000000", "0.27795000"], ["72714.46000000", "0.00000000"], ["72712.64000000", "0.00000000"], ["72712.52000000", "0.00000000"], ["72712.51000000", "1.76728000"], ["72712.43000000", "0.00239000"], ["72711.92000000", "0.49572000"], ["72710.82000000", "0.00000000"], ["72710.55000000", "0.00008000"], ["72710.54000000", "1.36327000"], ["72710.53000000", "0.03071000"], ["72710.01000000", "0.00000000"], ["72709.00000000", "0.00000000"], ["72707.76000000", "0.00000000"], ["72707.18000000", "0.00000000"], ["72706.37000000", "0.00412000"], ["72705.92000000", "0.00011000"], ["72703.74000000", "0.02653000"], ["72699.63000000", "0.00110000"], ["72699.35000000", "0.00000000"], ["72696.22000000", "0.00000000"], ["72693.30000000", "0.00000000"], ["72688.74000000", "1.10676000"], ["72686.98000000", "0.00102000"], ["72680.42000000", "0.00000000"], ["72679.58000000", "0.43420000"], ["72679.57000000", "0.00000000"], ["72673.64000000", "0.00000000"], ["72668.79000000", "0.00008000"], ["72664.57000000", "0.34334000"], ["72664.55000000", "0.00000000"], ["72663.93000000", "0.01723000"], ["72663.77000000", "0.00000000"], ["72662.84000000", "0.00000000"], ["72661.26000000", "0.00000000"], ["72655.25000000", "0.00000000"], ["72650.67000000", "0.00000000"], ["72648.64000000", "0.00000000"], ["72647.07000000", "0.00000000"], ["72644.83000000", "0.00000000"], ["72644.82000000", "0.00000000"], ["72638.34000000", "0.00000000"], ["72633.14000000", "0.04268000"], ["72623.18000000", "2.44633000"], ["72596.05000000", "0.00008000"], ["72588.52000000", "0.00000000"], ["72576.30000000", "0.09289000"], ["72571.72000000", "0.21159000"], ["72553.00000000", "0.00000000"], ["72539.01000000", "0.00000000"], ["72523.31000000", "0.00008000"], ["72515.79000000", "0.00000000"], ["72450.56000000", "0.00008000"], ["72444.66000000", "0.00000000"], ["72443.05000000", "0.00000000"], ["72377.82000000", "0.00008000"], ["72370.32000000", "0.00000000"], ["72305.08000000", "0.00008000"], ["72297.59000000", "0.00000000"], ["72232.34000000", "0.00008000"], ["72224.85000000", "0.00000000"], ["72159.60000000", "0.00008000"], ["72152.12000000", "0.00000000"], ["71716.70000000", "0.00000000"], ["71662.50000000", "1.64642000"], ["71610.94000000", "0.00000000"], ["65471.03000000", "0.00017000"], ["65467.13000000", "0.00000000"], ["58193.00000000", "0.00000000"]], "a": [["72741.26000000", "0.00000000"], ["72741.27000000", "0.00000000"], ["72741.54000000", "0.00000000"], ["72741.55000000", "0.00000000"], ["72741.92000000", "0.00000000"], ["72741.93000000", "0.00000000"], ["72741.99000000", "0.00000000"], ["72742.00000000", "0.00000000"], ["72742.33000000", "0.00000000"], ["72742.56000000", "0.00000000"], ["72742.57000000", "0.00000000"], ["72742.80000000", "0.00000000"], ["72742.87000000", "0.00000000"], ["72742.98000000", "0.00000000"], ["72742.99000000", "0.00000000"], ["72743.00000000", "0.00000000"], ["72744.00000000", "0.00000000"], ["72744.41000000", "0.00000000"], ["72744.45000000", "0.00000000"], ["72744.66000000", "0.00000000"], ["72744.79000000", "0.00000000"], ["72744.82000000", "0.00000000"], ["72745.05000000", "0.00000000"], ["72745.43000000", "0.00000000"], ["72745.58000000", "0.00000000"], ["72745.59000000", "0.40395000"], ["72745.60000000", "0.00064000"], ["72745.86000000", "0.00000000"], ["72745.96000000", "0.00016000"], ["72745.97000000", "0.65973000"], ["72745.98000000", "0.00016000"], ["72746.00000000", "0.02296000"], ["72746.12000000", "0.00000000"], ["72746.14000000", "0.00000000"], ["72746.20000000", "0.00000000"], ["72746.33000000", "0.00000000"], ["72746.53000000", "0.00000000"], ["72747.14000000", "0.00000000"], ["72747.21000000", "0.00016000"], ["72747.50000000", "0.00000000"], ["72747.55000000", "0.01384000"], ["72747.71000000", "0.00000000"], ["72747.72000000", "0.00016000"], ["72748.00000000", "0.02296000"], ["72748.05000000", "0.00016000"], ["72748.09000000", "0.00016000"], ["72748.10000000", "0.12101000"], ["72748.23000000", "0.02000000"], ["72748.39000000", "0.00000000"], ["72748.69000000", "0.00000000"], ["72748.76000000", "0.00000000"], ["72748.91000000", "0.65973000"], ["72748.92000000", "0.00000000"], ["72749.03000000", "0.00016000"], ["72749.04000000", "0.26576000"], ["72749.14000000", "0.00000000"], ["72749.22000000", "0.00773000"], ["72749.29000000", "0.00000000"], ["72750.55000000", "0.00000000"], ["72750.72000000", "0.00031000"], ["72750.86000000", "0.00000000"], ["72750.92000000", "0.00000000"], ["72751.35000000", "0.00000000"], ["72751.86000000", "0.00008000"], ["72751.87000000", "0.00000000"], ["72752.63000000", "0.00000000"], ["72753.04000000", "0.00020000"], ["72753.17000000", "0.00000000"], ["72753.27000000", "0.16386000"], ["72753.80000000", "1.06805000"], ["72753.81000000", "0.00008000"], ["72753.82000000", "0.41883000"], ["72753.83000000", "0.00000000"], ["72754.25000000", "0.00007000"], ["72754.97000000", "0.00000000"], ["72755.42000000", "0.00000000"], ["72755.83000000", "0.00000000"], ["72756.17000000", "0.00000000"], ["72756.87000000", "0.00000000"], ["72757.02000000", "0.16235000"], ["72757.11000000", "0.16379000"], ["72757.27000000", "0.65949000"], ["72757.41000000", "0.00007000"], ["72757.70000000", "0.26497000"], ["72758.18000000", "0.00000000"], ["72758.87000000", "0.00000000"], ["72759.29000000", "0.00020000"], ["72759.46000000", "0.16379000"], ["72759.50000000", "0.08600000"], ["72759.97000000", "0.16387000"], ["72760.17000000", "0.00000000"], ["72761.87000000", "2.74973000"], ["72761.88000000", "0.00000000"], ["72762.57000000", "0.15000000"], ["72763.16000000", "0.00000000"], ["72764.24000000", "0.37013000"], ["72764.52000000", "0.00020000"], ["72764.86000000", "0.38349000"], ["72765.99000000", "0.00000000"], ["72766.93000000", "0.00000000"], ["72767.19000000", "0.00000000"], ["72767.39000000", "0.00000000"], ["72769.82000000", "0.00400000"], ["72769.86000000", "0.00000000"], ["72769.91000000", "0.00000000"], ["72770.04000000", "0.00000000"], ["72770.11000000", "0.00000000"], ["72770.13000000", "0.00000000"], ["72770.88000000", "0.69214000"], ["72770.95000000", "0.00000000"], ["72771.21000000", "0.40470000"], ["72772.24000000", "0.50000000"], ["72772.61000000", "0.00020000"], ["72772.68000000", "0.00000000"], ["72772.77000000", "0.00200000"], ["72773.58000000", "0.00000000"], ["72773.99000000", "0.00000000"], ["72777.75000000", "0.00000000"], ["72777.87000000", "0.00007000"], ["72780.03000000", "0.00000000"], ["72780.95000000", "0.00000000"], ["72781.56000000", "0.00007000"], ["72781.80000000", "0.00400000"], ["72782.43000000", "0.00020000"], ["72783.13000000", "0.00000000"], ["72784.21000000", "0.00000000"], ["72784.36000000", "0.00400000"], ["72784.37000000", "0.00000000"], ["72784.41000000", "0.00000000"], ["72784.46000000", "0.00000000"], ["72784.61000000", "0.00000000"], ["72784.63000000", "0.00007000"], ["72785.44000000", "0.00400000"], ["72785.53000000", "0.08200000"], ["72787.94000000", "0.00000000"], ["72789.72000000", "0.49519000"], ["72791.21000000", "0.00000000"], ["72795.97000000", "0.08600000"], ["72797.97000000", "0.00000000"], ["72799.71000000", "0.09328000"], ["72803.24000000", "0.36892000"], ["72803.28000000", "0.00000000"], ["72809.85000000", "0.82338000"], ["72821.07000000", "0.00000000"], ["72824.89000000", "0.00000000"], ["72827.09000000", "0.00000000"], ["72842.44000000", "0.00000000"], ["72844.27000000", "0.08174000"], ["72848.43000000", "2.74973000"], ["72851.37000000", "0.04266000"], ["72859.99000000", "0.00137000"], ["72862.25000000", "0.31923000"], ["72863.84000000", "0.00000000"], ["72864.93000000", "0.03970000"], ["72890.32000000", "0.00000000"], ["72902.43000000", "0.27000000"], ["72929.81000000", "4.11871000"], ["72935.47000000", "0.00007000"], ["72939.10000000", "0.00007000"], ["73038.67000000", "4.11257000"], ["73369.48000000", "0.00000000"], ["90321.56000000", "0.00029000"]], "_local_ts_utc": "2026-06-01T07:49:12.311743+00:00"}
{"e": "depthUpdate", "E": 1780300153514, "s": "BTCUSDT", "U": 94551807691, "u": 94551808100, "b": [["72745.58000000", "3.38115000"], ["72745.04000000", "0.00016000"], ["72745.03000000", "0.04813000"], ["72745.02000000", "0.00000000"], ["72744.31000000", "0.16235000"], ["72744.11000000", "0.00000000"], ["72744.10000000", "0.07237000"], ["72744.09000000", "0.05958000"], ["72744.03000000", "0.00000000"], ["72744.02000000", "0.00016000"], ["72744.01000000", "0.17424000"], ["72743.04000000", "0.16235000"], ["72743.03000000", "0.00000000"], ["72743.02000000", "0.00016000"], ["72743.00000000", "0.00000000"], ["72741.77000000", "0.16235000"], ["72741.75000000", "0.00000000"], ["72741.74000000", "0.16395000"], ["72741.56000000", "0.13823000"], ["72741.55000000", "0.00024000"], ["72741.53000000", "0.19881000"], ["72741.26000000", "0.00530000"], ["72741.25000000", "0.25450000"], ["72740.96000000", "0.07007000"], ["72740.08000000", "0.00738000"], ["72740.01000000", "0.04055000"], ["72739.99000000", "0.00000000"], ["72739.80000000", "0.00000000"], ["72738.69000000", "0.00000000"], ["72738.18000000", "0.00751000"], ["72738.01000000", "0.59819000"], ["72738.00000000", "0.16379000"], ["72737.99000000", "0.00000000"], ["72736.69000000", "0.16235000"], ["72734.31000000", "0.47836000"], ["72734.25000000", "0.32409000"], ["72732.79000000", "0.00000000"], ["72732.73000000", "0.00000000"], ["72732.25000000", "0.04000000"], ["72722.84000000", "0.00200000"], ["72721.44000000", "0.00008000"], ["72720.18000000", "0.00000000"], ["72718.09000000", "0.00000000"], ["72717.27000000", "0.00000000"], ["72716.48000000", "0.00686000"], ["72712.32000000", "0.00000000"], ["72708.52000000", "0.02687000"], ["72705.94000000", "0.00000000"], ["72705.44000000", "0.00000000"], ["72703.74000000", "0.00000000"], ["72700.50000000", "0.00000000"], ["72688.75000000", "0.92230000"], ["72688.74000000", "1.66014000"], ["72687.76000000", "0.00000000"], ["72686.71000000", "0.45597000"], ["72686.38000000", "0.00000000"], ["72684.33000000", "0.36892000"], ["72676.01000000", "0.06799000"], ["72672.83000000", "0.00685000"], ["72671.42000000", "0.00000000"], ["72667.70000000", "0.01328000"], ["72661.19000000", "0.00222000"], ["72655.14000000", "0.00000000"], ["72654.58000000", "0.00000000"], ["72647.01000000", "0.05426000"], ["72456.52000000", "0.00030000"], ["72379.51000000", "0.00532000"], ["72006.90000000", "0.00000000"], ["65471.03000000", "0.00051000"], ["58196.47000000", "0.00034000"], ["58196.00000000", "0.00601000"]], "a": [["72745.59000000", "0.11972000"], ["72745.60000000", "0.00072000"], ["72745.94000000", "0.00016000"], ["72745.95000000", "0.00016000"], ["72745.96000000", "0.00000000"], ["72745.97000000", "0.00024000"], ["72745.98000000", "0.00000000"], ["72745.99000000", "0.00000000"], ["72746.00000000", "0.02296000"], ["72747.21000000", "0.00000000"], ["72747.54000000", "0.00000000"], ["72747.55000000", "0.01400000"], ["72747.72000000", "0.00000000"], ["72747.99000000", "0.00008000"], ["72748.00000000", "0.02296000"], ["72748.05000000", "0.00000000"], ["72748.08000000", "0.00024000"], ["72748.09000000", "0.00016000"], ["72748.10000000", "0.12101000"], ["72748.23000000", "0.00016000"], ["72748.31000000", "0.00000000"], ["72748.80000000", "0.00000000"], ["72748.89000000", "0.00008000"], ["72748.90000000", "0.00008000"], ["72748.91000000", "0.00024000"], ["72749.03000000", "0.00000000"], ["72749.04000000", "0.13211000"], ["72749.67000000", "0.00000000"], ["72750.54000000", "0.01721000"], ["72750.59000000", "0.00000000"], ["72750.67000000", "0.00000000"], ["72750.68000000", "0.00000000"], ["72750.72000000", "0.00000000"], ["72751.93000000", "0.00000000"], ["72751.94000000", "0.00000000"], ["72752.63000000", "0.00000000"], ["72753.21000000", "0.16235000"], ["72753.26000000", "0.00000000"], ["72753.54000000", "0.02000000"], ["72753.79000000", "0.34404000"], ["72753.82000000", "0.00000000"], ["72755.75000000", "0.16235000"], ["72757.26000000", "0.45935000"], ["72757.70000000", "0.00008000"], ["72759.78000000", "0.00191000"], ["72760.14000000", "0.00128000"], ["72761.87000000", "0.00000000"], ["72762.57000000", "0.03000000"], ["72764.24000000", "0.16548000"], ["72767.28000000", "0.00000000"], ["72768.20000000", "0.00000000"], ["72768.43000000", "0.00000000"], ["72768.51000000", "0.00000000"], ["72768.55000000", "0.00000000"], ["72768.57000000", "0.00000000"], ["72768.58000000", "0.00000000"], ["72768.59000000", "0.00000000"], ["72768.76000000", "0.00000000"], ["72768.80000000", "0.00000000"], ["72768.86000000", "0.00000000"], ["72769.08000000", "0.00000000"], ["72769.16000000", "0.06200000"], ["72769.20000000", "0.00000000"], ["72769.24000000", "0.00007000"], ["72769.36000000", "0.00000000"], ["72769.37000000", "0.00400000"], ["72769.44000000", "0.00000000"], ["72769.45000000", "0.00000000"], ["72769.61000000", "0.00000000"], ["72769.62000000", "0.00000000"], ["72769.63000000", "0.00000000"], ["72769.64000000", "0.00000000"], ["72769.73000000", "0.00000000"], ["72769.75000000", "0.00000000"], ["72769.82000000", "0.00000000"], ["72770.52000000", "0.00000000"], ["72770.89000000", "0.00000000"], ["72774.01000000", "0.00000000"], ["72774.69000000", "0.00686000"], ["72778.21000000", "0.00000000"], ["72779.74000000", "0.21776000"], ["72781.06000000", "0.00200000"], ["72782.45000000", "0.00000000"], ["72782.75000000", "0.00000000"], ["72782.99000000", "0.00000000"], ["72783.05000000", "0.00000000"], ["72783.10000000", "0.00000000"], ["72783.12000000", "0.00000000"], ["72783.13000000", "0.00000000"], ["72783.14000000", "0.00000000"], ["72783.31000000", "0.00000000"], ["72783.35000000", "0.00000000"], ["72783.41000000", "0.00000000"], ["72783.63000000", "0.00000000"], ["72783.70000000", "0.00000000"], ["72783.73000000", "0.00000000"], ["72783.78000000", "0.00000000"], ["72783.79000000", "0.00105000"], ["72783.95000000", "0.00000000"], ["72784.00000000", "0.02280000"], ["72784.16000000", "0.00000000"], ["72784.17000000", "0.00000000"], ["72784.18000000", "0.00000000"], ["72784.19000000", "0.00000000"], ["72784.28000000", "1.36189000"], ["72784.30000000", "0.00000000"], ["72784.36000000", "0.00000000"], ["72784.68000000", "0.00430000"], ["72787.95000000", "0.23232000"], ["72788.54000000", "0.00434000"], ["72791.07000000", "0.43360000"], ["72801.99000000", "0.00000000"], ["72808.42000000", "0.47013000"], ["72809.84000000", "0.36892000"], ["72818.34000000", "0.00685000"], ["72820.66000000", "1.02495000"], ["72822.75000000", "0.02604000"], ["72830.88000000", "0.00008000"], ["72831.95000000", "0.00000000"], ["72848.42000000", "2.19305000"], ["72848.44000000", "0.00000000"], ["72865.52000000", "0.13889000"], ["72875.08000000", "0.00000000"], ["73461.61000000", "0.00000000"], ["74156.46000000", "0.00000000"]], "_local_ts_utc": "2026-06-01T07:49:12.411729+00:00"}
{"e": "depthUpdate", "E": 1780300153614, "s": "BTCUSDT", "U": 94551808101, "u": 94551808654, "b": [["72745.99000000", "3.16727000"], ["72745.98000000", "0.00038000"], ["72745.97000000", "0.00014000"], ["72745.96000000", "0.00000000"], ["72745.95000000", "0.00000000"], ["72745.94000000", "0.00000000"], ["72745.93000000", "0.00000000"], ["72745.78000000", "0.04055000"], ["72745.60000000", "0.00008000"], ["72745.59000000", "0.66945000"], ["72745.58000000", "0.61601000"], ["72745.57000000", "0.00000000"], ["72745.56000000", "0.00000000"], ["72745.30000000", "0.11424000"], ["72745.04000000", "0.00000000"], ["72745.03000000", "0.00016000"], ["72744.72000000", "0.00000000"], ["72744.31000000", "0.16251000"], ["72744.10000000", "0.00016000"], ["72744.09000000", "0.05958000"], ["72744.02000000", "0.00000000"], ["72744.01000000", "0.17424000"], ["72743.90000000", "0.01376000"], ["72743.78000000", "0.01405000"], ["72743.04000000", "0.16251000"], ["72743.02000000", "0.00000000"], ["72742.98000000", "0.00742000"], ["72741.79000000", "0.00008000"], ["72741.78000000", "0.65949000"], ["72741.74000000", "0.00000000"], ["72741.55000000", "0.00000000"], ["72741.53000000", "0.19865000"], ["72739.64000000", "0.16235000"], ["72739.23000000", "0.16235000"], ["72738.02000000", "0.65949000"], ["72736.62000000", "0.00000000"], ["72736.02000000", "0.00165000"], ["72735.99000000", "0.99366000"], ["72734.56000000", "0.16235000"], ["72734.54000000", "0.03000000"], ["72734.34000000", "1.31893000"], ["72734.33000000", "2.74973000"], ["72734.31000000", "0.00000000"], ["72732.78000000", "0.00000000"], ["72732.76000000", "0.04000000"], ["72732.25000000", "0.00000000"], ["72732.13000000", "0.00000000"], ["72731.53000000", "0.00000000"], ["72730.46000000", "0.16235000"], ["72730.39000000", "0.00008000"], ["72730.02000000", "0.02000000"], ["72729.18000000", "0.02000000"], ["72728.94000000", "0.00000000"], ["72728.50000000", "0.02000000"], ["72727.74000000", "0.12071000"], ["72727.06000000", "0.00000000"], ["72726.64000000", "0.00000000"], ["72726.39000000", "0.00420000"], ["72725.55000000", "0.00000000"], ["72725.54000000", "0.25015000"], ["72725.31000000", "0.00000000"], ["72724.03000000", "0.00000000"], ["72724.01000000", "0.74232000"], ["72723.33000000", "0.00000000"], ["72722.44000000", "0.00000000"], ["72721.92000000", "0.00008000"], ["72720.69000000", "0.00000000"], ["72720.64000000", "0.79071000"], ["72718.98000000", "1.47747000"], ["72718.24000000", "1.74476000"], ["72717.86000000", "0.00007000"], ["72717.47000000", "0.49568000"], ["72716.48000000", "0.00000000"], ["72715.63000000", "0.00000000"], ["72715.61000000", "0.00137000"], ["72715.38000000", "0.00007000"], ["72715.05000000", "0.30212000"], ["72714.08000000", "0.00000000"], ["72713.94000000", "0.00000000"], ["72712.52000000", "0.00008000"], ["72710.55000000", "0.00000000"], ["72707.84000000", "0.00000000"], ["72704.08000000", "0.40856000"], ["72686.90000000", "0.50596000"], ["72686.89000000", "0.00000000"], ["72686.42000000", "0.06924000"], ["72681.54000000", "0.00000000"], ["72680.58000000", "0.00138000"], ["72677.64000000", "0.00000000"], ["72672.83000000", "0.00000000"], ["72672.39000000", "0.64215000"], ["72669.28000000", "0.65949000"], ["72657.60000000", "0.55598000"], ["72655.80000000", "0.00000000"], ["72654.95000000", "0.00000000"], ["72652.67000000", "0.00276000"], ["72650.03000000", "0.21020000"], ["72650.02000000", "0.00000000"], ["72648.22000000", "0.00012000"], ["72551.44000000", "0.09870000"], ["65471.40000000", "0.00034000"], ["65471.03000000", "0.00000000"], ["58196.47000000", "0.00000000"]], "a": [["72745.59000000", "0.00000000"], ["72745.60000000", "0.00000000"], ["72745.94000000", "0.00000000"], ["72745.95000000", "0.00000000"], ["72745.97000000", "0.00000000"], ["72745.99000000", "0.00000000"], ["72746.00000000", "0.02787000"], ["72746.01000000", "0.00072000"], ["72747.54000000", "0.00000000"], ["72747.55000000", "0.00016000"], ["72747.99000000", "0.00024000"], ["72748.08000000", "0.00008000"], ["72748.09000000", "0.00000000"], ["72748.10000000", "0.00016000"], ["72748.23000000", "0.00000000"], ["72748.73000000", "0.00000000"], ["72748.75000000", "0.00000000"], ["72748.89000000", "0.00000000"], ["72748.90000000", "0.00000000"], ["72748.91000000", "0.00008000"], ["72749.03000000", "0.00000000"], ["72749.04000000", "0.00016000"], ["72749.22000000", "0.00016000"], ["72749.71000000", "0.00000000"], ["72749.99000000", "0.00031000"], ["72750.00000000", "0.02296000"], ["72750.10000000", "0.00589000"], ["72750.38000000", "0.00000000"], ["72750.54000000", "0.00016000"], ["72750.74000000", "0.00000000"], ["72750.93000000", "0.00593000"], ["72751.38000000", "0.00000000"], ["72751.99000000", "0.00016000"], ["72752.99000000", "0.00000000"], ["72753.21000000", "0.00000000"], ["72753.27000000", "0.00007000"], ["72753.53000000", "0.00000000"], ["72753.54000000", "0.00000000"], ["72753.78000000", "0.00016000"], ["72753.79000000", "0.14975000"], ["72753.80000000", "0.00000000"], ["72753.99000000", "0.00000000"], ["72754.19000000", "0.00000000"], ["72754.43000000", "0.00000000"], ["72754.49000000", "0.00000000"], ["72754.50000000", "0.00000000"], ["72754.55000000", "0.00000000"], ["72754.59000000", "0.00000000"], ["72754.67000000", "0.00028000"], ["72754.86000000", "0.00000000"], ["72755.00000000", "0.00031000"], ["72755.34000000", "0.00000000"], ["72755.75000000", "0.00000000"], ["72756.16000000", "0.16235000"], ["72756.40000000", "0.00000000"], ["72757.11000000", "0.00000000"], ["72757.26000000", "0.41797000"], ["72757.27000000", "0.00000000"], ["72757.63000000", "0.00000000"], ["72757.99000000", "0.00000000"], ["72758.14000000", "0.02454000"], ["72758.70000000", "0.16235000"], ["72758.75000000", "0.00000000"], ["72758.89000000", "0.00000000"], ["72759.20000000", "0.65949000"], ["72759.35000000", "0.00000000"], ["72759.97000000", "0.00008000"], ["72759.98000000", "0.72879000"], ["72760.14000000", "0.00008000"], ["72760.32000000", "0.14888000"], ["72761.02000000", "0.00000000"], ["72761.27000000", "0.00771000"], ["72761.30000000", "0.00155000"], ["72761.40000000", "0.00000000"], ["72762.11000000", "0.00000000"], ["72762.37000000", "0.00000000"], ["72762.57000000", "0.00000000"], ["72763.78000000", "0.15546000"], ["72764.24000000", "0.32439000"], ["72764.28000000", "0.12085000"], ["72764.37000000", "0.03000000"], ["72764.47000000", "0.12000000"], ["72764.85000000", "0.16235000"], ["72764.91000000", "0.00770000"], ["72765.76000000", "0.01484000"], ["72766.32000000", "0.16235000"], ["72766.46000000", "0.00903000"], ["72767.40000000", "0.00000000"], ["72767.59000000", "0.16235000"], ["72768.06000000", "1.54685000"], ["72768.07000000", "0.14856000"], ["72768.55000000", "0.00745000"], ["72768.68000000", "2.74973000"], ["72768.69000000", "0.00008000"], ["72768.70000000", "0.00000000"], ["72769.37000000", "0.00000000"], ["72770.09000000", "0.15124000"], ["72770.87000000", "0.68808000"], ["72770.88000000", "0.00400000"], ["72771.20000000", "0.16235000"], ["72772.23000000", "0.00000000"], ["72772.77000000", "0.00000000"], ["72773.94000000", "0.16235000"], ["72774.11000000", "0.00120000"], ["72774.55000000", "0.16235000"], ["72774.69000000", "0.00000000"], ["72779.24000000", "0.00000000"], ["72781.93000000", "0.00343000"], ["72783.58000000", "0.00000000"], ["72783.79000000", "0.00000000"], ["72784.28000000", "0.00000000"], ["72784.57000000", "0.96884000"], ["72785.97000000", "0.32399000"], ["72786.26000000", "0.00000000"], ["72787.32000000", "0.00000000"], ["72789.08000000", "0.00400000"], ["72791.54000000", "0.00434000"], ["72793.09000000", "0.00000000"], ["72794.45000000", "0.49516000"], ["72797.99000000", "0.04076000"], ["72798.89000000", "0.00009000"], ["72802.33000000", "0.00000000"], ["72803.24000000", "0.00000000"], ["72805.62000000", "0.06200000"], ["72806.40000000", "0.05400000"], ["72809.48000000", "0.06856000"], ["72814.79000000", "1.20300000"], ["72814.80000000", "1.36132000"], ["72815.97000000", "0.36892000"], ["72815.99000000", "0.00000000"], ["72817.86000000", "1.84460000"], ["72818.34000000", "0.00000000"], ["72819.00000000", "0.02752000"], ["72824.85000000", "0.00105000"], ["72858.61000000", "0.82807000"], ["72858.62000000", "2.74973000"], ["72865.51000000", "0.00412000"], ["72941.72000000", "0.00007000"], ["72945.35000000", "0.00007000"]], "_local_ts_utc": "2026-06-01T07:49:12.510720+00:00"}
{"e": "depthUpdate", "E": 1780300153714, "s": "BTCUSDT", "U": 94551808655, "u": 94551809006, "b": [["72747.09000000", "4.67068000"], ["72747.08000000", "0.00038000"], ["72747.07000000", "0.00014000"], ["72746.50000000", "0.00000000"], ["72746.23000000", "0.00000000"], ["72746.00000000", "1.52255000"], ["72745.99000000", "0.39453000"], ["72745.98000000", "0.00000000"], ["72745.97000000", "0.00000000"], ["72745.79000000", "0.00000000"], ["72745.78000000", "0.04071000"], ["72745.60000000", "0.00024000"], ["72745.59000000", "0.00032000"], ["72745.58000000", "0.45341000"], ["72745.31000000", "0.00000000"], ["72745.30000000", "0.00016000"], ["72745.14000000", "0.00746000"], ["72745.03000000", "0.00000000"], ["72744.82000000", "0.00000000"], ["72744.31000000", "0.00016000"], ["72744.10000000", "0.00000000"], ["72744.09000000", "0.00016000"], ["72744.01000000", "0.17424000"], ["72743.90000000", "0.00000000"], ["72743.04000000", "0.00000000"], ["72741.77000000", "0.00000000"], ["72741.56000000", "0.20088000"], ["72741.26000000", "0.00000000"], ["72739.64000000", "0.00000000"], ["72739.23000000", "0.00000000"], ["72738.00000000", "0.00000000"], ["72735.99000000", "0.99366000"], ["72735.38000000", "0.00000000"], ["72735.20000000", "0.00008000"], ["72734.96000000", "0.00000000"], ["72734.32000000", "0.00000000"], ["72734.08000000", "0.04000000"], ["72732.88000000", "0.00000000"], ["72732.76000000", "0.00000000"], ["72732.71000000", "0.00000000"], ["72731.50000000", "0.00000000"], ["72730.46000000", "0.00000000"], ["72729.07000000", "0.00000000"], ["72728.23000000", "0.00000000"], ["72727.17000000", "0.00000000"], ["72725.14000000", "0.00000000"], ["72720.64000000", "0.77997000"], ["72720.29000000", "0.00012000"], ["72715.04000000", "0.22788000"], ["72713.49000000", "0.02728000"], ["72711.46000000", "0.00000000"], ["72708.52000000", "0.00000000"], ["72707.22000000", "0.00000000"], ["72693.82000000", "0.16099000"], ["72693.70000000", "0.00000000"], ["72690.76000000", "0.00427000"], ["72690.69000000", "0.00425000"], ["72686.90000000", "0.77241000"], ["72685.91000000", "1.04010000"], ["72684.57000000", "0.00000000"], ["72678.27000000", "0.00000000"], ["72669.88000000", "0.00000000"], ["72655.12000000", "0.00000000"], ["72633.14000000", "0.00000000"], ["72612.02000000", "0.00000000"], ["65471.40000000", "0.00000000"]], "a": [["72746.00000000", "0.00000000"], ["72746.01000000", "0.00000000"], ["72746.24000000", "0.00000000"], ["72746.51000000", "0.00000000"], ["72747.10000000", "0.20423000"], ["72747.11000000", "0.00086000"], ["72747.12000000", "0.00014000"], ["72747.37000000", "0.00008000"], ["72747.52000000", "0.00000000"], ["72747.55000000", "0.00000000"], ["72748.00000000", "0.02296000"], ["72748.10000000", "0.00000000"], ["72749.04000000", "0.00000000"], ["72749.22000000", "0.00000000"], ["72749.95000000", "0.00000000"], ["72749.99000000", "0.00024000"], ["72750.10000000", "0.00589000"], ["72750.31000000", "0.01997000"], ["72750.54000000", "0.00000000"], ["72750.93000000", "0.00016000"], ["72751.07000000", "0.00016000"], ["72751.08000000", "0.16229000"], ["72751.99000000", "0.00016000"], ["72752.00000000", "0.02296000"], ["72752.34000000", "0.00008000"], ["72752.35000000", "0.16229000"], ["72753.61000000", "0.00000000"], ["72753.62000000", "0.16229000"], ["72753.78000000", "0.06000000"], ["72753.79000000", "0.25289000"], ["72753.97000000", "0.00031000"], ["72753.99000000", "0.00000000"], ["72754.25000000", "0.00000000"], ["72754.89000000", "0.16229000"], ["72755.00000000", "0.00000000"], ["72756.07000000", "0.00031000"], ["72756.15000000", "0.65949000"], ["72756.42000000", "0.01402000"], ["72757.02000000", "0.00000000"], ["72757.36000000", "0.05942000"], ["72758.02000000", "0.00740000"], ["72758.28000000", "0.16236000"], ["72759.46000000", "0.00000000"], ["72760.29000000", "0.00000000"], ["72762.16000000", "0.16229000"], ["72768.07000000", "0.00008000"], ["72769.46000000", "0.00000000"], ["72770.09000000", "0.00000000"], ["72771.20000000", "0.00000000"], ["72773.94000000", "0.00000000"], ["72775.34000000", "0.00200000"], ["72781.30000000", "0.00000000"], ["72783.53000000", "0.00200000"], ["72793.25000000", "1.03000000"], ["72794.16000000", "0.00000000"], ["72794.80000000", "1.03854000"], ["72802.70000000", "0.01156000"], ["72807.14000000", "0.38626000"], ["72808.24000000", "0.00110000"], ["72812.36000000", "0.00000000"], ["72817.85000000", "0.37442000"], ["72819.85000000", "0.00008000"], ["72847.51000000", "0.44999000"], ["72851.37000000", "0.00000000"], ["72851.97000000", "0.96018000"], ["72851.98000000", "2.43865000"], ["72853.28000000", "0.00000000"], ["72853.85000000", "0.00000000"], ["72869.53000000", "0.24267000"], ["72885.10000000", "0.00000000"], ["72892.59000000", "0.00008000"], ["72933.37000000", "0.00007000"], ["72945.35000000", "0.00000000"], ["73030.58000000", "0.00000000"], ["73038.09000000", "0.00008000"], ["73103.32000000", "0.27000000"], ["73110.84000000", "0.00008000"], ["73248.80000000", "0.00000000"], ["73256.33000000", "0.00008000"]], "_local_ts_utc": "2026-06-01T07:49:12.610499+00:00"}
{"e": "depthUpdate", "E": 1780300153814, "s": "BTCUSDT", "U": 94551809007, "u": 94551809190, "b": [["72747.09000000", "5.25214000"], ["72746.14000000", "0.06607000"], ["72746.01000000", "0.16236000"], ["72746.00000000", "0.43232000"], ["72745.99000000", "0.06886000"], ["72745.78000000", "0.04071000"], ["72745.60000000", "0.00000000"], ["72745.59000000", "0.00000000"], ["72745.58000000", "0.45341000"], ["72745.30000000", "0.00000000"], ["72745.14000000", "0.00762000"], ["72744.55000000", "0.16228000"], ["72744.31000000", "0.00000000"], ["72744.09000000", "0.00000000"], ["72744.01000000", "0.17424000"], ["72743.78000000", "0.01421000"], ["72743.28000000", "0.16228000"], ["72742.01000000", "0.16228000"], ["72741.79000000", "0.16236000"], ["72740.92000000", "0.01375000"], ["72739.47000000", "0.16228000"], ["72738.20000000", "0.16228000"], ["72738.03000000", "0.16228000"], ["72738.02000000", "0.65956000"], ["72736.69000000", "0.00000000"], ["72736.32000000", "0.00189000"], ["72736.02000000", "0.16393000"], ["72735.59000000", "0.01375000"], ["72734.57000000", "0.16228000"], ["72734.56000000", "0.00000000"], ["72734.35000000", "0.16228000"], ["72734.08000000", "0.00000000"], ["72734.02000000", "0.04000000"], ["72730.98000000", "0.00007000"], ["72725.54000000", "0.25007000"], ["72724.02000000", "0.65977000"], ["72721.92000000", "0.00000000"], ["72720.48000000", "0.24872000"], ["72718.99000000", "0.00000000"], ["72717.48000000", "0.00008000"], ["72712.60000000", "0.00007000"], ["72697.63000000", "0.01151000"], ["72687.53000000", "0.00687000"], ["72677.54000000", "0.00000000"], ["72676.38000000", "0.00000000"], ["72649.58000000", "0.00000000"], ["72641.76000000", "0.04439000"], ["72544.77000000", "0.00000000"], ["72542.64000000", "0.00000000"], ["65472.39000000", "0.00095000"]], "a": [["72747.10000000", "0.20394000"], ["72747.11000000", "0.00086000"], ["72750.10000000", "0.00589000"], ["72750.30000000", "0.00000000"], ["72750.31000000", "0.00016000"], ["72750.93000000", "0.00000000"], ["72751.07000000", "0.00000000"], ["72751.08000000", "0.00016000"], ["72751.99000000", "0.06024000"], ["72752.00000000", "0.02296000"], ["72752.01000000", "0.00016000"], ["72752.02000000", "0.01537000"], ["72752.34000000", "0.00008000"], ["72752.35000000", "0.16245000"], ["72753.62000000", "0.16245000"], ["72753.78000000", "0.00000000"], ["72753.79000000", "0.25273000"], ["72753.84000000", "0.00000000"], ["72753.97000000", "0.00000000"], ["72755.40000000", "0.00031000"], ["72757.24000000", "0.00008000"], ["72760.09000000", "0.00007000"], ["72760.43000000", "0.00000000"], ["72760.44000000", "0.00000000"], ["72760.70000000", "0.08251000"], ["72763.17000000", "0.04000000"], ["72766.15000000", "0.16228000"], ["72771.52000000", "0.58552000"], ["72774.55000000", "0.00000000"], ["72786.47000000", "0.00000000"], ["72796.47000000", "0.00014000"], ["72817.85000000", "0.37992000"], ["72860.02000000", "0.04266000"], ["72941.72000000", "0.00000000"], ["75431.90000000", "0.00007000"]], "_local_ts_utc": "2026-06-01T07:49:12.710372+00:00"}
{"e": "depthUpdate", "E": 1780300153914, "s": "BTCUSDT", "U": 94551809191, "u": 94551809286, "b": [["72747.09000000", "5.24814000"], ["72746.14000000", "0.06623000"], ["72746.01000000", "0.16252000"], ["72745.14000000", "0.00762000"], ["72744.01000000", "0.17408000"], ["72743.78000000", "0.01405000"], ["72736.32000000", "0.00000000"], ["72732.55000000", "0.00007000"], ["72717.99000000", "0.00686000"], ["72703.45000000", "0.00102000"], ["72703.44000000", "0.00685000"], ["72700.30000000", "0.00000000"], ["72697.04000000", "0.26000000"], ["72688.89000000", "0.00000000"], ["72687.53000000", "0.00000000"], ["72661.52000000", "0.06215000"], ["72660.25000000", "0.00000000"], ["72566.01000000", "0.00822000"], ["72528.57000000", "0.00000000"], ["65472.39000000", "0.00146000"]], "a": [["72747.10000000", "0.20350000"], ["72747.11000000", "0.00086000"], ["72750.10000000", "0.00589000"], ["72750.30000000", "0.00008000"], ["72750.31000000", "0.00000000"], ["72751.08000000", "0.00000000"], ["72751.98000000", "0.00000000"], ["72751.99000000", "0.00032000"], ["72752.00000000", "0.02296000"], ["72752.02000000", "0.01553000"], ["72752.34000000", "0.00000000"], ["72752.35000000", "0.00016000"], ["72753.44000000", "0.00008000"], ["72753.45000000", "0.16228000"], ["72753.61000000", "0.00008000"], ["72753.62000000", "0.16245000"], ["72754.05000000", "0.00031000"], ["72754.17000000", "0.00000000"], ["72755.05000000", "0.00031000"], ["72755.40000000", "0.00000000"], ["72756.07000000", "0.00000000"], ["72756.42000000", "0.00000000"], ["72756.85000000", "0.00031000"], ["72758.02000000", "0.00000000"], ["72758.29000000", "0.00000000"], ["72760.70000000", "0.00000000"], ["72761.66000000", "0.27000000"], ["72763.61000000", "0.16228000"], ["72775.34000000", "0.00000000"], ["72776.20000000", "0.00686000"], ["72834.56000000", "0.00008000"], ["82071.40000000", "0.00010000"]], "_local_ts_utc": "2026-06-01T07:49:12.810343+00:00"}
{"e": "depthUpdate", "E": 1780300154014, "s": "BTCUSDT", "U": 94551809287, "u": 94551809396, "b": [["72747.09000000", "5.35364000"], ["72746.15000000", "0.00016000"], ["72746.03000000", "0.84792000"], ["72746.02000000", "0.65965000"], ["72746.01000000", "0.00040000"], ["72746.00000000", "0.00024000"], ["72744.55000000", "0.00000000"], ["72739.81000000", "0.00300000"], ["72738.88000000", "0.01381000"], ["72736.73000000", "0.03407000"], ["72736.52000000", "0.00188000"], ["72734.86000000", "0.02000000"], ["72734.35000000", "0.00000000"], ["72732.53000000", "0.00300000"], ["72731.29000000", "0.00000000"], ["72727.06000000", "0.00000000"], ["72726.97000000", "0.65949000"], ["72726.71000000", "0.64293000"], ["72719.69000000", "0.00000000"], ["72715.04000000", "0.22801000"], ["72708.95000000", "0.00000000"], ["72703.48000000", "1.23002000"], ["72697.74000000", "0.00343000"], ["72664.57000000", "0.14646000"], ["72664.56000000", "0.00000000"], ["72625.02000000", "0.00137000"], ["72551.44000000", "0.00000000"], ["72520.21000000", "0.03433000"], ["71456.68000000", "0.00008000"], ["65472.39000000", "0.00180000"], ["65472.00000000", "0.00020000"], ["58197.68000000", "0.00034000"]], "a": [["72747.10000000", "0.20085000"], ["72748.82000000", "0.00000000"], ["72750.10000000", "0.00589000"], ["72751.99000000", "0.00016000"], ["72752.02000000", "0.01553000"], ["72752.18000000", "0.16228000"], ["72752.35000000", "0.00000000"], ["72753.45000000", "0.16244000"], ["72753.61000000", "0.00000000"], ["72753.62000000", "0.00016000"], ["72753.79000000", "0.00016000"], ["72753.90000000", "0.00031000"], ["72754.38000000", "0.00300000"], ["72754.72000000", "0.16228000"], ["72756.14000000", "0.65949000"], ["72756.15000000", "0.00000000"], ["72756.32000000", "0.00000000"], ["72756.45000000", "0.01399000"], ["72756.85000000", "0.00000000"], ["72757.26000000", "0.33691000"], ["72757.36000000", "0.00000000"], ["72758.07000000", "0.01200000"], ["72759.19000000", "0.65949000"], ["72759.20000000", "0.00000000"], ["72759.98000000", "0.54349000"], ["72761.66000000", "0.27300000"], ["72762.21000000", "0.00000000"], ["72763.78000000", "0.00000000"], ["72764.22000000", "0.59797000"], ["72764.23000000", "0.65949000"], ["72764.24000000", "0.00000000"], ["72766.32000000", "0.00000000"], ["72767.42000000", "0.16228000"], ["72772.24000000", "0.00000000"], ["72778.44000000", "0.00200000"], ["72790.90000000", "0.00400000"], ["72803.73000000", "0.00189000"], ["72805.53000000", "0.09400000"], ["72812.49000000", "0.65949000"], ["72877.28000000", "0.00075000"], ["74936.47000000", "0.00000000"]], "_local_ts_utc": "2026-06-01T07:49:12.911728+00:00"}
{"e": "depthUpdate", "E": 1780300154114, "s": "BTCUSDT", "U": 94551809397, "u": 94551809524, "b": [["72747.09000000", "5.35551000"], ["72746.15000000", "0.00000000"], ["72746.14000000", "0.06623000"], ["72746.04000000", "0.00000000"], ["72746.03000000", "0.84792000"], ["72746.02000000", "0.65965000"], ["72746.01000000", "0.00008000"], ["72746.00000000", "0.00000000"], ["72745.59000000", "0.00000000"], ["72745.14000000", "0.00762000"], ["72736.52000000", "0.00000000"], ["72735.81000000", "0.02000000"], ["72722.23000000", "0.00118000"], ["72716.00000000", "0.01000000"], ["72714.00000000", "0.02640000"], ["72651.35000000", "0.00000000"], ["72650.43000000", "0.04267000"], ["72648.89000000", "0.00000000"], ["72641.76000000", "0.00007000"], ["72551.44000000", "0.09869000"], ["71292.14000000", "0.00000000"], ["65472.39000000", "0.00214000"], ["65472.00000000", "0.00000000"]], "a": [["72747.10000000", "0.20207000"], ["72747.11000000", "0.00094000"], ["72748.22000000", "0.00000000"], ["72748.91000000", "0.00000000"], ["72749.93000000", "0.00000000"], ["72751.86000000", "0.00000000"], ["72751.99000000", "0.00024000"], ["72752.02000000", "0.01553000"], ["72752.17000000", "0.00016000"], ["72752.18000000", "0.16244000"], ["72753.30000000", "0.00000000"], ["72753.44000000", "0.00016000"], ["72753.45000000", "0.16244000"], ["72753.62000000", "0.00000000"], ["72753.79000000", "0.00000000"], ["72753.81000000", "0.00000000"], ["72753.84000000", "0.00000000"], ["72753.90000000", "0.00000000"], ["72753.99000000", "0.00008000"], ["72754.00000000", "0.02296000"], ["72754.05000000", "0.00000000"], ["72754.57000000", "0.00000000"], ["72754.70000000", "0.00008000"], ["72754.71000000", "0.34962000"], ["72754.96000000", "0.00000000"], ["72755.02000000", "0.00031000"], ["72756.13000000", "0.00008000"], ["72756.84000000", "0.05942000"], ["72756.86000000", "0.00000000"], ["72757.25000000", "0.00008000"], ["72757.70000000", "0.00000000"], ["72757.99000000", "0.00008000"], ["72758.28000000", "0.16228000"], ["72759.18000000", "0.00008000"], ["72759.51000000", "0.00008000"], ["72760.32000000", "0.14896000"], ["72761.01000000", "0.00000000"], ["72761.40000000", "0.00008000"], ["72762.15000000", "0.00008000"], ["72762.82000000", "0.00008000"], ["72764.21000000", "0.00008000"], ["72764.22000000", "0.59805000"], ["72764.85000000", "0.16243000"], ["72766.14000000", "0.00008000"], ["72767.19000000", "0.00008000"], ["72768.05000000", "0.00008000"], ["72768.07000000", "0.00000000"], ["72768.67000000", "0.00008000"], ["72768.69000000", "0.00000000"], ["72769.06000000", "0.00408000"], ["72770.09000000", "0.00008000"], ["72770.86000000", "0.00008000"], ["72771.21000000", "0.40478000"], ["72777.20000000", "0.00008000"], ["72787.26000000", "0.00400000"], ["72790.90000000", "0.00000000"], ["72792.12000000", "0.00008000"], ["72807.70000000", "0.06600000"], ["72860.02000000", "0.00000000"], ["72868.72000000", "0.04429000"], ["74069.23000000", "0.00038000"]], "_local_ts_utc": "2026-06-01T07:49:13.010358+00:00"}
{"e": "depthUpdate", "E": 1780300154214, "s": "BTCUSDT", "U": 94551809525, "u": 94551809550, "b": [["72747.09000000", "5.35151000"], ["72732.55000000", "0.00014000"], ["72714.36000000", "0.00102000"], ["72703.44000000", "0.00000000"], ["72649.28000000", "0.00000000"], ["72595.13000000", "0.00000000"], ["65472.39000000", "0.00248000"], ["58197.68000000", "0.00000000"]], "a": [["72751.99000000", "0.06044000"], ["72754.00000000", "0.02296000"], ["72754.90000000", "0.00000000"], ["72755.02000000", "0.00000000"], ["72759.50000000", "0.00000000"], ["72759.52000000", "0.00000000"], ["72759.98000000", "0.39432000"], ["72760.33000000", "0.00000000"], ["72762.17000000", "0.00000000"], ["72775.59000000", "0.50000000"], ["72838.24000000", "0.00008000"]], "_local_ts_utc": "2026-06-01T07:49:13.110090+00:00"}
{"e": "depthUpdate", "E": 1780300154314, "s": "BTCUSDT", "U": 94551809551, "u": 94551809792, "b": [["72747.09000000", "3.71192000"], ["72746.50000000", "0.00000000"], ["72746.15000000", "0.00000000"], ["72746.14000000", "0.00016000"], ["72746.04000000", "0.65949000"], ["72746.03000000", "0.00016000"], ["72746.02000000", "0.00016000"], ["72746.00000000", "0.00016000"], ["72745.99000000", "0.06940000"], ["72745.82000000", "0.16230000"], ["72745.79000000", "0.00008000"], ["72745.59000000", "0.00000000"], ["72745.10000000", "0.00000000"], ["72745.09000000", "0.03814000"], ["72744.55000000", "0.16230000"], ["72744.02000000", "0.00000000"], ["72743.28000000", "0.16230000"], ["72742.01000000", "0.16230000"], ["72741.79000000", "0.00008000"], ["72741.78000000", "0.00000000"], ["72741.57000000", "0.16230000"], ["72741.56000000", "0.39825000"], ["72740.97000000", "0.65956000"], ["72739.47000000", "0.16230000"], ["72738.20000000", "0.16230000"], ["72738.04000000", "0.65949000"], ["72738.03000000", "0.00000000"], ["72738.02000000", "0.00007000"], ["72736.93000000", "0.16230000"], ["72736.73000000", "0.00000000"], ["72734.57000000", "0.00000000"], ["72734.39000000", "0.16230000"], ["72734.36000000", "1.31558000"], ["72734.35000000", "3.40874000"], ["72734.34000000", "0.00008000"], ["72734.33000000", "0.00000000"], ["72733.33000000", "0.00000000"], ["72730.58000000", "0.16230000"], ["72730.45000000", "0.00000000"], ["72730.38000000", "0.00000000"], ["72730.02000000", "0.00000000"], ["72729.62000000", "0.02000000"], ["72729.35000000", "0.16230000"], ["72729.34000000", "0.37501000"], ["72729.33000000", "0.65949000"], ["72728.12000000", "0.16230000"], ["72727.96000000", "0.00000000"], ["72727.08000000", "0.16230000"], ["72727.07000000", "1.79653000"], ["72727.06000000", "2.74925000"], ["72727.05000000", "0.00008000"], ["72727.04000000", "0.00000000"], ["72726.97000000", "0.00000000"], ["72724.02000000", "0.00028000"], ["72721.91000000", "0.00000000"], ["72720.69000000", "0.66367000"], ["72720.58000000", "0.00000000"], ["72720.41000000", "0.00000000"], ["72718.24000000", "0.38164000"], ["72717.99000000", "0.01371000"], ["72714.68000000", "0.00000000"], ["72713.68000000", "0.00011000"], ["72712.51000000", "1.66469000"], ["72705.16000000", "0.00102000"], ["72700.49000000", "0.58604000"], ["72697.04000000", "0.00000000"], ["72696.79000000", "0.00010000"], ["72689.67000000", "0.00000000"], ["72682.23000000", "0.00010000"], ["72679.58000000", "0.00000000"], ["72678.01000000", "0.41410000"], ["72672.39000000", "1.88217000"], ["72670.18000000", "4.13342000"], ["72668.62000000", "0.00000000"], ["72667.40000000", "0.10821000"], ["72661.52000000", "0.00000000"], ["72660.01000000", "0.05332000"], ["72656.00000000", "0.76270000"], ["72655.32000000", "0.00000000"], ["72650.61000000", "0.00000000"], ["72647.01000000", "0.00000000"], ["72646.88000000", "0.05423000"], ["72626.61000000", "0.00000000"], ["72624.80000000", "0.00000000"], ["72576.41000000", "0.00821000"], ["72566.01000000", "0.00000000"], ["65472.39000000", "0.00282000"]], "a": [["72747.10000000", "0.19859000"], ["72747.11000000", "0.00102000"], ["72747.37000000", "0.00000000"], ["72747.81000000", "0.00000000"], ["72748.11000000", "0.00008000"], ["72748.35000000", "0.00023000"], ["72748.36000000", "0.00016000"], ["72748.37000000", "0.00000000"], ["72749.63000000", "0.00016000"], ["72749.64000000", "0.00000000"], ["72750.10000000", "0.00589000"], ["72750.90000000", "0.00000000"], ["72750.91000000", "0.00000000"], ["72751.48000000", "0.00031000"], ["72751.53000000", "0.00000000"], ["72751.90000000", "0.03076000"], ["72751.98000000", "0.00000000"], ["72751.99000000", "0.00024000"], ["72752.01000000", "0.00000000"], ["72752.02000000", "0.00016000"], ["72752.16000000", "0.00000000"], ["72752.17000000", "0.00008000"], ["72752.18000000", "0.00016000"], ["72753.44000000", "0.00008000"], ["72753.88000000", "0.00000000"], ["72754.00000000", "0.02280000"], ["72754.38000000", "0.00300000"], ["72754.54000000", "0.02000000"], ["72754.61000000", "0.00031000"], ["72756.84000000", "0.00000000"], ["72758.14000000", "0.00454000"], ["72764.22000000", "0.54966000"], ["72769.92000000", "0.00000000"], ["72770.86000000", "0.00008000"], ["72773.77000000", "0.00000000"], ["72774.55000000", "0.00000000"], ["72785.91000000", "0.73253000"], ["72785.92000000", "1.36186000"], ["72785.97000000", "0.00000000"], ["72790.75000000", "0.00685000"], ["72803.73000000", "0.00000000"], ["72829.57000000", "0.79845000"], ["72839.64000000", "0.12980000"], ["72877.28000000", "0.00000000"], ["72983.95000000", "0.00000000"]], "_local_ts_utc": "2026-06-01T07:49:13.210390+00:00"}
{"e": "depthUpdate", "E": 1780300154414, "s": "BTCUSDT", "U": 94551809793, "u": 94551810016, "b": [["72747.09000000", "3.70993000"], ["72746.36000000", "0.05942000"], ["72746.29000000", "0.05762000"], ["72746.14000000", "0.00000000"], ["72746.06000000", "0.75006000"], ["72746.05000000", "0.65949000"], ["72746.04000000", "0.00016000"], ["72746.03000000", "0.00000000"], ["72746.02000000", "0.00000000"], ["72746.00000000", "0.00000000"], ["72745.99000000", "0.06940000"], ["72745.82000000", "0.16246000"], ["72745.79000000", "0.00000000"], ["72745.14000000", "0.00762000"], ["72745.09000000", "0.00016000"], ["72740.01000000", "0.00000000"], ["72737.61000000", "0.03407000"], ["72736.52000000", "0.02000000"], ["72736.17000000", "0.00000000"], ["72736.03000000", "0.40856000"], ["72736.01000000", "0.00000000"], ["72732.26000000", "0.00349000"], ["72732.00000000", "0.01000000"], ["72731.85000000", "0.16112000"], ["72730.00000000", "0.01000000"], ["72728.13000000", "0.40856000"], ["72728.11000000", "0.00000000"], ["72728.00000000", "0.01280000"], ["72727.84000000", "0.00008000"], ["72726.00000000", "0.01280000"], ["72724.00000000", "0.01280000"], ["72722.00000000", "0.01280000"], ["72721.11000000", "0.00011000"], ["72720.00000000", "0.01288000"], ["72718.00000000", "0.01280000"], ["72716.00000000", "0.01200000"], ["72714.00000000", "0.02200000"], ["72696.53000000", "0.00687000"], ["72682.23000000", "0.00000000"], ["72673.88000000", "0.00000000"], ["72657.60000000", "0.32009000"], ["65472.39000000", "0.00316000"], ["58197.67000000", "0.00000000"], ["58172.00000000", "0.00000000"]], "a": [["72747.10000000", "0.19008000"], ["72747.11000000", "0.00094000"], ["72748.25000000", "0.00000000"], ["72748.35000000", "0.00007000"], ["72748.36000000", "0.00000000"], ["72749.63000000", "0.00000000"], ["72750.10000000", "0.00589000"], ["72751.48000000", "0.00000000"], ["72751.89000000", "0.00000000"], ["72751.90000000", "0.00032000"], ["72751.91000000", "0.01305000"], ["72751.99000000", "0.00024000"], ["72752.00000000", "0.02296000"], ["72752.02000000", "0.00000000"], ["72752.17000000", "0.00008000"], ["72752.18000000", "0.00000000"], ["72753.44000000", "0.00008000"], ["72753.45000000", "0.00016000"], ["72753.57000000", "0.00008000"], ["72753.58000000", "0.00000000"], ["72753.99000000", "0.00016000"], ["72754.00000000", "0.02296000"], ["72754.54000000", "0.00016000"], ["72754.61000000", "0.00000000"], ["72754.71000000", "0.20428000"], ["72754.72000000", "0.00000000"], ["72754.89000000", "0.00000000"], ["72755.05000000", "0.00000000"], ["72755.88000000", "0.00031000"], ["72756.05000000", "0.05942000"], ["72756.16000000", "0.00000000"], ["72756.45000000", "0.00000000"], ["72756.67000000", "0.00000000"], ["72756.81000000", "0.01378000"], ["72757.34000000", "0.02018000"], ["72758.07000000", "0.00458000"], ["72758.36000000", "0.00000000"], ["72758.50000000", "0.00742000"], ["72762.73000000", "0.00008000"], ["72764.37000000", "0.00000000"], ["72764.47000000", "0.00000000"], ["72765.17000000", "0.00000000"], ["72766.77000000", "0.00000000"], ["72768.18000000", "0.00000000"], ["72768.28000000", "0.00000000"], ["72770.98000000", "0.08000000"], ["72785.91000000", "0.32602000"], ["72785.92000000", "0.00000000"], ["72792.98000000", "0.07400000"], ["72803.73000000", "0.00189000"], ["72807.13000000", "0.00000000"], ["72807.14000000", "0.01734000"], ["72811.22000000", "0.07400000"], ["72817.85000000", "1.13428000"], ["72822.76000000", "0.00000000"], ["72844.81000000", "0.04138000"], ["72877.28000000", "0.00075000"], ["73037.94000000", "4.11261000"], ["73401.81000000", "0.00010000"]], "_local_ts_utc": "2026-06-01T07:49:13.310234+00:00"}
{"e": "depthUpdate", "E": 1780300154514, "s": "BTCUSDT", "U": 94551810017, "u": 94551810981, "b": [["72751.99000000", "2.92691000"], ["72751.98000000", "0.14505000"], ["72751.90000000", "1.26938000"], ["72751.89000000", "0.14850000"], ["72750.99000000", "0.30000000"], ["72750.63000000", "0.16229000"], ["72750.29000000", "0.00350000"], ["72750.15000000", "0.00000000"], ["72750.09000000", "1.23348000"], ["72750.00000000", "3.60885000"], ["72749.99000000", "1.05844000"], ["72749.98000000", "0.00022000"], ["72749.97000000", "0.00014000"], ["72749.93000000", "0.00008000"], ["72749.92000000", "0.65949000"], ["72749.91000000", "0.98108000"], ["72749.90000000", "0.00000000"], ["72749.17000000", "0.13745000"], ["72749.04000000", "0.00400000"], ["72749.03000000", "0.00773000"], ["72748.64000000", "0.00000000"], ["72748.35000000", "0.16256000"], ["72748.34000000", "2.20895000"], ["72748.33000000", "0.00000000"], ["72748.32000000", "0.00000000"], ["72748.17000000", "0.00000000"], ["72748.16000000", "0.00000000"], ["72748.10000000", "0.00000000"], ["72748.07000000", "0.00000000"], ["72747.99000000", "0.19318000"], ["72747.98000000", "0.11136000"], ["72747.22000000", "0.00400000"], ["72747.16000000", "0.00009000"], ["72747.11000000", "0.00530000"], ["72747.10000000", "0.45787000"], ["72747.09000000", "0.17212000"], ["72747.08000000", "0.00000000"], ["72747.07000000", "0.00000000"], ["72746.36000000", "0.00016000"], ["72746.29000000", "0.00016000"], ["72746.18000000", "0.14842000"], ["72746.06000000", "0.15161000"], ["72746.05000000", "0.65949000"], ["72746.04000000", "0.00000000"], ["72746.01000000", "0.00000000"], ["72745.99000000", "0.06856000"], ["72745.82000000", "0.00000000"], ["72745.78000000", "0.04055000"], ["72745.58000000", "0.45325000"], ["72745.14000000", "0.00746000"], ["72745.09000000", "0.00000000"], ["72744.55000000", "0.00000000"], ["72744.01000000", "0.00000000"], ["72743.64000000", "0.16229000"], ["72743.28000000", "0.00000000"], ["72742.37000000", "0.16229000"], ["72742.01000000", "0.00000000"], ["72741.79000000", "0.00000000"], ["72741.68000000", "0.00011000"], ["72741.57000000", "0.16229000"], ["72740.98000000", "0.00008000"], ["72740.83000000", "0.00007000"], ["72739.91000000", "0.00000000"], ["72739.83000000", "0.16229000"], ["72739.75000000", "0.00000000"], ["72739.47000000", "0.00000000"], ["72738.56000000", "0.16229000"], ["72738.20000000", "0.00000000"], ["72738.05000000", "0.00000000"], ["72737.34000000", "0.12000000"], ["72737.09000000", "0.00000000"], ["72736.93000000", "0.02000000"], ["72736.66000000", "0.16229000"], ["72736.04000000", "0.16229000"], ["72736.02000000", "0.00165000"], ["72736.00000000", "0.00008000"], ["72735.99000000", "0.89735000"], ["72735.59000000", "0.00000000"], ["72735.45000000", "0.00000000"], ["72735.01000000", "0.02000000"], ["72734.67000000", "0.00000000"], ["72734.39000000", "0.00000000"], ["72734.37000000", "0.16229000"], ["72734.36000000", "1.15336000"], ["72734.34000000", "0.00000000"], ["72734.25000000", "0.32402000"], ["72732.81000000", "0.00000000"], ["72732.80000000", "0.00008000"], ["72731.85000000", "0.00000000"], ["72731.53000000", "0.00008000"], ["72730.94000000", "0.16229000"], ["72730.58000000", "0.00000000"], ["72730.39000000", "0.00000000"], ["72729.67000000", "0.15467000"], ["72729.62000000", "0.00000000"], ["72729.35000000", "0.16237000"], ["72728.72000000", "0.00011000"], ["72728.67000000", "0.00000000"], ["72728.17000000", "0.00137000"], ["72728.12000000", "0.00000000"], ["72727.13000000", "0.16229000"], ["72727.08000000", "0.00000000"], ["72727.07000000", "1.79661000"], ["72727.05000000", "0.00000000"], ["72725.99000000", "0.00000000"], ["72725.54000000", "0.25000000"], ["72725.53000000", "0.89511000"], ["72724.77000000", "0.00000000"], ["72724.59000000", "0.22684000"], ["72724.02000000", "0.00020000"], ["72724.01000000", "0.42162000"], ["72722.86000000", "0.00008000"], ["72722.85000000", "0.49565000"], ["72721.84000000", "0.00000000"], ["72721.11000000", "0.00000000"], ["72720.81000000", "0.00000000"], ["72720.64000000", "0.71772000"], ["72720.48000000", "0.24864000"], ["72720.47000000", "0.54840000"], ["72719.92000000", "0.00000000"], ["72719.26000000", "0.00000000"], ["72718.29000000", "1.36312000"], ["72718.10000000", "0.00000000"], ["72717.99000000", "0.00000000"], ["72717.48000000", "0.00000000"], ["72716.00000000", "0.01280000"], ["72715.04000000", "0.04110000"], ["72714.00000000", "0.02280000"], ["72712.43000000", "0.00102000"], ["72711.45000000", "0.00000000"], ["72695.81000000", "0.00000000"], ["72690.71000000", "0.03300000"], ["72677.16000000", "0.00008000"], ["72674.68000000", "0.00109000"], ["72672.39000000", "0.64215000"], ["72670.18000000", "0.00000000"], ["72668.79000000", "0.00000000"], ["72658.70000000", "0.00000000"], ["72657.60000000", "0.30634000"], ["72647.14000000", "0.00000000"], ["72636.88000000", "0.00030000"], ["72618.20000000", "0.00000000"], ["72614.28000000", "0.00028000"], ["72604.41000000", "0.00008000"], ["72596.05000000", "0.00000000"], ["72531.66000000", "0.00008000"], ["72523.31000000", "0.00000000"], ["72475.56000000", "0.00011000"], ["72458.91000000", "0.00008000"], ["72450.56000000", "0.00000000"], ["72387.26000000", "0.00000000"], ["72386.16000000", "0.00008000"], ["72377.82000000", "0.00000000"], ["72356.31000000", "0.37755000"], ["72315.64000000", "0.00000000"], ["72313.41000000", "0.00008000"], ["72305.08000000", "0.00000000"], ["72240.66000000", "0.00008000"], ["72232.34000000", "0.00000000"], ["72167.91000000", "0.00008000"], ["72159.60000000", "0.00000000"], ["71662.50000000", "0.00042000"], ["71294.99000000", "0.00000000"], ["65475.00000000", "0.00089000"], ["65472.39000000", "0.00078000"], ["58200.00000000", "7.89422000"]], "a": [["72747.10000000", "0.00000000"], ["72747.11000000", "0.00000000"], ["72747.12000000", "0.00000000"], ["72747.99000000", "0.00000000"], ["72748.00000000", "0.00000000"], ["72748.08000000", "0.00000000"], ["72748.11000000", "0.00000000"], ["72748.35000000", "0.00000000"], ["72749.92000000", "0.00000000"], ["72749.99000000", "0.00000000"], ["72750.00000000", "0.00000000"], ["72750.01000000", "0.00000000"], ["72750.10000000", "0.00000000"], ["72750.30000000", "0.00000000"], ["72751.00000000", "0.00000000"], ["72751.90000000", "0.00000000"], ["72751.91000000", "0.00000000"], ["72751.99000000", "0.00000000"], ["72752.00000000", "0.02144000"], ["72752.04000000", "0.00000000"], ["72753.04000000", "0.00000000"], ["72753.16000000", "0.00000000"], ["72753.45000000", "0.00000000"], ["72753.57000000", "0.00000000"], ["72753.99000000", "0.00024000"], ["72754.00000000", "0.02296000"], ["72754.54000000", "0.00000000"], ["72754.67000000", "0.00000000"], ["72754.70000000", "0.00008000"], ["72754.71000000", "0.00016000"], ["72755.14000000", "0.00540000"], ["72755.21000000", "0.00000000"], ["72755.88000000", "0.00000000"], ["72755.99000000", "0.00016000"], ["72756.00000000", "0.02296000"], ["72756.05000000", "0.00016000"], ["72756.08000000", "0.00000000"], ["72756.09000000", "0.00016000"], ["72756.10000000", "0.00000000"], ["72756.14000000", "0.00016000"], ["72756.81000000", "0.00000000"], ["72757.25000000", "0.00016000"], ["72757.26000000", "0.00000000"], ["72757.34000000", "0.02018000"], ["72757.48000000", "0.00026000"], ["72758.14000000", "0.00054000"], ["72758.28000000", "0.00000000"], ["72758.44000000", "0.00000000"], ["72758.50000000", "0.00000000"], ["72758.67000000", "0.00000000"], ["72758.70000000", "0.00000000"], ["72759.05000000", "0.00000000"], ["72759.31000000", "0.05942000"], ["72759.80000000", "0.00000000"], ["72759.98000000", "0.20284000"], ["72760.32000000", "0.00008000"], ["72761.58000000", "0.00031000"], ["72761.66000000", "0.00300000"], ["72762.16000000", "0.00000000"], ["72763.02000000", "0.00164000"], ["72763.61000000", "0.00000000"], ["72763.97000000", "0.16229000"], ["72764.21000000", "0.00008000"], ["72764.22000000", "0.39782000"], ["72764.25000000", "0.00000000"], ["72764.85000000", "0.00008000"], ["72764.86000000", "0.00000000"], ["72766.15000000", "0.00000000"], ["72766.51000000", "0.16229000"], ["72767.59000000", "0.00000000"], ["72768.05000000", "0.16237000"], ["72768.06000000", "0.54522000"], ["72768.38000000", "0.00000000"], ["72768.68000000", "0.00000000"], ["72768.78000000", "0.00000000"], ["72770.87000000", "0.00000000"], ["72770.98000000", "0.14000000"], ["72771.20000000", "0.16229000"], ["72771.21000000", "0.59875000"], ["72771.48000000", "0.01000000"], ["72771.82000000", "0.00137000"], ["72773.36000000", "0.68808000"], ["72774.55000000", "0.14676000"], ["72776.20000000", "0.00000000"], ["72777.99000000", "0.00000000"], ["72779.02000000", "0.00000000"], ["72781.93000000", "0.00000000"], ["72784.68000000", "0.00000000"], ["72785.25000000", "0.00007000"], ["72789.71000000", "0.00343000"], ["72789.72000000", "0.00000000"], ["72790.75000000", "0.00000000"], ["72792.72000000", "0.00400000"], ["72797.16000000", "0.00020000"], ["72797.22000000", "0.00000000"], ["72797.99000000", "0.18525000"], ["72798.92000000", "0.49513000"], ["72803.73000000", "0.00000000"], ["72805.27000000", "0.00189000"], ["72805.28000000", "0.00000000"], ["72805.80000000", "0.00000000"], ["72812.58000000", "0.00000000"], ["72812.60000000", "0.04600000"], ["72813.24000000", "0.00343000"], ["72815.93000000", "0.00000000"], ["72821.99000000", "0.01758000"], ["72822.75000000", "0.00000000"], ["72855.04000000", "0.00008000"], ["72865.34000000", "0.04678000"], ["72868.72000000", "0.00000000"], ["72877.28000000", "0.00000000"], ["72877.64000000", "0.00075000"], ["72909.71000000", "0.27000000"], ["72942.49000000", "0.00014000"], ["72946.12000000", "0.00007000"], ["73038.66000000", "0.00137000"], ["73369.28000000", "0.00000000"]], "_local_ts_utc": "2026-06-01T07:49:13.410398+00:00"}
{"e": "depthUpdate", "E": 1780300154620, "s": "BTCUSDT", "U": 94551810982, "u": 94551813606, "b": [["72761.99000000", "5.16004000"], ["72761.98000000", "0.14131000"], ["72761.65000000", "0.00000000"], ["72761.40000000", "0.04337000"], ["72761.39000000", "0.72502000"], ["72761.29000000", "0.00000000"], ["72761.26000000", "0.00000000"], ["72760.96000000", "3.07978000"], ["72760.95000000", "2.00070000"], ["72760.94000000", "0.00008000"], ["72760.57000000", "0.00020000"], ["72760.56000000", "0.42708000"], ["72760.35000000", "0.00000000"], ["72760.32000000", "0.00000000"], ["72760.31000000", "0.15040000"], ["72760.30000000", "0.00008000"], ["72760.29000000", "0.00000000"], ["72760.14000000", "0.00000000"], ["72760.13000000", "0.00016000"], ["72760.12000000", "0.00000000"], ["72760.01000000", "0.00000000"], ["72760.00000000", "0.00024000"], ["72759.99000000", "0.13606000"], ["72759.97000000", "0.00008000"], ["72759.96000000", "0.00000000"], ["72759.88000000", "0.00000000"], ["72759.69000000", "0.00000000"], ["72759.42000000", "0.00007000"], ["72759.41000000", "0.00000000"], ["72759.38000000", "0.00000000"], ["72759.31000000", "2.41827000"], ["72759.30000000", "0.00016000"], ["72759.28000000", "0.00000000"], ["72759.18000000", "0.00107000"], ["72759.17000000", "0.01537000"], ["72758.43000000", "0.16091000"], ["72758.41000000", "0.00000000"], ["72758.13000000", "0.11120000"], ["72758.10000000", "0.00000000"], ["72758.07000000", "0.16091000"], ["72758.06000000", "0.23157000"], ["72758.05000000", "0.00000000"], ["72758.01000000", "0.01376000"], ["72758.00000000", "0.00530000"], ["72757.99000000", "0.05223000"], ["72757.98000000", "0.00000000"], ["72757.97000000", "0.00000000"], ["72757.82000000", "0.00000000"], ["72757.81000000", "0.66867000"], ["72757.80000000", "0.00000000"], ["72757.79000000", "0.00000000"], ["72757.48000000", "0.17113000"], ["72757.47000000", "0.26315000"], ["72757.46000000", "0.00000000"], ["72757.40000000", "0.00000000"], ["72757.34000000", "0.00000000"], ["72757.33000000", "0.25795000"], ["72757.32000000", "0.00000000"], ["72757.27000000", "0.00000000"], ["72757.25000000", "0.00000000"], ["72757.24000000", "0.61950000"], ["72757.23000000", "0.00000000"], ["72757.09000000", "0.13744000"], ["72756.67000000", "0.00000000"], ["72756.54000000", "0.00000000"], ["72756.37000000", "0.00000000"], ["72756.13000000", "0.00000000"], ["72756.12000000", "0.00000000"], ["72756.08000000", "0.00000000"], ["72756.04000000", "0.00000000"], ["72756.01000000", "1.69858000"], ["72756.00000000", "0.65949000"], ["72755.99000000", "0.12550000"], ["72755.98000000", "0.00766000"], ["72755.97000000", "0.00000000"], ["72755.87000000", "0.00028000"], ["72755.73000000", "0.00007000"], ["72755.72000000", "0.00000000"], ["72755.71000000", "0.00000000"], ["72755.37000000", "0.00000000"], ["72755.15000000", "0.00000000"], ["72755.14000000", "0.00000000"], ["72755.13000000", "0.38128000"], ["72755.12000000", "0.00008000"], ["72755.11000000", "0.00000000"], ["72754.93000000", "0.00000000"], ["72754.84000000", "0.14000000"], ["72754.70000000", "0.00000000"], ["72754.69000000", "0.00000000"], ["72754.67000000", "0.00000000"], ["72754.55000000", "0.00009000"], ["72754.54000000", "0.01000000"], ["72754.37000000", "0.00000000"], ["72754.23000000", "0.00000000"], ["72753.99000000", "0.00000000"], ["72753.98000000", "0.00008000"], ["72753.97000000", "0.00000000"], ["72753.94000000", "0.00000000"], ["72753.65000000", "0.00000000"], ["72753.64000000", "0.04120000"], ["72753.59000000", "0.00000000"], ["72753.43000000", "0.00000000"], ["72753.27000000", "0.00000000"], ["72753.26000000", "0.00000000"], ["72752.63000000", "0.00000000"], ["72752.46000000", "0.00000000"], ["72752.34000000", "0.00743000"], ["72752.26000000", "0.00028000"], ["72752.25000000", "0.00000000"], ["72752.18000000", "0.00000000"], ["72752.16000000", "0.00000000"], ["72752.04000000", "0.00007000"], ["72752.01000000", "0.00000000"], ["72752.00000000", "3.59901000"], ["72751.99000000", "0.30859000"], ["72751.98000000", "0.00000000"], ["72751.97000000", "0.00000000"], ["72751.91000000", "0.00000000"], ["72751.90000000", "0.00000000"], ["72751.89000000", "0.00000000"], ["72751.01000000", "0.00008000"], ["72751.00000000", "0.00000000"], ["72750.99000000", "0.00000000"], ["72750.95000000", "0.00000000"], ["72750.86000000", "0.01160000"], ["72750.63000000", "0.00000000"], ["72750.56000000", "0.00000000"], ["72750.44000000", "0.00000000"], ["72750.37000000", "0.00000000"], ["72750.29000000", "0.00000000"], ["72750.19000000", "0.00000000"], ["72750.13000000", "0.03407000"], ["72750.10000000", "0.00000000"], ["72750.09000000", "0.00000000"], ["72750.02000000", "0.00000000"], ["72750.01000000", "0.65949000"], ["72750.00000000", "0.00000000"], ["72749.99000000", "0.23259000"], ["72749.98000000", "0.00000000"], ["72749.97000000", "0.00000000"], ["72749.93000000", "0.00000000"], ["72749.92000000", "0.00000000"], ["72749.91000000", "0.98092000"], ["72749.17000000", "0.00000000"], ["72749.06000000", "0.00011000"], ["72748.36000000", "0.00000000"], ["72748.35000000", "0.83548000"], ["72748.34000000", "2.22287000"], ["72748.25000000", "0.00007000"], ["72748.01000000", "0.00028000"], ["72747.99000000", "0.00000000"], ["72747.98000000", "0.00000000"], ["72747.87000000", "0.00000000"], ["72747.81000000", "0.00000000"], ["72747.47000000", "0.00000000"], ["72747.11000000", "0.00000000"], ["72747.10000000", "0.00000000"], ["72747.09000000", "0.11259000"], ["72746.56000000", "0.00000000"], ["72746.36000000", "0.00000000"], ["72746.29000000", "0.00000000"], ["72746.18000000", "0.00000000"], ["72746.06000000", "0.00000000"], ["72745.99000000", "0.00054000"], ["72745.94000000", "0.00165000"], ["72745.78000000", "0.00000000"], ["72745.58000000", "0.09871000"], ["72744.84000000", "0.02000000"], ["72744.82000000", "0.00028000"], ["72744.56000000", "0.00007000"], ["72744.44000000", "0.00000000"], ["72744.28000000", "0.00000000"], ["72744.22000000", "0.00189000"], ["72744.09000000", "0.00000000"], ["72744.02000000", "0.00000000"], ["72743.98000000", "0.00000000"], ["72743.65000000", "0.93423000"], ["72743.64000000", "0.00000000"], ["72743.34000000", "0.40856000"], ["72742.98000000", "0.00000000"], ["72742.75000000", "0.00000000"], ["72742.55000000", "0.00000000"], ["72742.37000000", "0.00000000"], ["72741.99000000", "0.00000000"], ["72741.94000000", "2.74925000"], ["72741.90000000", "0.00420000"], ["72741.83000000", "0.00000000"], ["72741.57000000", "0.00000000"], ["72741.56000000", "0.22389000"], ["72741.53000000", "0.00000000"], ["72741.30000000", "0.00000000"], ["72741.25000000", "0.09000000"], ["72740.98000000", "0.00008000"], ["72740.96000000", "0.00000000"], ["72740.92000000", "0.00000000"], ["72740.66000000", "0.49553000"], ["72740.08000000", "0.00000000"], ["72740.03000000", "0.00000000"], ["72739.99000000", "0.00000000"], ["72739.88000000", "0.00000000"], ["72739.83000000", "0.00000000"], ["72739.63000000", "0.00573000"], ["72739.56000000", "0.00349000"], ["72739.29000000", "0.00000000"], ["72738.76000000", "0.00000000"], ["72738.56000000", "0.00000000"], ["72738.18000000", "0.00000000"], ["72738.12000000", "0.00600000"], ["72738.05000000", "0.62202000"], ["72738.01000000", "0.00000000"], ["72737.34000000", "0.00000000"], ["72737.09000000", "0.00000000"], ["72736.93000000", "0.00000000"], ["72736.75000000", "0.00000000"], ["72736.66000000", "0.00000000"], ["72736.40000000", "0.00000000"], ["72736.22000000", "0.00000000"], ["72736.04000000", "0.00000000"], ["72736.02000000", "0.00000000"], ["72736.00000000", "0.00000000"], ["72735.99000000", "0.38081000"], ["72735.98000000", "0.22985000"], ["72735.92000000", "0.00000000"], ["72734.54000000", "0.00000000"], ["72734.40000000", "1.36282000"], ["72734.37000000", "0.00000000"], ["72734.25000000", "0.22395000"], ["72733.09000000", "0.00000000"], ["72732.59000000", "0.00000000"], ["72731.53000000", "0.00000000"], ["72731.32000000", "0.00000000"], ["72730.98000000", "0.00000000"], ["72730.94000000", "0.00000000"], ["72730.32000000", "0.86269000"], ["72730.31000000", "0.96885000"], ["72730.22000000", "0.00007000"], ["72730.05000000", "0.00000000"], ["72729.87000000", "0.00000000"], ["72729.85000000", "0.00000000"], ["72729.67000000", "0.00000000"], ["72729.63000000", "0.00000000"], ["72729.35000000", "0.00000000"], ["72729.34000000", "0.00008000"], ["72729.02000000", "0.49961000"], ["72728.18000000", "0.00137000"], ["72728.14000000", "0.00000000"], ["72728.01000000", "0.00412000"], ["72727.75000000", "0.00007000"], ["72727.51000000", "0.00000000"], ["72727.20000000", "0.00000000"], ["72727.13000000", "0.00000000"], ["72727.08000000", "0.00000000"], ["72726.20000000", "0.22007000"], ["72726.10000000", "1.36298000"], ["72725.66000000", "0.00189000"], ["72725.53000000", "0.71238000"], ["72725.38000000", "0.00000000"], ["72724.59000000", "0.08000000"], ["72724.01000000", "0.12000000"], ["72723.83000000", "0.00000000"], ["72723.69000000", "0.00686000"], ["72723.56000000", "0.00000000"], ["72722.86000000", "0.55689000"], ["72722.84000000", "0.00000000"], ["72722.52000000", "0.00000000"], ["72722.32000000", "0.00000000"], ["72721.74000000", "0.00000000"], ["72721.37000000", "0.00000000"], ["72720.69000000", "0.00000000"], ["72720.65000000", "0.00008000"], ["72720.64000000", "0.65949000"], ["72720.48000000", "0.00007000"], ["72720.47000000", "0.00000000"], ["72719.99000000", "0.00007000"], ["72718.92000000", "0.02000000"], ["72718.83000000", "0.00000000"], ["72718.72000000", "0.02657000"], ["72718.24000000", "0.00000000"], ["72718.11000000", "0.00000000"], ["72717.81000000", "0.00000000"], ["72717.48000000", "0.00412000"], ["72715.14000000", "0.00000000"], ["72715.05000000", "0.00000000"], ["72713.49000000", "0.00000000"], ["72713.20000000", "0.19770000"], ["72711.92000000", "0.00000000"], ["72711.35000000", "0.00000000"], ["72710.43000000", "0.00000000"], ["72708.31000000", "0.22498000"], ["72707.83000000", "0.00000000"], ["72706.36000000", "0.00000000"], ["72704.91000000", "0.94295000"], ["72704.08000000", "0.40864000"], ["72700.49000000", "0.43763000"], ["72699.37000000", "0.00000000"], ["72698.57000000", "0.00000000"], ["72694.72000000", "0.00008000"], ["72687.49000000", "0.00000000"], ["72686.90000000", "0.50596000"], ["72685.91000000", "0.00000000"], ["72684.71000000", "0.00008000"], ["72683.41000000", "0.00000000"], ["72682.11000000", "1.40970000"], ["72682.09000000", "0.00000000"], ["72680.10000000", "0.00000000"], ["72677.70000000", "0.00000000"], ["72677.16000000", "0.00000000"], ["72675.98000000", "0.00000000"], ["72675.74000000", "0.00282000"], ["72669.28000000", "0.00000000"], ["72667.70000000", "0.00239000"], ["72664.35000000", "0.00000000"], ["72663.93000000", "0.00000000"], ["72656.83000000", "0.00000000"], ["72656.00000000", "0.02486000"], ["72652.49000000", "0.00000000"], ["72635.29000000", "0.00000000"], ["72634.90000000", "0.00000000"], ["72623.18000000", "0.00000000"], ["72618.05000000", "2.84261000"], ["72611.96000000", "0.00008000"], ["72604.41000000", "0.00000000"], ["72602.61000000", "0.00121000"], ["72591.94000000", "1.20000000"], ["72590.31000000", "0.20374000"], ["72586.16000000", "0.00000000"], ["72574.24000000", "0.00000000"], ["72571.72000000", "0.00000000"], ["72555.96000000", "0.00000000"], ["72547.32000000", "0.00000000"], ["72539.20000000", "0.00008000"], ["72531.66000000", "0.00000000"], ["72524.75000000", "0.28077000"], ["72488.61000000", "0.00000000"], ["72466.44000000", "0.00008000"], ["72465.09000000", "0.00000000"], ["72458.91000000", "0.00000000"], ["72456.52000000", "0.00000000"], ["72446.73000000", "0.00000000"], ["72393.68000000", "0.00138000"], ["72386.16000000", "0.00000000"], ["72353.42000000", "0.00100000"], ["72320.93000000", "0.00008000"], ["72313.41000000", "0.00000000"], ["72248.17000000", "0.00008000"], ["72240.66000000", "0.00000000"], ["72175.41000000", "0.00008000"], ["72167.91000000", "0.00000000"], ["72136.57000000", "0.57874000"], ["72073.35000000", "0.00000000"], ["71909.86000000", "1.08687000"], ["71885.46000000", "0.00000000"], ["71682.49000000", "1.91551000"], ["71674.03000000", "0.00000000"], ["71302.83000000", "0.00000000"], ["71302.32000000", "0.00000000"], ["71296.95000000", "0.00000000"], ["65484.32000000", "0.00000000"], ["65478.59000000", "0.00000000"], ["58200.00000000", "7.89388000"]], "a": [["72752.00000000", "0.00000000"], ["72752.01000000", "0.00000000"], ["72752.17000000", "0.00000000"], ["72752.26000000", "0.00000000"], ["72752.47000000", "0.00000000"], ["72753.27000000", "0.00000000"], ["72753.44000000", "0.00000000"], ["72753.60000000", "0.00000000"], ["72753.99000000", "0.00000000"], ["72754.00000000", "0.00000000"], ["72754.38000000", "0.00000000"], ["72754.68000000", "0.00000000"], ["72754.70000000", "0.00000000"], ["72754.71000000", "0.00000000"], ["72754.94000000", "0.00000000"], ["72755.14000000", "0.00000000"], ["72755.15000000", "0.00000000"], ["72755.72000000", "0.00000000"], ["72755.73000000", "0.00000000"], ["72755.99000000", "0.00000000"], ["72756.00000000", "0.00000000"], ["72756.01000000", "0.00000000"], ["72756.05000000", "0.00000000"], ["72756.09000000", "0.00000000"], ["72756.13000000", "0.00000000"], ["72756.14000000", "0.00000000"], ["72756.81000000", "0.00000000"], ["72757.24000000", "0.00000000"], ["72757.25000000", "0.00000000"], ["72757.28000000", "0.00000000"], ["72757.33000000", "0.00000000"], ["72757.34000000", "0.00000000"], ["72757.41000000", "0.00000000"], ["72757.48000000", "0.00000000"], ["72757.82000000", "0.00000000"], ["72757.83000000", "0.00000000"], ["72757.99000000", "0.00000000"], ["72758.00000000", "0.00000000"], ["72758.01000000", "0.00000000"], ["72758.07000000", "0.00000000"], ["72758.14000000", "0.00000000"], ["72759.17000000", "0.00000000"], ["72759.18000000", "0.00000000"], ["72759.19000000", "0.00000000"], ["72759.29000000", "0.00000000"], ["72759.30000000", "0.00000000"], ["72759.31000000", "0.00000000"], ["72759.42000000", "0.00000000"], ["72759.51000000", "0.00000000"], ["72759.70000000", "0.00000000"], ["72759.78000000", "0.00000000"], ["72759.89000000", "0.00000000"], ["72759.96000000", "0.00000000"], ["72759.97000000", "0.00000000"], ["72759.98000000", "0.00000000"], ["72759.99000000", "0.00000000"], ["72760.00000000", "0.00000000"], ["72760.01000000", "0.00000000"], ["72760.09000000", "0.00000000"], ["72760.14000000", "0.00000000"], ["72760.32000000", "0.00000000"], ["72760.45000000", "0.00000000"], ["72760.57000000", "0.00000000"], ["72760.96000000", "0.00000000"], ["72760.97000000", "0.00000000"], ["72761.25000000", "0.00000000"], ["72761.27000000", "0.00000000"], ["72761.30000000", "0.00000000"], ["72761.40000000", "0.00000000"], ["72761.41000000", "0.00000000"], ["72761.58000000", "0.00000000"], ["72761.61000000", "0.00000000"], ["72761.66000000", "0.00000000"], ["72761.77000000", "0.00000000"], ["72761.78000000", "0.00000000"], ["72761.94000000", "0.00000000"], ["72761.98000000", "0.00000000"], ["72761.99000000", "0.00000000"], ["72762.00000000", "0.02319000"], ["72762.04000000", "0.00000000"], ["72762.21000000", "0.00000000"], ["72762.37000000", "0.00000000"], ["72762.64000000", "0.00000000"], ["72762.82000000", "0.00024000"], ["72763.02000000", "0.00000000"], ["72763.15000000", "0.00000000"], ["72763.16000000", "0.00016000"], ["72763.60000000", "0.00000000"], ["72763.97000000", "0.00000000"], ["72763.99000000", "0.00016000"], ["72764.22000000", "0.00008000"], ["72764.23000000", "0.00000000"], ["72764.28000000", "0.00000000"], ["72764.52000000", "0.00000000"], ["72764.91000000", "0.00000000"], ["72765.15000000", "0.00000000"], ["72765.42000000", "0.00000000"], ["72765.61000000", "0.00000000"], ["72765.76000000", "0.00000000"], ["72765.78000000", "0.00000000"], ["72765.98000000", "0.00008000"], ["72765.99000000", "0.00008000"], ["72766.46000000", "0.00000000"], ["72766.51000000", "0.00000000"], ["72767.24000000", "0.00000000"], ["72767.27000000", "0.00000000"], ["72767.41000000", "0.00000000"], ["72767.42000000", "0.00000000"], ["72767.84000000", "0.00000000"], ["72767.96000000", "0.00000000"], ["72768.04000000", "0.00000000"], ["72768.05000000", "0.00008000"], ["72768.06000000", "0.00000000"], ["72768.08000000", "0.00000000"], ["72768.12000000", "0.00000000"], ["72768.55000000", "0.00000000"], ["72768.72000000", "0.00000000"], ["72768.96000000", "0.00000000"], ["72768.97000000", "0.00000000"], ["72768.99000000", "0.00000000"], ["72769.05000000", "0.00000000"], ["72769.06000000", "0.00008000"], ["72769.07000000", "0.00000000"], ["72769.16000000", "0.00000000"], ["72769.33000000", "0.00000000"], ["72769.37000000", "0.01404000"], ["72769.68000000", "0.00000000"], ["72769.93000000", "0.00000000"], ["72770.10000000", "0.00000000"], ["72770.29000000", "0.00000000"], ["72770.88000000", "0.00000000"], ["72770.96000000", "0.02000000"], ["72770.97000000", "0.00000000"], ["72770.98000000", "0.00000000"], ["72771.20000000", "0.00000000"], ["72771.21000000", "0.40478000"], ["72771.22000000", "0.00000000"], ["72771.24000000", "0.00000000"], ["72771.48000000", "0.00000000"], ["72771.52000000", "0.00000000"], ["72772.18000000", "0.00000000"], ["72772.70000000", "0.00000000"], ["72772.92000000", "0.00000000"], ["72773.27000000", "0.00000000"], ["72773.36000000", "0.00000000"], ["72773.37000000", "0.00000000"], ["72773.56000000", "0.14918000"], ["72773.93000000", "0.00741000"], ["72774.30000000", "0.00000000"], ["72774.31000000", "0.00000000"], ["72774.53000000", "0.16227000"], ["72774.54000000", "0.00000000"], ["72774.55000000", "0.00000000"], ["72774.56000000", "0.00031000"], ["72774.78000000", "0.00000000"], ["72774.98000000", "0.16091000"], ["72774.99000000", "0.66198000"], ["72775.00000000", "0.00000000"], ["72775.37000000", "0.00189000"], ["72775.38000000", "0.00000000"], ["72775.59000000", "0.00000000"], ["72776.18000000", "0.00000000"], ["72776.43000000", "0.00000000"], ["72776.65000000", "0.01377000"], ["72776.88000000", "0.00000000"], ["72776.99000000", "0.16227000"], ["72777.37000000", "0.00000000"], ["72777.38000000", "0.27000000"], ["72777.48000000", "0.00000000"], ["72777.57000000", "0.00753000"], ["72778.00000000", "0.02280000"], ["72778.18000000", "0.00000000"], ["72778.44000000", "0.00000000"], ["72778.60000000", "0.14448000"], ["72779.37000000", "0.16227000"], ["72779.51000000", "0.00175000"], ["72779.63000000", "0.00000000"], ["72779.72000000", "0.00000000"], ["72779.73000000", "0.00000000"], ["72779.74000000", "0.40338000"], ["72779.75000000", "0.00000000"], ["72780.28000000", "0.00000000"], ["72780.47000000", "0.00191000"], ["72780.52000000", "0.00012000"], ["72781.06000000", "0.00000000"], ["72781.12000000", "0.16091000"], ["72781.21000000", "0.00756000"], ["72781.28000000", "0.00000000"], ["72781.42000000", "0.00155000"], ["72781.50000000", "0.00000000"], ["72781.51000000", "0.58226000"], ["72781.52000000", "0.00848000"], ["72781.93000000", "0.65949000"], ["72781.95000000", "0.00000000"], ["72782.27000000", "0.38382000"], ["72783.03000000", "0.00200000"], ["72783.30000000", "0.00000000"], ["72783.93000000", "0.01361000"], ["72784.57000000", "0.00000000"], ["72784.85000000", "0.00752000"], ["72784.89000000", "0.05000000"], ["72785.05000000", "0.00000000"], ["72785.09000000", "0.10000000"], ["72785.90000000", "0.65949000"], ["72786.89000000", "0.00000000"], ["72787.36000000", "0.01483000"], ["72787.95000000", "0.00000000"], ["72788.54000000", "0.00000000"], ["72788.94000000", "0.00007000"], ["72789.16000000", "0.65949000"], ["72789.71000000", "0.00000000"], ["72790.90000000", "0.00400000"], ["72791.07000000", "0.00000000"], ["72791.21000000", "0.01403000"], ["72791.54000000", "0.00000000"], ["72791.98000000", "0.15515000"], ["72791.99000000", "0.00000000"], ["72792.02000000", "2.74925000"], ["72792.03000000", "0.00000000"], ["72792.13000000", "0.00000000"], ["72792.14000000", "0.00000000"], ["72792.63000000", "0.00007000"], ["72792.68000000", "0.65949000"], ["72793.25000000", "0.24485000"], ["72793.26000000", "0.00000000"], ["72793.33000000", "0.00000000"], ["72793.93000000", "0.00000000"], ["72794.45000000", "0.00000000"], ["72794.80000000", "0.00000000"], ["72795.79000000", "0.04048000"], ["72796.32000000", "0.00207000"], ["72797.99000000", "0.15931000"], ["72798.42000000", "0.14562000"], ["72798.49000000", "0.01384000"], ["72798.64000000", "0.16228000"], ["72798.92000000", "0.00000000"], ["72799.71000000", "0.00000000"], ["72799.90000000", "2.74925000"], ["72799.91000000", "0.16228000"], ["72800.39000000", "0.32455000"], ["72800.40000000", "0.65949000"], ["72800.41000000", "0.00000000"], ["72801.02000000", "0.00105000"], ["72801.21000000", "0.00343000"], ["72801.22000000", "0.00000000"], ["72802.05000000", "0.14923000"], ["72802.31000000", "0.16228000"], ["72802.32000000", "0.00000000"], ["72802.58000000", "0.00000000"], ["72802.99000000", "0.00425000"], ["72803.17000000", "0.00020000"], ["72805.27000000", "0.00000000"], ["72805.71000000", "0.00000000"], ["72806.14000000", "2.74925000"], ["72806.15000000", "0.00000000"], ["72808.42000000", "0.30503000"], ["72808.94000000", "0.00020000"], ["72809.13000000", "0.65949000"], ["72809.14000000", "0.00000000"], ["72809.48000000", "0.00000000"], ["72809.84000000", "0.00000000"], ["72809.85000000", "0.27000000"], ["72810.34000000", "0.00000000"], ["72810.61000000", "0.00000000"], ["72811.37000000", "0.15126000"], ["72812.21000000", "0.16227000"], ["72812.26000000", "0.09388000"], ["72812.30000000", "0.01086000"], ["72812.48000000", "2.74933000"], ["72812.49000000", "0.00000000"], ["72812.51000000", "0.00000000"], ["72813.24000000", "0.00000000"], ["72813.33000000", "0.43679000"], ["72815.97000000", "0.00000000"], ["72817.84000000", "0.65949000"], ["72817.85000000", "0.00000000"], ["72817.86000000", "0.00000000"], ["72817.87000000", "0.03407000"], ["72819.85000000", "0.00000000"], ["72821.99000000", "0.47794000"], ["72822.55000000", "1.36117000"], ["72823.86000000", "0.00000000"], ["72824.84000000", "0.00341000"], ["72826.59000000", "0.29903000"], ["72826.60000000", "0.65949000"], ["72827.13000000", "0.00008000"], ["72827.98000000", "0.75436000"], ["72828.00000000", "0.02280000"], ["72828.52000000", "0.00000000"], ["72829.52000000", "0.94295000"], ["72829.57000000", "1.30198000"], ["72830.14000000", "0.00105000"], ["72830.84000000", "0.19409000"], ["72830.86000000", "4.11148000"], ["72833.12000000", "0.22738000"], ["72833.13000000", "0.02829000"], ["72833.93000000", "0.00000000"], ["72834.76000000", "0.00008000"], ["72835.33000000", "0.65949000"], ["72835.68000000", "1.36093000"], ["72836.11000000", "1.32013000"], ["72838.08000000", "0.02835000"], ["72838.81000000", "0.07005000"], ["72841.03000000", "0.65949000"], ["72841.98000000", "0.00550000"], ["72844.81000000", "0.00000000"], ["72845.60000000", "0.00008000"], ["72848.41000000", "0.65949000"], ["72851.98000000", "0.00000000"], ["72857.14000000", "0.65949000"], ["72859.99000000", "0.00000000"], ["72864.93000000", "0.00000000"], ["72865.52000000", "0.94179000"], ["72868.81000000", "2.74925000"], ["72871.99000000", "0.00000000"], ["72873.46000000", "0.00412000"], ["72873.47000000", "1.45268000"], ["72873.99000000", "0.00137000"], ["72874.60000000", "0.65949000"], ["72875.31000000", "2.74925000"], ["72877.29000000", "0.16765000"], ["72877.64000000", "0.00000000"], ["72883.33000000", "0.65960000"], ["72885.50000000", "0.00000000"], ["72889.99000000", "0.00000000"], ["72892.06000000", "0.65949000"], ["72892.59000000", "0.00000000"], ["72897.84000000", "0.00137000"], ["72899.89000000", "0.00008000"], ["72900.79000000", "0.65949000"], ["72901.51000000", "0.00010000"], ["72901.88000000", "0.00000000"], ["72902.38000000", "0.00000000"], ["72904.30000000", "0.00000000"], ["72907.52000000", "0.00008000"], ["72909.52000000", "0.65949000"], ["72913.00000000", "0.00007000"], ["72916.72000000", "0.00000000"], ["72916.99000000", "0.27000000"], ["72928.16000000", "0.00000000"], ["72933.87000000", "2.06252000"], ["72942.80000000", "0.00000000"], ["72949.30000000", "0.00007000"], ["72991.23000000", "0.07685000"], ["73038.09000000", "0.00000000"], ["73045.40000000", "0.00008000"], ["73053.05000000", "0.00008000"], ["73110.84000000", "0.00000000"], ["73118.15000000", "0.00008000"], ["73125.81000000", "0.00008000"], ["73256.33000000", "0.00000000"], ["73263.66000000", "0.00008000"], ["73271.33000000", "0.00008000"]], "_local_ts_utc": "2026-06-01T07:49:13.520055+00:00"}
{"e": "depthUpdate", "E": 1780300154714, "s": "BTCUSDT", "U": 94551813607, "u": 94551814371, "b": [["72763.80000000", "0.45273000"], ["72763.36000000", "0.76330000"], ["72763.35000000", "0.38836000"], ["72763.27000000", "0.67658000"], ["72763.16000000", "1.55995000"], ["72763.15000000", "0.29550000"], ["72763.10000000", "0.40045000"], ["72762.95000000", "0.44963000"], ["72762.94000000", "1.04137000"], ["72762.83000000", "0.99753000"], ["72762.82000000", "3.57710000"], ["72762.81000000", "0.35839000"], ["72762.80000000", "0.00014000"], ["72762.72000000", "0.00000000"], ["72762.67000000", "0.00000000"], ["72762.35000000", "0.00000000"], ["72762.14000000", "0.11120000"], ["72762.01000000", "1.62588000"], ["72762.00000000", "0.00000000"], ["72761.99000000", "0.48489000"], ["72761.98000000", "0.00016000"], ["72761.97000000", "0.04074000"], ["72761.94000000", "0.00009000"], ["72761.41000000", "0.00000000"], ["72761.40000000", "0.00016000"], ["72761.39000000", "0.40733000"], ["72761.00000000", "0.00000000"], ["72760.98000000", "0.00008000"], ["72760.97000000", "0.00000000"], ["72760.96000000", "0.00016000"], ["72760.95000000", "0.83482000"], ["72760.94000000", "0.00000000"], ["72760.56000000", "0.16552000"], ["72760.55000000", "0.00000000"], ["72760.31000000", "0.16431000"], ["72760.30000000", "0.00000000"], ["72760.13000000", "0.00000000"], ["72760.00000000", "0.00000000"], ["72759.99000000", "0.00000000"], ["72759.97000000", "0.00000000"], ["72759.47000000", "0.00000000"], ["72759.31000000", "0.50827000"], ["72759.30000000", "0.00000000"], ["72759.17000000", "0.01529000"], ["72758.43000000", "0.00000000"], ["72758.21000000", "0.00000000"], ["72758.14000000", "0.00000000"], ["72758.07000000", "0.00000000"], ["72758.00000000", "0.00000000"], ["72757.99000000", "0.05916000"], ["72757.82000000", "0.00008000"], ["72757.81000000", "0.63267000"], ["72757.48000000", "0.00000000"], ["72757.47000000", "0.26307000"], ["72757.33000000", "0.00000000"], ["72757.26000000", "0.00164000"], ["72757.24000000", "0.00000000"], ["72757.09000000", "0.00000000"], ["72756.85000000", "0.00000000"], ["72756.02000000", "0.00000000"], ["72756.01000000", "0.37018000"], ["72755.99000000", "0.12542000"], ["72755.13000000", "0.38120000"], ["72755.12000000", "0.00000000"], ["72754.43000000", "0.00000000"], ["72753.98000000", "0.00000000"], ["72753.60000000", "0.00008000"], ["72753.17000000", "0.16091000"], ["72752.95000000", "0.02000000"], ["72752.91000000", "0.00007000"], ["72752.13000000", "0.00349000"], ["72752.02000000", "0.14852000"], ["72752.01000000", "1.41739000"], ["72752.00000000", "2.74925000"], ["72751.99000000", "0.30828000"], ["72751.01000000", "0.00000000"], ["72750.56000000", "0.00000000"], ["72750.18000000", "0.00573000"], ["72748.35000000", "0.62356000"], ["72747.57000000", "0.12072000"], ["72747.09000000", "0.10494000"], ["72745.99000000", "0.00054000"], ["72745.87000000", "0.00007000"], ["72745.58000000", "0.09000000"], ["72745.14000000", "0.00000000"], ["72744.84000000", "0.00000000"], ["72744.22000000", "0.00000000"], ["72744.01000000", "0.00200000"], ["72742.34000000", "0.00014000"], ["72741.95000000", "0.00008000"], ["72741.56000000", "0.35395000"], ["72740.98000000", "0.00000000"], ["72738.32000000", "0.00119000"], ["72738.12000000", "0.00400000"], ["72737.23000000", "0.00012000"], ["72734.25000000", "0.17395000"], ["72733.96000000", "0.00000000"], ["72732.66000000", "0.00000000"], ["72732.26000000", "0.00000000"], ["72730.84000000", "0.00000000"], ["72730.32000000", "0.86277000"], ["72729.02000000", "0.49561000"], ["72727.74000000", "0.00000000"], ["72726.21000000", "0.00000000"], ["72725.66000000", "0.00000000"], ["72722.86000000", "0.55681000"], ["72722.23000000", "0.00000000"], ["72721.45000000", "0.00000000"], ["72720.65000000", "0.00000000"], ["72720.29000000", "0.00000000"], ["72719.71000000", "0.00000000"], ["72718.41000000", "0.00000000"], ["72715.61000000", "0.00000000"], ["72712.77000000", "0.01147000"], ["72712.52000000", "0.00000000"], ["72712.43000000", "0.00000000"], ["72708.80000000", "0.00000000"], ["72708.31000000", "0.50789000"], ["72707.72000000", "0.00430000"], ["72706.33000000", "0.00431000"], ["72705.65000000", "0.02752000"], ["72705.39000000", "1.03982000"], ["72705.16000000", "0.00000000"], ["72704.08000000", "0.40856000"], ["72699.63000000", "0.00008000"], ["72690.76000000", "0.00000000"], ["72690.69000000", "0.00000000"], ["72690.67000000", "0.00112000"], ["72689.22000000", "0.00000000"], ["72686.98000000", "0.00000000"], ["72685.66000000", "0.01072000"], ["72684.97000000", "0.01755000"], ["72683.25000000", "0.00000000"], ["72674.68000000", "0.00000000"], ["72661.77000000", "0.04627000"], ["72660.61000000", "0.04583000"], ["72657.60000000", "0.04355000"], ["72656.04000000", "0.00000000"], ["72651.71000000", "0.00000000"], ["72650.03000000", "0.86493000"], ["72647.82000000", "2.44550000"], ["72628.48000000", "0.00000000"], ["72578.30000000", "0.00821000"], ["72576.41000000", "0.00000000"], ["72555.78000000", "0.00000000"], ["72555.77000000", "0.00000000"], ["72552.14000000", "0.00000000"], ["72549.26000000", "0.00000000"], ["72478.95000000", "0.00029000"], ["71307.56000000", "0.00000000"], ["71306.75000000", "0.00000000"], ["65486.54000000", "0.00000000"], ["65485.80000000", "0.00000000"]], "a": [["72762.00000000", "0.00000000"], ["72762.01000000", "0.00000000"], ["72762.15000000", "0.00000000"], ["72762.36000000", "0.00000000"], ["72762.68000000", "0.00000000"], ["72762.73000000", "0.00000000"], ["72762.82000000", "0.00000000"], ["72762.83000000", "0.00000000"], ["72762.84000000", "0.00000000"], ["72763.11000000", "0.00000000"], ["72763.16000000", "0.00000000"], ["72763.17000000", "0.00000000"], ["72763.36000000", "0.00000000"], ["72764.00000000", "0.02296000"], ["72764.73000000", "0.00000000"], ["72764.84000000", "0.00000000"], ["72765.98000000", "0.00000000"], ["72765.99000000", "0.00016000"], ["72766.00000000", "0.02296000"], ["72766.47000000", "0.00000000"], ["72767.16000000", "0.00000000"], ["72767.19000000", "0.00024000"], ["72767.20000000", "0.10327000"], ["72767.29000000", "0.00522000"], ["72767.99000000", "0.00008000"], ["72768.00000000", "0.02296000"], ["72769.11000000", "0.00028000"], ["72769.37000000", "0.00016000"], ["72769.52000000", "0.00000000"], ["72770.00000000", "0.02296000"], ["72770.02000000", "0.00000000"], ["72770.36000000", "0.00000000"], ["72770.96000000", "0.00016000"], ["72771.21000000", "0.12493000"], ["72771.94000000", "0.00000000"], ["72772.08000000", "0.00000000"], ["72772.50000000", "0.01399000"], ["72772.96000000", "0.00000000"], ["72773.02000000", "0.00000000"], ["72773.34000000", "0.16091000"], ["72774.11000000", "0.00000000"], ["72774.52000000", "0.00000000"], ["72774.98000000", "0.00000000"], ["72774.99000000", "0.41013000"], ["72776.47000000", "0.02000000"], ["72776.69000000", "0.16091000"], ["72776.98000000", "0.65949000"], ["72778.38000000", "0.16091000"], ["72778.59000000", "0.28608000"], ["72778.60000000", "0.00000000"], ["72779.27000000", "0.00027000"], ["72779.37000000", "0.00000000"], ["72779.74000000", "0.00000000"], ["72780.05000000", "0.12085000"], ["72780.47000000", "0.15668000"], ["72780.52000000", "0.00000000"], ["72780.90000000", "0.16091000"], ["72781.12000000", "0.00000000"], ["72781.91000000", "0.16091000"], ["72781.92000000", "0.45943000"], ["72781.94000000", "0.00008000"], ["72783.42000000", "0.00000000"], ["72783.53000000", "0.00000000"], ["72784.25000000", "0.16091000"], ["72784.68000000", "0.16091000"], ["72784.89000000", "0.01000000"], ["72785.09000000", "0.02000000"], ["72785.28000000", "0.00000000"], ["72785.88000000", "0.16091000"], ["72785.89000000", "0.45668000"], ["72785.91000000", "0.00000000"], ["72786.89000000", "0.00000000"], ["72787.20000000", "0.00000000"], ["72788.03000000", "0.16091000"], ["72788.46000000", "0.00000000"], ["72788.69000000", "0.08000000"], ["72789.15000000", "0.16091000"], ["72789.96000000", "0.16091000"], ["72789.97000000", "1.30082000"], ["72789.98000000", "0.00000000"], ["72789.99000000", "0.00000000"], ["72790.17000000", "0.50000000"], ["72791.68000000", "0.00118000"], ["72791.81000000", "0.15040000"], ["72791.96000000", "0.15830000"], ["72791.97000000", "0.68793000"], ["72791.98000000", "0.00000000"], ["72792.02000000", "3.71810000"], ["72796.32000000", "0.00007000"], ["72797.28000000", "0.00000000"], ["72797.99000000", "0.97805000"], ["72798.42000000", "0.00000000"], ["72798.63000000", "0.00200000"], ["72798.64000000", "0.00000000"], ["72799.37000000", "0.00000000"], ["72799.89000000", "0.00000000"], ["72799.91000000", "0.00000000"], ["72800.39000000", "0.42700000"], ["72800.42000000", "0.00000000"], ["72801.02000000", "0.00000000"], ["72801.76000000", "0.00200000"], ["72802.05000000", "0.00000000"], ["72802.31000000", "0.00000000"], ["72803.99000000", "0.88748000"], ["72806.13000000", "0.65949000"], ["72807.14000000", "0.00000000"], ["72808.24000000", "0.00000000"], ["72808.26000000", "0.00551000"], ["72811.37000000", "0.00000000"], ["72812.21000000", "0.00000000"], ["72812.26000000", "0.00000000"], ["72812.30000000", "0.00007000"], ["72812.46000000", "0.16091000"], ["72812.47000000", "1.09865000"], ["72812.48000000", "3.40882000"], ["72812.50000000", "0.00000000"], ["72814.79000000", "0.74802000"], ["72815.88000000", "1.03824000"], ["72824.10000000", "0.01699000"], ["72825.18000000", "0.00112000"], ["72825.82000000", "0.09408000"], ["72826.59000000", "0.47235000"], ["72827.13000000", "0.00000000"], ["72827.81000000", "0.01088000"], ["72830.84000000", "0.18859000"], ["72833.12000000", "1.00310000"], ["72834.62000000", "0.01156000"], ["72835.77000000", "0.75436000"], ["72837.19000000", "0.00550000"], ["72837.52000000", "0.01100000"], ["72838.47000000", "0.00550000"], ["72845.14000000", "0.00000000"], ["72850.15000000", "0.00685000"], ["72851.97000000", "0.00000000"], ["72853.28000000", "0.08976000"], ["72855.90000000", "0.04583000"], ["72856.90000000", "0.31115000"], ["72864.56000000", "0.04137000"], ["72865.34000000", "0.00000000"], ["72865.87000000", "0.65949000"], ["72873.47000000", "2.19195000"], ["72873.48000000", "3.12534000"], ["72875.31000000", "0.00000000"], ["72876.63000000", "0.04655000"], ["72883.32000000", "0.19719000"], ["72885.55000000", "0.05118000"], ["72887.86000000", "0.09682000"], ["72893.31000000", "0.03968000"], ["72899.89000000", "0.00000000"], ["72909.52000000", "0.00000000"], ["72930.97000000", "0.00000000"], ["72933.08000000", "0.00000000"], ["72933.61000000", "0.00007000"], ["72934.19000000", "0.00000000"], ["72937.43000000", "0.00000000"], ["72953.47000000", "0.00007000"], ["72955.25000000", "0.00000000"], ["72957.10000000", "0.00000000"], ["72977.84000000", "0.00000000"], ["72978.46000000", "0.11537000"], ["72978.59000000", "0.01883000"], ["72981.97000000", "0.01886000"], ["73004.04000000", "0.04771000"], ["73045.40000000", "0.00000000"], ["73118.15000000", "0.00000000"], ["73263.66000000", "0.00000000"]], "_local_ts_utc": "2026-06-01T07:49:13.610714+00:00"}
