{"e": "depthUpdate", "E": 1780300129014, "s": "BTCUSDT", "U": 94551748562, "u": 94551748677, "b": [["72762.81000000", "3.32892000"], ["72762.25000000", "0.02915000"], ["72761.86000000", "0.00597000"], ["72761.38000000", "0.18415000"], ["72760.74000000", "0.00000000"], ["72760.26000000", "0.00016000"], ["72760.04000000", "0.18415000"], ["72760.03000000", "0.65949000"], ["72760.00000000", "0.16870000"], ["72754.39000000", "0.02000000"], ["72751.04000000", "0.40856000"], ["72750.01000000", "0.00590000"], ["72748.21000000", "0.00000000"], ["72747.50000000", "0.00008000"], ["72745.44000000", "0.00008000"], ["72741.90000000", "0.00320000"], ["72741.04000000", "0.00000000"], ["72738.11000000", "0.00000000"], ["72730.69000000", "0.00000000"], ["72730.01000000", "0.00000000"], ["72728.72000000", "0.00000000"], ["72720.47000000", "0.00000000"], ["72719.65000000", "0.08726000"], ["72719.01000000", "0.00000000"], ["72693.42000000", "0.02072000"], ["65486.53000000", "0.00170000"], ["58210.25000000", "0.00034000"]], "a": [["72762.82000000", "0.80920000"], ["72762.83000000", "0.21623000"], ["72763.65000000", "0.00008000"], ["72763.66000000", "0.00000000"], ["72763.67000000", "0.00000000"], ["72765.73000000", "0.02016000"], ["72765.93000000", "0.00000000"], ["72766.33000000", "0.00016000"], ["72766.34000000", "0.45423000"], ["72766.41000000", "0.00031000"], ["72766.42000000", "0.00000000"], ["72766.69000000", "0.00016000"], ["72767.07000000", "0.00000000"], ["72767.15000000", "0.00000000"], ["72767.19000000", "0.00016000"], ["72767.20000000", "0.10327000"], ["72767.34000000", "0.00031000"], ["72767.47000000", "0.00000000"], ["72767.48000000", "0.02576000"], ["72767.85000000", "0.00000000"], ["72768.70000000", "0.00008000"], ["72768.71000000", "0.29069000"], ["72769.68000000", "0.00028000"], ["72770.10000000", "0.27008000"], ["72771.52000000", "0.23462000"], ["72772.91000000", "0.05942000"], ["72773.04000000", "0.18391000"], ["72774.50000000", "0.16728000"], ["72775.92000000", "0.18391000"], ["72775.99000000", "0.18399000"], ["72777.38000000", "0.47000000"], ["72777.60000000", "0.00000000"], ["72777.82000000", "0.18391000"], ["72779.98000000", "0.00426000"], ["72781.80000000", "0.18791000"], ["72781.95000000", "0.16866000"], ["72782.46000000", "0.08200000"], ["72783.83000000", "0.00000000"], ["72784.72000000", "0.18398000"], ["72785.99000000", "0.71830000"], ["72787.26000000", "2.75265000"], ["72790.45000000", "0.00000000"], ["72790.56000000", "0.18391000"], ["72792.02000000", "0.18391000"], ["72793.33000000", "0.18391000"], ["72835.69000000", "0.00000000"], ["72875.29000000", "0.00000000"]], "_local_ts_utc": "2026-06-01T07:48:47.911849+00:00"}
{"e": "depthUpdate", "E": 1780300129114, "s": "BTCUSDT", "U": 94551748678, "u": 94551748744, "b": [["72762.81000000", "3.32916000"], ["72762.25000000", "0.00016000"], ["72762.01000000", "0.00008000"], ["72761.03000000", "0.05942000"], ["72760.26000000", "0.00000000"], ["72752.31000000", "0.02000000"], ["72751.57000000", "0.02000000"], ["72751.03000000", "0.00000000"], ["72693.42000000", "0.00072000"], ["72691.03000000", "0.02000000"], ["72690.31000000", "0.02000000"], ["71307.55000000", "0.00000000"], ["65486.53000000", "0.00204000"]], "a": [["72762.82000000", "0.80815000"], ["72766.00000000", "0.00080000"], ["72766.04000000", "0.00031000"], ["72766.34000000", "0.45423000"], ["72766.69000000", "0.00000000"], ["72767.20000000", "0.10327000"], ["72767.34000000", "0.00000000"], ["72767.48000000", "0.02592000"], ["72768.00000000", "0.00080000"], ["72770.00000000", "0.00080000"], ["72772.00000000", "0.00088000"], ["72774.00000000", "0.00080000"], ["72776.00000000", "0.91848000"], ["72776.99000000", "0.18517000"], ["72778.00000000", "1.06885000"], ["72780.23000000", "0.00000000"], ["72781.01000000", "0.00000000"], ["72784.74000000", "0.00400000"], ["72784.75000000", "0.05400000"], ["72785.48000000", "0.05400000"], ["72785.99000000", "1.52807000"], ["72786.01000000", "0.00000000"], ["72790.02000000", "0.00200000"], ["72790.56000000", "0.00000000"], ["72792.02000000", "0.00000000"], ["72793.33000000", "0.00000000"], ["80159.53000000", "0.00132000"]], "_local_ts_utc": "2026-06-01T07:48:48.010618+00:00"}
{"e": "depthUpdate", "E": 1780300129214, "s": "BTCUSDT", "U": 94551748745, "u": 94551748807, "b": [["72762.81000000", "3.32540000"], ["72762.80000000", "0.00064000"], ["72762.25000000", "0.02910000"], ["72761.03000000", "0.05958000"], ["72760.73000000", "0.00000000"], ["72739.55000000", "0.00200000"], ["72736.74000000", "0.00000000"], ["72719.65000000", "0.12989000"], ["72718.71000000", "0.18017000"], ["72715.60000000", "0.18517000"], ["72700.57000000", "0.18859000"], ["65486.53000000", "0.00238000"], ["58210.25000000", "0.00000000"]], "a": [["72762.82000000", "0.81065000"], ["72763.80000000", "0.33731000"], ["72765.51000000", "0.00031000"], ["72765.59000000", "0.00000000"], ["72765.63000000", "0.00031000"], ["72766.04000000", "0.00000000"], ["72766.41000000", "0.00000000"], ["72767.47000000", "0.00000000"], ["72767.48000000", "0.02601000"], ["72769.90000000", "0.05942000"], ["72771.51000000", "0.18517000"], ["72772.91000000", "0.00000000"], ["72792.44000000", "0.00000000"], ["72793.17000000", "0.00000000"], ["72794.96000000", "0.96806000"], ["72797.77000000", "0.00200000"], ["72830.94000000", "0.55338000"], ["72832.86000000", "0.18446000"]], "_local_ts_utc": "2026-06-01T07:48:48.110412+00:00"}
{"e": "depthUpdate", "E": 1780300129314, "s": "BTCUSDT", "U": 94551748808, "u": 94551748925, "b": [["72762.81000000", "3.32532000"], ["72762.80000000", "0.00048000"], ["72762.26000000", "0.00000000"], ["72762.25000000", "0.00000000"], ["72762.01000000", "0.00024000"], ["72761.39000000", "0.00008000"], ["72761.38000000", "0.18423000"], ["72761.37000000", "0.00016000"], ["72761.04000000", "0.00000000"], ["72761.03000000", "0.00016000"], ["72760.74000000", "0.00000000"], ["72760.73000000", "0.03905000"], ["72760.05000000", "0.65949000"], ["72760.03000000", "0.00000000"], ["72759.11000000", "0.00000000"], ["72756.80000000", "0.00000000"], ["72754.53000000", "0.02000000"], ["72752.07000000", "0.02000000"], ["72751.16000000", "0.00000000"], ["72730.15000000", "0.00274000"], ["72727.53000000", "0.18517000"], ["72696.40000000", "0.02000000"], ["72696.18000000", "0.02000000"], ["72693.96000000", "0.02000000"], ["72690.31000000", "0.00000000"], ["65486.53000000", "0.00272000"]], "a": [["72762.82000000", "0.99722000"], ["72762.83000000", "0.21623000"], ["72763.73000000", "0.00000000"], ["72763.79000000", "0.00016000"], ["72763.80000000", "0.33747000"], ["72764.58000000", "0.00031000"], ["72765.51000000", "0.00000000"], ["72765.63000000", "0.00000000"], ["72767.47000000", "0.00000000"], ["72767.48000000", "0.00016000"], ["72767.78000000", "0.05942000"], ["72768.70000000", "0.00000000"], ["72768.71000000", "0.29045000"], ["72769.90000000", "0.00000000"], ["72775.03000000", "0.65949000"], ["72777.82000000", "0.00000000"], ["72781.80000000", "0.00400000"], ["72781.95000000", "0.00000000"]], "_local_ts_utc": "2026-06-01T07:48:48.210822+00:00"}
{"e": "depthUpdate", "E": 1780300129414, "s": "BTCUSDT", "U": 94551748926, "u": 94551749248, "b": [["72762.81000000", "0.04601000"], ["72762.80000000", "0.00096000"], ["72762.41000000", "0.00000000"], ["72762.33000000", "0.01400000"], ["72762.25000000", "0.00000000"], ["72762.06000000", "0.00000000"], ["72761.94000000", "0.00000000"], ["72761.39000000", "0.00000000"], ["72761.38000000", "0.00024000"], ["72761.37000000", "0.00000000"], ["72761.04000000", "0.00000000"], ["72761.03000000", "0.00000000"], ["72760.74000000", "0.00000000"], ["72760.73000000", "0.00765000"], ["72760.36000000", "0.00016000"], ["72760.35000000", "0.02676000"], ["72760.06000000", "0.00000000"], ["72760.05000000", "0.00016000"], ["72760.04000000", "0.00024000"], ["72760.01000000", "0.00016000"], ["72759.28000000", "0.00000000"], ["72758.46000000", "0.00008000"], ["72758.45000000", "0.00000000"], ["72758.42000000", "0.00757000"], ["72758.29000000", "0.00000000"], ["72758.01000000", "0.00016000"], ["72757.31000000", "0.00031000"], ["72757.01000000", "0.00008000"], ["72757.00000000", "0.00000000"], ["72756.55000000", "0.00000000"], ["72756.23000000", "0.00000000"], ["72755.74000000", "0.00000000"], ["72755.54000000", "0.00008000"], ["72755.53000000", "0.00000000"], ["72754.50000000", "0.02400000"], ["72754.09000000", "0.00008000"], ["72754.08000000", "0.00000000"], ["72753.01000000", "0.00014000"], ["72752.78000000", "0.00008000"], ["72752.77000000", "0.00000000"], ["72752.58000000", "0.00000000"], ["72751.31000000", "0.00000000"], ["72751.15000000", "0.00000000"], ["72751.04000000", "0.00000000"], ["72751.02000000", "0.00100000"], ["72750.01000000", "0.00590000"], ["72747.49000000", "0.00000000"], ["72747.48000000", "0.00000000"], ["72747.36000000", "0.00000000"], ["72746.31000000", "0.00029000"], ["72746.22000000", "0.00000000"], ["72745.44000000", "0.65957000"], ["72744.81000000", "0.00000000"], ["72744.56000000", "0.00000000"], ["72743.21000000", "0.00000000"], ["72742.60000000", "0.00000000"], ["72741.90000000", "0.00000000"], ["72740.88000000", "0.01375000"], ["72740.87000000", "0.00000000"], ["72740.16000000", "0.00000000"], ["72740.11000000", "0.12007000"], ["72738.91000000", "0.00000000"], ["72738.11000000", "0.00000000"], ["72738.09000000", "0.00000000"], ["72736.10000000", "0.02000000"], ["72734.38000000", "0.00000000"], ["72730.47000000", "0.00000000"], ["72729.00000000", "0.01376000"], ["72727.53000000", "0.00000000"], ["72727.04000000", "0.18517000"], ["72721.17000000", "0.00000000"], ["72720.18000000", "0.18517000"], ["72719.65000000", "0.04263000"], ["72718.71000000", "0.18517000"], ["72717.55000000", "0.00000000"], ["72717.24000000", "0.18517000"], ["72715.79000000", "0.00000000"], ["72715.60000000", "0.18517000"], ["72715.45000000", "0.00000000"], ["72714.71000000", "0.00000000"], ["72702.54000000", "0.00000000"], ["72701.75000000", "0.18529000"], ["72697.71000000", "0.49582000"], ["72696.40000000", "0.00000000"], ["72696.38000000", "0.02000000"], ["72685.53000000", "1.36374000"], ["72669.24000000", "2.74865000"], ["65486.53000000", "0.00289000"]], "a": [["72762.82000000", "3.61927000"], ["72762.83000000", "0.21623000"], ["72762.99000000", "0.00031000"], ["72763.49000000", "0.75665000"], ["72763.50000000", "0.00000000"], ["72763.51000000", "0.45409000"], ["72763.79000000", "0.00000000"], ["72763.80000000", "0.00024000"], ["72764.58000000", "0.00000000"], ["72765.54000000", "0.00000000"], ["72765.73000000", "0.00016000"], ["72765.76000000", "0.18517000"], ["72766.33000000", "0.00000000"], ["72766.34000000", "0.00016000"], ["72766.64000000", "0.03407000"], ["72766.68000000", "0.03858000"], ["72767.14000000", "0.00008000"], ["72767.15000000", "0.18517000"], ["72767.19000000", "0.00000000"], ["72767.20000000", "0.10327000"], ["72767.47000000", "0.00000000"], ["72767.48000000", "0.00000000"], ["72767.78000000", "0.00016000"], ["72768.70000000", "0.17929000"], ["72770.06000000", "0.18517000"], ["72771.49000000", "0.49602000"], ["72771.50000000", "0.65949000"], ["72771.52000000", "0.00008000"], ["72773.37000000", "0.03407000"], ["72774.48000000", "0.00000000"], ["72777.42000000", "0.20008000"], ["72777.82000000", "0.18517000"], ["72779.98000000", "0.18943000"], ["72780.46000000", "1.36196000"], ["72781.93000000", "0.17968000"], ["72781.95000000", "0.18517000"], ["72784.71000000", "0.00171000"], ["72786.72000000", "0.18533000"], ["72788.24000000", "0.18517000"], ["72788.25000000", "1.36182000"], ["72788.53000000", "0.49520000"], ["72790.75000000", "0.18517000"], ["72791.74000000", "0.09616000"], ["72792.22000000", "0.17305000"], ["72793.33000000", "0.18517000"], ["72805.97000000", "0.00000000"], ["72810.24000000", "0.00000000"], ["72811.18000000", "0.00000000"], ["72834.47000000", "0.18859000"], ["73041.85000000", "0.00000000"], ["73417.69000000", "0.00000000"]], "_local_ts_utc": "2026-06-01T07:48:48.310839+00:00"}
{"e": "depthUpdate", "E": 1780300129514, "s": "BTCUSDT", "U": 94551749249, "u": 94551750053, "b": [["72762.81000000", "0.00000000"], ["72762.80000000", "0.00000000"], ["72762.79000000", "0.00000000"], ["72762.34000000", "0.00000000"], ["72762.33000000", "0.00000000"], ["72762.32000000", "0.00000000"], ["72762.02000000", "0.00000000"], ["72762.01000000", "0.00000000"], ["72762.00000000", "0.00000000"], ["72761.86000000", "0.00000000"], ["72761.38000000", "0.00000000"], ["72760.96000000", "0.00000000"], ["72760.92000000", "0.00000000"], ["72760.73000000", "0.00000000"], ["72760.36000000", "0.00000000"], ["72760.35000000", "0.00000000"], ["72760.05000000", "0.00000000"], ["72760.04000000", "0.00000000"], ["72760.01000000", "0.00000000"], ["72760.00000000", "0.29049000"], ["72759.99000000", "0.00072000"], ["72758.42000000", "0.00016000"], ["72758.19000000", "0.00008000"], ["72758.14000000", "0.00000000"], ["72758.00000000", "0.02296000"], ["72757.77000000", "0.00000000"], ["72757.43000000", "0.00000000"], ["72757.42000000", "0.00007000"], ["72757.31000000", "0.00000000"], ["72757.25000000", "0.00000000"], ["72757.21000000", "0.00000000"], ["72756.79000000", "0.00000000"], ["72756.28000000", "0.00164000"], ["72756.21000000", "0.00029000"], ["72756.01000000", "0.00016000"], ["72755.62000000", "0.00000000"], ["72755.61000000", "0.00000000"], ["72755.60000000", "0.00606000"], ["72755.28000000", "0.01012000"], ["72753.34000000", "0.01737000"], ["72753.01000000", "0.00000000"], ["72752.34000000", "0.00000000"], ["72751.01000000", "0.00008000"], ["72751.00000000", "1.01000000"], ["72750.11000000", "0.01484000"], ["72750.01000000", "0.00590000"], ["72749.72000000", "0.00028000"], ["72749.66000000", "0.00000000"], ["72749.65000000", "0.00000000"], ["72749.53000000", "0.00000000"], ["72749.25000000", "0.00000000"], ["72749.06000000", "0.00000000"], ["72747.84000000", "0.00000000"], ["72747.58000000", "0.00966000"], ["72746.68000000", "0.00000000"], ["72745.45000000", "3.40814000"], ["72745.44000000", "0.00008000"], ["72745.43000000", "0.00000000"], ["72744.32000000", "0.00000000"], ["72744.11000000", "0.33585000"], ["72742.86000000", "0.00000000"], ["72742.60000000", "0.15349000"], ["72742.57000000", "0.00000000"], ["72742.15000000", "0.40856000"], ["72742.14000000", "0.00000000"], ["72741.68000000", "0.00011000"], ["72740.81000000", "0.04100000"], ["72740.39000000", "0.00000000"], ["72740.29000000", "0.53930000"], ["72740.27000000", "0.00164000"], ["72740.11000000", "0.03007000"], ["72739.55000000", "0.00000000"], ["72739.31000000", "0.00000000"], ["72738.66000000", "0.00000000"], ["72738.11000000", "0.18518000"], ["72738.09000000", "0.95675000"], ["72737.71000000", "0.08000000"], ["72736.10000000", "0.00000000"], ["72734.38000000", "0.38228000"], ["72733.71000000", "0.00000000"], ["72733.22000000", "0.00000000"], ["72732.20000000", "0.02000000"], ["72731.27000000", "0.00200000"], ["72730.60000000", "0.18518000"], ["72729.13000000", "0.18518000"], ["72728.31000000", "0.00000000"], ["72727.66000000", "0.18518000"], ["72727.53000000", "0.18517000"], ["72727.05000000", "0.18391000"], ["72727.04000000", "0.00000000"], ["72726.21000000", "0.00007000"], ["72725.36000000", "0.00000000"], ["72719.65000000", "0.12371000"], ["72718.67000000", "0.00000000"], ["72713.29000000", "0.00000000"], ["72709.47000000", "0.00000000"], ["72708.73000000", "0.00000000"], ["72708.67000000", "0.35674000"], ["72707.32000000", "0.00000000"], ["72705.76000000", "0.18526000"], ["72704.57000000", "0.18518000"], ["72703.61000000", "0.00000000"], ["72702.72000000", "0.01144000"], ["72702.67000000", "0.18518000"], ["72702.54000000", "0.18517000"], ["72701.75000000", "0.00012000"], ["72701.42000000", "1.60557000"], ["72699.32000000", "0.65949000"], ["72697.04000000", "0.00000000"], ["72695.14000000", "0.19324000"], ["72694.38000000", "0.18859000"], ["72691.03000000", "0.00000000"], ["72685.54000000", "0.83370000"], ["72685.02000000", "0.00000000"], ["72683.80000000", "0.00000000"], ["72680.62000000", "0.00000000"], ["72677.60000000", "1.36389000"], ["72668.96000000", "0.00008000"], ["72662.39000000", "0.00000000"], ["72657.59000000", "0.00000000"], ["72656.22000000", "0.04628000"], ["72642.91000000", "0.69990000"], ["72616.79000000", "0.00000000"], ["72614.72000000", "0.00000000"], ["72612.94000000", "0.00000000"], ["72612.75000000", "2.84261000"], ["72549.26000000", "0.00007000"], ["72546.83000000", "0.00000000"], ["72543.83000000", "0.00014000"], ["72540.20000000", "0.00007000"], ["72457.28000000", "0.00028000"], ["71307.55000000", "0.00000000"], ["71307.08000000", "0.00000000"], ["71304.80000000", "0.00000000"], ["65486.53000000", "0.00000000"], ["65484.00000000", "0.00088000"], ["58208.00000000", "0.00034000"]], "a": [["72760.01000000", "6.54550000"], ["72760.02000000", "0.00408000"], ["72760.03000000", "0.00014000"], ["72760.36000000", "0.18471000"], ["72760.61000000", "0.00028000"], ["72760.68000000", "0.00000000"], ["72760.74000000", "0.00000000"], ["72760.93000000", "0.00000000"], ["72761.29000000", "0.07376000"], ["72761.87000000", "0.00000000"], ["72761.94000000", "0.00009000"], ["72762.00000000", "0.00008000"], ["72762.01000000", "0.36942000"], ["72762.02000000", "0.06982000"], ["72762.03000000", "0.00000000"], ["72762.34000000", "0.00000000"], ["72762.80000000", "1.01323000"], ["72762.81000000", "0.77069000"], ["72762.82000000", "2.22180000"], ["72762.83000000", "0.15193000"], ["72762.84000000", "0.00131000"], ["72762.99000000", "0.00000000"], ["72763.48000000", "0.18517000"], ["72763.49000000", "0.00016000"], ["72763.51000000", "0.00016000"], ["72763.65000000", "0.00000000"], ["72763.67000000", "0.12000000"], ["72763.74000000", "0.00000000"], ["72763.79000000", "0.00008000"], ["72763.80000000", "0.31457000"], ["72763.81000000", "0.50069000"], ["72765.28000000", "0.18517000"], ["72765.63000000", "0.00000000"], ["72765.71000000", "0.00164000"], ["72765.73000000", "0.00000000"], ["72765.76000000", "0.00016000"], ["72766.34000000", "0.00000000"], ["72766.64000000", "0.03423000"], ["72766.68000000", "0.00016000"], ["72767.15000000", "0.18517000"], ["72767.16000000", "0.00014000"], ["72767.20000000", "0.10311000"], ["72767.31000000", "0.00007000"], ["72767.78000000", "0.00000000"], ["72767.91000000", "0.00157000"], ["72768.32000000", "0.00008000"], ["72768.69000000", "0.00008000"], ["72768.71000000", "0.29028000"], ["72769.09000000", "0.00007000"], ["72770.09000000", "0.00008000"], ["72770.10000000", "0.27000000"], ["72771.49000000", "0.49610000"], ["72771.52000000", "0.00000000"], ["72771.57000000", "0.08249000"], ["72771.73000000", "0.08182000"], ["72771.96000000", "0.00581000"], ["72772.82000000", "0.00000000"], ["72772.83000000", "0.00000000"], ["72773.73000000", "0.00000000"], ["72774.02000000", "0.00582000"], ["72774.72000000", "0.00000000"], ["72775.02000000", "0.00008000"], ["72775.67000000", "0.00000000"], ["72775.96000000", "0.00000000"], ["72776.98000000", "0.18517000"], ["72776.99000000", "0.00000000"], ["72777.13000000", "0.00008000"], ["72777.14000000", "0.20000000"], ["72777.38000000", "0.47000000"], ["72777.42000000", "0.20000000"], ["72777.43000000", "0.00000000"], ["72777.82000000", "0.18525000"], ["72778.01000000", "0.11034000"], ["72778.58000000", "0.00000000"], ["72778.71000000", "0.00000000"], ["72779.96000000", "1.95208000"], ["72779.97000000", "2.74865000"], ["72779.98000000", "0.00425000"], ["72779.99000000", "0.00000000"], ["72780.00000000", "0.11208000"], ["72780.45000000", "0.00008000"], ["72780.72000000", "0.00000000"], ["72781.11000000", "0.00008000"], ["72781.12000000", "0.49525000"], ["72781.58000000", "0.00000000"], ["72781.93000000", "0.00000000"], ["72781.95000000", "0.00000000"], ["72783.53000000", "0.00000000"], ["72784.08000000", "0.00020000"], ["72784.39000000", "0.00000000"], ["72784.51000000", "0.00275000"], ["72784.63000000", "0.00007000"], ["72784.72000000", "0.00007000"], ["72785.28000000", "0.00000000"], ["72785.97000000", "0.00008000"], ["72786.72000000", "0.00016000"], ["72787.25000000", "0.00008000"], ["72787.98000000", "0.00000000"], ["72788.06000000", "0.00000000"], ["72788.24000000", "0.00008000"], ["72789.33000000", "0.00000000"], ["72789.49000000", "0.00200000"], ["72790.75000000", "0.00000000"], ["72790.90000000", "0.00000000"], ["72791.00000000", "0.00000000"], ["72791.21000000", "0.00125000"], ["72791.93000000", "0.00000000"], ["72791.94000000", "0.00000000"], ["72792.22000000", "0.00000000"], ["72792.35000000", "0.00000000"], ["72792.72000000", "0.00000000"], ["72793.33000000", "0.00000000"], ["72794.05000000", "0.00349000"], ["72794.95000000", "0.00008000"], ["72797.76000000", "0.02720000"], ["72797.77000000", "0.00000000"], ["72801.11000000", "0.00342000"], ["72801.47000000", "0.00000000"], ["72807.98000000", "0.27761000"], ["72808.99000000", "0.01144000"], ["72812.37000000", "0.00000000"], ["72823.42000000", "0.00343000"], ["72823.43000000", "0.41386000"], ["72823.44000000", "0.37718000"], ["72823.46000000", "0.00000000"], ["72824.08000000", "0.00000000"], ["72829.07000000", "0.00000000"], ["72832.21000000", "0.00000000"], ["72834.95000000", "0.00000000"], ["72839.09000000", "0.00000000"], ["72840.14000000", "0.09754000"], ["72840.73000000", "0.00000000"], ["72849.65000000", "0.04576000"], ["72860.54000000", "0.00000000"], ["72868.17000000", "0.00000000"], ["72868.18000000", "0.00000000"], ["72872.01000000", "0.00000000"], ["72872.89000000", "0.00000000"], ["72875.30000000", "0.00000000"], ["72878.72000000", "0.00000000"], ["72905.53000000", "0.00010000"], ["72937.90000000", "0.00000000"], ["72945.17000000", "0.00000000"], ["72952.45000000", "0.00000000"], ["73003.38000000", "0.00000000"], ["73040.32000000", "0.00000000"], ["73231.37000000", "0.00000000"]], "_local_ts_utc": "2026-06-01T07:48:48.411470+00:00"}
{"e": "depthUpdate", "E": 1780300129614, "s": "BTCUSDT", "U": 94551750054, "u": 94551750413, "b": [["72760.00000000", "2.03975000"], ["72759.99000000", "0.00072000"], ["72758.42000000", "0.00000000"], ["72758.00000000", "0.02296000"], ["72757.96000000", "0.00031000"], ["72757.06000000", "0.00028000"], ["72756.32000000", "0.00000000"], ["72756.20000000", "0.04139000"], ["72755.94000000", "0.00031000"], ["72755.60000000", "0.30137000"], ["72755.59000000", "0.18518000"], ["72755.28000000", "0.00000000"], ["72755.02000000", "0.03535000"], ["72755.01000000", "0.00000000"], ["72754.99000000", "0.00000000"], ["72754.95000000", "0.05942000"], ["72754.73000000", "0.00000000"], ["72754.71000000", "0.00746000"], ["72754.12000000", "0.18518000"], ["72752.66000000", "0.00000000"], ["72752.65000000", "0.18550000"], ["72751.44000000", "0.00000000"], ["72751.18000000", "0.18518000"], ["72751.01000000", "1.07615000"], ["72750.04000000", "0.00000000"], ["72750.01000000", "0.66539000"], ["72749.06000000", "0.00011000"], ["72748.24000000", "0.00000000"], ["72747.33000000", "0.01375000"], ["72746.77000000", "0.18518000"], ["72746.41000000", "0.00000000"], ["72745.46000000", "1.18420000"], ["72744.11000000", "0.32210000"], ["72743.63000000", "0.03407000"], ["72742.60000000", "0.00000000"], ["72741.55000000", "0.01376000"], ["72740.89000000", "0.00000000"], ["72740.88000000", "0.00000000"], ["72740.30000000", "0.00000000"], ["72738.11000000", "0.00000000"], ["72730.60000000", "0.00000000"], ["72729.13000000", "0.00000000"], ["72727.66000000", "0.00000000"], ["72727.53000000", "0.00000000"], ["72727.05000000", "0.00088000"], ["72723.36000000", "0.00012000"], ["72723.12000000", "0.02738000"], ["72720.18000000", "0.00000000"], ["72718.71000000", "0.00000000"], ["72714.64000000", "1.36320000"], ["72708.67000000", "0.90123000"], ["72707.09000000", "0.49589000"], ["72706.69000000", "1.36334000"], ["72705.76000000", "0.00008000"], ["72704.57000000", "0.00000000"], ["72702.67000000", "0.00000000"], ["72702.54000000", "0.00000000"], ["72690.65000000", "0.29871000"], ["72690.64000000", "0.49587000"], ["72689.55000000", "0.00000000"], ["72677.60000000", "0.00000000"], ["72669.16000000", "2.03600000"], ["72612.75000000", "0.00000000"], ["72612.66000000", "2.84261000"], ["72540.20000000", "0.00000000"], ["72522.71000000", "0.00000000"], ["65486.00000000", "0.00172000"], ["65484.00000000", "0.00105000"], ["58208.00000000", "0.00000000"]], "a": [["72760.01000000", "5.05955000"], ["72760.02000000", "0.00038000"], ["72760.35000000", "0.00000000"], ["72760.36000000", "0.00016000"], ["72760.61000000", "0.00000000"], ["72760.74000000", "0.00000000"], ["72761.28000000", "0.00000000"], ["72761.29000000", "0.00016000"], ["72762.00000000", "0.00008000"], ["72762.01000000", "0.00016000"], ["72762.02000000", "0.00016000"], ["72762.74000000", "0.00000000"], ["72762.79000000", "0.00016000"], ["72762.80000000", "0.71684000"], ["72762.81000000", "0.11152000"], ["72762.82000000", "2.12860000"], ["72762.83000000", "0.15193000"], ["72763.10000000", "0.00687000"], ["72763.28000000", "0.05172000"], ["72763.48000000", "0.00000000"], ["72763.49000000", "0.00000000"], ["72763.51000000", "0.00000000"], ["72763.67000000", "0.12000000"], ["72763.79000000", "0.00008000"], ["72763.80000000", "0.18318000"], ["72763.81000000", "0.50053000"], ["72764.18000000", "0.00000000"], ["72765.28000000", "0.00000000"], ["72765.30000000", "0.00000000"], ["72765.76000000", "0.00000000"], ["72766.23000000", "0.01347000"], ["72766.64000000", "0.00000000"], ["72766.68000000", "0.00000000"], ["72767.13000000", "0.00687000"], ["72767.15000000", "0.00000000"], ["72768.33000000", "0.65949000"], ["72768.70000000", "0.18519000"], ["72770.02000000", "0.01383000"], ["72770.06000000", "0.18519000"], ["72771.48000000", "0.18519000"], ["72771.49000000", "0.33424000"], ["72771.51000000", "0.00000000"], ["72773.04000000", "0.00000000"], ["72773.24000000", "0.18519000"], ["72774.50000000", "0.00000000"], ["72774.71000000", "0.18518000"], ["72775.92000000", "0.00000000"], ["72775.99000000", "0.18526000"], ["72776.98000000", "0.00000000"], ["72776.99000000", "0.18518000"], ["72777.82000000", "0.17982000"], ["72778.00000000", "1.07885000"], ["72779.94000000", "0.18015000"], ["72779.95000000", "0.33976000"], ["72779.96000000", "0.00044000"], ["72779.97000000", "0.00000000"], ["72779.98000000", "0.00407000"], ["72780.00000000", "0.12208000"], ["72780.46000000", "0.00000000"], ["72781.12000000", "0.00000000"], ["72782.00000000", "0.67229000"], ["72783.08000000", "0.05280000"], ["72783.41000000", "0.00000000"], ["72784.00000000", "0.01280000"], ["72784.71000000", "0.00000000"], ["72785.00000000", "0.18518000"], ["72785.97000000", "0.18526000"], ["72786.68000000", "0.00000000"], ["72787.80000000", "0.06200000"], ["72788.57000000", "0.05400000"], ["72790.32000000", "0.00000000"], ["72793.41000000", "0.02693000"], ["72794.50000000", "0.00000000"], ["72797.76000000", "0.00008000"], ["72802.32000000", "0.00000000"], ["72805.51000000", "0.49509000"], ["72807.41000000", "0.26000000"], ["72810.44000000", "0.09309000"], ["72826.05000000", "0.00550000"], ["72835.78000000", "0.00000000"], ["72844.44000000", "0.00000000"], ["72844.98000000", "0.06200000"], ["72845.75000000", "0.05400000"], ["72860.54000000", "0.57563000"], ["72868.18000000", "2.74865000"], ["72949.11000000", "0.00000000"], ["72952.03000000", "0.00000000"], ["72991.68000000", "0.07687000"], ["73033.79000000", "4.11286000"], ["81350.56000000", "0.00087000"]], "_local_ts_utc": "2026-06-01T07:48:48.510668+00:00"}
{"e": "depthUpdate", "E": 1780300129714, "s": "BTCUSDT", "U": 94551750414, "u": 94551750564, "b": [["72760.00000000", "0.46608000"], ["72759.08000000", "0.00008000"], ["72757.96000000", "0.00000000"], ["72757.06000000", "0.00000000"], ["72756.70000000", "0.00000000"], ["72756.18000000", "0.00000000"], ["72755.94000000", "0.00000000"], ["72755.78000000", "0.01598000"], ["72755.61000000", "0.00016000"], ["72755.60000000", "0.19324000"], ["72755.59000000", "0.00000000"], ["72755.02000000", "0.00000000"], ["72754.74000000", "0.00000000"], ["72754.71000000", "0.00000000"], ["72754.12000000", "0.00000000"], ["72752.65000000", "0.00032000"], ["72751.26000000", "0.00000000"], ["72751.18000000", "0.00000000"], ["72751.01000000", "0.89097000"], ["72750.01000000", "0.65957000"], ["72746.77000000", "0.00000000"], ["72745.46000000", "1.00480000"], ["72742.65000000", "0.00007000"], ["72741.55000000", "0.00000000"], ["72738.00000000", "0.02280000"], ["72725.99000000", "0.00000000"], ["72719.65000000", "0.13241000"], ["72717.37000000", "0.18519000"], ["72714.64000000", "0.00000000"], ["72713.98000000", "0.00000000"], ["72712.79000000", "0.49572000"], ["72702.67000000", "0.17407000"], ["72701.97000000", "0.00000000"], ["72701.75000000", "0.18531000"], ["72689.96000000", "0.00000000"], ["72677.95000000", "0.00000000"], ["72665.93000000", "0.00000000"], ["72641.51000000", "2.44571000"], ["72603.57000000", "0.00100000"], ["72463.32000000", "4.14523000"], ["72437.43000000", "0.00000000"], ["72399.85000000", "0.00100000"], ["65486.00000000", "0.00152000"], ["65484.00000000", "0.00139000"]], "a": [["72760.01000000", "5.15176000"], ["72760.36000000", "0.00000000"], ["72760.59000000", "0.04556000"], ["72761.29000000", "0.00000000"], ["72761.48000000", "0.16810000"], ["72762.01000000", "0.00000000"], ["72762.02000000", "0.00000000"], ["72762.15000000", "0.00028000"], ["72762.79000000", "0.83234000"], ["72762.80000000", "0.71668000"], ["72762.81000000", "0.11136000"], ["72762.83000000", "0.15193000"], ["72763.02000000", "0.00000000"], ["72763.10000000", "0.00703000"], ["72763.28000000", "0.00016000"], ["72763.66000000", "0.18519000"], ["72763.67000000", "0.12016000"], ["72763.80000000", "0.18334000"], ["72764.19000000", "0.00000000"], ["72765.89000000", "0.18519000"], ["72767.13000000", "0.00000000"], ["72767.36000000", "0.17939000"], ["72768.04000000", "0.00746000"], ["72768.32000000", "0.57297000"], ["72768.71000000", "0.04164000"], ["72771.68000000", "0.00760000"], ["72771.76000000", "0.00007000"], ["72773.10000000", "0.00400000"], ["72774.02000000", "0.00000000"], ["72774.57000000", "0.00000000"], ["72779.92000000", "1.39920000"], ["72779.93000000", "2.74865000"], ["72779.94000000", "0.00036000"], ["72779.95000000", "0.00000000"], ["72779.96000000", "0.00008000"], ["72780.00000000", "0.13208000"], ["72780.93000000", "1.36195000"], ["72781.94000000", "0.18334000"], ["72781.95000000", "0.00000000"], ["72782.00000000", "0.68229000"], ["72782.90000000", "0.49524000"], ["72784.74000000", "0.00000000"], ["72786.03000000", "0.00000000"], ["72798.04000000", "0.00000000"], ["72805.51000000", "0.00000000"], ["72807.32000000", "0.00100000"], ["72807.41000000", "0.00000000"], ["72810.06000000", "0.00000000"], ["72822.08000000", "0.00000000"], ["72834.09000000", "0.00000000"], ["72837.59000000", "0.00000000"], ["72846.10000000", "0.00000000"], ["72858.11000000", "0.00000000"], ["72868.18000000", "0.00000000"], ["72870.12000000", "0.00000000"], ["72882.13000000", "0.00000000"], ["72894.14000000", "0.00000000"], ["72906.16000000", "0.00000000"], ["72918.17000000", "0.00000000"], ["72930.18000000", "0.00000000"], ["72942.19000000", "0.00000000"], ["72954.20000000", "0.00000000"], ["72966.21000000", "0.00000000"], ["72978.22000000", "0.00000000"], ["72990.23000000", "0.00000000"], ["73002.24000000", "0.00000000"], ["73014.25000000", "0.00000000"], ["73026.27000000", "0.00000000"], ["73039.38000000", "0.00000000"], ["73123.74000000", "0.00000000"]], "_local_ts_utc": "2026-06-01T07:48:48.610689+00:00"}
{"e": "depthUpdate", "E": 1780300129814, "s": "BTCUSDT", "U": 94551750565, "u": 94551750648, "b": [["72760.00000000", "0.46208000"], ["72756.00000000", "0.02304000"], ["72755.98000000", "0.00031000"], ["72755.79000000", "0.00016000"], ["72755.60000000", "0.14292000"], ["72755.40000000", "0.00031000"], ["72754.95000000", "0.00000000"], ["72752.97000000", "0.00000000"], ["72752.79000000", "0.05942000"], ["72739.65000000", "0.01375000"], ["72737.50000000", "0.00000000"], ["72734.31000000", "0.01375000"], ["72731.27000000", "0.00000000"], ["72728.83000000", "0.00200000"], ["72719.65000000", "0.18302000"], ["72718.84000000", "0.18519000"], ["72561.24000000", "0.00000000"], ["72552.59000000", "0.00822000"], ["72035.18000000", "0.00000000"], ["72032.39000000", "0.00007000"], ["65484.00000000", "0.00173000"]], "a": [["72760.01000000", "5.21118000"], ["72760.59000000", "0.04572000"], ["72761.48000000", "0.16826000"], ["72762.78000000", "1.17892000"], ["72762.79000000", "0.83250000"], ["72762.80000000", "0.00024000"], ["72762.82000000", "2.12844000"], ["72763.10000000", "0.00703000"], ["72763.28000000", "0.00000000"], ["72763.66000000", "0.46141000"], ["72763.67000000", "0.12000000"], ["72763.80000000", "0.00008000"], ["72779.91000000", "1.98742000"], ["72779.92000000", "0.00036000"], ["72779.94000000", "0.00000000"], ["72781.94000000", "0.00000000"], ["72784.00000000", "0.02280000"], ["72785.00000000", "0.00000000"], ["72785.97000000", "0.00008000"], ["72786.00000000", "0.02280000"], ["72787.04000000", "0.00200000"], ["72789.49000000", "0.00000000"], ["72844.98000000", "0.00000000"], ["72865.14000000", "0.00000000"], ["72869.53000000", "0.12817000"], ["72880.56000000", "0.00000000"], ["72947.48000000", "0.00000000"], ["73487.62000000", "0.00007000"], ["73490.45000000", "0.00000000"]], "_local_ts_utc": "2026-06-01T07:48:48.710669+00:00"}
{"e": "depthUpdate", "E": 1780300129914, "s": "BTCUSDT", "U": 94551750649, "u": 94551750691, "b": [["72760.00000000", "0.41453000"], ["72757.23000000", "0.00000000"], ["72755.98000000", "0.00000000"], ["72755.61000000", "0.00000000"], ["72755.40000000", "0.00000000"], ["72743.72000000", "0.14670000"], ["72734.31000000", "0.00000000"], ["72730.89000000", "0.01371000"], ["72721.51000000", "0.00018000"], ["72720.31000000", "0.18519000"], ["65484.00000000", "0.00207000"], ["58208.00000000", "0.00000000"]], "a": [["72760.01000000", "5.30755000"], ["72761.48000000", "0.16826000"], ["72762.78000000", "1.17908000"], ["72762.79000000", "0.83250000"], ["72762.80000000", "0.00008000"], ["72779.91000000", "1.98778000"], ["72779.92000000", "0.00000000"], ["72789.12000000", "0.01371000"], ["72790.02000000", "0.00000000"], ["72791.74000000", "0.00000000"], ["72874.95000000", "0.02153000"], ["81514.80000000", "0.00052000"]], "_local_ts_utc": "2026-06-01T07:48:48.810342+00:00"}
{"e": "depthUpdate", "E": 1780300130014, "s": "BTCUSDT", "U": 94551750692, "u": 94551750744, "b": [["72760.00000000", "0.79051000"], ["72758.96000000", "0.00031000"], ["72758.89000000", "0.00031000"], ["72757.36000000", "0.00028000"], ["72755.91000000", "0.00000000"], ["72755.61000000", "0.00000000"], ["72751.18000000", "0.18519000"], ["72751.02000000", "0.18619000"], ["72747.45000000", "0.14736000"], ["72745.47000000", "0.18519000"], ["72743.72000000", "0.00000000"], ["72742.68000000", "0.01375000"], ["72727.66000000", "0.18519000"], ["72727.04000000", "0.18519000"], ["72724.47000000", "0.00400000"], ["72626.79000000", "0.00000000"], ["65484.00000000", "0.00224000"], ["58208.00000000", "0.00034000"]], "a": [["72760.01000000", "5.30083000"], ["72762.15000000", "0.00000000"], ["72762.78000000", "0.76825000"], ["72762.79000000", "0.17301000"], ["72762.83000000", "0.15123000"], ["72763.65000000", "0.00687000"], ["72763.66000000", "0.27622000"], ["72766.38000000", "0.00000000"], ["72768.30000000", "0.57292000"], ["72768.31000000", "0.65949000"], ["72768.32000000", "0.00008000"], ["72768.33000000", "0.00000000"], ["72777.82000000", "0.00008000"], ["72779.90000000", "0.00200000"], ["72779.91000000", "0.34300000"], ["72779.93000000", "0.00000000"], ["72780.92000000", "2.74876000"], ["72780.93000000", "0.00000000"], ["72788.59000000", "0.00200000"], ["72789.79000000", "0.00400000"], ["72796.20000000", "0.00000000"], ["72868.17000000", "0.30362000"], ["72868.18000000", "0.00000000"], ["72872.79000000", "0.00000000"], ["73032.66000000", "4.11292000"]], "_local_ts_utc": "2026-06-01T07:48:48.910888+00:00"}
{"e": "depthUpdate", "E": 1780300130114, "s": "BTCUSDT", "U": 94551750745, "u": 94551750816, "b": [["72760.00000000", "1.30606000"], ["72759.50000000", "0.00031000"], ["72759.23000000", "0.00031000"], ["72758.96000000", "0.00000000"], ["72758.91000000", "0.00000000"], ["72758.89000000", "0.00000000"], ["72757.36000000", "0.00000000"], ["72756.00000000", "0.02288000"], ["72755.89000000", "0.00016000"], ["72755.88000000", "0.02363000"], ["72755.79000000", "0.00000000"], ["72755.78000000", "0.00000000"], ["72749.04000000", "0.00400000"], ["72743.58000000", "0.00400000"], ["72739.94000000", "0.00400000"], ["72738.12000000", "0.00400000"], ["72736.30000000", "0.00400000"], ["72734.48000000", "0.00400000"], ["72732.66000000", "0.00400000"], ["72731.84000000", "0.00200000"], ["72730.84000000", "0.00400000"], ["72729.02000000", "0.00400000"], ["72728.83000000", "0.00000000"], ["72727.20000000", "0.00400000"], ["72725.38000000", "0.00400000"], ["72702.67000000", "0.00000000"], ["72701.47000000", "0.00432000"], ["72699.79000000", "0.00622000"], ["65484.00000000", "0.00258000"]], "a": [["72760.01000000", "5.28952000"], ["72760.59000000", "0.00016000"], ["72762.67000000", "0.05286000"], ["72763.10000000", "0.00703000"], ["72763.60000000", "0.00400000"], ["72765.42000000", "0.00400000"], ["72767.24000000", "0.00400000"], ["72769.06000000", "0.00400000"], ["72770.88000000", "0.00400000"], ["72772.70000000", "0.00400000"], ["72774.52000000", "0.00400000"], ["72776.34000000", "0.00400000"], ["72779.90000000", "0.00254000"], ["72779.91000000", "1.11934000"], ["72787.04000000", "0.00000000"], ["72790.06000000", "0.00200000"], ["72790.90000000", "0.00400000"], ["72796.08000000", "0.00432000"], ["72845.75000000", "0.00000000"], ["72868.17000000", "0.00000000"], ["72874.95000000", "0.00000000"], ["72935.99000000", "0.07500000"], ["77854.72000000", "0.00000000"], ["85045.16000000", "0.00057000"]], "_local_ts_utc": "2026-06-01T07:48:49.010838+00:00"}
{"e": "depthUpdate", "E": 1780300130214, "s": "BTCUSDT", "U": 94551750817, "u": 94551750857, "b": [["72760.00000000", "1.12863000"], ["72759.52000000", "0.00000000"], ["72759.50000000", "0.00000000"], ["72759.23000000", "0.00000000"], ["72758.21000000", "0.00031000"], ["72755.92000000", "0.00016000"], ["72755.91000000", "0.02202000"], ["72755.89000000", "0.00000000"], ["72755.88000000", "0.00000000"], ["72755.61000000", "0.00008000"], ["72752.68000000", "0.00400000"], ["72725.38000000", "0.00000000"], ["72694.38000000", "0.00000000"], ["72682.83000000", "0.82587000"], ["72604.23000000", "6.60323000"], ["65484.00000000", "0.00292000"], ["58208.00000000", "0.00000000"]], "a": [["72760.01000000", "5.29022000"], ["72760.59000000", "0.00000000"], ["72760.76000000", "0.03603000"], ["72761.48000000", "0.16826000"], ["72762.00000000", "0.00016000"], ["72762.67000000", "0.00016000"], ["72828.33000000", "0.82587000"]], "_local_ts_utc": "2026-06-01T07:48:49.110284+00:00"}
{"e": "depthUpdate", "E": 1780300130314, "s": "BTCUSDT", "U": 94551750858, "u": 94551750947, "b": [["72760.00000000", "2.65953000"], ["72759.07000000", "0.00000000"], ["72758.46000000", "0.00039000"], ["72758.24000000", "0.00031000"], ["72758.21000000", "0.00000000"], ["72757.02000000", "0.00028000"], ["72756.00000000", "0.02304000"], ["72755.97000000", "0.00000000"], ["72755.96000000", "0.00016000"], ["72755.95000000", "0.00000000"], ["72755.92000000", "0.00000000"], ["72755.91000000", "0.00000000"], ["72755.61000000", "0.00016000"], ["72752.65000000", "0.18551000"], ["72751.34000000", "0.14652000"], ["72747.45000000", "0.00000000"], ["72742.68000000", "0.00000000"], ["65484.00000000", "0.00326000"], ["58208.00000000", "0.00000000"]], "a": [["72760.01000000", "5.16484000"], ["72760.76000000", "0.00016000"], ["72760.77000000", "0.00000000"], ["72761.47000000", "0.00016000"], ["72761.48000000", "0.16826000"], ["72762.67000000", "0.00000000"], ["72762.68000000", "0.00016000"], ["72762.69000000", "0.00000000"], ["72762.77000000", "0.00016000"], ["72762.78000000", "0.76841000"], ["72762.79000000", "0.00016000"], ["72763.45000000", "0.05172000"], ["72763.65000000", "0.00000000"], ["72765.62000000", "0.00000000"], ["72765.89000000", "0.00000000"], ["72767.13000000", "0.00687000"], ["72767.36000000", "0.00000000"], ["72768.70000000", "0.00000000"], ["72780.41000000", "0.00000000"], ["72787.60000000", "0.00200000"], ["72788.59000000", "0.00000000"], ["72820.93000000", "0.00000000"], ["72900.00000000", "0.05969000"]], "_local_ts_utc": "2026-06-01T07:48:49.210797+00:00"}
{"e": "depthUpdate", "E": 1780300130414, "s": "BTCUSDT", "U": 94551750948, "u": 94551751061, "b": [["72760.00000000", "2.61865000"], ["72758.24000000", "0.00000000"], ["72756.00000000", "0.02288000"], ["72755.96000000", "0.00000000"], ["72755.24000000", "0.03537000"], ["72751.34000000", "0.00000000"], ["72751.06000000", "0.01375000"], ["72747.00000000", "0.03333000"], ["72746.77000000", "0.18513000"], ["72735.53000000", "0.00349000"], ["72733.81000000", "0.00000000"], ["72731.84000000", "0.00000000"], ["72731.81000000", "0.00200000"], ["72727.66000000", "0.00000000"], ["72718.84000000", "0.00000000"], ["72716.09000000", "0.00000000"], ["72697.35000000", "0.02000000"], ["65484.00000000", "0.00360000"]], "a": [["72760.01000000", "5.16297000"], ["72760.76000000", "0.00000000"], ["72761.09000000", "0.00031000"], ["72761.47000000", "0.00000000"], ["72761.48000000", "0.00016000"], ["72762.68000000", "0.00000000"], ["72762.77000000", "0.18519000"], ["72762.78000000", "0.76825000"], ["72762.79000000", "0.00000000"], ["72762.80000000", "0.00008000"], ["72762.81000000", "0.11136000"], ["72762.82000000", "2.12813000"], ["72763.10000000", "0.00016000"], ["72763.45000000", "0.05188000"], ["72763.65000000", "0.00000000"], ["72763.66000000", "0.27638000"], ["72763.80000000", "0.00008000"], ["72766.22000000", "0.00687000"], ["72767.36000000", "0.18519000"], ["72768.29000000", "0.18519000"], ["72771.27000000", "0.00187000"], ["72773.10000000", "0.00000000"], ["72778.20000000", "0.00400000"], ["72790.03000000", "0.00200000"], ["72790.06000000", "0.00000000"], ["72826.66000000", "0.07428000"], ["73414.84000000", "0.00010000"], ["85780.87000000", "0.00028000"]], "_local_ts_utc": "2026-06-01T07:48:49.310559+00:00"}
{"e": "depthUpdate", "E": 1780300130514, "s": "BTCUSDT", "U": 94551751062, "u": 94551751146, "b": [["72760.00000000", "0.87435000"], ["72758.46000000", "0.00008000"], ["72757.67000000", "0.00000000"], ["72757.02000000", "0.00000000"], ["72756.38000000", "0.00031000"], ["72755.97000000", "0.02140000"], ["72755.24000000", "0.00000000"], ["72752.65000000", "0.00032000"], ["72746.77000000", "0.00000000"], ["72727.09000000", "0.00400000"], ["72724.47000000", "0.00000000"], ["65484.00000000", "0.00394000"], ["58208.00000000", "0.00034000"]], "a": [["72760.01000000", "5.15251000"], ["72760.75000000", "0.03627000"], ["72761.48000000", "0.18505000"], ["72762.00000000", "0.00008000"], ["72762.76000000", "0.65957000"], ["72762.77000000", "0.18535000"], ["72762.80000000", "0.00000000"], ["72762.81000000", "0.11144000"], ["72762.83000000", "0.15123000"], ["72763.10000000", "0.00000000"], ["72763.45000000", "0.00016000"], ["72763.67000000", "0.12016000"], ["72763.79000000", "0.00000000"], ["72764.84000000", "0.00007000"], ["72765.89000000", "0.18349000"], ["72767.14000000", "0.00000000"], ["72767.19000000", "0.00008000"], ["72767.35000000", "0.00008000"], ["72768.30000000", "0.57300000"], ["72768.69000000", "0.00000000"], ["72770.05000000", "0.00008000"], ["72771.72000000", "0.00008000"], ["72773.03000000", "0.00000000"], ["72774.70000000", "0.00008000"], ["72775.02000000", "0.00000000"], ["72776.99000000", "0.18526000"], ["72777.13000000", "0.00000000"], ["72777.37000000", "0.00008000"], ["72777.82000000", "0.18505000"], ["72778.57000000", "0.00000000"], ["72779.90000000", "0.00062000"], ["72779.96000000", "0.00000000"], ["72780.45000000", "0.00000000"], ["72780.91000000", "0.00008000"], ["72781.11000000", "0.00000000"], ["72782.89000000", "0.00008000"], ["72785.97000000", "0.00000000"], ["72789.79000000", "0.00000000"], ["72792.34000000", "0.00400000"], ["72794.95000000", "0.00000000"], ["72800.42000000", "0.00008000"], ["72834.86000000", "0.00007000"]], "_local_ts_utc": "2026-06-01T07:48:49.410386+00:00"}
{"e": "depthUpdate", "E": 1780300130614, "s": "BTCUSDT", "U": 94551751147, "u": 94551751202, "b": [["72760.00000000", "0.87435000"], ["72759.18000000", "0.00095000"], ["72759.08000000", "0.00123000"], ["72758.18000000", "0.00031000"], ["72757.91000000", "0.00031000"], ["72756.60000000", "0.00000000"], ["72756.38000000", "0.00000000"], ["72756.00000000", "0.02304000"], ["72755.98000000", "0.00016000"], ["72755.61000000", "0.00000000"], ["72753.85000000", "0.00739000"], ["72746.33000000", "0.18764000"], ["72730.50000000", "0.00199000"], ["66095.00000000", "0.00756000"], ["65484.00000000", "0.00428000"], ["58208.00000000", "0.00000000"]], "a": [["72760.01000000", "5.10175000"], ["72760.75000000", "0.03643000"], ["72761.48000000", "0.18521000"], ["72762.34000000", "0.00028000"], ["72762.76000000", "0.65973000"], ["72762.83000000", "0.15123000"], ["72763.45000000", "0.00000000"], ["72763.66000000", "0.27622000"], ["72763.67000000", "0.12000000"], ["72771.27000000", "0.00000000"], ["72774.56000000", "0.00008000"], ["72776.29000000", "0.00200000"], ["72784.42000000", "0.00200000"], ["72786.28000000", "0.00008000"], ["72787.60000000", "0.00000000"], ["72788.40000000", "0.00199000"], ["72950.54000000", "0.10000000"], ["73001.48000000", "0.09586000"]], "_local_ts_utc": "2026-06-01T07:48:49.510516+00:00"}
{"e": "depthUpdate", "E": 1780300130714, "s": "BTCUSDT", "U": 94551751203, "u": 94551751282, "b": [["72760.00000000", "2.05745000"], ["72759.90000000", "0.00031000"], ["72758.53000000", "0.00031000"], ["72758.45000000", "0.00031000"], ["72758.18000000", "0.00000000"], ["72757.91000000", "0.00000000"], ["72756.00000000", "0.02288000"], ["72755.98000000", "0.00000000"], ["72755.97000000", "0.00000000"], ["72755.82000000", "0.00016000"], ["72755.81000000", "0.02746000"], ["72755.61000000", "0.00000000"], ["72740.91000000", "0.01376000"], ["72727.66000000", "0.17950000"], ["72702.67000000", "0.18505000"], ["72697.04000000", "0.26000000"], ["72647.76000000", "0.02153000"], ["72500.39000000", "0.00712000"], ["65484.00000000", "0.00445000"]], "a": [["72760.01000000", "5.10215000"], ["72760.74000000", "0.00000000"], ["72760.75000000", "0.00016000"], ["72761.47000000", "0.00016000"], ["72762.75000000", "0.00016000"], ["72762.76000000", "0.65989000"], ["72762.77000000", "0.18551000"], ["72762.80000000", "0.00008000"], ["72762.90000000", "0.05024000"], ["72765.89000000", "0.00000000"], ["72776.99000000", "0.00008000"], ["72777.82000000", "0.00000000"], ["72788.01000000", "0.00014000"], ["86269.38000000", "0.00020000"]], "_local_ts_utc": "2026-06-01T07:48:49.610243+00:00"}
{"e": "depthUpdate", "E": 1780300130814, "s": "BTCUSDT", "U": 94551751283, "u": 94551751331, "b": [["72760.00000000", "2.62546000"], ["72758.53000000", "0.00000000"], ["72758.45000000", "0.00000000"], ["72755.82000000", "0.00000000"], ["72755.81000000", "0.00000000"], ["72755.61000000", "0.00016000"], ["72755.25000000", "0.03610000"], ["72742.65000000", "0.00007000"], ["72512.88000000", "0.00575000"], ["65484.00000000", "0.00462000"], ["47294.01000000", "0.00013000"]], "a": [["72760.01000000", "4.50044000"], ["72760.75000000", "0.00000000"], ["72761.27000000", "0.00008000"], ["72762.83000000", "0.15123000"], ["72762.90000000", "0.00016000"], ["72763.57000000", "0.05225000"], ["72770.06000000", "0.00000000"], ["72770.76000000", "0.00191000"], ["72771.76000000", "0.00007000"], ["72776.29000000", "0.00000000"], ["72807.41000000", "0.26000000"]], "_local_ts_utc": "2026-06-01T07:48:49.710507+00:00"}
{"e": "depthUpdate", "E": 1780300130914, "s": "BTCUSDT", "U": 94551751332, "u": 94551751363, "b": [["72760.00000000", "2.62420000"], ["72759.99000000", "0.00086000"], ["72759.98000000", "0.00064000"], ["72525.37000000", "0.00575000"], ["65484.00000000", "0.00462000"], ["58208.00000000", "0.00000000"]], "a": [["72760.01000000", "4.50303000"], ["72762.83000000", "0.14862000"], ["72762.90000000", "0.00000000"], ["72763.57000000", "0.05241000"], ["72782.45000000", "0.00200000"], ["72823.99000000", "0.55338000"], ["86757.89000000", "0.00019000"]], "_local_ts_utc": "2026-06-01T07:48:49.812531+00:00"}
{"e": "depthUpdate", "E": 1780300131014, "s": "BTCUSDT", "U": 94551751364, "u": 94551751398, "b": [["72760.00000000", "2.63377000"], ["72759.99000000", "0.00094000"], ["72759.90000000", "0.00000000"], ["72758.83000000", "0.00031000"], ["72758.70000000", "0.00031000"], ["72758.13000000", "0.00031000"], ["72756.32000000", "0.00400000"], ["72732.37000000", "0.00200000"], ["72731.81000000", "0.00000000"], ["72727.20000000", "0.00000000"], ["72537.86000000", "0.00936000"], ["65484.00000000", "0.00462000"], ["58208.00000000", "0.00034000"]], "a": [["72762.75000000", "0.00000000"], ["72762.76000000", "0.65973000"], ["72762.77000000", "0.18535000"], ["72762.80000000", "0.00000000"], ["72790.03000000", "0.00000000"], ["72790.59000000", "0.00200000"]], "_local_ts_utc": "2026-06-01T07:48:49.914720+00:00"}
{"e": "depthUpdate", "E": 1780300131114, "s": "BTCUSDT", "U": 94551751399, "u": 94551751499, "b": [["72760.00000000", "2.47611000"], ["72759.99000000", "0.00102000"], ["72758.70000000", "0.00000000"], ["72758.62000000", "0.00043000"], ["72758.61000000", "0.01375000"], ["72758.14000000", "0.00400000"], ["72758.13000000", "0.00000000"], ["72757.12000000", "0.00028000"], ["72756.27000000", "0.00016000"], ["72756.26000000", "0.05942000"], ["72755.61000000", "0.00000000"], ["72755.60000000", "0.37571000"], ["72754.12000000", "0.18505000"], ["72753.37000000", "0.65949000"], ["72752.79000000", "0.00000000"], ["72752.65000000", "0.18537000"], ["72750.20000000", "0.16743000"], ["72746.77000000", "0.00000000"], ["72746.33000000", "0.00000000"], ["72729.02000000", "0.00000000"], ["72727.66000000", "0.00000000"], ["72727.04000000", "0.00000000"], ["72718.84000000", "0.00000000"], ["72702.67000000", "0.00000000"], ["72555.01000000", "0.00822000"], ["72552.59000000", "0.00000000"], ["72550.35000000", "0.00575000"], ["65484.00000000", "0.00462000"], ["58208.00000000", "0.00634000"]], "a": [["72760.01000000", "4.19666000"], ["72760.37000000", "0.00031000"], ["72761.09000000", "0.00000000"], ["72761.47000000", "0.00000000"], ["72761.48000000", "0.00016000"], ["72762.34000000", "0.00000000"], ["72762.75000000", "0.00000000"], ["72762.76000000", "0.00024000"], ["72762.77000000", "0.00016000"], ["72762.80000000", "0.00000000"], ["72762.81000000", "0.00024000"], ["72763.26000000", "0.05942000"], ["72763.60000000", "0.00000000"], ["72763.65000000", "0.00000000"], ["72763.80000000", "0.00008000"], ["72767.36000000", "0.00000000"], ["72768.27000000", "0.52062000"], ["72768.28000000", "0.65949000"], ["72768.30000000", "0.00008000"], ["72768.31000000", "0.00000000"], ["72771.46000000", "0.44769000"], ["72771.47000000", "0.65949000"], ["72771.49000000", "0.00008000"], ["72771.50000000", "0.00000000"], ["72796.36000000", "0.00400000"]], "_local_ts_utc": "2026-06-01T07:48:50.010453+00:00"}
{"e": "depthUpdate", "E": 1780300131214, "s": "BTCUSDT", "U": 94551751500, "u": 94551751579, "b": [["72760.00000000", "2.47604000"], ["72759.99000000", "0.00110000"], ["72758.83000000", "0.00000000"], ["72758.76000000", "0.00031000"], ["72758.61000000", "0.01391000"], ["72758.00000000", "0.02296000"], ["72757.12000000", "0.00000000"], ["72756.20000000", "0.04123000"], ["72754.12000000", "0.00000000"], ["72750.20000000", "0.00000000"], ["72562.84000000", "0.00574000"], ["65484.00000000", "0.00479000"], ["58208.00000000", "0.00000000"]], "a": [["72760.01000000", "4.19666000"], ["72760.75000000", "0.05942000"], ["72761.48000000", "0.18505000"], ["72762.76000000", "0.00008000"], ["72762.77000000", "0.18505000"], ["72762.78000000", "0.76825000"], ["72762.81000000", "0.00008000"], ["72762.83000000", "0.14862000"], ["72763.26000000", "0.00016000"], ["72763.65000000", "0.00000000"], ["72763.66000000", "0.27638000"], ["72763.67000000", "0.12016000"], ["72763.80000000", "0.00008000"], ["72763.81000000", "0.50069000"], ["72767.36000000", "0.18505000"], ["72770.06000000", "0.18505000"], ["72776.99000000", "0.18513000"], ["87246.40000000", "0.00020000"]], "_local_ts_utc": "2026-06-01T07:48:50.110493+00:00"}
{"e": "depthUpdate", "E": 1780300131314, "s": "BTCUSDT", "U": 94551751580, "u": 94551751621, "b": [["72758.78000000", "0.00031000"], ["72756.26000000", "0.05958000"], ["72752.65000000", "0.00032000"], ["72732.81000000", "0.00200000"], ["72732.37000000", "0.00000000"], ["72696.41000000", "0.02000000"], ["72575.33000000", "0.00574000"], ["65484.00000000", "0.00479000"], ["58208.00000000", "0.00200000"]], "a": [["72760.01000000", "4.19666000"], ["72760.75000000", "0.05958000"], ["72761.48000000", "0.18521000"], ["72762.77000000", "0.18521000"], ["72762.83000000", "0.14862000"], ["72763.26000000", "0.00000000"], ["72763.67000000", "0.12000000"], ["72763.81000000", "0.50053000"], ["72779.78000000", "0.08600000"], ["72779.83000000", "0.07400000"], ["72782.43000000", "0.06200000"], ["72790.59000000", "0.00000000"], ["72791.03000000", "0.00200000"], ["72794.54000000", "0.00400000"], ["72796.36000000", "0.00000000"], ["72865.82000000", "0.00275000"], ["72918.24000000", "0.00000000"]], "_local_ts_utc": "2026-06-01T07:48:50.210186+00:00"}
{"e": "depthUpdate", "E": 1780300131414, "s": "BTCUSDT", "U": 94551751622, "u": 94551751666, "b": [["72760.00000000", "1.90664000"], ["72758.78000000", "0.00000000"], ["72758.76000000", "0.00000000"], ["72758.61000000", "0.00016000"], ["72758.54000000", "0.00926000"], ["72757.64000000", "0.00031000"], ["72756.27000000", "0.00000000"], ["72756.26000000", "0.00000000"], ["72755.61000000", "0.00008000"], ["72753.16000000", "0.05942000"], ["72751.18000000", "0.00000000"], ["72751.02000000", "0.00100000"], ["72747.57000000", "0.15812000"], ["72727.09000000", "0.00000000"], ["72726.90000000", "0.00400000"], ["72587.82000000", "0.00574000"], ["65484.00000000", "0.00479000"], ["58208.00000000", "0.00000000"]], "a": [["72763.65000000", "0.18505000"], ["72765.89000000", "0.18505000"], ["72777.82000000", "0.16983000"], ["72779.50000000", "0.01288000"], ["72779.78000000", "0.08690000"], ["72779.79000000", "0.08600000"], ["72779.90000000", "0.00008000"], ["72781.96000000", "0.62817000"], ["72782.45000000", "0.00000000"], ["72791.84000000", "0.00400000"], ["72792.34000000", "0.00000000"], ["72792.72000000", "0.00400000"], ["72792.76000000", "0.00000000"], ["72794.54000000", "0.00000000"], ["72826.62000000", "0.00000000"], ["72844.86000000", "0.00000000"]], "_local_ts_utc": "2026-06-01T07:48:50.310671+00:00"}
{"e": "depthUpdate", "E": 1780300131514, "s": "BTCUSDT", "U": 94551751667, "u": 94551751850, "b": [["72760.00000000", "0.07206000"], ["72759.99000000", "0.00102000"], ["72758.62000000", "0.00027000"], ["72758.61000000", "0.00000000"], ["72758.54000000", "0.00942000"], ["72758.14000000", "0.00000000"], ["72758.00000000", "0.02296000"], ["72757.64000000", "0.00000000"], ["72756.58000000", "0.00000000"], ["72756.57000000", "0.00000000"], ["72756.48000000", "0.00000000"], ["72756.47000000", "0.00000000"], ["72756.20000000", "0.04139000"], ["72756.19000000", "0.00000000"], ["72755.71000000", "0.00000000"], ["72755.61000000", "0.00000000"], ["72755.60000000", "0.00606000"], ["72755.33000000", "0.00764000"], ["72755.25000000", "0.00000000"], ["72754.74000000", "0.00000000"], ["72754.55000000", "0.00009000"], ["72753.85000000", "0.00000000"], ["72753.37000000", "0.00000000"], ["72753.16000000", "0.00000000"], ["72752.74000000", "0.00031000"], ["72751.06000000", "0.00000000"], ["72747.57000000", "0.00000000"], ["72746.72000000", "0.05954000"], ["72745.47000000", "0.00000000"], ["72743.54000000", "0.01375000"], ["72740.91000000", "0.00000000"], ["72726.90000000", "0.00000000"], ["72725.38000000", "0.00400000"], ["72722.26000000", "0.27000000"], ["72721.66000000", "0.00000000"], ["72721.63000000", "0.00000000"], ["72721.61000000", "0.00400000"], ["72721.57000000", "0.00000000"], ["72720.31000000", "0.00000000"], ["72719.65000000", "0.08764000"], ["72717.24000000", "0.00000000"], ["72715.90000000", "0.18505000"], ["72698.08000000", "0.00035000"], ["72693.14000000", "0.00007000"], ["72600.31000000", "0.00574000"], ["65484.00000000", "0.00479000"], ["58208.00000000", "0.00034000"], ["50932.00000000", "0.00000000"]], "a": [["72760.01000000", "4.38184000"], ["72760.71000000", "0.00000000"], ["72760.74000000", "0.00008000"], ["72761.01000000", "0.10211000"], ["72761.78000000", "0.00400000"], ["72762.35000000", "0.00028000"], ["72762.75000000", "0.00008000"], ["72762.76000000", "0.65949000"], ["72762.81000000", "0.00008000"], ["72763.57000000", "0.00016000"], ["72763.60000000", "0.00400000"], ["72763.65000000", "0.18521000"], ["72763.66000000", "0.27622000"], ["72765.22000000", "0.03407000"], ["72765.58000000", "0.00737000"], ["72766.22000000", "0.00695000"], ["72767.13000000", "0.00000000"], ["72767.19000000", "0.00000000"], ["72768.27000000", "0.52070000"], ["72768.30000000", "0.00000000"], ["72770.05000000", "0.00000000"], ["72770.76000000", "0.00000000"], ["72771.46000000", "0.44777000"], ["72771.47000000", "0.65957000"], ["72771.49000000", "0.00000000"], ["72771.72000000", "0.00000000"], ["72772.11000000", "0.00400000"], ["72773.23000000", "0.00008000"], ["72774.70000000", "0.00000000"], ["72776.99000000", "0.18505000"], ["72777.37000000", "0.00000000"], ["72778.20000000", "0.00000000"], ["72779.50000000", "0.01774000"], ["72779.51000000", "0.00011000"], ["72779.68000000", "0.00007000"], ["72779.76000000", "0.00008000"], ["72779.77000000", "0.17851000"], ["72779.78000000", "0.08600000"], ["72780.17000000", "1.36197000"], ["72780.91000000", "0.18513000"], ["72781.92000000", "0.00200000"], ["72782.07000000", "0.00228000"], ["72784.42000000", "0.00000000"], ["72785.97000000", "0.17356000"], ["72786.09000000", "0.00200000"], ["72787.26000000", "2.75273000"], ["72788.29000000", "0.00000000"], ["72788.40000000", "0.00000000"], ["72789.34000000", "0.00000000"], ["72790.12000000", "0.00000000"], ["72790.16000000", "0.00000000"], ["72790.90000000", "0.00000000"], ["72792.72000000", "0.00000000"], ["72795.53000000", "0.00000000"], ["72800.42000000", "0.00000000"], ["73033.79000000", "0.00000000"]], "_local_ts_utc": "2026-06-01T07:48:50.410350+00:00"}
{"e": "depthUpdate", "E": 1780300131614, "s": "BTCUSDT", "U": 94551751851, "u": 94551752007, "b": [["72760.00000000", "0.20492000"], ["72759.99000000", "0.00094000"], ["72756.32000000", "0.00000000"], ["72756.20000000", "0.04139000"], ["72755.52000000", "0.01132000"], ["72755.33000000", "0.00000000"], ["72755.17000000", "0.00031000"], ["72755.01000000", "0.12032000"], ["72754.73000000", "0.00031000"], ["72753.35000000", "0.00000000"], ["72753.07000000", "0.00000000"], ["72752.74000000", "0.00000000"], ["72750.14000000", "0.01375000"], ["72747.33000000", "0.00000000"], ["72732.81000000", "0.00000000"], ["72729.02000000", "0.00400000"], ["72728.36000000", "0.00200000"], ["72727.04000000", "0.18505000"], ["72723.73000000", "0.00000000"], ["72723.59000000", "0.00000000"], ["72723.57000000", "0.00480000"], ["72723.54000000", "0.00000000"], ["72723.01000000", "0.00000000"], ["72722.70000000", "0.00000000"], ["72722.69000000", "0.37510000"], ["72722.60000000", "0.00000000"], ["72722.56000000", "0.00000000"], ["72722.54000000", "0.00216000"], ["72722.53000000", "0.00000000"], ["72722.52000000", "0.00120000"], ["72722.51000000", "0.00000000"], ["72722.50000000", "0.00028000"], ["72722.49000000", "0.02000000"], ["72721.83000000", "0.00000000"], ["72721.81000000", "0.00000000"], ["72721.79000000", "0.00000000"], ["72721.76000000", "0.00000000"], ["72721.75000000", "0.00000000"], ["72721.61000000", "0.00000000"], ["72720.31000000", "0.18505000"], ["72719.65000000", "0.07389000"], ["72718.84000000", "0.18505000"], ["72702.67000000", "0.18505000"], ["72697.04000000", "0.00000000"], ["72612.80000000", "0.00574000"], ["72547.32000000", "0.00007000"], ["72543.83000000", "0.00007000"], ["65484.00000000", "0.00479000"], ["58208.00000000", "0.00000000"]], "a": [["72760.01000000", "4.44111000"], ["72760.75000000", "0.00016000"], ["72760.80000000", "0.00000000"], ["72761.01000000", "0.00016000"], ["72761.42000000", "0.07653000"], ["72761.48000000", "0.18521000"], ["72762.76000000", "0.65965000"], ["72762.83000000", "0.14862000"], ["72763.57000000", "0.00000000"], ["72763.65000000", "0.18505000"], ["72778.43000000", "0.06200000"], ["72779.20000000", "0.05400000"], ["72780.91000000", "0.00008000"], ["72785.97000000", "0.00000000"], ["72786.57000000", "0.00200000"], ["72791.03000000", "0.00000000"]], "_local_ts_utc": "2026-06-01T07:48:50.510837+00:00"}
{"e": "depthUpdate", "E": 1780300131714, "s": "BTCUSDT", "U": 94551752008, "u": 94551752057, "b": [["72760.00000000", "0.20500000"], ["72756.62000000", "0.00031000"], ["72755.24000000", "0.00031000"], ["72755.17000000", "0.00000000"], ["72754.73000000", "0.00000000"], ["72746.04000000", "0.16442000"], ["72745.47000000", "0.17558000"], ["72735.13000000", "0.01376000"], ["72723.57000000", "0.00080000"], ["72723.55000000", "0.00000000"], ["72723.54000000", "0.00000000"], ["72723.53000000", "0.00000000"], ["72723.52000000", "0.00000000"], ["72723.51000000", "0.00036000"], ["72723.31000000", "0.00400000"], ["72723.26000000", "0.00000000"], ["72625.29000000", "0.00574000"], ["65484.00000000", "0.00479000"]], "a": [["72760.01000000", "4.44385000"], ["72760.75000000", "0.00000000"], ["72761.01000000", "0.00000000"], ["72761.41000000", "0.40856000"], ["72761.42000000", "0.07669000"], ["72763.65000000", "0.18521000"], ["72788.57000000", "0.00000000"], ["72846.53000000", "0.44459000"], ["72882.98000000", "0.00000000"], ["87734.91000000", "0.00012000"]], "_local_ts_utc": "2026-06-01T07:48:50.610461+00:00"}
{"e": "depthUpdate", "E": 1780300131814, "s": "BTCUSDT", "U": 94551752058, "u": 94551752087, "b": [["72760.00000000", "0.19700000"], ["72756.73000000", "0.00031000"], ["72755.24000000", "0.00000000"], ["72749.56000000", "0.05942000"], ["72746.72000000", "0.00012000"], ["72742.65000000", "0.00007000"], ["72637.78000000", "0.00584000"], ["65484.00000000", "0.00479000"]], "a": [["72760.01000000", "4.44385000"], ["72761.27000000", "0.00000000"], ["72761.41000000", "0.40872000"], ["72763.65000000", "0.18505000"], ["72771.76000000", "0.00007000"], ["72772.11000000", "0.00000000"], ["72773.70000000", "0.00400000"], ["72786.10000000", "0.00000000"], ["72787.80000000", "0.00000000"], ["80036.01000000", "0.00007000"]], "_local_ts_utc": "2026-06-01T07:48:50.710502+00:00"}
{"e": "depthUpdate", "E": 1780300131914, "s": "BTCUSDT", "U": 94551752088, "u": 94551752109, "b": [["72760.00000000", "0.19692000"], ["72756.73000000", "0.00000000"], ["72756.62000000", "0.00000000"], ["72754.27000000", "0.00031000"], ["72748.62000000", "0.00070000"], ["72702.67000000", "0.00000000"], ["72650.27000000", "0.00574000"], ["65484.00000000", "0.00462000"], ["58208.00000000", "0.00000000"]], "a": [["72762.52000000", "0.01370000"], ["72778.00000000", "1.08085000"], ["72780.00000000", "0.13408000"], ["80036.01000000", "0.00000000"]], "_local_ts_utc": "2026-06-01T07:48:50.809502+00:00"}
{"e": "depthUpdate", "E": 1780300132014, "s": "BTCUSDT", "U": 94551752110, "u": 94551752143, "b": [["72760.00000000", "0.16712000"], ["72754.36000000", "0.00031000"], ["72727.04000000", "0.00000000"], ["72723.31000000", "0.00000000"], ["72722.78000000", "0.00400000"], ["72720.31000000", "0.00000000"], ["72662.76000000", "0.00574000"], ["65484.00000000", "0.00445000"], ["58208.00000000", "0.00034000"]], "a": [["72761.48000000", "0.18521000"], ["72762.52000000", "0.01386000"], ["72762.83000000", "0.14846000"], ["72779.51000000", "0.00029000"], ["72781.92000000", "0.00000000"], ["72787.63000000", "0.00400000"], ["72791.84000000", "0.00000000"], ["72837.50000000", "0.00000000"], ["87997.75000000", "0.00197000"]], "_local_ts_utc": "2026-06-01T07:48:50.910671+00:00"}
{"e": "depthUpdate", "E": 1780300132114, "s": "BTCUSDT", "U": 94551752144, "u": 94551752190, "b": [["72760.00000000", "0.05440000"], ["72755.52000000", "0.00000000"], ["72755.49000000", "0.01082000"], ["72754.36000000", "0.00000000"], ["72754.27000000", "0.00000000"], ["72754.01000000", "0.00000000"], ["72753.23000000", "0.00000000"], ["72752.79000000", "0.00031000"], ["72746.04000000", "0.00000000"], ["72745.47000000", "0.00000000"], ["72744.11000000", "0.18353000"], ["72743.54000000", "0.00000000"], ["72742.15000000", "0.00000000"], ["72739.65000000", "0.00000000"], ["72736.97000000", "0.01375000"], ["72720.31000000", "0.18505000"], ["72718.84000000", "0.18505000"], ["72702.67000000", "0.18505000"], ["72675.25000000", "0.00573000"], ["65484.00000000", "0.00465000"]], "a": [["72761.35000000", "0.07910000"], ["72761.42000000", "0.00016000"], ["72762.00000000", "0.00088000"], ["72778.26000000", "0.00000000"], ["72779.42000000", "0.00200000"], ["72821.49000000", "0.00686000"]], "_local_ts_utc": "2026-06-01T07:48:51.010165+00:00"}
{"e": "depthUpdate", "E": 1780300132214, "s": "BTCUSDT", "U": 94551752191, "u": 94551752311, "b": [["72760.00000000", "0.18634000"], ["72755.49000000", "0.01085000"], ["72755.27000000", "0.00011000"], ["72755.26000000", "0.00000000"], ["72755.17000000", "0.00031000"], ["72755.01000000", "0.00000000"], ["72754.55000000", "0.00040000"], ["72754.32000000", "0.00031000"], ["72753.64000000", "0.00000000"], ["72752.79000000", "0.00000000"], ["72750.02000000", "0.65949000"], ["72750.01000000", "0.00008000"], ["72749.68000000", "0.00047000"], ["72742.31000000", "0.01375000"], ["72735.13000000", "0.00000000"], ["72728.36000000", "0.00200000"], ["72727.04000000", "0.18505000"], ["72705.47000000", "0.00000000"], ["72693.14000000", "0.00436000"], ["72689.94000000", "0.00000000"], ["65484.00000000", "0.00428000"], ["58208.00000000", "0.00000000"]], "a": [["72760.01000000", "4.44256000"], ["72760.98000000", "0.00000000"], ["72761.35000000", "0.00016000"], ["72761.36000000", "0.07889000"], ["72761.37000000", "0.00000000"], ["72761.41000000", "0.40872000"], ["72761.42000000", "0.00000000"], ["72762.68000000", "0.00573000"], ["72763.23000000", "0.00738000"], ["72764.00000000", "0.00080000"], ["72786.57000000", "0.00200000"], ["87997.80000000", "0.00040000"]], "_local_ts_utc": "2026-06-01T07:48:51.110507+00:00"}
{"e": "depthUpdate", "E": 1780300132314, "s": "BTCUSDT", "U": 94551752312, "u": 94551752351, "b": [["72760.00000000", "0.18876000"], ["72756.15000000", "0.00000000"], ["72755.38000000", "0.00038000"], ["72754.55000000", "0.00009000"], ["72754.32000000", "0.00000000"], ["72722.96000000", "0.03132000"], ["72722.78000000", "0.00000000"], ["72707.93000000", "0.00000000"], ["72674.49000000", "0.00111000"], ["65484.00000000", "0.00428000"]], "a": [["72760.01000000", "4.44272000"], ["72761.35000000", "0.00000000"], ["72761.36000000", "0.07905000"], ["72762.52000000", "0.01386000"], ["72762.68000000", "0.00589000"], ["72762.82000000", "2.12797000"], ["72775.17000000", "0.00573000"], ["72787.63000000", "0.00000000"], ["72787.76000000", "0.00400000"], ["72935.99000000", "0.17500000"], ["72944.61000000", "0.00000000"], ["72950.54000000", "0.20000000"], ["72957.82000000", "0.10000000"], ["72959.17000000", "0.00000000"], ["72965.10000000", "0.10000000"], ["72966.44000000", "0.00000000"], ["72973.72000000", "0.00000000"]], "_local_ts_utc": "2026-06-01T07:48:51.210268+00:00"}
{"e": "depthUpdate", "E": 1780300132414, "s": "BTCUSDT", "U": 94551752352, "u": 94551752366, "b": [["72760.00000000", "0.18476000"], ["72755.93000000", "0.00031000"], ["72755.17000000", "0.00000000"], ["72745.18000000", "0.15701000"], ["65484.00000000", "0.00428000"]], "a": [["72760.01000000", "4.44243000"], ["72787.66000000", "0.00573000"], ["73414.84000000", "0.00000000"]], "_local_ts_utc": "2026-06-01T07:48:51.311832+00:00"}
{"e": "depthUpdate", "E": 1780300132514, "s": "BTCUSDT", "U": 94551752367, "u": 94551752403, "b": [["72760.00000000", "0.18492000"], ["72755.93000000", "0.00000000"], ["72755.38000000", "0.00007000"], ["72755.01000000", "0.00000000"], ["72728.36000000", "0.00000000"], ["72727.84000000", "0.00208000"], ["72671.57000000", "0.00000000"], ["65484.00000000", "0.00428000"], ["58208.00000000", "0.00034000"]], "a": [["72760.01000000", "4.75272000"], ["72760.74000000", "0.00000000"], ["72761.40000000", "0.00008000"], ["72761.47000000", "0.00008000"], ["72762.75000000", "0.00000000"], ["72762.77000000", "0.18529000"], ["72762.82000000", "1.81753000"], ["72765.88000000", "0.00008000"], ["72766.22000000", "0.00687000"], ["72771.47000000", "0.65949000"], ["72779.05000000", "0.00008000"], ["72779.68000000", "0.00025000"], ["72779.76000000", "0.00000000"], ["72780.16000000", "0.00008000"], ["72782.07000000", "0.00220000"], ["72786.05000000", "0.00200000"], ["72786.57000000", "0.00000000"], ["72787.26000000", "2.75265000"], ["72800.15000000", "0.00573000"], ["88223.42000000", "0.00022000"]], "_local_ts_utc": "2026-06-01T07:48:51.410196+00:00"}
{"e": "depthUpdate", "E": 1780300132614, "s": "BTCUSDT", "U": 94551752404, "u": 94551752428, "b": [["72760.00000000", "0.18092000"], ["72755.01000000", "0.12023000"], ["72754.87000000", "0.00031000"], ["72754.60000000", "0.00031000"], ["72745.45000000", "3.40821000"], ["72719.65000000", "0.13374000"], ["72716.35000000", "0.00102000"], ["72700.55000000", "0.00007000"], ["72690.66000000", "0.00007000"], ["65484.00000000", "0.00428000"], ["58208.00000000", "0.00000000"]], "a": [["72760.01000000", "4.75259000"], ["72774.00000000", "0.01080000"], ["72776.00000000", "0.92848000"], ["72779.42000000", "0.00000000"], ["72792.35000000", "0.20705000"], ["72812.64000000", "0.00573000"], ["72868.07000000", "0.00000000"]], "_local_ts_utc": "2026-06-01T07:48:51.510220+00:00"}
{"e": "depthUpdate", "E": 1780300132714, "s": "BTCUSDT", "U": 94551752429, "u": 94551752460, "b": [["72758.55000000", "0.00000000"], ["72757.73000000", "0.00000000"], ["72757.15000000", "0.00000000"], ["72755.01000000", "0.10648000"], ["72754.98000000", "0.00000000"], ["72754.89000000", "0.00031000"], ["72754.87000000", "0.00000000"], ["72754.60000000", "0.00000000"], ["72735.13000000", "0.01376000"], ["72727.66000000", "0.17752000"], ["72697.04000000", "0.26000000"], ["65484.00000000", "0.00428000"]], "a": [["72762.35000000", "0.00000000"], ["72773.37000000", "0.03807000"], ["72773.70000000", "0.00000000"], ["72778.41000000", "0.00200000"], ["72785.21000000", "0.00200000"], ["72786.09000000", "0.00000000"], ["72786.67000000", "0.00333000"], ["72787.70000000", "0.00199000"], ["72798.01000000", "1.03849000"], ["72800.00000000", "0.02613000"], ["72804.86000000", "0.00000000"], ["88228.57000000", "0.00371000"]], "_local_ts_utc": "2026-06-01T07:48:51.610604+00:00"}
{"e": "depthUpdate", "E": 1780300132814, "s": "BTCUSDT", "U": 94551752461, "u": 94551752489, "b": [["72760.00000000", "0.18092000"], ["72756.72000000", "0.00031000"], ["72742.65000000", "0.00007000"], ["72728.13000000", "0.00200000"], ["72727.84000000", "0.00008000"], ["72555.01000000", "0.00000000"], ["72550.35000000", "0.01397000"], ["72548.45000000", "0.09868000"], ["72546.45000000", "0.00000000"], ["65484.00000000", "0.00428000"]], "a": [["72760.01000000", "4.43052000"], ["72771.76000000", "0.00007000"], ["72776.00000000", "0.93848000"], ["72778.00000000", "1.09085000"], ["72780.17000000", "0.00000000"], ["72786.05000000", "0.00000000"], ["72786.35000000", "0.00200000"], ["72825.13000000", "0.00572000"], ["72904.50000000", "0.00000000"], ["73017.63000000", "0.00000000"], ["73032.11000000", "4.11295000"]], "_local_ts_utc": "2026-06-01T07:48:51.710590+00:00"}
{"e": "depthUpdate", "E": 1780300132914, "s": "BTCUSDT", "U": 94551752490, "u": 94551752504, "b": [["72760.00000000", "0.17692000"], ["72757.51000000", "0.00031000"], ["72756.72000000", "0.00000000"], ["72723.11000000", "0.00411000"], ["72722.96000000", "0.02732000"], ["71602.67000000", "0.00000000"], ["65484.00000000", "0.00428000"]], "a": [["72778.41000000", "0.00000000"], ["72787.75000000", "0.00400000"], ["72787.76000000", "0.00000000"], ["72837.62000000", "0.00572000"]], "_local_ts_utc": "2026-06-01T07:48:51.810491+00:00"}
{"e": "depthUpdate", "E": 1780300133014, "s": "BTCUSDT", "U": 94551752505, "u": 94551752532, "b": [["72760.00000000", "0.17292000"], ["72757.91000000", "0.00031000"], ["72754.89000000", "0.00000000"], ["65484.00000000", "0.00428000"], ["58208.00000000", "0.00034000"]], "a": [["72760.01000000", "4.43016000"], ["72767.91000000", "0.00697000"], ["72773.20000000", "0.00400000"], ["72773.37000000", "0.03407000"], ["72778.22000000", "0.00200000"], ["72779.50000000", "0.01288000"], ["72779.51000000", "0.00011000"], ["72779.68000000", "0.00007000"], ["72785.21000000", "0.00000000"], ["72785.32000000", "0.00200000"], ["72850.11000000", "0.00572000"], ["88789.71000000", "0.00022000"]], "_local_ts_utc": "2026-06-01T07:48:51.910513+00:00"}
{"e": "depthUpdate", "E": 1780300133114, "s": "BTCUSDT", "U": 94551752533, "u": 94551752700, "b": [["72760.00000000", "3.20781000"], ["72759.99000000", "0.00086000"], ["72758.55000000", "0.01375000"], ["72758.21000000", "0.00031000"], ["72757.91000000", "0.00000000"], ["72757.28000000", "0.00047000"], ["72756.13000000", "0.03532000"], ["72755.49000000", "0.00000000"], ["72755.01000000", "0.16094000"], ["72754.12000000", "0.18231000"], ["72752.83000000", "0.05942000"], ["72752.65000000", "0.18537000"], ["72751.18000000", "0.18505000"], ["72751.02000000", "0.18605000"], ["72749.68000000", "0.00000000"], ["72749.56000000", "0.00000000"], ["72749.45000000", "0.20032000"], ["72746.77000000", "0.18505000"], ["72745.47000000", "0.17501000"], ["72745.18000000", "0.00000000"], ["72740.30000000", "0.18505000"], ["72729.13000000", "0.18505000"], ["72728.13000000", "0.00000000"], ["72727.45000000", "0.00200000"], ["65484.00000000", "0.00445000"]], "a": [["72760.01000000", "4.32572000"], ["72760.02000000", "0.00094000"], ["72760.37000000", "0.00000000"], ["72760.90000000", "0.00031000"], ["72761.35000000", "0.00016000"], ["72761.36000000", "0.00016000"], ["72761.40000000", "0.00024000"], ["72761.47000000", "0.00008000"], ["72761.48000000", "0.00016000"], ["72762.75000000", "0.00000000"], ["72762.76000000", "0.00032000"], ["72762.77000000", "0.18545000"], ["72762.81000000", "0.00016000"], ["72763.65000000", "0.00000000"], ["72763.99000000", "0.00000000"], ["72764.41000000", "0.05305000"], ["72764.73000000", "0.00000000"], ["72765.22000000", "0.00000000"], ["72765.89000000", "0.00000000"], ["72767.36000000", "0.00000000"], ["72768.26000000", "0.65949000"], ["72768.27000000", "0.27000000"], ["72768.28000000", "0.00000000"], ["72768.29000000", "0.00000000"], ["72768.70000000", "0.00687000"], ["72770.06000000", "0.00000000"], ["72771.45000000", "0.84454000"], ["72771.46000000", "0.19979000"], ["72771.47000000", "0.00000000"], ["72771.48000000", "0.00000000"], ["72774.65000000", "0.00000000"], ["72777.82000000", "0.00000000"], ["72779.77000000", "0.00000000"], ["72779.91000000", "0.34264000"], ["72780.92000000", "0.00000000"], ["72785.66000000", "0.00200000"], ["72786.35000000", "0.00000000"], ["72807.41000000", "0.00000000"], ["72862.60000000", "0.00572000"], ["72868.17000000", "0.70825000"], ["72868.18000000", "2.74876000"]], "_local_ts_utc": "2026-06-01T07:48:52.010512+00:00"}
{"e": "depthUpdate", "E": 1780300133214, "s": "BTCUSDT", "U": 94551752701, "u": 94551752854, "b": [["72760.00000000", "3.23185000"], ["72759.99000000", "0.00110000"], ["72758.56000000", "0.00016000"], ["72758.55000000", "0.03227000"], ["72758.21000000", "0.00047000"], ["72758.20000000", "0.05942000"], ["72758.14000000", "0.00400000"], ["72757.51000000", "0.00000000"], ["72756.32000000", "0.00400000"], ["72756.20000000", "0.04139000"], ["72756.14000000", "0.00016000"], ["72756.01000000", "0.00000000"], ["72755.15000000", "0.00000000"], ["72752.83000000", "0.00000000"], ["72748.62000000", "0.00000000"], ["72740.30000000", "0.00000000"], ["72735.13000000", "0.00000000"], ["72729.13000000", "0.00000000"], ["72729.02000000", "0.00000000"], ["72727.20000000", "0.00000000"], ["72725.38000000", "0.00000000"], ["72719.65000000", "0.07389000"], ["72718.84000000", "0.00000000"], ["72718.69000000", "0.49568000"], ["72714.68000000", "1.36320000"], ["72702.67000000", "0.18505000"], ["72690.64000000", "0.00000000"], ["72552.59000000", "0.00822000"], ["72550.35000000", "0.00575000"], ["72458.82000000", "0.00000000"], ["66959.50000000", "0.00015000"], ["65484.00000000", "0.00462000"], ["58208.00000000", "0.00000000"]], "a": [["72760.01000000", "3.51780000"], ["72760.02000000", "0.00094000"], ["72760.49000000", "0.00000000"], ["72760.90000000", "0.00000000"], ["72761.02000000", "0.00031000"], ["72761.35000000", "0.00000000"], ["72761.36000000", "0.00000000"], ["72761.41000000", "0.40872000"], ["72761.48000000", "0.00000000"], ["72761.78000000", "0.00000000"], ["72762.34000000", "0.00000000"], ["72762.35000000", "0.00000000"], ["72762.68000000", "0.00589000"], ["72762.75000000", "0.00016000"], ["72762.76000000", "0.64644000"], ["72762.77000000", "0.18529000"], ["72762.78000000", "0.00016000"], ["72762.81000000", "0.00024000"], ["72762.82000000", "1.81769000"], ["72762.83000000", "0.14862000"], ["72763.23000000", "0.00754000"], ["72763.66000000", "0.00000000"], ["72763.80000000", "0.20784000"], ["72765.83000000", "0.00000000"], ["72768.24000000", "0.18505000"], ["72768.25000000", "0.46677000"], ["72768.27000000", "0.00008000"], ["72771.44000000", "0.45180000"], ["72771.46000000", "0.00197000"], ["72773.20000000", "0.00000000"], ["72778.68000000", "0.00400000"], ["72779.77000000", "2.74876000"], ["72794.54000000", "0.00400000"], ["72868.17000000", "0.00000000"], ["72868.18000000", "0.00000000"], ["72871.10000000", "0.02153000"], ["72875.09000000", "0.00572000"], ["72900.32000000", "0.02153000"], ["72932.10000000", "0.00000000"], ["75322.22000000", "0.00000000"], ["89169.94000000", "0.00007000"]], "_local_ts_utc": "2026-06-01T07:48:52.110511+00:00"}
{"e": "depthUpdate", "E": 1780300133314, "s": "BTCUSDT", "U": 94551752855, "u": 94551752925, "b": [["72760.00000000", "2.68717000"], ["72758.54000000", "0.00942000"], ["72758.21000000", "0.00016000"], ["72758.20000000", "0.00016000"], ["72758.00000000", "0.02280000"], ["72757.28000000", "0.00019000"], ["72756.76000000", "0.00031000"], ["72756.20000000", "0.04123000"], ["72754.12000000", "0.00000000"], ["72749.45000000", "0.00000000"], ["72702.67000000", "0.00000000"], ["72701.75000000", "0.00012000"], ["72690.65000000", "0.14861000"], ["69643.84000000", "0.00105000"], ["66956.42000000", "0.00000000"], ["65484.00000000", "0.00462000"]], "a": [["72760.01000000", "3.51764000"], ["72761.40000000", "0.18529000"], ["72762.68000000", "0.00589000"], ["72762.75000000", "0.65949000"], ["72762.76000000", "0.00016000"], ["72762.77000000", "0.18529000"], ["72762.78000000", "0.00000000"], ["72762.81000000", "0.00008000"], ["72763.23000000", "0.00754000"], ["72763.50000000", "0.05942000"], ["72763.80000000", "0.00008000"], ["72765.89000000", "0.18505000"], ["72767.36000000", "0.18505000"], ["72770.06000000", "0.18505000"], ["72776.52000000", "0.08000000"], ["72785.32000000", "0.00000000"], ["72791.47000000", "0.00200000"], ["72825.02000000", "0.07400000"], ["72831.19000000", "0.08238000"], ["72846.53000000", "0.00000000"], ["73001.48000000", "0.19586000"]], "_local_ts_utc": "2026-06-01T07:48:52.210434+00:00"}
{"e": "depthUpdate", "E": 1780300133417, "s": "BTCUSDT", "U": 94551752926, "u": 94551753207, "b": [["72760.00000000", "0.00000000"], ["72759.99000000", "0.00000000"], ["72759.98000000", "0.00000000"], ["72759.96000000", "0.00000000"], ["72759.70000000", "0.00000000"], ["72759.62000000", "0.00000000"], ["72759.54000000", "0.00000000"], ["72759.42000000", "0.00000000"], ["72759.29000000", "0.00000000"], ["72759.18000000", "0.00000000"], ["72759.09000000", "0.00000000"], ["72759.08000000", "0.00000000"], ["72759.01000000", "0.00000000"], ["72758.98000000", "0.00000000"], ["72758.82000000", "0.00000000"], ["72758.62000000", "0.00000000"], ["72758.60000000", "0.00000000"], ["72758.56000000", "0.00000000"], ["72758.55000000", "0.00000000"], ["72758.54000000", "0.00000000"], ["72758.46000000", "0.00000000"], ["72758.38000000", "0.00000000"], ["72758.30000000", "0.00000000"], ["72758.28000000", "0.00000000"], ["72758.21000000", "0.00000000"], ["72758.20000000", "0.00000000"], ["72758.19000000", "0.00000000"], ["72758.14000000", "0.00000000"], ["72758.09000000", "0.00000000"], ["72758.06000000", "0.00000000"], ["72758.01000000", "0.00000000"], ["72758.00000000", "0.00000000"], ["72757.39000000", "0.00000000"], ["72757.01000000", "0.00000000"], ["72756.76000000", "0.00000000"], ["72756.32000000", "0.00000000"], ["72756.31000000", "0.00000000"], ["72756.14000000", "0.00000000"], ["72756.13000000", "0.00000000"], ["72756.01000000", "0.00016000"], ["72755.69000000", "0.00000000"], ["72755.54000000", "0.00000000"], ["72755.01000000", "0.00000000"], ["72754.88000000", "0.00345000"], ["72754.09000000", "0.00000000"], ["72754.08000000", "0.00008000"], ["72753.96000000", "0.00000000"], ["72752.91000000", "0.00000000"], ["72752.78000000", "0.00000000"], ["72752.66000000", "0.00008000"], ["72752.65000000", "0.00032000"], ["72752.20000000", "0.00031000"], ["72752.01000000", "0.00000000"], ["72751.96000000", "0.00000000"], ["72751.57000000", "0.02000000"], ["72751.18000000", "0.00000000"], ["72751.02000000", "0.00100000"], ["72751.01000000", "0.00000000"], ["72750.14000000", "0.00000000"], ["72750.02000000", "0.00000000"], ["72749.71000000", "0.00008000"], ["72749.20000000", "0.00000000"], ["72748.58000000", "0.00070000"], ["72747.50000000", "0.00000000"], ["72746.84000000", "0.00000000"], ["72746.78000000", "0.00008000"], ["72746.77000000", "0.00000000"], ["72745.47000000", "0.00000000"], ["72745.46000000", "0.00008000"], ["72745.45000000", "0.00007000"], ["72745.44000000", "0.00000000"], ["72744.11000000", "0.00008000"], ["72743.63000000", "0.00000000"], ["72742.13000000", "0.00000000"], ["72740.29000000", "0.00000000"], ["72739.99000000", "0.00000000"], ["72738.10000000", "0.00000000"], ["72738.09000000", "0.95683000"], ["72738.08000000", "0.00000000"], ["72734.37000000", "0.00013000"], ["72734.34000000", "0.00000000"], ["72733.18000000", "0.01375000"], ["72730.89000000", "0.00000000"], ["72729.44000000", "0.00200000"], ["72729.02000000", "0.00400000"], ["72728.71000000", "0.00000000"], ["72727.66000000", "0.00000000"], ["72727.45000000", "0.00000000"], ["72727.04000000", "0.00000000"], ["72727.03000000", "1.50499000"], ["72727.02000000", "0.00077000"], ["72727.01000000", "0.00000000"], ["72725.38000000", "0.00400000"], ["72720.31000000", "0.00000000"], ["72717.37000000", "0.00000000"], ["72715.60000000", "0.00000000"], ["72714.68000000", "0.00000000"], ["72682.02000000", "0.65949000"], ["72676.53000000", "0.00486000"], ["72673.28000000", "0.65949000"], ["72669.16000000", "0.00000000"], ["72612.66000000", "0.00000000"], ["72589.50000000", "0.40856000"], ["72463.87000000", "4.14520000"], ["65484.00000000", "0.00462000"]], "a": [["72758.01000000", "1.15669000"], ["72758.55000000", "0.27069000"], ["72759.71000000", "0.12819000"], ["72759.99000000", "0.62540000"], ["72760.00000000", "0.26045000"], ["72760.01000000", "5.04402000"], ["72760.02000000", "0.00038000"], ["72760.21000000", "0.03407000"], ["72760.68000000", "0.00000000"], ["72761.19000000", "0.13743000"], ["72761.21000000", "0.05942000"], ["72761.39000000", "0.00000000"], ["72761.40000000", "0.18529000"], ["72761.78000000", "0.00400000"], ["72762.04000000", "0.00028000"], ["72762.68000000", "0.00589000"], ["72762.74000000", "0.86075000"], ["72762.75000000", "0.65965000"], ["72762.76000000", "0.00000000"], ["72762.81000000", "0.00008000"], ["72763.23000000", "0.00738000"], ["72763.27000000", "0.00000000"], ["72763.50000000", "0.00000000"], ["72763.80000000", "0.31265000"], ["72764.25000000", "0.03407000"], ["72764.40000000", "0.18505000"], ["72764.41000000", "0.00000000"], ["72766.22000000", "0.00000000"], ["72768.70000000", "0.00000000"], ["72770.01000000", "0.00016000"], ["72771.46000000", "0.00008000"], ["72772.82000000", "0.00016000"], ["72772.83000000", "0.00008000"], ["72773.23000000", "0.15594000"], ["72777.16000000", "0.00008000"], ["72777.82000000", "0.18505000"], ["72779.75000000", "0.18505000"], ["72779.76000000", "1.23488000"], ["72779.91000000", "0.00000000"], ["72781.95000000", "0.18505000"], ["72783.53000000", "0.18505000"], ["72785.00000000", "0.17258000"], ["72785.66000000", "0.00000000"], ["72785.97000000", "0.18156000"], ["72787.65000000", "0.00200000"], ["72789.12000000", "0.00000000"], ["72790.90000000", "0.00000000"], ["72792.72000000", "0.00000000"], ["72794.54000000", "0.00000000"], ["72803.76000000", "0.00000000"], ["72823.43000000", "0.55676000"], ["72824.98000000", "0.08600000"], ["72841.67000000", "0.01563000"], ["72857.99000000", "0.00000000"], ["72870.83000000", "0.00000000"], ["73414.84000000", "0.00010000"]], "_local_ts_utc": "2026-06-01T07:48:52.313833+00:00"}
{"e": "depthUpdate", "E": 1780300133514, "s": "BTCUSDT", "U": 94551753208, "u": 94551754310, "b": [["72757.93000000", "0.00000000"], ["72757.83000000", "0.00000000"], ["72757.80000000", "0.00000000"], ["72757.69000000", "0.00000000"], ["72757.61000000", "0.00000000"], ["72757.50000000", "0.00000000"], ["72757.42000000", "0.00000000"], ["72757.28000000", "0.00000000"], ["72757.16000000", "0.00000000"], ["72757.14000000", "0.00000000"], ["72757.11000000", "0.00000000"], ["72757.08000000", "0.00000000"], ["72757.07000000", "0.00000000"], ["72756.28000000", "0.00000000"], ["72756.25000000", "0.00000000"], ["72756.21000000", "0.00000000"], ["72756.20000000", "0.00000000"], ["72756.01000000", "0.00000000"], ["72756.00000000", "0.00000000"], ["72755.99000000", "0.00000000"], ["72755.73000000", "0.00000000"], ["72755.72000000", "0.00000000"], ["72755.60000000", "0.00000000"], ["72755.55000000", "0.00000000"], ["72755.50000000", "0.00000000"], ["72755.38000000", "0.00000000"], ["72755.29000000", "0.00000000"], ["72755.27000000", "0.00000000"], ["72755.11000000", "0.00000000"], ["72755.10000000", "0.00000000"], ["72755.01000000", "0.00000000"], ["72755.00000000", "0.48545000"], ["72754.99000000", "0.00072000"], ["72754.88000000", "0.00000000"], ["72754.55000000", "0.00000000"], ["72754.54000000", "0.00000000"], ["72754.53000000", "0.00016000"], ["72754.51000000", "0.00000000"], ["72754.50000000", "0.00016000"], ["72754.40000000", "0.00000000"], ["72754.39000000", "0.00016000"], ["72754.34000000", "0.00000000"], ["72754.08000000", "0.00024000"], ["72754.07000000", "0.08258000"], ["72754.01000000", "0.00016000"], ["72753.35000000", "0.00016000"], ["72753.29000000", "0.00016000"], ["72752.68000000", "0.00000000"], ["72752.32000000", "0.00000000"], ["72752.31000000", "0.00000000"], ["72752.20000000", "0.00000000"], ["72752.07000000", "0.00000000"], ["72752.05000000", "0.00000000"], ["72752.01000000", "0.00008000"], ["72751.57000000", "0.00000000"], ["72751.47000000", "0.00000000"], ["72751.40000000", "0.00031000"], ["72750.96000000", "0.00000000"], ["72750.92000000", "0.00000000"], ["72750.11000000", "0.00000000"], ["72750.09000000", "0.00000000"], ["72750.06000000", "0.01475000"], ["72749.89000000", "0.00000000"], ["72749.72000000", "0.00000000"], ["72749.71000000", "0.00008000"], ["72749.23000000", "0.00000000"], ["72749.06000000", "0.00000000"], ["72748.68000000", "0.00000000"], ["72748.58000000", "0.00000000"], ["72748.44000000", "0.00000000"], ["72748.32000000", "0.00000000"], ["72748.17000000", "0.00164000"], ["72747.89000000", "0.01386000"], ["72747.00000000", "0.02045000"], ["72746.29000000", "0.00000000"], ["72744.91000000", "0.00068000"], ["72744.59000000", "0.02810000"], ["72744.31000000", "0.00028000"], ["72743.64000000", "0.01344000"], ["72743.41000000", "0.19305000"], ["72742.28000000", "0.01491000"], ["72741.94000000", "0.00000000"], ["72741.77000000", "0.16678000"], ["72741.68000000", "0.00000000"], ["72740.81000000", "0.00100000"], ["72740.30000000", "0.18506000"], ["72740.29000000", "0.65949000"], ["72740.28000000", "0.00105000"], ["72740.11000000", "0.00007000"], ["72738.83000000", "0.18506000"], ["72738.10000000", "0.18506000"], ["72738.09000000", "0.00008000"], ["72737.71000000", "0.00000000"], ["72736.97000000", "0.00000000"], ["72736.83000000", "1.75187000"], ["72736.36000000", "0.01358000"], ["72736.21000000", "0.15000000"], ["72735.89000000", "0.18514000"], ["72734.65000000", "2.74876000"], ["72734.58000000", "0.00000000"], ["72734.48000000", "0.18906000"], ["72734.38000000", "0.00000000"], ["72733.71000000", "0.38022000"], ["72733.70000000", "0.65949000"], ["72733.17000000", "0.00137000"], ["72733.02000000", "0.00000000"], ["72733.01000000", "0.18506000"], ["72732.67000000", "0.00000000"], ["72732.64000000", "0.03407000"], ["72732.20000000", "0.00000000"], ["72731.54000000", "0.18506000"], ["72730.50000000", "0.00000000"], ["72730.07000000", "0.18506000"], ["72729.98000000", "0.53116000"], ["72729.97000000", "0.65949000"], ["72729.96000000", "0.00000000"], ["72729.94000000", "0.00028000"], ["72729.54000000", "0.29000000"], ["72729.08000000", "0.01389000"], ["72728.88000000", "0.00000000"], ["72728.82000000", "0.00000000"], ["72728.72000000", "0.40856000"], ["72728.60000000", "0.18506000"], ["72728.39000000", "0.00000000"], ["72727.51000000", "0.12186000"], ["72727.13000000", "0.18506000"], ["72727.05000000", "1.59157000"], ["72727.04000000", "3.59331000"], ["72727.03000000", "0.00008000"], ["72724.19000000", "0.00000000"], ["72723.12000000", "0.00028000"], ["72723.11000000", "0.00011000"], ["72722.94000000", "0.72864000"], ["72722.93000000", "0.65949000"], ["72722.72000000", "0.00000000"], ["72722.69000000", "0.00000000"], ["72722.52000000", "0.00127000"], ["72721.80000000", "0.03382000"], ["72721.74000000", "0.00400000"], ["72721.25000000", "0.00000000"], ["72721.21000000", "0.00007000"], ["72720.01000000", "0.18534000"], ["72719.99000000", "0.00000000"], ["72719.92000000", "0.00400000"], ["72719.65000000", "0.07389000"], ["72718.83000000", "0.00007000"], ["72718.70000000", "0.00000000"], ["72718.69000000", "0.00000000"], ["72717.64000000", "0.00000000"], ["72717.23000000", "0.00000000"], ["72716.84000000", "0.21487000"], ["72716.42000000", "0.00400000"], ["72715.91000000", "2.74876000"], ["72715.90000000", "0.00000000"], ["72715.66000000", "0.96824000"], ["72715.60000000", "0.00000000"], ["72715.59000000", "0.00000000"], ["72715.58000000", "0.02014000"], ["72715.37000000", "0.00000000"], ["72713.90000000", "0.00000000"], ["72713.58000000", "0.00000000"], ["72712.80000000", "0.00000000"], ["72712.79000000", "0.00000000"], ["72710.96000000", "0.18506000"], ["72709.49000000", "0.18506000"], ["72709.12000000", "0.18506000"], ["72709.11000000", "0.00000000"], ["72708.81000000", "0.00000000"], ["72708.67000000", "0.00000000"], ["72707.10000000", "0.18506000"], ["72707.09000000", "0.00013000"], ["72707.05000000", "0.01374000"], ["72706.69000000", "0.00000000"], ["72706.07000000", "0.00000000"], ["72705.76000000", "0.18514000"], ["72705.74000000", "0.00000000"], ["72704.56000000", "0.00000000"], ["72703.83000000", "0.00000000"], ["72703.61000000", "0.18506000"], ["72703.60000000", "0.00000000"], ["72703.32000000", "0.00000000"], ["72702.95000000", "0.02790000"], ["72702.84000000", "0.49579000"], ["72702.61000000", "0.00020000"], ["72702.14000000", "0.18506000"], ["72701.75000000", "0.18518000"], ["72701.74000000", "0.00000000"], ["72701.42000000", "1.04321000"], ["72701.41000000", "0.38268000"], ["72701.39000000", "0.00000000"], ["72701.29000000", "0.00000000"], ["72700.91000000", "0.00000000"], ["72700.66000000", "0.00000000"], ["72700.01000000", "0.17192000"], ["72698.73000000", "0.00343000"], ["72698.07000000", "0.18506000"], ["72696.22000000", "0.49583000"], ["72696.20000000", "0.00000000"], ["72694.73000000", "0.00000000"], ["72694.21000000", "0.06828000"], ["72693.76000000", "0.18506000"], ["72692.62000000", "0.18506000"], ["72691.30000000", "0.36892000"], ["72690.92000000", "0.18446000"], ["72690.39000000", "0.00428000"], ["72690.08000000", "0.03300000"], ["72690.06000000", "0.00000000"], ["72689.47000000", "0.73784000"], ["72689.39000000", "0.18470000"], ["72689.36000000", "0.36892000"], ["72689.35000000", "0.36892000"], ["72687.38000000", "0.00000000"], ["72685.91000000", "0.00000000"], ["72685.55000000", "0.00000000"], ["72682.83000000", "0.00000000"], ["72682.24000000", "0.00008000"], ["72682.03000000", "0.00000000"], ["72681.03000000", "0.00000000"], ["72678.86000000", "0.45428000"], ["72678.65000000", "0.04440000"], ["72677.52000000", "0.82589000"], ["72677.29000000", "1.36400000"], ["72676.01000000", "0.00282000"], ["72664.54000000", "0.65949000"], ["72657.59000000", "2.74876000"], ["72654.58000000", "2.03608000"], ["72648.76000000", "0.00008000"], ["72645.94000000", "0.00000000"], ["72634.29000000", "0.00000000"], ["72625.07000000", "0.00275000"], ["72622.64000000", "0.00000000"], ["72617.29000000", "0.00000000"], ["72609.49000000", "0.00008000"], ["72592.90000000", "0.00000000"], ["72590.47000000", "2.84261000"], ["72548.23000000", "0.00250000"], ["72544.53000000", "0.00000000"], ["72542.64000000", "0.00007000"], ["72539.01000000", "0.00007000"], ["72536.74000000", "0.00008000"], ["72471.77000000", "0.00000000"], ["72470.97000000", "0.00000000"], ["72463.98000000", "0.00008000"], ["72460.91000000", "0.00028000"], ["72450.00000000", "1.83411000"], ["72399.01000000", "0.00500000"], ["72391.23000000", "0.00008000"], ["72326.24000000", "0.00000000"], ["72318.47000000", "0.00008000"], ["72253.48000000", "0.00000000"], ["72245.71000000", "0.00285000"], ["72180.72000000", "0.00000000"], ["72172.96000000", "0.00008000"], ["71302.27000000", "0.00000000"], ["71299.89000000", "0.00000000"], ["65484.00000000", "0.00173000"], ["65479.50000000", "0.00034000"], ["58208.00000000", "0.00000000"], ["58204.00000000", "0.00034000"]], "a": [["72755.01000000", "9.74596000"], ["72755.02000000", "0.00038000"], ["72755.03000000", "0.00014000"], ["72755.59000000", "0.00000000"], ["72755.73000000", "0.00007000"], ["72756.00000000", "0.00008000"], ["72756.01000000", "0.00000000"], ["72756.13000000", "0.07202000"], ["72756.21000000", "0.00000000"], ["72756.29000000", "0.00000000"], ["72756.32000000", "0.00400000"], ["72756.94000000", "0.00164000"], ["72757.17000000", "0.00000000"], ["72757.84000000", "0.00000000"], ["72757.91000000", "0.18506000"], ["72757.92000000", "0.00000000"], ["72757.93000000", "0.76544000"], ["72757.94000000", "1.37859000"], ["72757.95000000", "0.00000000"], ["72757.97000000", "0.00000000"], ["72757.99000000", "0.00000000"], ["72758.00000000", "0.00000000"], ["72758.01000000", "0.39808000"], ["72758.02000000", "0.00000000"], ["72758.09000000", "0.00000000"], ["72758.14000000", "0.00400000"], ["72758.54000000", "0.00428000"], ["72758.55000000", "0.00016000"], ["72758.56000000", "0.00000000"], ["72758.61000000", "0.00000000"], ["72758.77000000", "0.15000000"], ["72759.09000000", "0.07989000"], ["72759.19000000", "0.00000000"], ["72759.30000000", "0.00000000"], ["72759.42000000", "0.00007000"], ["72759.43000000", "0.00000000"], ["72759.49000000", "0.00000000"], ["72759.55000000", "0.00000000"], ["72759.63000000", "0.00000000"], ["72759.69000000", "0.00000000"], ["72759.70000000", "0.00008000"], ["72759.71000000", "0.90641000"], ["72759.85000000", "0.00000000"], ["72759.86000000", "0.00000000"], ["72759.96000000", "0.00400000"], ["72759.97000000", "0.00000000"], ["72759.98000000", "1.18376000"], ["72759.99000000", "0.00024000"], ["72760.00000000", "0.00016000"], ["72760.01000000", "0.87989000"], ["72760.02000000", "0.00000000"], ["72760.03000000", "0.00000000"], ["72760.21000000", "0.03423000"], ["72760.90000000", "0.00754000"], ["72761.02000000", "0.00000000"], ["72761.19000000", "0.00000000"], ["72761.21000000", "0.00000000"], ["72761.27000000", "0.00008000"], ["72761.40000000", "0.00008000"], ["72761.41000000", "0.40856000"], ["72761.47000000", "0.00000000"], ["72762.52000000", "0.01370000"], ["72762.68000000", "0.00573000"], ["72762.74000000", "0.00008000"], ["72762.75000000", "0.65949000"], ["72762.77000000", "0.00000000"], ["72762.82000000", "1.80201000"], ["72762.83000000", "0.13582000"], ["72763.67000000", "0.00000000"], ["72763.80000000", "0.19977000"], ["72764.09000000", "0.00007000"], ["72764.40000000", "0.00000000"], ["72764.64000000", "0.00008000"], ["72764.73000000", "0.00011000"], ["72765.71000000", "0.00000000"], ["72765.88000000", "0.00000000"], ["72765.89000000", "0.00000000"], ["72766.21000000", "0.00000000"], ["72767.14000000", "0.00028000"], ["72767.36000000", "0.00000000"], ["72768.00000000", "0.00098000"], ["72768.24000000", "0.00000000"], ["72768.25000000", "0.46685000"], ["72768.27000000", "0.00000000"], ["72769.09000000", "0.00000000"], ["72770.00000000", "0.00080000"], ["72770.01000000", "0.00000000"], ["72770.06000000", "0.00000000"], ["72770.07000000", "0.00000000"], ["72771.00000000", "0.00028000"], ["72771.42000000", "1.64697000"], ["72771.43000000", "2.74876000"], ["72771.44000000", "0.00000000"], ["72771.45000000", "0.65949000"], ["72771.46000000", "0.00000000"], ["72771.73000000", "0.00000000"], ["72772.28000000", "0.49531000"], ["72772.57000000", "0.96825000"], ["72772.82000000", "0.00000000"], ["72772.83000000", "0.00000000"], ["72772.92000000", "0.00330000"], ["72772.94000000", "0.00000000"], ["72773.23000000", "0.15586000"], ["72773.24000000", "0.00000000"], ["72773.48000000", "0.00008000"], ["72773.49000000", "0.00000000"], ["72773.82000000", "0.00458000"], ["72774.71000000", "0.00000000"], ["72775.02000000", "0.00008000"], ["72775.99000000", "0.00008000"], ["72776.84000000", "0.00137000"], ["72776.99000000", "0.00000000"], ["72777.13000000", "0.00008000"], ["72777.16000000", "0.00000000"], ["72777.82000000", "0.00000000"], ["72777.83000000", "0.00000000"], ["72778.01000000", "0.04007000"], ["72779.05000000", "0.00000000"], ["72779.36000000", "0.00283000"], ["72779.37000000", "0.38344000"], ["72779.40000000", "0.58447000"], ["72779.75000000", "0.00000000"], ["72779.90000000", "0.00000000"], ["72780.00000000", "0.13416000"], ["72780.01000000", "0.76091000"], ["72780.16000000", "0.00000000"], ["72780.77000000", "0.00008000"], ["72780.78000000", "1.36196000"], ["72780.88000000", "0.23809000"], ["72780.91000000", "0.00000000"], ["72780.93000000", "0.00400000"], ["72781.46000000", "0.00000000"], ["72781.76000000", "0.00000000"], ["72781.95000000", "0.00000000"], ["72782.89000000", "0.00000000"], ["72783.53000000", "0.00000000"], ["72784.08000000", "0.00000000"], ["72784.51000000", "0.00000000"], ["72785.00000000", "0.00000000"], ["72785.23000000", "0.00000000"], ["72785.44000000", "0.00000000"], ["72785.97000000", "0.00000000"], ["72787.12000000", "0.00000000"], ["72787.26000000", "2.74865000"], ["72787.29000000", "0.00000000"], ["72787.70000000", "0.00000000"], ["72787.75000000", "0.00000000"], ["72788.60000000", "0.02648000"], ["72789.08000000", "0.00000000"], ["72790.58000000", "0.00000000"], ["72790.78000000", "0.00000000"], ["72792.63000000", "0.00000000"], ["72793.41000000", "0.00000000"], ["72793.56000000", "0.00000000"], ["72793.62000000", "0.43044000"], ["72793.93000000", "0.00007000"], ["72794.96000000", "0.00000000"], ["72795.53000000", "0.00008000"], ["72796.32000000", "0.00000000"], ["72798.00000000", "0.02288000"], ["72798.18000000", "0.00000000"], ["72799.23000000", "0.00000000"], ["72800.43000000", "0.00008000"], ["72802.40000000", "0.00000000"], ["72802.96000000", "0.00000000"], ["72804.22000000", "0.00412000"], ["72804.23000000", "0.00000000"], ["72806.27000000", "0.00000000"], ["72808.00000000", "0.02280000"], ["72808.88000000", "0.00000000"], ["72818.87000000", "0.82589000"], ["72821.54000000", "4.12484000"], ["72827.77000000", "0.00008000"], ["72828.33000000", "0.00000000"], ["72834.07000000", "0.00000000"], ["72834.14000000", "0.00000000"], ["72834.86000000", "0.00000000"], ["72835.59000000", "0.00000000"], ["72848.44000000", "0.07886000"], ["72851.52000000", "0.00000000"], ["72855.14000000", "0.00000000"], ["72860.54000000", "0.00000000"], ["72862.25000000", "0.00000000"], ["72863.20000000", "0.69990000"], ["72869.53000000", "0.00000000"], ["72875.04000000", "0.00000000"], ["72899.51000000", "0.00000000"], ["72900.52000000", "0.00008000"], ["72906.16000000", "2.06252000"], ["72908.36000000", "0.00000000"], ["72912.53000000", "0.00000000"], ["72914.70000000", "0.00009000"], ["72930.15000000", "0.00000000"], ["72932.54000000", "0.00000000"], ["72933.61000000", "0.00007000"], ["72943.17000000", "0.00000000"], ["72945.05000000", "0.27000000"], ["72945.59000000", "0.00007000"], ["72947.24000000", "0.00000000"], ["72949.22000000", "0.00007000"], ["72949.68000000", "0.00011000"], ["72966.66000000", "0.00018000"], ["72970.00000000", "0.02291000"], ["72975.67000000", "0.00007000"], ["72982.61000000", "0.00009000"], ["72983.72000000", "0.00009000"], ["72983.87000000", "0.00026000"], ["72994.25000000", "0.00265000"], ["73007.83000000", "0.00010000"], ["73018.18000000", "0.00007000"], ["73024.24000000", "0.00000000"], ["73027.22000000", "0.00155000"], ["73032.66000000", "0.00000000"], ["73046.03000000", "0.00008000"], ["73053.88000000", "0.00000000"], ["73055.19000000", "0.00119000"], ["73055.62000000", "0.00009000"], ["73058.68000000", "0.00008000"], ["73061.22000000", "0.00008000"], ["73072.76000000", "0.00000000"], ["73079.57000000", "0.00000000"], ["73085.71000000", "0.00008000"], ["73103.44000000", "0.00008000"], ["73111.42000000", "0.00008000"], ["73118.79000000", "0.00008000"], ["73126.64000000", "0.00000000"], ["73129.61000000", "0.00011000"], ["73137.19000000", "0.00012000"], ["73142.38000000", "0.00017000"], ["73264.30000000", "0.00008000"], ["73265.97000000", "0.00008000"], ["73272.17000000", "0.00000000"], ["73276.92000000", "0.00010000"], ["73323.92000000", "0.00023000"], ["73373.29000000", "0.00032000"], ["73412.41000000", "0.00250000"], ["73443.91000000", "0.00013000"], ["73482.75000000", "0.00009000"], ["73637.85000000", "0.00022000"], ["73660.01000000", "0.00020000"], ["73691.03000000", "0.00017000"], ["73727.10000000", "0.00170000"], ["73793.10000000", "0.00131000"], ["73826.66000000", "0.00000000"], ["74577.69000000", "0.00031000"], ["74587.78000000", "0.00053000"], ["74978.78000000", "0.00000000"], ["75355.54000000", "0.00000000"], ["75384.85000000", "0.00007000"], ["89317.29000000", "0.00009000"]], "_local_ts_utc": "2026-06-01T07:48:52.411827+00:00"}
{"e": "depthUpdate", "E": 1780300133614, "s": "BTCUSDT", "U": 94551754311, "u": 94551754459, "b": [["72755.00000000", "0.48561000"], ["72754.99000000", "0.00080000"], ["72754.53000000", "0.00000000"], ["72754.50000000", "0.00000000"], ["72754.39000000", "0.00000000"], ["72754.00000000", "0.02296000"], ["72753.34000000", "0.01753000"], ["72753.28000000", "0.04666000"], ["72752.00000000", "0.02867000"], ["72751.89000000", "0.00028000"], ["72751.76000000", "0.00597000"], ["72751.40000000", "0.00000000"], ["72751.00000000", "1.01016000"], ["72750.87000000", "0.00016000"], ["72750.86000000", "0.00000000"], ["72750.18000000", "0.00031000"], ["72749.12000000", "0.00000000"], ["72744.97000000", "0.05942000"], ["72744.65000000", "0.00047000"], ["72743.42000000", "0.65949000"], ["72741.82000000", "0.02007000"], ["72741.68000000", "0.00011000"], ["72741.14000000", "0.02000000"], ["72740.99000000", "0.00000000"], ["72740.30000000", "0.48038000"], ["72736.83000000", "1.73812000"], ["72736.64000000", "0.01375000"], ["72733.18000000", "0.00000000"], ["72733.17000000", "0.00150000"], ["72733.01000000", "0.00000000"], ["72731.13000000", "0.01376000"], ["72727.04000000", "3.40825000"], ["72720.12000000", "0.63882000"], ["72720.01000000", "0.00028000"], ["72719.52000000", "0.00188000"], ["72719.16000000", "0.00000000"], ["72718.10000000", "0.00400000"], ["72711.35000000", "0.00639000"], ["72708.06000000", "0.49575000"], ["72697.33000000", "0.00007000"], ["72697.04000000", "0.00000000"], ["72696.82000000", "1.19578000"], ["72694.26000000", "1.04014000"], ["72689.98000000", "0.49587000"], ["72689.52000000", "0.00028000"], ["72689.41000000", "0.18446000"], ["72686.03000000", "0.02000000"], ["72685.35000000", "0.02000000"], ["72675.50000000", "0.00000000"], ["72667.69000000", "0.00013000"], ["72653.68000000", "0.00000000"], ["72645.87000000", "0.00013000"], ["72569.05000000", "0.00080000"], ["70000.00000000", "106.47866000"], ["65479.50000000", "0.00068000"], ["58204.00000000", "0.00000000"]], "a": [["72755.01000000", "9.74596000"], ["72756.13000000", "0.07218000"], ["72757.91000000", "0.18522000"], ["72757.93000000", "0.76560000"], ["72758.01000000", "0.39808000"], ["72758.14000000", "0.00454000"], ["72758.23000000", "0.00157000"], ["72758.55000000", "0.00000000"], ["72758.77000000", "0.15016000"], ["72759.09000000", "0.08005000"], ["72759.71000000", "0.90625000"], ["72759.89000000", "0.00007000"], ["72759.99000000", "0.00008000"], ["72760.00000000", "0.00000000"], ["72760.01000000", "0.87973000"], ["72760.21000000", "0.03407000"], ["72762.36000000", "0.00007000"], ["72762.83000000", "0.12951000"], ["72766.62000000", "0.00400000"], ["72767.91000000", "0.00540000"], ["72772.75000000", "0.00200000"], ["72773.56000000", "0.00188000"], ["72776.84000000", "0.00150000"], ["72777.65000000", "0.49528000"], ["72778.22000000", "0.00000000"], ["72778.68000000", "0.00000000"], ["72779.61000000", "0.00200000"], ["72784.66000000", "0.00000000"], ["72786.84000000", "0.00000000"], ["72787.27000000", "0.00000000"], ["72791.34000000", "0.00436000"], ["72791.47000000", "0.00000000"], ["72798.66000000", "0.65962000"], ["72802.04000000", "0.00000000"], ["72806.32000000", "0.01708000"], ["72806.49000000", "0.00000000"], ["72806.96000000", "0.00109000"], ["72820.47000000", "0.00000000"], ["72820.49000000", "0.00013000"], ["72821.20000000", "0.00000000"], ["72828.32000000", "0.00000000"], ["72842.32000000", "0.00013000"], ["72850.15000000", "0.00000000"], ["72864.14000000", "0.00013000"], ["72871.97000000", "0.00000000"], ["72882.01000000", "0.00000000"], ["72882.63000000", "0.00000000"], ["72999.54000000", "0.00080000"]], "_local_ts_utc": "2026-06-01T07:48:52.510369+00:00"}
{"e": "depthUpdate", "E": 1780300133714, "s": "BTCUSDT", "U": 94551754460, "u": 94551754574, "b": [["72755.00000000", "0.24479000"], ["72751.89000000", "0.00000000"], ["72751.00000000", "1.01016000"], ["72750.87000000", "0.00000000"], ["72750.18000000", "0.00000000"], ["72750.06000000", "0.00016000"], ["72749.96000000", "0.00000000"], ["72749.77000000", "0.00855000"], ["72748.39000000", "0.00000000"], ["72747.89000000", "0.00000000"], ["72747.59000000", "0.04532000"], ["72747.16000000", "0.00057000"], ["72746.45000000", "0.00199000"], ["72744.68000000", "0.00000000"], ["72744.11000000", "0.34801000"], ["72743.48000000", "0.00000000"], ["72743.41000000", "0.00000000"], ["72741.77000000", "0.00000000"], ["72740.30000000", "0.28157000"], ["72738.83000000", "0.00000000"], ["72735.89000000", "0.00008000"], ["72734.48000000", "0.00400000"], ["72733.71000000", "0.26510000"], ["72732.62000000", "0.00189000"], ["72731.54000000", "0.00000000"], ["72731.39000000", "0.00000000"], ["72731.13000000", "0.00000000"], ["72729.54000000", "0.27000000"], ["72729.44000000", "0.00000000"], ["72728.60000000", "0.00000000"], ["72728.02000000", "0.00000000"], ["72727.13000000", "0.00000000"], ["72724.24000000", "0.02000000"], ["72722.42000000", "0.00200000"], ["72717.82000000", "0.00119000"], ["72715.92000000", "1.51593000"], ["72710.96000000", "0.00000000"], ["72700.57000000", "0.00000000"], ["72698.07000000", "0.00000000"], ["72693.76000000", "0.00000000"], ["72692.62000000", "0.00000000"], ["72689.41000000", "0.36892000"], ["72616.05000000", "0.00000000"], ["72581.01000000", "0.09259000"], ["72473.03000000", "0.00000000"], ["72403.49000000", "0.07568000"], ["72032.39000000", "0.00000000"], ["72030.25000000", "0.00007000"], ["65479.50000000", "0.00102000"], ["65479.00000000", "0.00020000"]], "a": [["72755.01000000", "9.76207000"], ["72756.03000000", "0.12772000"], ["72756.13000000", "0.00016000"], ["72756.48000000", "0.16819000"], ["72758.01000000", "0.41929000"], ["72759.42000000", "0.18514000"], ["72759.70000000", "0.18515000"], ["72759.71000000", "0.90641000"], ["72767.91000000", "0.00000000"], ["72768.04000000", "0.01286000"], ["72768.24000000", "0.18507000"], ["72771.18000000", "0.18507000"], ["72771.41000000", "0.18507000"], ["72771.68000000", "0.00000000"], ["72772.34000000", "0.00119000"], ["72772.51000000", "0.00000000"], ["72780.63000000", "0.00200000"], ["72781.59000000", "0.00000000"], ["72783.21000000", "0.00125000"], ["72786.13000000", "0.00620000"], ["72786.20000000", "0.00000000"], ["72787.65000000", "0.00000000"], ["72790.50000000", "0.00435000"], ["72791.21000000", "0.00000000"], ["72797.60000000", "0.00000000"], ["72800.43000000", "1.18421000"], ["72801.46000000", "0.00000000"], ["72814.18000000", "0.00137000"], ["73106.66000000", "0.00000000"], ["73485.60000000", "0.00007000"], ["73487.62000000", "0.00000000"]], "_local_ts_utc": "2026-06-01T07:48:52.610205+00:00"}
{"e": "depthUpdate", "E": 1780300133814, "s": "BTCUSDT", "U": 94551754575, "u": 94551754965, "b": [["72755.00000000", "0.00000000"], ["72754.99000000", "0.00000000"], ["72754.64000000", "0.00000000"], ["72754.38000000", "0.00000000"], ["72754.08000000", "0.00000000"], ["72754.07000000", "0.08376000"], ["72754.06000000", "0.00072000"], ["72752.01000000", "0.00016000"], ["72751.01000000", "0.00008000"], ["72751.00000000", "1.01016000"], ["72750.06000000", "0.00000000"], ["72750.00000000", "1.11035000"], ["72749.77000000", "0.00871000"], ["72749.61000000", "0.00000000"], ["72749.52000000", "0.00057000"], ["72749.04000000", "0.00000000"], ["72747.59000000", "0.00000000"], ["72747.58000000", "0.00939000"], ["72747.42000000", "0.00033000"], ["72747.22000000", "0.00000000"], ["72747.16000000", "0.00017000"], ["72747.00000000", "0.00045000"], ["72746.45000000", "0.00168000"], ["72744.98000000", "0.11160000"], ["72744.97000000", "0.00000000"], ["72744.66000000", "0.00007000"], ["72744.36000000", "0.00756000"], ["72744.33000000", "0.00031000"], ["72744.11000000", "0.00008000"], ["72744.10000000", "0.00000000"], ["72743.42000000", "0.00000000"], ["72742.65000000", "0.00000000"], ["72742.05000000", "0.05942000"], ["72740.72000000", "0.00765000"], ["72740.29000000", "0.00000000"], ["72740.27000000", "0.00000000"], ["72738.10000000", "0.00000000"], ["72737.09000000", "0.00025000"], ["72737.08000000", "0.00757000"], ["72736.83000000", "1.07863000"], ["72736.64000000", "0.00000000"], ["72736.21000000", "0.00000000"], ["72735.53000000", "0.00000000"], ["72734.66000000", "0.65949000"], ["72734.65000000", "0.00000000"], ["72733.70000000", "0.00000000"], ["72733.44000000", "0.00742000"], ["72733.40000000", "0.00105000"], ["72732.56000000", "0.00000000"], ["72732.33000000", "0.01375000"], ["72731.21000000", "0.00000000"], ["72731.19000000", "0.00164000"], ["72730.15000000", "0.00000000"], ["72730.07000000", "0.00000000"], ["72729.81000000", "0.00000000"], ["72729.80000000", "0.00739000"], ["72729.11000000", "0.08000000"], ["72729.01000000", "0.03000000"], ["72728.91000000", "0.04000000"], ["72728.72000000", "0.00000000"], ["72725.81000000", "0.00832000"], ["72721.17000000", "0.40856000"], ["72717.27000000", "0.00000000"], ["72716.84000000", "0.02981000"], ["72716.42000000", "0.00000000"], ["72716.28000000", "0.00400000"], ["72715.93000000", "0.00000000"], ["72714.46000000", "0.00400000"], ["72713.79000000", "0.00000000"], ["72713.77000000", "0.00000000"], ["72713.76000000", "0.00000000"], ["72713.16000000", "0.00000000"], ["72713.15000000", "0.00000000"], ["72712.71000000", "0.00000000"], ["72712.67000000", "0.00000000"], ["72712.46000000", "0.00000000"], ["72711.52000000", "0.03386000"], ["72711.38000000", "0.00000000"], ["72709.49000000", "0.00000000"], ["72709.12000000", "0.00000000"], ["72707.10000000", "0.00000000"], ["72702.61000000", "0.02553000"], ["72701.75000000", "0.00012000"], ["72701.41000000", "0.00000000"], ["72700.47000000", "0.00000000"], ["72699.08000000", "0.00000000"], ["72689.90000000", "0.00000000"], ["72689.58000000", "0.36892000"], ["72686.55000000", "0.18446000"], ["72686.03000000", "0.00000000"], ["72684.54000000", "0.02661000"], ["72667.00000000", "0.00678000"], ["72645.94000000", "0.00000000"], ["72632.56000000", "0.00000000"], ["72621.14000000", "0.00137000"], ["72571.19000000", "0.00000000"], ["72471.43000000", "0.00000000"], ["72402.84000000", "0.04758000"], ["72030.25000000", "0.00000000"], ["72027.45000000", "0.00034000"], ["71538.81000000", "0.00007000"], ["66959.50000000", "0.00000000"], ["65479.50000000", "0.00000000"], ["65479.00000000", "0.00000000"]], "a": [["72754.08000000", "8.52353000"], ["72754.09000000", "0.00038000"], ["72754.10000000", "0.00014000"], ["72754.39000000", "0.00000000"], ["72754.50000000", "0.00400000"], ["72754.65000000", "0.00000000"], ["72754.98000000", "0.00000000"], ["72755.00000000", "3.13718000"], ["72755.01000000", "3.07135000"], ["72755.02000000", "0.00000000"], ["72755.03000000", "0.00000000"], ["72755.26000000", "0.03407000"], ["72756.03000000", "0.12788000"], ["72756.13000000", "0.00000000"], ["72756.48000000", "0.16835000"], ["72756.53000000", "0.12082000"], ["72758.01000000", "0.41861000"], ["72758.77000000", "0.00016000"], ["72759.09000000", "0.07989000"], ["72759.42000000", "0.00007000"], ["72759.70000000", "0.00008000"], ["72759.71000000", "0.90625000"], ["72759.97000000", "0.00000000"], ["72760.01000000", "0.87925000"], ["72762.36000000", "0.00007000"], ["72762.74000000", "0.00008000"], ["72763.79000000", "0.00000000"], ["72765.01000000", "0.00000000"], ["72765.30000000", "0.00000000"], ["72766.77000000", "0.00000000"], ["72768.24000000", "0.00000000"], ["72769.02000000", "0.00000000"], ["72769.71000000", "0.00000000"], ["72771.01000000", "0.04190000"], ["72771.18000000", "0.00000000"], ["72771.41000000", "0.00000000"], ["72771.76000000", "0.00000000"], ["72772.75000000", "0.00000000"], ["72783.62000000", "0.00000000"], ["72785.87000000", "0.00349000"], ["72798.01000000", "0.00000000"], ["72830.92000000", "0.00000000"], ["73223.20000000", "0.00000000"], ["73482.57000000", "0.00007000"], ["73485.60000000", "0.00000000"]], "_local_ts_utc": "2026-06-01T07:48:52.710263+00:00"}
{"e": "depthUpdate", "E": 1780300133914, "s": "BTCUSDT", "U": 94551754966, "u": 94551755964, "b": [["72754.07000000", "0.00000000"], ["72754.06000000", "0.00000000"], ["72754.01000000", "0.00000000"], ["72754.00000000", "0.00000000"], ["72753.99000000", "0.00000000"], ["72753.94000000", "0.00000000"], ["72753.93000000", "0.00000000"], ["72753.84000000", "0.00000000"], ["72753.83000000", "0.00000000"], ["72753.74000000", "0.00000000"], ["72753.63000000", "0.00000000"], ["72753.60000000", "0.00000000"], ["72753.45000000", "0.00000000"], ["72753.39000000", "0.00000000"], ["72753.35000000", "0.00000000"], ["72753.34000000", "0.00000000"], ["72753.33000000", "0.00000000"], ["72753.29000000", "0.00000000"], ["72753.28000000", "0.00000000"], ["72753.00000000", "0.00000000"], ["72752.80000000", "0.00000000"], ["72752.71000000", "0.00000000"], ["72752.66000000", "0.00000000"], ["72752.65000000", "0.00000000"], ["72752.53000000", "0.00000000"], ["72752.48000000", "0.00000000"], ["72752.47000000", "0.00000000"], ["72752.26000000", "0.00000000"], ["72752.12000000", "0.00000000"], ["72752.04000000", "0.00000000"], ["72752.01000000", "0.00000000"], ["72752.00000000", "0.00000000"], ["72751.76000000", "0.00000000"], ["72751.70000000", "0.00000000"], ["72751.35000000", "0.00000000"], ["72751.02000000", "0.00000000"], ["72751.01000000", "0.00000000"], ["72751.00000000", "0.96522000"], ["72750.99000000", "0.00072000"], ["72750.33000000", "0.00000000"], ["72750.01000000", "0.00024000"], ["72750.00000000", "1.11028000"], ["72749.77000000", "0.00016000"], ["72749.71000000", "0.00024000"], ["72748.78000000", "0.00000000"], ["72748.49000000", "0.00000000"], ["72748.46000000", "0.00000000"], ["72748.27000000", "0.00000000"], ["72746.31000000", "0.02361000"], ["72745.40000000", "0.00000000"], ["72745.00000000", "0.00021000"], ["72744.99000000", "0.00000000"], ["72744.98000000", "0.00000000"], ["72744.36000000", "0.00000000"], ["72744.33000000", "0.00000000"], ["72743.64000000", "0.00000000"], ["72743.63000000", "0.00000000"], ["72743.52000000", "0.00031000"], ["72742.92000000", "0.00000000"], ["72742.82000000", "0.00031000"], ["72742.59000000", "0.00000000"], ["72742.31000000", "0.00000000"], ["72742.05000000", "0.00000000"], ["72741.00000000", "0.00000000"], ["72740.98000000", "0.07180000"], ["72740.72000000", "0.00000000"], ["72740.39000000", "0.00000000"], ["72740.31000000", "0.01621000"], ["72740.30000000", "0.00000000"], ["72739.51000000", "0.00300000"], ["72739.00000000", "0.05942000"], ["72737.36000000", "0.00000000"], ["72736.84000000", "0.18507000"], ["72736.83000000", "1.09302000"], ["72736.72000000", "0.04091000"], ["72736.46000000", "0.00008000"], ["72734.83000000", "0.18507000"], ["72734.67000000", "0.18507000"], ["72734.66000000", "3.40825000"], ["72733.72000000", "0.00008000"], ["72733.71000000", "0.09587000"], ["72732.93000000", "0.15287000"], ["72732.70000000", "0.00000000"], ["72730.55000000", "0.00000000"], ["72730.09000000", "0.17422000"], ["72730.08000000", "0.40856000"], ["72730.01000000", "0.00000000"], ["72727.61000000", "0.17662000"], ["72727.06000000", "0.00000000"], ["72726.44000000", "0.00000000"], ["72724.96000000", "0.00000000"], ["72724.24000000", "0.00000000"], ["72723.13000000", "0.02000000"], ["72719.65000000", "0.00000000"], ["72718.01000000", "0.01375000"], ["72716.69000000", "0.00000000"], ["72716.50000000", "0.00000000"], ["72715.93000000", "0.18506000"], ["72715.53000000", "0.00000000"], ["72715.14000000", "0.00007000"], ["72714.29000000", "0.02729000"], ["72714.05000000", "0.02465000"], ["72712.93000000", "0.00000000"], ["72712.77000000", "0.00000000"], ["72712.68000000", "0.00000000"], ["72712.65000000", "0.00000000"], ["72712.64000000", "0.00400000"], ["72712.59000000", "0.00000000"], ["72712.55000000", "0.00000000"], ["72712.35000000", "0.00000000"], ["72712.03000000", "0.00000000"], ["72711.99000000", "0.00000000"], ["72711.95000000", "0.00000000"], ["72711.88000000", "0.00000000"], ["72711.56000000", "0.00000000"], ["72711.52000000", "0.03386000"], ["72711.46000000", "0.00000000"], ["72711.32000000", "0.00000000"], ["72711.27000000", "0.00007000"], ["72711.24000000", "0.27659000"], ["72711.19000000", "0.00000000"], ["72711.07000000", "0.00000000"], ["72711.06000000", "0.00000000"], ["72711.02000000", "0.00000000"], ["72711.00000000", "0.00441000"], ["72710.99000000", "0.00000000"], ["72710.98000000", "0.00000000"], ["72710.41000000", "0.00000000"], ["72709.97000000", "0.17155000"], ["72708.50000000", "0.18506000"], ["72708.06000000", "0.00000000"], ["72707.04000000", "0.33819000"], ["72707.03000000", "0.18506000"], ["72704.09000000", "0.18506000"], ["72703.61000000", "0.00000000"], ["72703.49000000", "0.02749000"], ["72702.85000000", "0.18536000"], ["72701.47000000", "0.00000000"], ["72701.43000000", "0.00000000"], ["72699.33000000", "0.18506000"], ["72698.07000000", "0.18507000"], ["72698.06000000", "1.31549000"], ["72694.68000000", "0.01275000"], ["72694.26000000", "0.00016000"], ["72690.65000000", "1.00266000"], ["72689.79000000", "0.00431000"], ["72687.07000000", "1.04008000"], ["72687.00000000", "0.49589000"], ["72686.08000000", "0.18446000"], ["72678.01000000", "1.03310000"], ["72677.52000000", "0.00000000"], ["72676.01000000", "0.00000000"], ["72673.29000000", "0.19691000"], ["72670.01000000", "0.00281000"], ["72669.25000000", "0.82053000"], ["72666.67000000", "0.29797000"], ["72608.61000000", "0.00000000"], ["72590.95000000", "1.20000000"], ["72578.85000000", "0.00412000"], ["72535.01000000", "0.00007000"], ["72531.54000000", "0.03433000"], ["72531.38000000", "0.00007000"], ["72444.48000000", "0.00008000"], ["72387.26000000", "0.00007000"], ["71298.98000000", "0.00000000"], ["71298.27000000", "0.00000000"], ["71295.97000000", "0.00000000"], ["65478.67000000", "0.00000000"], ["65475.90000000", "0.00017000"]], "a": [["72751.01000000", "6.71257000"], ["72751.02000000", "0.00038000"], ["72751.03000000", "0.00014000"], ["72751.70000000", "0.03998000"], ["72751.77000000", "0.00000000"], ["72752.00000000", "0.00008000"], ["72752.01000000", "0.36845000"], ["72752.04000000", "0.00007000"], ["72752.13000000", "0.00000000"], ["72752.68000000", "0.00400000"], ["72752.72000000", "0.00000000"], ["72752.81000000", "0.00000000"], ["72753.01000000", "0.00000000"], ["72753.22000000", "0.00008000"], ["72753.29000000", "0.36836000"], ["72753.30000000", "0.00000000"], ["72753.32000000", "1.33163000"], ["72753.33000000", "0.00008000"], ["72753.34000000", "0.00000000"], ["72753.35000000", "1.06764000"], ["72753.36000000", "0.00000000"], ["72753.37000000", "0.00000000"], ["72753.40000000", "0.00000000"], ["72753.46000000", "0.00000000"], ["72753.61000000", "0.00000000"], ["72753.64000000", "0.00000000"], ["72753.74000000", "0.00000000"], ["72753.75000000", "0.10945000"], ["72753.84000000", "0.00000000"], ["72753.85000000", "0.21846000"], ["72753.86000000", "0.00000000"], ["72753.93000000", "0.00000000"], ["72753.95000000", "0.00000000"], ["72754.00000000", "0.00000000"], ["72754.01000000", "0.01264000"], ["72754.02000000", "0.00000000"], ["72754.07000000", "0.00000000"], ["72754.08000000", "0.61939000"], ["72754.09000000", "0.00000000"], ["72754.10000000", "0.00000000"], ["72754.99000000", "0.00000000"], ["72755.00000000", "0.65973000"], ["72755.01000000", "2.12217000"], ["72755.05000000", "0.00000000"], ["72755.12000000", "0.00000000"], ["72755.26000000", "0.03423000"], ["72756.00000000", "0.00000000"], ["72756.03000000", "0.00016000"], ["72756.48000000", "0.00000000"], ["72756.53000000", "0.12082000"], ["72757.91000000", "0.00000000"], ["72757.93000000", "0.76544000"], ["72757.94000000", "1.37843000"], ["72758.00000000", "0.00008000"], ["72758.01000000", "0.41845000"], ["72758.77000000", "0.00000000"], ["72759.70000000", "0.00028000"], ["72759.71000000", "0.75012000"], ["72759.97000000", "0.00008000"], ["72759.99000000", "0.00000000"], ["72760.00000000", "0.00008000"], ["72760.01000000", "0.70957000"], ["72760.96000000", "0.00008000"], ["72761.36000000", "0.00300000"], ["72761.85000000", "0.00581000"], ["72762.74000000", "0.00000000"], ["72762.82000000", "1.21569000"], ["72763.79000000", "0.00008000"], ["72763.80000000", "0.32331000"], ["72763.85000000", "0.00000000"], ["72764.01000000", "0.00000000"], ["72765.01000000", "0.00000000"], ["72765.83000000", "0.00007000"], ["72766.49000000", "0.00008000"], ["72766.50000000", "0.49535000"], ["72767.35000000", "0.00000000"], ["72767.94000000", "0.00000000"], ["72768.24000000", "0.00008000"], ["72768.64000000", "0.00000000"], ["72768.71000000", "0.00000000"], ["72768.84000000", "0.00012000"], ["72768.94000000", "0.01288000"], ["72769.69000000", "0.00007000"], ["72770.92000000", "0.00200000"], ["72771.01000000", "0.01356000"], ["72771.41000000", "0.00000000"], ["72772.27000000", "0.00008000"], ["72772.56000000", "0.00008000"], ["72773.40000000", "0.00008000"], ["72773.41000000", "1.36210000"], ["72773.44000000", "0.00000000"], ["72773.45000000", "0.00000000"], ["72773.48000000", "0.00000000"], ["72775.02000000", "0.00000000"], ["72775.28000000", "0.00200000"], ["72775.34000000", "0.00275000"], ["72775.35000000", "0.96798000"], ["72776.44000000", "0.00000000"], ["72777.13000000", "0.00000000"], ["72777.37000000", "0.00008000"], ["72779.01000000", "0.00000000"], ["72779.36000000", "0.00008000"], ["72779.39000000", "0.00008000"], ["72779.61000000", "0.00000000"], ["72781.80000000", "0.00000000"], ["72782.07000000", "0.00200000"], ["72782.70000000", "0.00000000"], ["72783.19000000", "0.00000000"], ["72784.31000000", "0.00433000"], ["72785.65000000", "1.03867000"], ["72786.72000000", "0.00008000"], ["72788.94000000", "0.00000000"], ["72794.05000000", "0.00000000"], ["72794.35000000", "0.00000000"], ["72795.53000000", "0.00000000"], ["72796.08000000", "0.00000000"], ["72798.00000000", "0.02280000"], ["72798.65000000", "0.20512000"], ["72802.98000000", "0.01075000"], ["72817.97000000", "0.00000000"], ["72821.54000000", "0.00000000"], ["72829.22000000", "1.29091000"], ["72831.19000000", "0.00000000"], ["72831.66000000", "0.00000000"], ["72836.93000000", "1.01256000"], ["72840.14000000", "0.00000000"], ["72841.09000000", "0.10224000"], ["72844.27000000", "0.00000000"], ["72847.12000000", "0.35137000"], ["72848.44000000", "0.00000000"], ["72871.36000000", "0.00000000"], ["72900.32000000", "0.00000000"], ["72905.53000000", "0.00000000"], ["72938.58000000", "0.00023000"], ["72945.22000000", "0.00007000"], ["72945.59000000", "0.00000000"], ["72948.85000000", "0.00007000"], ["72949.22000000", "0.00000000"], ["72963.54000000", "0.00085000"], ["72963.81000000", "0.00018000"], ["72980.01000000", "0.00488000"], ["72980.19000000", "0.00011000"], ["72985.44000000", "0.00031000"], ["72996.38000000", "0.00032000"], ["73028.84000000", "0.00000000"], ["73030.76000000", "0.00042000"], ["73033.73000000", "0.00008000"], ["73037.38000000", "0.00008000"], ["73045.69000000", "0.00142000"], ["73048.54000000", "0.01737000"], ["73089.78000000", "0.00009000"], ["73099.59000000", "0.00000000"], ["73128.96000000", "0.00068000"], ["73143.51000000", "0.00130000"], ["73182.07000000", "0.00199000"], ["73184.61000000", "0.00086000"], ["73197.26000000", "0.00000000"], ["73304.83000000", "0.00020000"], ["73460.19000000", "0.00024000"], ["73572.28000000", "0.00015000"], ["73694.00000000", "0.00570000"]], "_local_ts_utc": "2026-06-01T07:48:52.810742+00:00"}
{"e": "depthUpdate", "E": 1780300134014, "s": "BTCUSDT", "U": 94551755965, "u": 94551756119, "b": [["72751.00000000", "0.96772000"], ["72750.01000000", "0.35264000"], ["72750.00000000", "1.11028000"], ["72749.77000000", "0.00000000"], ["72749.70000000", "0.06884000"], ["72748.00000000", "0.02296000"], ["72747.59000000", "0.04406000"], ["72747.58000000", "0.00955000"], ["72747.26000000", "0.00031000"], ["72746.65000000", "0.01390000"], ["72746.59000000", "0.02431000"], ["72746.52000000", "0.00031000"], ["72746.31000000", "0.02377000"], ["72746.00000000", "0.02296000"], ["72745.85000000", "0.00000000"], ["72744.61000000", "0.09996000"], ["72744.60000000", "0.00000000"], ["72743.52000000", "0.00000000"], ["72742.82000000", "0.00000000"], ["72741.82000000", "0.00007000"], ["72741.14000000", "0.00000000"], ["72739.24000000", "0.18507000"], ["72737.84000000", "0.01375000"], ["72737.77000000", "0.18507000"], ["72736.66000000", "0.15738000"], ["72736.23000000", "0.02000000"], ["72733.71000000", "0.05760000"], ["72732.93000000", "0.00000000"], ["72730.42000000", "0.17831000"], ["72724.26000000", "0.00000000"], ["72722.42000000", "0.00000000"], ["72719.01000000", "0.00200000"], ["72718.01000000", "0.01923000"], ["72714.29000000", "0.00000000"], ["72712.88000000", "0.00000000"], ["72712.75000000", "0.00000000"], ["72712.69000000", "0.00000000"], ["72712.43000000", "0.00000000"], ["72712.30000000", "0.00000000"], ["72712.18000000", "0.00000000"], ["72712.04000000", "0.00000000"], ["72711.93000000", "0.00000000"], ["72711.90000000", "0.00000000"], ["72711.89000000", "0.00000000"], ["72687.80000000", "0.02000000"], ["65484.00000000", "0.00054000"], ["65475.90000000", "0.00051000"], ["58200.80000000", "0.00034000"]], "a": [["72751.01000000", "6.90761000"], ["72751.70000000", "0.04014000"], ["72751.76000000", "0.00008000"], ["72752.01000000", "0.18434000"], ["72753.29000000", "0.18434000"], ["72753.32000000", "0.66871000"], ["72753.35000000", "0.79764000"], ["72753.75000000", "0.04037000"], ["72753.85000000", "0.18393000"], ["72754.01000000", "0.01391000"], ["72754.08000000", "0.61923000"], ["72755.00000000", "0.65957000"], ["72755.01000000", "2.12201000"], ["72755.26000000", "0.00000000"], ["72756.03000000", "0.00000000"], ["72761.27000000", "0.00000000"], ["72762.00000000", "0.00080000"], ["72768.24000000", "0.00026000"], ["72769.07000000", "0.09400000"], ["72773.41000000", "0.00000000"], ["72777.21000000", "0.00207000"], ["72779.06000000", "0.00000000"], ["72779.37000000", "0.00000000"], ["72779.40000000", "0.00000000"], ["72780.63000000", "0.00000000"], ["72784.10000000", "0.02746000"], ["72788.60000000", "0.00000000"], ["72821.97000000", "1.79274000"], ["72821.98000000", "4.12482000"], ["72823.43000000", "0.06973000"], ["72847.12000000", "0.78939000"], ["72948.85000000", "0.00000000"], ["73087.10000000", "0.00000000"], ["89497.83000000", "0.00037000"]], "_local_ts_utc": "2026-06-01T07:48:52.911826+00:00"}
{"e": "depthUpdate", "E": 1780300134114, "s": "BTCUSDT", "U": 94551756120, "u": 94551756390, "b": [["72751.00000000", "3.29105000"], ["72750.99000000", "0.00072000"], ["72750.92000000", "0.00031000"], ["72750.03000000", "0.00016000"], ["72750.02000000", "0.00016000"], ["72750.01000000", "0.35280000"], ["72749.71000000", "0.00008000"], ["72749.14000000", "0.00000000"], ["72748.15000000", "0.15471000"], ["72748.14000000", "0.00000000"], ["72748.00000000", "0.02296000"], ["72747.84000000", "0.00000000"], ["72747.59000000", "0.00016000"], ["72747.44000000", "0.03482000"], ["72747.26000000", "0.00000000"], ["72747.22000000", "0.00400000"], ["72746.72000000", "0.00020000"], ["72746.71000000", "0.18117000"], ["72746.52000000", "0.00000000"], ["72746.31000000", "0.00029000"], ["72746.00000000", "0.02280000"], ["72745.40000000", "0.00400000"], ["72745.35000000", "0.18117000"], ["72745.34000000", "0.00000000"], ["72744.65000000", "0.00000000"], ["72744.61000000", "0.23176000"], ["72743.85000000", "0.18117000"], ["72742.42000000", "0.18117000"], ["72742.05000000", "0.00000000"], ["72740.99000000", "0.16921000"], ["72740.98000000", "0.39257000"], ["72740.76000000", "0.65949000"], ["72740.75000000", "0.16206000"], ["72739.56000000", "0.18132000"], ["72739.46000000", "0.00737000"], ["72739.00000000", "0.00000000"], ["72737.78000000", "0.65949000"], ["72736.84000000", "0.00000000"], ["72736.66000000", "0.00000000"], ["72735.27000000", "0.18117000"], ["72734.67000000", "0.00000000"], ["72734.26000000", "0.02000000"], ["72733.71000000", "0.15019000"], ["72732.41000000", "0.00000000"], ["72730.98000000", "0.18136000"], ["72728.12000000", "0.00000000"], ["72727.61000000", "0.00000000"], ["72727.20000000", "0.00400000"], ["72723.56000000", "0.00400000"], ["72722.19000000", "0.00000000"], ["72720.13000000", "0.00000000"], ["72718.12000000", "0.12309000"], ["72718.11000000", "0.00000000"], ["72718.10000000", "0.00000000"], ["72718.01000000", "0.00000000"], ["72716.68000000", "0.17600000"], ["72716.28000000", "0.00000000"], ["72714.46000000", "0.00000000"], ["72712.64000000", "0.00000000"], ["72709.97000000", "0.00000000"], ["72709.12000000", "0.49574000"], ["72708.50000000", "0.00000000"], ["72708.22000000", "0.00000000"], ["72707.66000000", "0.74936000"], ["72707.65000000", "1.36333000"], ["72707.04000000", "0.00000000"], ["72707.03000000", "0.00000000"], ["72705.76000000", "0.00008000"], ["72699.33000000", "0.00000000"], ["72698.07000000", "0.00000000"], ["72687.00000000", "0.00000000"], ["72685.73000000", "0.02000000"], ["72678.01000000", "0.45223000"], ["72677.29000000", "0.00010000"], ["72604.49000000", "0.00000000"], ["72595.95000000", "0.00717000"], ["71387.40000000", "0.00009000"], ["65475.90000000", "0.00085000"]], "a": [["72751.01000000", "4.10228000"], ["72751.19000000", "0.00000000"], ["72751.29000000", "0.00031000"], ["72751.69000000", "0.00000000"], ["72751.70000000", "0.00016000"], ["72752.00000000", "0.00008000"], ["72752.01000000", "0.00016000"], ["72752.08000000", "0.00763000"], ["72752.68000000", "0.00000000"], ["72753.28000000", "0.00000000"], ["72753.29000000", "0.00016000"], ["72753.31000000", "0.00016000"], ["72753.32000000", "0.68047000"], ["72753.34000000", "0.00016000"], ["72753.35000000", "0.10764000"], ["72753.74000000", "0.00016000"], ["72753.84000000", "0.00016000"], ["72754.07000000", "0.00016000"], ["72754.08000000", "0.17897000"], ["72754.95000000", "0.00000000"], ["72754.99000000", "0.65949000"], ["72755.00000000", "0.00008000"], ["72755.72000000", "0.00000000"], ["72755.74000000", "0.05304000"], ["72757.94000000", "0.33517000"], ["72758.47000000", "0.15000000"], ["72759.70000000", "0.65977000"], ["72759.88000000", "0.00687000"], ["72760.21000000", "0.00000000"], ["72763.80000000", "0.19977000"], ["72766.50000000", "0.00000000"], ["72768.04000000", "0.00540000"], ["72770.92000000", "0.00000000"], ["72771.03000000", "0.18117000"], ["72771.24000000", "0.06600000"], ["72771.41000000", "0.18117000"], ["72772.28000000", "0.00000000"], ["72777.21000000", "0.20207000"], ["72780.93000000", "0.00000000"], ["72781.22000000", "0.00000000"], ["72785.44000000", "0.00400000"], ["72788.71000000", "0.49520000"], ["72807.69000000", "0.06600000"]], "_local_ts_utc": "2026-06-01T07:48:53.010669+00:00"}
{"e": "depthUpdate", "E": 1780300134214, "s": "BTCUSDT", "U": 94551756391, "u": 94551756532, "b": [["72751.00000000", "3.29222000"], ["72750.99000000", "0.00072000"], ["72750.03000000", "0.00000000"], ["72749.71000000", "0.00024000"], ["72749.70000000", "0.06884000"], ["72749.04000000", "0.00400000"], ["72748.16000000", "0.00016000"], ["72748.15000000", "0.07461000"], ["72748.00000000", "0.02296000"], ["72747.93000000", "0.05950000"], ["72747.59000000", "0.00000000"], ["72747.58000000", "0.00955000"], ["72747.44000000", "0.03498000"], ["72746.72000000", "0.00012000"], ["72746.71000000", "0.00000000"], ["72746.65000000", "0.01374000"], ["72746.59000000", "0.02415000"], ["72745.35000000", "0.00000000"], ["72744.95000000", "0.01375000"], ["72744.91000000", "0.00000000"], ["72744.61000000", "0.17234000"], ["72743.85000000", "0.00000000"], ["72736.45000000", "0.00014000"], ["72734.01000000", "0.05635000"], ["72733.71000000", "0.00000000"], ["72730.98000000", "0.00019000"], ["72730.42000000", "0.00000000"], ["72730.09000000", "0.00000000"], ["72727.06000000", "0.18117000"], ["72719.92000000", "0.00000000"], ["72718.27000000", "0.00102000"], ["72718.12000000", "0.00000000"], ["72716.85000000", "0.06193000"], ["72712.22000000", "0.02712000"], ["72711.25000000", "0.46762000"], ["72711.24000000", "0.00000000"], ["72708.69000000", "0.00274000"], ["72707.67000000", "0.18117000"], ["72703.72000000", "0.00102000"], ["72699.33000000", "0.17408000"], ["72695.65000000", "0.00000000"], ["72661.60000000", "0.00008000"], ["72657.14000000", "0.00000000"], ["72552.59000000", "0.00000000"], ["72540.01000000", "0.00822000"], ["72045.32000000", "0.00465000"], ["72027.45000000", "0.00027000"], ["72026.52000000", "0.00000000"], ["65475.90000000", "0.00136000"], ["58200.80000000", "0.00000000"]], "a": [["72751.01000000", "2.98976000"], ["72751.70000000", "0.00000000"], ["72752.01000000", "0.00000000"], ["72752.08000000", "0.00779000"], ["72752.43000000", "0.00016000"], ["72752.44000000", "0.18117000"], ["72753.29000000", "0.00000000"], ["72753.30000000", "0.00016000"], ["72753.31000000", "0.18133000"], ["72753.32000000", "0.96865000"], ["72753.74000000", "0.00000000"], ["72753.75000000", "0.04053000"], ["72754.07000000", "0.00000000"], ["72754.08000000", "0.17913000"], ["72754.98000000", "0.16751000"], ["72754.99000000", "0.65965000"], ["72755.01000000", "2.01081000"], ["72757.92000000", "0.18117000"], ["72760.00000000", "0.00571000"], ["72761.65000000", "0.00188000"], ["72768.04000000", "0.00000000"], ["72768.17000000", "0.18117000"], ["72768.24000000", "0.18143000"], ["72768.25000000", "0.47225000"], ["72774.76000000", "0.00200000"], ["72807.41000000", "0.26000000"], ["72854.66000000", "0.00000000"], ["72870.41000000", "0.00000000"], ["73481.63000000", "0.00000000"], ["73482.57000000", "0.00000000"], ["73633.15000000", "0.00000000"]], "_local_ts_utc": "2026-06-01T07:48:53.110285+00:00"}
{"e": "depthUpdate", "E": 1780300134314, "s": "BTCUSDT", "U": 94551756533, "u": 94551756590, "b": [["72751.00000000", "3.29171000"], ["72750.92000000", "0.00000000"], ["72750.26000000", "0.00000000"], ["72749.83000000", "0.00000000"], ["72748.00000000", "0.02296000"], ["72747.93000000", "0.05966000"], ["72747.44000000", "0.03482000"], ["72727.50000000", "0.00349000"], ["72723.24000000", "0.00200000"], ["72721.89000000", "0.01371000"], ["72719.01000000", "0.00000000"], ["72699.33000000", "0.00000000"], ["72674.04000000", "0.00087000"], ["72647.76000000", "0.00000000"], ["72640.38000000", "0.02153000"], ["72023.49000000", "0.00007000"], ["69965.00000000", "0.00008000"], ["65475.90000000", "0.00153000"]], "a": [["72751.01000000", "3.30520000"], ["72752.08000000", "0.00779000"], ["72752.44000000", "0.18133000"], ["72753.17000000", "0.00016000"], ["72753.18000000", "0.05942000"], ["72753.31000000", "0.18149000"], ["72753.84000000", "0.00000000"], ["72754.08000000", "0.17897000"], ["72754.76000000", "0.00028000"], ["72754.99000000", "0.65949000"], ["72768.17000000", "0.18675000"], ["72768.24000000", "0.18125000"], ["72768.25000000", "0.46685000"], ["72777.21000000", "0.20007000"], ["72780.12000000", "0.01371000"], ["72781.45000000", "0.00200000"], ["72865.24000000", "0.44999000"], ["73478.53000000", "0.00007000"], ["89513.33000000", "0.00059000"]], "_local_ts_utc": "2026-06-01T07:48:53.209761+00:00"}
{"e": "depthUpdate", "E": 1780300134414, "s": "BTCUSDT", "U": 94551756591, "u": 94551756671, "b": [["72751.00000000", "1.96967000"], ["72750.01000000", "0.00040000"], ["72748.96000000", "0.00000000"], ["72748.15000000", "0.00030000"], ["72747.93000000", "0.00024000"], ["72747.92000000", "0.00013000"], ["72747.85000000", "0.00000000"], ["72745.64000000", "0.05942000"], ["72744.61000000", "0.00000000"], ["72742.42000000", "0.00000000"], ["72740.99000000", "0.00000000"], ["72740.98000000", "0.00000000"], ["72740.75000000", "0.00000000"], ["72739.56000000", "0.00015000"], ["72739.24000000", "0.00000000"], ["72737.77000000", "0.00000000"], ["72736.45000000", "0.00028000"], ["72735.10000000", "0.02000000"], ["72734.83000000", "0.00000000"], ["72729.18000000", "0.00102000"], ["72714.63000000", "0.02102000"], ["72698.73000000", "0.00000000"], ["72691.31000000", "0.00342000"], ["72679.12000000", "0.00000000"], ["72607.72000000", "0.00000000"], ["72595.96000000", "0.00113000"], ["65475.90000000", "0.00170000"]], "a": [["72751.01000000", "3.90534000"], ["72752.43000000", "0.00000000"], ["72752.44000000", "0.18133000"], ["72753.17000000", "0.00000000"], ["72753.18000000", "0.05958000"], ["72753.30000000", "0.00000000"], ["72753.31000000", "0.18133000"], ["72753.34000000", "0.00000000"], ["72754.01000000", "0.01375000"], ["72756.73000000", "0.18117000"], ["72759.59000000", "0.18117000"], ["72759.69000000", "0.18117000"], ["72766.74000000", "0.18117000"], ["72768.97000000", "0.07400000"], ["72771.46000000", "0.49532000"], ["72774.76000000", "0.00000000"], ["72780.73000000", "0.00000000"], ["72783.62000000", "0.00400000"], ["72785.44000000", "0.00000000"], ["72788.71000000", "0.00000000"], ["72793.65000000", "0.49517000"], ["73414.84000000", "0.00000000"]], "_local_ts_utc": "2026-06-01T07:48:53.310706+00:00"}
{"e": "depthUpdate", "E": 1780300134514, "s": "BTCUSDT", "U": 94551756672, "u": 94551756787, "b": [["72751.00000000", "1.13566000"], ["72750.99000000", "0.00072000"], ["72750.02000000", "0.00000000"], ["72750.01000000", "0.00024000"], ["72749.70000000", "0.06884000"], ["72749.04000000", "0.00000000"], ["72748.16000000", "0.00000000"], ["72748.15000000", "0.00014000"], ["72748.00000000", "0.02296000"], ["72747.93000000", "0.00008000"], ["72747.83000000", "0.00031000"], ["72747.58000000", "0.00016000"], ["72747.55000000", "0.02122000"], ["72747.44000000", "0.00016000"], ["72747.22000000", "0.00000000"], ["72746.65000000", "0.01390000"], ["72745.65000000", "0.00000000"], ["72745.64000000", "0.00000000"], ["72745.58000000", "0.00031000"], ["72744.95000000", "0.00000000"], ["72744.74000000", "0.00000000"], ["72744.60000000", "0.09479000"], ["72744.43000000", "0.00031000"], ["72743.31000000", "0.05942000"], ["72741.53000000", "0.00048000"], ["72740.77000000", "0.23397000"], ["72740.55000000", "0.00069000"], ["72738.13000000", "0.18117000"], ["72737.34000000", "0.00939000"], ["72736.84000000", "0.18117000"], ["72736.45000000", "0.00042000"], ["72734.67000000", "0.18117000"], ["72733.65000000", "0.02000000"], ["72730.09000000", "0.17644000"], ["72725.54000000", "0.00102000"], ["72721.90000000", "0.00102000"], ["72718.10000000", "0.00400000"], ["72716.28000000", "0.00400000"], ["72707.66000000", "0.23193000"], ["72707.65000000", "0.00000000"], ["72705.76000000", "0.18125000"], ["72699.33000000", "0.18117000"], ["72688.16000000", "0.02000000"], ["72678.01000000", "0.78657000"], ["72677.83000000", "1.36389000"], ["72668.11000000", "0.00356000"], ["72637.70000000", "0.00087000"], ["72629.23000000", "0.00031000"], ["65475.90000000", "0.00204000"], ["58200.80000000", "0.00034000"]], "a": [["72751.01000000", "3.90852000"], ["72752.68000000", "0.00400000"], ["72753.83000000", "0.04964000"], ["72754.55000000", "0.00009000"], ["72755.74000000", "0.00000000"], ["72759.88000000", "0.00000000"], ["72761.65000000", "0.00000000"], ["72762.45000000", "0.18117000"], ["72762.74000000", "0.18117000"], ["72764.97000000", "0.00400000"], ["72766.62000000", "0.00000000"], ["72768.24000000", "0.18143000"], ["72770.39000000", "0.04600000"], ["72771.95000000", "0.00200000"], ["72773.16000000", "1.36210000"], ["72775.01000000", "0.00200000"], ["72775.28000000", "0.00000000"], ["72781.80000000", "0.00000000"], ["72783.62000000", "0.00000000"], ["72806.84000000", "0.04600000"], ["72821.97000000", "0.56148000"], ["72821.98000000", "0.00000000"], ["72848.44000000", "0.83877000"], ["72851.41000000", "0.00626000"], ["72863.16000000", "0.00000000"], ["90321.56000000", "0.00029000"]], "_local_ts_utc": "2026-06-01T07:48:53.410807+00:00"}
{"e": "depthUpdate", "E": 1780300134614, "s": "BTCUSDT", "U": 94551756788, "u": 94551756859, "b": [["72751.00000000", "1.13166000"], ["72750.99000000", "0.00072000"], ["72749.07000000", "0.00031000"], ["72748.67000000", "0.00000000"], ["72748.08000000", "0.00039000"], ["72748.00000000", "0.02296000"], ["72747.83000000", "0.00000000"], ["72747.58000000", "0.00000000"], ["72747.56000000", "0.04044000"], ["72747.55000000", "0.02138000"], ["72747.44000000", "0.00000000"], ["72747.06000000", "0.00000000"], ["72746.59000000", "0.02431000"], ["72745.58000000", "0.00000000"], ["72745.40000000", "0.00000000"], ["72744.61000000", "0.00016000"], ["72744.60000000", "0.08104000"], ["72744.43000000", "0.00000000"], ["72743.31000000", "0.00000000"], ["72742.65000000", "0.01375000"], ["72740.78000000", "0.37184000"], ["72740.77000000", "0.00000000"], ["72739.61000000", "0.18003000"], ["72739.56000000", "0.16744000"], ["72724.62000000", "0.00000000"], ["72723.24000000", "0.00000000"], ["72718.60000000", "0.00200000"], ["72712.64000000", "0.00400000"], ["72691.25000000", "0.00000000"], ["72687.61000000", "0.04710000"], ["72640.38000000", "0.00000000"], ["65475.90000000", "0.00238000"], ["58200.80000000", "0.00000000"]], "a": [["72751.01000000", "3.91069000"], ["72752.49000000", "0.00008000"], ["72753.75000000", "0.04053000"], ["72753.83000000", "0.04980000"], ["72753.85000000", "0.18377000"], ["72754.94000000", "0.00007000"], ["72755.01000000", "2.01064000"], ["72757.41000000", "0.00007000"], ["72762.74000000", "0.00000000"], ["72776.82000000", "0.00200000"], ["72781.45000000", "0.00000000"], ["72834.10000000", "0.00060000"]], "_local_ts_utc": "2026-06-01T07:48:53.510747+00:00"}
{"e": "depthUpdate", "E": 1780300134714, "s": "BTCUSDT", "U": 94551756860, "u": 94551756932, "b": [["72751.00000000", "1.12197000"], ["72750.99000000", "0.00080000"], ["72750.02000000", "0.00016000"], ["72750.01000000", "0.35314000"], ["72749.72000000", "0.00031000"], ["72749.07000000", "0.00000000"], ["72748.08000000", "0.00008000"], ["72748.00000000", "0.02296000"], ["72747.57000000", "0.05242000"], ["72747.56000000", "0.00000000"], ["72744.90000000", "0.00754000"], ["72744.61000000", "0.00000000"], ["72744.60000000", "0.13858000"], ["72743.85000000", "0.18117000"], ["72742.59000000", "0.00000000"], ["72742.42000000", "0.16796000"], ["72741.53000000", "0.00000000"], ["72741.26000000", "0.00746000"], ["72740.99000000", "0.16594000"], ["72734.01000000", "0.10921000"], ["72730.98000000", "0.18136000"], ["72729.07000000", "0.00000000"], ["72721.00000000", "0.00224000"], ["72719.92000000", "0.00400000"], ["72714.46000000", "0.00000000"], ["72712.64000000", "0.00000000"], ["72697.04000000", "0.26000000"], ["72680.00000000", "2.26983000"], ["65475.90000000", "0.00272000"]], "a": [["72752.43000000", "0.00016000"], ["72753.17000000", "0.00016000"], ["72753.30000000", "0.00016000"], ["72753.31000000", "0.18149000"], ["72753.34000000", "0.00008000"], ["72754.99000000", "0.00000000"], ["72759.69000000", "0.00000000"], ["72762.45000000", "0.00000000"], ["72766.74000000", "0.00000000"], ["72768.24000000", "0.00026000"], ["72771.03000000", "0.00000000"], ["72771.41000000", "0.00000000"], ["72771.95000000", "0.00000000"], ["72773.16000000", "0.00000000"], ["72778.80000000", "0.00199000"], ["72829.99000000", "0.00000000"], ["72853.43000000", "0.00000000"], ["73027.01000000", "4.11323000"]], "_local_ts_utc": "2026-06-01T07:48:53.610192+00:00"}
{"e": "depthUpdate", "E": 1780300134814, "s": "BTCUSDT", "U": 94551756933, "u": 94551756967, "b": [["72751.00000000", "1.31678000"], ["72750.99000000", "0.00088000"], ["72750.01000000", "0.35330000"], ["72750.00000000", "1.11302000"], ["72748.00000000", "0.02296000"], ["72745.81000000", "0.05942000"], ["72745.40000000", "0.00400000"], ["72744.94000000", "0.01361000"], ["72744.90000000", "0.00000000"], ["72744.60000000", "0.36442000"], ["72744.01000000", "0.65949000"], ["72716.28000000", "0.00000000"], ["71659.73000000", "0.00348000"], ["65475.90000000", "0.00289000"]], "a": [["72751.01000000", "3.69857000"], ["72764.97000000", "0.00000000"], ["72766.74000000", "0.00400000"], ["72770.77000000", "0.00200000"], ["72775.01000000", "0.00000000"], ["72776.23000000", "0.00200000"], ["72870.51000000", "0.00032000"]], "_local_ts_utc": "2026-06-01T07:48:53.710516+00:00"}
{"e": "depthUpdate", "E": 1780300134914, "s": "BTCUSDT", "U": 94551756968, "u": 94551757015, "b": [["72751.00000000", "1.31292000"], ["72750.99000000", "0.00102000"], ["72750.98000000", "0.00014000"], ["72750.01000000", "0.35299000"], ["72749.72000000", "0.00000000"], ["72748.71000000", "0.00031000"], ["72748.26000000", "0.00000000"], ["72743.22000000", "0.00769000"], ["72736.72000000", "0.04084000"], ["72736.45000000", "0.00342000"], ["72733.65000000", "0.02007000"], ["72720.01000000", "0.00228000"], ["72718.60000000", "0.00000000"], ["65475.90000000", "0.00323000"]], "a": [["72752.00000000", "0.00000000"], ["72752.43000000", "0.00024000"], ["72753.31000000", "0.18157000"], ["72753.33000000", "0.00000000"], ["72753.84000000", "0.00008000"], ["72754.96000000", "0.00008000"], ["72754.97000000", "0.65949000"], ["72757.92000000", "0.18125000"], ["72757.93000000", "0.76536000"], ["72760.00000000", "0.00563000"], ["72762.76000000", "0.00007000"], ["72763.79000000", "0.00000000"], ["72765.83000000", "0.00000000"], ["72766.49000000", "0.00000000"], ["72767.19000000", "0.00008000"], ["72768.24000000", "0.00018000"], ["72768.71000000", "0.00008000"], ["72770.00000000", "0.00280000"], ["72771.44000000", "0.00008000"], ["72772.00000000", "0.00288000"], ["72772.27000000", "0.00000000"], ["72773.40000000", "0.00000000"], ["72774.00000000", "0.01280000"], ["72775.34000000", "0.00283000"], ["72775.99000000", "0.00000000"], ["72776.82000000", "0.00000000"], ["72776.99000000", "0.00008000"], ["72778.22000000", "0.00200000"], ["72779.39000000", "0.00000000"], ["72788.24000000", "0.00000000"], ["74077.75000000", "0.04567000"], ["74482.74000000", "0.00328000"]], "_local_ts_utc": "2026-06-01T07:48:53.810201+00:00"}
{"e": "depthUpdate", "E": 1780300135014, "s": "BTCUSDT", "U": 94551757016, "u": 94551757038, "b": [["72749.01000000", "0.00031000"], ["72693.42000000", "0.02072000"], ["65475.90000000", "0.00357000"], ["65475.00000000", "0.00109000"], ["58200.80000000", "0.00044000"]], "a": [["72753.22000000", "0.00000000"], ["72757.92000000", "0.26376000"], ["72767.30000000", "0.08200000"], ["72768.24000000", "0.00000000"], ["72768.25000000", "0.46721000"], ["72776.00000000", "0.94048000"], ["72902.00000000", "0.02080000"], ["72904.00000000", "0.02080000"], ["72906.00000000", "0.02080000"], ["72908.00000000", "0.02080000"], ["72910.00000000", "0.02080000"], ["72912.00000000", "0.02080000"], ["72914.00000000", "0.02080000"], ["72916.00000000", "0.02080000"]], "_local_ts_utc": "2026-06-01T07:48:53.911819+00:00"}
{"e": "depthUpdate", "E": 1780300135115, "s": "BTCUSDT", "U": 94551757039, "u": 94551757084, "b": [["72751.00000000", "1.30884000"], ["72750.99000000", "0.00094000"], ["72750.02000000", "0.00000000"], ["72750.01000000", "0.00040000"], ["72749.01000000", "0.00000000"], ["72748.71000000", "0.00000000"], ["72747.62000000", "0.00031000"], ["72747.58000000", "0.00016000"], ["72745.82000000", "0.00016000"], ["72725.73000000", "0.08251000"], ["72691.03000000", "0.02000000"], ["72690.31000000", "0.02000000"], ["65475.90000000", "0.00374000"], ["65475.00000000", "0.00089000"], ["58200.80000000", "0.00034000"]], "a": [["72757.92000000", "0.18125000"], ["72760.01000000", "0.70877000"], ["72766.48000000", "0.00400000"], ["72766.74000000", "0.00000000"], ["72769.59000000", "0.05400000"], ["72770.32000000", "0.05400000"], ["72776.23000000", "0.00000000"], ["72778.64000000", "0.00208000"], ["72806.05000000", "0.05400000"], ["72806.78000000", "0.05400000"], ["72826.91000000", "0.00000000"], ["72918.00000000", "0.02080000"], ["72920.00000000", "0.02413000"], ["72922.00000000", "0.02080000"], ["72924.00000000", "0.02080000"], ["72926.00000000", "0.02080000"], ["72928.00000000", "0.02080000"], ["72930.00000000", "0.02080000"], ["72932.00000000", "0.02080000"], ["72934.00000000", "0.02080000"], ["72936.00000000", "0.02080000"], ["72938.00000000", "0.02080000"], ["72940.00000000", "0.15707000"]], "_local_ts_utc": "2026-06-01T07:48:54.012192+00:00"}
{"e": "depthUpdate", "E": 1780300135214, "s": "BTCUSDT", "U": 94551757085, "u": 94551757146, "b": [["72751.00000000", "1.27014000"], ["72750.99000000", "0.00086000"], ["72750.01000000", "0.00024000"], ["72748.85000000", "0.00000000"], ["72748.15000000", "0.00045000"], ["72747.62000000", "0.00000000"], ["72743.85000000", "0.00000000"], ["72730.98000000", "0.00019000"], ["72727.06000000", "0.00000000"], ["72718.01000000", "0.01375000"], ["72716.85000000", "0.00000000"], ["72716.68000000", "0.00000000"], ["72711.35000000", "0.00013000"], ["72710.62000000", "0.00626000"], ["69203.69000000", "0.00000000"], ["65475.90000000", "0.00374000"], ["58200.80000000", "0.00000000"]], "a": [["72751.01000000", "3.75784000"], ["72752.43000000", "0.00008000"], ["72753.17000000", "0.00000000"], ["72753.18000000", "0.00016000"], ["72753.30000000", "0.00000000"], ["72753.31000000", "0.18141000"], ["72753.34000000", "0.00000000"], ["72754.00000000", "0.00080000"], ["72756.00000000", "0.00080000"], ["72757.92000000", "0.18125000"], ["72760.01000000", "0.70618000"], ["72771.03000000", "0.18117000"], ["72942.00000000", "0.02080000"], ["72944.00000000", "0.02080000"], ["72946.00000000", "0.02080000"], ["72948.00000000", "0.02080000"], ["72950.00000000", "0.02080000"], ["72952.00000000", "0.02080000"], ["72954.00000000", "0.02080000"], ["72956.00000000", "0.02080000"], ["72958.00000000", "0.02080000"], ["72960.00000000", "0.02428000"], ["72962.00000000", "0.02080000"]], "_local_ts_utc": "2026-06-01T07:48:54.110375+00:00"}
{"e": "depthUpdate", "E": 1780300135314, "s": "BTCUSDT", "U": 94551757147, "u": 94551757227, "b": [["72751.00000000", "1.26856000"], ["72748.63000000", "0.00000000"], ["72748.25000000", "0.00031000"], ["72748.15000000", "0.00014000"], ["72747.57000000", "0.05258000"], ["72744.94000000", "0.00000000"], ["72743.22000000", "0.00000000"], ["72742.42000000", "0.00000000"], ["72741.26000000", "0.00000000"], ["72740.99000000", "0.00000000"], ["72739.56000000", "0.00015000"], ["72738.13000000", "0.00000000"], ["72736.84000000", "0.00000000"], ["72736.62000000", "0.02000000"], ["72736.39000000", "0.02000000"], ["72735.27000000", "0.00000000"], ["72734.17000000", "0.02000000"], ["72734.01000000", "0.05635000"], ["72730.09000000", "0.00000000"], ["72694.82000000", "0.02000000"], ["72678.18000000", "0.02000000"], ["72677.95000000", "0.02000000"], ["72675.73000000", "0.02000000"], ["72550.01000000", "0.01023000"], ["72540.01000000", "0.00000000"], ["65475.90000000", "0.00374000"]], "a": [["72751.01000000", "3.92321000"], ["72752.44000000", "0.18133000"], ["72753.18000000", "0.00000000"], ["72753.85000000", "0.18393000"], ["72757.92000000", "0.26376000"], ["72758.00000000", "0.00088000"], ["72759.69000000", "0.18117000"], ["72760.00000000", "0.00643000"], ["72762.74000000", "0.18117000"], ["72766.74000000", "0.18117000"], ["72767.28000000", "0.08000000"], ["72767.39000000", "0.08600000"], ["72767.43000000", "0.07400000"], ["72768.24000000", "0.18117000"], ["72770.04000000", "0.06200000"], ["72771.41000000", "0.18117000"], ["72829.64000000", "0.00000000"], ["72836.81000000", "0.44459000"], ["72855.49000000", "0.00000000"], ["72902.00000000", "0.02000000"], ["72904.00000000", "0.02000000"], ["72906.00000000", "0.02000000"], ["72908.00000000", "0.02000000"], ["72910.00000000", "0.02000000"], ["72912.00000000", "0.02000000"], ["72914.00000000", "0.02000000"], ["72964.00000000", "0.02080000"], ["72966.00000000", "0.02080000"], ["72968.00000000", "0.02080000"], ["72970.00000000", "0.02091000"], ["72972.00000000", "0.02080000"], ["72974.00000000", "0.02089000"], ["72976.00000000", "0.02080000"], ["72978.00000000", "0.02080000"], ["72980.00000000", "0.02906000"], ["72982.00000000", "0.02080000"], ["72984.00000000", "0.02080000"], ["72986.00000000", "0.02080000"]], "_local_ts_utc": "2026-06-01T07:48:54.210651+00:00"}
{"e": "depthUpdate", "E": 1780300135414, "s": "BTCUSDT", "U": 94551757228, "u": 94551757275, "b": [["72751.00000000", "1.07277000"], ["72748.25000000", "0.00000000"], ["72747.08000000", "0.00031000"], ["72736.61000000", "0.02000000"], ["72727.06000000", "0.16583000"], ["72718.01000000", "0.07036000"], ["72716.68000000", "0.18117000"], ["72708.10000000", "0.17566000"], ["72698.00000000", "0.06200000"], ["72696.00000000", "1.02063000"], ["72694.00000000", "0.02200000"], ["72678.18000000", "0.00000000"], ["72678.15000000", "0.02000000"], ["72600.00000000", "6.05473000"], ["65475.90000000", "0.00374000"]], "a": [["72751.01000000", "3.92296000"], ["72767.40000000", "0.08600000"], ["72768.24000000", "0.18153000"], ["72768.25000000", "0.46685000"], ["72770.77000000", "0.00000000"], ["72772.30000000", "0.00200000"], ["72825.02000000", "0.00000000"], ["72916.00000000", "0.02000000"], ["72918.00000000", "0.02000000"], ["72920.00000000", "0.02333000"], ["72922.00000000", "0.02000000"], ["72924.00000000", "0.02000000"], ["72926.00000000", "0.02000000"], ["72928.00000000", "0.02000000"], ["72930.00000000", "0.02000000"], ["72932.00000000", "0.02000000"], ["72934.00000000", "0.02000000"], ["72936.00000000", "0.02000000"], ["72938.00000000", "0.02000000"], ["72988.00000000", "0.02080000"], ["72990.00000000", "0.02080000"], ["72992.00000000", "0.02080000"], ["72994.00000000", "0.02080000"], ["72996.00000000", "0.52080000"], ["72998.00000000", "0.02080000"], ["73000.00000000", "0.54092000"], ["73405.76000000", "0.00010000"]], "_local_ts_utc": "2026-06-01T07:48:54.310487+00:00"}
{"e": "depthUpdate", "E": 1780300135514, "s": "BTCUSDT", "U": 94551757276, "u": 94551757321, "b": [["72751.00000000", "1.06877000"], ["72747.47000000", "0.00031000"], ["72736.84000000", "0.18117000"], ["72730.09000000", "0.18117000"], ["72720.01000000", "0.00028000"], ["72719.59000000", "0.00200000"], ["72692.00000000", "0.02200000"], ["72690.00000000", "0.02483000"], ["72688.00000000", "0.04836000"], ["72687.61000000", "0.00000000"], ["72686.00000000", "0.03200000"], ["72684.00000000", "0.02577000"], ["72682.13000000", "0.04710000"], ["72682.00000000", "0.26718000"], ["72680.00000000", "2.27183000"], ["72678.15000000", "0.00000000"], ["72678.00000000", "1.05250000"], ["72676.00000000", "0.02200000"], ["72674.00000000", "0.02200000"], ["72672.00000000", "0.02200000"], ["72670.00000000", "0.02200000"], ["65475.90000000", "0.00391000"], ["58200.80000000", "0.00034000"]], "a": [["72776.52000000", "0.00000000"], ["72777.80000000", "0.00200000"], ["72778.22000000", "0.00000000"], ["72779.78000000", "0.00000000"], ["72779.79000000", "0.00000000"], ["72779.83000000", "0.00000000"], ["72782.43000000", "0.00000000"], ["72824.98000000", "0.00000000"], ["72828.91000000", "0.00000000"], ["72854.81000000", "0.00000000"], ["72940.00000000", "0.15627000"], ["72942.00000000", "0.02000000"], ["72944.00000000", "0.02000000"], ["72946.00000000", "0.02000000"], ["72948.00000000", "0.02000000"], ["72950.00000000", "0.02000000"], ["72952.00000000", "0.02000000"], ["72954.00000000", "0.02000000"], ["72956.00000000", "0.02000000"], ["72958.00000000", "0.02000000"], ["72960.00000000", "0.02348000"]], "_local_ts_utc": "2026-06-01T07:48:54.410685+00:00"}
{"e": "depthUpdate", "E": 1780300135614, "s": "BTCUSDT", "U": 94551757322, "u": 94551757381, "b": [["72751.00000000", "1.07140000"], ["72749.76000000", "0.00063000"], ["72748.50000000", "0.00031000"], ["72748.35000000", "0.00058000"], ["72747.08000000", "0.00000000"], ["72740.99000000", "0.18117000"], ["72740.79000000", "0.18117000"], ["72738.13000000", "0.18117000"], ["72735.27000000", "0.16656000"], ["72734.63000000", "0.02028000"], ["72733.96000000", "0.02000000"], ["72686.03000000", "0.02000000"], ["72683.25000000", "0.00007000"], ["72678.31000000", "0.00007000"], ["72677.95000000", "0.00000000"], ["72675.73000000", "0.00000000"], ["72668.00000000", "0.02700000"], ["72666.00000000", "0.48221000"], ["72664.00000000", "0.02200000"], ["72662.00000000", "0.02200000"], ["72660.00000000", "0.02420000"], ["72658.00000000", "0.02200000"], ["72656.00000000", "0.02406000"], ["72654.00000000", "0.02200000"], ["72652.00000000", "0.02200000"], ["72650.00000000", "0.37266000"], ["72648.00000000", "0.00943000"], ["65475.90000000", "0.00391000"], ["58200.80000000", "0.00000000"]], "a": [["72762.74000000", "0.00000000"], ["72766.00000000", "0.01080000"], ["72766.74000000", "0.00000000"], ["72768.00000000", "0.01098000"], ["72768.24000000", "0.00036000"], ["72769.16000000", "0.06200000"], ["72769.93000000", "0.05400000"], ["72770.00000000", "0.01280000"], ["72771.03000000", "0.00000000"], ["72771.41000000", "0.00000000"], ["72772.00000000", "0.01288000"], ["72772.30000000", "0.00000000"], ["72962.00000000", "0.02000000"], ["72964.00000000", "0.02000000"], ["72966.00000000", "0.02000000"], ["72968.00000000", "0.02000000"], ["72970.00000000", "0.02011000"], ["72972.00000000", "0.02000000"], ["72974.00000000", "0.02009000"], ["72976.00000000", "0.02000000"], ["72978.00000000", "0.02000000"], ["72980.00000000", "0.02826000"], ["72982.00000000", "0.02000000"], ["72984.00000000", "0.02000000"], ["72986.00000000", "0.02000000"], ["73850.00000000", "0.50964000"]], "_local_ts_utc": "2026-06-01T07:48:54.510807+00:00"}
{"e": "depthUpdate", "E": 1780300135714, "s": "BTCUSDT", "U": 94551757382, "u": 94551757443, "b": [["72751.00000000", "1.31678000"], ["72750.82000000", "0.00031000"], ["72750.15000000", "0.00031000"], ["72750.01000000", "0.35371000"], ["72749.22000000", "0.00000000"], ["72748.50000000", "0.00000000"], ["72747.47000000", "0.00000000"], ["72732.00000000", "0.03656000"], ["72721.80000000", "0.01382000"], ["72698.00000000", "0.06280000"], ["72696.00000000", "1.02143000"], ["72646.00000000", "0.00289000"], ["72644.00000000", "0.00200000"], ["72642.00000000", "0.00200000"], ["72640.00000000", "0.18950000"], ["72638.00000000", "0.00200000"], ["72636.00000000", "0.00200000"], ["72634.00000000", "0.00200000"], ["72632.00000000", "0.00200000"], ["72630.00000000", "0.01658000"], ["72628.00000000", "0.00706000"], ["72626.00000000", "0.00200000"], ["72624.00000000", "0.00200000"], ["72622.00000000", "0.00229000"], ["72600.00000000", "6.01473000"], ["65475.90000000", "0.00408000"]], "a": [["72752.43000000", "0.00024000"], ["72753.30000000", "0.00016000"], ["72753.31000000", "0.18157000"], ["72753.34000000", "0.00016000"], ["72753.84000000", "0.00016000"], ["72759.59000000", "0.00000000"], ["72759.69000000", "0.00000000"], ["72766.45000000", "0.00400000"], ["72766.48000000", "0.00000000"], ["72768.24000000", "0.00000000"], ["72768.25000000", "0.46739000"], ["72770.97000000", "0.00200000"], ["72778.57000000", "0.00200000"], ["72778.64000000", "0.00008000"], ["72779.20000000", "0.00000000"], ["72988.00000000", "0.02000000"], ["72990.00000000", "0.02000000"], ["72992.00000000", "0.02000000"], ["72994.00000000", "0.02000000"], ["72996.00000000", "0.52000000"], ["72998.00000000", "0.02000000"], ["73000.00000000", "0.58012000"]], "_local_ts_utc": "2026-06-01T07:48:54.610500+00:00"}
{"e": "depthUpdate", "E": 1780300135814, "s": "BTCUSDT", "U": 94551757444, "u": 94551757681, "b": [["72751.00000000", "3.23860000"], ["72750.99000000", "0.00086000"], ["72750.15000000", "0.00000000"], ["72750.02000000", "0.00016000"], ["72748.10000000", "0.03039000"], ["72747.58000000", "0.00000000"], ["72747.57000000", "0.10578000"], ["72747.55000000", "0.00016000"], ["72747.22000000", "0.00400000"], ["72746.72000000", "0.00028000"], ["72746.71000000", "0.18117000"], ["72745.82000000", "0.00000000"], ["72745.42000000", "0.01375000"], ["72745.35000000", "0.00000000"], ["72745.34000000", "0.17737000"], ["72744.02000000", "0.16609000"], ["72743.28000000", "0.19569000"], ["72742.65000000", "0.00000000"], ["72742.42000000", "0.17512000"], ["72740.55000000", "0.00000000"], ["72739.61000000", "0.00000000"], ["72734.01000000", "0.11520000"], ["72732.00000000", "0.02280000"], ["72730.98000000", "0.18136000"], ["72728.12000000", "0.18117000"], ["72722.99000000", "0.00200000"], ["72722.49000000", "0.00000000"], ["72719.59000000", "0.00000000"], ["72718.10000000", "0.00000000"], ["72718.01000000", "0.05661000"], ["72714.85000000", "0.49570000"], ["72707.66000000", "0.66331000"], ["72706.63000000", "1.36334000"], ["72694.00000000", "0.02280000"], ["72692.00000000", "0.02280000"], ["72690.00000000", "0.02563000"], ["72689.98000000", "0.00000000"], ["72688.00000000", "0.04916000"], ["72686.00000000", "0.03280000"], ["72684.00000000", "0.02657000"], ["72682.00000000", "0.26798000"], ["72680.00000000", "2.27263000"], ["72678.01000000", "0.45223000"], ["72678.00000000", "1.05330000"], ["72677.83000000", "0.00000000"], ["72676.00000000", "0.02280000"], ["72674.00000000", "0.02280000"], ["72620.00000000", "2.00760000"], ["72618.00000000", "0.00213000"], ["72616.00000000", "0.00466000"], ["72614.00000000", "0.00200000"], ["72612.00000000", "0.00287000"], ["72610.00000000", "0.03168000"], ["72608.00000000", "0.00200000"], ["72606.00000000", "0.00216000"], ["72604.00000000", "0.00200000"], ["72602.00000000", "0.00200000"], ["72600.00000000", "6.01673000"], ["65475.90000000", "0.00391000"]], "a": [["72751.01000000", "1.49371000"], ["72751.29000000", "0.00000000"], ["72752.08000000", "0.00016000"], ["72752.43000000", "0.00008000"], ["72752.44000000", "0.00016000"], ["72753.31000000", "0.18141000"], ["72753.32000000", "0.00016000"], ["72753.35000000", "0.03436000"], ["72753.43000000", "0.00016000"], ["72753.44000000", "0.05942000"], ["72753.75000000", "0.00016000"], ["72753.83000000", "0.00016000"], ["72753.84000000", "0.00024000"], ["72753.85000000", "0.07093000"], ["72753.94000000", "0.00000000"], ["72754.01000000", "0.00000000"], ["72754.06000000", "0.00008000"], ["72754.07000000", "0.56070000"], ["72754.08000000", "0.10074000"], ["72754.45000000", "0.00031000"], ["72754.97000000", "0.00000000"], ["72754.98000000", "0.00000000"], ["72755.01000000", "1.71145000"], ["72755.67000000", "0.04894000"], ["72756.73000000", "0.00000000"], ["72757.92000000", "0.00008000"], ["72757.93000000", "0.49458000"], ["72758.29000000", "0.27000000"], ["72759.09000000", "0.00792000"], ["72759.69000000", "0.00000000"], ["72759.70000000", "0.00028000"], ["72759.71000000", "0.45966000"], ["72759.98000000", "0.75236000"], ["72762.22000000", "0.65949000"], ["72762.75000000", "0.00000000"], ["72763.80000000", "0.37530000"], ["72765.24000000", "0.65949000"], ["72768.00000000", "0.02098000"], ["72768.16000000", "0.65949000"], ["72768.17000000", "0.00558000"], ["72768.26000000", "0.00000000"], ["72770.00000000", "0.02280000"], ["72771.40000000", "0.18117000"], ["72771.41000000", "0.65949000"], ["72771.42000000", "0.00008000"], ["72771.43000000", "0.00000000"], ["72771.45000000", "0.00000000"], ["72771.46000000", "0.00000000"], ["72772.00000000", "0.02288000"], ["72774.00000000", "0.02280000"], ["72774.56000000", "0.65957000"], ["72775.02000000", "2.74910000"], ["72775.03000000", "0.00000000"], ["72776.00000000", "0.02280000"], ["72777.80000000", "0.00000000"], ["72778.00000000", "0.43136000"], ["72778.43000000", "0.00000000"], ["72779.75000000", "0.65949000"], ["72779.76000000", "0.00000000"], ["72779.77000000", "0.00000000"], ["72781.21000000", "0.00200000"], ["72781.94000000", "1.46980000"], ["72781.95000000", "2.74910000"], ["72781.96000000", "0.00000000"], ["72782.00000000", "0.02280000"], ["72783.30000000", "0.65949000"], ["72786.87000000", "0.00000000"], ["72787.26000000", "0.00000000"], ["72788.24000000", "2.74910000"], ["72792.04000000", "0.65949000"], ["72792.35000000", "0.00000000"], ["72792.36000000", "0.00000000"], ["72793.03000000", "0.49517000"], ["72793.34000000", "1.09824000"], ["72794.34000000", "0.00000000"], ["72857.34000000", "0.82972000"], ["72857.35000000", "2.74910000"], ["72867.53000000", "0.82885000"], ["72867.54000000", "0.00000000"]], "_local_ts_utc": "2026-06-01T07:48:54.710389+00:00"}
{"e": "depthUpdate", "E": 1780300135914, "s": "BTCUSDT", "U": 94551757682, "u": 94551757874, "b": [["72751.00000000", "3.06653000"], ["72750.01000000", "0.35387000"], ["72749.78000000", "0.05942000"], ["72749.70000000", "0.06884000"], ["72748.10000000", "0.03055000"], ["72747.58000000", "0.00000000"], ["72747.57000000", "0.05258000"], ["72747.55000000", "0.00000000"], ["72746.72000000", "0.00012000"], ["72746.71000000", "0.00000000"], ["72746.59000000", "0.02415000"], ["72745.81000000", "0.00000000"], ["72745.34000000", "0.00000000"], ["72744.02000000", "0.00000000"], ["72743.28000000", "0.00000000"], ["72742.42000000", "0.00000000"], ["72734.01000000", "0.05635000"], ["72733.65000000", "0.02007000"], ["72730.98000000", "0.00019000"], ["72730.09000000", "0.00000000"], ["72728.12000000", "0.00000000"], ["72727.06000000", "0.00000000"], ["72708.10000000", "0.00000000"], ["72707.67000000", "0.00000000"], ["72705.76000000", "0.00008000"], ["72704.09000000", "0.00000000"], ["72699.33000000", "0.00000000"], ["72672.00000000", "0.02280000"], ["72670.00000000", "0.02280000"], ["72668.00000000", "0.02780000"], ["72666.00000000", "0.48301000"], ["72664.00000000", "0.02280000"], ["72662.00000000", "0.02280000"], ["72660.00000000", "0.02500000"], ["72658.00000000", "0.02280000"], ["72656.00000000", "0.02486000"], ["72654.00000000", "0.02280000"], ["72652.00000000", "0.02280000"], ["72650.00000000", "0.37346000"], ["65475.90000000", "0.00391000"]], "a": [["72751.01000000", "2.40865000"], ["72752.08000000", "0.00000000"], ["72752.43000000", "0.00024000"], ["72752.44000000", "0.16555000"], ["72752.68000000", "0.00000000"], ["72753.30000000", "0.00024000"], ["72753.31000000", "0.18133000"], ["72753.32000000", "0.00000000"], ["72753.35000000", "0.03436000"], ["72753.43000000", "0.00000000"], ["72753.44000000", "0.00016000"], ["72753.75000000", "0.00000000"], ["72753.83000000", "0.00000000"], ["72753.84000000", "0.00016000"], ["72753.85000000", "0.07093000"], ["72754.05000000", "0.00016000"], ["72754.06000000", "0.94280000"], ["72754.07000000", "0.00032000"], ["72754.08000000", "0.10090000"], ["72754.68000000", "0.00028000"], ["72754.76000000", "0.00000000"], ["72754.96000000", "0.00000000"], ["72754.99000000", "0.18117000"], ["72755.00000000", "0.65957000"], ["72755.01000000", "1.71161000"], ["72755.13000000", "0.00758000"], ["72755.67000000", "0.04910000"], ["72756.15000000", "0.05942000"], ["72756.52000000", "0.00008000"], ["72757.91000000", "0.18125000"], ["72757.92000000", "0.65949000"], ["72758.45000000", "0.08251000"], ["72760.01000000", "0.60997000"], ["72762.21000000", "0.00008000"], ["72762.67000000", "0.00190000"], ["72762.76000000", "0.00007000"], ["72765.23000000", "0.00008000"], ["72766.73000000", "0.00008000"], ["72766.74000000", "0.18117000"], ["72767.39000000", "0.08608000"], ["72768.15000000", "0.18125000"], ["72768.16000000", "0.66561000"], ["72768.17000000", "0.00000000"], ["72768.25000000", "0.46677000"], ["72769.15000000", "0.00008000"], ["72771.03000000", "0.18117000"], ["72771.39000000", "0.00008000"], ["72771.40000000", "0.83564000"], ["72771.42000000", "0.00000000"], ["72771.44000000", "0.00000000"], ["72773.89000000", "0.18117000"], ["72774.54000000", "0.00008000"], ["72774.55000000", "0.18117000"], ["72775.01000000", "1.80822000"], ["72776.99000000", "0.00000000"], ["72777.37000000", "0.00000000"], ["72777.64000000", "0.00008000"], ["72777.99000000", "0.00000000"], ["72779.73000000", "0.00008000"], ["72779.74000000", "0.95991000"], ["72780.00000000", "0.13408000"], ["72781.94000000", "1.46988000"], ["72781.99000000", "0.00000000"], ["72785.44000000", "0.00400000"], ["72787.25000000", "0.00000000"], ["72788.23000000", "0.65957000"], ["72792.03000000", "0.20765000"], ["72794.33000000", "0.00000000"], ["72800.43000000", "1.18413000"], ["72828.00000000", "0.02280000"], ["72848.44000000", "1.30203000"], ["72860.54000000", "0.72793000"], ["72862.91000000", "0.36216000"], ["72867.53000000", "0.00000000"], ["72897.34000000", "0.09603000"]], "_local_ts_utc": "2026-06-01T07:48:54.810652+00:00"}
{"e": "depthUpdate", "E": 1780300136014, "s": "BTCUSDT", "U": 94551757875, "u": 94551758239, "b": [["72751.00000000", "1.98749000"], ["72750.99000000", "0.00086000"], ["72750.82000000", "0.00000000"], ["72750.02000000", "0.00000000"], ["72750.01000000", "0.00040000"], ["72750.00000000", "1.11302000"], ["72749.78000000", "0.00016000"], ["72749.46000000", "0.00031000"], ["72747.57000000", "0.00000000"], ["72747.22000000", "0.00000000"], ["72745.42000000", "0.00000000"], ["72745.40000000", "0.00000000"], ["72745.34000000", "0.00000000"], ["72744.87000000", "0.01357000"], ["72744.60000000", "0.00000000"], ["72744.31000000", "0.00000000"], ["72744.02000000", "0.65949000"], ["72744.01000000", "0.00000000"], ["72742.42000000", "0.00000000"], ["72742.31000000", "0.00028000"], ["72741.93000000", "0.00779000"], ["72740.99000000", "0.18117000"], ["72740.80000000", "0.65949000"], ["72740.79000000", "0.00000000"], ["72740.78000000", "0.00000000"], ["72740.76000000", "0.00000000"], ["72739.56000000", "0.18132000"], ["72738.14000000", "0.18117000"], ["72738.13000000", "0.00000000"], ["72737.79000000", "0.65949000"], ["72737.78000000", "0.00000000"], ["72736.85000000", "0.18117000"], ["72736.84000000", "0.00000000"], ["72735.27000000", "0.18117000"], ["72734.69000000", "0.18117000"], ["72734.68000000", "3.40859000"], ["72734.67000000", "0.00000000"], ["72734.66000000", "0.00000000"], ["72730.98000000", "0.18136000"], ["72730.10000000", "0.58405000"], ["72730.09000000", "0.65949000"], ["72730.08000000", "0.00000000"], ["72729.98000000", "0.00000000"], ["72729.97000000", "0.00000000"], ["72729.11000000", "0.00000000"], ["72729.01000000", "0.00000000"], ["72728.91000000", "0.00000000"], ["72728.70000000", "0.00000000"], ["72728.12000000", "0.18117000"], ["72727.81000000", "0.15000000"], ["72727.50000000", "0.00000000"], ["72727.07000000", "1.79104000"], ["72727.06000000", "3.40859000"], ["72727.05000000", "0.00088000"], ["72727.04000000", "0.00000000"], ["72725.73000000", "0.00000000"], ["72723.74000000", "0.08261000"], ["72722.94000000", "0.00000000"], ["72722.93000000", "0.00000000"], ["72721.89000000", "0.01371000"], ["72720.12000000", "0.00000000"], ["72719.97000000", "0.00000000"], ["72719.54000000", "0.16437000"], ["72718.33000000", "0.18117000"], ["72718.32000000", "0.65949000"], ["72716.69000000", "0.18117000"], ["72716.68000000", "0.00000000"], ["72716.28000000", "0.00400000"], ["72715.95000000", "1.52163000"], ["72715.94000000", "2.93027000"], ["72715.93000000", "0.00000000"], ["72715.92000000", "0.00032000"], ["72715.91000000", "0.00000000"], ["72715.39000000", "0.00000000"], ["72714.46000000", "0.00400000"], ["72712.22000000", "0.00000000"], ["72711.23000000", "0.00000000"], ["72709.59000000", "0.18117000"], ["72709.58000000", "0.65949000"], ["72708.10000000", "0.18117000"], ["72707.84000000", "0.02672000"], ["72706.67000000", "0.18450000"], ["72706.64000000", "0.18117000"], ["72703.82000000", "0.18117000"], ["72703.81000000", "0.00000000"], ["72702.86000000", "0.18117000"], ["72702.85000000", "0.00029000"], ["72702.14000000", "0.00000000"], ["72701.85000000", "0.03662000"], ["72701.43000000", "0.18117000"], ["72700.02000000", "0.18117000"], ["72700.01000000", "0.00055000"], ["72699.33000000", "0.00000000"], ["72698.06000000", "0.66778000"], ["72698.05000000", "0.00000000"], ["72697.04000000", "0.00000000"], ["72696.82000000", "0.00000000"], ["72687.08000000", "1.35818000"], ["72685.83000000", "0.92230000"], ["72685.54000000", "0.00000000"], ["72683.19000000", "0.18446000"], ["72655.80000000", "0.65949000"], ["72654.58000000", "0.00000000"], ["72648.00000000", "0.01023000"], ["72646.00000000", "0.00369000"], ["72645.94000000", "0.00000000"], ["72644.00000000", "0.00280000"], ["72642.00000000", "0.00280000"], ["72640.00000000", "0.19030000"], ["72638.00000000", "0.00280000"], ["72636.00000000", "0.00280000"], ["72634.29000000", "0.00000000"], ["72634.00000000", "0.00280000"], ["72632.00000000", "0.00280000"], ["72630.00000000", "0.01738000"], ["72628.00000000", "0.00786000"], ["72460.91000000", "0.00000000"], ["65475.90000000", "0.00425000"], ["58200.80000000", "0.00034000"], ["47288.16000000", "0.00013000"]], "a": [["72751.01000000", "3.58749000"], ["72751.46000000", "0.05942000"], ["72752.43000000", "0.00008000"], ["72752.44000000", "0.16571000"], ["72752.68000000", "0.00400000"], ["72753.23000000", "0.00031000"], ["72753.30000000", "0.00008000"], ["72753.34000000", "0.00000000"], ["72753.35000000", "0.03436000"], ["72753.44000000", "0.00000000"], ["72753.84000000", "0.00000000"], ["72753.85000000", "0.07093000"], ["72753.94000000", "0.00000000"], ["72754.05000000", "0.00008000"], ["72754.06000000", "0.94296000"], ["72754.07000000", "0.00008000"], ["72754.08000000", "0.10090000"], ["72754.45000000", "0.00000000"], ["72754.99000000", "0.18133000"], ["72755.00000000", "0.65973000"], ["72755.01000000", "1.71145000"], ["72755.67000000", "0.04894000"], ["72756.15000000", "0.00000000"], ["72756.73000000", "0.18117000"], ["72757.91000000", "0.95955000"], ["72757.93000000", "0.00000000"], ["72758.47000000", "0.00000000"], ["72759.59000000", "0.17732000"], ["72759.70000000", "0.18145000"], ["72762.21000000", "0.00008000"], ["72762.67000000", "0.00000000"], ["72762.81000000", "0.00008000"], ["72765.23000000", "0.00008000"], ["72766.74000000", "0.00000000"], ["72768.13000000", "1.44173000"], ["72768.14000000", "2.74910000"], ["72768.15000000", "0.00638000"], ["72768.16000000", "0.65949000"], ["72768.25000000", "0.00000000"], ["72769.58000000", "0.00000000"], ["72771.03000000", "0.00000000"], ["72771.39000000", "0.00008000"], ["72771.40000000", "0.65447000"], ["72773.89000000", "0.00000000"], ["72774.55000000", "0.00000000"], ["72778.57000000", "0.00000000"], ["72780.12000000", "0.01371000"], ["72781.36000000", "0.00200000"], ["72781.80000000", "0.00000000"], ["72783.62000000", "0.00000000"], ["72785.44000000", "0.00000000"], ["72820.32000000", "2.28299000"], ["72821.07000000", "4.12486000"], ["72836.81000000", "0.00000000"], ["72857.34000000", "0.00000000"], ["72857.35000000", "0.00000000"], ["72860.54000000", "0.00000000"], ["72860.55000000", "0.00000000"], ["73032.11000000", "0.00000000"]], "_local_ts_utc": "2026-06-01T07:48:54.911350+00:00"}
{"e": "depthUpdate", "E": 1780300136114, "s": "BTCUSDT", "U": 94551758240, "u": 94551758399, "b": [["72751.00000000", "1.01820000"], ["72750.99000000", "0.00086000"], ["72750.01000000", "0.00024000"], ["72750.00000000", "1.11302000"], ["72749.78000000", "0.00000000"], ["72749.46000000", "0.00000000"], ["72748.13000000", "0.00000000"], ["72748.10000000", "0.00016000"], ["72748.01000000", "0.00000000"], ["72748.00000000", "0.02296000"], ["72747.60000000", "0.02063000"], ["72746.59000000", "0.02431000"], ["72746.00000000", "0.02296000"], ["72745.69000000", "0.00031000"], ["72744.87000000", "0.00000000"], ["72744.60000000", "0.00000000"], ["72744.03000000", "0.00000000"], ["72744.02000000", "0.00000000"], ["72741.79000000", "0.00000000"], ["72741.11000000", "0.00068000"], ["72740.99000000", "0.00000000"], ["72740.81000000", "0.00100000"], ["72740.80000000", "0.00000000"], ["72739.56000000", "0.00015000"], ["72738.73000000", "0.00000000"], ["72738.14000000", "0.00000000"], ["72737.80000000", "0.55144000"], ["72736.85000000", "0.00000000"], ["72736.83000000", "0.00000000"], ["72735.27000000", "0.00000000"], ["72734.69000000", "0.00000000"], ["72734.68000000", "0.65949000"], ["72734.01000000", "0.05635000"], ["72730.98000000", "0.18136000"], ["72730.12000000", "0.18117000"], ["72730.11000000", "0.41557000"], ["72730.10000000", "0.00000000"], ["72728.12000000", "0.18117000"], ["72727.08000000", "0.18117000"], ["72727.07000000", "1.60987000"], ["72723.74000000", "0.00010000"], ["72723.56000000", "0.00400000"], ["72722.99000000", "0.00000000"], ["72722.49000000", "0.00200000"], ["72722.27000000", "0.27936000"], ["72721.18000000", "0.18117000"], ["72719.54000000", "0.18128000"], ["72718.34000000", "0.32471000"], ["72718.10000000", "0.00400000"], ["72718.01000000", "0.00000000"], ["72715.96000000", "0.18117000"], ["72715.94000000", "2.74910000"], ["72714.46000000", "0.00000000"], ["72709.60000000", "0.18117000"], ["72709.59000000", "0.00000000"], ["72708.10000000", "0.00000000"], ["72706.64000000", "0.00000000"], ["72703.82000000", "0.00000000"], ["72703.81000000", "0.18117000"], ["72692.62000000", "0.18117000"], ["72689.59000000", "0.65949000"], ["72645.94000000", "0.00000000"], ["72626.00000000", "0.00280000"], ["72624.00000000", "0.00280000"], ["72622.00000000", "0.00309000"], ["72620.00000000", "2.00840000"], ["72618.00000000", "0.00293000"], ["72616.00000000", "0.00546000"], ["72614.00000000", "0.00280000"], ["72612.00000000", "0.00367000"], ["72610.00000000", "0.03248000"], ["72608.00000000", "0.00280000"], ["72606.00000000", "0.00296000"], ["72452.74000000", "0.00040000"], ["65475.90000000", "0.00425000"], ["58200.80000000", "0.00034000"]], "a": [["72751.01000000", "3.59036000"], ["72751.46000000", "0.05958000"], ["72753.86000000", "0.04995000"], ["72755.00000000", "0.65957000"], ["72755.67000000", "0.00000000"], ["72755.96000000", "0.03407000"], ["72762.21000000", "0.18125000"], ["72762.81000000", "0.18125000"], ["72765.23000000", "0.18125000"], ["72766.74000000", "0.18117000"], ["72768.12000000", "0.18117000"], ["72768.13000000", "1.44803000"], ["72768.15000000", "0.00008000"], ["72772.53000000", "0.49531000"], ["72774.55000000", "0.18117000"], ["72780.12000000", "0.00686000"], ["72780.70000000", "0.00200000"], ["72781.21000000", "0.00000000"], ["72793.65000000", "0.00000000"], ["72851.41000000", "0.00000000"], ["72855.75000000", "0.00939000"]], "_local_ts_utc": "2026-06-01T07:48:55.010623+00:00"}
{"e": "depthUpdate", "E": 1780300136214, "s": "BTCUSDT", "U": 94551758400, "u": 94551758482, "b": [["72751.00000000", "1.01162000"], ["72750.99000000", "0.00086000"], ["72749.70000000", "0.06884000"], ["72748.10000000", "0.00000000"], ["72748.00000000", "0.02296000"], ["72747.61000000", "0.00031000"], ["72747.60000000", "0.02079000"], ["72747.01000000", "0.00031000"], ["72745.69000000", "0.00000000"], ["72743.58000000", "0.00000000"], ["72741.93000000", "0.00011000"], ["72741.84000000", "0.00056000"], ["72741.13000000", "0.00048000"], ["72740.82000000", "0.24801000"], ["72740.81000000", "0.66049000"], ["72738.13000000", "0.18117000"], ["72737.81000000", "0.18117000"], ["72737.80000000", "1.30330000"], ["72734.71000000", "0.18117000"], ["72734.70000000", "2.74910000"], ["72734.01000000", "0.11520000"], ["72732.64000000", "0.00000000"], ["72732.41000000", "0.00000000"], ["72730.09000000", "1.06805000"], ["72723.24000000", "0.00000000"], ["72723.19000000", "0.08251000"], ["72721.18000000", "0.00000000"], ["72717.11000000", "0.00022000"], ["72710.82000000", "0.00400000"], ["72709.60000000", "0.00000000"], ["72702.55000000", "0.00022000"], ["72692.62000000", "0.00000000"], ["72687.99000000", "0.00022000"], ["72604.00000000", "0.00280000"], ["72602.00000000", "0.00280000"], ["72600.00000000", "6.01753000"], ["65475.90000000", "0.00425000"], ["65475.00000000", "0.00109000"], ["58200.80000000", "0.00000000"]], "a": [["72751.01000000", "3.90337000"], ["72751.42000000", "0.03407000"], ["72753.85000000", "0.07093000"], ["72753.86000000", "0.05011000"], ["72754.30000000", "0.01409000"], ["72754.99000000", "0.18117000"], ["72768.12000000", "0.18747000"], ["72768.13000000", "1.44173000"], ["72770.97000000", "0.00000000"], ["72774.55000000", "0.00000000"]], "_local_ts_utc": "2026-06-01T07:48:55.110584+00:00"}
{"e": "depthUpdate", "E": 1780300136314, "s": "BTCUSDT", "U": 94551758483, "u": 94551758521, "b": [["72744.61000000", "0.00016000"], ["72744.60000000", "0.07577000"], ["72741.52000000", "0.05942000"], ["72740.83000000", "0.36237000"], ["72740.82000000", "0.00000000"], ["72737.82000000", "0.16023000"], ["72731.91000000", "0.03407000"], ["72723.19000000", "0.00000000"], ["72723.18000000", "0.08251000"], ["72722.60000000", "0.00349000"], ["72715.41000000", "0.64952000"], ["72692.17000000", "1.26782000"], ["72552.59000000", "0.00822000"], ["72550.01000000", "0.00201000"], ["65475.90000000", "0.00425000"], ["65475.00000000", "0.00089000"]], "a": [["72751.01000000", "3.90337000"], ["72751.42000000", "0.00016000"], ["72754.08000000", "0.10074000"], ["72769.93000000", "0.05600000"], ["72836.93000000", "1.65610000"], ["72838.49000000", "2.43910000"]], "_local_ts_utc": "2026-06-01T07:48:55.210156+00:00"}
{"e": "depthUpdate", "E": 1780300136414, "s": "BTCUSDT", "U": 94551758522, "u": 94551758560, "b": [["72751.00000000", "1.00762000"], ["72747.84000000", "0.00031000"], ["72747.61000000", "0.00000000"], ["72742.09000000", "0.01375000"], ["72740.84000000", "0.27705000"], ["72740.83000000", "0.00000000"], ["72728.12000000", "0.00000000"], ["72722.49000000", "0.00000000"], ["72720.59000000", "0.00200000"], ["72712.64000000", "0.00400000"], ["72710.82000000", "0.00000000"], ["72706.67000000", "0.00333000"], ["72703.81000000", "0.00000000"], ["65475.90000000", "0.00425000"]], "a": [["72751.01000000", "3.69670000"], ["72751.42000000", "0.00000000"], ["72754.08000000", "0.10090000"], ["72778.79000000", "0.00200000"], ["72780.12000000", "0.01371000"], ["72780.70000000", "0.00000000"], ["72848.44000000", "0.83877000"], ["72862.91000000", "0.00000000"], ["72897.34000000", "0.00000000"]], "_local_ts_utc": "2026-06-01T07:48:55.310216+00:00"}
{"e": "depthUpdate", "E": 1780300136514, "s": "BTCUSDT", "U": 94551758561, "u": 94551758584, "b": [["72751.00000000", "1.00754000"], ["72750.99000000", "0.00094000"], ["72749.54000000", "0.00925000"], ["72748.51000000", "0.00031000"], ["72748.00000000", "0.02327000"], ["72747.01000000", "0.00000000"], ["72745.94000000", "0.01291000"], ["72744.61000000", "0.00000000"], ["72734.01000000", "0.05635000"], ["72730.98000000", "0.00019000"], ["72714.46000000", "0.00400000"], ["72712.64000000", "0.00000000"], ["65475.90000000", "0.00425000"], ["58200.80000000", "0.00034000"]], "a": [["72751.01000000", "3.68491000"], ["72768.13000000", "1.44191000"], ["72769.93000000", "0.05400000"]], "_local_ts_utc": "2026-06-01T07:48:55.410552+00:00"}
{"e": "depthUpdate", "E": 1780300136614, "s": "BTCUSDT", "U": 94551758585, "u": 94551758716, "b": [["72751.00000000", "0.66792000"], ["72750.99000000", "0.00094000"], ["72749.70000000", "0.06884000"], ["72749.54000000", "0.00941000"], ["72748.51000000", "0.00000000"], ["72748.00000000", "0.02296000"], ["72747.84000000", "0.00000000"], ["72747.60000000", "0.00016000"], ["72747.20000000", "0.01812000"], ["72746.00000000", "0.02327000"], ["72745.94000000", "0.01275000"], ["72745.83000000", "0.00031000"], ["72744.60000000", "0.00000000"], ["72742.49000000", "0.00000000"], ["72741.52000000", "0.00000000"], ["72740.86000000", "0.24986000"], ["72740.85000000", "0.65949000"], ["72740.84000000", "0.00000000"], ["72740.81000000", "0.00100000"], ["72740.31000000", "0.00237000"], ["72740.30000000", "0.01352000"], ["72739.46000000", "0.00000000"], ["72738.13000000", "0.17729000"], ["72737.82000000", "0.00000000"], ["72737.81000000", "0.00000000"], ["72737.80000000", "0.00000000"], ["72736.84000000", "0.18117000"], ["72736.83000000", "1.15616000"], ["72734.71000000", "0.16712000"], ["72730.13000000", "0.18027000"], ["72730.12000000", "0.40856000"], ["72730.09000000", "0.65949000"], ["72727.08000000", "0.18117000"], ["72723.18000000", "0.00000000"], ["72721.89000000", "0.01371000"], ["72719.54000000", "0.18128000"], ["72718.35000000", "0.18117000"], ["72718.34000000", "0.21781000"], ["72718.33000000", "0.00000000"], ["72716.69000000", "0.00000000"], ["72716.68000000", "0.16496000"], ["72715.96000000", "0.18117000"], ["72714.85000000", "0.00000000"], ["72708.10000000", "0.18117000"], ["72706.67000000", "0.18450000"], ["72706.64000000", "0.17467000"], ["72703.81000000", "0.18117000"], ["72702.86000000", "0.00000000"], ["72702.85000000", "0.18146000"], ["72701.43000000", "0.18117000"], ["72700.02000000", "0.00000000"], ["72700.01000000", "0.18172000"], ["72699.33000000", "0.00000000"], ["72693.80000000", "0.00000000"], ["72692.62000000", "0.00000000"], ["72686.68000000", "0.49589000"], ["72685.72000000", "0.00007000"], ["72535.71000000", "0.00007000"], ["65475.90000000", "0.00425000"], ["58201.00000000", "0.09068000"], ["58200.80000000", "0.00000000"]], "a": [["72751.01000000", "3.99417000"], ["72751.71000000", "0.03729000"], ["72753.86000000", "0.00016000"], ["72764.31000000", "0.00400000"], ["72766.45000000", "0.00000000"], ["72769.58000000", "0.00000000"], ["72771.01000000", "0.01556000"], ["72771.03000000", "0.00000000"], ["72771.39000000", "0.00008000"], ["72772.52000000", "0.00000000"], ["72774.55000000", "0.00000000"], ["72777.67000000", "0.00200000"], ["72780.12000000", "0.00686000"], ["72781.36000000", "0.00000000"], ["72921.37000000", "0.19884000"], ["72939.81000000", "0.00000000"], ["73832.21000000", "1.73238000"], ["73849.36000000", "0.00000000"], ["77534.13000000", "0.00000000"]], "_local_ts_utc": "2026-06-01T07:48:55.510474+00:00"}
{"e": "depthUpdate", "E": 1780300136714, "s": "BTCUSDT", "U": 94551758717, "u": 94551758781, "b": [["72749.51000000", "0.00000000"], ["72748.54000000", "0.00031000"], ["72748.00000000", "0.02296000"], ["72747.60000000", "0.00000000"], ["72747.20000000", "0.01828000"], ["72746.00000000", "0.02296000"], ["72745.83000000", "0.00000000"], ["72744.60000000", "0.07987000"], ["72741.68000000", "0.00000000"], ["72741.05000000", "0.17266000"], ["72741.04000000", "0.05942000"], ["72740.87000000", "0.00000000"], ["72740.86000000", "0.35457000"], ["72739.56000000", "0.18132000"], ["72735.27000000", "0.18117000"], ["72730.00000000", "0.08793000"], ["72720.72000000", "0.00200000"], ["72720.59000000", "0.00000000"], ["72552.59000000", "0.00000000"], ["72550.35000000", "0.01397000"], ["65475.90000000", "0.00408000"], ["58201.00000000", "0.08468000"]], "a": [["72751.01000000", "3.99201000"], ["72751.46000000", "0.05958000"], ["72751.71000000", "0.03745000"], ["72753.85000000", "0.07093000"], ["72753.86000000", "0.00000000"], ["72754.98000000", "0.65949000"], ["72755.00000000", "0.00008000"], ["72765.23000000", "0.00008000"], ["72768.10000000", "1.44361000"], ["72768.11000000", "2.74910000"], ["72768.12000000", "0.00630000"], ["72768.13000000", "0.00018000"], ["72768.14000000", "0.00000000"], ["72778.79000000", "0.00000000"], ["72778.93000000", "0.00200000"], ["72854.77000000", "0.45094000"]], "_local_ts_utc": "2026-06-01T07:48:55.610096+00:00"}
{"e": "depthUpdate", "E": 1780300136814, "s": "BTCUSDT", "U": 94551758782, "u": 94551758821, "b": [["72751.00000000", "0.66263000"], ["72748.54000000", "0.00000000"], ["72748.24000000", "0.00031000"], ["72747.15000000", "0.00031000"], ["72746.62000000", "0.00000000"], ["72744.61000000", "0.00000000"], ["72741.05000000", "0.00000000"], ["72739.56000000", "0.00015000"], ["72736.45000000", "0.19591000"], ["72735.27000000", "0.00000000"], ["72734.71000000", "0.00000000"], ["72730.13000000", "0.00000000"], ["72719.54000000", "0.17059000"], ["72708.10000000", "0.00000000"], ["72706.64000000", "0.00000000"], ["72703.81000000", "0.18117000"], ["72692.62000000", "0.17472000"], ["65475.90000000", "0.00417000"]], "a": [["72751.01000000", "3.99114000"], ["72765.23000000", "0.16582000"], ["72768.09000000", "0.18117000"], ["72768.10000000", "1.45009000"], ["72768.12000000", "0.00000000"], ["72768.13000000", "0.00000000"], ["72771.01000000", "0.01356000"], ["72780.12000000", "0.01371000"], ["77898.14000000", "0.00009000"]], "_local_ts_utc": "2026-06-01T07:48:55.710311+00:00"}
{"e": "depthUpdate", "E": 1780300136914, "s": "BTCUSDT", "U": 94551758822, "u": 94551758894, "b": [["72751.00000000", "0.65987000"], ["72748.24000000", "0.00000000"], ["72747.15000000", "0.00000000"], ["72746.46000000", "0.00031000"], ["72745.15000000", "0.00031000"], ["72744.60000000", "0.07987000"], ["72741.04000000", "0.00000000"], ["72740.88000000", "0.24572000"], ["72740.87000000", "0.65949000"], ["72740.86000000", "0.00185000"], ["72740.85000000", "0.00000000"], ["72738.13000000", "0.00000000"], ["72737.80000000", "0.65949000"], ["72737.79000000", "0.00000000"], ["72736.84000000", "0.00000000"], ["72733.65000000", "0.02000000"], ["72730.13000000", "0.40856000"], ["72730.12000000", "0.00000000"], ["72727.12000000", "0.18117000"], ["72727.08000000", "0.00000000"], ["72723.11000000", "0.08262000"], ["72721.89000000", "0.00686000"], ["72719.54000000", "0.18128000"], ["72718.36000000", "0.16656000"], ["72718.35000000", "0.00000000"], ["72716.69000000", "0.18117000"], ["72716.68000000", "0.00000000"], ["72706.68000000", "0.18117000"], ["72706.67000000", "0.00333000"], ["72703.82000000", "0.16927000"], ["72703.81000000", "0.00000000"], ["72692.62000000", "0.00000000"], ["65475.90000000", "0.00391000"]], "a": [["72751.45000000", "0.00008000"], ["72753.30000000", "0.00000000"], ["72757.90000000", "0.00008000"], ["72757.91000000", "0.95947000"], ["72762.76000000", "0.00000000"], ["72763.79000000", "0.00008000"], ["72767.39000000", "0.08600000"], ["72768.08000000", "0.00008000"], ["72768.09000000", "0.18765000"], ["72768.10000000", "1.44369000"], ["72768.15000000", "0.00000000"], ["72769.15000000", "0.00000000"], ["72771.03000000", "0.00000000"], ["72771.37000000", "0.00200000"], ["72771.39000000", "0.00008000"], ["72771.40000000", "0.65455000"], ["72772.52000000", "0.00008000"], ["72774.54000000", "0.00000000"], ["72774.55000000", "0.00008000"], ["72779.73000000", "0.00000000"], ["72780.12000000", "0.00686000"], ["72780.77000000", "0.00000000"], ["72788.23000000", "0.65949000"], ["72891.65000000", "0.02153000"], ["78262.15000000", "0.00000000"]], "_local_ts_utc": "2026-06-01T07:48:55.810449+00:00"}
{"e": "depthUpdate", "E": 1780300137014, "s": "BTCUSDT", "U": 94551758895, "u": 94551758934, "b": [["72751.00000000", "0.65337000"], ["72747.02000000", "0.00031000"], ["72746.54000000", "0.00031000"], ["72746.46000000", "0.00000000"], ["72745.15000000", "0.00000000"], ["72742.74000000", "0.05942000"], ["72733.65000000", "0.02007000"], ["72730.14000000", "0.00000000"], ["72727.12000000", "0.00000000"], ["72723.11000000", "0.00011000"], ["72721.89000000", "0.01371000"], ["72721.51000000", "0.00000000"], ["72720.72000000", "0.00000000"], ["72720.60000000", "0.00200000"], ["72719.54000000", "0.00011000"], ["72713.52000000", "0.00687000"], ["65475.90000000", "0.00391000"], ["58201.00000000", "0.08468000"], ["58200.80000000", "0.00034000"]], "a": [["72762.76000000", "0.00007000"], ["72768.08000000", "0.00675000"], ["72768.09000000", "0.18117000"], ["72771.39000000", "0.17214000"], ["72778.81000000", "0.00200000"], ["72778.93000000", "0.00000000"]], "_local_ts_utc": "2026-06-01T07:48:55.911304+00:00"}
{"e": "depthUpdate", "E": 1780300137114, "s": "BTCUSDT", "U": 94551758935, "u": 94551758973, "b": [["72751.00000000", "0.56586000"], ["72750.99000000", "0.00174000"], ["72747.02000000", "0.00000000"], ["72746.54000000", "0.00000000"], ["72744.60000000", "0.00000000"], ["72730.00000000", "0.07417000"], ["72706.68000000", "0.00000000"], ["72703.82000000", "0.00000000"], ["72695.14000000", "0.00465000"], ["72690.08000000", "0.00000000"], ["72681.71000000", "0.18446000"], ["72679.96000000", "0.03300000"], ["65475.90000000", "0.00391000"], ["60050.00000000", "6.16870000"], ["58200.80000000", "0.00034000"]], "a": [["72751.01000000", "3.99034000"], ["72769.58000000", "0.18117000"], ["72771.03000000", "0.16299000"], ["72813.48000000", "0.00686000"], ["72821.49000000", "0.00000000"], ["73648.26000000", "0.00000000"], ["77854.72000000", "0.00019000"], ["79155.75000000", "0.00000000"]], "_local_ts_utc": "2026-06-01T07:48:56.010345+00:00"}
{"e": "depthUpdate", "E": 1780300137214, "s": "BTCUSDT", "U": 94551758974, "u": 94551759032, "b": [["72751.00000000", "0.56194000"], ["72750.99000000", "0.00182000"], ["72745.88000000", "0.00031000"], ["72745.26000000", "0.00031000"], ["72740.30000000", "0.00000000"], ["72736.45000000", "0.00342000"], ["72723.13000000", "0.00000000"], ["72723.08000000", "0.00000000"], ["72722.98000000", "0.08251000"], ["72721.11000000", "0.02000000"], ["72718.36000000", "0.00000000"], ["72718.35000000", "0.18117000"], ["72716.69000000", "0.00000000"], ["72716.68000000", "0.16642000"], ["72706.67000000", "0.18450000"], ["72706.64000000", "0.16256000"], ["72703.81000000", "0.18117000"], ["72699.79000000", "0.00000000"], ["72692.62000000", "0.18117000"], ["72688.09000000", "0.00618000"], ["72681.71000000", "0.00000000"], ["72680.52000000", "0.00000000"], ["72664.91000000", "0.01737000"], ["72550.35000000", "0.00575000"], ["72550.01000000", "0.01023000"], ["65475.90000000", "0.00391000"], ["58200.80000000", "0.00000000"]], "a": [["72751.01000000", "3.98777000"], ["72763.84000000", "0.00400000"], ["72764.31000000", "0.00000000"], ["72767.38000000", "0.00200000"], ["72771.37000000", "0.00000000"], ["72771.39000000", "0.00008000"], ["72772.52000000", "0.00008000"], ["72775.19000000", "0.00200000"], ["72777.67000000", "0.00000000"], ["72780.12000000", "0.01371000"], ["72847.13000000", "0.74334000"], ["73516.65000000", "0.00300000"]], "_local_ts_utc": "2026-06-01T07:48:56.109651+00:00"}
{"e": "depthUpdate", "E": 1780300137314, "s": "BTCUSDT", "U": 94551759033, "u": 94551759056, "b": [["72751.00000000", "0.56062000"], ["72750.99000000", "0.00438000"], ["72746.62000000", "0.00000000"], ["72745.26000000", "0.00000000"], ["72742.09000000", "0.00000000"], ["72740.24000000", "0.01362000"], ["72735.13000000", "0.01375000"], ["72727.08000000", "0.17984000"], ["72720.60000000", "0.00000000"], ["72719.54000000", "0.17389000"], ["72718.19000000", "0.00200000"], ["72706.64000000", "0.00000000"], ["72703.81000000", "0.00000000"], ["72664.30000000", "2.03633000"], ["65475.90000000", "0.00374000"]], "a": [["72769.58000000", "0.00000000"], ["72771.03000000", "0.00000000"], ["72776.40000000", "0.00200000"], ["72778.81000000", "0.00000000"], ["72825.02000000", "0.07400000"], ["79225.75000000", "0.00000000"]], "_local_ts_utc": "2026-06-01T07:48:56.210208+00:00"}
{"e": "depthUpdate", "E": 1780300137414, "s": "BTCUSDT", "U": 94551759057, "u": 94551759083, "b": [["72751.00000000", "0.55662000"], ["72746.37000000", "0.00000000"], ["72746.02000000", "0.00000000"], ["72745.88000000", "0.00000000"], ["72744.60000000", "0.09350000"], ["72735.33000000", "0.20053000"], ["72601.16000000", "0.02153000"], ["72550.44000000", "0.09869000"], ["72548.45000000", "0.00000000"], ["71659.73000000", "0.00482000"], ["70250.00000000", "0.91064000"], ["65475.90000000", "0.00374000"], ["65475.00000000", "0.00109000"]], "a": [["72824.98000000", "0.08600000"], ["72851.99000000", "0.00000000"], ["73478.51000000", "0.00200000"], ["74206.02000000", "0.00220000"], ["74933.53000000", "0.00242000"], ["75661.04000000", "0.00266000"], ["79666.01000000", "0.00000000"]], "_local_ts_utc": "2026-06-01T07:48:56.310501+00:00"}
{"e": "depthUpdate", "E": 1780300137514, "s": "BTCUSDT", "U": 94551759084, "u": 94551759141, "b": [["72751.00000000", "0.55262000"], ["72745.83000000", "0.00000000"], ["72745.32000000", "0.00031000"], ["72744.61000000", "0.00000000"], ["72744.60000000", "0.00000000"], ["72742.74000000", "0.00000000"], ["72741.92000000", "0.00031000"], ["72740.90000000", "0.24630000"], ["72740.89000000", "0.65949000"], ["72740.88000000", "0.00000000"], ["72740.87000000", "0.00000000"], ["72735.33000000", "0.00000000"], ["72735.13000000", "0.00000000"], ["72730.14000000", "0.40856000"], ["72730.13000000", "0.00000000"], ["72728.28000000", "0.01375000"], ["72727.81000000", "0.03000000"], ["72727.08000000", "0.00000000"], ["72726.81000000", "0.12000000"], ["72721.89000000", "0.00686000"], ["72719.54000000", "0.00011000"], ["72718.35000000", "0.00000000"], ["72716.68000000", "0.00000000"], ["72715.96000000", "0.00000000"], ["72707.66000000", "0.23193000"], ["72706.67000000", "0.00333000"], ["72706.63000000", "0.00000000"], ["72677.33000000", "1.36389000"], ["72664.30000000", "0.00000000"], ["65475.90000000", "0.00374000"], ["65475.00000000", "0.00089000"], ["58200.80000000", "0.00034000"]], "a": [["72765.57000000", "0.00000000"], ["72768.09000000", "0.18135000"], ["72769.58000000", "0.18117000"], ["72771.03000000", "0.18117000"], ["72771.39000000", "0.18125000"], ["72772.52000000", "0.18125000"], ["72774.55000000", "0.17951000"], ["72780.12000000", "0.00686000"], ["72849.08000000", "0.00021000"]], "_local_ts_utc": "2026-06-01T07:48:56.410504+00:00"}
