{"e": "depthUpdate", "E": 1780300136515, "s": "ETHUSDT", "U": 76583069075, "u": 76583069113, "b": [["1974.59000000", "8.92080000"], ["1974.20000000", "10.58340000"], ["1973.65000000", "4.00420000"], ["1973.29000000", "0.01100000"], ["1973.17000000", "17.23450000"], ["1973.15000000", "0.30450000"], ["1777.14000000", "0.05260000"]], "a": [["1974.60000000", "133.92320000"], ["1974.69000000", "1.39500000"], ["1974.76000000", "11.56500000"], ["1974.79000000", "1.73240000"], ["1974.98000000", "0.57860000"], ["2027.00000000", "1.39710000"]], "_local_ts_utc": "2026-06-01T07:48:55.411576+00:00"}
{"e": "depthUpdate", "E": 1780300136615, "s": "ETHUSDT", "U": 76583069114, "u": 76583069699, "b": [["1974.59000000", "0.00000000"], ["1974.58000000", "0.00000000"], ["1974.56000000", "0.00000000"], ["1974.55000000", "0.00000000"], ["1974.54000000", "0.00000000"], ["1974.53000000", "0.00000000"], ["1974.52000000", "0.00000000"], ["1974.51000000", "0.00000000"], ["1974.50000000", "0.00000000"], ["1974.49000000", "0.00000000"], ["1974.48000000", "0.00000000"], ["1974.47000000", "0.00000000"], ["1974.46000000", "30.52800000"], ["1974.45000000", "0.00520000"], ["1974.44000000", "0.03110000"], ["1974.43000000", "0.01200000"], ["1974.42000000", "0.14030000"], ["1974.40000000", "0.01200000"], ["1974.39000000", "0.03490000"], ["1974.38000000", "0.19770000"], ["1974.37000000", "0.00260000"], ["1974.36000000", "0.08320000"], ["1974.35000000", "0.04770000"], ["1974.33000000", "0.00000000"], ["1974.32000000", "0.02640000"], ["1974.30000000", "0.00260000"], ["1974.28000000", "0.03290000"], ["1974.27000000", "0.00620000"], ["1974.26000000", "0.03260000"], ["1974.22000000", "0.00740000"], ["1974.21000000", "0.10300000"], ["1974.20000000", "1.26400000"], ["1974.18000000", "0.04850000"], ["1974.16000000", "0.06920000"], ["1974.15000000", "0.50920000"], ["1974.14000000", "0.12910000"], ["1974.13000000", "0.65110000"], ["1974.12000000", "6.82920000"], ["1974.11000000", "22.68130000"], ["1974.10000000", "11.61990000"], ["1974.08000000", "0.03000000"], ["1974.03000000", "29.16320000"], ["1974.02000000", "0.32670000"], ["1974.01000000", "1.10560000"], ["1974.00000000", "26.17070000"], ["1973.97000000", "0.00540000"], ["1973.95000000", "0.09110000"], ["1973.93000000", "22.73910000"], ["1973.92000000", "14.14400000"], ["1973.86000000", "3.61140000"], ["1973.82000000", "7.98320000"], ["1973.81000000", "0.14200000"], ["1973.80000000", "8.51780000"], ["1973.78000000", "6.93240000"], ["1973.77000000", "0.00500000"], ["1973.76000000", "13.90270000"], ["1973.75000000", "20.73640000"], ["1973.74000000", "7.08920000"], ["1973.73000000", "1.55720000"], ["1973.72000000", "7.57050000"], ["1973.71000000", "1.39940000"], ["1973.70000000", "8.69100000"], ["1973.69000000", "17.21650000"], ["1973.65000000", "4.00420000"], ["1973.62000000", "0.19940000"], ["1973.61000000", "20.60130000"], ["1973.60000000", "7.24730000"], ["1973.59000000", "0.12230000"], ["1973.58000000", "0.00000000"], ["1973.57000000", "1.11390000"], ["1973.55000000", "0.11210000"], ["1973.54000000", "0.00000000"], ["1973.53000000", "0.02000000"], ["1973.52000000", "7.16520000"], ["1973.50000000", "1.07440000"], ["1973.48000000", "0.00740000"], ["1973.47000000", "15.02170000"], ["1973.46000000", "22.59030000"], ["1973.40000000", "1.50610000"], ["1973.39000000", "0.29350000"], ["1973.32000000", "7.18160000"], ["1973.29000000", "0.01100000"], ["1973.23000000", "8.94790000"], ["1973.16000000", "22.86010000"], ["1972.99000000", "15.27270000"], ["1972.90000000", "0.99980000"], ["1972.78000000", "13.79650000"], ["1972.72000000", "1.09750000"], ["1972.71000000", "0.50900000"], ["1972.68000000", "1.06550000"], ["1972.66000000", "5.67680000"], ["1972.62000000", "8.52340000"], ["1972.42000000", "8.59950000"], ["1972.30000000", "18.33350000"], ["1972.22000000", "14.22920000"], ["1972.02000000", "0.00270000"], ["1971.82000000", "0.00260000"], ["1971.75000000", "1.03400000"], ["1971.62000000", "0.00000000"], ["1970.69000000", "1.22000000"], ["1970.68000000", "0.00370000"], ["1968.84000000", "0.00260000"], ["1968.75000000", "0.06530000"], ["1965.14000000", "0.06860000"], ["1962.40000000", "0.12990000"], ["1953.29000000", "1.53210000"], ["1934.97000000", "0.00710000"], ["1777.14000000", "0.00300000"], ["1777.02000000", "0.01610000"], ["1579.86000000", "0.25900000"], ["1579.68000000", "0.05160000"]], "a": [["1974.47000000", "75.66350000"], ["1974.48000000", "0.01050000"], ["1974.49000000", "0.01050000"], ["1974.50000000", "18.03690000"], ["1974.51000000", "0.00000000"], ["1974.52000000", "0.00000000"], ["1974.53000000", "0.00000000"], ["1974.54000000", "0.00000000"], ["1974.55000000", "0.00000000"], ["1974.56000000", "0.03540000"], ["1974.57000000", "4.98470000"], ["1974.58000000", "0.00540000"], ["1974.59000000", "22.68810000"], ["1974.60000000", "10.37300000"], ["1974.66000000", "0.00000000"], ["1974.68000000", "0.00000000"], ["1974.69000000", "0.00260000"], ["1974.70000000", "4.26070000"], ["1974.72000000", "0.00300000"], ["1974.74000000", "9.73410000"], ["1974.75000000", "13.50330000"], ["1974.76000000", "7.08920000"], ["1974.77000000", "0.00260000"], ["1974.78000000", "7.59560000"], ["1974.79000000", "0.01280000"], ["1974.90000000", "0.01730000"], ["1974.92000000", "0.70260000"], ["1974.94000000", "0.60080000"], ["1974.98000000", "0.61750000"], ["1975.08000000", "0.00000000"], ["1975.09000000", "0.69100000"], ["1975.13000000", "0.00260000"], ["1975.17000000", "8.31970000"], ["1975.26000000", "0.00260000"], ["1975.30000000", "0.01330000"], ["1975.45000000", "0.44000000"], ["1975.49000000", "0.00300000"], ["1975.50000000", "8.56040000"], ["1975.56000000", "14.18060000"], ["1975.71000000", "0.00560000"], ["1975.93000000", "0.60300000"], ["1976.02000000", "0.00000000"], ["1976.03000000", "0.00260000"], ["1976.14000000", "1.00660000"], ["1976.20000000", "3.97870000"], ["1976.26000000", "0.00300000"], ["1976.29000000", "0.56700000"], ["1976.40000000", "5.23360000"], ["1976.48000000", "0.03300000"], ["1976.49000000", "0.00000000"], ["1976.80000000", "15.77920000"], ["1976.83000000", "1.28680000"], ["1976.96000000", "0.00000000"], ["1977.31000000", "19.66520000"], ["1978.31000000", "0.00000000"], ["1978.74000000", "0.01020000"], ["1979.61000000", "0.00000000"], ["1979.80000000", "0.00000000"], ["1979.83000000", "0.00000000"], ["1981.81000000", "0.00680000"], ["1982.76000000", "0.00280000"], ["1983.20000000", "0.02570000"], ["1984.40000000", "0.05140000"], ["1985.45000000", "0.00740000"], ["1987.03000000", "0.00000000"], ["1991.66000000", "0.02560000"], ["1993.20000000", "0.00760000"], ["1993.30000000", "0.01480000"], ["1994.32000000", "0.03590000"], ["2007.63000000", "0.00300000"], ["2011.66000000", "0.05630000"], ["2027.64000000", "0.14580000"]], "_local_ts_utc": "2026-06-01T07:48:55.511483+00:00"}
{"e": "depthUpdate", "E": 1780300136715, "s": "ETHUSDT", "U": 76583069700, "u": 76583069762, "b": [["1974.46000000", "30.58360000"], ["1974.45000000", "0.01040000"], ["1974.35000000", "0.04510000"], ["1974.14000000", "22.42360000"], ["1974.13000000", "23.33650000"], ["1974.12000000", "0.00770000"], ["1974.10000000", "11.62300000"], ["1974.03000000", "22.69560000"], ["1974.00000000", "27.44740000"], ["1972.91000000", "1.14990000"], ["1972.42000000", "0.09250000"], ["1972.30000000", "12.21240000"], ["1972.22000000", "0.05080000"], ["1972.00000000", "30.88160000"], ["1971.84000000", "0.00260000"], ["1953.29000000", "0.01740000"], ["1777.02000000", "0.02850000"]], "a": [["1974.47000000", "83.46620000"], ["1974.48000000", "0.00510000"], ["1974.50000000", "4.50690000"], ["1974.58000000", "0.00000000"], ["1974.59000000", "0.00540000"], ["1974.60000000", "8.33450000"], ["1974.61000000", "0.00000000"], ["1974.64000000", "0.00000000"], ["1974.67000000", "0.00000000"], ["1974.68000000", "1.32120000"], ["1974.74000000", "5.36650000"], ["1974.75000000", "0.00000000"], ["1976.03000000", "8.50960000"], ["1976.29000000", "7.65620000"], ["1976.49000000", "7.08920000"], ["1976.83000000", "14.79010000"], ["1979.97000000", "0.00000000"], ["2040.53000000", "0.01500000"]], "_local_ts_utc": "2026-06-01T07:48:55.612372+00:00"}
{"e": "depthUpdate", "E": 1780300136815, "s": "ETHUSDT", "U": 76583069763, "u": 76583069773, "b": [["1974.46000000", "32.11970000"], ["1972.51000000", "1.01300000"], ["1972.36000000", "1.12830000"], ["1777.02000000", "0.03470000"]], "a": [["1974.47000000", "83.39780000"], ["1974.96000000", "4.56540000"], ["1975.36000000", "13.53470000"], ["1975.58000000", "2.04950000"]], "_local_ts_utc": "2026-06-01T07:48:55.710800+00:00"}
{"e": "depthUpdate", "E": 1780300136915, "s": "ETHUSDT", "U": 76583069774, "u": 76583069791, "b": [["1974.46000000", "30.58360000"], ["1974.14000000", "15.95600000"], ["1973.71000000", "4.44280000"], ["1973.59000000", "0.29280000"], ["1973.57000000", "1.21390000"], ["1973.37000000", "0.20130000"], ["1973.05000000", "6.44590000"], ["1972.19000000", "54.93570000"], ["1777.02000000", "0.04710000"]], "a": [["1974.47000000", "83.25880000"], ["1974.50000000", "6.24780000"], ["1975.00000000", "9.98470000"], ["1975.08000000", "0.00260000"], ["1975.40000000", "9.73450000"], ["1976.35000000", "0.00380000"]], "_local_ts_utc": "2026-06-01T07:48:55.810449+00:00"}
{"e": "depthUpdate", "E": 1780300137015, "s": "ETHUSDT", "U": 76583069792, "u": 76583069812, "b": [["1974.21000000", "0.10840000"], ["1974.19000000", "6.47280000"], ["1973.96000000", "0.47080000"], ["1973.71000000", "1.39940000"], ["1972.20000000", "16.76590000"], ["1972.19000000", "0.00300000"], ["1777.02000000", "0.05950000"], ["1474.79000000", "0.08720000"]], "a": [["1974.47000000", "80.46210000"], ["1974.58000000", "0.73720000"], ["1974.83000000", "0.64940000"], ["1974.88000000", "0.94500000"], ["1976.10000000", "15.80130000"], ["1977.27000000", "0.96500000"], ["1979.00000000", "4.17730000"], ["2474.83000000", "0.05730000"]], "_local_ts_utc": "2026-06-01T07:48:55.911304+00:00"}
{"e": "depthUpdate", "E": 1780300137115, "s": "ETHUSDT", "U": 76583069813, "u": 76583069860, "b": [["1974.46000000", "6.98510000"], ["1974.20000000", "1.77110000"], ["1974.19000000", "0.00520000"], ["1974.18000000", "0.05390000"], ["1974.13000000", "0.65110000"], ["1974.08000000", "6.49760000"], ["1973.88000000", "5.44620000"], ["1973.86000000", "3.88140000"], ["1973.74000000", "8.10720000"], ["1972.20000000", "0.00830000"], ["1969.15000000", "127.91170000"], ["1777.02000000", "0.07190000"]], "a": [["1974.47000000", "72.50850000"], ["1974.57000000", "4.99010000"], ["1974.64000000", "0.00260000"], ["1974.74000000", "10.90910000"], ["1974.77000000", "13.50830000"], ["1974.84000000", "1.20550000"], ["1974.96000000", "5.32140000"], ["1974.98000000", "1.42750000"], ["1975.15000000", "8.69110000"], ["1975.24000000", "0.00000000"], ["1975.35000000", "12.28310000"], ["1976.83000000", "1.28680000"], ["1977.27000000", "0.02000000"]], "_local_ts_utc": "2026-06-01T07:48:56.013354+00:00"}
{"e": "depthUpdate", "E": 1780300137215, "s": "ETHUSDT", "U": 76583069861, "u": 76583069960, "b": [["1974.46000000", "13.05940000"], ["1974.42000000", "0.09030000"], ["1974.38000000", "0.05580000"], ["1974.22000000", "0.00740000"], ["1974.21000000", "0.10840000"], ["1974.20000000", "1.26400000"], ["1974.18000000", "0.04850000"], ["1974.17000000", "0.10430000"], ["1974.16000000", "0.06920000"], ["1974.14000000", "7.14820000"], ["1974.13000000", "0.00500000"], ["1974.08000000", "0.03000000"], ["1974.06000000", "0.07050000"], ["1973.97000000", "6.47300000"], ["1973.94000000", "13.71290000"], ["1973.92000000", "0.64070000"], ["1973.86000000", "3.93140000"], ["1973.68000000", "52.40170000"], ["1973.57000000", "1.11390000"], ["1973.35000000", "0.12000000"], ["1973.05000000", "3.87000000"], ["1972.22000000", "14.23180000"], ["1777.02000000", "0.08430000"]], "a": [["1974.47000000", "68.03110000"], ["1974.50000000", "3.00520000"], ["1974.51000000", "0.01160000"], ["1974.55000000", "5.94980000"], ["1974.56000000", "7.12590000"], ["1974.57000000", "4.98470000"], ["1974.59000000", "0.00540000"], ["1974.60000000", "13.22240000"], ["1974.64000000", "7.09310000"], ["1974.68000000", "9.82980000"], ["1974.72000000", "11.07230000"], ["1974.73000000", "13.50570000"], ["1974.74000000", "0.63410000"], ["1974.77000000", "0.00260000"], ["1974.90000000", "0.00570000"], ["1975.07000000", "0.05000000"], ["1975.25000000", "0.54600000"], ["1975.27000000", "1.32610000"], ["1975.33000000", "0.00000000"], ["1976.02000000", "0.00000000"], ["1976.03000000", "0.00260000"], ["1976.29000000", "0.56700000"], ["1976.49000000", "0.00000000"], ["1976.76000000", "0.03290000"]], "_local_ts_utc": "2026-06-01T07:48:56.111799+00:00"}
{"e": "depthUpdate", "E": 1780300137315, "s": "ETHUSDT", "U": 76583069961, "u": 76583070006, "b": [["1974.46000000", "12.99510000"], ["1974.43000000", "0.00660000"], ["1974.39000000", "0.02950000"], ["1974.36000000", "0.15460000"], ["1974.04000000", "1.33810000"], ["1973.98000000", "0.65860000"], ["1973.94000000", "13.98290000"], ["1973.93000000", "23.27910000"], ["1973.86000000", "4.20140000"], ["1973.72000000", "7.30050000"], ["1972.73000000", "9.14830000"], ["1972.69000000", "0.27000000"], ["1972.17000000", "0.43110000"], ["1967.37000000", "0.00730000"], ["1964.58000000", "0.06450000"], ["1777.02000000", "0.09050000"]], "a": [["1974.47000000", "68.02100000"], ["1974.51000000", "0.01700000"], ["1974.52000000", "1.28230000"], ["1974.54000000", "0.00540000"], ["1974.59000000", "0.00000000"], ["1974.68000000", "8.50860000"], ["1974.74000000", "0.00380000"], ["1974.90000000", "1.59870000"], ["1974.97000000", "13.98930000"], ["1975.20000000", "5.22870000"], ["1979.39000000", "0.00380000"], ["1984.48000000", "0.00380000"], ["1989.71000000", "0.00380000"], ["1995.11000000", "0.00380000"]], "_local_ts_utc": "2026-06-01T07:48:56.210799+00:00"}
{"e": "depthUpdate", "E": 1780300137415, "s": "ETHUSDT", "U": 76583070007, "u": 76583070035, "b": [["1974.46000000", "16.76180000"], ["1974.37000000", "0.00800000"], ["1973.89000000", "2.80310000"], ["1969.08000000", "0.00000000"], ["1969.03000000", "0.58790000"], ["1964.58000000", "0.07160000"], ["1960.47000000", "0.02000000"], ["1934.97000000", "0.01320000"], ["1777.02000000", "0.10290000"], ["1192.00000000", "0.00000000"]], "a": [["1974.47000000", "68.00080000"], ["1974.90000000", "2.03070000"], ["1975.40000000", "9.75450000"], ["1976.00000000", "24.77880000"], ["1976.61000000", "1.87580000"], ["1984.33000000", "0.00700000"], ["1994.20000000", "0.01460000"], ["2000.12000000", "0.01050000"], ["2023.82000000", "0.01080000"], ["2025.40000000", "0.01570000"], ["2068.24000000", "0.01940000"], ["2134.88000000", "0.05960000"]], "_local_ts_utc": "2026-06-01T07:48:56.311510+00:00"}
{"e": "depthUpdate", "E": 1780300137515, "s": "ETHUSDT", "U": 76583070036, "u": 76583070066, "b": [["1974.46000000", "13.94830000"], ["1973.97000000", "0.00540000"], ["1973.69000000", "16.94650000"], ["1959.54000000", "0.08130000"], ["1777.02000000", "0.11530000"]], "a": [["1974.47000000", "67.95020000"], ["1974.55000000", "14.45840000"], ["1975.20000000", "3.63570000"], ["1975.27000000", "0.84010000"], ["1975.87000000", "5.14860000"], ["1975.88000000", "0.22050000"], ["1976.55000000", "5.51320000"], ["1977.55000000", "0.01930000"], ["1978.14000000", "0.02430000"], ["1978.29000000", "0.00260000"], ["1978.88000000", "0.00260000"]], "_local_ts_utc": "2026-06-01T07:48:56.412515+00:00"}
{"e": "depthUpdate", "E": 1780300137615, "s": "ETHUSDT", "U": 76583070067, "u": 76583070107, "b": [["1974.46000000", "25.75100000"], ["1974.21000000", "0.10300000"], ["1974.05000000", "9.52760000"], ["1973.97000000", "0.00540000"], ["1973.85000000", "2.07210000"], ["1973.83000000", "1.69230000"], ["1973.48000000", "2.53660000"], ["1972.25000000", "4.08110000"], ["1972.23000000", "0.27570000"], ["1972.17000000", "0.16110000"], ["1953.17000000", "1.50060000"], ["1777.02000000", "0.12770000"]], "a": [["1974.47000000", "67.93860000"], ["1974.51000000", "0.00540000"], ["1974.56000000", "7.12590000"], ["1974.77000000", "0.00260000"], ["1974.95000000", "0.51300000"], ["1974.97000000", "14.44830000"], ["1975.00000000", "9.45100000"], ["1975.94000000", "0.51940000"], ["1975.96000000", "8.74760000"], ["2000.66000000", "0.00780000"]], "_local_ts_utc": "2026-06-01T07:48:56.510646+00:00"}
{"e": "depthUpdate", "E": 1780300137715, "s": "ETHUSDT", "U": 76583070108, "u": 76583070218, "b": [["1974.46000000", "33.57340000"], ["1974.45000000", "0.00260000"], ["1974.39000000", "0.03970000"], ["1974.21000000", "0.10300000"], ["1974.20000000", "1.87780000"], ["1974.17000000", "6.57190000"], ["1974.16000000", "15.15860000"], ["1974.15000000", "23.19880000"], ["1974.14000000", "0.12910000"], ["1974.05000000", "3.06000000"], ["1974.04000000", "0.00000000"], ["1973.92000000", "0.03000000"], ["1973.55000000", "0.21210000"], ["1973.40000000", "1.30610000"], ["1973.35000000", "0.02000000"], ["1972.32000000", "10.55270000"], ["1972.22000000", "0.05080000"], ["1972.00000000", "35.88160000"], ["1970.96000000", "0.27410000"], ["1777.02000000", "0.14010000"]], "a": [["1974.47000000", "27.56950000"], ["1974.51000000", "0.00000000"], ["1974.52000000", "0.00260000"], ["1974.55000000", "1.70830000"], ["1974.56000000", "0.03000000"], ["1974.57000000", "0.01300000"], ["1974.58000000", "0.72560000"], ["1974.59000000", "0.00540000"], ["1974.60000000", "10.69910000"], ["1974.64000000", "0.00000000"], ["1974.67000000", "0.00270000"], ["1974.68000000", "0.00000000"], ["1974.72000000", "6.85270000"], ["1974.73000000", "0.00000000"], ["1974.75000000", "0.01160000"], ["1974.76000000", "0.00000000"], ["1974.78000000", "0.50640000"], ["1974.84000000", "0.00000000"], ["1974.89000000", "0.00000000"], ["1974.92000000", "0.00260000"], ["1974.93000000", "0.00000000"], ["1975.20000000", "0.03570000"], ["1975.27000000", "0.38110000"], ["1975.89000000", "8.54160000"], ["1976.03000000", "8.51120000"], ["1976.29000000", "7.65750000"], ["1976.49000000", "7.09050000"], ["1976.70000000", "6.84080000"], ["1976.76000000", "13.53860000"], ["1976.87000000", "0.20050000"], ["1982.57000000", "126.26010000"], ["2234.84000000", "0.06940000"]], "_local_ts_utc": "2026-06-01T07:48:56.613171+00:00"}
{"e": "depthUpdate", "E": 1780300137815, "s": "ETHUSDT", "U": 76583070219, "u": 76583070508, "b": [["1974.49000000", "75.93490000"], ["1974.48000000", "2.78010000"], ["1974.47000000", "5.87610000"], ["1974.46000000", "3.26510000"], ["1974.45000000", "0.00260000"], ["1974.44000000", "0.03110000"], ["1974.37000000", "0.00000000"], ["1974.36000000", "0.15200000"], ["1974.30000000", "0.00800000"], ["1974.29000000", "2.56050000"], ["1974.28000000", "6.50050000"], ["1974.26000000", "15.63170000"], ["1974.25000000", "7.09050000"], ["1974.23000000", "1.28070000"], ["1974.21000000", "0.10300000"], ["1974.17000000", "0.10430000"], ["1974.16000000", "14.39580000"], ["1974.12000000", "13.51340000"], ["1974.10000000", "12.26110000"], ["1974.00000000", "26.17070000"], ["1973.98000000", "0.02220000"], ["1973.87000000", "0.27960000"], ["1973.80000000", "8.51780000"], ["1973.73000000", "1.95720000"], ["1973.65000000", "3.60420000"], ["1973.63000000", "0.83090000"], ["1973.50000000", "1.07180000"], ["1973.22000000", "1.34000000"], ["1972.62000000", "0.01640000"], ["1972.41000000", "0.25510000"], ["1972.25000000", "3.81110000"], ["1970.97000000", "0.03880000"], ["1969.46000000", "0.01170000"], ["1965.25000000", "0.61080000"], ["1951.75000000", "0.02860000"], ["1935.00000000", "42.21460000"], ["1934.98000000", "0.00000000"], ["1777.05000000", "0.01090000"], ["1777.03000000", "0.00000000"], ["1777.02000000", "0.00990000"], ["1474.47000000", "0.01200000"]], "a": [["1974.47000000", "0.00000000"], ["1974.48000000", "0.00000000"], ["1974.49000000", "0.00000000"], ["1974.50000000", "6.96060000"], ["1974.51000000", "0.10000000"], ["1974.54000000", "0.00000000"], ["1974.55000000", "0.00000000"], ["1974.56000000", "0.00000000"], ["1974.57000000", "0.00540000"], ["1974.60000000", "0.58190000"], ["1974.66000000", "0.53990000"], ["1974.67000000", "0.00000000"], ["1974.68000000", "0.00540000"], ["1974.69000000", "3.21040000"], ["1974.70000000", "10.73990000"], ["1974.71000000", "0.00540000"], ["1974.72000000", "4.58990000"], ["1974.73000000", "0.00000000"], ["1974.79000000", "7.10330000"], ["1974.80000000", "13.61400000"], ["1974.88000000", "0.96860000"], ["1974.89000000", "7.09050000"], ["1974.92000000", "7.76050000"], ["1974.93000000", "7.09050000"], ["1974.96000000", "0.79640000"], ["1975.08000000", "1.50260000"], ["1975.21000000", "2.67740000"], ["1975.25000000", "0.03300000"], ["1975.31000000", "0.00260000"], ["1975.35000000", "12.28570000"], ["1975.38000000", "8.50990000"], ["1975.96000000", "8.75520000"], ["1976.00000000", "19.77880000"], ["1976.49000000", "0.00000000"], ["1976.79000000", "0.00260000"], ["1976.80000000", "0.00310000"], ["1977.05000000", "2.65300000"], ["1977.12000000", "0.03000000"], ["1979.09000000", "0.00000000"], ["1983.00000000", "0.48390000"], ["1983.36000000", "0.00000000"], ["1985.48000000", "0.00000000"], ["2006.38000000", "0.00710000"]], "_local_ts_utc": "2026-06-01T07:48:56.711486+00:00"}
{"e": "depthUpdate", "E": 1780300137915, "s": "ETHUSDT", "U": 76583070509, "u": 76583070603, "b": [["1974.49000000", "39.59190000"], ["1974.48000000", "0.01550000"], ["1974.47000000", "0.82770000"], ["1974.38000000", "0.05320000"], ["1974.34000000", "0.01300000"], ["1974.33000000", "6.75390000"], ["1974.32000000", "22.60010000"], ["1974.29000000", "4.73510000"], ["1974.26000000", "0.03260000"], ["1974.23000000", "0.00000000"], ["1974.09000000", "1.27930000"], ["1972.66000000", "3.55640000"], ["1972.44000000", "4.56940000"], ["1970.95000000", "2.14170000"], ["1777.05000000", "0.02330000"], ["1758.13000000", "0.28010000"]], "a": [["1974.50000000", "38.63650000"], ["1974.51000000", "0.00000000"], ["1974.61000000", "0.01160000"], ["1974.65000000", "0.00540000"], ["1974.66000000", "0.55150000"], ["1974.68000000", "0.01160000"], ["1974.69000000", "3.20500000"], ["1974.71000000", "0.00000000"], ["1974.75000000", "0.00000000"], ["1974.85000000", "1.20550000"], ["1974.91000000", "0.05260000"], ["1976.60000000", "0.00570000"], ["1976.96000000", "0.03000000"], ["1977.12000000", "0.00000000"], ["2384.77000000", "0.11330000"]], "_local_ts_utc": "2026-06-01T07:48:56.811436+00:00"}
{"e": "depthUpdate", "E": 1780300138015, "s": "ETHUSDT", "U": 76583070604, "u": 76583070639, "b": [["1974.48000000", "0.02090000"], ["1974.47000000", "0.06490000"], ["1974.30000000", "0.00260000"], ["1974.29000000", "1.21020000"], ["1974.28000000", "0.03290000"], ["1974.25000000", "0.00000000"], ["1974.22000000", "1.30990000"], ["1974.20000000", "2.51910000"], ["1974.17000000", "6.57190000"], ["1974.12000000", "0.00770000"], ["1974.01000000", "1.37560000"], ["1973.73000000", "1.95720000"], ["1973.29000000", "0.01100000"], ["1972.32000000", "10.82270000"], ["1777.05000000", "0.03570000"], ["1474.47000000", "0.00000000"]], "a": [["1974.56000000", "0.00540000"], ["1974.57000000", "2.15420000"], ["1974.58000000", "7.19320000"], ["1974.68000000", "0.01430000"], ["1974.69000000", "1.49670000"], ["1974.70000000", "4.27230000"], ["1974.74000000", "1.30190000"], ["1974.79000000", "7.74710000"], ["1974.88000000", "0.94500000"], ["1974.92000000", "8.24650000"]], "_local_ts_utc": "2026-06-01T07:48:56.912256+00:00"}
{"e": "depthUpdate", "E": 1780300138115, "s": "ETHUSDT", "U": 76583070640, "u": 76583070655, "b": [["1974.49000000", "39.43740000"], ["1974.48000000", "0.01550000"], ["1974.47000000", "0.01310000"], ["1972.32000000", "10.55270000"], ["1972.23000000", "0.00570000"], ["1777.05000000", "0.04810000"]], "a": [["1974.50000000", "38.66060000"], ["1974.59000000", "0.00800000"], ["1975.10000000", "0.57270000"], ["1976.73000000", "0.00000000"], ["1977.07000000", "1.21570000"], ["1980.33000000", "0.00750000"], ["2012.28000000", "0.00380000"]], "_local_ts_utc": "2026-06-01T07:48:57.011179+00:00"}
{"e": "depthUpdate", "E": 1780300138215, "s": "ETHUSDT", "U": 76583070656, "u": 76583070675, "b": [["1974.49000000", "39.43740000"], ["1974.48000000", "0.01810000"], ["1974.47000000", "0.77590000"], ["1974.20000000", "3.02620000"], ["1974.16000000", "15.84580000"], ["1974.12000000", "13.51320000"], ["1973.83000000", "0.31230000"], ["1777.05000000", "0.06050000"]], "a": [["1974.50000000", "24.93220000"], ["1974.74000000", "1.93460000"], ["1975.68000000", "0.10290000"], ["1976.78000000", "0.94500000"], ["1979.77000000", "0.00000000"], ["1980.10000000", "1.28000000"], ["2609.68000000", "0.22540000"]], "_local_ts_utc": "2026-06-01T07:48:57.111334+00:00"}
{"e": "depthUpdate", "E": 1780300138315, "s": "ETHUSDT", "U": 76583070676, "u": 76583071447, "b": [["1974.65000000", "93.02940000"], ["1974.64000000", "3.40490000"], ["1974.63000000", "0.01050000"], ["1974.62000000", "0.00260000"], ["1974.60000000", "0.00260000"], ["1974.59000000", "0.41250000"], ["1974.58000000", "41.01000000"], ["1974.57000000", "13.67060000"], ["1974.56000000", "20.16010000"], ["1974.55000000", "8.15130000"], ["1974.54000000", "0.00000000"], ["1974.53000000", "0.00260000"], ["1974.52000000", "0.00260000"], ["1974.51000000", "0.00000000"], ["1974.50000000", "1.03180000"], ["1974.49000000", "0.04810000"], ["1974.48000000", "0.00260000"], ["1974.47000000", "0.00000000"], ["1974.46000000", "3.26250000"], ["1974.45000000", "0.00000000"], ["1974.44000000", "0.02850000"], ["1974.43000000", "0.00660000"], ["1974.42000000", "0.08770000"], ["1974.40000000", "0.01250000"], ["1974.39000000", "6.50470000"], ["1974.36000000", "16.18600000"], ["1974.35000000", "0.04770000"], ["1974.34000000", "0.00760000"], ["1974.33000000", "6.74850000"], ["1974.30000000", "0.00570000"], ["1974.29000000", "6.24580000"], ["1974.28000000", "1.31350000"], ["1974.27000000", "7.09660000"], ["1974.25000000", "15.59890000"], ["1974.20000000", "1.87780000"], ["1974.17000000", "0.10430000"], ["1974.16000000", "14.54860000"], ["1974.15000000", "22.69220000"], ["1974.13000000", "3.60500000"], ["1974.10000000", "11.62300000"], ["1973.98000000", "0.40030000"], ["1973.97000000", "0.00280000"], ["1973.95000000", "0.19240000"], ["1973.84000000", "1.98270000"], ["1973.80000000", "8.61780000"], ["1973.78000000", "0.31280000"], ["1973.63000000", "0.63090000"], ["1973.60000000", "6.86660000"], ["1973.55000000", "0.11210000"], ["1973.54000000", "0.00260000"], ["1973.40000000", "0.00610000"], ["1972.76000000", "0.27550000"], ["1972.61000000", "0.00260000"], ["1972.16000000", "0.90150000"], ["1972.00000000", "35.85160000"], ["1969.57000000", "0.00270000"], ["1969.56000000", "0.00900000"], ["1969.53000000", "0.13180000"], ["1969.49000000", "0.01710000"], ["1966.65000000", "0.00000000"], ["1965.25000000", "0.12290000"], ["1953.17000000", "0.00000000"], ["1935.07000000", "0.00000000"], ["1876.46000000", "0.00000000"], ["1876.26000000", "0.00000000"], ["1875.90000000", "0.01050000"], ["1875.77000000", "0.00280000"], ["1777.05000000", "0.00470000"], ["1579.86000000", "0.25200000"], ["1579.66000000", "0.00700000"]], "a": [["1974.50000000", "0.00000000"], ["1974.51000000", "0.00000000"], ["1974.52000000", "0.00000000"], ["1974.56000000", "0.00000000"], ["1974.57000000", "0.00000000"], ["1974.58000000", "0.00000000"], ["1974.59000000", "0.00000000"], ["1974.60000000", "0.00000000"], ["1974.61000000", "0.00000000"], ["1974.64000000", "0.00000000"], ["1974.65000000", "0.00000000"], ["1974.66000000", "0.56330000"], ["1974.67000000", "0.00780000"], ["1974.68000000", "0.00000000"], ["1974.69000000", "0.00540000"], ["1974.70000000", "0.00570000"], ["1974.71000000", "0.10000000"], ["1974.72000000", "0.00300000"], ["1974.73000000", "0.00540000"], ["1974.74000000", "0.00380000"], ["1974.77000000", "0.00540000"], ["1974.78000000", "0.00000000"], ["1974.79000000", "0.01820000"], ["1974.80000000", "0.00830000"], ["1974.81000000", "0.00000000"], ["1974.83000000", "0.00300000"], ["1974.85000000", "0.00000000"], ["1974.86000000", "0.00000000"], ["1974.87000000", "0.00270000"], ["1974.88000000", "0.00000000"], ["1974.89000000", "0.00000000"], ["1974.90000000", "1.00470000"], ["1974.92000000", "2.10270000"], ["1974.93000000", "0.62400000"], ["1974.94000000", "0.00680000"], ["1974.95000000", "0.00000000"], ["1974.96000000", "0.04300000"], ["1974.97000000", "0.00000000"], ["1974.98000000", "0.05050000"], ["1974.99000000", "0.50640000"], ["1975.00000000", "1.11310000"], ["1975.05000000", "4.29100000"], ["1975.06000000", "0.00000000"], ["1975.08000000", "0.00260000"], ["1975.09000000", "0.70110000"], ["1975.11000000", "0.00000000"], ["1975.12000000", "0.04160000"], ["1975.13000000", "0.64900000"], ["1975.14000000", "13.50930000"], ["1975.15000000", "5.22590000"], ["1975.16000000", "0.00300000"], ["1975.18000000", "1.50000000"], ["1975.27000000", "0.00300000"], ["1975.32000000", "0.00000000"], ["1975.33000000", "11.27060000"], ["1975.34000000", "13.50930000"], ["1975.35000000", "1.45630000"], ["1975.36000000", "0.03000000"], ["1975.40000000", "7.16290000"], ["1975.43000000", "0.00000000"], ["1975.50000000", "8.56300000"], ["1975.52000000", "0.52360000"], ["1975.56000000", "14.17800000"], ["1975.60000000", "14.64040000"], ["1975.68000000", "0.06300000"], ["1975.73000000", "0.37810000"], ["1976.26000000", "8.51150000"], ["1976.49000000", "22.68930000"], ["1976.71000000", "7.09040000"], ["1976.73000000", "7.09040000"], ["1976.79000000", "0.00260000"], ["1976.93000000", "7.09040000"], ["1977.09000000", "13.63680000"], ["1977.30000000", "0.00000000"], ["1978.10000000", "29.52520000"], ["1979.94000000", "0.00260000"], ["1983.00000000", "0.00000000"], ["1993.54000000", "0.01420000"], ["2018.35000000", "0.46580000"]], "_local_ts_utc": "2026-06-01T07:48:57.211485+00:00"}
{"e": "depthUpdate", "E": 1780300138415, "s": "ETHUSDT", "U": 76583071448, "u": 76583072567, "b": [["1974.79000000", "0.00000000"], ["1974.78000000", "0.00000000"], ["1974.77000000", "0.00000000"], ["1974.76000000", "0.00000000"], ["1974.74000000", "0.00000000"], ["1974.73000000", "7.73630000"], ["1974.72000000", "0.00000000"], ["1974.71000000", "0.00260000"], ["1974.70000000", "0.00520000"], ["1974.69000000", "0.00260000"], ["1974.68000000", "0.00260000"], ["1974.67000000", "0.00260000"], ["1974.66000000", "0.00800000"], ["1974.65000000", "0.00260000"], ["1974.64000000", "0.00260000"], ["1974.63000000", "0.00260000"], ["1974.62000000", "0.00000000"], ["1974.61000000", "0.00000000"], ["1974.60000000", "0.00260000"], ["1974.59000000", "0.00000000"], ["1974.58000000", "0.00000000"], ["1974.57000000", "0.00260000"], ["1974.56000000", "0.03000000"], ["1974.55000000", "0.00000000"], ["1974.53000000", "0.00000000"], ["1974.52000000", "0.00540000"], ["1974.51000000", "0.00000000"], ["1974.50000000", "0.00560000"], ["1974.49000000", "0.00540000"], ["1974.48000000", "0.61070000"], ["1974.47000000", "0.00540000"], ["1974.46000000", "3.26630000"], ["1974.45000000", "0.00270000"], ["1974.44000000", "0.52850000"], ["1974.43000000", "0.00660000"], ["1974.40000000", "0.00940000"], ["1974.39000000", "0.03710000"], ["1974.38000000", "4.05210000"], ["1974.37000000", "0.00000000"], ["1974.36000000", "0.58710000"], ["1974.34000000", "23.97400000"], ["1974.33000000", "0.00000000"], ["1974.32000000", "0.02640000"], ["1974.31000000", "22.57370000"], ["1974.30000000", "8.68710000"], ["1974.29000000", "6.47140000"], ["1974.28000000", "4.43890000"], ["1974.27000000", "0.00620000"], ["1974.26000000", "0.03260000"], ["1974.25000000", "0.00000000"], ["1974.24000000", "22.72700000"], ["1974.22000000", "0.00740000"], ["1974.20000000", "1.26710000"], ["1974.16000000", "1.51920000"], ["1974.15000000", "13.67040000"], ["1974.14000000", "22.81840000"], ["1974.13000000", "13.51050000"], ["1974.12000000", "0.10900000"], ["1974.09000000", "6.61540000"], ["1974.08000000", "0.03000000"], ["1974.05000000", "3.06000000"], ["1974.04000000", "7.09040000"], ["1974.03000000", "15.60910000"], ["1974.00000000", "26.44070000"], ["1973.96000000", "0.47080000"], ["1973.95000000", "0.09110000"], ["1973.94000000", "13.98270000"], ["1973.88000000", "1.03520000"], ["1973.87000000", "0.47960000"], ["1973.84000000", "0.31220000"], ["1973.80000000", "22.02330000"], ["1973.78000000", "0.31280000"], ["1973.76000000", "0.08030000"], ["1973.75000000", "7.23310000"], ["1973.73000000", "1.55720000"], ["1973.72000000", "7.10050000"], ["1973.70000000", "8.68840000"], ["1973.68000000", "52.70170000"], ["1973.65000000", "4.00420000"], ["1973.63000000", "0.73090000"], ["1973.59000000", "0.12230000"], ["1973.51000000", "8.30460000"], ["1973.44000000", "0.45060000"], ["1973.29000000", "0.01100000"], ["1973.22000000", "1.34000000"], ["1973.11000000", "8.78780000"], ["1973.02000000", "2.83830000"], ["1973.01000000", "8.10450000"], ["1972.96000000", "15.61160000"], ["1972.95000000", "0.00000000"], ["1972.86000000", "1.43750000"], ["1972.81000000", "7.56170000"], ["1972.79000000", "7.19130000"], ["1972.78000000", "1.05470000"], ["1972.75000000", "0.28260000"], ["1972.66000000", "0.27920000"], ["1972.61000000", "0.00260000"], ["1972.58000000", "0.00000000"], ["1972.41000000", "0.25510000"], ["1972.35000000", "0.22640000"], ["1972.22000000", "0.05080000"], ["1972.16000000", "0.87150000"], ["1971.25000000", "17.11690000"], ["1971.24000000", "0.00000000"], ["1970.97000000", "0.03880000"], ["1969.66000000", "0.00000000"], ["1969.65000000", "26.28890000"], ["1969.60000000", "25.43260000"], ["1969.57000000", "0.00270000"], ["1969.47000000", "0.02190000"], ["1969.29000000", "0.58960000"], ["1969.03000000", "0.00700000"], ["1968.84000000", "0.00000000"], ["1968.75000000", "0.06270000"], ["1967.09000000", "0.07020000"], ["1967.00000000", "47.91890000"], ["1965.86000000", "0.51420000"], ["1950.00000000", "1719.01790000"], ["1935.29000000", "0.11050000"], ["1935.23000000", "0.01760000"], ["1935.15000000", "0.00900000"], ["1777.32000000", "0.00000000"], ["1777.19000000", "0.00000000"], ["1579.86000000", "0.24500000"], ["1579.84000000", "0.03750000"]], "a": [["1974.66000000", "0.00000000"], ["1974.67000000", "0.00000000"], ["1974.69000000", "0.00000000"], ["1974.70000000", "0.00000000"], ["1974.71000000", "0.00000000"], ["1974.72000000", "0.00000000"], ["1974.73000000", "0.00000000"], ["1974.74000000", "67.28580000"], ["1974.75000000", "3.00000000"], ["1974.76000000", "0.01020000"], ["1974.77000000", "0.00540000"], ["1974.78000000", "18.38460000"], ["1974.79000000", "11.45860000"], ["1974.80000000", "15.82430000"], ["1974.82000000", "0.03560000"], ["1974.83000000", "6.47060000"], ["1974.87000000", "0.00000000"], ["1974.89000000", "0.00000000"], ["1974.90000000", "0.00570000"], ["1974.91000000", "0.05260000"], ["1974.92000000", "0.81450000"], ["1974.93000000", "0.00000000"], ["1974.94000000", "0.00680000"], ["1974.96000000", "0.04040000"], ["1974.97000000", "0.00000000"], ["1974.98000000", "0.05050000"], ["1974.99000000", "0.50640000"], ["1975.02000000", "0.20000000"], ["1975.03000000", "0.03300000"], ["1975.04000000", "13.05440000"], ["1975.07000000", "8.55850000"], ["1975.08000000", "0.00260000"], ["1975.09000000", "0.69100000"], ["1975.10000000", "0.58690000"], ["1975.12000000", "7.54630000"], ["1975.13000000", "14.15450000"], ["1975.14000000", "0.00380000"], ["1975.15000000", "0.01020000"], ["1975.16000000", "14.18380000"], ["1975.17000000", "1.22980000"], ["1975.18000000", "0.00000000"], ["1975.19000000", "0.00260000"], ["1975.22000000", "9.10090000"], ["1975.23000000", "1.30260000"], ["1975.32000000", "13.50550000"], ["1975.33000000", "7.23920000"], ["1975.34000000", "0.00380000"], ["1975.40000000", "10.76290000"], ["1975.42000000", "0.20070000"], ["1975.45000000", "0.00000000"], ["1975.48000000", "1.20550000"], ["1975.58000000", "0.56700000"], ["1975.63000000", "9.88810000"], ["1975.66000000", "0.15110000"], ["1975.68000000", "0.07310000"], ["1975.70000000", "0.00570000"], ["1975.72000000", "0.94500000"], ["1975.93000000", "0.20300000"], ["1975.96000000", "5.92500000"], ["1975.97000000", "0.00260000"], ["1976.00000000", "20.17880000"], ["1976.49000000", "14.18080000"], ["1976.71000000", "16.94640000"], ["1976.79000000", "0.00000000"], ["1976.93000000", "0.00000000"], ["1976.97000000", "0.00000000"], ["1977.15000000", "0.00000000"], ["1977.30000000", "0.00000000"], ["1977.33000000", "0.00000000"], ["1977.61000000", "0.00000000"], ["1979.79000000", "0.00000000"], ["1979.80000000", "0.00000000"], ["1980.00000000", "8.28010000"], ["1980.06000000", "0.02430000"], ["1980.15000000", "0.00260000"], ["1981.90000000", "1.00000000"], ["1982.75000000", "0.00000000"], ["1982.80000000", "0.47520000"], ["1984.65000000", "0.01850000"], ["2947.03000000", "0.36730000"]], "_local_ts_utc": "2026-06-01T07:48:57.311595+00:00"}
{"e": "depthUpdate", "E": 1780300138515, "s": "ETHUSDT", "U": 76583072568, "u": 76583072964, "b": [["1974.73000000", "0.00000000"], ["1974.71000000", "0.00000000"], ["1974.70000000", "0.00000000"], ["1974.69000000", "0.00000000"], ["1974.68000000", "0.00000000"], ["1974.67000000", "0.00000000"], ["1974.66000000", "0.00000000"], ["1974.65000000", "0.00000000"], ["1974.64000000", "0.00000000"], ["1974.63000000", "0.00000000"], ["1974.60000000", "0.00000000"], ["1974.57000000", "30.32010000"], ["1974.56000000", "0.01320000"], ["1974.55000000", "7.23160000"], ["1974.52000000", "0.00260000"], ["1974.51000000", "0.00000000"], ["1974.50000000", "0.00820000"], ["1974.49000000", "0.00260000"], ["1974.48000000", "0.00260000"], ["1974.47000000", "0.00800000"], ["1974.46000000", "3.26890000"], ["1974.45000000", "0.00800000"], ["1974.44000000", "0.03110000"], ["1974.39000000", "0.04250000"], ["1974.38000000", "14.39960000"], ["1974.37000000", "0.00000000"], ["1974.36000000", "0.58980000"], ["1974.35000000", "22.73700000"], ["1974.34000000", "1.28470000"], ["1974.32000000", "0.02640000"], ["1974.29000000", "0.00380000"], ["1974.25000000", "29.15690000"], ["1974.24000000", "0.03770000"], ["1974.18000000", "0.04850000"], ["1974.16000000", "15.63540000"], ["1974.13000000", "0.00500000"], ["1974.11000000", "23.95800000"], ["1973.97000000", "0.27280000"], ["1973.96000000", "0.49150000"], ["1973.71000000", "1.56990000"], ["1973.70000000", "8.69100000"], ["1973.60000000", "6.86920000"], ["1973.54000000", "0.00000000"], ["1972.78000000", "1.05470000"], ["1972.61000000", "0.00260000"], ["1972.31000000", "0.32590000"], ["1972.00000000", "35.88160000"], ["1969.06000000", "0.00300000"], ["1968.97000000", "0.00000000"], ["1968.93000000", "0.00000000"], ["1935.17000000", "0.00460000"], ["1777.26000000", "0.07470000"]], "a": [["1974.58000000", "29.72750000"], ["1974.60000000", "0.00800000"], ["1974.61000000", "0.00000000"], ["1974.64000000", "9.04600000"], ["1974.65000000", "0.00000000"], ["1974.66000000", "0.00540000"], ["1974.67000000", "3.00540000"], ["1974.68000000", "4.98250000"], ["1974.69000000", "6.47300000"], ["1974.70000000", "0.00260000"], ["1974.71000000", "0.00000000"], ["1974.72000000", "0.01160000"], ["1974.73000000", "26.50830000"], ["1974.74000000", "1.79210000"], ["1974.75000000", "0.00000000"], ["1974.76000000", "0.01020000"], ["1974.77000000", "0.00000000"], ["1974.78000000", "2.39240000"], ["1974.79000000", "7.04070000"], ["1974.80000000", "16.48130000"], ["1974.82000000", "1.96880000"], ["1974.83000000", "0.00300000"], ["1974.86000000", "0.52840000"], ["1974.92000000", "0.00260000"], ["1974.98000000", "2.32060000"], ["1974.99000000", "7.59680000"], ["1975.00000000", "0.00830000"], ["1975.03000000", "3.32500000"], ["1975.04000000", "7.12040000"], ["1975.05000000", "0.00300000"], ["1975.12000000", "7.53470000"], ["1975.18000000", "0.56700000"], ["1975.46000000", "0.03300000"], ["1975.47000000", "0.01020000"], ["1975.60000000", "14.63780000"], ["1975.70000000", "0.00310000"], ["1976.73000000", "0.00000000"], ["1976.79000000", "0.56700000"], ["1979.67000000", "0.13380000"], ["1979.72000000", "0.00000000"], ["1979.74000000", "0.00000000"], ["1979.79000000", "0.00000000"]], "_local_ts_utc": "2026-06-01T07:48:57.413234+00:00"}
{"e": "depthUpdate", "E": 1780300138615, "s": "ETHUSDT", "U": 76583072965, "u": 76583073046, "b": [["1974.57000000", "29.26630000"], ["1974.56000000", "0.01040000"], ["1974.55000000", "0.02190000"], ["1974.48000000", "0.00800000"], ["1974.47000000", "1.02400000"], ["1974.45000000", "0.00260000"], ["1974.44000000", "0.02850000"], ["1974.38000000", "8.15080000"], ["1974.37000000", "0.00540000"], ["1974.36000000", "0.58710000"], ["1974.35000000", "0.05040000"], ["1974.28000000", "0.03290000"], ["1974.16000000", "2.12990000"], ["1974.12000000", "13.61450000"], ["1973.68000000", "25.95670000"], ["1973.28000000", "0.31330000"], ["1973.20000000", "1.48880000"], ["1972.48000000", "0.01480000"], ["1972.00000000", "35.85160000"], ["1969.04000000", "0.00260000"], ["1968.95000000", "0.00260000"], ["1953.27000000", "1.48870000"], ["1935.07000000", "0.00000000"], ["1777.12000000", "0.01240000"]], "a": [["1974.58000000", "34.46340000"], ["1974.60000000", "0.00260000"], ["1974.62000000", "0.00540000"], ["1974.63000000", "4.31740000"], ["1974.64000000", "0.00000000"], ["1974.67000000", "3.00800000"], ["1974.69000000", "6.46760000"], ["1974.72000000", "0.04430000"], ["1974.73000000", "7.73850000"], ["1974.80000000", "15.85690000"], ["1974.82000000", "0.03560000"], ["1974.87000000", "1.28470000"], ["1974.88000000", "4.29800000"], ["1975.10000000", "0.01990000"], ["1975.15000000", "26.76220000"], ["1975.85000000", "3.93600000"], ["1975.88000000", "0.22310000"], ["1976.16000000", "0.00000000"], ["1976.48000000", "0.00300000"], ["1976.78000000", "0.94760000"], ["1976.96000000", "0.00000000"], ["1977.29000000", "0.00000000"], ["1980.06000000", "0.02170000"], ["1980.15000000", "0.00000000"], ["2006.84000000", "0.02430000"], ["2024.60000000", "0.00380000"]], "_local_ts_utc": "2026-06-01T07:48:57.510792+00:00"}
{"e": "depthUpdate", "E": 1780300138715, "s": "ETHUSDT", "U": 76583073047, "u": 76583073094, "b": [["1974.57000000", "28.08130000"], ["1974.35000000", "0.04770000"], ["1974.34000000", "0.00760000"], ["1974.32000000", "0.02910000"], ["1974.30000000", "8.06740000"], ["1974.22000000", "0.62690000"], ["1974.13000000", "13.51050000"], ["1974.12000000", "0.10900000"], ["1974.05000000", "7.46700000"], ["1973.87000000", "0.27960000"], ["1973.74000000", "34.85920000"], ["1973.65000000", "4.20420000"], ["1973.22000000", "1.34000000"], ["1973.12000000", "0.03000000"], ["1973.04000000", "0.00000000"], ["1972.31000000", "0.05590000"], ["1969.66000000", "0.58070000"], ["1969.29000000", "0.00880000"], ["1777.12000000", "0.03100000"]], "a": [["1974.58000000", "47.65430000"], ["1974.68000000", "4.99410000"], ["1974.73000000", "5.45050000"], ["1974.74000000", "1.76830000"], ["1974.82000000", "0.67780000"], ["1975.10000000", "0.00830000"], ["1975.62000000", "0.17310000"], ["1975.71000000", "0.60560000"], ["1975.78000000", "0.80260000"], ["1975.93000000", "0.00300000"], ["1976.00000000", "18.97880000"], ["1976.79000000", "0.00000000"], ["1976.99000000", "0.12640000"], ["1980.00000000", "8.27750000"]], "_local_ts_utc": "2026-06-01T07:48:57.611452+00:00"}
{"e": "depthUpdate", "E": 1780300138815, "s": "ETHUSDT", "U": 76583073095, "u": 76583073128, "b": [["1974.57000000", "26.45110000"], ["1974.56000000", "0.00780000"], ["1974.48000000", "0.00260000"], ["1974.47000000", "0.00800000"], ["1974.32000000", "0.03180000"], ["1974.31000000", "22.57640000"], ["1974.27000000", "1.33610000"], ["1974.25000000", "22.68930000"], ["1974.14000000", "29.28600000"], ["1972.19000000", "54.93840000"], ["1969.08000000", "0.01030000"], ["1777.12000000", "0.04340000"], ["1777.11000000", "0.00310000"]], "a": [["1974.58000000", "53.50930000"], ["1974.66000000", "0.01700000"], ["1974.73000000", "6.75290000"], ["1974.80000000", "15.84530000"], ["1974.81000000", "2.00540000"], ["1974.82000000", "0.67780000"], ["1974.87000000", "0.00000000"], ["1990.87000000", "0.00000000"], ["1995.82000000", "0.00000000"], ["2000.77000000", "0.00000000"], ["2031.04000000", "0.00380000"]], "_local_ts_utc": "2026-06-01T07:48:57.710793+00:00"}
{"e": "depthUpdate", "E": 1780300138915, "s": "ETHUSDT", "U": 76583073129, "u": 76583073153, "b": [["1974.57000000", "26.02970000"], ["1972.69000000", "1.83410000"], ["1969.37000000", "0.15200000"], ["1969.15000000", "127.91430000"], ["1777.12000000", "0.05580000"], ["1777.11000000", "0.00000000"]], "a": [["1974.58000000", "59.98900000"], ["1974.61000000", "0.01160000"], ["1974.63000000", "2.39450000"], ["1974.68000000", "4.98870000"], ["1974.69000000", "0.00000000"], ["1974.72000000", "0.04700000"], ["1974.74000000", "1.75670000"], ["1975.31000000", "12.34780000"], ["1975.33000000", "0.00000000"], ["1976.20000000", "7.82860000"], ["1977.05000000", "6.20820000"], ["1980.08000000", "0.01030000"], ["2020.22000000", "0.01970000"]], "_local_ts_utc": "2026-06-01T07:48:57.812821+00:00"}
{"e": "depthUpdate", "E": 1780300139015, "s": "ETHUSDT", "U": 76583073154, "u": 76583073184, "b": [["1974.57000000", "20.05590000"], ["1973.90000000", "17.55470000"], ["1972.66000000", "0.54920000"], ["1969.66000000", "0.00000000"], ["1969.26000000", "0.58080000"], ["1777.12000000", "0.06820000"]], "a": [["1974.58000000", "60.21120000"], ["1974.62000000", "0.00800000"], ["1974.73000000", "6.75290000"], ["1974.82000000", "0.67520000"], ["1974.91000000", "7.00890000"], ["1974.92000000", "7.09300000"], ["1974.94000000", "8.51530000"], ["1974.98000000", "0.05050000"], ["1975.03000000", "4.27000000"], ["1975.33000000", "0.37810000"], ["1975.73000000", "0.00000000"], ["1976.20000000", "3.97870000"], ["1976.26000000", "0.00300000"], ["1976.71000000", "9.85600000"], ["1977.27000000", "0.96500000"]], "_local_ts_utc": "2026-06-01T07:48:57.911802+00:00"}
{"e": "depthUpdate", "E": 1780300139115, "s": "ETHUSDT", "U": 76583073185, "u": 76583073236, "b": [["1974.57000000", "19.87810000"], ["1974.31000000", "22.57640000"], ["1974.29000000", "0.09490000"], ["1974.27000000", "0.51320000"], ["1974.25000000", "22.69940000"], ["1974.00000000", "32.13070000"], ["1973.55000000", "0.01080000"], ["1973.41000000", "23.06200000"], ["1972.61000000", "7.09270000"], ["1972.58000000", "0.27000000"], ["1972.56000000", "0.27000000"], ["1777.12000000", "0.08060000"]], "a": [["1974.58000000", "60.22280000"], ["1974.72000000", "0.03540000"], ["1974.73000000", "10.79770000"], ["1974.79000000", "14.13080000"], ["1974.81000000", "5.41970000"], ["1974.90000000", "13.51070000"], ["1975.15000000", "27.51820000"], ["1975.17000000", "2.03980000"], ["1976.48000000", "0.00300000"], ["1976.49000000", "7.09040000"], ["1977.05000000", "2.65300000"], ["1977.09000000", "0.13130000"], ["1977.27000000", "0.02000000"], ["1977.35000000", "0.75600000"], ["1977.37000000", "32.45750000"], ["2033.70000000", "0.02470000"], ["2037.68000000", "0.01880000"]], "_local_ts_utc": "2026-06-01T07:48:58.011287+00:00"}
{"e": "depthUpdate", "E": 1780300139215, "s": "ETHUSDT", "U": 76583073237, "u": 76583073251, "b": [["1974.57000000", "19.92280000"], ["1974.27000000", "0.56320000"], ["1974.00000000", "32.08070000"], ["1777.12000000", "0.08680000"], ["1192.00000000", "0.00000000"]], "a": [["1974.73000000", "10.79770000"], ["1974.79000000", "22.63890000"], ["1974.91000000", "6.95890000"], ["1975.18000000", "0.61700000"], ["1976.03000000", "0.00260000"], ["1978.91000000", "0.00000000"]], "_local_ts_utc": "2026-06-01T07:48:58.110791+00:00"}
{"e": "depthUpdate", "E": 1780300139315, "s": "ETHUSDT", "U": 76583073252, "u": 76583073276, "b": [["1974.57000000", "20.28290000"], ["1974.50000000", "0.26030000"], ["1974.31000000", "22.57640000"], ["1972.78000000", "1.32470000"], ["1777.12000000", "0.09300000"]], "a": [["1974.73000000", "10.79770000"], ["1974.80000000", "20.38650000"], ["1975.03000000", "5.61690000"], ["1975.05000000", "1.59600000"], ["1975.11000000", "0.48600000"], ["1975.85000000", "1.28280000"], ["1977.11000000", "2.54640000"], ["1977.17000000", "0.48860000"], ["1977.37000000", "31.64750000"], ["1977.54000000", "0.79720000"], ["1979.04000000", "0.00000000"], ["2044.51000000", "0.01300000"]], "_local_ts_utc": "2026-06-01T07:48:58.210790+00:00"}
{"e": "depthUpdate", "E": 1780300139415, "s": "ETHUSDT", "U": 76583073277, "u": 76583073951, "b": [["1974.57000000", "0.00000000"], ["1974.56000000", "0.00000000"], ["1974.55000000", "0.00000000"], ["1974.52000000", "0.00000000"], ["1974.51000000", "0.00000000"], ["1974.50000000", "0.00000000"], ["1974.49000000", "0.00000000"], ["1974.48000000", "0.00000000"], ["1974.47000000", "0.00000000"], ["1974.46000000", "0.00000000"], ["1974.45000000", "0.00000000"], ["1974.44000000", "0.00000000"], ["1974.43000000", "0.00000000"], ["1974.42000000", "0.00000000"], ["1974.40000000", "0.00000000"], ["1974.39000000", "0.00000000"], ["1974.38000000", "6.51430000"], ["1974.37000000", "0.00780000"], ["1974.36000000", "0.08320000"], ["1974.35000000", "0.04770000"], ["1974.34000000", "0.00260000"], ["1974.32000000", "0.02900000"], ["1974.31000000", "0.00260000"], ["1974.30000000", "0.00520000"], ["1974.29000000", "0.00640000"], ["1974.28000000", "0.03550000"], ["1974.27000000", "0.05620000"], ["1974.26000000", "0.03260000"], ["1974.25000000", "0.00000000"], ["1974.24000000", "0.00770000"], ["1974.22000000", "0.00740000"], ["1974.21000000", "0.10840000"], ["1974.20000000", "1.26400000"], ["1974.18000000", "0.05390000"], ["1974.17000000", "0.10970000"], ["1974.16000000", "2.12990000"], ["1974.15000000", "0.00260000"], ["1974.14000000", "0.12910000"], ["1974.13000000", "0.00500000"], ["1974.12000000", "0.01310000"], ["1974.11000000", "0.11030000"], ["1974.10000000", "6.17220000"], ["1974.09000000", "0.00260000"], ["1974.08000000", "0.03000000"], ["1974.04000000", "0.00000000"], ["1974.03000000", "0.10130000"], ["1974.02000000", "0.32670000"], ["1974.00000000", "31.04790000"], ["1973.98000000", "0.03230000"], ["1973.97000000", "0.00280000"], ["1973.95000000", "0.09110000"], ["1973.94000000", "0.47720000"], ["1973.92000000", "0.03000000"], ["1973.90000000", "17.55470000"], ["1973.86000000", "0.60140000"], ["1973.84000000", "0.06130000"], ["1973.80000000", "8.51780000"], ["1973.76000000", "27.06410000"], ["1973.75000000", "20.73810000"], ["1973.71000000", "8.10830000"], ["1973.70000000", "8.58100000"], ["1973.69000000", "11.85140000"], ["1973.68000000", "22.61310000"], ["1973.65000000", "3.60420000"], ["1973.63000000", "0.63090000"], ["1973.61000000", "7.09800000"], ["1973.58000000", "0.20000000"], ["1973.56000000", "0.44860000"], ["1973.55000000", "0.01080000"], ["1973.54000000", "0.00000000"], ["1973.51000000", "7.10460000"], ["1973.50000000", "1.07440000"], ["1973.49000000", "0.05060000"], ["1973.48000000", "0.00740000"], ["1973.47000000", "15.02170000"], ["1973.45000000", "3.82220000"], ["1973.44000000", "0.65060000"], ["1973.40000000", "1.30870000"], ["1973.38000000", "1.31810000"], ["1973.32000000", "7.18920000"], ["1973.22000000", "0.94000000"], ["1973.16000000", "22.96770000"], ["1973.14000000", "20.77730000"], ["1973.13000000", "0.17750000"], ["1973.08000000", "0.15290000"], ["1973.07000000", "1.09560000"], ["1973.02000000", "4.59190000"], ["1973.00000000", "8.47440000"], ["1972.88000000", "0.08250000"], ["1972.86000000", "3.37130000"], ["1972.84000000", "0.54000000"], ["1972.79000000", "18.82150000"], ["1972.78000000", "9.83280000"], ["1972.75000000", "0.53350000"], ["1972.69000000", "5.94760000"], ["1972.62000000", "7.10650000"], ["1972.58000000", "8.77810000"], ["1972.49000000", "0.25870000"], ["1972.45000000", "12.04390000"], ["1972.44000000", "7.20870000"], ["1972.43000000", "13.54710000"], ["1972.41000000", "15.85330000"], ["1972.40000000", "14.09560000"], ["1972.24000000", "7.84910000"], ["1972.22000000", "15.64900000"], ["1972.19000000", "0.00300000"], ["1972.04000000", "7.09010000"], ["1972.02000000", "7.09280000"], ["1972.00000000", "30.85160000"], ["1971.64000000", "0.01270000"], ["1971.63000000", "1.02660000"], ["1970.98000000", "6.26890000"], ["1970.97000000", "13.54380000"], ["1970.95000000", "0.00000000"], ["1970.69000000", "14.72500000"], ["1968.85000000", "3.68560000"], ["1968.76000000", "0.04920000"], ["1968.60000000", "0.01390000"], ["1967.09000000", "0.06070000"], ["1966.65000000", "3.60000000"], ["1965.86000000", "0.01970000"], ["1964.52000000", "0.20270000"], ["1960.64000000", "0.02190000"], ["1957.15000000", "15.95930000"], ["1953.27000000", "0.00610000"], ["1934.89000000", "0.00000000"], ["1777.12000000", "0.00000000"], ["1776.95000000", "0.11860000"], ["1579.86000000", "0.23800000"], ["1579.60000000", "1.82870000"]], "a": [["1974.39000000", "111.54120000"], ["1974.40000000", "6.47840000"], ["1974.41000000", "0.01530000"], ["1974.43000000", "0.01160000"], ["1974.44000000", "0.00000000"], ["1974.45000000", "4.69260000"], ["1974.46000000", "0.00000000"], ["1974.47000000", "0.00000000"], ["1974.48000000", "0.03000000"], ["1974.49000000", "3.00000000"], ["1974.50000000", "3.05940000"], ["1974.51000000", "0.14440000"], ["1974.52000000", "1.33790000"], ["1974.53000000", "0.00000000"], ["1974.56000000", "0.03000000"], ["1974.57000000", "23.22030000"], ["1974.58000000", "11.25310000"], ["1974.60000000", "0.03870000"], ["1974.61000000", "0.01460000"], ["1974.62000000", "0.00260000"], ["1974.63000000", "0.00000000"], ["1974.64000000", "0.03000000"], ["1974.66000000", "0.00000000"], ["1974.67000000", "0.00260000"], ["1974.68000000", "0.00000000"], ["1974.70000000", "0.00570000"], ["1974.72000000", "13.53500000"], ["1974.73000000", "13.50180000"], ["1974.74000000", "1.76310000"], ["1974.77000000", "7.09010000"], ["1974.78000000", "1.11180000"], ["1974.79000000", "17.66180000"], ["1974.81000000", "3.50540000"], ["1974.82000000", "0.03300000"], ["1974.84000000", "0.64640000"], ["1974.86000000", "1.73390000"], ["1974.89000000", "0.00260000"], ["1974.90000000", "0.00570000"], ["1974.91000000", "10.10080000"], ["1974.93000000", "13.50500000"], ["1974.99000000", "7.09040000"], ["1975.02000000", "0.00000000"], ["1975.05000000", "2.02800000"], ["1975.10000000", "0.00570000"], ["1975.12000000", "17.43100000"], ["1975.13000000", "13.50810000"], ["1975.14000000", "0.02310000"], ["1975.18000000", "4.21700000"], ["1975.23000000", "0.00260000"], ["1975.32000000", "13.60550000"], ["1975.40000000", "10.76030000"], ["1975.41000000", "0.17050000"], ["1975.50000000", "8.56040000"], ["1975.56000000", "14.98060000"], ["1975.68000000", "0.04310000"], ["1975.76000000", "0.59400000"], ["1975.78000000", "0.00260000"], ["1975.84000000", "0.00260000"], ["1975.88000000", "0.22310000"], ["1975.89000000", "0.03300000"], ["1975.98000000", "9.85920000"], ["1976.26000000", "0.00300000"], ["1976.27000000", "0.00000000"], ["1976.29000000", "0.56700000"], ["1976.49000000", "0.00000000"], ["1976.71000000", "0.00000000"], ["1976.76000000", "0.03290000"], ["1976.78000000", "0.94500000"], ["1976.83000000", "1.28680000"], ["1976.85000000", "12.09230000"], ["1976.86000000", "32.41680000"], ["1977.09000000", "0.13130000"], ["1978.10000000", "4.20400000"], ["1979.56000000", "0.00000000"], ["1979.61000000", "0.00000000"], ["1979.68000000", "0.00000000"], ["1979.79000000", "0.00000000"], ["1979.81000000", "3.60000000"], ["1979.84000000", "0.00430000"], ["1979.90000000", "1.20550000"], ["1979.94000000", "0.00000000"], ["1980.42000000", "0.00490000"], ["1981.25000000", "0.20650000"], ["1982.58000000", "3.60000000"], ["1982.98000000", "0.00780000"], ["1983.95000000", "0.00400000"], ["1986.63000000", "0.00280000"], ["1987.07000000", "0.02000000"], ["1990.14000000", "0.02390000"], ["1993.64000000", "0.00400000"], ["2005.09000000", "0.04900000"], ["2017.67000000", "0.01760000"], ["2020.15000000", "0.03160000"], ["2474.58000000", "0.02060000"]], "_local_ts_utc": "2026-06-01T07:48:58.311700+00:00"}
{"e": "depthUpdate", "E": 1780300139515, "s": "ETHUSDT", "U": 76583073952, "u": 76583074070, "b": [["1974.38000000", "20.80860000"], ["1974.24000000", "0.00510000"], ["1974.18000000", "0.05390000"], ["1974.17000000", "0.64000000"], ["1974.16000000", "1.51920000"], ["1974.12000000", "0.00770000"], ["1974.11000000", "0.11300000"], ["1974.07000000", "0.51680000"], ["1974.06000000", "0.07050000"], ["1974.05000000", "8.77950000"], ["1974.03000000", "0.01020000"], ["1973.98000000", "0.02220000"], ["1973.91000000", "36.25580000"], ["1973.90000000", "17.55470000"], ["1973.87000000", "0.89030000"], ["1973.79000000", "6.46760000"], ["1973.74000000", "34.95030000"], ["1973.70000000", "8.59110000"], ["1973.67000000", "0.00000000"], ["1973.63000000", "0.88180000"], ["1973.58000000", "0.60000000"], ["1973.41000000", "22.81110000"], ["1973.22000000", "0.54000000"], ["1972.93000000", "22.57370000"], ["1972.51000000", "1.09900000"], ["1972.47000000", "0.26110000"], ["1972.30000000", "17.57160000"], ["1972.03000000", "0.00000000"], ["1971.56000000", "0.00410000"], ["1970.70000000", "5.25180000"], ["1970.69000000", "13.50810000"], ["1968.67000000", "0.00260000"], ["1968.58000000", "0.00260000"], ["1966.85000000", "3.63120000"], ["1955.24000000", "0.13180000"], ["1776.95000000", "0.13100000"]], "a": [["1974.39000000", "113.81560000"], ["1974.40000000", "6.50840000"], ["1974.42000000", "0.00260000"], ["1974.44000000", "0.00540000"], ["1974.45000000", "1.81770000"], ["1974.48000000", "0.03540000"], ["1974.49000000", "3.00540000"], ["1974.50000000", "7.62680000"], ["1974.51000000", "0.14710000"], ["1974.58000000", "4.03650000"], ["1974.62000000", "0.00000000"], ["1974.70000000", "0.51220000"], ["1974.71000000", "0.40000000"], ["1974.74000000", "1.10820000"], ["1975.34000000", "0.37340000"], ["1975.60000000", "14.60780000"], ["1975.62000000", "0.00260000"], ["1976.20000000", "1.56450000"], ["1976.70000000", "3.22170000"], ["1977.35000000", "0.00000000"], ["1979.83000000", "0.00260000"], ["1979.92000000", "0.15110000"], ["1981.74000000", "2.31700000"], ["1983.35000000", "0.00000000"], ["1989.85000000", "4.17050000"], ["1993.10000000", "0.00000000"]], "_local_ts_utc": "2026-06-01T07:48:58.412806+00:00"}
{"e": "depthUpdate", "E": 1780300139615, "s": "ETHUSDT", "U": 76583074071, "u": 76583074094, "b": [["1974.38000000", "9.62650000"], ["1974.17000000", "7.31050000"], ["1974.12000000", "0.01040000"], ["1974.11000000", "22.68670000"], ["1974.08000000", "0.03000000"], ["1974.05000000", "7.46700000"], ["1973.87000000", "2.16700000"], ["1973.39000000", "2.86480000"], ["1970.88000000", "0.69230000"], ["1776.95000000", "0.14340000"]], "a": [["1974.39000000", "105.67780000"], ["1974.97000000", "0.51300000"], ["1974.99000000", "7.54940000"], ["1975.20000000", "2.69050000"], ["1977.04000000", "0.51560000"], ["1977.07000000", "1.67470000"], ["1977.11000000", "1.52040000"], ["1977.17000000", "0.00260000"], ["2051.55000000", "0.00380000"]], "_local_ts_utc": "2026-06-01T07:48:58.511512+00:00"}
{"e": "depthUpdate", "E": 1780300139715, "s": "ETHUSDT", "U": 76583074095, "u": 76583074117, "b": [["1974.38000000", "7.78510000"], ["1974.37000000", "0.01040000"], ["1974.36000000", "0.08860000"], ["1974.35000000", "0.52310000"], ["1974.18000000", "0.76690000"], ["1974.11000000", "22.68400000"], ["1973.92000000", "6.49760000"], ["1973.79000000", "0.00000000"], ["1956.82000000", "0.00930000"], ["1776.95000000", "0.14960000"]], "a": [["1974.39000000", "106.35600000"], ["1974.42000000", "0.77970000"], ["1974.45000000", "0.91020000"], ["1974.48000000", "0.03800000"], ["1974.51000000", "0.14440000"], ["1974.67000000", "0.00000000"], ["1974.72000000", "13.53800000"], ["1977.91000000", "0.00000000"]], "_local_ts_utc": "2026-06-01T07:48:58.611163+00:00"}
{"e": "depthUpdate", "E": 1780300139815, "s": "ETHUSDT", "U": 76583074118, "u": 76583074130, "b": [["1974.19000000", "0.01060000"], ["1974.12000000", "0.00770000"], ["1974.11000000", "22.68130000"], ["1973.99000000", "0.66560000"], ["1950.00000000", "1720.11490000"], ["1776.95000000", "0.16200000"]], "a": [["1974.51000000", "0.77040000"], ["1974.58000000", "3.93650000"], ["1974.59000000", "1.16550000"], ["1977.04000000", "0.00260000"], ["2058.80000000", "0.00380000"]], "_local_ts_utc": "2026-06-01T07:48:58.710781+00:00"}
{"e": "depthUpdate", "E": 1780300139915, "s": "ETHUSDT", "U": 76583074131, "u": 76583074247, "b": [["1974.38000000", "42.45720000"], ["1973.71000000", "8.00700000"], ["1970.58000000", "30.34000000"], ["1965.66000000", "0.54220000"], ["1945.12000000", "0.01540000"], ["1776.95000000", "0.17440000"]], "a": [["1974.39000000", "93.45820000"], ["1974.73000000", "13.50440000"], ["1974.82000000", "0.03560000"], ["1975.07000000", "8.65980000"], ["1975.96000000", "9.30340000"], ["1976.00000000", "23.97880000"], ["1982.80000000", "0.00310000"], ["3449.67000000", "0.00540000"], ["3479.48000000", "0.00540000"], ["3489.42000000", "0.00540000"], ["3509.29000000", "0.03500000"], ["3539.10000000", "0.80330000"], ["3549.03000000", "0.00540000"], ["3558.97000000", "0.00540000"], ["3568.91000000", "0.00540000"], ["3578.84000000", "0.00540000"], ["3598.71000000", "0.00540000"], ["3618.58000000", "0.00940000"], ["3638.46000000", "0.01190000"], ["3648.39000000", "0.00540000"], ["3658.33000000", "0.23380000"], ["3678.20000000", "0.01480000"], ["3708.01000000", "0.00540000"], ["3717.94000000", "0.00540000"], ["3727.88000000", "0.00540000"], ["3737.82000000", "0.00710000"], ["3797.43000000", "0.00540000"], ["3827.24000000", "0.00540000"], ["3837.17000000", "0.00540000"], ["3847.11000000", "0.00850000"], ["3866.98000000", "0.00540000"], ["3886.85000000", "0.00540000"], ["3896.79000000", "0.00540000"], ["3906.73000000", "0.49400000"], ["3926.60000000", "0.00540000"], ["3936.53000000", "0.01950000"], ["3976.28000000", "0.00540000"], ["4016.02000000", "0.00540000"], ["4025.96000000", "0.00540000"], ["4035.89000000", "0.00540000"], ["4045.83000000", "0.01240000"], ["4055.76000000", "0.00540000"], ["4065.70000000", "0.00540000"], ["4085.57000000", "0.00540000"], ["4095.51000000", "0.00540000"], ["4115.38000000", "0.02690000"], ["4135.25000000", "0.00540000"], ["4155.12000000", "0.26000000"], ["4165.06000000", "0.00540000"], ["4175.00000000", "7.76390000"], ["4184.93000000", "0.00540000"], ["4214.74000000", "0.00540000"], ["4224.67000000", "0.00990000"], ["4234.61000000", "0.00540000"], ["4244.55000000", "0.00540000"], ["4254.48000000", "0.00540000"], ["4274.35000000", "0.03260000"], ["4324.03000000", "0.05700000"], ["4333.97000000", "0.00540000"], ["4363.78000000", "0.00540000"], ["4373.71000000", "0.06440000"], ["4393.58000000", "0.00540000"], ["4403.52000000", "0.00540000"], ["4413.46000000", "0.00840000"], ["4423.39000000", "0.00720000"], ["4443.26000000", "0.00540000"], ["4473.07000000", "0.01780000"], ["4512.82000000", "0.00540000"], ["4542.62000000", "0.00540000"], ["4572.43000000", "0.00540000"], ["4641.98000000", "0.02060000"], ["4651.92000000", "0.00540000"], ["4671.79000000", "0.00540000"], ["4701.60000000", "0.20650000"], ["4741.34000000", "0.00540000"], ["4791.02000000", "0.00540000"], ["4830.76000000", "0.08500000"], ["4840.70000000", "0.00540000"], ["4890.38000000", "0.00540000"], ["4900.32000000", "0.14440000"], ["4910.25000000", "0.00540000"], ["4940.06000000", "0.08540000"], ["4950.00000000", "1475.57290000"]], "_local_ts_utc": "2026-06-01T07:48:58.811456+00:00"}
{"e": "depthUpdate", "E": 1780300140015, "s": "ETHUSDT", "U": 76583074248, "u": 76583074406, "b": [["1974.38000000", "42.46000000"], ["1974.36000000", "0.08320000"], ["1974.35000000", "0.04770000"], ["1974.01000000", "8.71990000"], ["1973.81000000", "2.67710000"], ["1973.69000000", "11.84880000"], ["1973.58000000", "3.64370000"], ["1973.54000000", "7.09080000"], ["1973.29000000", "0.81100000"], ["1973.07000000", "0.29560000"], ["1972.63000000", "7.12470000"], ["1972.34000000", "7.09080000"], ["1972.13000000", "7.13430000"], ["1972.04000000", "0.00000000"], ["1972.03000000", "7.09080000"], ["1970.94000000", "0.00280000"], ["1970.74000000", "0.00000000"], ["1970.57000000", "22.57790000"], ["1970.37000000", "0.01350000"], ["1970.17000000", "0.00260000"], ["1953.06000000", "1.64030000"], ["1779.73000000", "0.00000000"], ["1776.95000000", "0.18680000"]], "a": [["1974.39000000", "79.48670000"], ["1974.41000000", "0.02070000"], ["1974.42000000", "0.00260000"], ["1974.64000000", "0.03260000"], ["1974.65000000", "7.09080000"], ["1974.66000000", "22.57370000"], ["1974.75000000", "0.10140000"], ["1974.78000000", "8.20260000"], ["1974.89000000", "0.00000000"], ["1974.90000000", "29.67020000"], ["1974.92000000", "10.11410000"], ["1975.11000000", "30.15050000"], ["1975.30000000", "7.10410000"], ["1975.47000000", "22.58390000"], ["1975.49000000", "7.09380000"], ["1975.66000000", "7.24190000"], ["1975.78000000", "22.57630000"], ["1975.88000000", "7.31390000"], ["1975.90000000", "14.17380000"], ["1975.98000000", "32.43290000"], ["1976.27000000", "7.09080000"], ["1976.29000000", "23.14070000"], ["1976.54000000", "0.03670000"], ["1976.65000000", "26.17630000"], ["1976.73000000", "0.48600000"], ["1976.77000000", "1.64400000"], ["1976.89000000", "0.00000000"], ["1977.01000000", "22.57370000"], ["1977.06000000", "0.00000000"], ["1977.18000000", "0.00000000"], ["1977.30000000", "22.57370000"], ["1977.40000000", "0.00570000"], ["1977.61000000", "9.37810000"], ["1977.62000000", "0.96550000"], ["1977.84000000", "0.03290000"], ["1978.01000000", "0.01010000"], ["1978.39000000", "0.00000000"], ["1978.99000000", "0.00000000"], ["1979.19000000", "0.00000000"], ["1979.55000000", "0.00000000"], ["1979.91000000", "0.00000000"], ["1980.27000000", "0.26110000"], ["1980.63000000", "0.00000000"], ["1980.94000000", "126.36450000"], ["1981.22000000", "0.00000000"], ["1981.58000000", "0.00000000"], ["1981.93000000", "0.02000000"], ["2474.58000000", "0.00860000"], ["3409.93000000", "0.00540000"], ["3419.87000000", "0.00540000"], ["3429.80000000", "0.00540000"], ["3439.74000000", "0.00780000"], ["3459.61000000", "0.00540000"], ["3469.55000000", "0.00540000"], ["3499.35000000", "0.02090000"], ["3519.23000000", "0.01110000"], ["3529.16000000", "0.00850000"], ["3588.78000000", "0.01000000"], ["3608.65000000", "0.00540000"], ["3628.52000000", "0.00540000"], ["3668.26000000", "0.00540000"], ["3688.14000000", "0.00540000"], ["3698.07000000", "0.00540000"], ["3747.75000000", "0.00540000"], ["3757.69000000", "0.03220000"], ["3767.62000000", "0.00540000"], ["3777.56000000", "0.00540000"], ["3787.50000000", "0.05040000"], ["3807.37000000", "0.14820000"], ["3817.30000000", "0.01040000"], ["3857.05000000", "0.00540000"], ["3876.92000000", "0.02430000"], ["3916.66000000", "0.61480000"], ["3946.47000000", "0.29910000"], ["3956.41000000", "0.00540000"], ["3966.34000000", "0.00540000"], ["3986.21000000", "0.00540000"], ["3996.15000000", "0.00720000"], ["4006.08000000", "0.00540000"], ["4075.64000000", "0.00540000"], ["4105.44000000", "0.00540000"], ["4125.32000000", "0.00540000"], ["4145.19000000", "0.00540000"], ["4194.87000000", "0.00540000"], ["4204.80000000", "0.00540000"], ["4264.42000000", "0.02850000"], ["4284.29000000", "0.15800000"], ["4294.23000000", "0.00540000"], ["4304.16000000", "0.00770000"], ["4314.10000000", "0.21760000"], ["4343.91000000", "0.00540000"], ["4353.84000000", "0.07440000"], ["4383.65000000", "0.00540000"], ["4433.33000000", "0.43200000"], ["4453.20000000", "0.01780000"], ["4463.14000000", "0.00540000"], ["4483.01000000", "0.01240000"], ["4492.94000000", "0.00540000"], ["4502.88000000", "0.00540000"], ["4522.75000000", "0.00540000"], ["4532.69000000", "0.00540000"], ["4552.56000000", "0.00540000"], ["4562.50000000", "1.05270000"], ["4582.37000000", "0.00540000"], ["4592.30000000", "0.01020000"], ["4602.24000000", "0.00540000"], ["4612.17000000", "0.00540000"], ["4622.11000000", "0.00540000"], ["4632.05000000", "0.00540000"], ["4661.85000000", "0.00680000"], ["4681.73000000", "0.00540000"], ["4691.66000000", "0.00660000"], ["4711.53000000", "0.07040000"], ["4721.47000000", "0.00540000"], ["4731.41000000", "0.00540000"], ["4751.28000000", "0.00540000"], ["4761.21000000", "0.10140000"], ["4771.15000000", "0.00540000"], ["4781.08000000", "0.00540000"], ["4800.96000000", "0.00540000"], ["4810.89000000", "0.00540000"], ["4820.83000000", "0.01120000"], ["4850.64000000", "0.00540000"], ["4860.57000000", "0.00540000"], ["4870.51000000", "0.00540000"], ["4880.44000000", "0.00540000"], ["4920.19000000", "0.00540000"], ["4930.12000000", "0.00540000"]], "_local_ts_utc": "2026-06-01T07:48:58.911798+00:00"}
{"e": "depthUpdate", "E": 1780300140115, "s": "ETHUSDT", "U": 76583074407, "u": 76583074477, "b": [["1974.38000000", "41.89310000"], ["1974.37000000", "0.00780000"], ["1974.28000000", "0.03820000"], ["1974.27000000", "0.51830000"], ["1974.12000000", "0.00770000"], ["1974.10000000", "6.67930000"], ["1974.01000000", "8.46640000"], ["1974.00000000", "31.30140000"], ["1973.92000000", "20.00390000"], ["1973.91000000", "22.75080000"], ["1973.89000000", "2.80570000"], ["1973.60000000", "9.51560000"], ["1972.14000000", "2.14900000"], ["1971.70000000", "0.55800000"], ["1970.98000000", "4.15290000"], ["1970.80000000", "0.69770000"], ["1970.75000000", "0.55720000"], ["1969.26000000", "0.00000000"], ["1969.03000000", "0.58790000"], ["1776.95000000", "0.19920000"]], "a": [["1974.39000000", "79.45640000"], ["1974.41000000", "0.01530000"], ["1974.44000000", "0.00800000"], ["1974.50000000", "7.62950000"], ["1974.64000000", "9.04030000"], ["1974.69000000", "0.00260000"], ["1974.71000000", "20.72830000"], ["1974.73000000", "0.00260000"], ["1974.81000000", "12.10520000"], ["1974.97000000", "1.08000000"], ["1975.10000000", "28.17320000"], ["1975.11000000", "30.40050000"], ["1975.12000000", "0.03000000"], ["1975.21000000", "4.51610000"], ["1975.46000000", "9.25260000"], ["1975.77000000", "11.16930000"], ["1975.79000000", "0.01020000"], ["1975.96000000", "15.60970000"], ["1976.20000000", "10.21970000"], ["1976.51000000", "1.20810000"], ["1976.54000000", "2.12810000"], ["1976.61000000", "8.43020000"], ["1976.70000000", "0.00300000"], ["1976.73000000", "0.00000000"], ["1976.78000000", "1.51200000"], ["1977.00000000", "4.62870000"], ["1977.05000000", "0.00000000"], ["1977.07000000", "1.21570000"], ["1977.10000000", "0.00000000"], ["1977.31000000", "0.07500000"], ["1977.60000000", "0.00310000"], ["1977.64000000", "0.59800000"], ["1977.83000000", "0.00000000"], ["1978.00000000", "0.00580000"], ["1978.10000000", "0.00000000"], ["2066.26000000", "0.00900000"]], "_local_ts_utc": "2026-06-01T07:48:59.011609+00:00"}
{"e": "depthUpdate", "E": 1780300140215, "s": "ETHUSDT", "U": 76583074478, "u": 76583074687, "b": [["1974.38000000", "56.77340000"], ["1974.37000000", "0.01040000"], ["1974.29000000", "0.00640000"], ["1974.28000000", "0.61790000"], ["1974.21000000", "0.10840000"], ["1974.19000000", "0.00520000"], ["1974.18000000", "0.76150000"], ["1974.17000000", "2.95210000"], ["1974.12000000", "29.67220000"], ["1974.11000000", "0.10760000"], ["1974.10000000", "15.35160000"], ["1974.06000000", "22.76100000"], ["1974.04000000", "1.28780000"], ["1974.00000000", "31.30140000"], ["1973.94000000", "13.98350000"], ["1973.92000000", "0.03000000"], ["1973.66000000", "0.95430000"], ["1973.61000000", "7.09800000"], ["1973.58000000", "3.64370000"], ["1973.47000000", "15.12170000"], ["1973.39000000", "0.29350000"], ["1973.38000000", "1.21810000"], ["1973.29000000", "0.01100000"], ["1973.04000000", "0.03000000"], ["1972.96000000", "15.61160000"], ["1972.88000000", "0.05250000"], ["1972.24000000", "0.75900000"], ["1972.22000000", "7.14090000"], ["1972.02000000", "0.00270000"], ["1971.70000000", "0.00000000"], ["1971.20000000", "1.25790000"], ["1971.19000000", "0.01280000"], ["1969.65000000", "92.21660000"], ["1967.09000000", "60.91710000"], ["1964.52000000", "76.27320000"], ["1953.06000000", "0.18000000"], ["1776.95000000", "0.21160000"], ["1579.86000000", "0.22400000"], ["1579.51000000", "0.01400000"]], "a": [["1974.39000000", "10.56940000"], ["1974.40000000", "0.01080000"], ["1974.43000000", "0.00000000"], ["1974.44000000", "0.00260000"], ["1974.45000000", "0.00000000"], ["1974.46000000", "0.00540000"], ["1974.47000000", "0.00000000"], ["1974.49000000", "3.00000000"], ["1974.50000000", "0.01110000"], ["1974.51000000", "0.00800000"], ["1974.52000000", "0.00000000"], ["1974.56000000", "0.03270000"], ["1974.57000000", "0.53200000"], ["1974.58000000", "3.92490000"], ["1974.61000000", "0.00300000"], ["1974.65000000", "0.00000000"], ["1974.66000000", "0.00000000"], ["1974.69000000", "0.05260000"], ["1974.70000000", "23.08590000"], ["1974.71000000", "11.84050000"], ["1974.72000000", "0.03300000"], ["1974.74000000", "0.10800000"], ["1974.75000000", "0.00000000"], ["1974.77000000", "0.01160000"], ["1974.78000000", "22.38420000"], ["1974.79000000", "2.06360000"], ["1974.80000000", "27.89520000"], ["1974.81000000", "10.60520000"], ["1974.86000000", "0.52840000"], ["1974.88000000", "4.59800000"], ["1974.89000000", "1.20000000"], ["1974.91000000", "8.39250000"], ["1974.92000000", "7.57900000"], ["1974.93000000", "0.00000000"], ["1975.06000000", "13.50630000"], ["1975.07000000", "8.60980000"], ["1975.13000000", "0.00260000"], ["1975.20000000", "0.03570000"], ["1975.32000000", "0.10000000"], ["1975.37000000", "13.50630000"], ["1975.56000000", "14.18060000"], ["1975.60000000", "1.14470000"], ["1975.70000000", "0.00310000"], ["1975.84000000", "0.03260000"], ["1975.85000000", "2.08280000"], ["1975.87000000", "8.32820000"], ["1975.90000000", "22.68270000"], ["1976.00000000", "18.97880000"], ["1976.13000000", "0.00000000"], ["1976.27000000", "14.18160000"], ["1976.28000000", "7.09080000"], ["1976.49000000", "7.09080000"], ["1976.51000000", "5.42700000"], ["1976.52000000", "0.00000000"], ["1976.54000000", "0.03670000"], ["1976.78000000", "0.94500000"], ["1976.83000000", "14.79310000"], ["1977.16000000", "13.50630000"], ["1977.36000000", "9.27520000"], ["1977.49000000", "13.50630000"], ["1977.61000000", "0.00000000"], ["1977.64000000", "0.00260000"], ["1977.66000000", "22.57630000"], ["1977.82000000", "0.00000000"], ["1977.85000000", "9.37810000"], ["1978.72000000", "65.92770000"], ["1978.78000000", "0.00260000"], ["1981.29000000", "64.67880000"], ["1982.45000000", "0.49020000"], ["1983.86000000", "76.07050000"]], "_local_ts_utc": "2026-06-01T07:48:59.131619+00:00"}
{"e": "depthUpdate", "E": 1780300140315, "s": "ETHUSDT", "U": 76583074688, "u": 76583074842, "b": [["1974.38000000", "56.76560000"], ["1974.37000000", "0.00260000"], ["1974.29000000", "0.01180000"], ["1974.28000000", "0.04090000"], ["1974.24000000", "0.03510000"], ["1974.20000000", "1.26400000"], ["1974.19000000", "0.00520000"], ["1974.18000000", "36.24970000"], ["1974.17000000", "7.19510000"], ["1974.16000000", "2.12990000"], ["1974.13000000", "14.78540000"], ["1974.10000000", "15.34850000"], ["1974.08000000", "0.03000000"], ["1974.04000000", "1.90680000"], ["1973.87000000", "0.27960000"], ["1973.66000000", "0.15430000"], ["1973.58000000", "4.44370000"], ["1973.04000000", "0.00000000"], ["1972.41000000", "7.34520000"], ["1972.34000000", "0.00000000"], ["1972.30000000", "12.21240000"], ["1972.22000000", "0.05080000"], ["1971.39000000", "1.80890000"], ["1970.70000000", "1.22060000"], ["1970.69000000", "0.00310000"], ["1776.95000000", "0.22400000"]], "a": [["1974.39000000", "7.23040000"], ["1974.41000000", "0.00510000"], ["1974.46000000", "0.00000000"], ["1974.47000000", "0.00540000"], ["1974.48000000", "0.90350000"], ["1974.50000000", "0.00570000"], ["1974.51000000", "0.00260000"], ["1974.55000000", "0.00540000"], ["1974.56000000", "2.37430000"], ["1974.57000000", "0.53740000"], ["1974.58000000", "3.92490000"], ["1974.59000000", "1.16550000"], ["1974.60000000", "1.33670000"], ["1974.63000000", "0.01160000"], ["1974.67000000", "6.46760000"], ["1974.70000000", "23.08590000"], ["1974.71000000", "6.63690000"], ["1974.77000000", "7.10240000"], ["1974.78000000", "1.11180000"], ["1974.79000000", "9.17860000"], ["1974.80000000", "34.98600000"], ["1974.87000000", "0.00000000"], ["1974.89000000", "1.20000000"], ["1975.03000000", "9.92610000"], ["1975.04000000", "9.65530000"], ["1975.11000000", "30.15050000"], ["1975.30000000", "9.63370000"], ["1975.68000000", "0.07310000"], ["1976.10000000", "18.25470000"], ["1976.13000000", "0.00000000"], ["1976.40000000", "8.80320000"], ["1976.48000000", "0.00300000"], ["1976.51000000", "3.31040000"], ["1976.70000000", "2.90890000"], ["1976.71000000", "0.00000000"], ["1976.76000000", "0.03290000"], ["1977.00000000", "5.79340000"], ["1977.29000000", "4.64670000"], ["1977.32000000", "5.12900000"], ["1977.35000000", "13.50630000"], ["1977.49000000", "0.00000000"], ["2073.95000000", "0.02210000"]], "_local_ts_utc": "2026-06-01T07:48:59.211687+00:00"}
{"e": "depthUpdate", "E": 1780300140415, "s": "ETHUSDT", "U": 76583074843, "u": 76583074972, "b": [["1974.38000000", "47.77080000"], ["1974.37000000", "0.00780000"], ["1974.29000000", "0.01180000"], ["1974.28000000", "0.04090000"], ["1974.20000000", "1.26940000"], ["1974.19000000", "23.72670000"], ["1974.18000000", "0.76150000"], ["1974.17000000", "0.10430000"], ["1974.15000000", "0.00260000"], ["1974.13000000", "22.69550000"], ["1974.12000000", "0.00770000"], ["1974.10000000", "15.34850000"], ["1974.07000000", "7.60760000"], ["1974.06000000", "0.07050000"], ["1974.03000000", "22.70070000"], ["1974.01000000", "1.37560000"], ["1974.00000000", "31.29830000"], ["1973.99000000", "0.03150000"], ["1973.98000000", "1.29890000"], ["1973.95000000", "7.18190000"], ["1973.94000000", "13.98350000"], ["1973.90000000", "17.55160000"], ["1973.88000000", "1.30520000"], ["1973.59000000", "0.29280000"], ["1973.58000000", "3.64370000"], ["1973.38000000", "0.01260000"], ["1973.23000000", "10.15340000"], ["1973.22000000", "1.34000000"], ["1972.46000000", "0.01120000"], ["1972.35000000", "0.22640000"], ["1972.24000000", "0.75900000"], ["1972.22000000", "0.05080000"], ["1969.03000000", "0.00700000"], ["1968.01000000", "0.58120000"], ["1963.33000000", "0.07830000"], ["1776.95000000", "0.23640000"]], "a": [["1974.39000000", "28.58010000"], ["1974.53000000", "0.01160000"], ["1974.55000000", "6.48460000"], ["1974.56000000", "2.36890000"], ["1974.57000000", "0.53200000"], ["1974.58000000", "3.93650000"], ["1974.60000000", "1.33670000"], ["1974.66000000", "0.62250000"], ["1974.67000000", "0.00000000"], ["1974.71000000", "14.83250000"], ["1974.77000000", "7.09080000"], ["1974.81000000", "11.81070000"], ["1974.83000000", "0.00300000"], ["1974.86000000", "0.00000000"], ["1974.87000000", "13.50630000"], ["1974.96000000", "0.63440000"], ["1975.22000000", "8.50690000"], ["1975.56000000", "15.68530000"], ["1975.76000000", "0.62400000"], ["1975.84000000", "0.00260000"], ["1976.10000000", "15.80130000"], ["1976.70000000", "0.00300000"], ["1976.76000000", "0.80660000"], ["1976.83000000", "14.19910000"], ["1977.35000000", "0.00000000"]], "_local_ts_utc": "2026-06-01T07:48:59.311502+00:00"}
{"e": "depthUpdate", "E": 1780300140515, "s": "ETHUSDT", "U": 76583074973, "u": 76583075734, "b": [["1974.38000000", "0.00000000"], ["1974.37000000", "0.00000000"], ["1974.36000000", "0.00000000"], ["1974.35000000", "0.00000000"], ["1974.34000000", "0.00000000"], ["1974.32000000", "0.00000000"], ["1974.31000000", "0.00000000"], ["1974.30000000", "0.00000000"], ["1974.29000000", "0.00000000"], ["1974.28000000", "0.00000000"], ["1974.27000000", "0.00000000"], ["1974.26000000", "0.00000000"], ["1974.24000000", "0.00000000"], ["1974.22000000", "0.00000000"], ["1974.21000000", "0.00000000"], ["1974.20000000", "0.00000000"], ["1974.19000000", "0.00000000"], ["1974.18000000", "4.54520000"], ["1974.17000000", "0.12520000"], ["1974.16000000", "1.49690000"], ["1974.15000000", "0.00260000"], ["1974.14000000", "0.13170000"], ["1974.13000000", "0.00760000"], ["1974.12000000", "0.01030000"], ["1974.11000000", "0.11560000"], ["1974.10000000", "0.17400000"], ["1974.09000000", "0.00260000"], ["1974.08000000", "0.03540000"], ["1974.07000000", "0.51680000"], ["1974.06000000", "0.07590000"], ["1974.05000000", "3.06270000"], ["1974.04000000", "1.28780000"], ["1974.03000000", "0.01020000"], ["1974.01000000", "1.10560000"], ["1974.00000000", "36.04420000"], ["1973.98000000", "0.02220000"], ["1973.96000000", "0.22150000"], ["1973.95000000", "0.09110000"], ["1973.94000000", "0.20720000"], ["1973.93000000", "0.32370000"], ["1973.92000000", "0.03000000"], ["1973.91000000", "0.17710000"], ["1973.90000000", "11.22780000"], ["1973.89000000", "2.80570000"], ["1973.88000000", "1.64590000"], ["1973.87000000", "0.00960000"], ["1973.86000000", "0.33140000"], ["1973.85000000", "2.07210000"], ["1973.84000000", "0.06130000"], ["1973.82000000", "0.89400000"], ["1973.81000000", "0.14200000"], ["1973.80000000", "0.00770000"], ["1973.77000000", "0.00500000"], ["1973.76000000", "14.09450000"], ["1973.75000000", "0.14390000"], ["1973.74000000", "1.10910000"], ["1973.72000000", "0.28130000"], ["1973.71000000", "1.39940000"], ["1973.70000000", "0.08410000"], ["1973.68000000", "0.03940000"], ["1973.66000000", "0.15430000"], ["1973.65000000", "0.00420000"], ["1973.63000000", "0.63090000"], ["1973.61000000", "0.00880000"], ["1973.59000000", "0.12230000"], ["1973.58000000", "0.00000000"], ["1973.54000000", "0.00000000"], ["1973.52000000", "0.07600000"], ["1973.51000000", "0.01540000"], ["1973.47000000", "14.87060000"], ["1973.46000000", "38.19000000"], ["1973.44000000", "0.45060000"], ["1973.43000000", "7.60770000"], ["1973.42000000", "0.00510000"], ["1973.41000000", "1.54410000"], ["1973.40000000", "0.00870000"], ["1973.37000000", "0.20130000"], ["1973.36000000", "0.30530000"], ["1973.35000000", "0.02000000"], ["1973.31000000", "7.36160000"], ["1973.30000000", "11.32880000"], ["1973.29000000", "0.01100000"], ["1973.26000000", "0.00380000"], ["1973.23000000", "1.85890000"], ["1973.22000000", "0.54000000"], ["1973.20000000", "1.49140000"], ["1973.18000000", "0.10600000"], ["1973.15000000", "0.90450000"], ["1973.14000000", "7.27400000"], ["1973.08000000", "0.15290000"], ["1973.04000000", "0.03000000"], ["1973.00000000", "9.29440000"], ["1972.94000000", "7.09160000"], ["1972.90000000", "27.75380000"], ["1972.88000000", "0.08250000"], ["1972.86000000", "16.87760000"], ["1972.72000000", "1.12750000"], ["1972.66000000", "0.57920000"], ["1972.57000000", "22.57370000"], ["1972.46000000", "8.52010000"], ["1972.39000000", "0.00000000"], ["1972.31000000", "0.32590000"], ["1972.30000000", "18.33500000"], ["1972.29000000", "0.05330000"], ["1972.26000000", "8.51510000"], ["1972.24000000", "7.84980000"], ["1972.22000000", "7.14160000"], ["1972.15000000", "0.11020000"], ["1972.06000000", "8.52630000"], ["1972.04000000", "7.09080000"], ["1972.02000000", "7.09350000"], ["1972.00000000", "30.85160000"], ["1971.91000000", "8.50890000"], ["1971.84000000", "7.09340000"], ["1971.83000000", "7.10100000"], ["1971.82000000", "7.09340000"], ["1971.63000000", "8.11740000"], ["1971.62000000", "7.09080000"], ["1971.53000000", "0.00300000"], ["1971.44000000", "7.09080000"], ["1971.43000000", "7.09080000"], ["1971.42000000", "7.24930000"], ["1971.27000000", "7.09400000"], ["1970.70000000", "5.09650000"], ["1970.69000000", "13.50940000"], ["1970.51000000", "13.52150000"], ["1970.08000000", "13.56320000"], ["1968.39000000", "0.10000000"], ["1966.45000000", "3.60000000"], ["1965.66000000", "0.05080000"], ["1965.54000000", "0.00000000"], ["1964.45000000", "0.00260000"], ["1963.33000000", "1.28380000"], ["1776.95000000", "0.11240000"], ["1776.77000000", "0.00620000"], ["1579.86000000", "0.17500000"], ["1579.84000000", "0.02350000"], ["1579.51000000", "0.02100000"], ["1579.35000000", "0.00700000"]], "a": [["1974.19000000", "78.96360000"], ["1974.20000000", "3.01310000"], ["1974.21000000", "6.14990000"], ["1974.23000000", "0.00000000"], ["1974.25000000", "5.00050000"], ["1974.27000000", "0.02880000"], ["1974.28000000", "6.46760000"], ["1974.29000000", "0.00000000"], ["1974.30000000", "0.00260000"], ["1974.31000000", "0.00000000"], ["1974.32000000", "0.03000000"], ["1974.33000000", "0.00000000"], ["1974.35000000", "0.00000000"], ["1974.36000000", "0.00000000"], ["1974.37000000", "0.00760000"], ["1974.38000000", "7.23260000"], ["1974.39000000", "9.33780000"], ["1974.40000000", "0.03570000"], ["1974.41000000", "0.00000000"], ["1974.46000000", "0.01160000"], ["1974.47000000", "0.00000000"], ["1974.48000000", "0.92810000"], ["1974.49000000", "0.00000000"], ["1974.50000000", "7.09950000"], ["1974.51000000", "0.01420000"], ["1974.53000000", "2.08080000"], ["1974.54000000", "0.00000000"], ["1974.55000000", "0.00000000"], ["1974.56000000", "0.67640000"], ["1974.58000000", "3.92490000"], ["1974.60000000", "1.33670000"], ["1974.62000000", "13.87550000"], ["1974.63000000", "29.78130000"], ["1974.64000000", "0.03260000"], ["1974.67000000", "0.00260000"], ["1974.79000000", "9.15440000"], ["1974.84000000", "0.00000000"], ["1974.85000000", "0.00260000"], ["1974.88000000", "4.39800000"], ["1975.20000000", "0.03310000"], ["1975.30000000", "9.63110000"], ["1975.41000000", "0.77050000"], ["1975.52000000", "0.49360000"], ["1975.56000000", "14.98060000"], ["1975.60000000", "1.10480000"], ["1975.67000000", "0.00000000"], ["1975.68000000", "0.04310000"], ["1975.71000000", "0.00560000"], ["1975.74000000", "9.67630000"], ["1975.76000000", "0.59400000"], ["1975.85000000", "1.28280000"], ["1975.86000000", "0.10000000"], ["1975.90000000", "7.08690000"], ["1976.05000000", "7.58190000"], ["1976.26000000", "0.00300000"], ["1976.27000000", "0.00000000"], ["1976.28000000", "0.00000000"], ["1976.40000000", "5.23360000"], ["1976.49000000", "0.00000000"], ["1977.04000000", "0.00000000"], ["1977.13000000", "0.00000000"], ["1977.16000000", "0.00000000"], ["1977.80000000", "0.00310000"], ["1978.77000000", "7.77900000"], ["1979.28000000", "0.00000000"], ["1979.39000000", "0.00380000"], ["1979.46000000", "0.03000000"], ["1979.58000000", "36.21670000"], ["1979.68000000", "0.00000000"], ["1979.80000000", "0.00000000"], ["1982.74000000", "1.30550000"], ["1985.23000000", "0.00000000"], ["1985.37000000", "0.10260000"], ["1986.85000000", "0.05780000"], ["1989.73000000", "0.00000000"], ["2001.65000000", "0.10000000"], ["2003.43000000", "17.68350000"], ["2003.87000000", "0.00260000"], ["2268.49000000", "0.06780000"], ["2474.28000000", "0.07630000"]], "_local_ts_utc": "2026-06-01T07:48:59.411627+00:00"}
{"e": "depthUpdate", "E": 1780300140615, "s": "ETHUSDT", "U": 76583075735, "u": 76583076310, "b": [["1974.18000000", "20.39580000"], ["1974.17000000", "0.11980000"], ["1974.16000000", "0.04690000"], ["1974.11000000", "0.11560000"], ["1974.08000000", "0.00000000"], ["1974.07000000", "0.00000000"], ["1974.06000000", "0.07050000"], ["1974.05000000", "0.01000000"], ["1974.04000000", "0.00000000"], ["1974.03000000", "0.01020000"], ["1974.02000000", "0.02510000"], ["1974.01000000", "1.06070000"], ["1974.00000000", "12.29260000"], ["1973.93000000", "0.05370000"], ["1973.92000000", "0.03000000"], ["1973.91000000", "0.10800000"], ["1973.90000000", "2.49460000"], ["1973.89000000", "2.53570000"], ["1973.88000000", "1.37590000"], ["1973.87000000", "0.51630000"], ["1973.86000000", "0.06140000"], ["1973.85000000", "1.80210000"], ["1973.83000000", "0.04230000"], ["1973.82000000", "0.84370000"], ["1973.77000000", "15.60470000"], ["1973.76000000", "0.03000000"], ["1973.74000000", "1.36260000"], ["1973.73000000", "0.03600000"], ["1973.72000000", "0.01130000"], ["1973.71000000", "0.00000000"], ["1973.69000000", "9.86190000"], ["1973.67000000", "15.59970000"], ["1973.66000000", "25.39440000"], ["1973.65000000", "7.09500000"], ["1973.64000000", "0.00000000"], ["1973.63000000", "7.72170000"], ["1973.60000000", "8.71010000"], ["1973.57000000", "7.19190000"], ["1973.56000000", "0.39830000"], ["1973.54000000", "8.50890000"], ["1973.53000000", "9.64630000"], ["1973.51000000", "3.37270000"], ["1973.50000000", "33.24800000"], ["1973.49000000", "13.55690000"], ["1973.48000000", "7.09820000"], ["1973.47000000", "7.09340000"], ["1973.46000000", "22.59030000"], ["1973.44000000", "1.05060000"], ["1973.43000000", "0.51690000"], ["1973.41000000", "0.01080000"], ["1973.39000000", "0.29350000"], ["1973.37000000", "11.41570000"], ["1973.36000000", "7.39610000"], ["1973.35000000", "29.12600000"], ["1973.33000000", "0.16130000"], ["1973.32000000", "7.28640000"], ["1973.31000000", "0.27260000"], ["1973.30000000", "7.86330000"], ["1973.29000000", "0.01100000"], ["1973.26000000", "0.00380000"], ["1973.25000000", "13.16240000"], ["1973.24000000", "1.68310000"], ["1973.23000000", "3.25890000"], ["1973.21000000", "0.00000000"], ["1973.19000000", "20.85650000"], ["1973.18000000", "43.39360000"], ["1973.17000000", "0.00000000"], ["1973.15000000", "1.10450000"], ["1973.14000000", "0.18500000"], ["1973.13000000", "0.17750000"], ["1973.11000000", "0.01570000"], ["1973.10000000", "1.20550000"], ["1973.06000000", "0.14300000"], ["1973.03000000", "16.77270000"], ["1973.02000000", "43.28760000"], ["1973.01000000", "1.01410000"], ["1973.00000000", "8.49440000"], ["1972.99000000", "0.55160000"], ["1972.97000000", "14.64950000"], ["1972.96000000", "0.04270000"], ["1972.94000000", "0.00260000"], ["1972.93000000", "24.10720000"], ["1972.91000000", "30.93120000"], ["1972.90000000", "0.99980000"], ["1972.87000000", "0.03760000"], ["1972.86000000", "5.54970000"], ["1972.81000000", "0.73490000"], ["1972.80000000", "20.88320000"], ["1972.72000000", "3.70570000"], ["1972.70000000", "1.35850000"], ["1972.66000000", "1.59240000"], ["1972.60000000", "10.98350000"], ["1972.58000000", "22.28440000"], ["1972.47000000", "8.27310000"], ["1972.45000000", "3.62720000"], ["1972.43000000", "0.04410000"], ["1972.40000000", "11.35680000"], ["1972.35000000", "0.00000000"], ["1972.34000000", "7.09080000"], ["1972.31000000", "13.83220000"], ["1972.30000000", "17.82870000"], ["1972.26000000", "8.51890000"], ["1972.16000000", "0.00580000"], ["1972.14000000", "3.99120000"], ["1972.10000000", "0.00260000"], ["1972.09000000", "25.75060000"], ["1972.06000000", "0.01740000"], ["1972.04000000", "0.00000000"], ["1972.03000000", "20.59710000"], ["1972.01000000", "15.98460000"], ["1971.96000000", "10.73230000"], ["1971.92000000", "7.10250000"], ["1971.91000000", "0.00000000"], ["1971.90000000", "15.61850000"], ["1971.84000000", "0.00260000"], ["1971.82000000", "0.00260000"], ["1971.80000000", "0.00310000"], ["1971.76000000", "0.01280000"], ["1971.75000000", "14.54030000"], ["1971.72000000", "0.00260000"], ["1971.71000000", "0.00000000"], ["1971.69000000", "1.83700000"], ["1971.67000000", "0.53070000"], ["1971.66000000", "0.29260000"], ["1971.64000000", "0.01270000"], ["1971.63000000", "1.02660000"], ["1971.62000000", "0.00000000"], ["1971.61000000", "0.22900000"], ["1971.51000000", "0.01280000"], ["1971.49000000", "3.95610000"], ["1971.44000000", "0.00000000"], ["1971.43000000", "0.00000000"], ["1971.42000000", "0.15850000"], ["1971.39000000", "0.00000000"], ["1971.31000000", "0.01530000"], ["1971.28000000", "0.00880000"], ["1971.27000000", "0.00320000"], ["1971.08000000", "1.20820000"], ["1971.07000000", "0.00530000"], ["1970.49000000", "1.85310000"], ["1970.36000000", "31.94180000"], ["1970.25000000", "10.62450000"], ["1970.09000000", "0.50440000"], ["1970.08000000", "0.05690000"], ["1968.47000000", "0.00260000"], ["1968.38000000", "0.00990000"], ["1966.85000000", "3.62280000"], ["1966.64000000", "0.08940000"], ["1964.79000000", "1.37260000"], ["1963.33000000", "0.07830000"], ["1954.09000000", "0.01820000"], ["1918.91000000", "0.03030000"], ["1776.77000000", "0.01860000"], ["1579.84000000", "0.01650000"], ["1579.68000000", "0.03760000"], ["1579.35000000", "0.07700000"]], "a": [["1974.19000000", "64.54820000"], ["1974.20000000", "3.02240000"], ["1974.21000000", "0.01050000"], ["1974.22000000", "1.50480000"], ["1974.23000000", "0.00000000"], ["1974.24000000", "0.00800000"], ["1974.25000000", "4.98870000"], ["1974.27000000", "0.00000000"], ["1974.28000000", "0.00000000"], ["1974.30000000", "0.00570000"], ["1974.34000000", "0.00000000"], ["1974.35000000", "0.53650000"], ["1974.36000000", "4.48160000"], ["1974.37000000", "7.09840000"], ["1974.38000000", "7.23260000"], ["1974.39000000", "0.64710000"], ["1974.42000000", "0.00000000"], ["1974.44000000", "0.00000000"], ["1974.46000000", "12.89450000"], ["1974.47000000", "8.50890000"], ["1974.48000000", "0.03260000"], ["1974.49000000", "29.66450000"], ["1974.51000000", "0.00260000"], ["1974.54000000", "0.00380000"], ["1974.57000000", "1.00000000"], ["1974.58000000", "3.89970000"], ["1974.63000000", "43.28760000"], ["1974.87000000", "13.60760000"], ["1974.89000000", "0.40000000"], ["1975.00000000", "0.38640000"], ["1975.07000000", "8.50850000"], ["1975.20000000", "0.20360000"], ["1975.33000000", "0.00000000"], ["1975.34000000", "0.37720000"], ["1975.50000000", "8.77280000"], ["1975.74000000", "1.16740000"], ["1975.81000000", "0.48600000"], ["1975.87000000", "5.14860000"], ["1975.88000000", "7.09600000"], ["1975.91000000", "0.00000000"], ["1976.00000000", "13.68110000"], ["1977.26000000", "0.91580000"], ["1977.36000000", "0.00940000"], ["1978.08000000", "0.00000000"], ["1978.54000000", "0.00260000"], ["1978.58000000", "0.00000000"], ["1979.09000000", "0.00260000"], ["1979.60000000", "1.29570000"], ["1979.63000000", "0.00000000"], ["1979.67000000", "0.13120000"], ["1979.73000000", "0.00000000"], ["1979.83000000", "0.00000000"], ["1980.10000000", "0.00000000"], ["1980.31000000", "0.13460000"], ["1981.77000000", "1.91740000"], ["1982.42000000", "0.01820000"], ["1983.42000000", "0.20360000"], ["1984.69000000", "0.11570000"], ["1984.78000000", "0.20800000"], ["1985.83000000", "1.24450000"], ["1986.47000000", "0.00510000"], ["1987.07000000", "0.04000000"], ["1991.42000000", "0.01660000"], ["1994.60000000", "0.00740000"], ["1994.91000000", "0.00520000"], ["2000.40000000", "0.04700000"], ["2004.42000000", "0.08060000"], ["2015.74000000", "0.00000000"], ["2022.85000000", "0.07060000"], ["2081.87000000", "0.00380000"], ["2267.99000000", "0.06460000"], ["2268.49000000", "0.12990000"], ["2291.11000000", "0.06800000"]], "_local_ts_utc": "2026-06-01T07:48:59.511624+00:00"}
{"e": "depthUpdate", "E": 1780300140729, "s": "ETHUSDT", "U": 76583076311, "u": 76583077659, "b": [["1974.18000000", "0.00000000"], ["1974.17000000", "0.00000000"], ["1974.16000000", "0.00000000"], ["1974.15000000", "0.00000000"], ["1974.14000000", "0.00000000"], ["1974.13000000", "0.00000000"], ["1974.12000000", "0.00000000"], ["1974.11000000", "0.00000000"], ["1974.10000000", "0.00000000"], ["1974.09000000", "0.00000000"], ["1974.06000000", "0.00000000"], ["1974.05000000", "0.00000000"], ["1974.03000000", "0.00000000"], ["1974.02000000", "0.00000000"], ["1974.01000000", "0.00000000"], ["1974.00000000", "0.00000000"], ["1973.99000000", "0.00000000"], ["1973.98000000", "0.00000000"], ["1973.97000000", "0.00000000"], ["1973.96000000", "0.00000000"], ["1973.95000000", "0.00000000"], ["1973.94000000", "0.00000000"], ["1973.93000000", "0.00000000"], ["1973.92000000", "0.00000000"], ["1973.91000000", "0.00000000"], ["1973.90000000", "0.00000000"], ["1973.89000000", "0.00000000"], ["1973.88000000", "0.00000000"], ["1973.87000000", "0.00000000"], ["1973.86000000", "0.00000000"], ["1973.85000000", "0.00000000"], ["1973.84000000", "0.00000000"], ["1973.83000000", "0.00000000"], ["1973.82000000", "0.00000000"], ["1973.81000000", "0.00000000"], ["1973.80000000", "0.00000000"], ["1973.78000000", "0.00000000"], ["1973.77000000", "0.00000000"], ["1973.76000000", "0.00000000"], ["1973.75000000", "0.00000000"], ["1973.74000000", "0.00000000"], ["1973.73000000", "0.00000000"], ["1973.72000000", "0.00000000"], ["1973.70000000", "0.00000000"], ["1973.69000000", "0.00000000"], ["1973.68000000", "0.00000000"], ["1973.67000000", "0.00000000"], ["1973.66000000", "6.24870000"], ["1973.65000000", "0.00680000"], ["1973.64000000", "0.00540000"], ["1973.63000000", "0.63630000"], ["1973.62000000", "0.20480000"], ["1973.61000000", "0.01420000"], ["1973.60000000", "0.05980000"], ["1973.59000000", "0.12500000"], ["1973.58000000", "0.00000000"], ["1973.57000000", "0.10110000"], ["1973.56000000", "0.02020000"], ["1973.54000000", "0.00000000"], ["1973.53000000", "0.02000000"], ["1973.52000000", "0.04600000"], ["1973.51000000", "3.37270000"], ["1973.50000000", "1.10850000"], ["1973.49000000", "0.05060000"], ["1973.48000000", "0.09860000"], ["1973.47000000", "0.02680000"], ["1973.46000000", "0.01660000"], ["1973.45000000", "0.23230000"], ["1973.44000000", "0.45060000"], ["1973.43000000", "0.50670000"], ["1973.42000000", "0.00510000"], ["1973.40000000", "0.00560000"], ["1973.39000000", "0.14950000"], ["1973.37000000", "0.20130000"], ["1973.36000000", "0.03530000"], ["1973.35000000", "0.02000000"], ["1973.34000000", "0.27000000"], ["1973.32000000", "0.19560000"], ["1973.31000000", "0.00260000"], ["1973.30000000", "0.03560000"], ["1973.28000000", "0.04330000"], ["1973.27000000", "0.00000000"], ["1973.25000000", "9.56240000"], ["1973.23000000", "0.33700000"], ["1973.20000000", "0.16980000"], ["1973.19000000", "0.27700000"], ["1973.18000000", "0.00600000"], ["1973.16000000", "0.29400000"], ["1973.15000000", "0.50450000"], ["1973.12000000", "0.03000000"], ["1973.11000000", "0.01570000"], ["1973.10000000", "0.00260000"], ["1973.08000000", "0.15290000"], ["1973.07000000", "0.64120000"], ["1973.06000000", "0.04300000"], ["1973.05000000", "0.27000000"], ["1973.03000000", "1.01310000"], ["1973.02000000", "0.00000000"], ["1973.01000000", "0.00000000"], ["1973.00000000", "8.49700000"], ["1972.99000000", "0.00000000"], ["1972.98000000", "0.10260000"], ["1972.96000000", "0.65340000"], ["1972.94000000", "0.00260000"], ["1972.93000000", "1.93350000"], ["1972.91000000", "0.00560000"], ["1972.90000000", "1.00240000"], ["1972.89000000", "0.01670000"], ["1972.86000000", "6.34970000"], ["1972.85000000", "3.65260000"], ["1972.81000000", "0.83490000"], ["1972.80000000", "0.31870000"], ["1972.79000000", "11.73110000"], ["1972.78000000", "1.32470000"], ["1972.77000000", "16.32700000"], ["1972.73000000", "0.54000000"], ["1972.72000000", "0.08460000"], ["1972.71000000", "0.00260000"], ["1972.70000000", "0.00260000"], ["1972.68000000", "8.15630000"], ["1972.65000000", "4.99850000"], ["1972.64000000", "0.04520000"], ["1972.63000000", "0.03390000"], ["1972.62000000", "0.01640000"], ["1972.61000000", "0.00260000"], ["1972.58000000", "7.36080000"], ["1972.57000000", "0.00000000"], ["1972.56000000", "0.27000000"], ["1972.53000000", "0.00260000"], ["1972.51000000", "0.08600000"], ["1972.49000000", "0.00000000"], ["1972.48000000", "0.04480000"], ["1972.46000000", "0.01120000"], ["1972.44000000", "0.11860000"], ["1972.43000000", "1.39110000"], ["1972.41000000", "0.10400000"], ["1972.40000000", "24.89310000"], ["1972.39000000", "0.00000000"], ["1972.38000000", "7.09890000"], ["1972.36000000", "7.20610000"], ["1972.34000000", "0.00000000"], ["1972.33000000", "0.01430000"], ["1972.32000000", "0.04550000"], ["1972.31000000", "0.53840000"], ["1972.28000000", "0.00000000"], ["1972.26000000", "0.01000000"], ["1972.24000000", "0.03000000"], ["1972.22000000", "0.05080000"], ["1972.19000000", "7.09380000"], ["1972.18000000", "7.14920000"], ["1972.16000000", "0.03580000"], ["1972.14000000", "2.14900000"], ["1972.13000000", "0.04350000"], ["1972.12000000", "13.50630000"], ["1972.10000000", "0.00260000"], ["1972.06000000", "0.02120000"], ["1972.04000000", "0.00000000"], ["1972.03000000", "0.00000000"], ["1972.02000000", "0.00270000"], ["1972.01000000", "0.00760000"], ["1972.00000000", "30.88160000"], ["1971.99000000", "0.00000000"], ["1971.98000000", "7.22240000"], ["1971.97000000", "0.00560000"], ["1971.96000000", "6.95040000"], ["1971.92000000", "0.01170000"], ["1971.91000000", "0.00000000"], ["1971.90000000", "10.61500000"], ["1971.89000000", "1.35920000"], ["1971.86000000", "0.51890000"], ["1971.85000000", "5.12770000"], ["1971.84000000", "20.59970000"], ["1971.83000000", "0.01020000"], ["1971.82000000", "0.00260000"], ["1971.79000000", "7.12380000"], ["1971.76000000", "8.08530000"], ["1971.75000000", "0.00300000"], ["1971.72000000", "0.00260000"], ["1971.71000000", "0.00000000"], ["1971.69000000", "10.34590000"], ["1971.66000000", "0.29640000"], ["1971.64000000", "7.10350000"], ["1971.63000000", "0.01370000"], ["1971.62000000", "0.00000000"], ["1971.61000000", "0.22900000"], ["1971.60000000", "16.72970000"], ["1971.56000000", "13.51040000"], ["1971.52000000", "8.51150000"], ["1971.51000000", "7.10360000"], ["1971.48000000", "0.02070000"], ["1971.42000000", "0.15850000"], ["1971.40000000", "11.21580000"], ["1971.38000000", "38.86860000"], ["1971.31000000", "7.10610000"], ["1971.28000000", "13.51510000"], ["1971.27000000", "0.00320000"], ["1971.25000000", "3.61140000"], ["1971.24000000", "8.50890000"], ["1971.18000000", "7.09080000"], ["1971.11000000", "7.50770000"], ["1971.07000000", "7.09610000"], ["1971.04000000", "8.53390000"], ["1971.01000000", "13.81930000"], ["1970.98000000", "11.24370000"], ["1970.97000000", "0.03880000"], ["1970.96000000", "0.00390000"], ["1970.91000000", "14.18160000"], ["1970.84000000", "8.51410000"], ["1970.78000000", "7.09540000"], ["1970.73000000", "13.52630000"], ["1970.71000000", "14.21980000"], ["1970.69000000", "0.00310000"], ["1970.64000000", "8.50890000"], ["1970.59000000", "28.18790000"], ["1970.55000000", "0.01360000"], ["1970.52000000", "7.09370000"], ["1970.51000000", "0.01520000"], ["1970.50000000", "0.97250000"], ["1970.39000000", "7.09080000"], ["1970.37000000", "29.11950000"], ["1970.35000000", "0.02560000"], ["1970.23000000", "0.01020000"], ["1970.19000000", "7.65710000"], ["1970.17000000", "0.00260000"], ["1970.13000000", "0.10760000"], ["1970.09000000", "14.01070000"], ["1970.02000000", "0.13180000"], ["1969.90000000", "0.53550000"], ["1969.81000000", "13.50630000"], ["1969.66000000", "13.50630000"], ["1969.65000000", "26.28890000"], ["1969.38000000", "13.50630000"], ["1969.35000000", "0.00000000"], ["1969.17000000", "13.50630000"], ["1969.02000000", "0.01510000"], ["1968.59000000", "7.64410000"], ["1968.31000000", "0.49760000"], ["1968.22000000", "0.00260000"], ["1967.18000000", "4.18880000"], ["1967.09000000", "60.85640000"], ["1966.64000000", "0.08150000"], ["1966.25000000", "3.62140000"], ["1966.05000000", "6.45240000"], ["1965.74000000", "0.03310000"], ["1965.40000000", "0.00000000"], ["1965.18000000", "0.38160000"], ["1964.79000000", "0.02550000"], ["1964.75000000", "6.72500000"], ["1964.44000000", "0.03310000"], ["1964.37000000", "0.20220000"], ["1964.04000000", "0.00000000"], ["1963.33000000", "1.28380000"], ["1963.31000000", "70.59190000"], ["1962.74000000", "1.20550000"], ["1961.76000000", "0.18590000"], ["1958.15000000", "0.00280000"], ["1955.18000000", "0.00000000"], ["1950.09000000", "24.48380000"], ["1776.77000000", "0.00000000"], ["1776.75000000", "0.00000000"], ["1776.31000000", "0.01480000"], ["1592.05000000", "0.00000000"], ["1588.64000000", "0.00000000"], ["1588.49000000", "0.08400000"], ["1587.82000000", "0.03500000"], ["1586.63000000", "0.04900000"], ["1583.52000000", "0.11200000"], ["1582.64000000", "0.08400000"], ["1582.32000000", "0.06300000"], ["1581.14000000", "0.06300000"], ["1579.84000000", "0.00950000"], ["1579.68000000", "0.01660000"], ["1579.66000000", "0.00000000"], ["1579.60000000", "1.82170000"], ["1579.51000000", "0.01400000"], ["1578.94000000", "0.04560000"], ["1384.56000000", "0.00800000"], ["1383.40000000", "0.01750000"], ["1383.33000000", "0.00000000"]], "a": [["1973.67000000", "39.83350000"], ["1973.68000000", "0.03000000"], ["1973.69000000", "48.64650000"], ["1973.70000000", "8.77820000"], ["1973.71000000", "0.00510000"], ["1973.72000000", "0.00510000"], ["1973.74000000", "3.00000000"], ["1973.75000000", "0.00000000"], ["1973.76000000", "0.03000000"], ["1973.77000000", "0.03380000"], ["1973.78000000", "0.01020000"], ["1973.80000000", "0.00260000"], ["1973.81000000", "0.03380000"], ["1973.82000000", "46.27550000"], ["1973.83000000", "0.00000000"], ["1973.84000000", "0.03000000"], ["1973.86000000", "14.53370000"], ["1973.87000000", "13.50630000"], ["1973.88000000", "0.00000000"], ["1973.89000000", "0.03640000"], ["1973.90000000", "0.00260000"], ["1973.91000000", "0.00000000"], ["1973.92000000", "0.03000000"], ["1973.93000000", "22.57370000"], ["1973.94000000", "14.53850000"], ["1973.97000000", "0.64640000"], ["1973.98000000", "0.00760000"], ["1973.99000000", "0.03380000"], ["1974.00000000", "31.67600000"], ["1974.01000000", "11.79700000"], ["1974.02000000", "9.54130000"], ["1974.03000000", "2.69060000"], ["1974.04000000", "0.00000000"], ["1974.05000000", "0.20000000"], ["1974.06000000", "0.00000000"], ["1974.07000000", "0.00260000"], ["1974.08000000", "0.03000000"], ["1974.09000000", "0.00000000"], ["1974.10000000", "0.00260000"], ["1974.11000000", "0.00000000"], ["1974.12000000", "15.65060000"], ["1974.13000000", "25.95990000"], ["1974.14000000", "0.00000000"], ["1974.15000000", "0.00000000"], ["1974.16000000", "52.59060000"], ["1974.17000000", "75.36300000"], ["1974.18000000", "2.22760000"], ["1974.19000000", "7.80700000"], ["1974.20000000", "0.06780000"], ["1974.21000000", "1.33130000"], ["1974.22000000", "0.01160000"], ["1974.23000000", "1.20550000"], ["1974.24000000", "0.03520000"], ["1974.25000000", "0.00000000"], ["1974.26000000", "0.64640000"], ["1974.30000000", "3.60570000"], ["1974.32000000", "0.03260000"], ["1974.33000000", "0.00000000"], ["1974.34000000", "8.51270000"], ["1974.35000000", "7.62730000"], ["1974.36000000", "4.63240000"], ["1974.38000000", "7.09080000"], ["1974.39000000", "0.64710000"], ["1974.43000000", "0.00260000"], ["1974.44000000", "1.20550000"], ["1974.45000000", "0.00000000"], ["1974.46000000", "12.88290000"], ["1974.49000000", "29.66450000"], ["1974.50000000", "33.85350000"], ["1974.56000000", "0.03000000"], ["1974.57000000", "0.00000000"], ["1974.58000000", "0.16360000"], ["1974.60000000", "0.03870000"], ["1974.66000000", "0.00000000"], ["1974.69000000", "0.05000000"], ["1974.70000000", "22.57680000"], ["1974.74000000", "0.00640000"], ["1974.76000000", "15.14840000"], ["1974.78000000", "0.12760000"], ["1974.79000000", "7.09080000"], ["1974.80000000", "20.17660000"], ["1974.87000000", "13.50630000"], ["1974.88000000", "4.29800000"], ["1974.89000000", "0.00000000"], ["1974.90000000", "29.66760000"], ["1974.94000000", "0.00680000"], ["1974.96000000", "0.60440000"], ["1974.97000000", "1.25050000"], ["1974.98000000", "3.60000000"], ["1975.00000000", "0.00570000"], ["1975.04000000", "9.62530000"], ["1975.07000000", "0.00000000"], ["1975.09000000", "0.00260000"], ["1975.10000000", "28.17060000"], ["1975.12000000", "0.00000000"], ["1975.13000000", "9.86180000"], ["1975.15000000", "0.76620000"], ["1975.16000000", "7.09340000"], ["1975.19000000", "0.60260000"], ["1975.20000000", "0.17360000"], ["1975.22000000", "0.00000000"], ["1975.28000000", "0.00000000"], ["1975.34000000", "0.37720000"], ["1975.35000000", "1.54300000"], ["1975.36000000", "0.00000000"], ["1975.38000000", "0.00300000"], ["1975.39000000", "0.00000000"], ["1975.40000000", "3.67130000"], ["1975.41000000", "0.80000000"], ["1975.44000000", "0.00520000"], ["1975.49000000", "0.00300000"], ["1975.51000000", "0.00260000"], ["1975.55000000", "0.00260000"], ["1975.56000000", "0.00260000"], ["1975.66000000", "0.15110000"], ["1975.69000000", "0.76260000"], ["1975.85000000", "1.20550000"], ["1975.87000000", "2.14800000"], ["1975.88000000", "0.00520000"], ["1975.90000000", "0.00000000"], ["1975.93000000", "0.00300000"], ["1975.98000000", "22.57370000"], ["1976.00000000", "3.60580000"], ["1976.05000000", "0.49280000"], ["1976.10000000", "0.67660000"], ["1976.20000000", "1.56450000"], ["1976.40000000", "0.11310000"], ["1976.50000000", "0.00260000"], ["1976.51000000", "1.20810000"], ["1976.56000000", "0.00000000"], ["1976.60000000", "0.00310000"], ["1976.61000000", "1.87580000"], ["1976.68000000", "0.48600000"], ["1976.76000000", "0.03290000"], ["1976.79000000", "100.78660000"], ["1976.83000000", "0.69280000"], ["1976.85000000", "0.00000000"], ["1976.86000000", "32.41420000"], ["1976.89000000", "0.34560000"], ["1976.92000000", "0.00820000"], ["1976.95000000", "69.27920000"], ["1977.00000000", "0.00310000"], ["1977.03000000", "0.00560000"], ["1977.29000000", "0.00000000"], ["1977.48000000", "0.00260000"], ["1977.50000000", "0.00000000"], ["1977.66000000", "0.00260000"], ["1977.94000000", "0.00000000"], ["1978.06000000", "0.00000000"], ["1978.11000000", "0.00520000"], ["1978.26000000", "0.00000000"], ["1978.27000000", "8.84980000"], ["1978.32000000", "0.00000000"], ["1978.34000000", "0.00000000"], ["1978.40000000", "0.00570000"], ["1978.72000000", "0.00000000"], ["1978.77000000", "0.00000000"], ["1979.09000000", "0.00000000"], ["1979.17000000", "0.00000000"], ["1979.21000000", "0.00000000"], ["1979.30000000", "0.00000000"], ["1979.39000000", "0.00380000"], ["1979.68000000", "0.00000000"], ["1979.92000000", "0.00000000"], ["1980.91000000", "0.00000000"], ["1980.94000000", "126.36190000"], ["1982.45000000", "0.00000000"], ["1983.64000000", "0.00000000"], ["1984.99000000", "0.00000000"], ["1986.49000000", "0.00000000"], ["1986.55000000", "0.00000000"], ["1986.67000000", "0.00000000"], ["1988.62000000", "0.02380000"], ["1988.91000000", "1.06920000"], ["1989.37000000", "0.00000000"], ["1989.81000000", "0.13280000"], ["1990.87000000", "15.07050000"], ["1992.64000000", "0.07890000"], ["1996.74000000", "17.47450000"], ["1998.81000000", "0.00980000"], ["2002.91000000", "14.77730000"], ["2003.43000000", "0.00000000"], ["2055.02000000", "0.05290000"], ["2062.01000000", "0.04980000"], ["2072.37000000", "0.00810000"], ["2073.84000000", "0.03100000"], ["2092.01000000", "0.00000000"]], "_local_ts_utc": "2026-06-01T07:48:59.626421+00:00"}
{"e": "depthUpdate", "E": 1780300140865, "s": "ETHUSDT", "U": 76583077660, "u": 76583079552, "b": [["1973.66000000", "0.00000000"], ["1973.65000000", "0.00000000"], ["1973.64000000", "0.00000000"], ["1973.63000000", "0.00000000"], ["1973.62000000", "0.00000000"], ["1973.61000000", "0.00000000"], ["1973.60000000", "0.00000000"], ["1973.59000000", "0.00000000"], ["1973.57000000", "0.00000000"], ["1973.56000000", "0.00000000"], ["1973.55000000", "0.00000000"], ["1973.53000000", "0.00000000"], ["1973.52000000", "0.00000000"], ["1973.51000000", "0.00000000"], ["1973.50000000", "0.00000000"], ["1973.49000000", "0.00000000"], ["1973.48000000", "0.00000000"], ["1973.47000000", "0.00000000"], ["1973.46000000", "0.00000000"], ["1973.45000000", "0.00000000"], ["1973.44000000", "0.00000000"], ["1973.43000000", "0.00000000"], ["1973.42000000", "0.00000000"], ["1973.41000000", "0.00000000"], ["1973.40000000", "0.00000000"], ["1973.39000000", "0.00000000"], ["1973.38000000", "0.00000000"], ["1973.37000000", "0.00000000"], ["1973.36000000", "0.00000000"], ["1973.35000000", "0.00000000"], ["1973.34000000", "0.00000000"], ["1973.33000000", "0.00000000"], ["1973.32000000", "0.00000000"], ["1973.31000000", "0.00000000"], ["1973.30000000", "0.00000000"], ["1973.29000000", "0.00000000"], ["1973.28000000", "0.00000000"], ["1973.26000000", "0.00000000"], ["1973.25000000", "0.00000000"], ["1973.24000000", "0.00000000"], ["1973.23000000", "0.00000000"], ["1973.22000000", "0.00000000"], ["1973.20000000", "0.00000000"], ["1973.19000000", "0.00000000"], ["1973.18000000", "0.00000000"], ["1973.16000000", "0.00000000"], ["1973.15000000", "14.13900000"], ["1973.14000000", "0.00000000"], ["1973.13000000", "0.00000000"], ["1973.12000000", "0.00000000"], ["1973.11000000", "0.00000000"], ["1973.10000000", "7.47480000"], ["1973.09000000", "0.00000000"], ["1973.08000000", "0.00000000"], ["1973.07000000", "0.00000000"], ["1973.06000000", "0.00000000"], ["1973.05000000", "0.00000000"], ["1973.04000000", "0.00000000"], ["1973.03000000", "0.00000000"], ["1973.00000000", "0.00000000"], ["1972.99000000", "0.68600000"], ["1972.98000000", "0.00000000"], ["1972.97000000", "0.00000000"], ["1972.96000000", "0.00000000"], ["1972.94000000", "0.00000000"], ["1972.93000000", "0.00000000"], ["1972.92000000", "0.00000000"], ["1972.91000000", "0.00000000"], ["1972.90000000", "25.72330000"], ["1972.89000000", "0.00000000"], ["1972.88000000", "0.00000000"], ["1972.87000000", "0.00000000"], ["1972.86000000", "0.00000000"], ["1972.85000000", "0.95400000"], ["1972.84000000", "0.00000000"], ["1972.83000000", "0.00000000"], ["1972.82000000", "0.00000000"], ["1972.81000000", "0.00000000"], ["1972.80000000", "79.14940000"], ["1972.79000000", "17.09420000"], ["1972.78000000", "1.46030000"], ["1972.77000000", "0.49960000"], ["1972.76000000", "0.00550000"], ["1972.75000000", "0.96400000"], ["1972.74000000", "0.00570000"], ["1972.73000000", "0.27000000"], ["1972.70000000", "15.15090000"], ["1972.69000000", "0.00000000"], ["1972.68000000", "0.01590000"], ["1972.66000000", "0.03920000"], ["1972.65000000", "1.15250000"], ["1972.64000000", "0.38090000"], ["1972.62000000", "0.01640000"], ["1972.61000000", "15.61340000"], ["1972.60000000", "2.51880000"], ["1972.59000000", "3.86580000"], ["1972.58000000", "0.00000000"], ["1972.57000000", "0.00000000"], ["1972.56000000", "0.03000000"], ["1972.55000000", "15.51650000"], ["1972.53000000", "0.00000000"], ["1972.51000000", "0.00000000"], ["1972.50000000", "0.36750000"], ["1972.49000000", "4.80400000"], ["1972.48000000", "8.55980000"], ["1972.47000000", "0.01020000"], ["1972.46000000", "0.02130000"], ["1972.45000000", "0.22720000"], ["1972.43000000", "7.13960000"], ["1972.42000000", "0.01520000"], ["1972.41000000", "0.10400000"], ["1972.40000000", "2.94200000"], ["1972.39000000", "3.60000000"], ["1972.38000000", "1.20810000"], ["1972.37000000", "0.00510000"], ["1972.36000000", "0.11530000"], ["1972.35000000", "0.61070000"], ["1972.32000000", "0.03510000"], ["1972.31000000", "7.15170000"], ["1972.30000000", "0.01680000"], ["1972.29000000", "0.00540000"], ["1972.26000000", "3.30030000"], ["1972.25000000", "0.21110000"], ["1972.24000000", "0.23000000"], ["1972.23000000", "0.00570000"], ["1972.22000000", "31.13920000"], ["1972.21000000", "0.04210000"], ["1972.20000000", "0.01090000"], ["1972.19000000", "0.00300000"], ["1972.18000000", "0.05840000"], ["1972.17000000", "2.99650000"], ["1972.16000000", "0.03580000"], ["1972.15000000", "0.01020000"], ["1972.14000000", "0.00260000"], ["1972.13000000", "14.23510000"], ["1972.12000000", "6.60380000"], ["1972.10000000", "8.52330000"], ["1972.09000000", "10.31020000"], ["1972.08000000", "0.03760000"], ["1972.03000000", "13.50630000"], ["1972.01000000", "22.58130000"], ["1972.00000000", "30.88160000"], ["1971.99000000", "8.51500000"], ["1971.98000000", "1.43160000"], ["1971.97000000", "11.53600000"], ["1971.96000000", "1.87370000"], ["1971.95000000", "0.30930000"], ["1971.94000000", "0.80000000"], ["1971.93000000", "0.06130000"], ["1971.92000000", "0.04170000"], ["1971.90000000", "11.82310000"], ["1971.89000000", "0.00000000"], ["1971.86000000", "0.27600000"], ["1971.85000000", "3.60770000"], ["1971.84000000", "0.03000000"], ["1971.81000000", "0.00000000"], ["1971.80000000", "4.63480000"], ["1971.79000000", "0.03300000"], ["1971.78000000", "0.02460000"], ["1971.77000000", "0.24860000"], ["1971.76000000", "0.04280000"], ["1971.75000000", "0.00300000"], ["1971.74000000", "0.01700000"], ["1971.69000000", "10.67870000"], ["1971.68000000", "0.04350000"], ["1971.67000000", "0.02420000"], ["1971.66000000", "1.56640000"], ["1971.65000000", "10.70600000"], ["1971.64000000", "0.01270000"], ["1971.63000000", "0.01370000"], ["1971.62000000", "1.01330000"], ["1971.61000000", "36.20180000"], ["1971.60000000", "14.71560000"], ["1971.56000000", "0.00410000"], ["1971.54000000", "0.12700000"], ["1971.52000000", "0.03260000"], ["1971.51000000", "0.01280000"], ["1971.49000000", "0.00000000"], ["1971.47000000", "0.07570000"], ["1971.46000000", "14.36230000"], ["1971.45000000", "10.69080000"], ["1971.42000000", "1.17190000"], ["1971.41000000", "29.10600000"], ["1971.40000000", "0.99720000"], ["1971.39000000", "1.01370000"], ["1971.38000000", "0.03430000"], ["1971.36000000", "0.13560000"], ["1971.31000000", "0.01530000"], ["1971.30000000", "0.76580000"], ["1971.29000000", "37.68400000"], ["1971.28000000", "0.00880000"], ["1971.27000000", "0.00320000"], ["1971.26000000", "0.71060000"], ["1971.24000000", "1.01340000"], ["1971.23000000", "23.58890000"], ["1971.20000000", "7.91280000"], ["1971.19000000", "4.45170000"], ["1971.18000000", "0.00000000"], ["1971.17000000", "0.04840000"], ["1971.13000000", "13.52680000"], ["1971.11000000", "0.41690000"], ["1971.09000000", "1.05030000"], ["1971.07000000", "0.00530000"], ["1971.06000000", "9.76830000"], ["1971.04000000", "0.02500000"], ["1971.01000000", "0.31300000"], ["1971.00000000", "8.17170000"], ["1970.99000000", "6.50450000"], ["1970.98000000", "0.00260000"], ["1970.97000000", "0.63380000"], ["1970.96000000", "1.52460000"], ["1970.95000000", "4.41400000"], ["1970.90000000", "11.30800000"], ["1970.89000000", "0.00390000"], ["1970.88000000", "0.00260000"], ["1970.87000000", "23.95870000"], ["1970.86000000", "0.00390000"], ["1970.84000000", "0.00520000"], ["1970.80000000", "10.99060000"], ["1970.79000000", "0.00910000"], ["1970.74000000", "0.00000000"], ["1970.73000000", "0.02000000"], ["1970.70000000", "3.60480000"], ["1970.64000000", "15.00000000"], ["1970.61000000", "0.26200000"], ["1970.60000000", "17.67790000"], ["1970.59000000", "20.59710000"], ["1970.58000000", "0.13720000"], ["1970.52000000", "0.00290000"], ["1970.50000000", "0.04450000"], ["1970.40000000", "8.19970000"], ["1970.39000000", "0.00000000"], ["1970.38000000", "6.24760000"], ["1970.37000000", "13.51980000"], ["1970.36000000", "0.04050000"], ["1970.26000000", "0.00790000"], ["1970.24000000", "23.52480000"], ["1970.22000000", "0.50680000"], ["1970.20000000", "2.50610000"], ["1970.19000000", "0.06630000"], ["1970.17000000", "0.00260000"], ["1970.14000000", "0.13810000"], ["1970.07000000", "0.00000000"], ["1970.06000000", "0.04550000"], ["1970.02000000", "0.56080000"], ["1970.01000000", "142.67630000"], ["1970.00000000", "409.86310000"], ["1969.91000000", "0.01610000"], ["1969.86000000", "6.19170000"], ["1969.85000000", "4.64670000"], ["1969.80000000", "3.04660000"], ["1969.67000000", "19.50780000"], ["1969.66000000", "0.00000000"], ["1969.64000000", "0.00000000"], ["1969.59000000", "0.21140000"], ["1969.46000000", "2.06930000"], ["1969.40000000", "0.00000000"], ["1969.39000000", "4.41220000"], ["1969.38000000", "0.00000000"], ["1969.30000000", "8.27790000"], ["1969.29000000", "22.57880000"], ["1969.25000000", "58.53850000"], ["1969.18000000", "14.94370000"], ["1969.17000000", "0.00000000"], ["1969.15000000", "0.79600000"], ["1969.14000000", "0.92400000"], ["1969.08000000", "0.00000000"], ["1969.06000000", "3.62790000"], ["1968.93000000", "22.57370000"], ["1968.89000000", "0.00000000"], ["1968.86000000", "0.67630000"], ["1968.61000000", "0.00000000"], ["1968.57000000", "22.58330000"], ["1968.45000000", "3.60000000"], ["1968.40000000", "0.02620000"], ["1968.26000000", "0.02300000"], ["1968.24000000", "66.03920000"], ["1968.21000000", "22.57720000"], ["1968.20000000", "0.00990000"], ["1968.11000000", "0.00580000"], ["1968.02000000", "0.00590000"], ["1967.97000000", "0.00260000"], ["1967.89000000", "0.50310000"], ["1967.82000000", "0.03020000"], ["1967.80000000", "0.00260000"], ["1967.79000000", "0.00270000"], ["1967.60000000", "0.00310000"], ["1967.18000000", "0.21480000"], ["1967.17000000", "0.89310000"], ["1967.09000000", "0.00000000"], ["1967.00000000", "48.13880000"], ["1966.98000000", "0.00000000"], ["1966.82000000", "0.35290000"], ["1966.29000000", "0.11380000"], ["1966.18000000", "60.88920000"], ["1965.89000000", "0.39020000"], ["1965.87000000", "0.00000000"], ["1965.85000000", "3.65460000"], ["1965.65000000", "4.10140000"], ["1965.45000000", "3.69640000"], ["1965.32000000", "2.50140000"], ["1964.75000000", "0.02930000"], ["1964.64000000", "0.00280000"], ["1964.52000000", "0.20270000"], ["1964.43000000", "0.06070000"], ["1964.32000000", "0.02490000"], ["1964.23000000", "4.00710000"], ["1964.16000000", "0.00000000"], ["1964.06000000", "0.49060000"], ["1963.91000000", "1.76930000"], ["1963.71000000", "6.69650000"], ["1963.44000000", "1.45990000"], ["1963.42000000", "1.93650000"], ["1963.09000000", "76.19210000"], ["1963.05000000", "0.21990000"], ["1962.67000000", "107.03910000"], ["1962.15000000", "1.20550000"], ["1962.14000000", "12.04210000"], ["1962.05000000", "236.55920000"], ["1961.82000000", "0.02000000"], ["1961.32000000", "0.00000000"], ["1960.80000000", "0.01490000"], ["1960.00000000", "403.69970000"], ["1957.74000000", "90.02460000"], ["1957.68000000", "0.00000000"], ["1957.14000000", "3.76780000"], ["1953.08000000", "0.00390000"], ["1949.05000000", "0.03920000"], ["1944.00000000", "5.54330000"], ["1942.38000000", "0.01550000"], ["1942.16000000", "0.00460000"], ["1934.19000000", "1.27900000"], ["1932.47000000", "0.00000000"], ["1932.25000000", "0.00360000"], ["1924.32000000", "0.77430000"], ["1923.20000000", "0.93400000"], ["1876.51000000", "0.00750000"], ["1876.24000000", "0.00330000"], ["1876.17000000", "0.00000000"], ["1876.16000000", "0.00000000"], ["1875.90000000", "0.00770000"], ["1875.77000000", "0.00000000"], ["1793.53000000", "0.00000000"], ["1776.31000000", "0.00860000"], ["1775.99000000", "0.00000000"], ["1775.57000000", "0.05570000"], ["1586.08000000", "0.00000000"], ["1583.52000000", "0.10500000"], ["1582.64000000", "0.03500000"], ["1581.14000000", "0.04900000"], ["1579.51000000", "0.00000000"], ["1579.35000000", "0.00000000"], ["1578.94000000", "0.00360000"], ["1578.93000000", "0.11200000"], ["1578.77000000", "0.00000000"], ["1578.68000000", "0.00000000"], ["1578.54000000", "0.00000000"], ["1578.50000000", "0.00700000"], ["1578.46000000", "0.02800000"], ["1578.38000000", "0.04900000"], ["1578.31000000", "0.02100000"], ["1578.28000000", "0.00700000"]], "a": [["1972.91000000", "0.00000000"], ["1972.93000000", "0.00000000"], ["1972.97000000", "0.00000000"], ["1972.98000000", "0.00000000"], ["1972.99000000", "0.00000000"], ["1973.00000000", "0.00000000"], ["1973.04000000", "0.00000000"], ["1973.06000000", "0.00000000"], ["1973.07000000", "0.00000000"], ["1973.10000000", "0.00000000"], ["1973.11000000", "0.00000000"], ["1973.12000000", "0.00000000"], ["1973.13000000", "0.00000000"], ["1973.15000000", "0.00000000"], ["1973.16000000", "0.00000000"], ["1973.19000000", "0.00000000"], ["1973.20000000", "4.35930000"], ["1973.23000000", "0.00260000"], ["1973.24000000", "0.00000000"], ["1973.25000000", "0.06240000"], ["1973.26000000", "0.00000000"], ["1973.27000000", "0.06240000"], ["1973.28000000", "0.08980000"], ["1973.29000000", "0.00000000"], ["1973.30000000", "0.00570000"], ["1973.31000000", "6.89580000"], ["1973.32000000", "9.59270000"], ["1973.33000000", "0.00000000"], ["1973.34000000", "0.00390000"], ["1973.35000000", "0.00000000"], ["1973.36000000", "0.09480000"], ["1973.37000000", "30.03150000"], ["1973.38000000", "0.00000000"], ["1973.39000000", "0.43560000"], ["1973.40000000", "0.00570000"], ["1973.42000000", "0.00000000"], ["1973.43000000", "7.09580000"], ["1973.44000000", "0.03000000"], ["1973.45000000", "1.18300000"], ["1973.46000000", "3.35440000"], ["1973.47000000", "0.00260000"], ["1973.48000000", "2.86230000"], ["1973.49000000", "0.01160000"], ["1973.50000000", "0.63970000"], ["1973.51000000", "0.04940000"], ["1973.52000000", "15.29270000"], ["1973.53000000", "4.68030000"], ["1973.54000000", "0.00390000"], ["1973.55000000", "7.09580000"], ["1973.57000000", "4.68030000"], ["1973.58000000", "21.42260000"], ["1973.59000000", "50.72530000"], ["1973.60000000", "0.03570000"], ["1973.61000000", "0.00000000"], ["1973.62000000", "0.00000000"], ["1973.63000000", "0.00000000"], ["1973.64000000", "53.20170000"], ["1973.65000000", "0.00260000"], ["1973.66000000", "0.00000000"], ["1973.67000000", "9.97140000"], ["1973.68000000", "0.67640000"], ["1973.69000000", "22.57370000"], ["1973.70000000", "0.48860000"], ["1973.71000000", "0.00000000"], ["1973.72000000", "0.00000000"], ["1973.73000000", "1.16840000"], ["1973.74000000", "9.97400000"], ["1973.75000000", "0.00000000"], ["1973.76000000", "0.65820000"], ["1973.77000000", "0.00000000"], ["1973.79000000", "0.00260000"], ["1973.80000000", "0.00570000"], ["1973.81000000", "18.48400000"], ["1973.82000000", "0.00000000"], ["1973.83000000", "0.00260000"], ["1973.85000000", "1.79950000"], ["1973.86000000", "0.00000000"], ["1973.87000000", "0.00000000"], ["1973.88000000", "0.00000000"], ["1973.89000000", "0.53910000"], ["1973.90000000", "0.00310000"], ["1973.92000000", "19.96100000"], ["1973.93000000", "23.77920000"], ["1973.94000000", "0.00390000"], ["1973.95000000", "0.03300000"], ["1973.97000000", "0.00000000"], ["1973.98000000", "0.00000000"], ["1973.99000000", "0.00000000"], ["1974.00000000", "1.10270000"], ["1974.01000000", "8.44430000"], ["1974.02000000", "0.00000000"], ["1974.03000000", "9.93710000"], ["1974.05000000", "0.00000000"], ["1974.10000000", "0.00310000"], ["1974.12000000", "0.00000000"], ["1974.13000000", "0.00260000"], ["1974.14000000", "0.00390000"], ["1974.15000000", "0.00000000"], ["1974.16000000", "0.03000000"], ["1974.17000000", "22.62090000"], ["1974.18000000", "0.00000000"], ["1974.19000000", "0.00000000"], ["1974.20000000", "1.91610000"], ["1974.21000000", "0.00000000"], ["1974.22000000", "0.00000000"], ["1974.24000000", "0.12520000"], ["1974.26000000", "0.00000000"], ["1974.30000000", "3.60310000"], ["1974.32000000", "0.00260000"], ["1974.33000000", "9.26100000"], ["1974.34000000", "0.00380000"], ["1974.35000000", "0.53650000"], ["1974.36000000", "0.00000000"], ["1974.37000000", "0.00000000"], ["1974.38000000", "0.03300000"], ["1974.39000000", "0.11280000"], ["1974.40000000", "0.00310000"], ["1974.45000000", "9.86480000"], ["1974.46000000", "16.53400000"], ["1974.47000000", "0.00000000"], ["1974.48000000", "8.51500000"], ["1974.49000000", "22.57370000"], ["1974.50000000", "0.20730000"], ["1974.52000000", "0.00000000"], ["1974.53000000", "0.00000000"], ["1974.55000000", "0.00260000"], ["1974.56000000", "0.00000000"], ["1974.60000000", "0.03610000"], ["1974.61000000", "8.51800000"], ["1974.62000000", "20.97130000"], ["1974.63000000", "0.00000000"], ["1974.64000000", "0.00260000"], ["1974.68000000", "0.00000000"], ["1974.71000000", "14.83250000"], ["1974.72000000", "0.00300000"], ["1974.75000000", "7.09580000"], ["1974.77000000", "0.00000000"], ["1974.78000000", "11.21580000"], ["1974.79000000", "0.00000000"], ["1974.80000000", "5.92830000"], ["1974.87000000", "0.00000000"], ["1974.88000000", "0.00000000"], ["1974.90000000", "22.57680000"], ["1974.91000000", "6.15040000"], ["1974.92000000", "0.48860000"], ["1974.96000000", "0.59680000"], ["1974.99000000", "8.57770000"], ["1975.02000000", "8.36830000"], ["1975.03000000", "0.97800000"], ["1975.04000000", "0.00000000"], ["1975.10000000", "9.35380000"], ["1975.11000000", "23.05970000"], ["1975.13000000", "0.00260000"], ["1975.14000000", "1.02760000"], ["1975.16000000", "0.00300000"], ["1975.17000000", "2.01810000"], ["1975.19000000", "0.17830000"], ["1975.20000000", "0.00310000"], ["1975.21000000", "0.00000000"], ["1975.25000000", "1.05480000"], ["1975.27000000", "0.23380000"], ["1975.30000000", "0.00310000"], ["1975.31000000", "5.73400000"], ["1975.34000000", "0.00760000"], ["1975.35000000", "1.45630000"], ["1975.38000000", "0.01910000"], ["1975.40000000", "3.62310000"], ["1975.41000000", "0.00000000"], ["1975.46000000", "0.03300000"], ["1975.50000000", "0.00310000"], ["1975.52000000", "0.48600000"], ["1975.55000000", "0.43820000"], ["1975.58000000", "66.31280000"], ["1975.59000000", "5.00000000"], ["1975.63000000", "3.69370000"], ["1975.69000000", "0.00260000"], ["1975.71000000", "0.00300000"], ["1975.77000000", "0.00000000"], ["1975.80000000", "14.82910000"], ["1975.87000000", "0.02000000"], ["1975.91000000", "0.00260000"], ["1975.96000000", "0.45900000"], ["1975.97000000", "0.00000000"], ["1975.99000000", "0.00000000"], ["1976.01000000", "0.00000000"], ["1976.03000000", "3.13150000"], ["1976.05000000", "0.37780000"], ["1976.10000000", "0.00000000"], ["1976.15000000", "0.00300000"], ["1976.20000000", "0.00310000"], ["1976.24000000", "0.00260000"], ["1976.27000000", "0.33580000"], ["1976.30000000", "0.56960000"], ["1976.31000000", "0.00000000"], ["1976.39000000", "0.00000000"], ["1976.40000000", "0.00310000"], ["1976.42000000", "0.00000000"], ["1976.53000000", "15.00000000"], ["1976.55000000", "0.51300000"], ["1976.61000000", "0.43200000"], ["1976.77000000", "1.20810000"], ["1976.83000000", "0.00000000"], ["1976.89000000", "0.00000000"], ["1976.94000000", "0.00380000"], ["1976.95000000", "3.60260000"], ["1977.01000000", "0.00000000"], ["1977.14000000", "0.00300000"], ["1977.19000000", "65.99610000"], ["1977.26000000", "0.00000000"], ["1977.30000000", "0.00000000"], ["1977.32000000", "3.60260000"], ["1977.34000000", "0.00000000"], ["1977.35000000", "0.02010000"], ["1977.36000000", "0.10010000"], ["1977.37000000", "0.00000000"], ["1977.39000000", "0.01020000"], ["1977.54000000", "0.79340000"], ["1977.74000000", "0.28240000"], ["1977.81000000", "0.00000000"], ["1977.99000000", "2.53310000"], ["1978.00000000", "0.00310000"], ["1978.09000000", "3.70760000"], ["1978.14000000", "0.02050000"], ["1978.27000000", "0.03550000"], ["1978.35000000", "0.07070000"], ["1978.38000000", "0.13120000"], ["1978.40000000", "0.02450000"], ["1978.55000000", "0.01030000"], ["1978.59000000", "0.00260000"], ["1978.67000000", "0.02000000"], ["1978.70000000", "0.00000000"], ["1978.95000000", "0.00000000"], ["1979.01000000", "1.20550000"], ["1979.05000000", "0.20020000"], ["1979.15000000", "0.00000000"], ["1979.23000000", "0.00000000"], ["1979.32000000", "0.13110000"], ["1979.33000000", "0.02010000"], ["1979.38000000", "0.00380000"], ["1979.44000000", "0.00000000"], ["1979.51000000", "0.00000000"], ["1979.57000000", "0.23350000"], ["1980.00000000", "8.28920000"], ["1980.08000000", "0.00000000"], ["1980.26000000", "60.88920000"], ["1980.27000000", "0.25090000"], ["1980.42000000", "0.00760000"], ["1980.43000000", "0.05620000"], ["1980.47000000", "126.39140000"], ["1980.48000000", "0.00000000"], ["1980.59000000", "0.00000000"], ["1980.64000000", "0.00000000"], ["1980.70000000", "0.00000000"], ["1980.77000000", "0.00000000"], ["1980.85000000", "0.16420000"], ["1980.87000000", "0.00750000"], ["1980.88000000", "0.14690000"], ["1980.91000000", "0.00260000"], ["1980.94000000", "0.00000000"], ["1981.11000000", "0.20770000"], ["1981.29000000", "3.82240000"], ["1981.30000000", "0.02010000"], ["1981.32000000", "0.00300000"], ["1981.52000000", "0.00780000"], ["1981.63000000", "0.00000000"], ["1981.98000000", "1.35000000"], ["1982.04000000", "0.01960000"], ["1982.16000000", "0.03610000"], ["1982.18000000", "0.00270000"], ["1982.30000000", "76.27170000"], ["1982.57000000", "0.00270000"], ["1982.74000000", "1.35800000"], ["1983.00000000", "0.00340000"], ["1983.10000000", "0.00000000"], ["1983.27000000", "0.02010000"], ["1983.30000000", "0.00300000"], ["1983.60000000", "0.00310000"], ["1983.86000000", "0.00000000"], ["1983.94000000", "0.00280000"], ["1984.22000000", "0.54250000"], ["1984.27000000", "0.04410000"], ["1984.31000000", "0.03480000"], ["1984.38000000", "0.00000000"], ["1984.39000000", "0.00000000"], ["1984.42000000", "113.37150000"], ["1984.77000000", "0.00000000"], ["1984.90000000", "0.01080000"], ["1984.98000000", "66.36820000"], ["1985.29000000", "0.03110000"], ["1985.34000000", "0.21840000"], ["1985.51000000", "0.01970000"], ["1985.60000000", "0.06320000"], ["1985.71000000", "0.00520000"], ["1985.78000000", "0.00000000"], ["1985.96000000", "0.00750000"], ["1986.00000000", "0.06170000"], ["1986.22000000", "0.00000000"], ["1986.42000000", "0.00790000"], ["1986.52000000", "0.01650000"], ["1986.58000000", "0.01480000"], ["1986.81000000", "0.00270000"], ["1987.24000000", "0.01680000"], ["1987.50000000", "0.21330000"], ["1987.76000000", "0.00000000"], ["1987.82000000", "0.00000000"], ["1987.87000000", "0.05370000"], ["1987.92000000", "0.00480000"], ["1988.02000000", "0.00000000"], ["1988.15000000", "0.00740000"], ["1988.25000000", "0.00490000"], ["1988.28000000", "0.01760000"], ["1988.50000000", "0.00700000"], ["1988.92000000", "0.96750000"], ["1988.94000000", "0.00000000"], ["1988.96000000", "0.00270000"], ["1989.07000000", "1.04260000"], ["1989.14000000", "0.00270000"], ["1989.30000000", "0.01550000"], ["1989.37000000", "0.00400000"], ["1989.57000000", "0.02280000"], ["1990.00000000", "6.31610000"], ["1990.62000000", "0.01940000"], ["1990.66000000", "0.02490000"], ["1991.66000000", "0.02830000"], ["1992.41000000", "0.02000000"], ["1992.64000000", "0.05660000"], ["1992.95000000", "0.00440000"], ["1993.68000000", "0.12910000"], ["1993.84000000", "0.07230000"], ["1993.89000000", "0.00280000"], ["1996.41000000", "0.01570000"], ["1997.78000000", "0.01460000"], ["1999.50000000", "0.00760000"], ["1999.51000000", "0.00000000"], ["2000.05000000", "0.02530000"], ["2002.21000000", "0.05370000"], ["2002.27000000", "12.29690000"], ["2002.64000000", "0.00860000"], ["2002.73000000", "0.02920000"], ["2002.91000000", "0.00000000"], ["2004.17000000", "0.00540000"], ["2006.31000000", "0.01650000"], ["2013.93000000", "0.03730000"], ["2014.00000000", "0.13300000"], ["2014.73000000", "0.00000000"], ["2019.20000000", "0.01460000"], ["2026.31000000", "0.04440000"], ["2036.66000000", "0.03970000"], ["2071.63000000", "0.17380000"], ["2072.03000000", "0.01300000"], ["2072.37000000", "0.00290000"], ["2073.70000000", "0.00270000"], ["2073.84000000", "0.02580000"], ["2090.03000000", "0.00380000"]], "_local_ts_utc": "2026-06-01T07:48:59.763801+00:00"}
{"e": "depthUpdate", "E": 1780300140941, "s": "ETHUSDT", "U": 76583079553, "u": 76583080597, "b": [["1973.15000000", "16.98400000"], ["1973.12000000", "0.00540000"], ["1973.11000000", "1.20060000"], ["1973.10000000", "0.00520000"], ["1973.00000000", "0.00800000"], ["1972.99000000", "0.84210000"], ["1972.98000000", "3.00000000"], ["1972.97000000", "0.00000000"], ["1972.96000000", "0.00000000"], ["1972.92000000", "0.00000000"], ["1972.91000000", "7.19090000"], ["1972.90000000", "12.67260000"], ["1972.88000000", "0.08030000"], ["1972.87000000", "0.03300000"], ["1972.86000000", "0.00390000"], ["1972.85000000", "0.95660000"], ["1972.84000000", "0.00260000"], ["1972.83000000", "0.00000000"], ["1972.82000000", "29.43890000"], ["1972.81000000", "11.77660000"], ["1972.80000000", "23.68470000"], ["1972.79000000", "6.14200000"], ["1972.78000000", "0.00000000"], ["1972.77000000", "0.62080000"], ["1972.76000000", "0.50550000"], ["1972.75000000", "0.96660000"], ["1972.74000000", "0.00300000"], ["1972.73000000", "0.00000000"], ["1972.72000000", "0.11460000"], ["1972.70000000", "0.95660000"], ["1972.67000000", "0.66530000"], ["1972.66000000", "0.62000000"], ["1972.63000000", "7.13020000"], ["1972.62000000", "22.72450000"], ["1972.61000000", "0.00260000"], ["1972.60000000", "1.69450000"], ["1972.59000000", "3.86580000"], ["1972.57000000", "22.57370000"], ["1972.56000000", "0.03000000"], ["1972.55000000", "2.25860000"], ["1972.54000000", "0.20410000"], ["1972.50000000", "7.46380000"], ["1972.49000000", "4.76870000"], ["1972.48000000", "13.55110000"], ["1972.47000000", "6.71530000"], ["1972.45000000", "0.02720000"], ["1972.43000000", "0.04410000"], ["1972.41000000", "22.81210000"], ["1972.40000000", "0.43570000"], ["1972.38000000", "0.05840000"], ["1972.35000000", "0.00000000"], ["1972.33000000", "22.58800000"], ["1972.32000000", "4.08340000"], ["1972.31000000", "13.56220000"], ["1972.30000000", "4.35840000"], ["1972.29000000", "7.10170000"], ["1972.28000000", "8.51830000"], ["1972.26000000", "0.01000000"], ["1972.24000000", "0.03000000"], ["1972.23000000", "14.19830000"], ["1972.22000000", "0.05080000"], ["1972.20000000", "0.00780000"], ["1972.17000000", "0.16110000"], ["1972.14000000", "8.78320000"], ["1972.13000000", "21.33140000"], ["1972.10000000", "8.52070000"], ["1972.09000000", "21.92250000"], ["1972.03000000", "14.80630000"], ["1972.01000000", "21.29650000"], ["1972.00000000", "34.38390000"], ["1971.98000000", "0.13160000"], ["1971.97000000", "0.00560000"], ["1971.94000000", "0.00000000"], ["1971.90000000", "5.95000000"], ["1971.89000000", "7.09580000"], ["1971.87000000", "0.04460000"], ["1971.86000000", "38.46150000"], ["1971.81000000", "7.09630000"], ["1971.80000000", "0.00310000"], ["1971.76000000", "4.05470000"], ["1971.75000000", "13.50930000"], ["1971.69000000", "15.37600000"], ["1971.68000000", "0.01350000"], ["1971.66000000", "39.75190000"], ["1971.65000000", "3.61520000"], ["1971.62000000", "8.10960000"], ["1971.61000000", "20.60210000"], ["1971.60000000", "0.03570000"], ["1971.59000000", "0.00000000"], ["1971.54000000", "0.12700000"], ["1971.52000000", "0.00260000"], ["1971.50000000", "1.00990000"], ["1971.47000000", "36.21440000"], ["1971.46000000", "1.30370000"], ["1971.45000000", "3.60000000"], ["1971.41000000", "7.09630000"], ["1971.33000000", "16.38170000"], ["1971.30000000", "26.94900000"], ["1971.29000000", "15.61540000"], ["1971.26000000", "0.92670000"], ["1971.20000000", "0.82200000"], ["1971.19000000", "0.01280000"], ["1971.16000000", "12.22700000"], ["1971.15000000", "26.75660000"], ["1971.12000000", "1.18650000"], ["1971.10000000", "9.01180000"], ["1971.09000000", "23.75840000"], ["1971.08000000", "8.30450000"], ["1971.06000000", "0.00390000"], ["1970.99000000", "0.11560000"], ["1970.98000000", "0.04040000"], ["1970.97000000", "0.54560000"], ["1970.95000000", "0.00000000"], ["1970.93000000", "7.87400000"], ["1970.92000000", "43.37640000"], ["1970.91000000", "0.00000000"], ["1970.89000000", "0.00390000"], ["1970.80000000", "0.00570000"], ["1970.78000000", "0.00460000"], ["1970.74000000", "13.50630000"], ["1970.72000000", "14.85540000"], ["1970.71000000", "0.03820000"], ["1970.70000000", "5.62170000"], ["1970.66000000", "0.15440000"], ["1970.64000000", "0.00000000"], ["1970.61000000", "7.35830000"], ["1970.60000000", "6.87020000"], ["1970.59000000", "0.00000000"], ["1970.49000000", "2.07930000"], ["1970.46000000", "13.50630000"], ["1970.40000000", "1.10560000"], ["1970.38000000", "0.00320000"], ["1970.37000000", "0.01350000"], ["1970.26000000", "13.51420000"], ["1970.20000000", "0.01090000"], ["1970.09000000", "0.50440000"], ["1970.02000000", "14.06710000"], ["1970.01000000", "142.52520000"], ["1969.86000000", "2.31340000"], ["1969.81000000", "0.00000000"], ["1969.50000000", "0.94130000"], ["1969.39000000", "0.00630000"], ["1969.30000000", "23.59610000"], ["1969.19000000", "0.03310000"], ["1969.18000000", "10.91210000"], ["1968.98000000", "70.63890000"], ["1968.94000000", "6.79990000"], ["1968.54000000", "0.00260000"], ["1968.39000000", "0.00000000"], ["1968.18000000", "0.00580000"], ["1968.13000000", "0.74860000"], ["1967.85000000", "26.17370000"], ["1967.79000000", "0.00000000"], ["1967.69000000", "0.01030000"], ["1967.60000000", "0.10310000"], ["1966.90000000", "1.33330000"], ["1966.66000000", "26.83600000"], ["1966.21000000", "0.01210000"], ["1965.57000000", "1.11020000"], ["1964.82000000", "0.01000000"], ["1964.06000000", "0.00000000"], ["1963.39000000", "3.06760000"], ["1962.15000000", "0.00000000"], ["1944.00000000", "5.54060000"], ["1874.51000000", "0.01160000"], ["1874.25000000", "0.00580000"], ["1775.86000000", "0.00000000"], ["1775.84000000", "0.00620000"], ["1775.57000000", "0.04950000"], ["1578.54000000", "0.02800000"], ["1578.52000000", "0.18130000"], ["1578.50000000", "0.00000000"], ["1578.38000000", "0.00000000"], ["1578.32000000", "0.02100000"], ["1578.31000000", "0.01400000"], ["1578.28000000", "0.06300000"]], "a": [["1973.16000000", "43.73010000"], ["1973.18000000", "0.00540000"], ["1973.19000000", "22.34300000"], ["1973.20000000", "23.55930000"], ["1973.21000000", "0.00000000"], ["1973.22000000", "0.00000000"], ["1973.23000000", "0.00000000"], ["1973.25000000", "0.00540000"], ["1973.26000000", "7.91280000"], ["1973.27000000", "2.18890000"], ["1973.28000000", "0.03260000"], ["1973.29000000", "0.00000000"], ["1973.30000000", "7.44940000"], ["1973.31000000", "0.04100000"], ["1973.32000000", "0.00260000"], ["1973.34000000", "0.00650000"], ["1973.36000000", "0.09740000"], ["1973.37000000", "0.00260000"], ["1973.38000000", "0.64900000"], ["1973.39000000", "0.05460000"], ["1973.40000000", "0.00870000"], ["1973.42000000", "7.09630000"], ["1973.43000000", "0.01020000"], ["1973.45000000", "0.00000000"], ["1973.46000000", "0.00000000"], ["1973.48000000", "0.00000000"], ["1973.49000000", "4.31760000"], ["1973.50000000", "0.00570000"], ["1973.51000000", "18.72630000"], ["1973.52000000", "0.07060000"], ["1973.53000000", "0.00000000"], ["1973.55000000", "0.00000000"], ["1973.56000000", "0.00260000"], ["1973.57000000", "0.00000000"], ["1973.58000000", "0.00000000"], ["1973.59000000", "0.73900000"], ["1973.60000000", "0.23570000"], ["1973.63000000", "22.57370000"], ["1973.64000000", "26.75660000"], ["1973.65000000", "0.00260000"], ["1973.66000000", "1.20550000"], ["1973.67000000", "0.08730000"], ["1973.68000000", "1.33000000"], ["1973.69000000", "0.00260000"], ["1973.70000000", "0.48860000"], ["1973.71000000", "0.00000000"], ["1973.73000000", "0.00000000"], ["1973.74000000", "0.03690000"], ["1973.75000000", "0.00000000"], ["1973.76000000", "0.03000000"], ["1973.77000000", "0.00760000"], ["1973.79000000", "0.00260000"], ["1973.80000000", "0.00570000"], ["1973.81000000", "0.00000000"], ["1973.85000000", "1.80710000"], ["1973.90000000", "0.00570000"], ["1973.91000000", "0.00000000"], ["1973.92000000", "0.03000000"], ["1973.93000000", "0.00000000"], ["1973.96000000", "22.57370000"], ["1973.97000000", "0.04840000"], ["1973.99000000", "0.00000000"], ["1974.00000000", "0.03570000"], ["1974.01000000", "0.00260000"], ["1974.03000000", "0.00000000"], ["1974.07000000", "15.14080000"], ["1974.10000000", "0.00570000"], ["1974.11000000", "0.00260000"], ["1974.12000000", "0.00000000"], ["1974.14000000", "0.08060000"], ["1974.15000000", "0.00000000"], ["1974.19000000", "0.01010000"], ["1974.20000000", "0.09680000"], ["1974.24000000", "0.15520000"], ["1974.29000000", "0.21530000"], ["1974.30000000", "3.61070000"], ["1974.32000000", "7.66290000"], ["1974.33000000", "21.29280000"], ["1974.37000000", "0.08560000"], ["1974.39000000", "0.01280000"], ["1974.40000000", "0.00310000"], ["1974.44000000", "22.26770000"], ["1974.45000000", "24.05740000"], ["1974.46000000", "0.00000000"], ["1974.48000000", "15.61130000"], ["1974.51000000", "0.00260000"], ["1974.56000000", "0.00000000"], ["1974.59000000", "2.56550000"], ["1974.60000000", "0.03610000"], ["1974.61000000", "15.61430000"], ["1974.62000000", "14.19210000"], ["1974.69000000", "13.55630000"], ["1974.71000000", "0.00000000"], ["1974.73000000", "0.76260000"], ["1974.74000000", "6.12790000"], ["1974.75000000", "14.19210000"], ["1974.76000000", "0.01020000"], ["1974.80000000", "15.51140000"], ["1974.81000000", "1.20550000"], ["1974.83000000", "2.58300000"], ["1974.89000000", "7.09630000"], ["1974.91000000", "0.00260000"], ["1974.93000000", "0.00000000"], ["1975.01000000", "0.00260000"], ["1975.05000000", "2.02800000"], ["1975.14000000", "0.99520000"], ["1975.17000000", "2.70870000"], ["1975.46000000", "0.03300000"], ["1975.57000000", "13.50630000"], ["1975.59000000", "0.00000000"], ["1975.60000000", "101.94800000"], ["1975.62000000", "0.00260000"], ["1975.63000000", "3.60260000"], ["1975.68000000", "0.03300000"], ["1975.77000000", "11.16930000"], ["1975.86000000", "0.00000000"], ["1975.87000000", "0.02000000"], ["1975.88000000", "31.67650000"], ["1975.97000000", "9.04000000"], ["1976.02000000", "2.24290000"], ["1976.13000000", "13.50630000"], ["1976.14000000", "0.00640000"], ["1976.15000000", "0.90780000"], ["1976.37000000", "31.66650000"], ["1976.40000000", "0.00310000"], ["1976.52000000", "0.00000000"], ["1976.53000000", "0.00000000"], ["1976.64000000", "7.55590000"], ["1976.79000000", "0.00000000"], ["1976.82000000", "0.00000000"], ["1976.99000000", "0.00000000"], ["1977.40000000", "0.22410000"], ["1977.69000000", "0.00000000"], ["1977.89000000", "126.55650000"], ["1978.00000000", "0.00580000"], ["1978.68000000", "0.00600000"], ["1978.69000000", "0.01000000"], ["1978.78000000", "0.00000000"], ["1978.82000000", "0.15370000"], ["1978.88000000", "0.00000000"], ["1978.92000000", "0.19620000"], ["1979.31000000", "0.38150000"], ["1979.34000000", "4.56970000"], ["1979.42000000", "0.15630000"], ["1979.46000000", "0.00000000"], ["1980.19000000", "0.00300000"], ["1980.25000000", "0.03000000"], ["1980.47000000", "0.00000000"], ["1980.73000000", "0.14760000"], ["1981.10000000", "127.35150000"], ["1981.15000000", "0.02070000"], ["1981.54000000", "0.47940000"], ["1981.98000000", "0.00300000"], ["1982.15000000", "0.00000000"], ["1982.18000000", "0.01330000"], ["1982.74000000", "1.25800000"], ["1982.97000000", "0.01040000"], ["1983.14000000", "0.00970000"], ["1983.50000000", "1.44220000"], ["1983.53000000", "0.10000000"], ["1983.90000000", "3.60550000"], ["1984.21000000", "0.00590000"], ["1984.79000000", "0.00290000"], ["1985.00000000", "4.24580000"], ["1985.28000000", "0.00430000"], ["1985.29000000", "0.03560000"], ["1985.64000000", "0.01320000"], ["1987.66000000", "0.00330000"], ["1988.23000000", "0.00890000"], ["1988.58000000", "3.09550000"], ["1989.50000000", "0.15580000"], ["1989.72000000", "0.00260000"], ["1990.04000000", "0.00460000"], ["1991.54000000", "0.01780000"], ["1991.59000000", "0.00470000"], ["1994.11000000", "0.75370000"], ["1994.88000000", "0.02710000"], ["1995.08000000", "0.00400000"], ["2001.65000000", "0.00000000"], ["2002.45000000", "0.10000000"], ["2010.00000000", "101.82680000"], ["2011.93000000", "0.03550000"]], "_local_ts_utc": "2026-06-01T07:48:59.838676+00:00"}
{"e": "depthUpdate", "E": 1780300141018, "s": "ETHUSDT", "U": 76583080598, "u": 76583081295, "b": [["1973.24000000", "46.99610000"], ["1973.20000000", "0.00260000"], ["1973.19000000", "0.00540000"], ["1973.18000000", "4.61520000"], ["1973.17000000", "26.15050000"], ["1973.16000000", "46.11580000"], ["1973.15000000", "5.23060000"], ["1973.14000000", "0.00260000"], ["1973.12000000", "0.00260000"], ["1973.11000000", "0.00260000"], ["1973.10000000", "0.00520000"], ["1973.09000000", "0.31180000"], ["1973.07000000", "0.05030000"], ["1973.00000000", "0.00520000"], ["1972.99000000", "0.83930000"], ["1972.98000000", "0.00000000"], ["1972.97000000", "0.00000000"], ["1972.93000000", "0.00000000"], ["1972.92000000", "10.20920000"], ["1972.91000000", "0.00000000"], ["1972.90000000", "0.96180000"], ["1972.88000000", "0.08030000"], ["1972.86000000", "0.25760000"], ["1972.85000000", "0.95400000"], ["1972.84000000", "0.00000000"], ["1972.83000000", "29.79980000"], ["1972.82000000", "10.11670000"], ["1972.81000000", "0.00000000"], ["1972.80000000", "22.35070000"], ["1972.79000000", "1.94530000"], ["1972.78000000", "0.00000000"], ["1972.77000000", "0.62360000"], ["1972.76000000", "0.00550000"], ["1972.72000000", "22.81920000"], ["1972.67000000", "0.00560000"], ["1972.65000000", "0.57660000"], ["1972.64000000", "7.90210000"], ["1972.63000000", "20.64490000"], ["1972.60000000", "5.81650000"], ["1972.58000000", "0.05030000"], ["1972.57000000", "0.00000000"], ["1972.54000000", "6.47170000"], ["1972.53000000", "22.57370000"], ["1972.51000000", "2.53670000"], ["1972.50000000", "18.02550000"], ["1972.49000000", "25.80360000"], ["1972.48000000", "0.04480000"], ["1972.47000000", "6.71530000"], ["1972.45000000", "0.02720000"], ["1972.40000000", "0.63570000"], ["1972.35000000", "12.91960000"], ["1972.34000000", "7.09630000"], ["1972.32000000", "0.03510000"], ["1972.30000000", "8.46700000"], ["1972.26000000", "0.21000000"], ["1972.20000000", "0.00830000"], ["1972.18000000", "0.85840000"], ["1972.15000000", "0.16130000"], ["1972.08000000", "0.14760000"], ["1972.03000000", "41.56030000"], ["1972.02000000", "0.27270000"], ["1971.97000000", "0.10560000"], ["1971.93000000", "4.44730000"], ["1971.90000000", "17.48440000"], ["1971.89000000", "7.09580000"], ["1971.73000000", "0.01170000"], ["1971.71000000", "1.14500000"], ["1971.69000000", "20.60240000"], ["1971.68000000", "0.04350000"], ["1971.60000000", "0.00570000"], ["1971.59000000", "0.52090000"], ["1971.54000000", "0.12700000"], ["1971.48000000", "13.89420000"], ["1971.46000000", "0.00390000"], ["1971.40000000", "9.63540000"], ["1971.30000000", "14.95840000"], ["1971.28000000", "0.09590000"], ["1971.24000000", "8.30010000"], ["1971.15000000", "0.00260000"], ["1971.03000000", "0.27000000"], ["1970.98000000", "0.00260000"], ["1970.93000000", "11.96070000"], ["1970.92000000", "27.76460000"], ["1970.89000000", "1.00030000"], ["1970.83000000", "0.09200000"], ["1970.75000000", "8.82210000"], ["1970.72000000", "7.75910000"], ["1970.70000000", "4.09850000"], ["1970.62000000", "2.80650000"], ["1970.61000000", "0.26200000"], ["1970.50000000", "10.74450000"], ["1970.49000000", "16.25940000"], ["1970.33000000", "4.57410000"], ["1970.32000000", "15.20520000"], ["1970.27000000", "12.47510000"], ["1970.25000000", "3.60380000"], ["1969.67000000", "0.00000000"], ["1969.66000000", "14.55390000"], ["1969.53000000", "0.71130000"], ["1969.46000000", "1.92010000"], ["1969.30000000", "24.65440000"], ["1969.18000000", "0.00000000"], ["1969.16000000", "0.52290000"], ["1969.06000000", "3.62790000"], ["1968.94000000", "0.01370000"], ["1968.82000000", "106.72430000"], ["1967.71000000", "0.00650000"], ["1967.62000000", "0.00260000"], ["1967.53000000", "0.02620000"], ["1967.44000000", "0.00520000"], ["1967.18000000", "4.18880000"], ["1965.67000000", "0.25650000"], ["1952.86000000", "1.57920000"], ["1775.84000000", "0.00000000"], ["1578.60000000", "0.00700000"], ["1578.52000000", "0.22330000"], ["1578.32000000", "0.01400000"], ["1192.00000000", "0.00000000"]], "a": [["1973.16000000", "0.00000000"], ["1973.17000000", "0.00000000"], ["1973.18000000", "0.00000000"], ["1973.19000000", "0.00000000"], ["1973.20000000", "0.00000000"], ["1973.25000000", "21.06690000"], ["1973.26000000", "7.56290000"], ["1973.27000000", "0.00260000"], ["1973.28000000", "0.03260000"], ["1973.29000000", "0.00000000"], ["1973.30000000", "0.00830000"], ["1973.31000000", "0.03560000"], ["1973.32000000", "0.00260000"], ["1973.34000000", "0.00390000"], ["1973.35000000", "0.00000000"], ["1973.36000000", "0.03760000"], ["1973.37000000", "0.00540000"], ["1973.39000000", "0.00000000"], ["1973.40000000", "5.72360000"], ["1973.41000000", "0.00000000"], ["1973.42000000", "0.00000000"], ["1973.49000000", "4.31760000"], ["1973.50000000", "5.74630000"], ["1973.51000000", "0.00260000"], ["1973.54000000", "0.00390000"], ["1973.58000000", "0.10140000"], ["1973.60000000", "0.03570000"], ["1973.62000000", "7.09520000"], ["1973.63000000", "10.91020000"], ["1973.66000000", "2.53670000"], ["1973.67000000", "0.16740000"], ["1973.68000000", "0.03000000"], ["1973.70000000", "0.36860000"], ["1973.74000000", "4.29010000"], ["1973.75000000", "8.49520000"], ["1973.76000000", "22.60370000"], ["1973.80000000", "0.00570000"], ["1973.84000000", "6.06620000"], ["1973.85000000", "18.84710000"], ["1973.89000000", "0.00260000"], ["1973.90000000", "23.57350000"], ["1973.91000000", "14.19260000"], ["1973.94000000", "13.51860000"], ["1973.96000000", "22.57650000"], ["1974.06000000", "6.64840000"], ["1974.07000000", "22.23710000"], ["1974.13000000", "10.49450000"], ["1974.14000000", "15.69240000"], ["1974.15000000", "7.09630000"], ["1974.17000000", "22.60930000"], ["1974.19000000", "0.95510000"], ["1974.20000000", "0.09940000"], ["1974.23000000", "6.42550000"], ["1974.24000000", "13.66150000"], ["1974.30000000", "12.71960000"], ["1974.31000000", "8.66660000"], ["1974.32000000", "0.03260000"], ["1974.42000000", "2.83710000"], ["1974.43000000", "23.03530000"], ["1974.44000000", "14.71180000"], ["1974.58000000", "0.94020000"], ["1974.61000000", "24.66480000"], ["1974.64000000", "0.00000000"], ["1974.68000000", "8.51550000"], ["1974.70000000", "22.57370000"], ["1974.74000000", "9.36330000"], ["1974.80000000", "5.92830000"], ["1974.85000000", "0.00260000"], ["1974.88000000", "17.37160000"], ["1974.90000000", "22.57370000"], ["1974.96000000", "0.59400000"], ["1974.97000000", "4.88720000"], ["1975.01000000", "9.54930000"], ["1975.05000000", "10.54220000"], ["1975.09000000", "7.09890000"], ["1975.10000000", "11.98850000"], ["1975.15000000", "0.77620000"], ["1975.16000000", "5.00300000"], ["1975.21000000", "7.09520000"], ["1975.26000000", "7.09780000"], ["1975.30000000", "7.09520000"], ["1975.31000000", "0.00260000"], ["1975.36000000", "21.67030000"], ["1975.38000000", "31.69830000"], ["1975.46000000", "14.23120000"], ["1975.50000000", "0.00000000"], ["1975.57000000", "63.73210000"], ["1975.70000000", "0.00000000"], ["1975.77000000", "0.00000000"], ["1975.86000000", "0.00000000"], ["1975.87000000", "15.02000000"], ["1975.97000000", "1.01960000"], ["1976.02000000", "0.00750000"], ["1976.12000000", "13.51470000"], ["1976.13000000", "0.00000000"], ["1976.28000000", "0.00000000"], ["1976.36000000", "0.00260000"], ["1976.64000000", "9.37810000"], ["1976.80000000", "0.00570000"], ["1976.91000000", "0.55770000"], ["1977.23000000", "0.00970000"], ["1977.80000000", "0.00000000"], ["1977.85000000", "0.00000000"], ["1977.89000000", "0.00000000"], ["1978.20000000", "0.00000000"], ["1978.33000000", "0.00610000"], ["1978.54000000", "0.00000000"], ["1978.60000000", "0.00000000"], ["1978.63000000", "0.00000000"], ["1978.70000000", "0.01030000"], ["1979.58000000", "0.00000000"], ["1979.85000000", "0.20240000"], ["1980.66000000", "6.77510000"], ["1981.08000000", "0.05670000"], ["1981.63000000", "0.00270000"], ["1982.05000000", "0.01380000"], ["1982.80000000", "0.01980000"], ["1983.07000000", "0.01340000"], ["1983.31000000", "0.00420000"], ["1983.46000000", "0.05280000"], ["1983.70000000", "0.00000000"], ["1984.35000000", "13.52010000"], ["1984.40000000", "0.04830000"], ["1985.00000000", "4.24840000"], ["1985.29000000", "0.04170000"], ["1985.71000000", "0.05450000"], ["1985.85000000", "0.00310000"], ["1986.42000000", "0.01090000"], ["1986.66000000", "0.05900000"], ["1986.92000000", "0.00750000"], ["1987.69000000", "0.01490000"], ["1987.73000000", "0.03360000"], ["1988.09000000", "0.00000000"], ["1988.21000000", "0.00260000"], ["1988.42000000", "0.00000000"], ["1988.64000000", "0.00000000"], ["1988.85000000", "0.00000000"], ["1989.07000000", "1.00990000"], ["1989.29000000", "0.00000000"], ["1989.43000000", "0.00460000"], ["1990.67000000", "0.01350000"], ["1991.17000000", "0.01500000"], ["1991.66000000", "0.03100000"], ["1993.73000000", "0.00000000"], ["1996.00000000", "1.70150000"], ["1998.20000000", "0.00440000"], ["1999.51000000", "0.01310000"], ["2001.40000000", "0.12230000"], ["2001.79000000", "0.08720000"], ["2009.93000000", "0.24710000"], ["2010.00000000", "101.84460000"], ["2010.55000000", "0.01200000"], ["2011.05000000", "0.02220000"], ["2020.00000000", "196.24210000"], ["2020.80000000", "0.00000000"], ["2036.13000000", "0.00000000"], ["2069.55000000", "0.00360000"], ["2111.96000000", "0.00660000"], ["2164.12000000", "0.00000000"], ["2226.90000000", "0.00440000"], ["2301.30000000", "0.00000000"], ["2388.51000000", "0.00000000"], ["2474.28000000", "0.06430000"], ["2489.95000000", "0.00000000"], ["2607.32000000", "0.00000000"], ["2742.70000000", "0.00000000"], ["2898.65000000", "0.00000000"], ["3078.46000000", "0.00000000"], ["3286.34000000", "0.09470000"]], "_local_ts_utc": "2026-06-01T07:48:59.915357+00:00"}
{"e": "depthUpdate", "E": 1780300141115, "s": "ETHUSDT", "U": 76583081296, "u": 76583082644, "b": [["1973.51000000", "74.35020000"], ["1973.50000000", "0.00260000"], ["1973.49000000", "0.00270000"], ["1973.48000000", "5.83560000"], ["1973.47000000", "0.41520000"], ["1973.46000000", "0.30510000"], ["1973.45000000", "0.00000000"], ["1973.44000000", "0.00540000"], ["1973.43000000", "5.22880000"], ["1973.42000000", "0.00000000"], ["1973.40000000", "0.00800000"], ["1973.39000000", "17.41420000"], ["1973.38000000", "0.00260000"], ["1973.37000000", "12.44450000"], ["1973.36000000", "0.00260000"], ["1973.35000000", "19.86950000"], ["1973.33000000", "0.00260000"], ["1973.32000000", "0.00000000"], ["1973.31000000", "10.07480000"], ["1973.30000000", "3.27680000"], ["1973.29000000", "0.00000000"], ["1973.28000000", "0.00000000"], ["1973.27000000", "0.00260000"], ["1973.26000000", "0.00000000"], ["1973.25000000", "10.20720000"], ["1973.24000000", "0.06800000"], ["1973.21000000", "0.00260000"], ["1973.20000000", "0.03260000"], ["1973.19000000", "0.25360000"], ["1973.18000000", "0.00000000"], ["1973.17000000", "15.60940000"], ["1973.16000000", "7.26890000"], ["1973.15000000", "19.34780000"], ["1973.14000000", "0.00260000"], ["1973.13000000", "0.01020000"], ["1973.12000000", "0.03000000"], ["1973.11000000", "0.00000000"], ["1973.10000000", "0.50950000"], ["1973.09000000", "0.34480000"], ["1973.06000000", "8.51420000"], ["1973.05000000", "14.19040000"], ["1973.04000000", "7.12520000"], ["1973.03000000", "0.61850000"], ["1973.02000000", "0.61330000"], ["1973.00000000", "0.00260000"], ["1972.99000000", "0.83670000"], ["1972.97000000", "0.05030000"], ["1972.96000000", "16.83480000"], ["1972.95000000", "31.08790000"], ["1972.94000000", "0.00000000"], ["1972.93000000", "34.80030000"], ["1972.92000000", "0.00000000"], ["1972.90000000", "0.00830000"], ["1972.86000000", "0.00390000"], ["1972.85000000", "27.75430000"], ["1972.84000000", "12.28750000"], ["1972.82000000", "0.00000000"], ["1972.80000000", "33.89770000"], ["1972.79000000", "3.61020000"], ["1972.77000000", "14.13830000"], ["1972.75000000", "0.01260000"], ["1972.73000000", "22.57370000"], ["1972.70000000", "6.60950000"], ["1972.68000000", "0.06620000"], ["1972.66000000", "0.00930000"], ["1972.64000000", "10.97470000"], ["1972.62000000", "22.86450000"], ["1972.60000000", "16.03940000"], ["1972.58000000", "4.43630000"], ["1972.55000000", "0.93630000"], ["1972.54000000", "0.00410000"], ["1972.53000000", "22.57370000"], ["1972.50000000", "18.02290000"], ["1972.49000000", "13.51470000"], ["1972.47000000", "6.61400000"], ["1972.46000000", "0.29130000"], ["1972.44000000", "0.38860000"], ["1972.43000000", "1.34410000"], ["1972.40000000", "0.63310000"], ["1972.30000000", "8.46440000"], ["1972.26000000", "0.01000000"], ["1972.18000000", "0.95840000"], ["1972.12000000", "0.00000000"], ["1972.03000000", "40.26030000"], ["1972.00000000", "34.35390000"], ["1971.97000000", "0.00560000"], ["1971.93000000", "0.06130000"], ["1971.92000000", "0.01170000"], ["1971.86000000", "38.19780000"], ["1971.84000000", "0.00000000"], ["1971.76000000", "4.05470000"], ["1971.68000000", "0.01350000"], ["1971.66000000", "24.14010000"], ["1971.47000000", "20.87260000"], ["1971.45000000", "3.87000000"], ["1971.41000000", "0.00000000"], ["1971.30000000", "0.76580000"], ["1971.29000000", "0.00460000"], ["1971.16000000", "4.53410000"], ["1971.09000000", "1.05030000"], ["1971.08000000", "1.20820000"], ["1971.06000000", "0.76390000"], ["1970.93000000", "0.01730000"], ["1970.92000000", "13.57200000"], ["1970.75000000", "4.80400000"], ["1970.72000000", "0.66280000"], ["1970.70000000", "1.29900000"], ["1970.62000000", "1.36510000"], ["1970.26000000", "0.00790000"], ["1970.02000000", "0.56080000"], ["1969.46000000", "1.16010000"], ["1968.91000000", "65.96930000"], ["1968.86000000", "0.68140000"], ["1968.39000000", "0.00000000"], ["1968.37000000", "0.00690000"], ["1968.36000000", "0.00000000"], ["1968.30000000", "0.09800000"], ["1968.24000000", "0.07600000"], ["1968.15000000", "0.00290000"], ["1967.85000000", "26.17370000"], ["1967.35000000", "0.00260000"], ["1967.26000000", "0.00260000"], ["1966.66000000", "63.58860000"], ["1965.95000000", "0.20980000"], ["1965.67000000", "0.24780000"], ["1965.45000000", "0.09640000"], ["1964.77000000", "0.48420000"], ["1964.47000000", "0.00000000"], ["1963.44000000", "1.45730000"], ["1957.59000000", "3.51250000"], ["1776.06000000", "0.00000000"], ["1775.92000000", "0.00000000"], ["1578.71000000", "0.00700000"], ["1578.60000000", "0.05600000"], ["1578.52000000", "0.21630000"], ["1578.32000000", "0.00000000"], ["1381.36000000", "0.02400000"]], "a": [["1973.25000000", "0.00000000"], ["1973.26000000", "0.00000000"], ["1973.27000000", "0.00000000"], ["1973.28000000", "0.00000000"], ["1973.30000000", "0.00000000"], ["1973.31000000", "0.00000000"], ["1973.32000000", "0.00000000"], ["1973.34000000", "0.00000000"], ["1973.36000000", "0.00000000"], ["1973.37000000", "0.00000000"], ["1973.38000000", "0.00000000"], ["1973.39000000", "0.00000000"], ["1973.40000000", "0.00000000"], ["1973.43000000", "0.00000000"], ["1973.44000000", "0.00000000"], ["1973.46000000", "0.00000000"], ["1973.47000000", "0.00000000"], ["1973.48000000", "0.00000000"], ["1973.49000000", "0.00000000"], ["1973.50000000", "0.00000000"], ["1973.51000000", "0.00000000"], ["1973.52000000", "0.16260000"], ["1973.53000000", "0.00000000"], ["1973.54000000", "1.95390000"], ["1973.55000000", "0.00000000"], ["1973.56000000", "0.00260000"], ["1973.58000000", "0.00260000"], ["1973.59000000", "0.00260000"], ["1973.60000000", "0.03830000"], ["1973.62000000", "1.30870000"], ["1973.63000000", "0.00260000"], ["1973.64000000", "0.00260000"], ["1973.65000000", "0.00520000"], ["1973.66000000", "0.00000000"], ["1973.67000000", "0.00000000"], ["1973.70000000", "0.00570000"], ["1973.71000000", "5.29810000"], ["1973.72000000", "0.00000000"], ["1973.73000000", "0.50670000"], ["1973.74000000", "0.03690000"], ["1973.75000000", "0.00000000"], ["1973.76000000", "0.03000000"], ["1973.78000000", "0.01020000"], ["1973.82000000", "0.00000000"], ["1973.84000000", "3.19030000"], ["1973.85000000", "1.80710000"], ["1973.90000000", "6.83020000"], ["1973.91000000", "0.00000000"], ["1973.93000000", "0.00000000"], ["1973.94000000", "0.00650000"], ["1973.95000000", "0.03300000"], ["1973.96000000", "22.77730000"], ["1974.01000000", "0.00260000"], ["1974.04000000", "0.00000000"], ["1974.05000000", "0.20000000"], ["1974.06000000", "0.00000000"], ["1974.07000000", "0.00260000"], ["1974.09000000", "0.64640000"], ["1974.12000000", "2.53630000"], ["1974.13000000", "10.49450000"], ["1974.14000000", "0.08060000"], ["1974.15000000", "0.00000000"], ["1974.16000000", "0.03000000"], ["1974.19000000", "0.94500000"], ["1974.23000000", "1.20550000"], ["1974.24000000", "0.15520000"], ["1974.25000000", "0.78300000"], ["1974.27000000", "0.81000000"], ["1974.30000000", "12.72220000"], ["1974.31000000", "0.00000000"], ["1974.33000000", "7.10020000"], ["1974.38000000", "13.54770000"], ["1974.40000000", "0.03570000"], ["1974.44000000", "1.20550000"], ["1974.45000000", "14.19260000"], ["1974.50000000", "0.20990000"], ["1974.52000000", "0.53120000"], ["1974.53000000", "0.37810000"], ["1974.55000000", "0.01010000"], ["1974.56000000", "0.03000000"], ["1974.58000000", "0.16360000"], ["1974.59000000", "1.16550000"], ["1974.60000000", "0.03610000"], ["1974.64000000", "0.03000000"], ["1974.66000000", "0.00000000"], ["1974.80000000", "4.77690000"], ["1974.82000000", "15.17740000"], ["1974.87000000", "21.13710000"], ["1974.88000000", "8.91420000"], ["1974.95000000", "0.80000000"], ["1975.02000000", "7.09580000"], ["1975.04000000", "8.51420000"], ["1975.05000000", "2.02800000"], ["1975.10000000", "11.02770000"], ["1975.14000000", "0.00380000"], ["1975.20000000", "6.74310000"], ["1975.27000000", "10.10090000"], ["1975.28000000", "8.51420000"], ["1975.34000000", "7.67910000"], ["1975.35000000", "8.55150000"], ["1975.36000000", "0.00000000"], ["1975.38000000", "0.01910000"], ["1975.45000000", "22.70460000"], ["1975.46000000", "7.13500000"], ["1975.56000000", "7.09780000"], ["1975.57000000", "67.91260000"], ["1975.58000000", "0.56700000"], ["1975.59000000", "7.09520000"], ["1975.65000000", "1.27200000"], ["1975.77000000", "22.85610000"], ["1975.86000000", "12.82280000"], ["1976.03000000", "0.00260000"], ["1976.05000000", "0.00000000"], ["1976.11000000", "13.56040000"], ["1976.12000000", "0.00000000"], ["1976.44000000", "13.51730000"], ["1976.55000000", "1.10870000"], ["1976.68000000", "0.86360000"], ["1976.77000000", "14.72280000"], ["1976.78000000", "0.00000000"], ["1976.80000000", "0.00310000"], ["1976.84000000", "65.72910000"], ["1976.91000000", "0.00000000"], ["1977.19000000", "0.03290000"], ["1977.29000000", "0.00000000"], ["1977.36000000", "0.00940000"], ["1977.86000000", "97.61140000"], ["1978.34000000", "8.72300000"], ["1978.48000000", "38.11240000"], ["1978.51000000", "0.00260000"], ["1978.62000000", "3.60260000"], ["1979.42000000", "0.00630000"], ["1980.43000000", "0.17690000"], ["1981.19000000", "126.34540000"], ["1981.54000000", "0.00000000"], ["1982.25000000", "1.37820000"], ["1986.48000000", "0.02040000"], ["1986.69000000", "0.00000000"], ["1986.91000000", "0.00000000"], ["1987.12000000", "0.00000000"], ["1987.34000000", "0.00000000"], ["1987.55000000", "0.00260000"], ["1987.77000000", "0.00000000"], ["1987.99000000", "0.00000000"], ["1995.14000000", "0.50100000"], ["2098.44000000", "1.04060000"]], "_local_ts_utc": "2026-06-01T07:49:00.012281+00:00"}
{"e": "depthUpdate", "E": 1780300141215, "s": "ETHUSDT", "U": 76583082645, "u": 76583083676, "b": [["1973.67000000", "41.01250000"], ["1973.66000000", "0.00780000"], ["1973.65000000", "0.00540000"], ["1973.64000000", "3.00000000"], ["1973.63000000", "0.00520000"], ["1973.62000000", "0.00260000"], ["1973.61000000", "0.04720000"], ["1973.60000000", "0.00800000"], ["1973.59000000", "2.07410000"], ["1973.58000000", "0.00260000"], ["1973.57000000", "0.31820000"], ["1973.56000000", "0.00260000"], ["1973.55000000", "0.00000000"], ["1973.54000000", "0.00000000"], ["1973.53000000", "0.00260000"], ["1973.52000000", "0.00540000"], ["1973.51000000", "0.98290000"], ["1973.50000000", "0.00520000"], ["1973.49000000", "0.00270000"], ["1973.48000000", "2.23300000"], ["1973.47000000", "0.00000000"], ["1973.46000000", "0.00000000"], ["1973.45000000", "0.01280000"], ["1973.44000000", "0.00000000"], ["1973.43000000", "5.17900000"], ["1973.40000000", "0.00560000"], ["1973.39000000", "13.23030000"], ["1973.38000000", "0.00000000"], ["1973.37000000", "20.95870000"], ["1973.36000000", "22.60370000"], ["1973.35000000", "30.45730000"], ["1973.33000000", "0.00000000"], ["1973.31000000", "0.00000000"], ["1973.30000000", "3.30980000"], ["1973.28000000", "7.12780000"], ["1973.27000000", "8.51420000"], ["1973.26000000", "0.00000000"], ["1973.25000000", "14.19040000"], ["1973.24000000", "0.00000000"], ["1973.21000000", "13.56730000"], ["1973.20000000", "0.03260000"], ["1973.16000000", "22.57370000"], ["1973.12000000", "1.36710000"], ["1973.11000000", "0.63820000"], ["1973.10000000", "0.00260000"], ["1973.09000000", "0.34740000"], ["1973.08000000", "4.38700000"], ["1973.07000000", "13.56500000"], ["1973.03000000", "0.00000000"], ["1973.00000000", "0.00570000"], ["1972.99000000", "7.54180000"], ["1972.96000000", "19.70270000"], ["1972.91000000", "0.05000000"], ["1972.90000000", "0.00830000"], ["1972.84000000", "12.43150000"], ["1972.83000000", "29.79980000"], ["1972.81000000", "0.10000000"], ["1972.80000000", "46.73240000"], ["1972.79000000", "31.56420000"], ["1972.78000000", "0.00260000"], ["1972.77000000", "14.33830000"], ["1972.74000000", "1.52500000"], ["1972.70000000", "0.00570000"], ["1972.69000000", "0.20000000"], ["1972.68000000", "0.01590000"], ["1972.65000000", "0.19850000"], ["1972.64000000", "15.00070000"], ["1972.61000000", "0.40260000"], ["1972.60000000", "15.93550000"], ["1972.58000000", "0.05030000"], ["1972.54000000", "0.80410000"], ["1972.53000000", "22.57630000"], ["1972.51000000", "0.00000000"], ["1972.50000000", "18.02290000"], ["1972.47000000", "0.01020000"], ["1972.43000000", "0.04410000"], ["1972.42000000", "0.01520000"], ["1972.40000000", "0.03310000"], ["1972.29000000", "7.20170000"], ["1972.18000000", "0.05840000"], ["1972.16000000", "0.00580000"], ["1972.08000000", "0.11760000"], ["1972.03000000", "13.50630000"], ["1971.99000000", "8.56530000"], ["1971.90000000", "12.73570000"], ["1971.86000000", "22.58600000"], ["1971.81000000", "7.09630000"], ["1971.79000000", "0.03300000"], ["1971.77000000", "0.33390000"], ["1971.70000000", "0.21170000"], ["1971.69000000", "10.59340000"], ["1971.61000000", "13.50630000"], ["1971.48000000", "14.18650000"], ["1971.47000000", "13.77630000"], ["1971.43000000", "31.74250000"], ["1971.42000000", "1.17190000"], ["1971.40000000", "5.39890000"], ["1971.28000000", "0.00880000"], ["1971.26000000", "0.71060000"], ["1971.10000000", "0.00000000"], ["1971.06000000", "4.51920000"], ["1970.94000000", "14.74610000"], ["1970.93000000", "31.76800000"], ["1970.75000000", "0.55720000"], ["1970.74000000", "0.00000000"], ["1970.62000000", "0.00260000"], ["1970.50000000", "14.82500000"], ["1970.46000000", "0.00000000"], ["1970.40000000", "32.86480000"], ["1970.27000000", "8.44340000"], ["1969.92000000", "9.65530000"], ["1969.91000000", "31.78310000"], ["1969.50000000", "0.25640000"], ["1969.22000000", "31.86110000"], ["1969.09000000", "7.99960000"], ["1968.59000000", "0.00000000"], ["1968.58000000", "0.00260000"], ["1968.51000000", "0.31260000"], ["1968.48000000", "0.00940000"], ["1968.38000000", "0.00990000"], ["1967.89000000", "0.50050000"], ["1967.80000000", "0.00000000"], ["1967.71000000", "0.00390000"], ["1967.62000000", "0.00000000"], ["1967.53000000", "0.02360000"], ["1967.44000000", "0.00260000"], ["1967.35000000", "0.00000000"], ["1967.26000000", "0.00000000"], ["1966.22000000", "0.12790000"], ["1965.95000000", "0.20160000"], ["1965.78000000", "128.33540000"], ["1965.65000000", "0.50140000"], ["1963.44000000", "0.08170000"], ["1952.86000000", "0.06800000"], ["1946.21000000", "0.00000000"], ["1944.37000000", "32.06960000"], ["1934.95000000", "0.02470000"], ["1776.31000000", "0.02100000"], ["1578.94000000", "0.01760000"], ["1578.91000000", "0.00700000"], ["1578.81000000", "0.00700000"], ["1578.54000000", "0.01400000"], ["1578.52000000", "0.20930000"]], "a": [["1973.52000000", "0.00000000"], ["1973.54000000", "0.00000000"], ["1973.56000000", "0.00000000"], ["1973.58000000", "0.00000000"], ["1973.59000000", "0.00000000"], ["1973.60000000", "0.00000000"], ["1973.61000000", "0.00000000"], ["1973.62000000", "0.00000000"], ["1973.63000000", "0.00000000"], ["1973.64000000", "0.00000000"], ["1973.65000000", "0.00000000"], ["1973.66000000", "0.00000000"], ["1973.68000000", "24.35910000"], ["1973.69000000", "0.00260000"], ["1973.70000000", "0.00830000"], ["1973.71000000", "0.00260000"], ["1973.72000000", "0.00000000"], ["1973.73000000", "0.00260000"], ["1973.74000000", "0.03950000"], ["1973.75000000", "0.00000000"], ["1973.76000000", "0.03260000"], ["1973.77000000", "0.64580000"], ["1973.78000000", "0.01280000"], ["1973.79000000", "0.00520000"], ["1973.82000000", "0.05000000"], ["1973.83000000", "0.00260000"], ["1973.84000000", "2.44680000"], ["1973.85000000", "8.27470000"], ["1973.87000000", "0.01160000"], ["1973.90000000", "0.00570000"], ["1973.92000000", "0.03260000"], ["1973.93000000", "0.00000000"], ["1973.96000000", "0.20360000"], ["1974.02000000", "0.00000000"], ["1974.04000000", "0.45000000"], ["1974.05000000", "0.00000000"], ["1974.07000000", "0.00260000"], ["1974.09000000", "0.64640000"], ["1974.11000000", "0.00260000"], ["1974.12000000", "0.05000000"], ["1974.13000000", "0.00260000"], ["1974.16000000", "7.09060000"], ["1974.19000000", "0.99550000"], ["1974.20000000", "0.00830000"], ["1974.23000000", "0.00000000"], ["1974.24000000", "0.03260000"], ["1974.26000000", "8.64820000"], ["1974.27000000", "10.75370000"], ["1974.28000000", "0.00000000"], ["1974.29000000", "22.70460000"], ["1974.30000000", "0.01330000"], ["1974.32000000", "0.03260000"], ["1974.33000000", "0.00390000"], ["1974.37000000", "0.00000000"], ["1974.38000000", "0.03300000"], ["1974.41000000", "19.78680000"], ["1974.42000000", "17.02750000"], ["1974.43000000", "26.75660000"], ["1974.44000000", "16.81490000"], ["1974.45000000", "0.00000000"], ["1974.47000000", "13.51470000"], ["1974.48000000", "0.00000000"], ["1974.52000000", "2.61150000"], ["1974.57000000", "0.09110000"], ["1974.60000000", "7.13390000"], ["1974.62000000", "7.09580000"], ["1974.67000000", "0.15370000"], ["1974.69000000", "13.50630000"], ["1974.72000000", "0.03300000"], ["1974.73000000", "1.16260000"], ["1974.74000000", "6.67440000"], ["1974.78000000", "14.90280000"], ["1974.80000000", "4.57690000"], ["1974.81000000", "23.96640000"], ["1974.83000000", "0.00300000"], ["1974.87000000", "7.09520000"], ["1974.88000000", "9.54420000"], ["1974.95000000", "0.00000000"], ["1974.96000000", "0.62400000"], ["1974.99000000", "7.55480000"], ["1975.04000000", "8.51420000"], ["1975.16000000", "0.00300000"], ["1975.18000000", "4.16700000"], ["1975.20000000", "11.36820000"], ["1975.29000000", "0.00000000"], ["1975.39000000", "1.01420000"], ["1975.40000000", "5.00420000"], ["1975.44000000", "13.89440000"], ["1975.46000000", "0.03300000"], ["1975.57000000", "48.40030000"], ["1975.62000000", "3.86170000"], ["1975.69000000", "0.00260000"], ["1975.75000000", "18.56360000"], ["1975.76000000", "21.87960000"], ["1975.77000000", "0.00000000"], ["1975.85000000", "11.63200000"], ["1975.86000000", "31.67160000"], ["1975.88000000", "0.00520000"], ["1975.89000000", "1.05560000"], ["1975.96000000", "13.31520000"], ["1975.97000000", "7.09520000"], ["1975.99000000", "0.96050000"], ["1976.27000000", "0.00000000"], ["1976.28000000", "7.07750000"], ["1976.36000000", "9.45600000"], ["1976.40000000", "0.00310000"], ["1976.63000000", "0.00000000"], ["1976.64000000", "0.00000000"], ["1976.76000000", "13.54760000"], ["1976.77000000", "1.20810000"], ["1976.78000000", "0.00260000"], ["1976.91000000", "0.33570000"], ["1977.01000000", "22.57370000"], ["1977.09000000", "0.13130000"], ["1977.10000000", "0.00000000"], ["1977.85000000", "9.37810000"], ["1978.00000000", "0.15580000"], ["1978.61000000", "126.51070000"], ["1978.67000000", "0.02260000"], ["1978.74000000", "0.01530000"], ["1980.80000000", "1.20860000"], ["1981.10000000", "1.00000000"], ["1981.79000000", "0.47710000"], ["1982.25000000", "0.00000000"], ["1982.30000000", "0.16030000"], ["1982.35000000", "0.00000000"], ["1982.43000000", "1.35450000"], ["1986.04000000", "0.00530000"], ["1986.26000000", "0.00000000"], ["1988.58000000", "0.00000000"]], "_local_ts_utc": "2026-06-01T07:49:00.112281+00:00"}
{"e": "depthUpdate", "E": 1780300141315, "s": "ETHUSDT", "U": 76583083677, "u": 76583084500, "b": [["1973.78000000", "68.48490000"], ["1973.77000000", "38.29150000"], ["1973.76000000", "6.27830000"], ["1973.75000000", "0.00000000"], ["1973.73000000", "0.00540000"], ["1973.72000000", "22.64380000"], ["1973.71000000", "0.00000000"], ["1973.70000000", "0.00260000"], ["1973.69000000", "0.00000000"], ["1973.68000000", "0.00540000"], ["1973.67000000", "4.48350000"], ["1973.66000000", "0.00260000"], ["1973.65000000", "0.00260000"], ["1973.64000000", "0.00260000"], ["1973.62000000", "0.00260000"], ["1973.61000000", "0.00000000"], ["1973.60000000", "8.77040000"], ["1973.59000000", "0.00000000"], ["1973.58000000", "0.00000000"], ["1973.57000000", "0.00000000"], ["1973.56000000", "0.00000000"], ["1973.55000000", "6.35450000"], ["1973.54000000", "14.19300000"], ["1973.53000000", "7.09520000"], ["1973.52000000", "0.03000000"], ["1973.51000000", "0.00000000"], ["1973.50000000", "1.31160000"], ["1973.49000000", "8.51420000"], ["1973.48000000", "1.00000000"], ["1973.46000000", "0.00390000"], ["1973.45000000", "0.01280000"], ["1973.44000000", "15.86100000"], ["1973.43000000", "6.46760000"], ["1973.40000000", "35.96650000"], ["1973.39000000", "0.00000000"], ["1973.38000000", "38.18310000"], ["1973.37000000", "0.64200000"], ["1973.36000000", "0.03000000"], ["1973.35000000", "1.00000000"], ["1973.34000000", "0.61070000"], ["1973.33000000", "0.50680000"], ["1973.30000000", "10.40500000"], ["1973.29000000", "7.09520000"], ["1973.28000000", "19.38370000"], ["1973.27000000", "0.00000000"], ["1973.26000000", "0.00390000"], ["1973.25000000", "0.00000000"], ["1973.22000000", "13.51470000"], ["1973.21000000", "7.14780000"], ["1973.20000000", "7.13090000"], ["1973.19000000", "8.48270000"], ["1973.18000000", "15.76050000"], ["1973.17000000", "0.00000000"], ["1973.15000000", "5.15740000"], ["1973.12000000", "0.03000000"], ["1973.11000000", "0.00000000"], ["1973.10000000", "0.00570000"], ["1973.09000000", "14.79620000"], ["1973.08000000", "17.90170000"], ["1973.07000000", "3.65030000"], ["1973.06000000", "8.51810000"], ["1973.04000000", "7.39520000"], ["1973.03000000", "0.27000000"], ["1973.02000000", "0.00260000"], ["1972.99000000", "7.44050000"], ["1972.97000000", "0.32030000"], ["1972.90000000", "0.20830000"], ["1972.84000000", "13.03150000"], ["1972.81000000", "0.00000000"], ["1972.79000000", "30.36420000"], ["1972.78000000", "0.00000000"], ["1972.77000000", "14.13830000"], ["1972.76000000", "0.40550000"], ["1972.74000000", "1.52500000"], ["1972.71000000", "0.00260000"], ["1972.70000000", "1.20860000"], ["1972.69000000", "0.00000000"], ["1972.64000000", "15.90070000"], ["1972.61000000", "0.00260000"], ["1972.57000000", "0.10000000"], ["1972.55000000", "1.20630000"], ["1972.54000000", "0.80410000"], ["1972.44000000", "0.38860000"], ["1972.36000000", "0.11530000"], ["1972.32000000", "0.00510000"], ["1972.29000000", "7.10170000"], ["1972.26000000", "0.01000000"], ["1972.24000000", "0.00000000"], ["1972.16000000", "0.00580000"], ["1972.10000000", "0.00570000"], ["1972.05000000", "3.88930000"], ["1972.04000000", "0.27000000"], ["1972.01000000", "14.20020000"], ["1972.00000000", "31.56610000"], ["1971.99000000", "0.00000000"], ["1971.98000000", "0.40160000"], ["1971.89000000", "0.00000000"], ["1971.82000000", "0.00260000"], ["1971.79000000", "0.03300000"], ["1971.70000000", "0.21170000"], ["1971.63000000", "0.01370000"], ["1971.56000000", "0.27410000"], ["1971.50000000", "1.00990000"], ["1971.49000000", "0.00000000"], ["1971.29000000", "0.00460000"], ["1970.95000000", "0.00000000"], ["1970.94000000", "9.50520000"], ["1970.92000000", "0.06570000"], ["1970.81000000", "5.13400000"], ["1970.62000000", "0.82090000"], ["1970.23000000", "0.69410000"], ["1969.53000000", "0.13180000"], ["1968.76000000", "0.04920000"], ["1968.72000000", "0.00910000"], ["1968.67000000", "0.00260000"], ["1968.63000000", "0.00000000"], ["1968.48000000", "0.00940000"], ["1964.77000000", "0.00500000"], ["1964.36000000", "0.49850000"], ["1964.07000000", "1.50700000"], ["1963.43000000", "0.50930000"], ["1963.19000000", "0.03560000"], ["1962.74000000", "0.00000000"], ["1956.85000000", "0.07420000"], ["1776.31000000", "0.00860000"], ["1578.94000000", "0.04560000"], ["1578.54000000", "0.00000000"], ["1578.52000000", "0.19530000"]], "a": [["1973.68000000", "0.00000000"], ["1973.69000000", "0.00000000"], ["1973.70000000", "0.00000000"], ["1973.71000000", "0.00000000"], ["1973.73000000", "0.00000000"], ["1973.74000000", "0.00000000"], ["1973.76000000", "0.00000000"], ["1973.77000000", "0.00000000"], ["1973.78000000", "0.00000000"], ["1973.79000000", "1.42190000"], ["1973.80000000", "0.55480000"], ["1973.82000000", "0.05260000"], ["1973.83000000", "0.01060000"], ["1973.84000000", "0.58980000"], ["1973.85000000", "1.80210000"], ["1973.87000000", "0.01420000"], ["1973.89000000", "0.00260000"], ["1973.90000000", "0.00830000"], ["1973.92000000", "0.03260000"], ["1973.94000000", "0.00390000"], ["1973.95000000", "0.03600000"], ["1973.96000000", "0.71020000"], ["1973.97000000", "0.00000000"], ["1974.01000000", "0.01280000"], ["1974.03000000", "0.00000000"], ["1974.04000000", "0.00000000"], ["1974.05000000", "0.00000000"], ["1974.09000000", "0.00000000"], ["1974.11000000", "0.00260000"], ["1974.14000000", "4.37160000"], ["1974.15000000", "0.00000000"], ["1974.16000000", "0.03000000"], ["1974.17000000", "0.03560000"], ["1974.23000000", "0.00000000"], ["1974.24000000", "13.78680000"], ["1974.25000000", "23.35670000"], ["1974.26000000", "1.30000000"], ["1974.27000000", "11.54770000"], ["1974.28000000", "1.08000000"], ["1974.29000000", "0.00000000"], ["1974.34000000", "0.51680000"], ["1974.42000000", "25.54170000"], ["1974.44000000", "8.30070000"], ["1974.47000000", "0.00000000"], ["1974.48000000", "0.00000000"], ["1974.67000000", "0.00260000"], ["1974.70000000", "22.57630000"], ["1974.73000000", "0.76260000"], ["1974.74000000", "9.20800000"], ["1974.88000000", "8.54420000"], ["1974.95000000", "1.40000000"], ["1975.01000000", "13.78210000"], ["1975.20000000", "11.39820000"], ["1975.39000000", "0.00000000"], ["1975.51000000", "0.00260000"], ["1975.55000000", "5.17380000"], ["1975.57000000", "25.60150000"], ["1975.60000000", "1.10480000"], ["1975.62000000", "1.51340000"], ["1975.69000000", "8.51680000"], ["1975.73000000", "18.04810000"], ["1975.74000000", "22.45300000"], ["1975.75000000", "0.86400000"], ["1975.76000000", "0.59400000"], ["1975.85000000", "1.20550000"], ["1975.86000000", "0.00000000"], ["1975.87000000", "0.02000000"], ["1975.95000000", "21.28560000"], ["1975.96000000", "0.45900000"], ["1975.97000000", "0.00000000"], ["1976.24000000", "0.59660000"], ["1976.43000000", "3.59280000"], ["1976.48000000", "1.02240000"], ["1976.50000000", "15.00260000"], ["1976.64000000", "8.11740000"], ["1976.75000000", "13.52490000"], ["1976.76000000", "0.03290000"], ["1976.78000000", "0.00000000"], ["1976.83000000", "6.91780000"], ["1976.88000000", "0.00000000"], ["1976.89000000", "100.86720000"], ["1977.08000000", "13.51470000"], ["1978.76000000", "0.98280000"], ["1978.85000000", "0.00260000"], ["1979.15000000", "0.02020000"], ["1979.40000000", "0.16050000"], ["1980.80000000", "1.35970000"], ["1981.69000000", "126.31410000"], ["1981.79000000", "0.00000000"], ["1982.15000000", "0.00000000"], ["1982.34000000", "0.00000000"], ["1982.43000000", "0.01000000"], ["1982.93000000", "0.03540000"], ["1983.64000000", "0.00260000"], ["1984.62000000", "0.00260000"], ["1988.72000000", "0.00000000"], ["1988.82000000", "0.00000000"], ["1992.88000000", "0.00000000"], ["2001.45000000", "0.00670000"], ["2107.09000000", "0.01250000"]], "_local_ts_utc": "2026-06-01T07:49:00.211467+00:00"}
{"e": "depthUpdate", "E": 1780300141415, "s": "ETHUSDT", "U": 76583084501, "u": 76583085519, "b": [["1973.91000000", "20.58680000"], ["1973.90000000", "0.01290000"], ["1973.89000000", "0.00510000"], ["1973.88000000", "0.00000000"], ["1973.87000000", "0.00000000"], ["1973.86000000", "0.00000000"], ["1973.85000000", "0.00540000"], ["1973.84000000", "3.00260000"], ["1973.83000000", "0.00260000"], ["1973.82000000", "0.00260000"], ["1973.81000000", "0.00000000"], ["1973.80000000", "0.00260000"], ["1973.79000000", "0.00260000"], ["1973.78000000", "0.01820000"], ["1973.77000000", "0.00260000"], ["1973.76000000", "0.00260000"], ["1973.73000000", "0.00260000"], ["1973.72000000", "0.00260000"], ["1973.69000000", "0.00260000"], ["1973.68000000", "0.03540000"], ["1973.67000000", "3.48090000"], ["1973.66000000", "0.01300000"], ["1973.65000000", "0.00000000"], ["1973.64000000", "0.61070000"], ["1973.63000000", "0.00260000"], ["1973.62000000", "0.00260000"], ["1973.60000000", "0.03260000"], ["1973.59000000", "0.00000000"], ["1973.58000000", "0.00000000"], ["1973.57000000", "8.51420000"], ["1973.56000000", "0.00000000"], ["1973.55000000", "20.60990000"], ["1973.54000000", "7.09780000"], ["1973.53000000", "0.00000000"], ["1973.52000000", "0.06300000"], ["1973.51000000", "7.09520000"], ["1973.50000000", "0.00260000"], ["1973.49000000", "0.00000000"], ["1973.48000000", "0.00000000"], ["1973.45000000", "8.52700000"], ["1973.44000000", "11.39060000"], ["1973.43000000", "7.09520000"], ["1973.41000000", "20.60990000"], ["1973.40000000", "1.45710000"], ["1973.38000000", "0.00000000"], ["1973.37000000", "0.00260000"], ["1973.36000000", "22.60370000"], ["1973.35000000", "9.51420000"], ["1973.34000000", "7.09520000"], ["1973.33000000", "7.60200000"], ["1973.31000000", "7.09520000"], ["1973.30000000", "3.31290000"], ["1973.29000000", "0.00000000"], ["1973.28000000", "6.80200000"], ["1973.26000000", "0.00390000"], ["1973.25000000", "8.51420000"], ["1973.24000000", "7.09520000"], ["1973.23000000", "0.10140000"], ["1973.22000000", "20.11100000"], ["1973.21000000", "0.32260000"], ["1973.20000000", "0.03570000"], ["1973.19000000", "15.57790000"], ["1973.18000000", "0.00000000"], ["1973.17000000", "0.15110000"], ["1973.16000000", "22.70370000"], ["1973.15000000", "12.25260000"], ["1973.14000000", "7.09780000"], ["1973.13000000", "8.52440000"], ["1973.09000000", "7.44260000"], ["1973.08000000", "4.38700000"], ["1973.06000000", "0.00390000"], ["1973.05000000", "7.09520000"], ["1973.04000000", "0.30000000"], ["1973.02000000", "8.51680000"], ["1972.99000000", "0.83670000"], ["1972.98000000", "0.00000000"], ["1972.97000000", "14.80900000"], ["1972.96000000", "0.03260000"], ["1972.95000000", "22.57370000"], ["1972.94000000", "7.09520000"], ["1972.93000000", "13.51470000"], ["1972.91000000", "0.05000000"], ["1972.90000000", "0.20570000"], ["1972.89000000", "7.09520000"], ["1972.88000000", "0.78030000"], ["1972.86000000", "7.09910000"], ["1972.85000000", "20.46930000"], ["1972.84000000", "12.43150000"], ["1972.83000000", "0.40000000"], ["1972.82000000", "8.51420000"], ["1972.81000000", "7.09780000"], ["1972.80000000", "33.89510000"], ["1972.77000000", "0.62360000"], ["1972.76000000", "0.00550000"], ["1972.72000000", "0.11460000"], ["1972.70000000", "0.00310000"], ["1972.69000000", "7.14550000"], ["1972.66000000", "7.10450000"], ["1972.65000000", "21.60840000"], ["1972.64000000", "8.89510000"], ["1972.63000000", "0.03390000"], ["1972.62000000", "0.15640000"], ["1972.61000000", "0.80260000"], ["1972.60000000", "10.79980000"], ["1972.57000000", "0.00000000"], ["1972.56000000", "0.00000000"], ["1972.54000000", "0.00410000"], ["1972.52000000", "8.51990000"], ["1972.51000000", "7.09520000"], ["1972.50000000", "0.36800000"], ["1972.49000000", "0.00000000"], ["1972.48000000", "0.01480000"], ["1972.46000000", "7.38650000"], ["1972.45000000", "7.12240000"], ["1972.41000000", "0.10400000"], ["1972.40000000", "0.00310000"], ["1972.37000000", "13.51980000"], ["1972.36000000", "7.21050000"], ["1972.35000000", "9.40650000"], ["1972.34000000", "0.00000000"], ["1972.32000000", "15.64450000"], ["1972.31000000", "0.05590000"], ["1972.30000000", "4.35890000"], ["1972.29000000", "0.00540000"], ["1972.28000000", "0.00280000"], ["1972.26000000", "7.10520000"], ["1972.25000000", "7.30630000"], ["1972.23000000", "0.00570000"], ["1972.22000000", "0.32080000"], ["1972.21000000", "8.55630000"], ["1972.14000000", "9.24680000"], ["1972.13000000", "7.13980000"], ["1972.10000000", "13.52040000"], ["1972.09000000", "14.57550000"], ["1972.03000000", "7.09520000"], ["1972.01000000", "15.61810000"], ["1971.94000000", "7.09520000"], ["1971.90000000", "12.75770000"], ["1971.84000000", "0.00260000"], ["1971.83000000", "7.10540000"], ["1971.82000000", "13.51730000"], ["1971.81000000", "7.09520000"], ["1971.76000000", "1.28950000"], ["1971.75000000", "0.00300000"], ["1971.74000000", "7.11220000"], ["1971.63000000", "7.10890000"], ["1971.62000000", "1.08980000"], ["1971.61000000", "0.00000000"], ["1971.59000000", "2.65280000"], ["1971.54000000", "0.12700000"], ["1971.44000000", "0.00000000"], ["1971.34000000", "0.00390000"], ["1971.31000000", "0.26860000"], ["1971.25000000", "3.61140000"], ["1971.24000000", "8.53110000"], ["1971.16000000", "0.00510000"], ["1971.14000000", "0.03960000"], ["1971.13000000", "0.02050000"], ["1971.06000000", "6.15700000"], ["1971.05000000", "17.31570000"], ["1971.04000000", "0.02500000"], ["1970.95000000", "0.00000000"], ["1970.83000000", "0.01640000"], ["1970.81000000", "2.29710000"], ["1970.77000000", "13.52530000"], ["1970.65000000", "3.67870000"], ["1970.51000000", "13.52990000"], ["1970.50000000", "15.60380000"], ["1970.49000000", "16.03320000"], ["1970.33000000", "4.57410000"], ["1970.25000000", "17.11850000"], ["1970.02000000", "0.56080000"], ["1969.74000000", "0.52710000"], ["1969.54000000", "0.50260000"], ["1969.46000000", "0.01170000"], ["1968.95000000", "0.50260000"], ["1968.78000000", "0.01680000"], ["1968.75000000", "0.56270000"], ["1968.72000000", "0.00910000"], ["1968.36000000", "0.50000000"], ["1968.24000000", "0.00000000"], ["1968.18000000", "0.00320000"], ["1968.11000000", "0.00320000"], ["1968.02000000", "0.00330000"], ["1968.01000000", "0.00000000"], ["1967.97000000", "0.00000000"], ["1967.68000000", "0.61440000"], ["1966.82000000", "0.35030000"], ["1966.29000000", "0.12370000"], ["1966.22000000", "0.11800000"], ["1965.85000000", "0.05460000"], ["1964.65000000", "6.79610000"], ["1963.71000000", "0.00000000"], ["1963.09000000", "0.08070000"], ["1962.74000000", "1.20550000"], ["1961.76000000", "0.18590000"], ["1776.52000000", "0.01240000"], ["1579.13000000", "0.05210000"], ["1578.52000000", "0.15330000"]], "a": [["1973.79000000", "0.00000000"], ["1973.80000000", "0.00000000"], ["1973.82000000", "0.00000000"], ["1973.83000000", "0.00000000"], ["1973.84000000", "0.00000000"], ["1973.85000000", "0.00000000"], ["1973.87000000", "0.00000000"], ["1973.88000000", "0.00000000"], ["1973.89000000", "0.00000000"], ["1973.90000000", "0.00000000"], ["1973.92000000", "89.48920000"], ["1973.94000000", "0.00650000"], ["1973.95000000", "0.03860000"], ["1973.96000000", "1.84110000"], ["1973.97000000", "0.00000000"], ["1973.99000000", "1.82750000"], ["1974.00000000", "1.99170000"], ["1974.01000000", "6.48040000"], ["1974.03000000", "0.01160000"], ["1974.07000000", "0.00260000"], ["1974.08000000", "0.03260000"], ["1974.10000000", "0.70810000"], ["1974.11000000", "0.01680000"], ["1974.12000000", "0.57300000"], ["1974.13000000", "0.00260000"], ["1974.14000000", "4.29490000"], ["1974.22000000", "14.38290000"], ["1974.23000000", "21.28560000"], ["1974.24000000", "0.03260000"], ["1974.25000000", "0.78300000"], ["1974.26000000", "22.57370000"], ["1974.27000000", "1.40400000"], ["1974.33000000", "0.00390000"], ["1974.34000000", "1.28580000"], ["1974.35000000", "1.33650000"], ["1974.37000000", "0.45900000"], ["1974.39000000", "1.21830000"], ["1974.40000000", "13.55040000"], ["1974.41000000", "20.43600000"], ["1974.42000000", "21.28560000"], ["1974.43000000", "26.85660000"], ["1974.44000000", "0.00000000"], ["1974.48000000", "8.94420000"], ["1974.52000000", "6.43830000"], ["1974.53000000", "0.00000000"], ["1974.55000000", "0.00000000"], ["1974.57000000", "0.00000000"], ["1974.59000000", "22.60220000"], ["1974.60000000", "0.03870000"], ["1974.61000000", "27.51220000"], ["1974.62000000", "0.00000000"], ["1974.67000000", "22.03150000"], ["1974.68000000", "0.00000000"], ["1974.69000000", "0.00000000"], ["1974.70000000", "22.57940000"], ["1974.73000000", "0.05020000"], ["1974.80000000", "4.57950000"], ["1974.81000000", "16.92590000"], ["1974.82000000", "0.03560000"], ["1974.86000000", "13.51470000"], ["1974.88000000", "9.74420000"], ["1974.90000000", "22.57630000"], ["1974.91000000", "0.07870000"], ["1974.95000000", "0.00000000"], ["1974.96000000", "0.63410000"], ["1974.97000000", "4.88720000"], ["1975.01000000", "13.87320000"], ["1975.02000000", "7.29580000"], ["1975.04000000", "8.54420000"], ["1975.10000000", "11.02770000"], ["1975.11000000", "23.05970000"], ["1975.12000000", "0.03000000"], ["1975.13000000", "1.50550000"], ["1975.17000000", "2.01810000"], ["1975.20000000", "11.36820000"], ["1975.25000000", "0.03300000"], ["1975.28000000", "8.51420000"], ["1975.36000000", "0.00000000"], ["1975.55000000", "8.43230000"], ["1975.57000000", "35.74330000"], ["1975.60000000", "1.86480000"], ["1975.62000000", "1.51340000"], ["1975.64000000", "0.00000000"], ["1975.69000000", "9.51930000"], ["1975.73000000", "17.13420000"], ["1975.81000000", "1.41190000"], ["1975.93000000", "0.00300000"], ["1975.94000000", "8.96320000"], ["1975.95000000", "0.00000000"], ["1976.00000000", "4.29410000"], ["1976.03000000", "1.19050000"], ["1976.10000000", "4.68140000"], ["1976.15000000", "0.00300000"], ["1976.17000000", "0.00000000"], ["1976.19000000", "0.00000000"], ["1976.24000000", "1.05560000"], ["1976.28000000", "7.07750000"], ["1976.43000000", "8.37050000"], ["1976.48000000", "0.00300000"], ["1976.75000000", "0.01020000"], ["1976.80000000", "0.00310000"], ["1976.90000000", "0.91960000"], ["1977.08000000", "0.00000000"], ["1977.37000000", "22.57370000"], ["1977.41000000", "0.03290000"], ["1977.86000000", "31.64210000"], ["1978.55000000", "0.01290000"], ["1978.96000000", "0.00260000"], ["1979.00000000", "4.17990000"], ["1980.80000000", "1.20860000"], ["1982.70000000", "1.38210000"], ["1989.09000000", "0.00420000"]], "_local_ts_utc": "2026-06-01T07:49:00.311779+00:00"}
{"e": "depthUpdate", "E": 1780300141515, "s": "ETHUSDT", "U": 76583085520, "u": 76583085739, "b": [["1973.91000000", "0.00000000"], ["1973.90000000", "0.00000000"], ["1973.89000000", "0.00000000"], ["1973.85000000", "0.00000000"], ["1973.84000000", "2.91280000"], ["1973.82000000", "0.00260000"], ["1973.80000000", "0.00520000"], ["1973.78000000", "0.01280000"], ["1973.77000000", "0.00000000"], ["1973.76000000", "0.00000000"], ["1973.73000000", "0.00000000"], ["1973.72000000", "0.00000000"], ["1973.69000000", "0.00260000"], ["1973.68000000", "0.00540000"], ["1973.67000000", "0.00000000"], ["1973.66000000", "0.00380000"], ["1973.65000000", "0.00000000"], ["1973.64000000", "0.00000000"], ["1973.62000000", "0.00560000"], ["1973.59000000", "0.50670000"], ["1973.58000000", "0.00000000"], ["1973.57000000", "0.00540000"], ["1973.56000000", "0.00000000"], ["1973.55000000", "0.00000000"], ["1973.54000000", "0.00260000"], ["1973.51000000", "0.00000000"], ["1973.46000000", "0.25750000"], ["1973.45000000", "8.52700000"], ["1973.44000000", "8.18960000"], ["1973.43000000", "0.00000000"], ["1973.42000000", "6.46760000"], ["1973.41000000", "7.09520000"], ["1973.40000000", "16.90230000"], ["1973.39000000", "0.00260000"], ["1973.37000000", "13.51730000"], ["1973.33000000", "7.09520000"], ["1973.29000000", "0.61070000"], ["1973.28000000", "9.97100000"], ["1973.19000000", "21.16500000"], ["1973.18000000", "0.00280000"], ["1973.17000000", "0.00000000"], ["1973.08000000", "10.30980000"], ["1972.90000000", "0.00570000"], ["1972.88000000", "0.18030000"], ["1972.87000000", "12.56350000"], ["1972.85000000", "0.00260000"], ["1972.83000000", "0.00000000"], ["1972.77000000", "0.62360000"], ["1972.69000000", "7.74550000"], ["1972.67000000", "8.87280000"], ["1972.61000000", "0.00260000"], ["1972.60000000", "10.85010000"], ["1972.48000000", "0.04480000"], ["1972.47000000", "4.50680000"], ["1972.40000000", "0.80310000"], ["1972.38000000", "17.67970000"], ["1972.35000000", "0.00000000"], ["1972.30000000", "6.41810000"], ["1972.29000000", "0.10540000"], ["1972.28000000", "0.00000000"], ["1972.14000000", "13.00620000"], ["1972.00000000", "33.67320000"], ["1971.76000000", "2.38270000"], ["1971.67000000", "7.11940000"], ["1971.59000000", "0.52090000"], ["1971.54000000", "7.22220000"], ["1971.49000000", "7.09520000"], ["1970.78000000", "4.26120000"], ["1970.60000000", "10.02640000"], ["1970.27000000", "11.62950000"], ["1967.69000000", "0.00000000"], ["1962.74000000", "0.00000000"], ["1776.52000000", "0.02480000"]], "a": [["1973.85000000", "15.76070000"], ["1973.86000000", "4.00000000"], ["1973.90000000", "4.00000000"], ["1973.91000000", "4.00000000"], ["1973.92000000", "83.55010000"], ["1973.96000000", "7.62280000"], ["1973.99000000", "0.62460000"], ["1974.00000000", "24.56540000"], ["1974.01000000", "6.48040000"], ["1974.03000000", "0.01420000"], ["1974.10000000", "0.00570000"], ["1974.11000000", "0.01420000"], ["1974.15000000", "1.20550000"], ["1974.19000000", "0.05050000"], ["1974.20000000", "17.40730000"], ["1974.21000000", "22.57370000"], ["1974.22000000", "0.70920000"], ["1974.25000000", "8.51420000"], ["1974.26000000", "0.00000000"], ["1974.27000000", "0.00000000"], ["1974.28000000", "0.00000000"], ["1974.34000000", "4.85970000"], ["1974.39000000", "1.21830000"], ["1974.41000000", "20.46730000"], ["1974.59000000", "22.45110000"], ["1974.62000000", "0.37810000"], ["1975.12000000", "0.00000000"], ["1975.62000000", "4.16100000"], ["1975.69000000", "1.00510000"], ["1975.84000000", "1.02400000"], ["1976.24000000", "0.59660000"], ["1976.64000000", "0.00000000"], ["1976.66000000", "1.01930000"], ["1976.83000000", "0.00000000"], ["1977.21000000", "3.13760000"], ["1977.67000000", "0.00320000"], ["1978.70000000", "0.00000000"], ["1979.09000000", "0.00260000"], ["1979.18000000", "0.00260000"], ["1979.27000000", "0.00260000"], ["1979.36000000", "0.00260000"], ["1980.80000000", "1.20860000"], ["1987.75000000", "0.00360000"], ["2005.08000000", "0.00420000"], ["2030.18000000", "0.07690000"]], "_local_ts_utc": "2026-06-01T07:49:00.411931+00:00"}
