{"e": "depthUpdate", "E": 1780300137614, "s": "BTCUSDT", "U": 94551759142, "u": 94551759205, "b": [["72751.00000000", "0.52640000"], ["72745.66000000", "0.00031000"], ["72745.48000000", "0.00031000"], ["72745.32000000", "0.00000000"], ["72742.33000000", "0.05942000"], ["72741.92000000", "0.00000000"], ["72740.92000000", "0.08615000"], ["72740.91000000", "0.00000000"], ["72740.90000000", "0.00000000"], ["72740.89000000", "0.00000000"], ["72732.33000000", "0.00000000"], ["72730.15000000", "0.17923000"], ["72727.08000000", "0.18117000"], ["72722.98000000", "0.00000000"], ["72722.97000000", "0.08270000"], ["72719.54000000", "0.18128000"], ["72718.89000000", "0.00200000"], ["72718.35000000", "0.18117000"], ["72718.19000000", "0.00000000"], ["72716.68000000", "0.17597000"], ["72715.96000000", "0.18117000"], ["72708.10000000", "0.18117000"], ["72706.67000000", "0.18450000"], ["72705.76000000", "0.18125000"], ["72705.49000000", "0.00007000"], ["72703.81000000", "0.18117000"], ["72699.33000000", "0.18117000"], ["72696.23000000", "0.17705000"], ["72693.80000000", "0.18117000"], ["72692.62000000", "0.00000000"], ["72680.48000000", "0.00000000"], ["72665.13000000", "0.01086000"], ["72529.62000000", "0.00007000"], ["65475.90000000", "0.00357000"], ["58200.80000000", "0.00000000"]], "a": [["72751.01000000", "4.07792000"], ["72765.57000000", "0.00000000"], ["72769.58000000", "0.00000000"], ["72771.03000000", "0.00000000"], ["72771.39000000", "0.00008000"], ["72772.52000000", "0.00008000"], ["72774.55000000", "0.00008000"], ["72776.40000000", "0.00000000"], ["72777.10000000", "0.00200000"], ["72799.45000000", "0.09399000"], ["72810.44000000", "0.00000000"], ["80159.53000000", "0.00000000"]], "_local_ts_utc": "2026-06-01T07:48:56.509648+00:00"}
{"e": "depthUpdate", "E": 1780300137714, "s": "BTCUSDT", "U": 94551759206, "u": 94551759277, "b": [["72751.00000000", "0.94275000"], ["72748.98000000", "0.00031000"], ["72747.68000000", "0.00031000"], ["72747.39000000", "0.02024000"], ["72747.20000000", "0.00016000"], ["72746.61000000", "0.00000000"], ["72745.96000000", "0.00000000"], ["72745.66000000", "0.00000000"], ["72745.48000000", "0.00000000"], ["72744.60000000", "0.09350000"], ["72740.95000000", "0.06384000"], ["72740.94000000", "0.00000000"], ["72740.93000000", "0.00000000"], ["72740.92000000", "0.00000000"], ["72740.24000000", "0.00000000"], ["72740.17000000", "0.01405000"], ["72738.13000000", "0.16409000"], ["72736.84000000", "0.18117000"], ["72736.74000000", "0.18283000"], ["72735.27000000", "0.16568000"], ["72734.71000000", "0.18117000"], ["72730.15000000", "0.18117000"], ["72727.50000000", "0.01376000"], ["72727.08000000", "0.18066000"], ["72719.54000000", "0.18128000"], ["72708.10000000", "0.00000000"], ["72706.67000000", "0.18302000"], ["72696.23000000", "0.00000000"], ["72693.80000000", "0.18117000"], ["72692.62000000", "0.18117000"], ["72678.01000000", "0.78740000"], ["65475.90000000", "0.00357000"]], "a": [["72751.01000000", "3.98777000"], ["72751.71000000", "0.00016000"], ["72753.78000000", "0.05312000"], ["72767.38000000", "0.00000000"], ["72769.58000000", "0.00000000"], ["72771.03000000", "0.00000000"], ["72771.39000000", "0.00008000"], ["72777.10000000", "0.20200000"], ["72777.42000000", "0.00000000"], ["76388.55000000", "0.00292000"]], "_local_ts_utc": "2026-06-01T07:48:56.610151+00:00"}
{"e": "depthUpdate", "E": 1780300137814, "s": "BTCUSDT", "U": 94551759278, "u": 94551759408, "b": [["72751.00000000", "2.01485000"], ["72750.99000000", "0.00446000"], ["72750.02000000", "0.00016000"], ["72750.01000000", "0.35643000"], ["72749.82000000", "0.00000000"], ["72749.76000000", "0.00091000"], ["72749.40000000", "0.00000000"], ["72749.31000000", "0.00031000"], ["72748.98000000", "0.00000000"], ["72748.00000000", "0.02296000"], ["72747.68000000", "0.00000000"], ["72747.41000000", "0.05231000"], ["72747.40000000", "0.00138000"], ["72747.39000000", "0.02040000"], ["72747.20000000", "0.00000000"], ["72746.19000000", "0.05942000"], ["72744.60000000", "0.13538000"], ["72743.58000000", "0.00400000"], ["72742.42000000", "0.17046000"], ["72742.33000000", "0.00000000"], ["72741.68000000", "0.00011000"], ["72741.00000000", "0.23106000"], ["72740.99000000", "0.18117000"], ["72740.95000000", "0.01375000"], ["72739.56000000", "0.18132000"], ["72734.01000000", "0.11109000"], ["72730.98000000", "0.18136000"], ["72728.28000000", "0.00000000"], ["72728.12000000", "0.00000000"], ["72719.54000000", "0.00011000"], ["72714.46000000", "0.00000000"], ["72708.10000000", "0.00000000"], ["72693.80000000", "0.00000000"], ["72692.62000000", "0.00000000"], ["65475.90000000", "0.00374000"]], "a": [["72751.01000000", "3.20334000"], ["72751.45000000", "0.00008000"], ["72751.46000000", "0.00016000"], ["72751.71000000", "0.00000000"], ["72752.43000000", "0.00024000"], ["72753.30000000", "0.00000000"], ["72753.34000000", "0.00000000"], ["72753.35000000", "0.03436000"], ["72753.74000000", "0.05942000"], ["72753.77000000", "0.00000000"], ["72753.78000000", "0.05328000"], ["72753.84000000", "0.00000000"], ["72754.68000000", "0.00000000"], ["72759.59000000", "0.00000000"], ["72759.70000000", "0.00028000"], ["72762.21000000", "0.00008000"], ["72762.81000000", "0.00008000"], ["72763.84000000", "0.00000000"], ["72765.23000000", "0.00008000"], ["72766.74000000", "0.18117000"], ["72767.43000000", "0.07800000"], ["72768.09000000", "0.18135000"], ["72770.05000000", "0.00200000"], ["72775.19000000", "0.00000000"], ["72779.89000000", "0.00200000"], ["81350.56000000", "0.00000000"]], "_local_ts_utc": "2026-06-01T07:48:56.710476+00:00"}
{"e": "depthUpdate", "E": 1780300137914, "s": "BTCUSDT", "U": 94551759409, "u": 94551759498, "b": [["72751.00000000", "1.10695000"], ["72750.99000000", "0.00366000"], ["72750.02000000", "0.00000000"], ["72750.01000000", "0.00040000"], ["72749.76000000", "0.00063000"], ["72749.31000000", "0.00000000"], ["72748.00000000", "0.02296000"], ["72747.65000000", "0.00000000"], ["72747.42000000", "0.00049000"], ["72747.41000000", "0.00000000"], ["72746.87000000", "0.00000000"], ["72746.59000000", "0.02415000"], ["72746.27000000", "0.00031000"], ["72746.20000000", "0.00016000"], ["72746.00000000", "0.02280000"], ["72744.60000000", "0.07975000"], ["72742.42000000", "0.00000000"], ["72741.02000000", "0.36181000"], ["72741.01000000", "0.65949000"], ["72741.00000000", "0.00000000"], ["72740.99000000", "0.00000000"], ["72740.95000000", "0.00000000"], ["72739.56000000", "0.00015000"], ["72735.27000000", "0.00000000"], ["72734.71000000", "0.00000000"], ["72734.01000000", "0.05635000"], ["72730.98000000", "0.00019000"], ["72730.15000000", "0.00000000"], ["72722.50000000", "0.00228000"], ["72721.89000000", "0.01371000"], ["72718.89000000", "0.00000000"], ["72693.80000000", "0.16735000"], ["72692.62000000", "0.18117000"], ["65475.90000000", "0.00391000"]], "a": [["72751.01000000", "3.20334000"], ["72751.45000000", "0.00000000"], ["72751.46000000", "0.00000000"], ["72751.76000000", "0.00000000"], ["72752.43000000", "0.00008000"], ["72753.35000000", "0.03436000"], ["72753.74000000", "0.05958000"], ["72754.76000000", "0.00028000"], ["72756.52000000", "0.00000000"], ["72756.72000000", "0.00008000"], ["72759.59000000", "0.18117000"], ["72759.70000000", "0.17495000"], ["72762.21000000", "0.18125000"], ["72762.81000000", "0.18125000"], ["72762.82000000", "1.21577000"], ["72763.79000000", "0.00000000"], ["72765.23000000", "0.18125000"], ["72768.08000000", "0.00667000"], ["72771.39000000", "0.00000000"], ["72777.10000000", "0.20000000"], ["72780.71000000", "0.00200000"], ["72785.98000000", "0.40856000"], ["77116.06000000", "0.01384000"], ["81514.80000000", "0.00000000"]], "_local_ts_utc": "2026-06-01T07:48:56.810419+00:00"}
{"e": "depthUpdate", "E": 1780300138014, "s": "BTCUSDT", "U": 94551759499, "u": 94551759544, "b": [["72751.00000000", "1.10545000"], ["72750.01000000", "0.00024000"], ["72748.00000000", "0.02296000"], ["72747.42000000", "0.00033000"], ["72747.14000000", "0.00031000"], ["72746.59000000", "0.02431000"], ["72744.60000000", "0.00000000"], ["72741.02000000", "0.25699000"], ["72738.13000000", "0.00000000"], ["72735.13000000", "0.01375000"], ["72733.65000000", "0.02007000"], ["72729.80000000", "0.02114000"], ["72719.54000000", "0.16309000"], ["65475.90000000", "0.00391000"], ["58200.80000000", "0.00034000"]], "a": [["72751.01000000", "3.86275000"], ["72751.02000000", "0.00118000"], ["72753.74000000", "0.00016000"], ["72753.78000000", "0.06049000"], ["72762.76000000", "0.00007000"], ["72768.00000000", "0.02080000"], ["72768.08000000", "0.00000000"], ["72768.09000000", "0.18117000"], ["72780.12000000", "0.01371000"]], "_local_ts_utc": "2026-06-01T07:48:56.910679+00:00"}
{"e": "depthUpdate", "E": 1780300138114, "s": "BTCUSDT", "U": 94551759545, "u": 94551759576, "b": [["72751.00000000", "1.10529000"], ["72750.99000000", "0.00110000"], ["72747.76000000", "0.00031000"], ["72747.14000000", "0.00000000"], ["72746.19000000", "0.05958000"], ["72744.60000000", "0.07696000"], ["72741.65000000", "0.00000000"], ["72741.02000000", "0.24324000"], ["72738.13000000", "0.18117000"], ["72731.55000000", "0.00000000"], ["72730.15000000", "0.18117000"], ["72721.44000000", "0.00000000"], ["72711.34000000", "0.00000000"], ["72701.23000000", "0.00000000"], ["72691.13000000", "0.00000000"], ["72681.02000000", "0.00000000"], ["65475.90000000", "0.00408000"], ["58200.80000000", "0.00034000"]], "a": [["72751.01000000", "3.86241000"], ["72753.35000000", "0.03436000"], ["72753.74000000", "0.00000000"], ["72754.30000000", "0.01425000"], ["72761.85000000", "0.00000000"], ["72765.38000000", "0.00400000"], ["72767.43000000", "0.07400000"], ["72771.96000000", "0.00000000"], ["72782.07000000", "0.00000000"], ["72792.17000000", "0.00000000"], ["72802.28000000", "0.00000000"], ["72812.38000000", "0.00000000"], ["72822.49000000", "0.00000000"], ["72842.71000000", "0.00000000"], ["72852.81000000", "0.00000000"], ["72862.92000000", "0.00000000"], ["72873.02000000", "0.00000000"], ["72883.13000000", "0.00000000"], ["72893.23000000", "0.00000000"], ["72903.34000000", "0.00000000"], ["72913.44000000", "0.00000000"], ["72923.55000000", "0.00000000"], ["72933.65000000", "0.00000000"], ["72943.76000000", "0.00000000"], ["72953.86000000", "0.00000000"], ["72963.97000000", "0.00000000"], ["72974.07000000", "0.00000000"], ["72984.18000000", "0.00000000"], ["85045.16000000", "0.00000000"]], "_local_ts_utc": "2026-06-01T07:48:57.010170+00:00"}
{"e": "depthUpdate", "E": 1780300138214, "s": "BTCUSDT", "U": 94551759577, "u": 94551759612, "b": [["72751.00000000", "1.10137000"], ["72747.41000000", "0.00016000"], ["72747.40000000", "0.05922000"], ["72744.60000000", "0.10745000"], ["72742.42000000", "0.18117000"], ["72741.03000000", "0.18117000"], ["72741.02000000", "0.33581000"], ["72739.56000000", "0.18132000"], ["72735.27000000", "0.18117000"], ["72734.71000000", "0.18117000"], ["72730.15000000", "0.00000000"], ["72722.50000000", "0.00028000"], ["72720.56000000", "0.00200000"], ["65475.90000000", "0.00408000"], ["58200.80000000", "0.00000000"]], "a": [["72751.01000000", "3.86211000"], ["72751.02000000", "0.00374000"], ["72762.21000000", "0.00008000"], ["72762.81000000", "0.00008000"], ["72765.23000000", "0.00008000"], ["72766.74000000", "0.18117000"], ["72778.77000000", "0.00200000"], ["72780.71000000", "0.00000000"], ["77843.57000000", "0.00370000"]], "_local_ts_utc": "2026-06-01T07:48:57.110324+00:00"}
{"e": "depthUpdate", "E": 1780300138314, "s": "BTCUSDT", "U": 94551759613, "u": 94551759879, "b": [["72751.00000000", "3.79049000"], ["72750.99000000", "0.00054000"], ["72750.02000000", "0.18117000"], ["72750.01000000", "0.35636000"], ["72749.76000000", "0.00091000"], ["72749.71000000", "0.00008000"], ["72749.67000000", "0.00031000"], ["72749.25000000", "0.00000000"], ["72749.19000000", "0.05942000"], ["72749.04000000", "0.00400000"], ["72748.14000000", "0.18117000"], ["72748.11000000", "0.00000000"], ["72748.00000000", "0.02296000"], ["72747.76000000", "0.00000000"], ["72747.56000000", "0.03000000"], ["72747.41000000", "0.07543000"], ["72747.40000000", "0.00154000"], ["72747.39000000", "0.00016000"], ["72747.22000000", "0.00400000"], ["72746.97000000", "0.16838000"], ["72746.71000000", "0.18117000"], ["72746.27000000", "0.00000000"], ["72746.20000000", "0.00000000"], ["72746.19000000", "0.00000000"], ["72745.40000000", "0.00400000"], ["72745.34000000", "0.18117000"], ["72744.61000000", "0.16311000"], ["72744.60000000", "0.00000000"], ["72743.85000000", "0.18117000"], ["72742.70000000", "0.00760000"], ["72741.85000000", "0.03407000"], ["72740.79000000", "0.00000000"], ["72739.06000000", "0.00758000"], ["72737.84000000", "0.00000000"], ["72736.74000000", "0.00000000"], ["72732.41000000", "0.18117000"], ["72730.98000000", "0.18136000"], ["72730.19000000", "0.02000000"], ["72730.15000000", "0.18117000"], ["72729.80000000", "0.00739000"], ["72728.12000000", "0.18117000"], ["72727.50000000", "0.00000000"], ["72723.83000000", "0.17474000"], ["72722.40000000", "0.18117000"], ["72721.18000000", "0.18117000"], ["72721.11000000", "0.00000000"], ["72719.92000000", "0.00000000"], ["72718.10000000", "0.00000000"], ["72716.28000000", "0.00000000"], ["72714.45000000", "1.36320000"], ["72713.91000000", "0.49571000"], ["72712.42000000", "0.02709000"], ["72711.26000000", "0.18117000"], ["72709.59000000", "0.18117000"], ["72708.10000000", "0.16760000"], ["72707.84000000", "0.00000000"], ["72707.66000000", "0.71697000"], ["72707.03000000", "1.36333000"], ["72696.22000000", "0.00000000"], ["72692.62000000", "0.00000000"], ["72686.68000000", "0.00000000"], ["72684.64000000", "0.18453000"], ["72678.01000000", "0.45223000"], ["72677.33000000", "0.00000000"], ["72463.32000000", "0.00000000"], ["65475.90000000", "0.00408000"]], "a": [["72751.01000000", "1.10467000"], ["72751.02000000", "0.00430000"], ["72751.81000000", "0.00000000"], ["72752.33000000", "0.00000000"], ["72752.43000000", "0.00024000"], ["72752.44000000", "0.00016000"], ["72752.68000000", "0.00000000"], ["72752.71000000", "0.02000000"], ["72753.23000000", "0.00000000"], ["72753.30000000", "0.00016000"], ["72753.31000000", "0.00016000"], ["72753.34000000", "0.00016000"], ["72753.77000000", "0.00016000"], ["72753.78000000", "0.00737000"], ["72753.84000000", "0.00008000"], ["72754.06000000", "0.00016000"], ["72754.76000000", "0.00000000"], ["72754.86000000", "0.04929000"], ["72754.97000000", "0.76555000"], ["72754.98000000", "0.00000000"], ["72754.99000000", "0.00000000"], ["72755.13000000", "0.00000000"], ["72755.66000000", "0.00000000"], ["72755.96000000", "0.00000000"], ["72756.17000000", "0.00031000"], ["72756.73000000", "0.00000000"], ["72757.87000000", "0.07000000"], ["72757.91000000", "0.77830000"], ["72757.92000000", "0.00000000"], ["72758.97000000", "0.08000000"], ["72759.59000000", "0.00000000"], ["72759.70000000", "0.00028000"], ["72762.21000000", "0.65957000"], ["72762.22000000", "0.00000000"], ["72765.24000000", "0.00000000"], ["72765.38000000", "0.00000000"], ["72766.74000000", "0.00000000"], ["72768.08000000", "0.65949000"], ["72768.09000000", "0.00000000"], ["72768.10000000", "0.56768000"], ["72768.11000000", "0.00000000"], ["72768.16000000", "0.00000000"], ["72770.05000000", "0.00000000"], ["72770.98000000", "0.00400000"], ["72771.41000000", "0.00000000"], ["72772.53000000", "0.00000000"], ["72773.23000000", "0.00000000"], ["72775.00000000", "2.74910000"], ["72775.02000000", "0.00000000"], ["72780.12000000", "0.01371000"], ["72780.78000000", "0.00000000"], ["72783.21000000", "0.00000000"], ["72785.44000000", "0.00400000"], ["72791.11000000", "0.00114000"], ["72793.15000000", "0.49517000"], ["72807.41000000", "0.00000000"], ["72811.24000000", "1.36138000"], ["72820.23000000", "0.00000000"], ["72857.35000000", "2.74910000"], ["85780.87000000", "0.00000000"]], "_local_ts_utc": "2026-06-01T07:48:57.210476+00:00"}
{"e": "depthUpdate", "E": 1780300138414, "s": "BTCUSDT", "U": 94551759880, "u": 94551760262, "b": [["72751.00000000", "3.41036000"], ["72750.99000000", "0.00110000"], ["72750.03000000", "0.00000000"], ["72750.02000000", "0.00032000"], ["72750.01000000", "0.35668000"], ["72749.76000000", "0.00063000"], ["72749.71000000", "0.00024000"], ["72749.67000000", "0.00000000"], ["72749.54000000", "0.00941000"], ["72749.19000000", "0.05958000"], ["72748.93000000", "0.00000000"], ["72748.51000000", "0.02958000"], ["72748.16000000", "0.00000000"], ["72748.15000000", "0.04385000"], ["72748.14000000", "0.00016000"], ["72748.00000000", "0.02296000"], ["72747.56000000", "0.00000000"], ["72747.41000000", "0.00000000"], ["72747.40000000", "0.00138000"], ["72747.39000000", "0.00000000"], ["72746.97000000", "0.00000000"], ["72746.71000000", "0.00000000"], ["72746.65000000", "0.01374000"], ["72746.59000000", "0.02415000"], ["72745.35000000", "0.16421000"], ["72745.34000000", "0.00000000"], ["72744.61000000", "0.00000000"], ["72744.51000000", "0.01388000"], ["72743.85000000", "0.00000000"], ["72741.13000000", "0.00000000"], ["72741.11000000", "0.00000000"], ["72740.09000000", "0.01375000"], ["72739.96000000", "0.00164000"], ["72732.41000000", "0.00000000"], ["72731.19000000", "0.00000000"], ["72730.98000000", "0.00019000"], ["72730.19000000", "0.00000000"], ["72730.16000000", "0.40856000"], ["72730.15000000", "0.00000000"], ["72730.14000000", "0.00000000"], ["72728.12000000", "0.00000000"], ["72725.38000000", "0.02400000"], ["72724.47000000", "0.00022000"], ["72723.83000000", "0.00000000"], ["72722.40000000", "0.00000000"], ["72721.74000000", "0.00000000"], ["72721.18000000", "0.00000000"], ["72719.54000000", "0.00011000"], ["72717.11000000", "0.00000000"], ["72716.52000000", "0.02691000"], ["72714.45000000", "0.00000000"], ["72712.42000000", "0.00000000"], ["72711.26000000", "0.00000000"], ["72709.59000000", "0.00000000"], ["72708.10000000", "0.00000000"], ["72706.67000000", "0.00333000"], ["72705.76000000", "0.00008000"], ["72703.81000000", "0.00000000"], ["72702.85000000", "0.18146000"], ["72701.43000000", "0.17966000"], ["72700.01000000", "0.16326000"], ["72699.33000000", "0.00000000"], ["72693.80000000", "0.18117000"], ["72692.62000000", "0.18117000"], ["72463.50000000", "4.14521000"], ["65475.90000000", "0.00408000"]], "a": [["72751.01000000", "3.03818000"], ["72751.02000000", "0.00430000"], ["72752.43000000", "0.00024000"], ["72752.44000000", "0.17540000"], ["72752.49000000", "0.00000000"], ["72752.70000000", "0.00000000"], ["72752.71000000", "0.00016000"], ["72753.00000000", "0.00031000"], ["72753.30000000", "0.00000000"], ["72753.31000000", "0.00000000"], ["72753.77000000", "0.00721000"], ["72753.78000000", "0.00016000"], ["72753.83000000", "0.00016000"], ["72753.84000000", "0.18133000"], ["72753.85000000", "0.07093000"], ["72754.06000000", "0.00000000"], ["72754.07000000", "0.00016000"], ["72754.30000000", "0.00016000"], ["72754.43000000", "0.00028000"], ["72754.50000000", "0.00000000"], ["72754.85000000", "0.00000000"], ["72754.86000000", "0.00016000"], ["72754.97000000", "0.00016000"], ["72755.00000000", "0.69357000"], ["72755.60000000", "0.04345000"], ["72755.85000000", "0.00000000"], ["72756.17000000", "0.00000000"], ["72756.32000000", "0.00000000"], ["72756.73000000", "0.18117000"], ["72757.09000000", "0.00000000"], ["72757.70000000", "0.05942000"], ["72757.85000000", "0.85307000"], ["72757.86000000", "0.18117000"], ["72757.91000000", "0.00000000"], ["72757.94000000", "0.33300000"], ["72758.01000000", "0.41093000"], ["72758.30000000", "0.00759000"], ["72758.45000000", "0.00000000"], ["72759.59000000", "0.18117000"], ["72759.70000000", "0.18145000"], ["72760.49000000", "0.00000000"], ["72760.96000000", "0.00008000"], ["72760.97000000", "0.00000000"], ["72762.20000000", "0.18117000"], ["72762.81000000", "0.00008000"], ["72763.26000000", "0.00187000"], ["72763.80000000", "0.28332000"], ["72765.31000000", "0.00000000"], ["72766.74000000", "0.18117000"], ["72768.06000000", "0.18117000"], ["72768.07000000", "1.36920000"], ["72768.10000000", "0.00008000"], ["72768.71000000", "2.74918000"], ["72769.58000000", "0.00000000"], ["72771.03000000", "0.00000000"], ["72771.40000000", "0.00008000"], ["72772.46000000", "0.00000000"], ["72772.56000000", "0.31140000"], ["72773.36000000", "0.49974000"], ["72773.89000000", "0.00000000"], ["72774.55000000", "0.00008000"], ["72774.99000000", "1.80811000"], ["72775.01000000", "0.00008000"], ["72775.66000000", "0.00200000"], ["72779.74000000", "0.00000000"], ["72779.89000000", "0.00000000"], ["72781.31000000", "0.00200000"], ["72784.10000000", "0.00000000"], ["72788.88000000", "0.02656000"], ["72818.87000000", "0.00000000"], ["72856.90000000", "0.00000000"], ["72857.35000000", "0.00000000"], ["72878.77000000", "0.09605000"], ["78571.08000000", "0.00389000"], ["86269.38000000", "0.00000000"]], "_local_ts_utc": "2026-06-01T07:48:57.310587+00:00"}
{"e": "depthUpdate", "E": 1780300138514, "s": "BTCUSDT", "U": 94551760263, "u": 94551760390, "b": [["72751.00000000", "3.28930000"], ["72750.87000000", "0.05942000"], ["72750.02000000", "0.00016000"], ["72749.19000000", "0.00016000"], ["72748.51000000", "0.02974000"], ["72748.15000000", "0.04401000"], ["72748.14000000", "0.00000000"], ["72748.00000000", "0.02296000"], ["72745.36000000", "0.00016000"], ["72743.85000000", "0.18117000"], ["72730.98000000", "0.18136000"], ["72730.17000000", "0.18141000"], ["72728.12000000", "0.00000000"], ["72723.43000000", "0.00200000"], ["72720.56000000", "0.00000000"], ["72719.54000000", "0.00011000"], ["72703.81000000", "0.18117000"], ["72699.33000000", "0.00000000"], ["72693.80000000", "0.00000000"], ["72692.62000000", "0.17154000"], ["72622.75000000", "0.00000000"], ["72350.00000000", "0.20248000"], ["65475.90000000", "0.00425000"], ["58200.80000000", "0.00034000"]], "a": [["72751.01000000", "2.90932000"], ["72751.02000000", "0.00430000"], ["72752.40000000", "0.00031000"], ["72752.44000000", "0.17556000"], ["72752.71000000", "0.00000000"], ["72753.00000000", "0.00000000"], ["72753.35000000", "0.03436000"], ["72753.77000000", "0.00016000"], ["72753.78000000", "0.00739000"], ["72753.84000000", "0.18149000"], ["72754.08000000", "0.10090000"], ["72754.30000000", "0.00000000"], ["72754.86000000", "0.00000000"], ["72754.97000000", "0.00000000"], ["72755.00000000", "0.69373000"], ["72755.01000000", "1.71161000"], ["72757.83000000", "0.18117000"], ["72757.84000000", "0.65949000"], ["72757.85000000", "0.60214000"], ["72757.86000000", "0.00000000"], ["72759.59000000", "0.00000000"], ["72759.70000000", "0.00028000"], ["72762.20000000", "0.00000000"], ["72778.77000000", "0.00000000"], ["72781.60000000", "0.00200000"], ["72785.44000000", "0.00000000"], ["72986.77000000", "0.00000000"]], "_local_ts_utc": "2026-06-01T07:48:57.410214+00:00"}
{"e": "depthUpdate", "E": 1780300138614, "s": "BTCUSDT", "U": 94551760391, "u": 94551760505, "b": [["72751.00000000", "3.12418000"], ["72750.99000000", "0.00118000"], ["72750.88000000", "0.00000000"], ["72750.87000000", "0.00016000"], ["72749.54000000", "0.00941000"], ["72749.19000000", "0.00000000"], ["72748.68000000", "0.00016000"], ["72748.67000000", "0.07064000"], ["72748.66000000", "0.05942000"], ["72748.15000000", "0.00030000"], ["72745.36000000", "0.00000000"], ["72745.35000000", "0.25603000"], ["72744.95000000", "0.01375000"], ["72743.43000000", "0.18300000"], ["72736.90000000", "0.01376000"], ["72710.44000000", "0.00007000"], ["72697.04000000", "0.26000000"], ["72693.80000000", "0.18117000"], ["72692.17000000", "0.00000000"], ["72523.53000000", "0.00007000"], ["65475.90000000", "0.00425000"], ["58201.00000000", "0.08468000"], ["58200.80000000", "0.00000000"]], "a": [["72751.01000000", "2.71787000"], ["72751.02000000", "0.00430000"], ["72751.61000000", "0.00000000"], ["72752.43000000", "0.00016000"], ["72753.35000000", "0.03436000"], ["72753.77000000", "0.00739000"], ["72753.78000000", "0.00016000"], ["72753.83000000", "0.00024000"], ["72754.05000000", "0.00000000"], ["72755.37000000", "0.05942000"], ["72757.70000000", "0.00000000"], ["72757.83000000", "0.18125000"], ["72757.90000000", "0.00000000"], ["72758.96000000", "0.00008000"], ["72760.00000000", "0.00651000"], ["72761.40000000", "0.00000000"], ["72762.20000000", "0.00008000"], ["72762.21000000", "0.65949000"], ["72762.82000000", "1.21569000"], ["72765.23000000", "0.00000000"], ["72768.06000000", "0.18125000"], ["72768.10000000", "0.00000000"], ["72768.70000000", "0.00008000"], ["72768.71000000", "2.74910000"], ["72769.06000000", "0.00408000"], ["72771.40000000", "0.00000000"], ["72771.56000000", "0.00008000"], ["72772.52000000", "0.00000000"], ["72773.35000000", "0.00008000"], ["72774.99000000", "1.80819000"], ["72775.01000000", "0.00000000"], ["72777.13000000", "0.00008000"], ["72779.74000000", "0.00008000"], ["72780.00000000", "0.13416000"], ["72800.43000000", "1.18421000"], ["72880.65000000", "0.00000000"], ["86757.89000000", "0.00000000"]], "_local_ts_utc": "2026-06-01T07:48:57.510225+00:00"}
{"e": "depthUpdate", "E": 1780300138714, "s": "BTCUSDT", "U": 94551760506, "u": 94551760581, "b": [["72751.00000000", "3.11792000"], ["72750.99000000", "0.00110000"], ["72750.87000000", "0.00000000"], ["72750.68000000", "0.00000000"], ["72749.54000000", "0.00941000"], ["72748.67000000", "0.07080000"], ["72748.66000000", "0.05958000"], ["72748.51000000", "0.02958000"], ["72748.15000000", "0.00014000"], ["72730.98000000", "0.00019000"], ["72569.12000000", "0.00014000"], ["65475.90000000", "0.00425000"], ["65475.00000000", "0.00109000"]], "a": [["72751.01000000", "2.40131000"], ["72751.02000000", "0.00398000"], ["72753.35000000", "0.03436000"], ["72753.77000000", "0.00016000"], ["72753.78000000", "0.00739000"], ["72755.01000000", "1.71161000"], ["72755.60000000", "0.05116000"], ["72759.70000000", "0.17703000"], ["72781.31000000", "0.00000000"], ["72782.07000000", "0.00200000"], ["72824.25000000", "0.08239000"], ["72932.88000000", "0.00014000"]], "_local_ts_utc": "2026-06-01T07:48:57.610446+00:00"}
{"e": "depthUpdate", "E": 1780300138814, "s": "BTCUSDT", "U": 94551760582, "u": 94551760648, "b": [["72751.00000000", "2.95423000"], ["72749.91000000", "0.00031000"], ["72749.89000000", "0.00031000"], ["72744.95000000", "0.00000000"], ["72743.85000000", "0.00000000"], ["72742.42000000", "0.00000000"], ["72730.17000000", "0.00024000"], ["72723.96000000", "0.00200000"], ["72723.43000000", "0.00000000"], ["66959.50000000", "0.00015000"], ["65475.90000000", "0.00425000"], ["65475.00000000", "0.00089000"]], "a": [["72751.01000000", "3.00114000"], ["72751.02000000", "0.00382000"], ["72751.82000000", "0.00765000"], ["72752.10000000", "0.01404000"], ["72753.11000000", "0.05942000"], ["72753.34000000", "0.00000000"], ["72753.35000000", "0.03436000"], ["72753.77000000", "0.00739000"], ["72753.78000000", "0.00016000"], ["72753.83000000", "0.00008000"], ["72753.84000000", "0.18133000"], ["72754.07000000", "0.00008000"], ["72755.37000000", "0.00000000"], ["72759.59000000", "0.18117000"], ["72781.60000000", "0.00000000"], ["72782.18000000", "0.00200000"], ["87246.40000000", "0.00000000"]], "_local_ts_utc": "2026-06-01T07:48:57.710793+00:00"}
{"e": "depthUpdate", "E": 1780300138914, "s": "BTCUSDT", "U": 94551760649, "u": 94551760731, "b": [["72751.00000000", "2.77912000"], ["72750.99000000", "0.00102000"], ["72750.02000000", "0.00000000"], ["72750.01000000", "0.00040000"], ["72749.91000000", "0.00000000"], ["72749.89000000", "0.00000000"], ["72749.41000000", "0.00031000"], ["72749.18000000", "0.00031000"], ["72748.67000000", "0.07096000"], ["72745.35000000", "0.11013000"], ["72743.43000000", "0.00000000"], ["72740.09000000", "0.00000000"], ["72739.56000000", "0.00015000"], ["72736.90000000", "0.00000000"], ["72735.27000000", "0.00000000"], ["72734.71000000", "0.00000000"], ["72724.63000000", "0.62613000"], ["72699.07000000", "0.49581000"], ["65475.90000000", "0.00425000"]], "a": [["72751.01000000", "3.09928000"], ["72751.02000000", "0.00382000"], ["72751.82000000", "0.00781000"], ["72752.10000000", "0.01420000"], ["72752.43000000", "0.00000000"], ["72752.44000000", "0.17556000"], ["72753.11000000", "0.05958000"], ["72753.22000000", "0.00008000"], ["72753.35000000", "0.03436000"], ["72753.77000000", "0.00016000"], ["72753.78000000", "0.00739000"], ["72754.08000000", "0.10074000"], ["72755.00000000", "0.69357000"], ["72755.01000000", "1.71145000"], ["72762.20000000", "0.18125000"], ["72762.81000000", "0.16783000"], ["72763.26000000", "0.00000000"], ["72765.31000000", "0.18117000"], ["72772.70000000", "0.49931000"], ["72775.66000000", "0.00000000"], ["72780.54000000", "1.36196000"], ["72793.15000000", "0.00000000"], ["72816.49000000", "0.21396000"], ["72817.65000000", "0.00000000"], ["72878.77000000", "0.00000000"]], "_local_ts_utc": "2026-06-01T07:48:57.810252+00:00"}
{"e": "depthUpdate", "E": 1780300139014, "s": "BTCUSDT", "U": 94551760732, "u": 94551760771, "b": [["72751.00000000", "2.54242000"], ["72750.11000000", "0.00031000"], ["72750.01000000", "0.00024000"], ["72749.48000000", "0.00000000"], ["72749.45000000", "0.00000000"], ["72749.41000000", "0.00000000"], ["72749.18000000", "0.00000000"], ["72738.64000000", "0.01375000"], ["72733.65000000", "0.02007000"], ["65475.90000000", "0.00425000"], ["58200.80000000", "0.00034000"]], "a": [["72752.49000000", "0.00008000"], ["72753.35000000", "0.03436000"], ["72753.77000000", "0.00757000"], ["72753.78000000", "0.00016000"], ["72762.76000000", "0.00007000"], ["72767.51000000", "0.00400000"], ["72770.98000000", "0.00000000"], ["72773.84000000", "0.00200000"], ["72783.58000000", "0.00114000"], ["72791.11000000", "0.00000000"], ["87734.91000000", "0.00000000"]], "_local_ts_utc": "2026-06-01T07:48:57.910792+00:00"}
{"e": "depthUpdate", "E": 1780300139114, "s": "BTCUSDT", "U": 94551760772, "u": 94551760820, "b": [["72751.00000000", "2.53765000"], ["72750.99000000", "0.00094000"], ["72750.11000000", "0.00000000"], ["72749.49000000", "0.00031000"], ["72748.67000000", "0.07080000"], ["72748.66000000", "0.00016000"], ["72748.19000000", "0.00031000"], ["72746.44000000", "0.00016000"], ["72746.43000000", "0.05942000"], ["72741.75000000", "0.00070000"], ["72738.89000000", "0.16246000"], ["72736.76000000", "0.00047000"], ["72730.17000000", "0.18141000"], ["72592.98000000", "0.00574000"], ["72552.59000000", "0.00822000"], ["72550.01000000", "0.00201000"], ["65475.90000000", "0.00425000"], ["58200.80000000", "0.00034000"]], "a": [["72751.01000000", "3.09928000"], ["72751.02000000", "0.00382000"], ["72753.35000000", "0.03436000"], ["72753.77000000", "0.00016000"], ["72753.78000000", "0.00757000"], ["72758.74000000", "0.08251000"], ["72798.59000000", "0.00048000"], ["87997.75000000", "0.00000000"]], "_local_ts_utc": "2026-06-01T07:48:58.010272+00:00"}
{"e": "depthUpdate", "E": 1780300139214, "s": "BTCUSDT", "U": 94551760821, "u": 94551760868, "b": [["72751.00000000", "2.53803000"], ["72750.25000000", "0.00031000"], ["72749.55000000", "0.00031000"], ["72749.49000000", "0.00000000"], ["72748.67000000", "0.07080000"], ["72748.66000000", "0.00000000"], ["72748.51000000", "0.02974000"], ["72748.19000000", "0.00000000"], ["72746.65000000", "0.01390000"], ["72746.59000000", "0.02431000"], ["72743.98000000", "0.01375000"], ["72741.75000000", "0.00000000"], ["72737.46000000", "0.00048000"], ["72734.71000000", "0.18117000"], ["72603.45000000", "0.00574000"], ["65475.90000000", "0.00408000"], ["58200.80000000", "0.00000000"]], "a": [["72751.01000000", "3.09821000"], ["72751.02000000", "0.00398000"], ["72753.35000000", "0.03436000"], ["72753.77000000", "0.00757000"], ["72753.78000000", "0.00016000"], ["72758.74000000", "0.00000000"], ["72773.84000000", "0.00000000"]], "_local_ts_utc": "2026-06-01T07:48:58.110200+00:00"}
{"e": "depthUpdate", "E": 1780300139314, "s": "BTCUSDT", "U": 94551760869, "u": 94551760914, "b": [["72751.00000000", "2.71092000"], ["72750.98000000", "0.00014000"], ["72750.02000000", "0.00016000"], ["72750.01000000", "0.35771000"], ["72749.55000000", "0.00000000"], ["72746.44000000", "0.00000000"], ["72745.35000000", "0.09638000"], ["72613.93000000", "0.00574000"], ["66959.50000000", "0.00000000"], ["65475.90000000", "0.00391000"]], "a": [["72751.01000000", "3.09821000"], ["72751.02000000", "0.00398000"], ["72753.35000000", "0.03436000"], ["72753.77000000", "0.00016000"], ["72753.78000000", "0.00757000"], ["72758.75000000", "0.08251000"], ["72774.06000000", "0.00200000"], ["72824.25000000", "0.00000000"], ["87997.80000000", "0.00000000"]], "_local_ts_utc": "2026-06-01T07:48:58.210197+00:00"}
{"e": "depthUpdate", "E": 1780300139414, "s": "BTCUSDT", "U": 94551760915, "u": 94551761033, "b": [["72751.00000000", "0.94865000"], ["72750.99000000", "0.00086000"], ["72750.53000000", "0.00000000"], ["72750.25000000", "0.00000000"], ["72750.02000000", "0.00000000"], ["72750.01000000", "0.00040000"], ["72749.04000000", "0.00000000"], ["72748.68000000", "0.00000000"], ["72748.67000000", "0.00016000"], ["72748.51000000", "0.00016000"], ["72747.71000000", "0.02072000"], ["72746.59000000", "0.02415000"], ["72746.44000000", "0.00016000"], ["72746.43000000", "0.00000000"], ["72745.99000000", "0.00031000"], ["72745.35000000", "0.00000000"], ["72744.60000000", "0.08757000"], ["72744.55000000", "0.00031000"], ["72743.98000000", "0.00000000"], ["72743.64000000", "0.05942000"], ["72741.85000000", "0.00000000"], ["72741.34000000", "0.00069000"], ["72741.05000000", "0.31558000"], ["72741.04000000", "0.65949000"], ["72741.03000000", "0.00000000"], ["72741.02000000", "0.00000000"], ["72741.01000000", "0.00000000"], ["72738.89000000", "0.00000000"], ["72738.64000000", "0.00000000"], ["72736.84000000", "0.00000000"], ["72734.71000000", "0.00000000"], ["72730.17000000", "0.18141000"], ["72726.39000000", "0.00000000"], ["72724.69000000", "0.00686000"], ["72724.62000000", "0.00200000"], ["72723.96000000", "0.00000000"], ["72720.94000000", "0.00000000"], ["72712.94000000", "0.00000000"], ["72710.88000000", "0.00778000"], ["72707.03000000", "0.00000000"], ["72703.81000000", "0.18117000"], ["72693.80000000", "0.00000000"], ["72692.62000000", "0.00000000"], ["72681.63000000", "0.00686000"], ["72677.82000000", "1.36388000"], ["72667.40000000", "0.10821000"], ["72624.40000000", "0.00574000"], ["72552.59000000", "0.00000000"], ["72550.45000000", "0.00822000"], ["65475.90000000", "0.00374000"]], "a": [["72751.01000000", "3.27331000"], ["72751.02000000", "0.00374000"], ["72753.22000000", "0.00000000"], ["72753.35000000", "0.03436000"], ["72753.77000000", "0.00000000"], ["72753.78000000", "0.00016000"], ["72753.97000000", "0.04914000"], ["72755.60000000", "0.00771000"], ["72756.76000000", "0.03407000"], ["72767.50000000", "0.49534000"], ["72768.70000000", "0.18125000"], ["72772.46000000", "0.18117000"], ["72772.55000000", "0.18117000"], ["72782.18000000", "0.00000000"], ["72782.83000000", "0.00200000"], ["72793.03000000", "0.00000000"], ["72807.41000000", "0.26000000"]], "_local_ts_utc": "2026-06-01T07:48:58.310689+00:00"}
{"e": "depthUpdate", "E": 1780300139514, "s": "BTCUSDT", "U": 94551761034, "u": 94551761126, "b": [["72751.00000000", "0.94667000"], ["72750.99000000", "0.00070000"], ["72750.01000000", "0.00024000"], ["72749.54000000", "0.00941000"], ["72748.67000000", "0.00000000"], ["72748.51000000", "0.00000000"], ["72748.00000000", "0.02296000"], ["72747.88000000", "0.00031000"], ["72747.72000000", "0.04318000"], ["72747.71000000", "0.02088000"], ["72747.30000000", "0.00031000"], ["72746.84000000", "0.00000000"], ["72746.59000000", "0.02431000"], ["72746.44000000", "0.00000000"], ["72745.99000000", "0.00000000"], ["72744.61000000", "0.12725000"], ["72744.60000000", "0.00000000"], ["72744.55000000", "0.00000000"], ["72741.66000000", "0.00048000"], ["72736.84000000", "0.18117000"], ["72735.27000000", "0.16827000"], ["72734.71000000", "0.18117000"], ["72724.69000000", "0.00000000"], ["72707.66000000", "0.23193000"], ["72705.76000000", "0.18125000"], ["72703.77000000", "0.00000000"], ["72699.33000000", "0.18117000"], ["72697.04000000", "0.00000000"], ["72693.80000000", "0.17692000"], ["72692.62000000", "0.18117000"], ["72678.01000000", "0.78740000"], ["72669.54000000", "0.00686000"], ["72648.21000000", "0.00686000"], ["72634.88000000", "0.00574000"], ["71298.76000000", "0.02415000"], ["65475.90000000", "0.00374000"], ["58200.80000000", "0.00034000"]], "a": [["72751.01000000", "3.27354000"], ["72751.02000000", "0.00382000"], ["72753.35000000", "0.03436000"], ["72753.77000000", "0.00775000"], ["72753.78000000", "0.00000000"], ["72753.85000000", "0.07093000"], ["72753.97000000", "0.04930000"], ["72772.46000000", "0.00000000"], ["72772.55000000", "0.00000000"], ["72774.06000000", "0.00000000"], ["72806.62000000", "0.02751000"], ["72842.97000000", "0.00000000"], ["72887.25000000", "0.00000000"], ["72939.86000000", "0.00686000"], ["74939.89000000", "0.00000000"], ["88223.42000000", "0.00000000"]], "_local_ts_utc": "2026-06-01T07:48:58.410224+00:00"}
{"e": "depthUpdate", "E": 1780300139614, "s": "BTCUSDT", "U": 94551761127, "u": 94551761189, "b": [["72751.00000000", "0.94528000"], ["72748.00000000", "0.02296000"], ["72747.88000000", "0.00000000"], ["72747.72000000", "0.00000000"], ["72744.61000000", "0.09470000"], ["72744.51000000", "0.00000000"], ["72743.75000000", "0.01375000"], ["72742.70000000", "0.00000000"], ["72741.66000000", "0.00000000"], ["72741.48000000", "0.00048000"], ["72738.42000000", "0.01375000"], ["72735.49000000", "0.18693000"], ["72728.43000000", "0.01376000"], ["72712.91000000", "0.00007000"], ["72664.30000000", "2.03633000"], ["72645.35000000", "0.00574000"], ["72517.44000000", "0.00007000"], ["65475.90000000", "0.00391000"], ["58200.80000000", "0.00000000"]], "a": [["72752.09000000", "0.00008000"], ["72753.35000000", "0.03436000"], ["72753.77000000", "0.00016000"], ["72753.83000000", "0.00783000"], ["72753.97000000", "0.04914000"], ["72754.07000000", "0.00000000"], ["72758.74000000", "0.00008000"], ["72758.96000000", "0.00000000"], ["72759.70000000", "0.17711000"], ["72760.00000000", "0.00643000"], ["72765.30000000", "0.00008000"], ["72765.65000000", "0.00400000"], ["72767.49000000", "0.00008000"], ["72767.51000000", "0.00000000"], ["72772.62000000", "0.00200000"], ["72774.55000000", "0.00000000"], ["72774.98000000", "0.00008000"], ["72775.34000000", "0.00275000"], ["72777.13000000", "0.00000000"], ["72777.37000000", "0.00008000"], ["72779.29000000", "0.00200000"], ["72779.74000000", "0.00000000"], ["72782.07000000", "0.00000000"], ["72800.43000000", "1.18413000"], ["88228.57000000", "0.00355000"]], "_local_ts_utc": "2026-06-01T07:48:58.510502+00:00"}
{"e": "depthUpdate", "E": 1780300139714, "s": "BTCUSDT", "U": 94551761190, "u": 94551761211, "b": [["72751.00000000", "0.94128000"], ["72748.00000000", "0.02296000"], ["72741.79000000", "0.00751000"], ["72655.83000000", "0.00573000"], ["65475.90000000", "0.00374000"]], "a": [["72753.35000000", "0.03436000"], ["72753.77000000", "0.00775000"], ["72753.83000000", "0.00024000"], ["72779.74000000", "0.95929000"]], "_local_ts_utc": "2026-06-01T07:48:58.610155+00:00"}
{"e": "depthUpdate", "E": 1780300139814, "s": "BTCUSDT", "U": 94551761212, "u": 94551761236, "b": [["72751.00000000", "0.93240000"], ["72666.30000000", "0.00573000"], ["65475.90000000", "0.00374000"]], "a": [["72753.35000000", "0.03436000"], ["72753.77000000", "0.00016000"], ["72753.83000000", "0.00783000"], ["72772.62000000", "0.00000000"], ["72797.80000000", "0.01373000"], ["72805.93000000", "0.00686000"], ["72822.30000000", "0.00686000"], ["72838.66000000", "0.00686000"], ["72896.58000000", "0.00000000"], ["72903.64000000", "0.00000000"], ["72920.02000000", "0.00000000"], ["72939.86000000", "0.00000000"], ["88789.71000000", "0.00000000"]], "_local_ts_utc": "2026-06-01T07:48:58.709773+00:00"}
{"e": "depthUpdate", "E": 1780300139914, "s": "BTCUSDT", "U": 94551761237, "u": 94551761270, "b": [["72751.00000000", "0.92624000"], ["72748.29000000", "0.00031000"], ["72747.96000000", "0.00031000"], ["72747.37000000", "0.00031000"], ["72747.30000000", "0.00000000"], ["72741.06000000", "0.16524000"], ["72739.56000000", "0.17070000"], ["72676.78000000", "0.00573000"], ["65475.90000000", "0.00374000"], ["65475.00000000", "0.00109000"]], "a": [["72751.01000000", "3.27378000"], ["72751.02000000", "0.00406000"], ["72753.35000000", "0.03436000"], ["72753.77000000", "0.00775000"], ["72753.83000000", "0.00024000"], ["72771.36000000", "0.00200000"]], "_local_ts_utc": "2026-06-01T07:48:58.810445+00:00"}
{"e": "depthUpdate", "E": 1780300140014, "s": "BTCUSDT", "U": 94551761271, "u": 94551761324, "b": [["72749.10000000", "0.00031000"], ["72747.96000000", "0.00000000"], ["72747.72000000", "0.04309000"], ["72747.37000000", "0.00000000"], ["72741.48000000", "0.00000000"], ["72733.65000000", "0.02007000"], ["72730.18000000", "0.77189000"], ["72724.62000000", "0.00000000"], ["72720.73000000", "0.00210000"], ["72716.89000000", "0.00400000"], ["72702.01000000", "0.00343000"], ["72687.25000000", "0.00573000"], ["72629.24000000", "0.00137000"], ["72628.70000000", "0.00000000"], ["72603.82000000", "0.01691000"], ["65503.41000000", "0.00030000"], ["65475.90000000", "0.00374000"], ["65475.00000000", "0.00089000"], ["58200.80000000", "0.00034000"]], "a": [["72751.01000000", "3.27354000"], ["72751.02000000", "0.00382000"], ["72753.35000000", "0.03436000"], ["72753.77000000", "0.00016000"], ["72753.83000000", "0.41657000"], ["72762.76000000", "0.00007000"], ["72765.99000000", "0.68814000"], ["72766.73000000", "0.45893000"], ["72773.36000000", "0.00000000"], ["72778.93000000", "0.00200000"], ["72779.99000000", "0.00400000"], ["72782.83000000", "0.00000000"], ["72807.40000000", "0.00189000"], ["72880.56000000", "0.00075000"], ["72924.53000000", "0.00000000"], ["89169.94000000", "0.00000000"]], "_local_ts_utc": "2026-06-01T07:48:58.910788+00:00"}
{"e": "depthUpdate", "E": 1780300140114, "s": "BTCUSDT", "U": 94551761325, "u": 94551761388, "b": [["72751.00000000", "0.92180000"], ["72749.10000000", "0.00000000"], ["72748.29000000", "0.00000000"], ["72748.00000000", "0.02296000"], ["72747.72000000", "0.00000000"], ["72747.32000000", "0.00031000"], ["72747.12000000", "0.00031000"], ["72744.61000000", "0.10020000"], ["72744.54000000", "0.00550000"], ["72730.19000000", "0.79037000"], ["72730.17000000", "0.00024000"], ["72730.11000000", "0.00000000"], ["72727.08000000", "0.00000000"], ["72721.74000000", "0.00400000"], ["72718.10000000", "0.00400000"], ["72717.00000000", "0.00463000"], ["72716.89000000", "0.00000000"], ["72697.73000000", "0.00573000"], ["72693.80000000", "0.00000000"], ["72673.83000000", "0.82582000"], ["72640.47000000", "0.04432000"], ["65475.90000000", "0.00374000"], ["58201.00000000", "0.08468000"], ["58200.80000000", "0.00044000"]], "a": [["72751.01000000", "3.28454000"], ["72753.35000000", "0.03436000"], ["72753.77000000", "0.00793000"], ["72753.82000000", "0.81229000"], ["72753.83000000", "0.40880000"], ["72754.50000000", "0.00400000"], ["72755.00000000", "0.18125000"], ["72756.32000000", "0.00400000"], ["72763.80000000", "0.61834000"], ["72768.70000000", "0.00008000"], ["72779.99000000", "0.00000000"], ["72780.08000000", "0.00400000"], ["72781.80000000", "0.00400000"], ["72783.62000000", "0.00000000"], ["72819.31000000", "0.82582000"], ["72858.72000000", "0.04266000"], ["89317.29000000", "0.00000000"]], "_local_ts_utc": "2026-06-01T07:48:59.010600+00:00"}
{"e": "depthUpdate", "E": 1780300140214, "s": "BTCUSDT", "U": 94551761389, "u": 94551761535, "b": [["72751.00000000", "2.21499000"], ["72750.03000000", "0.00031000"], ["72750.01000000", "0.35643000"], ["72749.42000000", "0.00031000"], ["72748.05000000", "0.00000000"], ["72748.00000000", "0.02296000"], ["72747.97000000", "0.02807000"], ["72747.72000000", "0.04300000"], ["72747.71000000", "0.00016000"], ["72747.32000000", "0.00000000"], ["72747.12000000", "0.00000000"], ["72744.61000000", "0.09470000"], ["72744.54000000", "0.00000000"], ["72743.64000000", "0.00000000"], ["72742.42000000", "0.18117000"], ["72740.24000000", "0.19304000"], ["72735.49000000", "0.00000000"], ["72730.20000000", "0.18117000"], ["72728.43000000", "0.00000000"], ["65475.90000000", "0.00374000"], ["58200.80000000", "0.00000000"]], "a": [["72751.01000000", "3.27362000"], ["72751.02000000", "0.00390000"], ["72752.09000000", "0.00024000"], ["72752.43000000", "0.00016000"], ["72753.10000000", "0.00000000"], ["72753.11000000", "0.00016000"], ["72753.34000000", "0.00016000"], ["72753.35000000", "0.03436000"], ["72753.77000000", "0.00016000"], ["72753.80000000", "0.00000000"], ["72753.81000000", "0.00016000"], ["72753.82000000", "0.82046000"], ["72753.84000000", "0.18117000"], ["72753.85000000", "0.07077000"], ["72753.97000000", "0.00000000"], ["72755.08000000", "0.04741000"], ["72756.76000000", "0.00000000"], ["72757.82000000", "0.65949000"], ["72757.84000000", "0.00000000"], ["72759.59000000", "0.00000000"], ["72759.70000000", "0.00036000"], ["72762.20000000", "0.00008000"], ["72762.81000000", "0.00008000"], ["72763.80000000", "0.40943000"], ["72765.31000000", "0.00000000"], ["72765.65000000", "0.00000000"], ["72765.99000000", "0.00000000"], ["72766.73000000", "0.00008000"], ["72766.74000000", "0.00000000"], ["72766.98000000", "0.00400000"], ["72767.99000000", "0.68814000"], ["72768.06000000", "0.00008000"], ["72768.07000000", "0.56700000"], ["72768.71000000", "0.00000000"], ["72779.29000000", "0.00000000"], ["72780.11000000", "0.00200000"], ["72848.44000000", "1.09047000"], ["72857.35000000", "2.74910000"]], "_local_ts_utc": "2026-06-01T07:48:59.131619+00:00"}
{"e": "depthUpdate", "E": 1780300140314, "s": "BTCUSDT", "U": 94551761536, "u": 94551761660, "b": [["72751.00000000", "2.16528000"], ["72750.12000000", "0.00000000"], ["72750.03000000", "0.00000000"], ["72750.02000000", "0.00000000"], ["72750.01000000", "0.00040000"], ["72749.42000000", "0.00000000"], ["72748.00000000", "0.02296000"], ["72747.99000000", "0.00016000"], ["72747.98000000", "0.00000000"], ["72747.97000000", "0.02823000"], ["72747.72000000", "0.00016000"], ["72747.71000000", "0.00000000"], ["72747.05000000", "0.00057000"], ["72746.59000000", "0.02415000"], ["72745.74000000", "0.00000000"], ["72744.28000000", "0.00000000"], ["72741.57000000", "0.00069000"], ["72741.34000000", "0.00000000"], ["72740.24000000", "0.00000000"], ["72724.69000000", "0.00686000"], ["72723.07000000", "0.00200000"], ["72720.73000000", "0.00010000"], ["72708.32000000", "0.00696000"], ["72708.20000000", "0.00573000"], ["72669.54000000", "0.00000000"], ["72648.21000000", "0.00000000"], ["65475.90000000", "0.00374000"]], "a": [["72751.01000000", "2.82893000"], ["72751.02000000", "0.00398000"], ["72751.61000000", "0.00016000"], ["72751.62000000", "0.05942000"], ["72752.44000000", "0.17556000"], ["72753.05000000", "0.01100000"], ["72753.11000000", "0.00000000"], ["72753.34000000", "0.00000000"], ["72753.35000000", "0.03436000"], ["72753.77000000", "0.00793000"], ["72753.80000000", "0.00000000"], ["72753.81000000", "0.65949000"], ["72753.82000000", "0.81245000"], ["72753.84000000", "0.18133000"], ["72753.85000000", "0.07093000"], ["72763.80000000", "0.28450000"], ["72766.74000000", "0.17579000"], ["72767.19000000", "0.18125000"], ["72767.49000000", "0.92661000"], ["72768.07000000", "0.00000000"], ["72768.71000000", "0.45885000"], ["72772.46000000", "0.18117000"], ["72772.55000000", "0.18117000"], ["72778.93000000", "0.00000000"], ["72781.29000000", "0.00200000"], ["81577.77000000", "0.00519000"], ["89497.83000000", "0.00000000"]], "_local_ts_utc": "2026-06-01T07:48:59.210689+00:00"}
{"e": "depthUpdate", "E": 1780300140414, "s": "BTCUSDT", "U": 94551761661, "u": 94551761819, "b": [["72751.00000000", "1.52642000"], ["72750.01000000", "0.00024000"], ["72748.58000000", "0.00000000"], ["72747.99000000", "0.00031000"], ["72747.98000000", "0.00000000"], ["72747.97000000", "0.02823000"], ["72747.72000000", "0.00000000"], ["72747.13000000", "0.00031000"], ["72746.59000000", "0.02431000"], ["72746.25000000", "0.00000000"], ["72746.00000000", "0.02296000"], ["72742.42000000", "0.00000000"], ["72741.57000000", "0.00000000"], ["72734.71000000", "0.00000000"], ["72730.20000000", "0.00000000"], ["72724.69000000", "0.00000000"], ["72718.68000000", "0.00573000"], ["72718.35000000", "0.00000000"], ["65475.90000000", "0.00391000"]], "a": [["72751.01000000", "3.01316000"], ["72751.02000000", "0.00398000"], ["72751.61000000", "0.00000000"], ["72751.62000000", "0.05958000"], ["72752.09000000", "0.00008000"], ["72752.27000000", "0.01100000"], ["72752.43000000", "0.00000000"], ["72752.44000000", "0.17556000"], ["72753.05000000", "0.00016000"], ["72753.35000000", "0.03436000"], ["72753.77000000", "0.00016000"], ["72753.81000000", "0.66758000"], ["72753.82000000", "0.81229000"], ["72753.83000000", "0.40864000"], ["72753.84000000", "0.18117000"], ["72753.85000000", "0.07077000"], ["72759.59000000", "0.18117000"], ["72759.70000000", "0.17315000"], ["72762.20000000", "0.18125000"], ["72762.81000000", "0.17381000"], ["72765.31000000", "0.18117000"], ["72768.70000000", "2.74918000"], ["72857.35000000", "0.00000000"], ["82351.89000000", "0.00342000"], ["82385.16000000", "0.00684000"], ["83168.68000000", "0.00338000"], ["83235.10000000", "0.00338000"], ["83276.27000000", "0.00338000"]], "_local_ts_utc": "2026-06-01T07:48:59.310500+00:00"}
{"e": "depthUpdate", "E": 1780300140514, "s": "BTCUSDT", "U": 94551761820, "u": 94551761974, "b": [["72751.00000000", "1.52392000"], ["72747.99000000", "0.00000000"], ["72747.98000000", "0.00000000"], ["72747.81000000", "0.00031000"], ["72747.13000000", "0.00000000"], ["72746.77000000", "0.00000000"], ["72744.61000000", "0.00000000"], ["72742.42000000", "0.18117000"], ["72741.05000000", "0.00000000"], ["72741.04000000", "0.00000000"], ["72737.80000000", "0.00000000"], ["72737.40000000", "0.14802000"], ["72734.71000000", "0.17661000"], ["72734.70000000", "0.00000000"], ["72734.68000000", "0.00000000"], ["72730.20000000", "0.17820000"], ["72730.18000000", "0.00000000"], ["72729.15000000", "0.00584000"], ["72718.35000000", "0.18117000"], ["72708.32000000", "0.00010000"], ["72693.80000000", "0.18117000"], ["72687.07000000", "0.00000000"], ["65475.90000000", "0.00408000"], ["58200.80000000", "0.00034000"]], "a": [["72751.01000000", "3.02392000"], ["72751.02000000", "0.00406000"], ["72751.61000000", "0.00016000"], ["72751.76000000", "0.00008000"], ["72752.09000000", "0.00024000"], ["72752.10000000", "0.01420000"], ["72752.27000000", "0.00016000"], ["72752.43000000", "0.00016000"], ["72752.44000000", "0.17556000"], ["72753.05000000", "0.00000000"], ["72753.34000000", "0.00016000"], ["72753.35000000", "0.03436000"], ["72753.77000000", "0.00811000"], ["72753.80000000", "0.00000000"], ["72753.81000000", "0.65965000"], ["72753.82000000", "0.81245000"], ["72756.44000000", "0.03407000"], ["72762.20000000", "0.00008000"], ["72762.81000000", "0.00008000"], ["72765.31000000", "0.00000000"], ["72767.49000000", "1.76572000"], ["72772.46000000", "0.00000000"], ["72772.55000000", "0.00000000"], ["82385.16000000", "0.00684000"], ["82859.34000000", "0.00340000"], ["82941.94000000", "0.00340000"], ["83220.87000000", "0.00338000"], ["89513.33000000", "0.00016000"]], "_local_ts_utc": "2026-06-01T07:48:59.411627+00:00"}
{"e": "depthUpdate", "E": 1780300140614, "s": "BTCUSDT", "U": 94551761975, "u": 94551762287, "b": [["72751.00000000", "0.75709000"], ["72749.92000000", "0.00106000"], ["72748.48000000", "0.00106000"], ["72748.16000000", "0.00000000"], ["72747.97000000", "0.00016000"], ["72747.81000000", "0.00000000"], ["72747.44000000", "0.01888000"], ["72746.88000000", "0.00031000"], ["72746.28000000", "0.00031000"], ["72743.24000000", "0.00000000"], ["72742.42000000", "0.00000000"], ["72741.68000000", "0.00000000"], ["72739.63000000", "0.00573000"], ["72736.86000000", "1.33118000"], ["72736.85000000", "3.40859000"], ["72736.83000000", "0.00000000"], ["72734.01000000", "0.14920000"], ["72732.41000000", "0.18117000"], ["72730.98000000", "0.18136000"], ["72730.92000000", "0.01376000"], ["72730.22000000", "0.61079000"], ["72730.21000000", "1.06805000"], ["72730.19000000", "0.00000000"], ["72730.16000000", "0.00000000"], ["72730.09000000", "0.00000000"], ["72728.12000000", "0.18117000"], ["72727.09000000", "1.97525000"], ["72727.08000000", "3.40859000"], ["72727.07000000", "0.00000000"], ["72727.06000000", "0.00000000"], ["72725.26000000", "0.00000000"], ["72723.83000000", "0.00000000"], ["72722.40000000", "0.00000000"], ["72722.27000000", "0.48955000"], ["72721.24000000", "0.65949000"], ["72721.18000000", "0.00000000"], ["72719.54000000", "0.00011000"], ["72718.10000000", "0.00800000"], ["72717.00000000", "0.00063000"], ["72715.38000000", "0.00007000"], ["72713.92000000", "0.00000000"], ["72712.39000000", "0.00000000"], ["72711.26000000", "0.00000000"], ["72709.59000000", "0.00000000"], ["72708.10000000", "0.00000000"], ["72706.67000000", "0.00333000"], ["72696.66000000", "0.00000000"], ["72696.01000000", "0.00000000"], ["72693.86000000", "1.03998000"], ["72693.80000000", "0.00000000"], ["72692.62000000", "0.00000000"], ["72645.94000000", "0.00000000"], ["72634.29000000", "0.00000000"], ["72555.01000000", "0.00822000"], ["72550.45000000", "0.00000000"], ["72512.49000000", "0.00194000"], ["72511.35000000", "0.00007000"], ["65475.90000000", "0.00408000"], ["58200.80000000", "0.00000000"]], "a": [["72751.01000000", "3.33070000"], ["72751.02000000", "0.00430000"], ["72751.61000000", "0.00000000"], ["72751.62000000", "0.00016000"], ["72752.09000000", "0.00000000"], ["72752.10000000", "0.01420000"], ["72752.27000000", "0.00000000"], ["72752.43000000", "0.00000000"], ["72753.34000000", "0.00000000"], ["72753.35000000", "0.03436000"], ["72753.77000000", "0.00016000"], ["72753.81000000", "0.66784000"], ["72753.83000000", "0.40856000"], ["72753.85000000", "0.12574000"], ["72755.08000000", "0.00000000"], ["72757.81000000", "0.00008000"], ["72757.83000000", "0.18117000"], ["72758.74000000", "0.00000000"], ["72759.58000000", "0.00008000"], ["72759.70000000", "0.17307000"], ["72762.20000000", "0.18125000"], ["72762.81000000", "0.18125000"], ["72763.79000000", "0.00008000"], ["72765.31000000", "0.18117000"], ["72767.18000000", "0.00008000"], ["72767.19000000", "0.18117000"], ["72767.48000000", "0.00008000"], ["72767.49000000", "1.76564000"], ["72768.06000000", "0.00000000"], ["72768.69000000", "0.00008000"], ["72771.56000000", "0.00000000"], ["72773.35000000", "0.00000000"], ["72774.98000000", "0.00000000"], ["72779.73000000", "0.00008000"], ["72780.53000000", "0.00008000"], ["90321.56000000", "0.00000000"]], "_local_ts_utc": "2026-06-01T07:48:59.510623+00:00"}
{"e": "depthUpdate", "E": 1780300140727, "s": "BTCUSDT", "U": 94551762288, "u": 94551762544, "b": [["72751.00000000", "0.02814000"], ["72750.99000000", "0.00086000"], ["72748.00000000", "0.02296000"], ["72747.97000000", "0.00000000"], ["72747.44000000", "0.01904000"], ["72747.22000000", "0.00000000"], ["72746.88000000", "0.00000000"], ["72746.28000000", "0.00000000"], ["72745.63000000", "0.00000000"], ["72745.36000000", "0.00000000"], ["72743.75000000", "0.00000000"], ["72742.22000000", "0.00000000"], ["72741.79000000", "0.00000000"], ["72741.44000000", "0.00048000"], ["72741.20000000", "0.00068000"], ["72741.06000000", "0.00000000"], ["72740.17000000", "0.01436000"], ["72739.56000000", "0.00015000"], ["72738.42000000", "0.00000000"], ["72738.13000000", "0.00000000"], ["72737.40000000", "0.00000000"], ["72736.87000000", "0.00000000"], ["72736.86000000", "0.00000000"], ["72736.85000000", "0.00000000"], ["72736.84000000", "0.00000000"], ["72736.82000000", "0.00000000"], ["72735.27000000", "0.00000000"], ["72734.71000000", "0.00000000"], ["72734.01000000", "0.00012000"], ["72732.41000000", "0.00000000"], ["72731.91000000", "0.00000000"], ["72730.98000000", "0.00019000"], ["72730.92000000", "0.00000000"], ["72730.23000000", "0.65949000"], ["72730.22000000", "0.00000000"], ["72730.21000000", "0.00000000"], ["72730.20000000", "0.00000000"], ["72728.12000000", "0.00000000"], ["72727.81000000", "0.00000000"], ["72727.09000000", "0.00000000"], ["72727.08000000", "0.00000000"], ["72725.38000000", "0.00400000"], ["72724.47000000", "0.00000000"], ["72723.35000000", "0.00000000"], ["72722.27000000", "0.00000000"], ["72722.25000000", "0.02015000"], ["72721.49000000", "0.65949000"], ["72721.24000000", "0.00000000"], ["72720.25000000", "0.02022000"], ["72718.35000000", "0.00000000"], ["72718.34000000", "0.00000000"], ["72718.32000000", "0.00000000"], ["72718.10000000", "0.00400000"], ["72716.78000000", "0.00000000"], ["72716.68000000", "0.00000000"], ["72715.97000000", "0.65949000"], ["72715.96000000", "0.00000000"], ["72715.95000000", "0.00000000"], ["72715.61000000", "0.00000000"], ["72714.46000000", "0.00400000"], ["72713.91000000", "0.00000000"], ["72713.85000000", "0.00000000"], ["72713.67000000", "0.00022000"], ["72711.25000000", "0.00000000"], ["72709.12000000", "0.00000000"], ["72707.66000000", "0.00000000"], ["72705.76000000", "0.00008000"], ["72702.55000000", "0.00000000"], ["72702.01000000", "0.00000000"], ["72699.33000000", "0.00000000"], ["72697.04000000", "0.00000000"], ["72684.55000000", "0.00305000"], ["72681.63000000", "0.00000000"], ["72673.84000000", "0.44348000"], ["72673.83000000", "0.00000000"], ["72673.29000000", "0.00000000"], ["72653.12000000", "0.00011000"], ["72645.94000000", "2.74910000"], ["72634.29000000", "2.74910000"], ["72629.24000000", "0.00000000"], ["72539.45000000", "0.12264000"], ["72058.83000000", "0.00000000"], ["71885.46000000", "1.03777000"], ["65475.90000000", "0.00408000"]], "a": [["72751.01000000", "3.32990000"], ["72751.02000000", "0.00374000"], ["72751.50000000", "0.03407000"], ["72751.62000000", "0.00000000"], ["72752.68000000", "0.00400000"], ["72753.35000000", "0.03436000"], ["72753.77000000", "0.00811000"], ["72753.81000000", "0.65973000"], ["72753.83000000", "0.40872000"], ["72753.84000000", "0.18133000"], ["72760.57000000", "0.00573000"], ["72768.69000000", "0.18125000"], ["72772.46000000", "0.18117000"], ["72772.55000000", "0.18117000"], ["72772.97000000", "1.36210000"], ["72779.65000000", "0.00400000"], ["72780.08000000", "0.00000000"], ["72781.80000000", "0.00000000"], ["72811.24000000", "0.00000000"]], "_local_ts_utc": "2026-06-01T07:48:59.625300+00:00"}
{"e": "depthUpdate", "E": 1780300140864, "s": "BTCUSDT", "U": 94551762545, "u": 94551763779, "b": [["72751.00000000", "0.00000000"], ["72750.99000000", "0.00000000"], ["72750.98000000", "0.00000000"], ["72750.27000000", "0.00000000"], ["72750.01000000", "0.00000000"], ["72750.00000000", "0.00000000"], ["72749.92000000", "0.00000000"], ["72749.76000000", "0.00000000"], ["72749.75000000", "0.00000000"], ["72749.71000000", "0.00000000"], ["72749.70000000", "0.00000000"], ["72749.54000000", "0.00000000"], ["72749.52000000", "0.00000000"], ["72749.27000000", "0.00000000"], ["72749.08000000", "0.00000000"], ["72748.53000000", "0.00000000"], ["72748.48000000", "0.00000000"], ["72748.35000000", "0.00000000"], ["72748.17000000", "0.00000000"], ["72748.15000000", "0.00000000"], ["72748.08000000", "0.00000000"], ["72748.00000000", "0.00000000"], ["72747.93000000", "0.00000000"], ["72747.92000000", "0.00000000"], ["72747.91000000", "0.00000000"], ["72747.53000000", "0.00000000"], ["72747.44000000", "0.00000000"], ["72747.42000000", "0.00000000"], ["72747.40000000", "0.00000000"], ["72747.16000000", "0.00000000"], ["72747.05000000", "0.00000000"], ["72747.03000000", "0.00000000"], ["72747.00000000", "0.00000000"], ["72746.78000000", "0.00000000"], ["72746.72000000", "0.00000000"], ["72746.67000000", "0.00000000"], ["72746.66000000", "0.00000000"], ["72746.65000000", "0.00000000"], ["72746.59000000", "0.00000000"], ["72746.45000000", "0.00000000"], ["72746.31000000", "0.00000000"], ["72746.24000000", "0.00000000"], ["72746.00000000", "0.00000000"], ["72745.94000000", "0.00000000"], ["72745.90000000", "0.00000000"], ["72745.46000000", "0.00000000"], ["72745.45000000", "0.00000000"], ["72745.40000000", "0.00000000"], ["72745.33000000", "0.00000000"], ["72745.06000000", "0.00000000"], ["72745.00000000", "0.00000000"], ["72744.82000000", "0.00000000"], ["72744.66000000", "0.00000000"], ["72744.59000000", "0.00000000"], ["72744.47000000", "0.00000000"], ["72744.42000000", "0.00000000"], ["72744.30000000", "0.00000000"], ["72744.11000000", "0.00000000"], ["72744.08000000", "0.00000000"], ["72744.00000000", "0.00000000"], ["72743.58000000", "0.00000000"], ["72743.56000000", "0.00000000"], ["72743.38000000", "0.00000000"], ["72743.36000000", "0.00000000"], ["72743.16000000", "0.00000000"], ["72743.11000000", "0.00000000"], ["72742.85000000", "0.00000000"], ["72742.73000000", "0.00000000"], ["72742.56000000", "0.00000000"], ["72742.35000000", "0.00000000"], ["72742.31000000", "0.00000000"], ["72742.28000000", "0.00000000"], ["72742.00000000", "1.95708000"], ["72741.82000000", "0.00000000"], ["72741.76000000", "0.00000000"], ["72741.44000000", "0.00000000"], ["72740.98000000", "0.00024000"], ["72740.33000000", "0.00000000"], ["72740.28000000", "0.00269000"], ["72740.18000000", "0.00008000"], ["72740.17000000", "0.00000000"], ["72740.11000000", "0.00000000"], ["72740.01000000", "0.00008000"], ["72740.00000000", "0.02326000"], ["72739.96000000", "0.00000000"], ["72739.94000000", "0.00000000"], ["72739.82000000", "0.00000000"], ["72739.77000000", "0.00000000"], ["72739.06000000", "0.00000000"], ["72738.69000000", "0.04000000"], ["72738.36000000", "0.00008000"], ["72738.09000000", "0.00000000"], ["72737.09000000", "0.00000000"], ["72737.08000000", "0.00000000"], ["72737.00000000", "0.00028000"], ["72736.99000000", "0.00031000"], ["72736.73000000", "0.00021000"], ["72736.45000000", "0.00300000"], ["72735.13000000", "0.00000000"], ["72734.63000000", "0.02000000"], ["72734.57000000", "0.01484000"], ["72734.30000000", "0.00000000"], ["72733.04000000", "0.00031000"], ["72732.41000000", "0.00000000"], ["72730.98000000", "0.00019000"], ["72730.24000000", "0.00008000"], ["72730.23000000", "0.00000000"], ["72730.07000000", "0.00000000"], ["72729.70000000", "0.17752000"], ["72729.61000000", "0.00000000"], ["72729.54000000", "0.00000000"], ["72729.18000000", "0.00000000"], ["72728.27000000", "0.18120000"], ["72728.12000000", "0.00000000"], ["72727.91000000", "0.00165000"], ["72727.52000000", "0.00008000"], ["72727.51000000", "0.00104000"], ["72727.12000000", "0.00000000"], ["72727.11000000", "0.00000000"], ["72727.03000000", "0.00000000"], ["72727.01000000", "0.65949000"], ["72726.92000000", "0.00137000"], ["72726.84000000", "0.18120000"], ["72726.82000000", "0.00008000"], ["72726.81000000", "0.00000000"], ["72725.54000000", "0.00000000"], ["72725.41000000", "0.18120000"], ["72725.26000000", "0.18117000"], ["72724.64000000", "0.00008000"], ["72724.63000000", "0.00000000"], ["72723.83000000", "0.18117000"], ["72722.96000000", "2.77642000"], ["72722.81000000", "0.07000000"], ["72722.60000000", "0.00000000"], ["72722.40000000", "0.18117000"], ["72722.27000000", "0.65957000"], ["72722.25000000", "0.00015000"], ["72721.90000000", "0.00000000"], ["72721.89000000", "0.00000000"], ["72721.81000000", "0.08000000"], ["72721.59000000", "0.00000000"], ["72721.50000000", "0.00008000"], ["72721.49000000", "0.00000000"], ["72721.17000000", "0.00000000"], ["72720.25000000", "0.00022000"], ["72720.01000000", "0.18145000"], ["72719.54000000", "0.18117000"], ["72719.08000000", "0.65949000"], ["72718.35000000", "0.00000000"], ["72718.27000000", "0.00000000"], ["72718.11000000", "0.18117000"], ["72716.68000000", "0.18117000"], ["72716.35000000", "0.00000000"], ["72716.01000000", "0.65949000"], ["72715.98000000", "0.00000000"], ["72715.97000000", "0.00000000"], ["72715.95000000", "0.00008000"], ["72715.94000000", "0.00000000"], ["72715.66000000", "0.00000000"], ["72715.41000000", "0.00000000"], ["72715.24000000", "0.03427000"], ["72714.63000000", "0.02000000"], ["72714.21000000", "0.00007000"], ["72713.97000000", "0.18120000"], ["72713.82000000", "0.18117000"], ["72713.67000000", "0.00000000"], ["72713.34000000", "0.00000000"], ["72713.08000000", "0.00000000"], ["72712.64000000", "0.00400000"], ["72712.39000000", "0.18117000"], ["72711.58000000", "0.00000000"], ["72711.45000000", "0.00007000"], ["72710.96000000", "0.18117000"], ["72710.82000000", "0.00400000"], ["72709.59000000", "0.18117000"], ["72709.34000000", "0.02067000"], ["72709.00000000", "0.00400000"], ["72708.10000000", "0.18117000"], ["72707.76000000", "0.00007000"], ["72707.34000000", "0.00000000"], ["72707.18000000", "0.00400000"], ["72706.91000000", "0.00000000"], ["72706.67000000", "0.18450000"], ["72705.76000000", "0.00008000"], ["72704.78000000", "0.00022000"], ["72704.77000000", "0.18118000"], ["72704.33000000", "0.12264000"], ["72704.24000000", "0.00000000"], ["72704.20000000", "1.33288000"], ["72703.72000000", "0.00000000"], ["72702.94000000", "0.02415000"], ["72702.85000000", "0.00029000"], ["72702.84000000", "0.00000000"], ["72702.01000000", "0.00000000"], ["72701.91000000", "0.18118000"], ["72701.74000000", "0.00020000"], ["72701.42000000", "0.00000000"], ["72700.07000000", "0.00000000"], ["72700.01000000", "1.04098000"], ["72699.33000000", "0.18117000"], ["72699.31000000", "0.00000000"], ["72699.07000000", "0.00000000"], ["72698.07000000", "0.18117000"], ["72698.06000000", "0.00000000"], ["72697.72000000", "0.60900000"], ["72697.71000000", "0.00000000"], ["72697.40000000", "0.00022000"], ["72696.74000000", "0.12083000"], ["72696.66000000", "0.18117000"], ["72696.01000000", "0.00000000"], ["72694.76000000", "0.18118000"], ["72694.47000000", "0.00020000"], ["72694.23000000", "0.00000000"], ["72693.87000000", "0.18117000"], ["72693.86000000", "0.00000000"], ["72693.76000000", "1.98697000"], ["72693.14000000", "0.00007000"], ["72692.62000000", "0.00000000"], ["72692.61000000", "0.00000000"], ["72692.39000000", "0.00000000"], ["72692.14000000", "0.00000000"], ["72691.31000000", "0.00000000"], ["72691.30000000", "0.18446000"], ["72690.92000000", "0.00000000"], ["72690.65000000", "0.00000000"], ["72690.39000000", "0.00000000"], ["72689.66000000", "0.18120000"], ["72689.59000000", "1.52803000"], ["72689.41000000", "0.00000000"], ["72689.39000000", "0.00024000"], ["72689.36000000", "0.00000000"], ["72689.35000000", "0.00000000"], ["72686.13000000", "0.96843000"], ["72684.65000000", "0.00343000"], ["72682.51000000", "0.18120000"], ["72682.24000000", "0.00000000"], ["72680.90000000", "0.18120000"], ["72678.65000000", "0.01690000"], ["72673.84000000", "0.00000000"], ["72673.49000000", "0.00008000"], ["72671.75000000", "0.27548000"], ["72671.07000000", "0.18120000"], ["72670.01000000", "0.00000000"], ["72669.64000000", "0.18120000"], ["72669.26000000", "0.18120000"], ["72668.43000000", "1.36430000"], ["72664.55000000", "0.00282000"], ["72664.30000000", "0.00000000"], ["72657.92000000", "0.00008000"], ["72645.74000000", "0.00011000"], ["72642.91000000", "0.00000000"], ["72640.68000000", "0.00000000"], ["72638.36000000", "0.00011000"], ["72634.30000000", "0.00000000"], ["72634.29000000", "0.00000000"], ["72630.98000000", "0.00011000"], ["72629.24000000", "0.00000000"], ["72623.60000000", "0.00011000"], ["72609.49000000", "0.00000000"], ["72604.23000000", "0.00000000"], ["72600.75000000", "0.00008000"], ["72590.53000000", "2.84261000"], ["72590.47000000", "0.00000000"], ["72544.77000000", "0.00007000"], ["72536.74000000", "0.00000000"], ["72534.83000000", "0.00000000"], ["72533.13000000", "0.00000000"], ["72528.56000000", "0.12264000"], ["72528.00000000", "0.00008000"], ["72526.62000000", "0.00000000"], ["72492.61000000", "0.28066000"], ["72463.98000000", "0.00000000"], ["72455.26000000", "0.00008000"], ["72442.72000000", "0.00028000"], ["72427.20000000", "0.00008000"], ["72391.23000000", "0.00000000"], ["72382.51000000", "0.00008000"], ["72318.47000000", "0.00000000"], ["72309.76000000", "0.00008000"], ["72245.71000000", "0.00277000"], ["72237.02000000", "0.00008000"], ["72172.96000000", "0.00000000"], ["72164.27000000", "0.00008000"], ["71967.12000000", "0.00011000"], ["65475.90000000", "0.00136000"], ["65471.40000000", "0.00017000"]], "a": [["72742.01000000", "0.68285000"], ["72742.29000000", "0.52382000"], ["72742.36000000", "0.30000000"], ["72742.86000000", "0.30000000"], ["72743.12000000", "0.40000000"], ["72743.37000000", "0.70000000"], ["72743.39000000", "0.40000000"], ["72743.57000000", "1.19721000"], ["72743.59000000", "0.93572000"], ["72743.99000000", "0.63572000"], ["72744.00000000", "0.13011000"], ["72744.01000000", "5.34851000"], ["72744.02000000", "0.00038000"], ["72744.03000000", "0.00014000"], ["72744.09000000", "0.00000000"], ["72744.43000000", "0.11136000"], ["72744.46000000", "0.02349000"], ["72744.60000000", "0.00000000"], ["72744.66000000", "0.00007000"], ["72744.83000000", "0.00000000"], ["72745.07000000", "0.00000000"], ["72745.33000000", "0.18118000"], ["72745.34000000", "0.04138000"], ["72745.40000000", "0.00400000"], ["72745.46000000", "0.00000000"], ["72745.47000000", "0.00000000"], ["72745.89000000", "0.02349000"], ["72745.90000000", "0.00020000"], ["72745.91000000", "0.75804000"], ["72745.92000000", "0.37466000"], ["72745.94000000", "1.27670000"], ["72745.95000000", "0.00241000"], ["72745.99000000", "0.65921000"], ["72746.01000000", "1.08459000"], ["72746.02000000", "0.00008000"], ["72746.24000000", "0.00020000"], ["72746.25000000", "0.37386000"], ["72746.26000000", "0.00008000"], ["72746.30000000", "0.00000000"], ["72746.32000000", "0.00000000"], ["72746.59000000", "0.00000000"], ["72746.60000000", "0.00000000"], ["72746.65000000", "0.63572000"], ["72746.66000000", "0.63572000"], ["72746.67000000", "0.00000000"], ["72746.68000000", "0.01484000"], ["72746.79000000", "0.00000000"], ["72747.00000000", "0.65949000"], ["72747.01000000", "0.00000000"], ["72747.16000000", "0.00009000"], ["72747.22000000", "0.00400000"], ["72747.44000000", "0.18118000"], ["72747.45000000", "0.00000000"], ["72747.55000000", "0.00164000"], ["72747.94000000", "0.00000000"], ["72748.01000000", "0.00000000"], ["72748.18000000", "0.12173000"], ["72748.35000000", "0.00007000"], ["72748.36000000", "0.00000000"], ["72749.04000000", "0.00400000"], ["72749.53000000", "0.00000000"], ["72749.55000000", "0.65914000"], ["72749.71000000", "2.22841000"], ["72749.72000000", "0.00000000"], ["72749.76000000", "0.05602000"], ["72749.77000000", "0.13997000"], ["72749.82000000", "0.00000000"], ["72749.91000000", "0.00000000"], ["72749.93000000", "0.22515000"], ["72749.97000000", "0.80853000"], ["72750.00000000", "0.00000000"], ["72750.01000000", "0.48763000"], ["72750.02000000", "0.00000000"], ["72750.28000000", "1.15670000"], ["72750.32000000", "0.00000000"], ["72750.52000000", "0.00000000"], ["72750.59000000", "0.00000000"], ["72750.66000000", "0.00000000"], ["72750.81000000", "0.31044000"], ["72750.85000000", "1.27061000"], ["72750.86000000", "0.83139000"], ["72750.93000000", "1.46391000"], ["72750.94000000", "1.34360000"], ["72750.95000000", "0.00000000"], ["72750.96000000", "0.00000000"], ["72750.97000000", "0.00000000"], ["72750.99000000", "0.00541000"], ["72751.00000000", "2.85298000"], ["72751.01000000", "0.35897000"], ["72751.02000000", "0.00336000"], ["72751.03000000", "0.00000000"], ["72751.82000000", "0.00765000"], ["72752.02000000", "0.00000000"], ["72752.10000000", "0.01404000"], ["72752.26000000", "0.00028000"], ["72752.40000000", "0.00000000"], ["72752.44000000", "0.00000000"], ["72753.00000000", "0.01580000"], ["72753.27000000", "0.00007000"], ["72753.35000000", "0.03420000"], ["72753.60000000", "0.00008000"], ["72753.77000000", "0.00000000"], ["72753.81000000", "0.00008000"], ["72753.82000000", "0.81229000"], ["72753.83000000", "0.40856000"], ["72753.84000000", "0.00000000"], ["72753.85000000", "0.07077000"], ["72754.00000000", "0.01660000"], ["72754.08000000", "0.09538000"], ["72755.00000000", "0.00008000"], ["72755.01000000", "1.68397000"], ["72756.73000000", "0.00000000"], ["72756.94000000", "0.00000000"], ["72757.34000000", "0.00018000"], ["72757.41000000", "0.00357000"], ["72757.82000000", "0.00000000"], ["72757.87000000", "0.00000000"], ["72758.97000000", "0.00000000"], ["72759.59000000", "0.00000000"], ["72759.70000000", "0.00028000"], ["72759.97000000", "0.00008000"], ["72759.98000000", "1.75313000"], ["72760.00000000", "0.00663000"], ["72760.01000000", "0.60927000"], ["72760.80000000", "0.00000000"], ["72760.94000000", "0.00008000"], ["72761.02000000", "0.00000000"], ["72761.09000000", "0.49539000"], ["72761.40000000", "0.00000000"], ["72762.19000000", "0.00000000"], ["72762.20000000", "0.00008000"], ["72762.81000000", "0.00008000"], ["72762.82000000", "0.00000000"], ["72762.83000000", "0.12931000"], ["72763.35000000", "0.00000000"], ["72763.36000000", "0.00008000"], ["72763.79000000", "0.00008000"], ["72764.57000000", "0.00000000"], ["72765.01000000", "0.00000000"], ["72765.27000000", "1.36224000"], ["72765.31000000", "0.00000000"], ["72766.74000000", "0.00000000"], ["72766.98000000", "0.00000000"], ["72767.16000000", "0.00007000"], ["72767.19000000", "0.00000000"], ["72768.69000000", "0.00008000"], ["72768.70000000", "0.00008000"], ["72768.71000000", "0.00000000"], ["72769.69000000", "0.00000000"], ["72769.99000000", "0.00000000"], ["72771.03000000", "0.00000000"], ["72771.05000000", "0.00573000"], ["72772.01000000", "0.00000000"], ["72772.46000000", "0.00000000"], ["72772.55000000", "0.00000000"], ["72772.56000000", "0.82604000"], ["72774.52000000", "0.00000000"], ["72774.55000000", "0.00000000"], ["72775.34000000", "0.00000000"], ["72775.35000000", "0.00000000"], ["72776.26000000", "0.00114000"], ["72776.34000000", "0.00000000"], ["72777.82000000", "0.00349000"], ["72778.16000000", "0.00000000"], ["72778.80000000", "0.00000000"], ["72779.50000000", "0.00000000"], ["72779.65000000", "0.00000000"], ["72779.98000000", "0.00007000"], ["72780.00000000", "0.02296000"], ["72780.12000000", "0.00000000"], ["72781.56000000", "0.00000000"], ["72784.74000000", "0.00343000"], ["72785.25000000", "0.00000000"], ["72785.65000000", "0.00000000"], ["72788.00000000", "0.02280000"], ["72788.53000000", "0.00000000"], ["72790.50000000", "0.00000000"], ["72793.33000000", "0.00412000"], ["72793.34000000", "0.00000000"], ["72793.62000000", "0.00000000"], ["72795.54000000", "0.00000000"], ["72797.80000000", "0.00000000"], ["72798.57000000", "0.00007000"], ["72800.43000000", "1.36859000"], ["72800.54000000", "0.00000000"], ["72801.11000000", "0.00000000"], ["72802.09000000", "0.82593000"], ["72803.08000000", "0.18446000"], ["72805.93000000", "0.00000000"], ["72807.31000000", "0.00343000"], ["72814.04000000", "0.00000000"], ["72819.00000000", "0.00008000"], ["72819.31000000", "0.00000000"], ["72821.76000000", "0.00000000"], ["72822.30000000", "0.00000000"], ["72823.42000000", "0.00000000"], ["72826.71000000", "0.00000000"], ["72827.77000000", "0.00000000"], ["72829.22000000", "0.00000000"], ["72833.29000000", "0.00000000"], ["72833.74000000", "0.23210000"], ["72834.96000000", "0.00000000"], ["72836.93000000", "0.00000000"], ["72847.12000000", "0.00000000"], ["72847.13000000", "0.00550000"], ["72847.16000000", "0.00000000"], ["72848.44000000", "0.25170000"], ["72867.68000000", "0.00000000"], ["72872.73000000", "0.00000000"], ["72877.96000000", "0.00000000"], ["72890.68000000", "0.00000000"], ["72891.74000000", "0.00008000"], ["72900.00000000", "0.05983000"], ["72900.52000000", "0.00000000"], ["72901.20000000", "4.12033000"], ["72905.14000000", "0.00000000"], ["72915.99000000", "0.00000000"], ["72928.57000000", "0.00042000"], ["72929.13000000", "0.00000000"], ["72936.92000000", "0.00000000"], ["72938.74000000", "0.00000000"], ["72940.56000000", "0.00000000"], ["72945.22000000", "0.00000000"], ["72945.55000000", "0.00000000"], ["72996.00000000", "0.02000000"], ["73000.00000000", "0.58059000"], ["73037.24000000", "0.00008000"], ["73043.74000000", "0.00056000"], ["73046.03000000", "0.00000000"], ["73052.37000000", "0.00011000"], ["73064.40000000", "0.00000000"], ["73097.10000000", "0.00000000"], ["73108.66000000", "0.00000000"], ["73109.98000000", "0.00008000"], ["73118.79000000", "0.00000000"], ["73125.00000000", "0.00300000"], ["73137.72000000", "0.00000000"], ["73166.66000000", "0.00175000"], ["73184.27000000", "0.00045000"], ["73215.78000000", "0.00000000"], ["73255.47000000", "0.00008000"], ["73264.30000000", "0.00000000"], ["73500.00000000", "1.40312000"], ["73625.00000000", "0.00860000"], ["73687.13000000", "0.00012000"], ["73700.00000000", "1.45806000"], ["74450.00000000", "0.72807000"], ["75000.00000000", "42.32029000"], ["75400.00000000", "1.00042000"], ["76383.31000000", "0.00020000"], ["76383.56000000", "0.00020000"], ["76443.70000000", "0.00000000"], ["76444.20000000", "0.00000000"]], "_local_ts_utc": "2026-06-01T07:48:59.761792+00:00"}
{"e": "depthUpdate", "E": 1780300140941, "s": "BTCUSDT", "U": 94551763780, "u": 94551764561, "b": [["72742.00000000", "3.76682000"], ["72741.99000000", "0.00080000"], ["72741.93000000", "0.00011000"], ["72741.20000000", "0.00000000"], ["72740.97000000", "0.04144000"], ["72740.23000000", "0.00000000"], ["72740.18000000", "0.00000000"], ["72740.01000000", "0.00016000"], ["72740.00000000", "0.02342000"], ["72739.63000000", "0.00589000"], ["72738.70000000", "0.00047000"], ["72738.69000000", "0.04016000"], ["72738.44000000", "0.00016000"], ["72738.43000000", "0.05091000"], ["72738.36000000", "0.00016000"], ["72738.35000000", "0.05472000"], ["72738.18000000", "0.00000000"], ["72738.12000000", "0.00000000"], ["72738.00000000", "0.02296000"], ["72737.92000000", "0.00031000"], ["72737.46000000", "0.00000000"], ["72736.99000000", "0.00000000"], ["72736.76000000", "0.00000000"], ["72736.62000000", "0.00000000"], ["72736.61000000", "0.00000000"], ["72736.39000000", "0.00000000"], ["72736.28000000", "0.00000000"], ["72734.85000000", "0.00000000"], ["72734.63000000", "0.00000000"], ["72733.96000000", "0.00000000"], ["72733.65000000", "0.00007000"], ["72733.42000000", "0.18121000"], ["72733.04000000", "0.00000000"], ["72732.01000000", "0.18121000"], ["72731.34000000", "0.00070000"], ["72730.56000000", "0.18121000"], ["72730.25000000", "0.25635000"], ["72730.24000000", "0.00008000"], ["72730.01000000", "0.00000000"], ["72729.70000000", "0.00000000"], ["72729.13000000", "0.18121000"], ["72728.27000000", "0.00000000"], ["72728.07000000", "0.00022000"], ["72727.70000000", "0.18131000"], ["72727.04000000", "0.00047000"], ["72727.01000000", "0.67417000"], ["72726.92000000", "0.00148000"], ["72726.84000000", "0.00000000"], ["72726.27000000", "0.18121000"], ["72725.63000000", "0.16165000"], ["72725.26000000", "0.00000000"], ["72723.36000000", "0.00000000"], ["72722.97000000", "1.32006000"], ["72722.81000000", "0.00000000"], ["72722.41000000", "0.00000000"], ["72721.81000000", "0.15000000"], ["72721.18000000", "0.40856000"], ["72721.00000000", "0.00025000"], ["72720.55000000", "0.18121000"], ["72719.54000000", "0.00011000"], ["72719.09000000", "0.33420000"], ["72717.48000000", "0.00000000"], ["72716.52000000", "0.00000000"], ["72714.83000000", "0.18121000"], ["72714.01000000", "0.00000000"], ["72713.89000000", "0.00000000"], ["72713.82000000", "0.00000000"], ["72712.82000000", "0.00000000"], ["72712.16000000", "0.00011000"], ["72711.01000000", "0.35030000"], ["72709.60000000", "0.40856000"], ["72707.88000000", "0.00012000"], ["72707.17000000", "0.00000000"], ["72707.07000000", "0.00000000"], ["72707.06000000", "0.28591000"], ["72706.68000000", "0.00000000"], ["72705.92000000", "0.00000000"], ["72705.36000000", "0.00400000"], ["72704.82000000", "0.18121000"], ["72704.78000000", "0.00011000"], ["72703.81000000", "0.00000000"], ["72702.66000000", "0.00000000"], ["72702.65000000", "0.00000000"], ["72701.96000000", "0.18121000"], ["72700.02000000", "0.40856000"], ["72700.01000000", "0.63398000"], ["72699.33000000", "0.00000000"], ["72697.40000000", "0.00011000"], ["72695.15000000", "0.00343000"], ["72694.83000000", "0.18121000"], ["72693.87000000", "0.00000000"], ["72692.60000000", "0.18121000"], ["72691.31000000", "0.00000000"], ["72691.30000000", "0.00000000"], ["72689.60000000", "0.00000000"], ["72689.59000000", "0.65949000"], ["72689.47000000", "0.36892000"], ["72687.66000000", "0.00000000"], ["72687.09000000", "0.00000000"], ["72686.09000000", "0.00000000"], ["72685.26000000", "0.01146000"], ["72683.94000000", "0.00000000"], ["72683.59000000", "0.49592000"], ["72682.51000000", "0.00000000"], ["72682.03000000", "0.00000000"], ["72681.92000000", "1.04015000"], ["72680.90000000", "0.00000000"], ["72680.65000000", "0.00016000"], ["72680.01000000", "0.00315000"], ["72678.67000000", "0.18446000"], ["72678.02000000", "0.00007000"], ["72677.92000000", "0.00434000"], ["72677.34000000", "0.00428000"], ["72676.22000000", "0.00000000"], ["72674.79000000", "0.00000000"], ["72674.49000000", "0.00000000"], ["72673.93000000", "0.00000000"], ["72673.36000000", "0.00000000"], ["72672.50000000", "0.00000000"], ["72671.93000000", "0.00000000"], ["72671.07000000", "0.00000000"], ["72669.64000000", "0.00000000"], ["72669.26000000", "0.00000000"], ["72664.55000000", "0.00000000"], ["72658.01000000", "0.00282000"], ["72657.77000000", "0.82593000"], ["72656.93000000", "0.07140000"], ["72656.04000000", "0.02751000"], ["72634.30000000", "2.74910000"], ["72629.70000000", "0.69990000"], ["72622.01000000", "0.00137000"], ["72621.14000000", "0.00000000"], ["72621.13000000", "0.00000000"], ["72608.01000000", "0.00137000"], ["72576.40000000", "0.40856000"], ["72536.90000000", "0.00007000"], ["72526.01000000", "0.00007000"], ["72522.38000000", "0.00007000"], ["72518.75000000", "0.00007000"], ["72504.12000000", "0.00007000"], ["72478.29000000", "0.11390000"], ["72463.24000000", "0.00000000"], ["72410.05000000", "0.00028000"], ["65471.40000000", "0.00000000"], ["65469.60000000", "0.00000000"], ["65467.80000000", "0.00017000"], ["58195.00000000", "0.01379000"]], "a": [["72742.01000000", "4.77313000"], ["72742.02000000", "0.00038000"], ["72742.03000000", "0.00014000"], ["72742.28000000", "0.00000000"], ["72742.29000000", "0.00016000"], ["72742.35000000", "0.00000000"], ["72742.36000000", "0.00008000"], ["72742.57000000", "0.00000000"], ["72742.85000000", "0.00000000"], ["72742.86000000", "0.00016000"], ["72743.11000000", "0.00000000"], ["72743.12000000", "0.00016000"], ["72743.17000000", "0.00000000"], ["72743.37000000", "0.00016000"], ["72743.39000000", "0.85957000"], ["72743.55000000", "0.00000000"], ["72743.56000000", "2.16729000"], ["72743.57000000", "0.52093000"], ["72743.58000000", "0.00408000"], ["72743.59000000", "0.00008000"], ["72744.00000000", "1.82230000"], ["72744.01000000", "2.10524000"], ["72744.02000000", "0.00000000"], ["72744.03000000", "0.00000000"], ["72744.42000000", "0.40856000"], ["72744.43000000", "0.00000000"], ["72744.96000000", "0.15000000"], ["72745.33000000", "0.00000000"], ["72745.34000000", "0.00000000"], ["72745.41000000", "0.00000000"], ["72745.56000000", "0.00000000"], ["72745.89000000", "0.00000000"], ["72745.91000000", "0.63572000"], ["72745.92000000", "0.00000000"], ["72745.94000000", "0.80270000"], ["72745.95000000", "0.00000000"], ["72745.99000000", "0.63572000"], ["72746.00000000", "0.00008000"], ["72746.01000000", "0.73580000"], ["72746.02000000", "0.00000000"], ["72746.24000000", "0.00028000"], ["72746.25000000", "0.05363000"], ["72746.26000000", "0.00000000"], ["72746.28000000", "0.00000000"], ["72746.66000000", "0.00000000"], ["72746.99000000", "0.00008000"], ["72747.44000000", "0.00000000"], ["72748.18000000", "0.00000000"], ["72749.11000000", "0.00000000"], ["72749.34000000", "0.00155000"], ["72749.55000000", "0.00000000"], ["72749.70000000", "0.00008000"], ["72749.71000000", "0.70362000"], ["72749.95000000", "0.00011000"], ["72749.97000000", "0.00000000"], ["72750.01000000", "0.04000000"], ["72750.27000000", "0.00008000"], ["72750.28000000", "0.65949000"], ["72750.81000000", "0.00000000"], ["72750.85000000", "0.00020000"], ["72750.86000000", "0.00400000"], ["72750.92000000", "0.00008000"], ["72750.93000000", "0.00000000"], ["72750.94000000", "0.00000000"], ["72750.99000000", "0.00008000"], ["72751.00000000", "0.91940000"], ["72751.01000000", "0.28825000"], ["72752.01000000", "0.00008000"], ["72752.43000000", "0.00008000"], ["72753.80000000", "0.00008000"], ["72753.81000000", "0.00008000"], ["72754.00000000", "0.00080000"], ["72755.01000000", "1.63554000"], ["72755.88000000", "0.00400000"], ["72756.52000000", "0.00008000"], ["72756.72000000", "0.00000000"], ["72757.80000000", "0.55781000"], ["72757.81000000", "0.65949000"], ["72757.82000000", "0.00008000"], ["72757.83000000", "0.00000000"], ["72757.84000000", "0.00008000"], ["72757.85000000", "0.00000000"], ["72758.00000000", "0.00080000"], ["72758.01000000", "0.34327000"], ["72758.07000000", "0.00458000"], ["72758.23000000", "0.00000000"], ["72758.28000000", "0.00008000"], ["72759.58000000", "0.00000000"], ["72759.71000000", "0.00000000"], ["72759.98000000", "0.75236000"], ["72760.94000000", "0.00000000"], ["72761.09000000", "0.00000000"], ["72761.40000000", "0.00008000"], ["72761.98000000", "0.00007000"], ["72762.18000000", "0.00008000"], ["72762.19000000", "2.74910000"], ["72762.81000000", "0.00000000"], ["72763.79000000", "0.00000000"], ["72765.26000000", "0.00008000"], ["72765.30000000", "0.00000000"], ["72766.73000000", "0.00000000"], ["72767.18000000", "0.00000000"], ["72767.49000000", "0.92653000"], ["72768.07000000", "0.00008000"], ["72768.68000000", "2.74910000"], ["72768.69000000", "0.00000000"], ["72768.70000000", "0.00000000"], ["72769.06000000", "0.00400000"], ["72769.24000000", "0.00007000"], ["72770.09000000", "0.00000000"], ["72770.43000000", "0.00400000"], ["72771.01000000", "0.00000000"], ["72772.56000000", "0.82596000"], ["72772.70000000", "0.49531000"], ["72772.96000000", "0.00008000"], ["72774.98000000", "0.00008000"], ["72776.34000000", "0.00634000"], ["72777.37000000", "0.00000000"], ["72777.64000000", "0.00000000"], ["72777.77000000", "1.03878000"], ["72779.38000000", "0.00428000"], ["72779.81000000", "0.00011000"], ["72780.00000000", "0.02288000"], ["72780.21000000", "0.00436000"], ["72781.52000000", "0.00573000"], ["72784.08000000", "0.00000000"], ["72786.13000000", "0.00000000"], ["72786.57000000", "0.49521000"], ["72788.88000000", "0.00000000"], ["72791.34000000", "0.00000000"], ["72793.34000000", "0.54395000"], ["72800.43000000", "1.36867000"], ["72802.09000000", "0.00000000"], ["72803.22000000", "0.82593000"], ["72807.40000000", "0.00000000"], ["72821.97000000", "0.00000000"], ["72823.47000000", "0.00000000"], ["72825.78000000", "0.00000000"], ["72826.08000000", "0.63976000"], ["72833.74000000", "0.00000000"], ["72841.09000000", "0.00000000"], ["72845.99000000", "0.04552000"], ["72848.44000000", "0.00000000"], ["72865.65000000", "0.03560000"], ["72880.56000000", "0.00000000"], ["72887.49000000", "0.00010000"], ["72897.75000000", "0.00000000"], ["72934.75000000", "0.00000000"], ["72937.50000000", "0.00064000"], ["72978.00000000", "0.02031000"], ["72993.36000000", "0.00015000"], ["72994.90000000", "0.00007000"], ["73000.00000000", "0.58987000"], ["73002.81000000", "0.00000000"], ["73032.35000000", "0.00030000"], ["73060.37000000", "0.00017000"], ["73062.50000000", "0.00011000"], ["73071.88000000", "0.00007000"], ["73095.37000000", "0.00013000"], ["73100.00000000", "1.15900000"], ["73102.63000000", "0.00029000"], ["73113.19000000", "0.00009000"], ["73125.00000000", "0.00535000"], ["73133.95000000", "0.00014000"], ["73135.30000000", "0.00024000"], ["73181.48000000", "0.20952000"], ["73208.80000000", "0.00115000"], ["73266.66000000", "0.00125000"], ["73269.58000000", "0.00000000"], ["73287.50000000", "0.00009000"], ["73332.70000000", "0.00168000"], ["73429.18000000", "0.00029000"], ["73456.49000000", "0.00009000"], ["73463.27000000", "0.00057000"], ["73486.92000000", "0.00020000"], ["73495.60000000", "0.00019000"], ["73500.00000000", "1.40797000"], ["73625.00000000", "0.00875000"], ["73720.05000000", "0.00012000"], ["74257.41000000", "0.00000000"]], "_local_ts_utc": "2026-06-01T07:48:59.837690+00:00"}
{"e": "depthUpdate", "E": 1780300141017, "s": "BTCUSDT", "U": 94551764562, "u": 94551764945, "b": [["72742.00000000", "3.44019000"], ["72741.99000000", "0.00072000"], ["72740.96000000", "0.00031000"], ["72739.91000000", "0.00054000"], ["72739.72000000", "0.00000000"], ["72739.51000000", "0.00000000"], ["72738.70000000", "0.00000000"], ["72738.69000000", "0.00016000"], ["72738.36000000", "0.00024000"], ["72738.35000000", "0.05480000"], ["72738.05000000", "0.00008000"], ["72738.04000000", "0.03892000"], ["72737.92000000", "0.00000000"], ["72734.85000000", "0.17753000"], ["72734.73000000", "0.18922000"], ["72734.17000000", "0.00000000"], ["72733.65000000", "0.00000000"], ["72733.43000000", "0.00000000"], ["72732.19000000", "0.00048000"], ["72731.04000000", "0.05942000"], ["72730.90000000", "0.00007000"], ["72730.58000000", "0.00000000"], ["72730.28000000", "0.18120000"], ["72730.27000000", "1.18607000"], ["72730.26000000", "3.40859000"], ["72730.25000000", "0.00017000"], ["72729.33000000", "0.00550000"], ["72729.24000000", "0.00550000"], ["72729.13000000", "0.00000000"], ["72728.05000000", "0.00047000"], ["72727.60000000", "0.00041000"], ["72727.45000000", "0.00300000"], ["72727.02000000", "0.66026000"], ["72726.73000000", "0.00000000"], ["72726.60000000", "0.00000000"], ["72726.27000000", "0.00000000"], ["72725.63000000", "0.00000000"], ["72725.56000000", "0.01376000"], ["72725.41000000", "0.00000000"], ["72722.98000000", "0.18121000"], ["72722.40000000", "0.00000000"], ["72721.19000000", "0.77198000"], ["72720.55000000", "0.00000000"], ["72720.23000000", "0.01376000"], ["72720.01000000", "0.00028000"], ["72719.09000000", "0.21678000"], ["72718.95000000", "0.02000000"], ["72718.11000000", "0.00000000"], ["72716.68000000", "0.00000000"], ["72716.02000000", "0.37436000"], ["72714.83000000", "0.00000000"], ["72710.79000000", "0.62731000"], ["72710.68000000", "0.00022000"], ["72709.34000000", "0.00067000"], ["72709.27000000", "0.00053000"], ["72708.87000000", "0.00000000"], ["72708.31000000", "0.00000000"], ["72708.15000000", "0.00000000"], ["72708.12000000", "0.00000000"], ["72708.04000000", "0.00000000"], ["72707.99000000", "0.00000000"], ["72707.98000000", "0.00000000"], ["72707.81000000", "0.00011000"], ["72707.80000000", "0.00000000"], ["72707.79000000", "0.00000000"], ["72707.77000000", "0.00000000"], ["72707.74000000", "0.00000000"], ["72707.57000000", "0.00000000"], ["72707.46000000", "0.00000000"], ["72707.44000000", "0.00000000"], ["72707.32000000", "0.00000000"], ["72707.02000000", "0.02729000"], ["72693.76000000", "0.00000000"], ["72692.60000000", "0.00000000"], ["72691.52000000", "0.49586000"], ["72689.66000000", "0.00000000"], ["72688.98000000", "1.17209000"], ["72687.99000000", "0.00000000"], ["72681.58000000", "0.00011000"], ["72680.91000000", "0.49593000"], ["72658.45000000", "0.00109000"], ["72656.49000000", "0.00000000"], ["72635.69000000", "0.04608000"], ["72634.30000000", "0.00000000"], ["72581.82000000", "6.57786000"], ["72518.75000000", "0.00000000"], ["72402.61000000", "0.00028000"], ["72395.17000000", "0.00776000"], ["72393.99000000", "0.00498000"], ["72387.73000000", "0.00028000"], ["72380.29000000", "0.00028000"], ["65475.90000000", "0.00000000"], ["65467.80000000", "0.00051000"], ["58193.60000000", "0.00034000"]], "a": [["72742.01000000", "4.59372000"], ["72742.29000000", "0.00000000"], ["72742.36000000", "0.00000000"], ["72742.86000000", "0.00000000"], ["72743.12000000", "0.00000000"], ["72743.36000000", "0.00016000"], ["72743.37000000", "0.47466000"], ["72743.38000000", "0.65965000"], ["72743.39000000", "0.00016000"], ["72743.55000000", "0.00000000"], ["72743.56000000", "0.00016000"], ["72743.57000000", "0.00016000"], ["72743.59000000", "0.00000000"], ["72743.99000000", "0.00016000"], ["72744.00000000", "0.00040000"], ["72744.01000000", "0.30652000"], ["72744.41000000", "0.00008000"], ["72744.42000000", "0.40872000"], ["72744.46000000", "0.00016000"], ["72745.91000000", "0.00000000"], ["72745.94000000", "0.42580000"], ["72745.99000000", "0.00000000"], ["72746.01000000", "0.11370000"], ["72746.62000000", "0.05256000"], ["72746.65000000", "0.00000000"], ["72749.29000000", "0.27300000"], ["72749.70000000", "0.92550000"], ["72749.71000000", "0.00007000"], ["72749.76000000", "0.00000000"], ["72749.77000000", "0.00000000"], ["72749.93000000", "0.00025000"], ["72750.01000000", "0.00000000"], ["72751.00000000", "0.25585000"], ["72751.01000000", "0.28808000"], ["72753.77000000", "0.00829000"], ["72753.81000000", "0.18129000"], ["72757.41000000", "0.00007000"], ["72757.74000000", "0.18121000"], ["72757.79000000", "1.14708000"], ["72760.12000000", "0.03872000"], ["72762.76000000", "0.00000000"], ["72763.23000000", "0.00000000"], ["72763.81000000", "0.00053000"], ["72765.27000000", "0.00000000"], ["72765.58000000", "0.00000000"], ["72766.35000000", "0.00275000"], ["72766.36000000", "0.97024000"], ["72767.50000000", "0.00000000"], ["72767.99000000", "0.00000000"], ["72770.11000000", "0.00000000"], ["72770.26000000", "0.00400000"], ["72770.43000000", "0.00000000"], ["72772.03000000", "0.00000000"], ["72778.64000000", "0.43354000"], ["72779.78000000", "0.02727000"], ["72785.87000000", "0.00000000"], ["72792.00000000", "0.02852000"], ["72792.25000000", "0.49517000"], ["72794.54000000", "1.36170000"], ["72798.58000000", "0.00000000"], ["72806.57000000", "0.01138000"], ["72854.77000000", "0.00000000"], ["72858.01000000", "0.00000000"], ["72871.09000000", "0.00000000"], ["72892.55000000", "0.00011000"], ["72900.00000000", "0.06039000"], ["72936.22000000", "0.00007000"], ["72939.85000000", "0.00000000"], ["72959.26000000", "0.11350000"], ["72971.42000000", "0.00008000"], ["72972.36000000", "0.00012000"], ["72993.36000000", "0.00023000"], ["73000.00000000", "0.59031000"], ["73032.35000000", "0.00057000"], ["73035.71000000", "0.00010000"], ["73057.55000000", "0.00033000"], ["73095.37000000", "0.01275000"], ["73100.00000000", "1.16097000"], ["73113.19000000", "0.00490000"], ["73125.00000000", "0.00686000"], ["73139.88000000", "0.00036000"], ["73189.95000000", "0.00000000"], ["73232.03000000", "0.00048000"], ["73264.43000000", "0.00019000"], ["73285.71000000", "0.00403000"], ["73313.16000000", "0.00036000"], ["73333.33000000", "0.03330000"], ["73463.27000000", "0.00106000"], ["73484.69000000", "0.01551000"], ["73491.57000000", "0.00030000"], ["73494.85000000", "0.00021000"], ["73500.00000000", "1.40849000"], ["73515.15000000", "0.00140000"], ["73937.50000000", "0.00247000"]], "_local_ts_utc": "2026-06-01T07:48:59.915357+00:00"}
{"e": "depthUpdate", "E": 1780300141114, "s": "BTCUSDT", "U": 94551764946, "u": 94551765327, "b": [["72742.00000000", "4.15184000"], ["72741.99000000", "0.00056000"], ["72740.57000000", "0.18120000"], ["72740.01000000", "0.00000000"], ["72739.91000000", "0.00023000"], ["72739.63000000", "0.00589000"], ["72739.60000000", "0.03206000"], ["72739.14000000", "0.18120000"], ["72738.86000000", "0.16760000"], ["72738.69000000", "0.00000000"], ["72738.44000000", "0.00000000"], ["72738.36000000", "0.00008000"], ["72738.35000000", "0.05480000"], ["72738.12000000", "0.00400000"], ["72738.05000000", "0.00000000"], ["72738.04000000", "0.00016000"], ["72737.71000000", "0.18120000"], ["72736.28000000", "0.17622000"], ["72736.01000000", "0.03407000"], ["72735.10000000", "0.00000000"], ["72734.78000000", "0.00000000"], ["72734.73000000", "0.18922000"], ["72734.30000000", "0.00011000"], ["72734.03000000", "0.00059000"], ["72733.43000000", "0.00000000"], ["72732.19000000", "0.00000000"], ["72731.93000000", "0.00000000"], ["72731.86000000", "0.00000000"], ["72731.34000000", "0.00000000"], ["72731.04000000", "0.00000000"], ["72730.27000000", "0.00000000"], ["72729.33000000", "0.00000000"], ["72729.24000000", "0.00000000"], ["72728.35000000", "0.03407000"], ["72727.03000000", "0.18120000"], ["72727.01000000", "0.00000000"], ["72724.84000000", "0.18120000"], ["72724.66000000", "0.00007000"], ["72722.97000000", "0.00019000"], ["72721.20000000", "0.16453000"], ["72721.09000000", "0.12083000"], ["72720.23000000", "0.00000000"], ["72719.92000000", "0.00400000"], ["72719.12000000", "0.18120000"], ["72719.09000000", "0.00000000"], ["72717.69000000", "0.18250000"], ["72716.28000000", "0.00400000"], ["72716.26000000", "0.18120000"], ["72716.02000000", "0.00000000"], ["72715.49000000", "0.00000000"], ["72715.00000000", "0.00000000"], ["72714.83000000", "0.18120000"], ["72714.51000000", "0.00000000"], ["72714.15000000", "0.00000000"], ["72714.07000000", "0.00000000"], ["72714.06000000", "0.00000000"], ["72714.03000000", "0.00000000"], ["72714.02000000", "0.00000000"], ["72713.29000000", "0.00000000"], ["72712.86000000", "0.00000000"], ["72712.84000000", "0.00000000"], ["72712.54000000", "0.00000000"], ["72712.52000000", "0.00000000"], ["72712.41000000", "0.00000000"], ["72712.32000000", "0.00000000"], ["72712.04000000", "0.00000000"], ["72712.03000000", "0.00000000"], ["72711.74000000", "0.00000000"], ["72711.72000000", "0.00000000"], ["72711.71000000", "0.00000000"], ["72711.01000000", "0.00000000"], ["72710.69000000", "0.00000000"], ["72710.67000000", "0.00000000"], ["72710.62000000", "0.00626000"], ["72710.52000000", "0.96897000"], ["72710.51000000", "0.00000000"], ["72710.49000000", "0.00000000"], ["72710.47000000", "0.00000000"], ["72710.38000000", "0.00071000"], ["72710.37000000", "0.00000000"], ["72710.30000000", "0.00000000"], ["72710.25000000", "0.00000000"], ["72710.24000000", "0.00000000"], ["72710.10000000", "0.00000000"], ["72709.69000000", "0.00000000"], ["72709.39000000", "0.00000000"], ["72709.00000000", "0.00000000"], ["72707.18000000", "0.00000000"], ["72707.06000000", "0.00000000"], ["72705.36000000", "0.00000000"], ["72700.60000000", "0.99689000"], ["72700.59000000", "1.36346000"], ["72700.01000000", "0.16326000"], ["72696.74000000", "0.00000000"], ["72695.15000000", "0.00000000"], ["72692.60000000", "1.59901000"], ["72689.60000000", "0.18097000"], ["72686.13000000", "0.00000000"], ["72680.05000000", "0.36892000"], ["72668.43000000", "0.00024000"], ["72665.38000000", "0.82598000"], ["72657.77000000", "0.00000000"], ["72654.24000000", "0.00043000"], ["72641.12000000", "0.00008000"], ["72622.01000000", "0.00000000"], ["72372.85000000", "0.00028000"], ["72365.41000000", "0.00028000"], ["72357.97000000", "0.00028000"], ["72350.53000000", "0.00028000"], ["72343.09000000", "0.00028000"], ["72335.65000000", "0.00028000"], ["72023.49000000", "0.00000000"], ["72014.58000000", "0.00007000"], ["65467.80000000", "0.00085000"], ["58193.60000000", "0.00034000"]], "a": [["72742.01000000", "0.42645000"], ["72742.02000000", "0.00054000"], ["72742.03000000", "0.00014000"], ["72742.07000000", "0.04000000"], ["72743.37000000", "0.16961000"], ["72743.38000000", "0.00016000"], ["72743.39000000", "0.00000000"], ["72743.56000000", "0.00000000"], ["72743.57000000", "0.00000000"], ["72743.58000000", "0.00408000"], ["72743.72000000", "0.00008000"], ["72743.99000000", "0.00000000"], ["72744.00000000", "0.00024000"], ["72744.01000000", "0.19501000"], ["72744.41000000", "0.00016000"], ["72744.42000000", "0.40872000"], ["72744.46000000", "0.00000000"], ["72744.76000000", "0.01000000"], ["72744.83000000", "0.02000000"], ["72744.95000000", "0.00016000"], ["72744.96000000", "0.02016000"], ["72745.46000000", "0.00000000"], ["72745.93000000", "0.00000000"], ["72745.94000000", "0.03939000"], ["72746.00000000", "0.00008000"], ["72746.01000000", "0.02142000"], ["72746.25000000", "0.05379000"], ["72746.28000000", "0.00031000"], ["72746.62000000", "0.00000000"], ["72747.00000000", "0.00000000"], ["72747.04000000", "0.00031000"], ["72747.15000000", "0.00000000"], ["72747.16000000", "0.04535000"], ["72747.73000000", "0.00000000"], ["72748.76000000", "0.08000000"], ["72749.16000000", "0.18120000"], ["72749.65000000", "0.00768000"], ["72749.67000000", "0.58801000"], ["72749.68000000", "0.18120000"], ["72749.69000000", "0.00000000"], ["72749.70000000", "0.00008000"], ["72749.93000000", "0.00000000"], ["72750.28000000", "0.00000000"], ["72751.50000000", "0.00000000"], ["72751.76000000", "0.00000000"], ["72752.02000000", "0.18120000"], ["72752.49000000", "0.00000000"], ["72753.45000000", "0.18120000"], ["72753.76000000", "0.00007000"], ["72753.77000000", "0.00000000"], ["72753.80000000", "0.65957000"], ["72753.81000000", "0.18958000"], ["72755.88000000", "0.00000000"], ["72756.44000000", "0.00000000"], ["72757.78000000", "0.85661000"], ["72757.79000000", "0.00000000"], ["72757.80000000", "0.00000000"], ["72758.74000000", "0.00000000"], ["72759.97000000", "0.00008000"], ["72760.82000000", "0.00000000"], ["72760.89000000", "0.00000000"], ["72762.18000000", "0.00008000"], ["72762.19000000", "0.00000000"], ["72762.91000000", "0.00400000"], ["72763.79000000", "0.68818000"], ["72766.32000000", "0.18120000"], ["72766.35000000", "0.64280000"], ["72772.70000000", "0.00000000"], ["72776.26000000", "0.00000000"], ["72798.58000000", "0.00000000"], ["72802.47000000", "0.00572000"], ["72803.22000000", "0.00000000"], ["72806.49000000", "0.82598000"], ["72812.58000000", "0.02830000"], ["72871.09000000", "0.00000000"], ["73469.44000000", "0.00007000"], ["73478.53000000", "0.00000000"]], "_local_ts_utc": "2026-06-01T07:49:00.011282+00:00"}
{"e": "depthUpdate", "E": 1780300141214, "s": "BTCUSDT", "U": 94551765328, "u": 94551765834, "b": [["72742.00000000", "4.15240000"], ["72741.99000000", "0.00016000"], ["72741.76000000", "0.00400000"], ["72741.40000000", "0.00016000"], ["72741.39000000", "0.03108000"], ["72741.38000000", "0.00000000"], ["72741.37000000", "0.00008000"], ["72741.12000000", "0.00016000"], ["72741.11000000", "0.03407000"], ["72740.99000000", "0.00000000"], ["72740.98000000", "0.00024000"], ["72740.97000000", "0.04144000"], ["72740.59000000", "0.00016000"], ["72740.58000000", "0.20435000"], ["72740.57000000", "0.18136000"], ["72740.01000000", "0.00000000"], ["72739.94000000", "0.00400000"], ["72739.77000000", "0.00009000"], ["72739.63000000", "0.00589000"], ["72739.60000000", "0.00016000"], ["72739.51000000", "0.00000000"], ["72739.50000000", "0.00000000"], ["72739.47000000", "0.00000000"], ["72739.14000000", "0.18136000"], ["72738.86000000", "0.00016000"], ["72738.56000000", "0.00000000"], ["72738.53000000", "0.00000000"], ["72738.35000000", "0.05464000"], ["72738.04000000", "0.00000000"], ["72738.00000000", "0.02280000"], ["72737.00000000", "0.00028000"], ["72736.99000000", "0.00000000"], ["72736.95000000", "0.00000000"], ["72736.46000000", "0.33836000"], ["72736.29000000", "0.65949000"], ["72734.73000000", "0.00000000"], ["72734.30000000", "0.00011000"], ["72733.34000000", "0.28458000"], ["72733.17000000", "0.66099000"], ["72731.09000000", "0.01375000"], ["72730.27000000", "1.14231000"], ["72728.05000000", "0.00000000"], ["72727.46000000", "0.00014000"], ["72727.03000000", "1.05663000"], ["72726.92000000", "0.00148000"], ["72723.07000000", "0.00000000"], ["72721.20000000", "0.00000000"], ["72721.19000000", "0.00000000"], ["72720.18000000", "0.00102000"], ["72719.54000000", "0.00011000"], ["72719.12000000", "0.00000000"], ["72718.45000000", "0.00200000"], ["72717.80000000", "0.00000000"], ["72717.74000000", "0.00000000"], ["72717.69000000", "0.00130000"], ["72717.42000000", "0.00000000"], ["72717.41000000", "0.00000000"], ["72717.39000000", "0.00008000"], ["72717.36000000", "0.00000000"], ["72717.18000000", "0.00000000"], ["72716.79000000", "0.00000000"], ["72716.70000000", "0.00000000"], ["72716.66000000", "0.00050000"], ["72716.65000000", "0.00000000"], ["72716.58000000", "0.00000000"], ["72716.57000000", "0.00000000"], ["72716.56000000", "0.00000000"], ["72716.55000000", "0.00102000"], ["72716.48000000", "0.00000000"], ["72716.45000000", "0.00000000"], ["72716.44000000", "0.00000000"], ["72716.42000000", "0.00000000"], ["72716.40000000", "0.00000000"], ["72716.39000000", "0.00000000"], ["72716.33000000", "0.00000000"], ["72716.23000000", "0.00000000"], ["72715.99000000", "0.00000000"], ["72715.59000000", "0.00000000"], ["72714.83000000", "0.18120000"], ["72714.58000000", "0.00000000"], ["72712.90000000", "0.01371000"], ["72712.64000000", "0.00000000"], ["72712.16000000", "0.00011000"], ["72710.82000000", "0.00000000"], ["72707.06000000", "0.29402000"], ["72700.60000000", "0.98314000"], ["72700.01000000", "0.00055000"], ["72698.82000000", "0.49581000"], ["72698.07000000", "0.00000000"], ["72697.72000000", "0.00000000"], ["72696.66000000", "0.00000000"], ["72694.83000000", "0.00000000"], ["72694.76000000", "0.00000000"], ["72692.61000000", "0.00342000"], ["72690.52000000", "0.00007000"], ["72689.60000000", "0.00000000"], ["72685.91000000", "0.36892000"], ["72680.11000000", "1.29122000"], ["72672.78000000", "0.49599000"], ["72620.01000000", "0.00137000"], ["72328.21000000", "0.00028000"], ["72320.77000000", "0.00028000"], ["72313.33000000", "0.00028000"], ["72305.90000000", "0.00028000"], ["65467.80000000", "0.00119000"], ["58193.60000000", "0.00000000"]], "a": [["72742.01000000", "0.37159000"], ["72742.02000000", "0.00094000"], ["72742.06000000", "0.00000000"], ["72742.07000000", "0.00016000"], ["72742.52000000", "0.00024000"], ["72742.53000000", "0.04000000"], ["72743.36000000", "0.00000000"], ["72743.37000000", "0.00016000"], ["72743.38000000", "0.00000000"], ["72743.58000000", "0.00000000"], ["72744.00000000", "0.00000000"], ["72744.01000000", "0.00552000"], ["72744.40000000", "0.00016000"], ["72744.41000000", "0.12838000"], ["72744.42000000", "0.40872000"], ["72744.76000000", "0.00016000"], ["72744.83000000", "0.02016000"], ["72744.95000000", "0.00000000"], ["72744.96000000", "0.00016000"], ["72745.27000000", "0.00031000"], ["72745.29000000", "0.00000000"], ["72745.40000000", "0.00000000"], ["72745.93000000", "0.00016000"], ["72745.94000000", "0.09627000"], ["72746.00000000", "0.00000000"], ["72746.01000000", "0.00000000"], ["72746.24000000", "0.00036000"], ["72746.25000000", "0.05363000"], ["72746.28000000", "0.00000000"], ["72746.67000000", "0.00008000"], ["72746.86000000", "0.00000000"], ["72746.87000000", "0.00000000"], ["72746.89000000", "0.00000000"], ["72746.96000000", "0.01406000"], ["72746.97000000", "0.02860000"], ["72746.99000000", "0.00000000"], ["72747.04000000", "0.00000000"], ["72747.16000000", "0.00000000"], ["72747.22000000", "0.00000000"], ["72747.73000000", "0.18120000"], ["72748.43000000", "0.00031000"], ["72748.76000000", "0.04000000"], ["72749.04000000", "0.00000000"], ["72749.06000000", "0.01000000"], ["72749.15000000", "0.00008000"], ["72749.26000000", "0.02000000"], ["72749.28000000", "0.28395000"], ["72749.29000000", "0.27300000"], ["72749.67000000", "0.00000000"], ["72749.68000000", "0.00000000"], ["72749.70000000", "0.00000000"], ["72749.76000000", "0.08000000"], ["72749.92000000", "0.00008000"], ["72750.27000000", "0.00000000"], ["72750.55000000", "0.00000000"], ["72750.58000000", "0.00008000"], ["72750.59000000", "0.18120000"], ["72750.92000000", "0.00000000"], ["72750.99000000", "0.00000000"], ["72751.00000000", "0.00008000"], ["72751.01000000", "0.19186000"], ["72752.20000000", "0.00047000"], ["72752.21000000", "0.00048000"], ["72752.43000000", "0.00000000"], ["72752.77000000", "0.00190000"], ["72753.34000000", "0.00008000"], ["72753.78000000", "0.00008000"], ["72753.79000000", "0.65949000"], ["72753.80000000", "0.00829000"], ["72753.81000000", "0.18129000"], ["72755.00000000", "0.17503000"], ["72755.21000000", "0.00007000"], ["72757.77000000", "0.18120000"], ["72757.78000000", "0.51421000"], ["72757.80000000", "0.00008000"], ["72757.82000000", "0.00000000"], ["72757.84000000", "0.00000000"], ["72759.96000000", "0.00408000"], ["72759.97000000", "0.18128000"], ["72762.18000000", "0.00000000"], ["72762.82000000", "0.00008000"], ["72763.46000000", "0.18120000"], ["72763.79000000", "0.00000000"], ["72763.80000000", "0.28442000"], ["72764.89000000", "0.18120000"], ["72765.26000000", "0.00000000"], ["72765.98000000", "0.00008000"], ["72765.99000000", "0.68816000"], ["72766.35000000", "0.18403000"], ["72767.19000000", "0.00008000"], ["72767.48000000", "0.00000000"], ["72767.49000000", "0.00000000"], ["72768.68000000", "0.00000000"], ["72768.71000000", "2.74944000"], ["72770.26000000", "0.00000000"], ["72771.11000000", "0.01371000"], ["72772.04000000", "0.00000000"], ["72772.55000000", "0.00008000"], ["72772.56000000", "0.31132000"], ["72772.70000000", "0.00400000"], ["72772.96000000", "0.00000000"], ["72772.97000000", "0.00000000"], ["72774.55000000", "0.17390000"], ["72774.98000000", "0.00000000"], ["72776.34000000", "0.01034000"], ["72776.66000000", "0.00200000"], ["72777.65000000", "0.00000000"], ["72777.76000000", "0.00008000"], ["72779.72000000", "0.00400000"], ["72779.73000000", "0.00000000"], ["72779.98000000", "0.00407000"], ["72780.53000000", "0.00000000"], ["72781.29000000", "0.00000000"], ["72781.80000000", "0.00400000"], ["72795.47000000", "0.49515000"], ["72798.58000000", "0.00189000"], ["72800.43000000", "1.36859000"], ["72802.69000000", "1.36154000"], ["72805.02000000", "0.09615000"], ["72805.92000000", "0.18446000"], ["72806.49000000", "0.00000000"], ["72807.71000000", "0.00000000"], ["72808.49000000", "0.00000000"], ["72812.95000000", "0.00572000"], ["72813.30000000", "0.00114000"], ["72828.20000000", "0.50000000"], ["72847.13000000", "2.75494000"], ["72859.91000000", "0.44999000"], ["72865.24000000", "0.00000000"], ["72871.09000000", "0.00075000"], ["72936.22000000", "0.00000000"]], "_local_ts_utc": "2026-06-01T07:49:00.111283+00:00"}
{"e": "depthUpdate", "E": 1780300141314, "s": "BTCUSDT", "U": 94551765835, "u": 94551766062, "b": [["72742.00000000", "4.17941000"], ["72741.59000000", "0.04463000"], ["72741.58000000", "0.00000000"], ["72741.57000000", "0.00000000"], ["72741.40000000", "0.00000000"], ["72741.39000000", "0.00016000"], ["72741.18000000", "0.00000000"], ["72741.12000000", "0.00000000"], ["72741.11000000", "0.00016000"], ["72740.98000000", "0.00008000"], ["72740.97000000", "0.04144000"], ["72740.91000000", "0.05942000"], ["72740.89000000", "0.00550000"], ["72740.86000000", "0.03592000"], ["72740.84000000", "0.00550000"], ["72740.59000000", "0.00000000"], ["72740.58000000", "0.20435000"], ["72740.01000000", "0.00000000"], ["72739.63000000", "0.00589000"], ["72739.60000000", "0.00000000"], ["72739.14000000", "0.18120000"], ["72738.86000000", "0.00000000"], ["72738.43000000", "0.05075000"], ["72737.20000000", "0.00769000"], ["72732.76000000", "0.02000000"], ["72732.51000000", "0.02000000"], ["72732.14000000", "0.00000000"], ["72730.30000000", "0.02000000"], ["72727.46000000", "0.00021000"], ["72727.04000000", "0.40856000"], ["72721.18000000", "0.00000000"], ["72719.12000000", "0.18120000"], ["72717.78000000", "0.40856000"], ["72717.69000000", "0.18250000"], ["72710.72000000", "0.02746000"], ["72707.02000000", "0.00000000"], ["72705.63000000", "0.00102000"], ["72700.03000000", "0.18120000"], ["72696.24000000", "0.18120000"], ["72694.83000000", "0.16281000"], ["72693.76000000", "0.18120000"], ["72681.89000000", "0.19134000"], ["72680.70000000", "0.19322000"], ["72680.47000000", "0.57402000"], ["72678.18000000", "0.02000000"], ["72677.96000000", "0.02000000"], ["72675.73000000", "0.02000000"], ["72665.38000000", "0.00000000"], ["65467.80000000", "0.00153000"], ["65467.00000000", "0.00230000"]], "a": [["72742.01000000", "0.07210000"], ["72742.07000000", "0.00000000"], ["72742.52000000", "0.00008000"], ["72742.53000000", "0.00016000"], ["72742.55000000", "0.00016000"], ["72742.56000000", "0.00000000"], ["72742.57000000", "0.04000000"], ["72743.37000000", "0.00000000"], ["72744.01000000", "0.00552000"], ["72744.35000000", "0.00000000"], ["72744.40000000", "0.00000000"], ["72744.41000000", "0.00040000"], ["72744.42000000", "0.40872000"], ["72744.76000000", "0.00000000"], ["72744.83000000", "0.00016000"], ["72744.96000000", "0.00000000"], ["72745.27000000", "0.00000000"], ["72745.94000000", "0.00016000"], ["72746.24000000", "0.00044000"], ["72746.25000000", "0.05379000"], ["72746.30000000", "0.00000000"], ["72746.68000000", "0.01500000"], ["72746.86000000", "0.01717000"], ["72746.91000000", "0.00000000"], ["72746.96000000", "0.00000000"], ["72746.97000000", "0.00000000"], ["72747.12000000", "0.00000000"], ["72747.14000000", "0.00028000"], ["72747.30000000", "0.00000000"], ["72747.72000000", "0.00008000"], ["72748.24000000", "0.01351000"], ["72748.43000000", "0.00000000"], ["72748.76000000", "0.00000000"], ["72748.83000000", "0.00000000"], ["72748.93000000", "0.02000000"], ["72749.26000000", "0.00000000"], ["72749.29000000", "0.00300000"], ["72749.65000000", "0.00000000"], ["72749.76000000", "0.00000000"], ["72749.93000000", "0.00765000"], ["72750.37000000", "0.00031000"], ["72751.90000000", "0.00048000"], ["72752.26000000", "0.14028000"], ["72753.78000000", "0.65957000"], ["72753.79000000", "0.00000000"], ["72757.72000000", "0.56830000"], ["72757.73000000", "0.65949000"], ["72757.77000000", "0.00000000"], ["72757.78000000", "0.00000000"], ["72757.81000000", "0.00000000"], ["72759.97000000", "0.00008000"], ["72759.98000000", "0.75236000"], ["72762.82000000", "0.00008000"], ["72763.46000000", "0.00000000"], ["72764.89000000", "0.00000000"], ["72765.98000000", "0.18128000"], ["72766.32000000", "0.00000000"], ["72766.35000000", "0.18403000"], ["72768.70000000", "2.74944000"], ["72768.71000000", "0.00000000"], ["72771.36000000", "0.00000000"], ["72774.52000000", "0.00400000"], ["72774.55000000", "0.00008000"], ["72779.78000000", "0.00000000"], ["72781.80000000", "0.00000000"], ["72823.42000000", "0.00572000"], ["72847.12000000", "2.74944000"], ["72847.13000000", "0.00550000"], ["73210.18000000", "0.00000000"]], "_local_ts_utc": "2026-06-01T07:49:00.210458+00:00"}
{"e": "depthUpdate", "E": 1780300141414, "s": "BTCUSDT", "U": 94551766063, "u": 94551766315, "b": [["72742.00000000", "3.89903000"], ["72741.99000000", "0.00072000"], ["72741.60000000", "0.00000000"], ["72741.59000000", "0.00032000"], ["72741.58000000", "0.04439000"], ["72741.39000000", "0.00000000"], ["72741.30000000", "0.00000000"], ["72741.18000000", "0.00000000"], ["72741.11000000", "0.00000000"], ["72740.98000000", "0.00024000"], ["72740.97000000", "0.04144000"], ["72740.92000000", "0.00000000"], ["72740.91000000", "0.00016000"], ["72740.89000000", "0.00016000"], ["72740.87000000", "0.00000000"], ["72740.86000000", "0.00201000"], ["72740.84000000", "0.00016000"], ["72740.59000000", "0.00016000"], ["72740.58000000", "0.20451000"], ["72740.57000000", "0.00016000"], ["72740.04000000", "0.01342000"], ["72740.01000000", "0.00008000"], ["72740.00000000", "0.02326000"], ["72739.63000000", "0.00573000"], ["72739.14000000", "0.00000000"], ["72738.75000000", "0.00000000"], ["72736.47000000", "0.65949000"], ["72736.29000000", "0.00000000"], ["72736.09000000", "0.03407000"], ["72736.01000000", "0.00000000"], ["72735.22000000", "0.01375000"], ["72732.73000000", "0.02000000"], ["72732.27000000", "0.00000000"], ["72730.29000000", "2.74944000"], ["72730.27000000", "0.26755000"], ["72730.26000000", "0.65949000"], ["72727.70000000", "0.00010000"], ["72727.03000000", "0.87543000"], ["72724.84000000", "0.00000000"], ["72721.68000000", "0.00022000"], ["72719.12000000", "0.00000000"], ["72717.69000000", "0.00130000"], ["72716.96000000", "0.00349000"], ["72700.03000000", "0.00000000"], ["72694.83000000", "0.18120000"], ["72692.62000000", "0.00342000"], ["72692.61000000", "0.00000000"], ["72692.50000000", "0.02672000"], ["72681.58000000", "0.00000000"], ["72678.15000000", "0.02000000"], ["72676.00000000", "0.03715000"], ["72634.30000000", "0.00000000"], ["72620.02000000", "0.00137000"], ["72620.01000000", "0.00000000"], ["65467.80000000", "0.00204000"]], "a": [["72742.01000000", "0.36761000"], ["72742.02000000", "0.00062000"], ["72742.49000000", "0.00016000"], ["72742.50000000", "0.04000000"], ["72742.53000000", "0.00000000"], ["72742.55000000", "0.00000000"], ["72742.56000000", "0.00000000"], ["72742.57000000", "0.00016000"], ["72743.44000000", "0.18120000"], ["72744.01000000", "0.00552000"], ["72744.41000000", "0.00024000"], ["72744.42000000", "0.40872000"], ["72744.83000000", "0.00000000"], ["72744.87000000", "0.18120000"], ["72745.93000000", "0.00000000"], ["72745.94000000", "0.00000000"], ["72746.29000000", "0.11880000"], ["72746.30000000", "0.18151000"], ["72746.68000000", "0.01500000"], ["72746.86000000", "0.00016000"], ["72746.87000000", "0.01733000"], ["72747.01000000", "0.00000000"], ["72747.72000000", "0.00016000"], ["72747.73000000", "0.18136000"], ["72748.24000000", "0.00016000"], ["72748.74000000", "0.00550000"], ["72748.75000000", "0.06492000"], ["72748.93000000", "0.00000000"], ["72749.15000000", "0.00039000"], ["72749.28000000", "0.30608000"], ["72749.29000000", "0.27300000"], ["72749.51000000", "0.00000000"], ["72749.93000000", "0.00000000"], ["72749.95000000", "0.00022000"], ["72750.26000000", "0.00000000"], ["72750.37000000", "0.00000000"], ["72750.63000000", "0.02000000"], ["72751.61000000", "0.00069000"], ["72751.82000000", "0.00000000"], ["72752.05000000", "0.00742000"], ["72753.76000000", "0.00836000"], ["72753.80000000", "0.00000000"], ["72759.17000000", "0.18120000"], ["72759.97000000", "0.18128000"], ["72762.03000000", "0.18120000"], ["72762.82000000", "2.74952000"], ["72763.46000000", "0.18120000"], ["72763.80000000", "0.61894000"], ["72764.89000000", "0.18120000"], ["72768.07000000", "0.16841000"], ["72770.91000000", "0.00200000"], ["72777.75000000", "0.00200000"], ["72780.11000000", "0.00000000"], ["72833.90000000", "0.00572000"], ["72847.12000000", "0.00000000"], ["73405.76000000", "0.00000000"]], "_local_ts_utc": "2026-06-01T07:49:00.310774+00:00"}
{"e": "depthUpdate", "E": 1780300141514, "s": "BTCUSDT", "U": 94551766316, "u": 94551766547, "b": [["72742.00000000", "3.89775000"], ["72741.99000000", "0.00016000"], ["72741.60000000", "0.00016000"], ["72741.59000000", "0.04231000"], ["72741.58000000", "0.00016000"], ["72741.53000000", "0.00016000"], ["72741.52000000", "0.00550000"], ["72741.41000000", "0.00550000"], ["72740.99000000", "0.00016000"], ["72740.98000000", "0.15928000"], ["72740.97000000", "0.04144000"], ["72740.91000000", "0.00000000"], ["72740.89000000", "0.00000000"], ["72740.87000000", "0.00000000"], ["72740.86000000", "0.00185000"], ["72740.84000000", "0.00000000"], ["72740.59000000", "0.00000000"], ["72740.58000000", "0.00024000"], ["72740.57000000", "0.18120000"], ["72740.04000000", "0.01358000"], ["72740.01000000", "0.00000000"], ["72740.00000000", "0.02342000"], ["72739.63000000", "0.00589000"], ["72739.14000000", "0.18120000"], ["72738.44000000", "0.00000000"], ["72738.43000000", "0.05091000"], ["72736.61000000", "0.35061000"], ["72736.46000000", "0.00008000"], ["72733.17000000", "0.66086000"], ["72731.91000000", "0.00047000"], ["72730.30000000", "1.16234000"], ["72730.27000000", "0.00000000"], ["72727.70000000", "0.18130000"], ["72727.46000000", "0.00028000"], ["72727.05000000", "0.18208000"], ["72724.84000000", "0.16853000"], ["72720.18000000", "0.00115000"], ["72719.77000000", "0.00200000"], ["72718.45000000", "0.00000000"], ["72717.79000000", "0.18302000"], ["72711.35000000", "0.00000000"], ["72709.27000000", "0.00155000"], ["72698.35000000", "0.00013000"], ["72689.52000000", "0.00015000"], ["72678.15000000", "0.00000000"], ["72676.53000000", "0.00499000"], ["72667.69000000", "0.00000000"], ["72654.71000000", "0.00013000"], ["72650.56000000", "0.00008000"], ["72645.87000000", "0.00000000"], ["72632.89000000", "0.00013000"], ["65467.80000000", "0.00238000"], ["58193.60000000", "0.00034000"], ["50919.40000000", "0.00000000"]], "a": [["72742.01000000", "0.36831000"], ["72742.50000000", "0.04016000"], ["72742.57000000", "0.00000000"], ["72743.42000000", "0.00016000"], ["72743.43000000", "0.23202000"], ["72743.44000000", "0.00016000"], ["72744.42000000", "0.40872000"], ["72744.86000000", "0.00016000"], ["72744.87000000", "0.18136000"], ["72746.25000000", "0.05379000"], ["72746.29000000", "0.13982000"], ["72746.30000000", "0.18136000"], ["72746.68000000", "0.01484000"], ["72746.75000000", "0.00031000"], ["72746.83000000", "0.01767000"], ["72746.86000000", "0.00000000"], ["72746.87000000", "0.00000000"], ["72747.68000000", "0.00000000"], ["72747.72000000", "0.00000000"], ["72747.73000000", "0.18120000"], ["72748.24000000", "0.00000000"], ["72749.15000000", "0.00008000"], ["72749.95000000", "0.00011000"], ["72751.01000000", "0.39003000"], ["72751.61000000", "0.00000000"], ["72753.80000000", "0.00018000"], ["72756.00000000", "0.01080000"], ["72756.56000000", "0.00008000"], ["72757.28000000", "0.00008000"], ["72758.00000000", "0.01080000"], ["72759.17000000", "0.00000000"], ["72759.98000000", "1.40067000"], ["72760.00000000", "0.01663000"], ["72761.45000000", "0.50000000"], ["72762.00000000", "0.01080000"], ["72762.03000000", "0.00000000"], ["72763.46000000", "0.00000000"], ["72763.83000000", "0.00013000"], ["72764.00000000", "0.01080000"], ["72764.89000000", "0.00000000"], ["72765.98000000", "0.00008000"], ["72766.35000000", "0.00283000"], ["72768.07000000", "0.00008000"], ["72774.56000000", "0.65949000"], ["72776.66000000", "0.00000000"], ["72776.84000000", "0.00137000"], ["72777.98000000", "0.00200000"], ["72785.66000000", "0.00013000"], ["72798.66000000", "0.65949000"], ["72807.48000000", "0.00013000"], ["72820.49000000", "0.00000000"], ["72829.30000000", "0.00013000"], ["72842.32000000", "0.00000000"], ["72844.37000000", "0.00572000"], ["72851.12000000", "0.00013000"], ["72860.32000000", "0.00000000"], ["72864.14000000", "0.00000000"]], "_local_ts_utc": "2026-06-01T07:49:00.409921+00:00"}
{"e": "depthUpdate", "E": 1780300141614, "s": "BTCUSDT", "U": 94551766548, "u": 94551766755, "b": [["72742.00000000", "3.98397000"], ["72741.99000000", "0.00016000"], ["72741.60000000", "0.00000000"], ["72741.59000000", "0.00032000"], ["72741.58000000", "0.00000000"], ["72741.53000000", "0.00000000"], ["72741.52000000", "0.00016000"], ["72741.42000000", "0.00000000"], ["72741.41000000", "0.03215000"], ["72740.98000000", "0.15944000"], ["72740.97000000", "0.04144000"], ["72740.58000000", "0.00016000"], ["72740.55000000", "0.00924000"], ["72740.40000000", "0.00000000"], ["72740.01000000", "0.00008000"], ["72739.63000000", "0.00573000"], ["72738.43000000", "0.05075000"], ["72736.79000000", "0.18958000"], ["72736.28000000", "0.21029000"], ["72736.09000000", "0.00000000"], ["72731.96000000", "0.01376000"], ["72731.91000000", "0.00000000"], ["72730.74000000", "0.02000000"], ["72730.31000000", "0.18120000"], ["72730.28000000", "0.00000000"], ["72730.06000000", "0.02017000"], ["72726.68000000", "0.02000000"], ["72724.84000000", "0.00000000"], ["72718.95000000", "0.00000000"], ["72717.79000000", "0.00182000"], ["72694.83000000", "0.00000000"], ["72677.96000000", "0.00000000"], ["72675.73000000", "0.00000000"], ["72667.80000000", "0.02000000"], ["72667.12000000", "0.02000000"], ["65467.80000000", "0.00255000"], ["58193.60000000", "0.00000000"]], "a": [["72742.01000000", "0.36831000"], ["72742.31000000", "0.04000000"], ["72742.41000000", "0.00016000"], ["72742.42000000", "0.00000000"], ["72742.49000000", "0.00000000"], ["72742.50000000", "0.00016000"], ["72743.38000000", "0.00755000"], ["72743.43000000", "0.23218000"], ["72743.44000000", "0.00000000"], ["72744.78000000", "0.00000000"], ["72745.59000000", "0.00000000"], ["72745.96000000", "0.00000000"], ["72746.15000000", "0.00008000"], ["72746.16000000", "0.05942000"], ["72746.24000000", "0.00036000"], ["72746.75000000", "0.00000000"], ["72746.83000000", "0.00000000"], ["72746.84000000", "0.00000000"], ["72746.90000000", "0.02674000"], ["72747.02000000", "0.00742000"], ["72747.41000000", "0.00031000"], ["72747.48000000", "0.01100000"], ["72747.52000000", "0.00007000"], ["72748.26000000", "0.00765000"], ["72748.31000000", "0.01381000"], ["72748.74000000", "0.00000000"], ["72748.75000000", "0.00000000"], ["72749.99000000", "0.00007000"], ["72753.78000000", "0.65975000"], ["72753.80000000", "0.00000000"], ["72760.90000000", "0.00000000"], ["72809.98000000", "0.19134000"], ["72854.85000000", "0.00572000"]], "_local_ts_utc": "2026-06-01T07:49:00.510557+00:00"}
{"e": "depthUpdate", "E": 1780300141714, "s": "BTCUSDT", "U": 94551766756, "u": 94551766966, "b": [["72742.00000000", "3.98256000"], ["72741.99000000", "0.00072000"], ["72741.64000000", "0.00000000"], ["72741.59000000", "0.00000000"], ["72741.52000000", "0.00000000"], ["72741.42000000", "0.00016000"], ["72741.41000000", "0.03419000"], ["72741.22000000", "0.07042000"], ["72741.20000000", "0.00000000"], ["72741.19000000", "0.00000000"], ["72740.86000000", "0.00000000"], ["72740.57000000", "0.18136000"], ["72740.01000000", "0.00008000"], ["72737.34000000", "0.00000000"], ["72736.49000000", "0.03407000"], ["72736.28000000", "0.17622000"], ["72732.00000000", "0.02280000"], ["72727.70000000", "0.00010000"], ["72727.19000000", "0.00185000"], ["72727.05000000", "0.00088000"], ["72726.10000000", "0.00939000"], ["72725.21000000", "0.03560000"], ["72722.97000000", "1.24898000"], ["72716.26000000", "0.00000000"], ["72711.35000000", "0.00626000"], ["72710.62000000", "0.00000000"], ["72696.24000000", "0.00000000"], ["72694.83000000", "0.18120000"], ["72692.62000000", "0.00000000"], ["72689.60000000", "0.91961000"], ["72664.30000000", "2.03659000"], ["72620.02000000", "0.00000000"], ["65467.80000000", "0.00289000"]], "a": [["72742.01000000", "0.83969000"], ["72742.28000000", "0.04000000"], ["72742.30000000", "0.00016000"], ["72742.31000000", "0.00016000"], ["72742.41000000", "0.00000000"], ["72742.50000000", "0.00000000"], ["72742.99000000", "0.00008000"], ["72743.38000000", "0.00016000"], ["72743.42000000", "0.00000000"], ["72743.43000000", "0.00016000"], ["72744.21000000", "0.00000000"], ["72744.39000000", "0.00016000"], ["72744.40000000", "0.18136000"], ["72744.41000000", "0.12236000"], ["72744.86000000", "0.00000000"], ["72744.87000000", "0.00016000"], ["72745.70000000", "0.00031000"], ["72746.15000000", "0.00016000"], ["72746.16000000", "0.07058000"], ["72746.23000000", "0.14587000"], ["72746.24000000", "0.18148000"], ["72746.29000000", "0.00000000"], ["72746.30000000", "0.00000000"], ["72746.89000000", "0.00000000"], ["72746.90000000", "0.00000000"], ["72746.97000000", "0.02594000"], ["72746.99000000", "0.00000000"], ["72747.02000000", "0.00000000"], ["72747.41000000", "0.00000000"], ["72747.48000000", "0.00000000"], ["72747.94000000", "0.00031000"], ["72748.26000000", "0.00000000"], ["72748.31000000", "0.00000000"], ["72749.29000000", "0.27300000"], ["72757.71000000", "0.18120000"], ["72757.74000000", "0.00000000"], ["72759.17000000", "0.00000000"], ["72762.91000000", "0.00000000"], ["72763.10000000", "0.00400000"], ["72768.08000000", "0.66149000"], ["72770.91000000", "0.00000000"], ["72805.02000000", "0.00000000"], ["72829.22000000", "1.23651000"], ["72841.86000000", "0.09610000"], ["72844.08000000", "0.00939000"], ["72855.75000000", "0.00000000"], ["72859.90000000", "0.14120000"], ["72865.32000000", "0.00572000"], ["72899.67000000", "0.00185000"], ["72913.37000000", "0.00000000"], ["72914.10000000", "0.00000000"]], "_local_ts_utc": "2026-06-01T07:49:00.609978+00:00"}
{"e": "depthUpdate", "E": 1780300141814, "s": "BTCUSDT", "U": 94551766967, "u": 94551767393, "b": [["72742.00000000", "3.59890000"], ["72741.99000000", "0.00072000"], ["72741.76000000", "0.00000000"], ["72741.42000000", "0.00000000"], ["72741.41000000", "0.00016000"], ["72741.23000000", "0.00000000"], ["72741.22000000", "0.00016000"], ["72740.99000000", "0.00000000"], ["72740.98000000", "0.00032000"], ["72740.96000000", "0.00000000"], ["72740.86000000", "0.00000000"], ["72740.58000000", "0.00008000"], ["72740.57000000", "0.00016000"], ["72740.55000000", "0.00940000"], ["72740.05000000", "0.00016000"], ["72740.01000000", "0.00016000"], ["72739.94000000", "0.00000000"], ["72739.15000000", "0.00008000"], ["72739.14000000", "0.00000000"], ["72738.44000000", "0.00016000"], ["72738.36000000", "0.00008000"], ["72737.71000000", "0.00000000"], ["72737.00000000", "0.00000000"], ["72736.79000000", "0.00000000"], ["72736.74000000", "0.05958000"], ["72736.73000000", "0.04473000"], ["72736.62000000", "0.00008000"], ["72736.61000000", "0.00000000"], ["72736.49000000", "0.00000000"], ["72736.48000000", "0.00008000"], ["72736.47000000", "0.00000000"], ["72736.28000000", "0.00000000"], ["72735.22000000", "0.00000000"], ["72735.17000000", "0.00028000"], ["72734.85000000", "0.00000000"], ["72733.44000000", "0.05518000"], ["72733.43000000", "0.00000000"], ["72733.42000000", "0.00000000"], ["72733.34000000", "0.00000000"], ["72733.27000000", "0.06492000"], ["72733.18000000", "0.00008000"], ["72733.17000000", "0.00137000"], ["72732.02000000", "0.00008000"], ["72732.01000000", "0.18120000"], ["72731.96000000", "0.00000000"], ["72731.09000000", "0.00000000"], ["72731.05000000", "0.04000000"], ["72730.56000000", "0.18120000"], ["72730.34000000", "0.47112000"], ["72730.33000000", "0.18120000"], ["72730.32000000", "0.65949000"], ["72730.31000000", "0.00000000"], ["72730.30000000", "0.02008000"], ["72730.29000000", "0.00000000"], ["72730.26000000", "0.00000000"], ["72730.24000000", "0.00000000"], ["72730.20000000", "0.00047000"], ["72727.70000000", "0.18130000"], ["72727.52000000", "0.00000000"], ["72727.46000000", "0.00035000"], ["72727.06000000", "1.78281000"], ["72727.05000000", "3.40981000"], ["72727.04000000", "0.00008000"], ["72727.03000000", "0.00000000"], ["72727.02000000", "0.00077000"], ["72726.82000000", "0.00000000"], ["72726.68000000", "0.00000000"], ["72724.64000000", "0.00000000"], ["72723.83000000", "0.00000000"], ["72723.52000000", "0.55222000"], ["72723.51000000", "0.65985000"], ["72722.99000000", "0.40856000"], ["72722.98000000", "0.00000000"], ["72722.97000000", "0.00027000"], ["72722.96000000", "0.02732000"], ["72722.28000000", "0.00000000"], ["72722.27000000", "0.00000000"], ["72721.68000000", "0.00000000"], ["72721.50000000", "0.00000000"], ["72719.77000000", "0.00000000"], ["72719.38000000", "0.18120000"], ["72719.37000000", "2.74944000"], ["72717.87000000", "0.02015000"], ["72717.78000000", "0.00000000"], ["72716.04000000", "0.00200000"], ["72716.02000000", "0.00008000"], ["72715.95000000", "0.00000000"], ["72714.83000000", "0.18120000"], ["72713.97000000", "0.00000000"], ["72713.40000000", "0.18120000"], ["72712.91000000", "0.00109000"], ["72710.82000000", "0.00400000"], ["72710.79000000", "0.00000000"], ["72710.53000000", "0.18128000"], ["72709.59000000", "0.00000000"], ["72709.00000000", "0.00400000"], ["72708.10000000", "0.00000000"], ["72707.68000000", "0.18120000"], ["72704.20000000", "1.33296000"], ["72700.60000000", "0.00000000"], ["72700.59000000", "0.00000000"], ["72700.03000000", "0.18120000"], ["72697.67000000", "0.18214000"], ["72696.24000000", "0.18120000"], ["72694.83000000", "0.18120000"], ["72689.60000000", "0.00000000"], ["72688.98000000", "0.00000000"], ["72684.65000000", "0.00000000"], ["72683.12000000", "0.00011000"], ["72682.14000000", "0.00341000"], ["72682.13000000", "0.00000000"], ["72679.22000000", "0.04710000"], ["72671.25000000", "1.36401000"], ["72667.80000000", "0.00000000"], ["72664.55000000", "0.33678000"], ["72664.30000000", "0.00000000"], ["72660.01000000", "0.00282000"], ["72658.01000000", "0.00000000"], ["72634.30000000", "0.00000000"], ["72610.01000000", "0.00137000"], ["72608.01000000", "0.00000000"], ["72595.96000000", "0.00000000"], ["72587.51000000", "0.00113000"], ["72555.01000000", "0.00000000"], ["72550.45000000", "0.00822000"], ["65467.80000000", "0.00323000"]], "a": [["72742.01000000", "4.98140000"], ["72742.03000000", "0.00030000"], ["72742.04000000", "0.04000000"], ["72742.16000000", "0.01100000"], ["72742.27000000", "0.00000000"], ["72742.28000000", "0.00016000"], ["72742.30000000", "0.00000000"], ["72742.31000000", "0.00000000"], ["72743.15000000", "0.00000000"], ["72743.38000000", "0.00000000"], ["72743.42000000", "0.00016000"], ["72743.43000000", "0.23675000"], ["72743.44000000", "0.18120000"], ["72743.89000000", "0.00008000"], ["72743.90000000", "0.05942000"], ["72744.01000000", "0.00552000"], ["72744.39000000", "0.00016000"], ["72744.40000000", "0.18136000"], ["72744.41000000", "0.00024000"], ["72744.42000000", "0.40872000"], ["72744.57000000", "0.00031000"], ["72744.77000000", "0.00000000"], ["72744.87000000", "0.00000000"], ["72745.40000000", "0.00400000"], ["72745.70000000", "0.00000000"], ["72746.14000000", "0.34646000"], ["72746.15000000", "0.65949000"], ["72746.16000000", "0.00016000"], ["72746.23000000", "0.00016000"], ["72746.24000000", "0.18164000"], ["72746.25000000", "0.05363000"], ["72746.63000000", "0.05964000"], ["72746.76000000", "0.00000000"], ["72746.97000000", "0.00000000"], ["72747.22000000", "0.00400000"], ["72747.29000000", "0.00000000"], ["72747.94000000", "0.00000000"], ["72749.04000000", "0.00400000"], ["72749.14000000", "0.60990000"], ["72749.15000000", "0.65957000"], ["72749.28000000", "0.00008000"], ["72750.63000000", "0.00000000"], ["72751.90000000", "0.00000000"], ["72752.20000000", "0.00000000"], ["72752.21000000", "0.00000000"], ["72752.99000000", "0.03407000"], ["72757.70000000", "0.50637000"], ["72758.00000000", "0.02080000"], ["72759.17000000", "0.00000000"], ["72759.97000000", "0.00008000"], ["72760.00000000", "0.02663000"], ["72761.40000000", "0.00008000"], ["72762.00000000", "0.02080000"], ["72762.20000000", "0.00008000"], ["72763.80000000", "0.00000000"], ["72764.00000000", "0.02080000"], ["72765.99000000", "0.00000000"], ["72772.92000000", "1.36541000"], ["72774.25000000", "0.00200000"], ["72774.52000000", "0.00000000"], ["72776.15000000", "0.49529000"], ["72776.34000000", "0.00634000"], ["72777.98000000", "0.00000000"], ["72779.98000000", "0.00007000"], ["72783.43000000", "0.02682000"], ["72795.47000000", "0.00000000"], ["72801.07000000", "0.49511000"], ["72802.69000000", "0.00000000"], ["72875.80000000", "0.00572000"], ["80016.21000000", "0.00007000"]], "_local_ts_utc": "2026-06-01T07:49:00.709951+00:00"}
{"e": "depthUpdate", "E": 1780300141914, "s": "BTCUSDT", "U": 94551767394, "u": 94551767518, "b": [["72742.00000000", "3.41541000"], ["72741.99000000", "0.00086000"], ["72741.98000000", "0.00014000"], ["72741.41000000", "0.00000000"], ["72741.22000000", "0.00000000"], ["72740.98000000", "0.00016000"], ["72740.97000000", "0.04144000"], ["72740.76000000", "0.00000000"], ["72740.57000000", "0.00000000"], ["72740.45000000", "0.00000000"], ["72740.05000000", "0.00000000"], ["72740.04000000", "0.00016000"], ["72739.63000000", "0.00589000"], ["72739.60000000", "0.00031000"], ["72738.43000000", "0.05091000"], ["72738.36000000", "0.00016000"], ["72738.35000000", "0.05480000"], ["72738.01000000", "0.00008000"], ["72736.75000000", "0.09518000"], ["72736.74000000", "0.00000000"], ["72736.21000000", "0.05942000"], ["72733.44000000", "0.30182000"], ["72733.28000000", "0.65949000"], ["72733.27000000", "0.00000000"], ["72729.86000000", "0.00047000"], ["72727.46000000", "0.00042000"], ["72694.72000000", "0.00110000"], ["72678.18000000", "0.00000000"], ["72640.47000000", "0.00000000"], ["72636.46000000", "0.04432000"], ["65467.80000000", "0.00357000"]], "a": [["72742.01000000", "5.03778000"], ["72742.04000000", "0.04016000"], ["72742.15000000", "0.00016000"], ["72742.16000000", "0.01116000"], ["72742.28000000", "0.00000000"], ["72743.43000000", "0.23691000"], ["72743.44000000", "0.18136000"], ["72743.90000000", "0.05958000"], ["72744.39000000", "0.00000000"], ["72744.40000000", "0.18136000"], ["72744.41000000", "0.00008000"], ["72744.42000000", "0.40872000"], ["72746.12000000", "0.34639000"], ["72746.13000000", "0.65949000"], ["72746.14000000", "0.00000000"], ["72746.15000000", "0.00000000"], ["72746.16000000", "0.00000000"], ["72746.23000000", "0.00000000"], ["72746.24000000", "0.18148000"], ["72749.13000000", "0.65949000"], ["72749.14000000", "0.41261000"], ["72749.15000000", "0.00008000"], ["72762.81000000", "2.74944000"], ["72762.82000000", "0.00008000"], ["72766.00000000", "0.02080000"], ["72768.08000000", "0.65949000"], ["72775.98000000", "0.00114000"], ["72813.30000000", "0.00000000"], ["72854.70000000", "0.04266000"], ["72858.72000000", "0.00000000"], ["72886.27000000", "0.00572000"], ["73000.00000000", "0.59281000"], ["80016.21000000", "0.00000000"]], "_local_ts_utc": "2026-06-01T07:49:00.810356+00:00"}
{"e": "depthUpdate", "E": 1780300142014, "s": "BTCUSDT", "U": 94551767519, "u": 94551767593, "b": [["72742.00000000", "3.51828000"], ["72740.55000000", "0.00940000"], ["72740.04000000", "0.00000000"], ["72739.93000000", "0.00031000"], ["72739.90000000", "0.00031000"], ["72739.60000000", "0.00000000"], ["72736.76000000", "0.05966000"], ["72736.75000000", "0.00000000"], ["72736.21000000", "0.00000000"], ["72729.44000000", "0.18193000"], ["72728.65000000", "0.01375000"], ["72722.27000000", "0.77197000"], ["72719.65000000", "0.64879000"], ["72719.38000000", "0.00000000"], ["72714.83000000", "0.00000000"], ["72697.83000000", "1.20916000"], ["72697.67000000", "0.00094000"], ["72692.61000000", "0.00342000"], ["72682.15000000", "0.00341000"], ["72682.14000000", "0.00000000"], ["72660.02000000", "0.00282000"], ["72660.01000000", "0.00000000"], ["72636.46000000", "0.00000000"], ["72620.01000000", "0.00137000"], ["72610.02000000", "0.36290000"], ["72610.01000000", "0.00000000"], ["72587.52000000", "0.00113000"], ["72587.51000000", "0.00000000"], ["72500.00000000", "42.10394000"], ["70146.50000000", "0.00142000"], ["65467.80000000", "0.00391000"], ["58193.60000000", "0.00034000"]], "a": [["72742.01000000", "5.17260000"], ["72742.15000000", "0.00000000"], ["72742.16000000", "0.00016000"], ["72743.89000000", "0.00000000"], ["72744.42000000", "0.40872000"], ["72752.77000000", "0.00000000"], ["72753.81000000", "0.18147000"], ["72757.70000000", "0.00000000"], ["72758.28000000", "0.62328000"], ["72759.97000000", "0.45893000"], ["72760.00000000", "0.02863000"], ["72762.00000000", "0.02280000"], ["72763.00000000", "0.00200000"], ["72764.00000000", "0.02280000"], ["72770.31000000", "0.00200000"], ["72777.75000000", "0.00000000"], ["72854.70000000", "0.00000000"], ["72896.75000000", "0.00572000"]], "_local_ts_utc": "2026-06-01T07:49:00.912799+00:00"}
{"e": "depthUpdate", "E": 1780300142114, "s": "BTCUSDT", "U": 94551767594, "u": 94551767625, "b": [["72742.00000000", "3.51838000"], ["72740.24000000", "0.00031000"], ["72739.90000000", "0.00000000"], ["72735.71000000", "0.05983000"], ["72728.65000000", "0.00000000"], ["72724.66000000", "0.00007000"], ["72718.89000000", "0.08252000"], ["72667.12000000", "0.00000000"], ["72633.62000000", "0.04568000"], ["72550.44000000", "0.00000000"], ["72549.45000000", "0.09870000"], ["65467.80000000", "0.00408000"]], "a": [["72742.01000000", "5.17450000"], ["72742.04000000", "0.04016000"], ["72742.16000000", "0.00000000"], ["72746.12000000", "0.34655000"], ["72747.37000000", "0.00762000"], ["72751.01000000", "0.39746000"], ["72753.76000000", "0.00836000"], ["72758.28000000", "0.00008000"], ["72758.74000000", "0.62125000"], ["72766.00000000", "0.02280000"], ["72768.00000000", "0.02280000"], ["72851.86000000", "0.04266000"], ["72907.22000000", "0.00571000"]], "_local_ts_utc": "2026-06-01T07:49:01.009979+00:00"}
{"e": "depthUpdate", "E": 1780300142214, "s": "BTCUSDT", "U": 94551767626, "u": 94551767724, "b": [["72742.00000000", "3.51438000"], ["72740.67000000", "0.00000000"], ["72740.24000000", "0.00000000"], ["72739.93000000", "0.00000000"], ["72738.46000000", "0.00170000"], ["72736.76000000", "0.00000000"], ["72733.28000000", "0.00000000"], ["72722.28000000", "0.01376000"], ["72718.89000000", "0.00000000"], ["72718.88000000", "0.08252000"], ["72717.87000000", "0.00015000"], ["72714.37000000", "0.02000000"], ["72713.40000000", "0.00000000"], ["72694.83000000", "0.00000000"], ["72692.61000000", "0.00000000"], ["72680.11000000", "0.18446000"], ["72680.05000000", "0.00000000"], ["72678.67000000", "0.00000000"], ["72667.22000000", "0.02703000"], ["72620.01000000", "0.00000000"], ["65467.80000000", "0.00408000"], ["58193.60000000", "0.00000000"]], "a": [["72742.01000000", "4.95816000"], ["72742.02000000", "0.00054000"], ["72742.03000000", "0.00038000"], ["72742.52000000", "0.00000000"], ["72743.23000000", "0.00774000"], ["72743.42000000", "0.00008000"], ["72743.43000000", "0.23675000"], ["72743.89000000", "0.00000000"], ["72744.00000000", "0.00080000"], ["72744.39000000", "0.00000000"], ["72746.12000000", "0.34663000"], ["72746.24000000", "0.18140000"], ["72746.95000000", "0.01345000"], ["72749.12000000", "0.00008000"], ["72749.13000000", "0.65957000"], ["72749.15000000", "0.00000000"], ["72749.28000000", "0.00000000"], ["72751.00000000", "0.00108000"], ["72753.34000000", "0.00000000"], ["72753.44000000", "0.00008000"], ["72753.78000000", "0.65967000"], ["72754.07000000", "0.00008000"], ["72757.72000000", "0.56838000"], ["72757.80000000", "0.00000000"], ["72758.28000000", "0.00000000"], ["72758.73000000", "0.00008000"], ["72759.96000000", "0.00400000"], ["72760.00000000", "0.02871000"], ["72761.40000000", "0.00000000"], ["72761.44000000", "0.00008000"], ["72762.80000000", "0.00008000"], ["72762.82000000", "0.00000000"], ["72763.00000000", "0.00000000"], ["72765.98000000", "0.00000000"], ["72767.19000000", "0.00000000"], ["72767.39000000", "0.08608000"], ["72768.07000000", "0.00000000"], ["72768.69000000", "0.00008000"], ["72770.09000000", "0.00008000"], ["72772.55000000", "0.00000000"], ["72772.91000000", "0.00008000"], ["72774.55000000", "0.00000000"], ["72776.14000000", "0.00008000"], ["72788.23000000", "0.65957000"], ["72832.86000000", "0.00000000"], ["72834.47000000", "0.00000000"], ["72839.62000000", "0.00000000"], ["72841.86000000", "0.00000000"], ["73107.37000000", "0.00000000"], ["73120.86000000", "0.00013000"], ["73180.33000000", "0.00020000"]], "_local_ts_utc": "2026-06-01T07:49:01.110510+00:00"}
{"e": "depthUpdate", "E": 1780300142314, "s": "BTCUSDT", "U": 94551767725, "u": 94551767840, "b": [["72742.00000000", "3.17470000"], ["72741.39000000", "0.00031000"], ["72740.99000000", "0.00016000"], ["72740.98000000", "0.06047000"], ["72739.50000000", "0.00000000"], ["72739.20000000", "0.00031000"], ["72738.46000000", "0.00139000"], ["72738.01000000", "0.00000000"], ["72738.00000000", "0.02296000"], ["72737.39000000", "0.00031000"], ["72737.20000000", "0.00000000"], ["72736.74000000", "0.06377000"], ["72736.51000000", "0.00000000"], ["72735.90000000", "0.00951000"], ["72735.87000000", "0.00739000"], ["72735.71000000", "0.00041000"], ["72735.52000000", "0.00028000"], ["72735.17000000", "0.00000000"], ["72733.46000000", "0.18561000"], ["72733.45000000", "0.84069000"], ["72733.44000000", "0.00742000"], ["72732.65000000", "0.00070000"], ["72732.28000000", "0.05942000"], ["72730.36000000", "0.44229000"], ["72730.35000000", "0.65949000"], ["72730.34000000", "0.00000000"], ["72730.32000000", "0.00000000"], ["72725.56000000", "0.00000000"], ["72718.88000000", "0.00000000"], ["72718.87000000", "0.08252000"], ["72713.40000000", "0.16841000"], ["72697.84000000", "0.18120000"], ["72692.61000000", "0.00342000"], ["72620.01000000", "0.00137000"], ["65467.80000000", "0.00408000"]], "a": [["72742.01000000", "4.31643000"], ["72742.03000000", "0.00038000"], ["72742.04000000", "0.04016000"], ["72742.99000000", "0.00000000"], ["72743.23000000", "0.00790000"], ["72743.42000000", "0.00024000"], ["72743.43000000", "0.23691000"], ["72743.89000000", "0.00016000"], ["72744.39000000", "0.00008000"], ["72746.00000000", "0.00080000"], ["72746.10000000", "0.35291000"], ["72746.11000000", "0.65949000"], ["72746.12000000", "0.00008000"], ["72746.13000000", "0.00000000"], ["72748.00000000", "0.00080000"], ["72750.00000000", "0.00080000"], ["72752.00000000", "0.00080000"], ["72752.40000000", "0.00000000"], ["72757.93000000", "0.00000000"], ["72758.74000000", "0.00000000"], ["72759.96000000", "0.66349000"], ["72759.97000000", "0.00008000"], ["72759.98000000", "0.75236000"], ["72762.81000000", "0.00000000"], ["72766.95000000", "0.00200000"], ["72770.02000000", "0.00000000"], ["72770.31000000", "0.00000000"], ["72772.94000000", "0.00200000"]], "_local_ts_utc": "2026-06-01T07:49:01.210609+00:00"}
{"e": "depthUpdate", "E": 1780300142414, "s": "BTCUSDT", "U": 94551767841, "u": 94551767951, "b": [["72742.00000000", "0.28562000"], ["72741.39000000", "0.00000000"], ["72740.99000000", "0.00000000"], ["72740.98000000", "0.00032000"], ["72739.65000000", "0.00000000"], ["72739.37000000", "0.00000000"], ["72739.20000000", "0.00000000"], ["72738.01000000", "0.00008000"], ["72738.00000000", "0.02280000"], ["72737.39000000", "0.00000000"], ["72736.75000000", "0.10160000"], ["72736.74000000", "0.00000000"], ["72735.19000000", "0.00000000"], ["72733.46000000", "0.35895000"], ["72733.45000000", "0.00000000"], ["72732.73000000", "0.02069000"], ["72732.65000000", "0.00000000"], ["72732.28000000", "0.00000000"], ["72732.01000000", "0.00000000"], ["72730.56000000", "0.00000000"], ["72730.35000000", "0.00000000"], ["72730.33000000", "0.00000000"], ["72730.01000000", "0.02000000"], ["72729.44000000", "0.00000000"], ["72728.75000000", "0.01375000"], ["72727.05000000", "2.75032000"], ["72723.51000000", "0.00036000"], ["72719.08000000", "0.00000000"], ["72718.87000000", "0.00000000"], ["72716.04000000", "0.00000000"], ["72715.11000000", "0.00200000"], ["72713.40000000", "0.00000000"], ["72712.39000000", "0.00000000"], ["72697.84000000", "0.00000000"], ["72696.24000000", "0.00000000"], ["72679.12000000", "0.00000000"], ["65467.80000000", "0.00408000"], ["58195.00000000", "0.01379000"]], "a": [["72742.01000000", "4.79641000"], ["72742.03000000", "0.00022000"], ["72743.42000000", "0.00008000"], ["72743.43000000", "0.23675000"], ["72743.89000000", "0.00000000"], ["72744.39000000", "0.00000000"], ["72744.42000000", "0.40872000"], ["72759.17000000", "0.18120000"], ["72759.95000000", "0.18120000"], ["72761.40000000", "0.18120000"], ["72762.20000000", "0.18128000"], ["72762.80000000", "2.74952000"], ["72764.89000000", "0.18120000"], ["72766.32000000", "0.18120000"], ["72766.35000000", "0.18403000"], ["72768.07000000", "0.16831000"], ["72773.31000000", "0.00200000"], ["72774.25000000", "0.00000000"], ["73396.68000000", "0.00010000"]], "_local_ts_utc": "2026-06-01T07:49:01.310939+00:00"}
{"e": "depthUpdate", "E": 1780300142518, "s": "BTCUSDT", "U": 94551767952, "u": 94551769402, "b": [["72742.00000000", "0.00000000"], ["72741.99000000", "0.00000000"], ["72741.98000000", "0.00000000"], ["72741.93000000", "0.00000000"], ["72741.84000000", "0.00000000"], ["72741.63000000", "0.00000000"], ["72741.37000000", "0.00000000"], ["72741.25000000", "0.00000000"], ["72741.24000000", "0.00000000"], ["72741.23000000", "0.00000000"], ["72740.98000000", "0.00000000"], ["72740.97000000", "0.00000000"], ["72740.81000000", "0.00000000"], ["72740.74000000", "0.00000000"], ["72740.58000000", "0.00000000"], ["72740.55000000", "0.00000000"], ["72740.52000000", "0.00000000"], ["72740.44000000", "0.00000000"], ["72740.37000000", "0.00000000"], ["72740.31000000", "0.00000000"], ["72740.28000000", "0.00000000"], ["72740.22000000", "0.00000000"], ["72740.06000000", "0.00000000"], ["72740.01000000", "0.00000000"], ["72740.00000000", "0.00000000"], ["72739.91000000", "0.00000000"], ["72739.77000000", "0.00000000"], ["72739.63000000", "0.00000000"], ["72739.56000000", "0.00000000"], ["72739.40000000", "0.00000000"], ["72739.36000000", "0.00000000"], ["72739.30000000", "0.00000000"], ["72739.15000000", "0.00000000"], ["72739.12000000", "0.00000000"], ["72738.92000000", "0.00000000"], ["72738.88000000", "0.00000000"], ["72738.85000000", "0.00000000"], ["72738.46000000", "0.00000000"], ["72738.44000000", "0.00000000"], ["72738.43000000", "0.00000000"], ["72738.38000000", "0.00000000"], ["72738.36000000", "0.00000000"], ["72738.35000000", "0.00000000"], ["72738.25000000", "0.00000000"], ["72738.12000000", "0.00000000"], ["72738.01000000", "0.00000000"], ["72738.00000000", "0.00000000"], ["72737.98000000", "0.00000000"], ["72737.94000000", "0.00000000"], ["72737.64000000", "0.00000000"], ["72737.38000000", "0.00000000"], ["72737.34000000", "0.00000000"], ["72737.28000000", "0.00000000"], ["72737.05000000", "0.00000000"], ["72736.89000000", "0.00000000"], ["72736.75000000", "0.00000000"], ["72736.73000000", "0.00000000"], ["72736.72000000", "0.00753000"], ["72736.71000000", "0.00056000"], ["72736.61000000", "0.00016000"], ["72736.46000000", "0.00000000"], ["72736.37000000", "0.00016000"], ["72736.30000000", "0.00000000"], ["72736.23000000", "0.00000000"], ["72736.01000000", "0.00016000"], ["72735.89000000", "0.00008000"], ["72735.87000000", "0.00000000"], ["72735.52000000", "0.00000000"], ["72735.44000000", "0.00000000"], ["72734.93000000", "0.00000000"], ["72734.57000000", "0.00000000"], ["72734.26000000", "0.00000000"], ["72734.01000000", "0.00028000"], ["72733.46000000", "0.00000000"], ["72733.17000000", "0.00000000"], ["72732.76000000", "0.00000000"], ["72732.73000000", "0.00069000"], ["72732.62000000", "0.00000000"], ["72732.51000000", "0.00000000"], ["72732.44000000", "0.00164000"], ["72732.38000000", "0.00000000"], ["72732.27000000", "0.00000000"], ["72732.01000000", "0.00008000"], ["72731.28000000", "0.00000000"], ["72731.25000000", "0.00000000"], ["72730.74000000", "0.00000000"], ["72730.67000000", "0.00000000"], ["72730.57000000", "0.00000000"], ["72730.36000000", "0.00000000"], ["72730.30000000", "0.00008000"], ["72730.06000000", "0.00017000"], ["72730.02000000", "0.00000000"], ["72730.01000000", "0.02000000"], ["72729.83000000", "0.00000000"], ["72729.82000000", "0.00048000"], ["72728.75000000", "0.00000000"], ["72728.35000000", "0.00000000"], ["72727.70000000", "0.00010000"], ["72727.19000000", "0.00000000"], ["72727.07000000", "0.00000000"], ["72727.06000000", "0.00000000"], ["72727.05000000", "0.00088000"], ["72726.56000000", "0.01485000"], ["72726.46000000", "0.00185000"], ["72726.10000000", "0.00000000"], ["72725.37000000", "0.00939000"], ["72723.52000000", "0.19274000"], ["72722.99000000", "0.00000000"], ["72722.96000000", "0.00000000"], ["72722.73000000", "0.00038000"], ["72722.66000000", "0.18128000"], ["72722.28000000", "0.01376000"], ["72722.27000000", "0.00000000"], ["72721.92000000", "0.00000000"], ["72721.81000000", "0.00000000"], ["72721.49000000", "0.00192000"], ["72721.23000000", "0.18120000"], ["72721.17000000", "0.02000000"], ["72720.55000000", "0.17882000"], ["72719.66000000", "0.00000000"], ["72719.65000000", "0.00000000"], ["72719.53000000", "0.00000000"], ["72719.52000000", "0.00000000"], ["72719.40000000", "0.18120000"], ["72719.39000000", "0.96623000"], ["72719.38000000", "0.00000000"], ["72719.37000000", "0.00000000"], ["72718.53000000", "0.00000000"], ["72717.82000000", "0.00000000"], ["72717.53000000", "0.15000000"], ["72717.19000000", "0.65949000"], ["72716.96000000", "0.00000000"], ["72716.26000000", "2.74944000"], ["72716.02000000", "0.26800000"], ["72716.01000000", "0.00000000"], ["72715.58000000", "0.00014000"], ["72714.90000000", "0.00137000"], ["72714.37000000", "0.00000000"], ["72714.08000000", "0.16342000"], ["72713.40000000", "0.16864000"], ["72712.90000000", "0.00000000"], ["72711.97000000", "0.18120000"], ["72710.96000000", "0.00000000"], ["72710.72000000", "0.00000000"], ["72710.68000000", "0.00000000"], ["72710.53000000", "0.18129000"], ["72710.06000000", "0.00000000"], ["72709.60000000", "0.00000000"], ["72708.69000000", "0.00000000"], ["72708.36000000", "0.18120000"], ["72707.68000000", "0.00000000"], ["72707.53000000", "0.40856000"], ["72707.05000000", "0.00000000"], ["72706.69000000", "0.18121000"], ["72706.67000000", "0.00333000"], ["72706.65000000", "0.00000000"], ["72705.93000000", "0.02000000"], ["72705.76000000", "0.17564000"], ["72705.37000000", "0.00192000"], ["72705.36000000", "0.00400000"], ["72704.77000000", "0.00000000"], ["72704.07000000", "0.00007000"], ["72703.54000000", "0.00400000"], ["72702.72000000", "0.00011000"], ["72702.64000000", "0.18120000"], ["72701.96000000", "0.00000000"], ["72701.91000000", "0.00000000"], ["72701.43000000", "0.00000000"], ["72700.97000000", "0.18121000"], ["72700.53000000", "0.18120000"], ["72700.38000000", "0.00007000"], ["72700.03000000", "0.00000000"], ["72698.82000000", "0.00000000"], ["72698.44000000", "0.18121000"], ["72698.36000000", "0.18120000"], ["72698.35000000", "0.00013000"], ["72697.84000000", "0.00000000"], ["72697.83000000", "0.00000000"], ["72696.73000000", "0.18120000"], ["72696.25000000", "0.00027000"], ["72696.24000000", "0.00000000"], ["72696.01000000", "0.18121000"], ["72695.38000000", "0.00000000"], ["72694.83000000", "0.00000000"], ["72694.21000000", "0.00000000"], ["72694.15000000", "0.18121000"], ["72693.87000000", "0.00000000"], ["72693.77000000", "0.00000000"], ["72693.76000000", "0.00000000"], ["72692.61000000", "0.00000000"], ["72692.60000000", "0.17374000"], ["72692.59000000", "0.00000000"], ["72691.52000000", "0.00000000"], ["72690.96000000", "0.18121000"], ["72690.82000000", "0.16361000"], ["72689.77000000", "0.18120000"], ["72689.58000000", "0.00000000"], ["72689.47000000", "0.00000000"], ["72688.34000000", "0.18120000"], ["72687.66000000", "0.00000000"], ["72687.09000000", "0.18121000"], ["72687.08000000", "0.00000000"], ["72686.55000000", "0.00000000"], ["72686.08000000", "0.00000000"], ["72685.91000000", "0.00000000"], ["72685.83000000", "0.00000000"], ["72685.57000000", "0.18121000"], ["72685.54000000", "0.18120000"], ["72684.55000000", "0.00294000"], ["72683.81000000", "0.18121000"], ["72683.67000000", "0.18121000"], ["72682.62000000", "0.00000000"], ["72682.48000000", "0.02827000"], ["72682.15000000", "0.00000000"], ["72682.03000000", "0.18121000"], ["72674.62000000", "0.06841000"], ["72673.62000000", "0.00011000"], ["72673.49000000", "0.00000000"], ["72671.60000000", "0.04102000"], ["72670.74000000", "0.38268000"], ["72670.71000000", "0.19134000"], ["72670.20000000", "0.49601000"], ["72669.93000000", "0.02000000"], ["72668.60000000", "1.33938000"], ["72667.00000000", "0.00000000"], ["72666.11000000", "0.00008000"], ["72662.91000000", "1.36417000"], ["72660.02000000", "0.00000000"], ["72646.88000000", "0.00008000"], ["72634.30000000", "2.74944000"], ["72633.62000000", "0.00136000"], ["72620.01000000", "0.00000000"], ["72610.02000000", "0.36153000"], ["72600.75000000", "0.00000000"], ["72593.37000000", "0.00008000"], ["72587.52000000", "0.00000000"], ["72587.50000000", "0.01779000"], ["72553.00000000", "0.21414000"], ["72548.23000000", "0.00000000"], ["72529.23000000", "0.00018000"], ["72528.00000000", "0.00000000"], ["72522.38000000", "0.00000000"], ["72520.63000000", "0.00008000"], ["72458.81000000", "0.00000000"], ["72455.26000000", "0.00000000"], ["72452.74000000", "0.00000000"], ["72447.89000000", "0.00008000"], ["72441.58000000", "0.00028000"], ["72426.85000000", "1.87704000"], ["72382.51000000", "0.00000000"], ["72375.16000000", "0.00008000"], ["72329.14000000", "0.00000000"], ["72309.76000000", "0.00000000"], ["72302.42000000", "0.00008000"], ["72237.02000000", "0.00000000"], ["72229.68000000", "0.00008000"], ["72181.98000000", "2.50000000"], ["72164.27000000", "0.00000000"], ["72156.94000000", "0.00008000"], ["65467.80000000", "0.00000000"], ["65467.13000000", "0.00000000"], ["58190.41000000", "0.00034000"]], "a": [["72736.73000000", "4.75139000"], ["72736.74000000", "0.12212000"], ["72736.75000000", "0.00014000"], ["72736.76000000", "0.00000000"], ["72736.90000000", "0.36074000"], ["72737.05000000", "0.57729000"], ["72737.06000000", "0.34635000"], ["72737.07000000", "0.00008000"], ["72737.28000000", "0.00007000"], ["72737.29000000", "0.65949000"], ["72737.39000000", "0.00000000"], ["72737.65000000", "0.11120000"], ["72737.95000000", "0.00000000"], ["72737.99000000", "0.00000000"], ["72738.01000000", "1.48589000"], ["72738.02000000", "3.53791000"], ["72738.03000000", "0.00008000"], ["72738.04000000", "0.00000000"], ["72738.26000000", "0.00000000"], ["72738.36000000", "0.00000000"], ["72738.39000000", "0.00000000"], ["72738.44000000", "0.00000000"], ["72738.45000000", "0.00000000"], ["72738.47000000", "0.00000000"], ["72739.11000000", "0.00028000"], ["72739.16000000", "0.00000000"], ["72739.36000000", "0.14000000"], ["72739.48000000", "0.00000000"], ["72739.57000000", "0.02412000"], ["72739.59000000", "0.18121000"], ["72739.64000000", "1.00662000"], ["72739.65000000", "0.00000000"], ["72739.92000000", "0.00000000"], ["72739.94000000", "0.00400000"], ["72740.01000000", "0.00000000"], ["72740.29000000", "0.00000000"], ["72740.32000000", "0.00000000"], ["72740.45000000", "0.00000000"], ["72740.53000000", "0.00000000"], ["72740.56000000", "0.00000000"], ["72740.57000000", "0.00000000"], ["72740.59000000", "0.63588000"], ["72740.67000000", "0.00000000"], ["72740.73000000", "0.63572000"], ["72740.75000000", "0.00000000"], ["72740.80000000", "0.00000000"], ["72740.82000000", "0.27000000"], ["72740.84000000", "0.00020000"], ["72740.85000000", "0.00024000"], ["72740.86000000", "0.00000000"], ["72740.96000000", "0.00000000"], ["72740.97000000", "0.00007000"], ["72740.98000000", "0.00000000"], ["72740.99000000", "0.00000000"], ["72741.24000000", "0.00000000"], ["72741.25000000", "1.65686000"], ["72741.26000000", "3.05501000"], ["72741.27000000", "0.00000000"], ["72741.28000000", "0.00000000"], ["72741.38000000", "0.00000000"], ["72741.64000000", "0.00000000"], ["72741.76000000", "0.00400000"], ["72741.85000000", "0.00000000"], ["72741.94000000", "0.00000000"], ["72741.99000000", "1.14206000"], ["72742.00000000", "0.00000000"], ["72742.01000000", "0.28040000"], ["72742.02000000", "0.00000000"], ["72742.03000000", "0.00008000"], ["72742.66000000", "0.00000000"], ["72743.15000000", "0.00000000"], ["72743.16000000", "0.00000000"], ["72743.23000000", "0.00774000"], ["72743.43000000", "0.00000000"], ["72743.44000000", "0.00000000"], ["72743.58000000", "0.00400000"], ["72743.90000000", "0.00000000"], ["72744.01000000", "0.00000000"], ["72744.36000000", "0.00000000"], ["72744.40000000", "0.00000000"], ["72744.42000000", "0.40856000"], ["72744.57000000", "0.00000000"], ["72745.12000000", "0.03407000"], ["72745.90000000", "0.00000000"], ["72746.14000000", "0.00007000"], ["72746.24000000", "0.00008000"], ["72746.25000000", "0.00000000"], ["72746.63000000", "0.00000000"], ["72746.85000000", "0.00000000"], ["72747.16000000", "0.00009000"], ["72747.73000000", "0.00000000"], ["72749.06000000", "0.00000000"], ["72749.12000000", "0.57073000"], ["72749.14000000", "0.00000000"], ["72749.16000000", "0.00000000"], ["72750.59000000", "0.00000000"], ["72752.01000000", "0.68834000"], ["72752.02000000", "0.18120000"], ["72752.25000000", "0.00000000"], ["72752.26000000", "0.00028000"], ["72753.00000000", "0.00000000"], ["72753.77000000", "0.00000000"], ["72753.81000000", "0.00026000"], ["72753.82000000", "1.64265000"], ["72754.98000000", "0.00000000"], ["72754.99000000", "2.74944000"], ["72755.00000000", "0.00008000"], ["72755.01000000", "1.63349000"], ["72755.59000000", "0.00000000"], ["72755.72000000", "0.00008000"], ["72756.52000000", "0.00008000"], ["72756.56000000", "0.00008000"], ["72756.99000000", "0.00000000"], ["72757.41000000", "0.00397000"], ["72757.71000000", "0.00000000"], ["72758.54000000", "0.00000000"], ["72758.55000000", "0.00137000"], ["72759.09000000", "0.00000000"], ["72759.17000000", "0.00000000"], ["72759.28000000", "0.00188000"], ["72759.95000000", "0.00000000"], ["72759.96000000", "0.00400000"], ["72760.01000000", "0.00084000"], ["72761.40000000", "0.04600000"], ["72762.20000000", "0.00008000"], ["72762.79000000", "0.00000000"], ["72764.61000000", "0.00020000"], ["72764.89000000", "0.00000000"], ["72765.65000000", "1.36224000"], ["72766.32000000", "0.00000000"], ["72766.35000000", "0.00283000"], ["72768.07000000", "0.00000000"], ["72768.67000000", "0.00114000"], ["72768.69000000", "0.00008000"], ["72768.94000000", "0.00000000"], ["72769.06000000", "0.00000000"], ["72769.28000000", "0.49533000"], ["72770.61000000", "0.00000000"], ["72770.88000000", "0.00000000"], ["72771.11000000", "0.00000000"], ["72772.04000000", "0.00000000"], ["72772.34000000", "0.00000000"], ["72772.55000000", "0.00000000"], ["72772.70000000", "0.00000000"], ["72773.56000000", "0.00000000"], ["72774.18000000", "0.00000000"], ["72775.98000000", "0.00000000"], ["72776.84000000", "0.00000000"], ["72777.87000000", "0.00000000"], ["72779.53000000", "0.02745000"], ["72783.43000000", "0.00000000"], ["72784.31000000", "0.00000000"], ["72786.88000000", "0.01145000"], ["72787.74000000", "0.07108000"], ["72790.57000000", "0.01727000"], ["72794.54000000", "0.00000000"], ["72798.58000000", "0.00000000"], ["72801.07000000", "0.00000000"], ["72806.32000000", "0.00000000"], ["72806.96000000", "0.00000000"], ["72808.99000000", "0.00000000"], ["72810.76000000", "0.00008000"], ["72812.14000000", "0.00007000"], ["72814.33000000", "0.00000000"], ["72819.00000000", "0.00000000"], ["72819.28000000", "0.00000000"], ["72820.41000000", "0.00000000"], ["72823.43000000", "0.00000000"], ["72836.94000000", "0.00000000"], ["72843.35000000", "0.00939000"], ["72844.08000000", "0.00000000"], ["72844.25000000", "0.00000000"], ["72847.13000000", "0.00000000"], ["72849.65000000", "0.00000000"], ["72851.86000000", "0.00000000"], ["72856.64000000", "0.00000000"], ["72870.32000000", "0.00000000"], ["72871.09000000", "0.00000000"], ["72883.50000000", "0.00008000"], ["72891.74000000", "0.00000000"], ["72896.55000000", "0.00008000"], ["72898.94000000", "0.00185000"], ["72899.67000000", "0.00000000"], ["72906.85000000", "0.00000000"], ["72964.38000000", "0.00000000"], ["72964.53000000", "0.00056000"], ["72965.11000000", "0.00626000"], ["72997.79000000", "0.00000000"], ["73017.00000000", "1.19998000"], ["73028.97000000", "0.00008000"], ["73037.24000000", "0.00000000"], ["73045.23000000", "0.00000000"], ["73084.68000000", "0.00000000"], ["73087.16000000", "0.00000000"], ["73101.71000000", "0.00008000"], ["73109.98000000", "0.00000000"], ["73175.33000000", "0.00000000"], ["73182.64000000", "0.00000000"], ["73207.13000000", "0.00000000"], ["73247.19000000", "0.00008000"], ["73255.47000000", "0.00000000"], ["73412.41000000", "0.00000000"], ["73419.35000000", "0.00011000"], ["74196.07000000", "0.00136000"]], "_local_ts_utc": "2026-06-01T07:49:01.414941+00:00"}
{"e": "depthUpdate", "E": 1780300142614, "s": "BTCUSDT", "U": 94551769403, "u": 94551772125, "b": [["72736.72000000", "0.00000000"], ["72736.71000000", "0.00000000"], ["72736.70000000", "0.00000000"], ["72736.65000000", "0.00000000"], ["72736.62000000", "0.00000000"], ["72736.61000000", "0.00000000"], ["72736.60000000", "0.00000000"], ["72736.48000000", "0.00000000"], ["72736.45000000", "0.00000000"], ["72736.37000000", "0.00000000"], ["72736.36000000", "0.00000000"], ["72736.12000000", "0.00000000"], ["72736.11000000", "0.00000000"], ["72736.01000000", "0.00000000"], ["72736.00000000", "0.00000000"], ["72735.90000000", "0.00000000"], ["72735.89000000", "0.00000000"], ["72735.80000000", "0.00000000"], ["72735.71000000", "0.00000000"], ["72735.54000000", "0.00000000"], ["72735.30000000", "0.00000000"], ["72735.29000000", "0.00000000"], ["72735.20000000", "0.00000000"], ["72734.77000000", "0.00000000"], ["72734.76000000", "0.00000000"], ["72734.54000000", "0.00000000"], ["72734.48000000", "0.00000000"], ["72734.37000000", "0.00000000"], ["72734.30000000", "0.00000000"], ["72734.03000000", "0.00000000"], ["72734.01000000", "0.00000000"], ["72734.00000000", "0.00000000"], ["72733.99000000", "0.00000000"], ["72733.75000000", "0.00000000"], ["72733.72000000", "0.00000000"], ["72733.61000000", "0.00000000"], ["72733.59000000", "0.00000000"], ["72733.44000000", "0.00000000"], ["72733.40000000", "0.00000000"], ["72733.33000000", "0.00000000"], ["72733.32000000", "0.00000000"], ["72733.18000000", "0.00000000"], ["72732.80000000", "0.00000000"], ["72732.73000000", "0.00000000"], ["72732.69000000", "0.00000000"], ["72732.66000000", "0.00000000"], ["72732.60000000", "0.00000000"], ["72732.44000000", "0.00000000"], ["72732.40000000", "0.00000000"], ["72732.32000000", "0.00000000"], ["72732.25000000", "0.00000000"], ["72732.24000000", "0.00000000"], ["72732.02000000", "0.00000000"], ["72732.01000000", "0.00000000"], ["72732.00000000", "0.00000000"], ["72731.56000000", "0.00000000"], ["72731.53000000", "0.00000000"], ["72731.52000000", "0.00000000"], ["72731.51000000", "0.00000000"], ["72731.17000000", "0.00000000"], ["72731.06000000", "0.00000000"], ["72731.05000000", "0.09140000"], ["72731.04000000", "0.00056000"], ["72730.98000000", "0.00019000"], ["72730.91000000", "0.00000000"], ["72730.90000000", "0.00000000"], ["72730.84000000", "0.00000000"], ["72730.20000000", "0.00000000"], ["72730.01000000", "0.00016000"], ["72729.89000000", "0.00000000"], ["72729.88000000", "0.00000000"], ["72729.86000000", "0.00000000"], ["72729.82000000", "0.00000000"], ["72729.09000000", "0.00016000"], ["72729.07000000", "0.00000000"], ["72729.02000000", "0.00000000"], ["72729.01000000", "0.00016000"], ["72728.41000000", "0.00164000"], ["72728.07000000", "0.00000000"], ["72728.01000000", "0.00016000"], ["72727.91000000", "0.00000000"], ["72727.49000000", "0.00000000"], ["72727.46000000", "0.00014000"], ["72727.39000000", "0.00000000"], ["72727.32000000", "0.00000000"], ["72727.26000000", "0.00000000"], ["72727.20000000", "0.00000000"], ["72726.77000000", "0.00000000"], ["72726.57000000", "0.00000000"], ["72726.56000000", "0.00000000"], ["72726.36000000", "0.00926000"], ["72726.01000000", "0.00008000"], ["72725.11000000", "0.00069000"], ["72724.88000000", "0.00000000"], ["72724.66000000", "0.00000000"], ["72723.85000000", "0.00000000"], ["72723.52000000", "0.00000000"], ["72722.66000000", "0.00008000"], ["72722.42000000", "0.00000000"], ["72722.28000000", "0.00000000"], ["72722.26000000", "0.00000000"], ["72721.81000000", "0.04765000"], ["72721.71000000", "0.00031000"], ["72721.23000000", "0.00000000"], ["72721.17000000", "0.00000000"], ["72721.09000000", "0.00000000"], ["72720.76000000", "0.00028000"], ["72720.55000000", "0.00000000"], ["72720.07000000", "0.00031000"], ["72720.01000000", "0.00000000"], ["72720.00000000", "0.11239000"], ["72719.40000000", "0.00000000"], ["72719.39000000", "0.02217000"], ["72719.14000000", "0.01508000"], ["72719.05000000", "0.00047000"], ["72718.57000000", "0.00000000"], ["72717.86000000", "0.00034000"], ["72717.53000000", "0.00000000"], ["72717.20000000", "0.00000000"], ["72717.19000000", "0.00000000"], ["72716.53000000", "0.00000000"], ["72716.28000000", "0.11339000"], ["72716.27000000", "0.00000000"], ["72716.26000000", "0.00000000"], ["72716.02000000", "0.00008000"], ["72715.94000000", "0.01376000"], ["72715.24000000", "0.00020000"], ["72715.11000000", "0.00000000"], ["72714.13000000", "0.17926000"], ["72714.08000000", "0.00000000"], ["72713.93000000", "0.00000000"], ["72713.89000000", "0.17715000"], ["72713.71000000", "0.00007000"], ["72713.40000000", "0.00000000"], ["72712.91000000", "0.00007000"], ["72712.58000000", "0.16541000"], ["72712.55000000", "0.18122000"], ["72711.97000000", "0.00000000"], ["72711.52000000", "0.00000000"], ["72711.35000000", "0.00000000"], ["72711.12000000", "0.18122000"], ["72710.88000000", "0.00458000"], ["72710.63000000", "0.04000000"], ["72710.62000000", "0.00626000"], ["72710.55000000", "0.00000000"], ["72710.54000000", "0.57940000"], ["72710.53000000", "0.00008000"], ["72710.52000000", "0.00054000"], ["72710.19000000", "0.00000000"], ["72710.04000000", "0.00000000"], ["72709.77000000", "0.05024000"], ["72709.73000000", "0.11000000"], ["72709.58000000", "0.00000000"], ["72709.56000000", "0.16473000"], ["72709.55000000", "0.62497000"], ["72709.27000000", "0.00053000"], ["72708.74000000", "0.12083000"], ["72708.36000000", "0.00000000"], ["72708.26000000", "0.18122000"], ["72708.01000000", "0.28771000"], ["72708.00000000", "0.68310000"], ["72707.53000000", "0.00000000"], ["72707.07000000", "0.00000000"], ["72707.06000000", "0.00000000"], ["72706.74000000", "0.18122000"], ["72706.69000000", "0.00000000"], ["72706.66000000", "0.00000000"], ["72705.93000000", "0.00000000"], ["72705.76000000", "0.00008000"], ["72705.75000000", "0.00000000"], ["72705.63000000", "0.00000000"], ["72705.31000000", "0.00000000"], ["72705.12000000", "0.00165000"], ["72705.03000000", "0.01376000"], ["72704.82000000", "0.00000000"], ["72704.34000000", "0.18122000"], ["72704.33000000", "0.12264000"], ["72704.26000000", "0.02120000"], ["72704.22000000", "0.17926000"], ["72704.21000000", "0.65949000"], ["72704.20000000", "0.90469000"], ["72704.16000000", "0.00000000"], ["72704.00000000", "0.02566000"], ["72702.95000000", "0.00000000"], ["72702.72000000", "0.00000000"], ["72702.64000000", "0.00000000"], ["72702.57000000", "0.18122000"], ["72702.54000000", "0.00000000"], ["72702.49000000", "0.00000000"], ["72701.72000000", "0.00400000"], ["72701.33000000", "0.02000000"], ["72701.11000000", "0.18122000"], ["72700.97000000", "0.00000000"], ["72700.53000000", "0.00000000"], ["72700.03000000", "0.59408000"], ["72699.90000000", "0.00400000"], ["72698.36000000", "0.00000000"], ["72698.08000000", "0.00435000"], ["72696.85000000", "0.18122000"], ["72696.82000000", "0.00000000"], ["72696.73000000", "0.00000000"], ["72696.69000000", "0.00007000"], ["72696.42000000", "0.33556000"], ["72696.26000000", "0.00400000"], ["72696.01000000", "0.00000000"], ["72695.37000000", "0.00350000"], ["72694.98000000", "0.00011000"], ["72694.75000000", "0.03938000"], ["72694.74000000", "0.02847000"], ["72694.72000000", "0.18130000"], ["72694.68000000", "0.00000000"], ["72694.44000000", "0.00400000"], ["72694.27000000", "0.00000000"], ["72694.15000000", "0.00000000"], ["72693.77000000", "0.17926000"], ["72693.76000000", "1.13434000"], ["72692.55000000", "0.00000000"], ["72691.10000000", "0.00000000"], ["72690.96000000", "0.00000000"], ["72690.82000000", "0.00000000"], ["72689.79000000", "0.00000000"], ["72689.78000000", "0.00000000"], ["72689.77000000", "0.00000000"], ["72689.60000000", "0.76597000"], ["72689.47000000", "0.03387000"], ["72688.44000000", "0.96847000"], ["72688.34000000", "0.00000000"], ["72688.09000000", "0.00000000"], ["72687.75000000", "0.00000000"], ["72687.74000000", "1.22022000"], ["72687.09000000", "0.00000000"], ["72686.14000000", "0.00000000"], ["72685.66000000", "0.00000000"], ["72685.58000000", "0.28997000"], ["72685.57000000", "0.00000000"], ["72685.54000000", "0.00000000"], ["72685.53000000", "0.00000000"], ["72684.64000000", "0.00007000"], ["72683.98000000", "0.18122000"], ["72683.95000000", "0.00000000"], ["72683.81000000", "0.00000000"], ["72683.67000000", "0.00000000"], ["72683.59000000", "0.00000000"], ["72683.19000000", "0.00000000"], ["72683.12000000", "0.00000000"], ["72682.43000000", "0.18122000"], ["72682.39000000", "0.01368000"], ["72682.04000000", "0.00343000"], ["72682.03000000", "0.00000000"], ["72681.92000000", "0.00000000"], ["72681.89000000", "0.00000000"], ["72681.56000000", "0.03297000"], ["72680.92000000", "0.00000000"], ["72680.91000000", "0.00000000"], ["72680.66000000", "0.00020000"], ["72680.48000000", "0.01142000"], ["72680.47000000", "0.00000000"], ["72679.96000000", "0.00000000"], ["72678.86000000", "0.00000000"], ["72677.90000000", "0.00425000"], ["72677.34000000", "0.00000000"], ["72676.00000000", "0.02280000"], ["72675.53000000", "0.00622000"], ["72673.29000000", "0.19691000"], ["72672.78000000", "0.00000000"], ["72672.31000000", "0.04125000"], ["72671.75000000", "0.00000000"], ["72671.66000000", "0.01275000"], ["72671.26000000", "1.79668000"], ["72669.26000000", "0.65949000"], ["72669.25000000", "0.00000000"], ["72669.13000000", "0.19134000"], ["72668.64000000", "0.38268000"], ["72668.63000000", "0.38268000"], ["72668.61000000", "1.01417000"], ["72668.58000000", "0.38268000"], ["72668.11000000", "0.00000000"], ["72668.06000000", "0.03300000"], ["72667.97000000", "0.19134000"], ["72666.67000000", "0.00333000"], ["72666.34000000", "0.49603000"], ["72666.11000000", "0.00000000"], ["72665.88000000", "0.00011000"], ["72665.13000000", "0.00000000"], ["72664.91000000", "0.00000000"], ["72664.55000000", "0.70093000"], ["72660.01000000", "0.05370000"], ["72658.32000000", "0.00008000"], ["72657.60000000", "1.46411000"], ["72656.22000000", "0.00000000"], ["72655.81000000", "1.36430000"], ["72655.16000000", "0.45583000"], ["72653.47000000", "0.00000000"], ["72652.49000000", "0.19482000"], ["72652.47000000", "0.00000000"], ["72652.05000000", "0.27611000"], ["72650.01000000", "0.17445000"], ["72647.07000000", "0.65949000"], ["72645.95000000", "0.82476000"], ["72643.47000000", "0.01286000"], ["72641.52000000", "0.05691000"], ["72641.51000000", "0.00000000"], ["72638.34000000", "0.65949000"], ["72636.58000000", "0.00000000"], ["72631.84000000", "0.04432000"], ["72631.11000000", "0.04570000"], ["72630.00000000", "0.01746000"], ["72629.70000000", "0.00000000"], ["72629.23000000", "0.00000000"], ["72625.84000000", "0.00008000"], ["72622.66000000", "2.74944000"], ["72619.41000000", "0.69990000"], ["72616.26000000", "1.83831000"], ["72613.04000000", "3.04079000"], ["72608.01000000", "0.00137000"], ["72595.95000000", "0.00000000"], ["72593.37000000", "0.00000000"], ["72590.95000000", "0.00000000"], ["72590.53000000", "0.00000000"], ["72585.59000000", "0.00008000"], ["72580.97000000", "0.00717000"], ["72574.77000000", "0.00412000"], ["72574.76000000", "1.20000000"], ["72569.05000000", "0.00000000"], ["72562.17000000", "2.84261000"], ["72555.02000000", "0.00009000"], ["72538.31000000", "0.00000000"], ["72535.90000000", "0.00000000"], ["72522.32000000", "0.00000000"], ["72521.51000000", "0.00007000"], ["72520.63000000", "0.00000000"], ["72517.88000000", "0.00007000"], ["72512.86000000", "0.00008000"], ["72512.49000000", "0.00331000"], ["72447.89000000", "0.00000000"], ["72441.17000000", "1.84224000"], ["72440.13000000", "0.00008000"], ["72435.44000000", "0.00028000"], ["72430.93000000", "4.14708000"], ["72428.16000000", "0.00028000"], ["72375.16000000", "0.00000000"], ["72367.39000000", "0.00008000"], ["72302.42000000", "0.00000000"], ["72294.66000000", "0.00111000"], ["72229.68000000", "0.00000000"], ["72221.93000000", "0.00008000"], ["72156.94000000", "0.00000000"], ["72149.20000000", "0.00008000"], ["65463.05000000", "0.00000000"], ["65458.99000000", "0.00000000"], ["58190.41000000", "0.00000000"]], "a": [["72731.06000000", "5.23107000"], ["72731.07000000", "0.00038000"], ["72731.08000000", "0.00014000"], ["72731.53000000", "0.00000000"], ["72732.01000000", "0.18036000"], ["72732.02000000", "0.00000000"], ["72732.03000000", "0.00096000"], ["72732.21000000", "0.09395000"], ["72732.26000000", "0.00000000"], ["72732.32000000", "0.04115000"], ["72732.33000000", "0.00024000"], ["72732.34000000", "0.00000000"], ["72732.35000000", "0.00000000"], ["72732.40000000", "1.00857000"], ["72732.41000000", "0.10466000"], ["72732.42000000", "0.00000000"], ["72732.44000000", "0.00000000"], ["72732.45000000", "0.00024000"], ["72732.46000000", "0.00000000"], ["72732.60000000", "0.18122000"], ["72732.61000000", "0.43446000"], ["72732.62000000", "0.00000000"], ["72732.63000000", "0.00000000"], ["72732.66000000", "0.00400000"], ["72732.67000000", "0.00000000"], ["72732.70000000", "0.00000000"], ["72732.74000000", "0.00000000"], ["72732.81000000", "0.12785000"], ["72733.18000000", "0.00000000"], ["72733.19000000", "0.82606000"], ["72733.31000000", "0.00000000"], ["72733.33000000", "0.00000000"], ["72733.34000000", "1.41646000"], ["72733.35000000", "0.00000000"], ["72733.36000000", "0.00000000"], ["72733.41000000", "0.65949000"], ["72733.45000000", "0.00000000"], ["72733.59000000", "0.00007000"], ["72733.60000000", "0.00000000"], ["72733.62000000", "0.00000000"], ["72733.73000000", "0.00000000"], ["72733.76000000", "0.00000000"], ["72734.00000000", "0.00000000"], ["72734.01000000", "0.42144000"], ["72734.02000000", "0.00000000"], ["72734.04000000", "0.00000000"], ["72734.30000000", "0.00000000"], ["72734.31000000", "0.00000000"], ["72734.38000000", "0.00000000"], ["72734.48000000", "0.00400000"], ["72734.49000000", "0.00000000"], ["72734.53000000", "0.00000000"], ["72734.55000000", "0.00000000"], ["72734.77000000", "0.00000000"], ["72734.78000000", "0.18006000"], ["72734.83000000", "2.93725000"], ["72734.84000000", "0.00000000"], ["72734.85000000", "0.00000000"], ["72735.11000000", "0.00000000"], ["72735.19000000", "0.00000000"], ["72735.20000000", "0.00155000"], ["72735.21000000", "0.06409000"], ["72735.22000000", "0.00000000"], ["72735.23000000", "0.00000000"], ["72735.28000000", "0.00000000"], ["72735.30000000", "0.00000000"], ["72735.31000000", "0.46895000"], ["72735.32000000", "0.00000000"], ["72735.53000000", "0.00000000"], ["72735.55000000", "0.00000000"], ["72735.71000000", "0.13627000"], ["72735.72000000", "0.41536000"], ["72735.73000000", "0.00000000"], ["72735.74000000", "0.00000000"], ["72735.79000000", "0.00000000"], ["72735.80000000", "0.00000000"], ["72735.81000000", "0.20182000"], ["72735.82000000", "0.00000000"], ["72735.89000000", "0.00000000"], ["72735.90000000", "0.20008000"], ["72735.91000000", "0.00000000"], ["72736.00000000", "0.00000000"], ["72736.01000000", "0.31044000"], ["72736.02000000", "0.20008000"], ["72736.03000000", "0.00000000"], ["72736.10000000", "0.00000000"], ["72736.11000000", "0.00000000"], ["72736.12000000", "0.00000000"], ["72736.13000000", "0.38447000"], ["72736.14000000", "0.00000000"], ["72736.15000000", "0.00000000"], ["72736.30000000", "0.00400000"], ["72736.35000000", "0.00000000"], ["72736.36000000", "0.00000000"], ["72736.37000000", "0.20741000"], ["72736.38000000", "0.00000000"], ["72736.39000000", "0.00000000"], ["72736.46000000", "0.00000000"], ["72736.49000000", "0.00000000"], ["72736.60000000", "0.00000000"], ["72736.61000000", "0.24007000"], ["72736.62000000", "0.00000000"], ["72736.63000000", "0.00000000"], ["72736.65000000", "0.00000000"], ["72736.66000000", "0.00000000"], ["72736.67000000", "0.00000000"], ["72736.68000000", "0.00008000"], ["72736.69000000", "0.00000000"], ["72736.71000000", "0.00000000"], ["72736.72000000", "0.07866000"], ["72736.73000000", "0.17013000"], ["72736.74000000", "0.00000000"], ["72736.75000000", "0.00000000"], ["72736.90000000", "0.00000000"], ["72737.04000000", "0.00008000"], ["72737.05000000", "0.40856000"], ["72737.06000000", "0.00000000"], ["72737.07000000", "0.00000000"], ["72737.29000000", "0.65949000"], ["72737.54000000", "0.12083000"], ["72737.65000000", "0.00000000"], ["72737.90000000", "0.00000000"], ["72737.91000000", "0.00000000"], ["72738.00000000", "0.00000000"], ["72738.01000000", "0.00008000"], ["72738.02000000", "0.62115000"], ["72738.03000000", "0.00000000"], ["72738.12000000", "0.00400000"], ["72738.77000000", "0.00000000"], ["72739.08000000", "0.00400000"], ["72739.35000000", "0.00000000"], ["72739.52000000", "0.00000000"], ["72739.57000000", "0.00000000"], ["72739.59000000", "0.00000000"], ["72739.63000000", "0.00008000"], ["72739.64000000", "0.01000000"], ["72739.77000000", "0.00009000"], ["72740.00000000", "0.02897000"], ["72740.01000000", "0.00752000"], ["72740.14000000", "0.00007000"], ["72740.58000000", "0.00008000"], ["72740.59000000", "0.00000000"], ["72740.73000000", "0.00000000"], ["72740.81000000", "0.35670000"], ["72740.85000000", "0.00000000"], ["72741.24000000", "0.00000000"], ["72741.25000000", "0.27008000"], ["72741.26000000", "1.36099000"], ["72741.99000000", "0.36000000"], ["72742.01000000", "0.11735000"], ["72742.04000000", "0.00000000"], ["72742.41000000", "0.00000000"], ["72742.42000000", "0.00007000"], ["72742.56000000", "0.00011000"], ["72742.57000000", "0.00007000"], ["72742.61000000", "0.00000000"], ["72742.81000000", "0.00007000"], ["72743.16000000", "0.00000000"], ["72743.34000000", "0.00000000"], ["72743.42000000", "0.00000000"], ["72743.76000000", "0.00000000"], ["72743.81000000", "0.00000000"], ["72743.88000000", "0.00000000"], ["72743.93000000", "0.00000000"], ["72744.01000000", "0.00000000"], ["72744.41000000", "0.68843000"], ["72744.82000000", "0.00028000"], ["72745.05000000", "0.00007000"], ["72745.21000000", "0.00000000"], ["72745.31000000", "0.00000000"], ["72745.85000000", "0.00000000"], ["72745.90000000", "0.00000000"], ["72746.09000000", "0.00000000"], ["72746.10000000", "0.21102000"], ["72746.12000000", "0.00000000"], ["72746.37000000", "0.00000000"], ["72746.67000000", "0.00000000"], ["72746.68000000", "0.01484000"], ["72746.73000000", "0.00000000"], ["72747.57000000", "0.00000000"], ["72748.02000000", "0.00000000"], ["72748.05000000", "0.00000000"], ["72748.10000000", "0.00000000"], ["72748.17000000", "0.00000000"], ["72749.09000000", "0.96847000"], ["72749.10000000", "1.37901000"], ["72749.11000000", "2.74952000"], ["72749.12000000", "0.00008000"], ["72749.13000000", "0.65949000"], ["72749.34000000", "0.00000000"], ["72750.00000000", "0.00088000"], ["72750.10000000", "0.00573000"], ["72750.58000000", "0.00000000"], ["72750.91000000", "0.00000000"], ["72750.96000000", "0.00000000"], ["72751.00000000", "0.00100000"], ["72751.01000000", "0.20000000"], ["72752.00000000", "0.00088000"], ["72752.01000000", "0.00000000"], ["72752.02000000", "0.00000000"], ["72752.05000000", "0.00000000"], ["72753.18000000", "0.00200000"], ["72753.29000000", "0.00000000"], ["72753.35000000", "0.00000000"], ["72753.44000000", "0.00000000"], ["72753.45000000", "0.00000000"], ["72753.76000000", "0.00829000"], ["72753.77000000", "0.00008000"], ["72753.85000000", "0.00000000"], ["72754.07000000", "0.00000000"], ["72754.08000000", "0.00000000"], ["72754.98000000", "0.00008000"], ["72755.01000000", "1.13342000"], ["72755.14000000", "0.00012000"], ["72755.49000000", "0.38286000"], ["72755.60000000", "0.00000000"], ["72755.92000000", "0.00200000"], ["72756.52000000", "0.00000000"], ["72756.53000000", "0.00000000"], ["72756.75000000", "0.00000000"], ["72757.36000000", "0.99274000"], ["72757.37000000", "1.36240000"], ["72757.71000000", "0.00000000"], ["72757.72000000", "0.00008000"], ["72757.96000000", "0.00275000"], ["72758.07000000", "0.00458000"], ["72758.25000000", "0.00120000"], ["72758.30000000", "0.00000000"], ["72758.73000000", "0.00000000"], ["72759.03000000", "0.23224000"], ["72759.61000000", "0.00000000"], ["72759.98000000", "1.28334000"], ["72760.00000000", "0.02863000"], ["72761.04000000", "0.00000000"], ["72761.35000000", "0.00114000"], ["72761.45000000", "0.00000000"], ["72761.78000000", "0.00000000"], ["72762.04000000", "0.00228000"], ["72762.20000000", "0.00000000"], ["72762.46000000", "0.43346000"], ["72762.56000000", "0.49538000"], ["72762.79000000", "0.00008000"], ["72762.80000000", "2.74944000"], ["72763.10000000", "0.00000000"], ["72763.60000000", "0.00000000"], ["72764.61000000", "0.00000000"], ["72765.42000000", "0.00000000"], ["72765.64000000", "0.44504000"], ["72766.23000000", "0.00000000"], ["72766.35000000", "0.00008000"], ["72766.36000000", "0.00000000"], ["72766.95000000", "0.00000000"], ["72767.24000000", "0.00000000"], ["72767.39000000", "0.08600000"], ["72768.69000000", "1.32849000"], ["72768.84000000", "0.00000000"], ["72769.27000000", "0.00008000"], ["72770.09000000", "0.00000000"], ["72770.19000000", "0.00349000"], ["72770.39000000", "0.00000000"], ["72770.49000000", "0.00000000"], ["72771.00000000", "0.00008000"], ["72772.56000000", "0.31132000"], ["72772.57000000", "0.00000000"], ["72772.72000000", "0.00435000"], ["72772.94000000", "0.00000000"], ["72773.31000000", "0.00000000"], ["72774.99000000", "1.33939000"], ["72776.14000000", "0.00000000"], ["72776.34000000", "0.00000000"], ["72777.14000000", "0.00000000"], ["72777.21000000", "0.00007000"], ["72777.37000000", "0.00008000"], ["72777.38000000", "0.27000000"], ["72777.77000000", "0.00000000"], ["72778.64000000", "0.00008000"], ["72779.38000000", "0.00000000"], ["72780.00000000", "0.02296000"], ["72780.21000000", "0.00000000"], ["72780.88000000", "0.00000000"], ["72782.45000000", "0.00412000"], ["72785.98000000", "0.40864000"], ["72785.99000000", "1.58052000"], ["72786.57000000", "0.00000000"], ["72786.73000000", "0.58747000"], ["72786.85000000", "0.09234000"], ["72788.75000000", "0.01079000"], ["72790.59000000", "0.00112000"], ["72792.03000000", "0.20705000"], ["72792.25000000", "0.00000000"], ["72793.32000000", "0.00189000"], ["72793.34000000", "0.41546000"], ["72798.65000000", "0.66662000"], ["72798.80000000", "0.00000000"], ["72799.40000000", "1.54745000"], ["72799.45000000", "0.00000000"], ["72800.43000000", "1.39745000"], ["72802.98000000", "0.00000000"], ["72804.93000000", "0.00000000"], ["72806.37000000", "1.17198000"], ["72807.68000000", "0.32882000"], ["72807.98000000", "0.00000000"], ["72809.38000000", "0.00000000"], ["72811.99000000", "0.00000000"], ["72813.17000000", "1.15426000"], ["72815.51000000", "0.05428000"], ["72816.49000000", "0.00000000"], ["72816.50000000", "0.00000000"], ["72820.32000000", "2.25527000"], ["72825.81000000", "0.04627000"], ["72826.08000000", "0.00000000"], ["72829.22000000", "0.00000000"], ["72829.23000000", "0.06200000"], ["72834.99000000", "0.00000000"], ["72838.48000000", "0.00000000"], ["72839.61000000", "0.00000000"], ["72841.11000000", "0.05198000"], ["72848.44000000", "0.00000000"], ["72850.07000000", "0.04266000"], ["72859.90000000", "0.00000000"], ["72865.81000000", "0.00075000"], ["72874.65000000", "0.00000000"], ["72877.79000000", "2.06252000"], ["72879.48000000", "0.00010000"], ["72883.33000000", "0.00011000"], ["72887.49000000", "0.00000000"], ["72890.36000000", "0.00000000"], ["72902.53000000", "0.19209000"], ["72906.16000000", "0.00000000"], ["72910.33000000", "0.00000000"], ["72921.37000000", "0.00000000"], ["72931.11000000", "0.00000000"], ["72932.93000000", "0.00000000"], ["72933.08000000", "0.02777000"], ["72943.74000000", "0.00010000"], ["72945.69000000", "0.00028000"], ["72946.49000000", "0.00000000"], ["72946.53000000", "0.00000000"], ["72947.61000000", "0.00000000"], ["72960.14000000", "0.00008000"], ["72960.61000000", "0.01435000"], ["72964.38000000", "0.00626000"], ["72965.11000000", "0.00000000"], ["72971.62000000", "0.00951000"], ["72972.11000000", "0.00176000"], ["72979.56000000", "0.00008000"], ["72980.34000000", "0.00000000"], ["72980.62000000", "0.00000000"], ["72981.78000000", "0.00000000"], ["72999.11000000", "0.00013000"], ["72999.54000000", "0.00000000"], ["73000.00000000", "0.59415000"], ["73002.28000000", "0.00008000"], ["73010.36000000", "0.00009000"], ["73016.66000000", "0.00035000"], ["73020.00000000", "0.00500000"], ["73026.53000000", "0.00008000"], ["73034.62000000", "0.00266000"], ["73041.96000000", "0.00016000"], ["73044.24000000", "0.00053000"], ["73046.57000000", "0.00230000"], ["73055.26000000", "0.00000000"], ["73070.26000000", "0.00237000"], ["73073.27000000", "0.00017000"], ["73082.46000000", "0.54998000"], ["73089.80000000", "0.00023000"], ["73091.17000000", "0.00009000"], ["73094.48000000", "0.00089000"], ["73100.31000000", "0.00105000"], ["73100.57000000", "0.00008000"], ["73105.16000000", "0.00184000"], ["73111.11000000", "0.00277000"], ["73116.66000000", "0.00009000"], ["73117.99000000", "0.00000000"], ["73125.01000000", "0.00000000"], ["73130.76000000", "0.00138000"], ["73132.12000000", "0.00008000"], ["73137.03000000", "0.00000000"], ["73144.64000000", "0.00000000"], ["73151.95000000", "0.00000000"], ["73164.50000000", "0.00008000"], ["73164.54000000", "0.00000000"], ["73199.76000000", "0.00000000"], ["73200.00000000", "1.20393000"], ["73216.66000000", "0.00033000"], ["73222.22000000", "0.00031000"], ["73247.35000000", "0.00020000"], ["73251.89000000", "0.00008000"], ["73267.88000000", "0.00084000"], ["73301.94000000", "0.00015000"], ["73305.43000000", "0.00013000"], ["73327.16000000", "0.00012000"], ["73466.66000000", "0.00178000"], ["73483.76000000", "0.00009000"], ["73491.00000000", "0.00018000"], ["73527.78000000", "0.00010000"], ["73572.14000000", "0.00025000"], ["73755.26000000", "0.00010000"], ["73811.94000000", "1.82105000"], ["73832.21000000", "0.00000000"], ["74017.56000000", "0.00110000"], ["74120.00000000", "1.07309000"], ["74321.74000000", "0.00022000"], ["100000.00000000", "98.72401000"]], "_local_ts_utc": "2026-06-01T07:49:01.510776+00:00"}
{"e": "depthUpdate", "E": 1780300142714, "s": "BTCUSDT", "U": 94551772126, "u": 94551772993, "b": [["72731.05000000", "0.00000000"], ["72731.04000000", "0.00000000"], ["72730.98000000", "0.00000000"], ["72730.85000000", "0.00000000"], ["72730.76000000", "0.00000000"], ["72730.61000000", "2.36100000"], ["72730.60000000", "0.00080000"], ["72730.30000000", "0.00000000"], ["72730.01000000", "0.00024000"], ["72730.00000000", "0.07433000"], ["72729.83000000", "0.00031000"], ["72729.80000000", "0.00755000"], ["72729.15000000", "0.00600000"], ["72729.08000000", "0.01405000"], ["72729.05000000", "0.00031000"], ["72729.00000000", "0.01392000"], ["72728.04000000", "0.00028000"], ["72728.00000000", "0.02296000"], ["72727.46000000", "0.00000000"], ["72727.38000000", "0.00008000"], ["72727.37000000", "0.02922000"], ["72727.27000000", "0.00555000"], ["72727.04000000", "0.00000000"], ["72727.01000000", "0.68276000"], ["72726.92000000", "0.00137000"], ["72726.38000000", "0.17926000"], ["72726.36000000", "0.00000000"], ["72726.01000000", "0.00000000"], ["72725.99000000", "0.00000000"], ["72725.38000000", "0.00000000"], ["72725.22000000", "0.00008000"], ["72724.97000000", "0.17926000"], ["72723.56000000", "0.18326000"], ["72723.27000000", "0.00000000"], ["72722.97000000", "0.00019000"], ["72722.86000000", "0.00000000"], ["72722.48000000", "0.14367000"], ["72722.16000000", "0.15515000"], ["72722.15000000", "0.17926000"], ["72722.01000000", "0.00000000"], ["72721.81000000", "0.00000000"], ["72721.71000000", "0.00000000"], ["72721.49000000", "0.00000000"], ["72720.74000000", "0.17926000"], ["72720.18000000", "0.00013000"], ["72720.07000000", "0.00000000"], ["72720.01000000", "0.00008000"], ["72719.39000000", "0.18704000"], ["72719.33000000", "0.17926000"], ["72718.33000000", "0.05942000"], ["72717.93000000", "0.00008000"], ["72717.92000000", "0.17926000"], ["72716.55000000", "0.00000000"], ["72716.52000000", "0.00008000"], ["72716.51000000", "0.17926000"], ["72716.28000000", "0.38543000"], ["72716.02000000", "0.00000000"], ["72715.54000000", "0.00000000"], ["72715.39000000", "0.00048000"], ["72715.11000000", "0.00008000"], ["72715.10000000", "0.17926000"], ["72714.14000000", "0.65949000"], ["72713.89000000", "0.00000000"], ["72712.80000000", "0.00000000"], ["72712.59000000", "0.00008000"], ["72712.55000000", "0.00000000"], ["72711.79000000", "1.54677000"], ["72711.78000000", "2.74944000"], ["72711.14000000", "0.00008000"], ["72711.13000000", "0.65949000"], ["72710.63000000", "0.02000000"], ["72710.54000000", "0.00000000"], ["72710.53000000", "0.00000000"], ["72710.37000000", "0.00187000"], ["72709.73000000", "0.01000000"], ["72708.03000000", "0.52608000"], ["72708.02000000", "0.40856000"], ["72708.01000000", "0.00008000"], ["72707.88000000", "0.00000000"], ["72706.53000000", "0.12000000"], ["72705.23000000", "0.17926000"], ["72705.03000000", "0.00000000"], ["72704.22000000", "0.00000000"], ["72704.00000000", "0.02366000"], ["72701.57000000", "0.00000000"], ["72700.78000000", "0.00200000"], ["72700.01000000", "0.17989000"], ["72696.43000000", "0.17926000"], ["72693.82000000", "0.00012000"], ["72692.62000000", "0.00400000"], ["72692.60000000", "0.00000000"], ["72691.14000000", "0.00000000"], ["72691.13000000", "0.00000000"], ["72690.16000000", "0.00000000"], ["72689.61000000", "0.00000000"], ["72687.75000000", "0.00000000"], ["72685.60000000", "0.00000000"], ["72685.59000000", "0.00000000"], ["72685.58000000", "0.65941000"], ["72685.41000000", "1.36374000"], ["72685.02000000", "0.00000000"], ["72684.09000000", "0.00000000"], ["72684.08000000", "0.00008000"], ["72683.98000000", "0.00000000"], ["72682.67000000", "0.00000000"], ["72682.43000000", "0.00000000"], ["72682.04000000", "0.00000000"], ["72680.90000000", "0.00000000"], ["72680.70000000", "0.00188000"], ["72680.11000000", "0.00000000"], ["72677.92000000", "0.00000000"], ["72676.91000000", "0.49596000"], ["72671.39000000", "0.00000000"], ["72671.27000000", "0.00007000"], ["72669.05000000", "1.04034000"], ["72666.91000000", "0.19134000"], ["72666.89000000", "0.19134000"], ["72666.71000000", "0.19134000"], ["72665.87000000", "0.00009000"], ["72665.50000000", "0.00428000"], ["72664.29000000", "0.00434000"], ["72661.57000000", "0.20805000"], ["72661.56000000", "0.49607000"], ["72660.01000000", "0.00000000"], ["72649.98000000", "0.00000000"], ["72648.41000000", "0.00000000"], ["72646.77000000", "0.01075000"], ["72646.47000000", "0.01729000"], ["72631.84000000", "0.00000000"], ["72627.51000000", "0.06354000"], ["72622.66000000", "0.00000000"], ["72616.15000000", "0.04643000"], ["72615.14000000", "2.44660000"], ["72608.01000000", "0.00000000"], ["72604.72000000", "0.00007000"], ["72597.72000000", "0.00000000"], ["72580.97000000", "0.00000000"], ["72575.34000000", "0.00000000"], ["72569.39000000", "0.00717000"], ["72562.18000000", "0.00412000"], ["72543.91000000", "0.00080000"], ["72518.48000000", "0.00000000"], ["72513.97000000", "0.00000000"], ["72463.50000000", "0.00000000"], ["72463.15000000", "0.11416000"], ["72461.92000000", "0.00010000"], ["72280.15000000", "0.00000000"], ["72164.79000000", "0.20952000"], ["65457.55000000", "0.00034000"]], "a": [["72730.62000000", "3.63580000"], ["72730.63000000", "0.00038000"], ["72730.64000000", "0.00014000"], ["72730.77000000", "0.00000000"], ["72730.84000000", "0.00400000"], ["72730.85000000", "0.00016000"], ["72730.86000000", "0.11120000"], ["72730.97000000", "0.00000000"], ["72730.99000000", "0.00000000"], ["72731.03000000", "0.42152000"], ["72731.04000000", "0.65957000"], ["72731.05000000", "0.00008000"], ["72731.06000000", "0.00698000"], ["72731.07000000", "0.00000000"], ["72731.08000000", "0.00000000"], ["72731.81000000", "0.02000000"], ["72731.99000000", "0.00000000"], ["72732.01000000", "0.00016000"], ["72732.03000000", "0.00000000"], ["72732.20000000", "0.00000000"], ["72732.21000000", "0.00016000"], ["72732.31000000", "0.00016000"], ["72732.32000000", "0.04131000"], ["72732.33000000", "0.00000000"], ["72732.39000000", "0.00000000"], ["72732.40000000", "0.00032000"], ["72732.41000000", "0.10458000"], ["72732.45000000", "0.00000000"], ["72732.60000000", "0.00032000"], ["72732.61000000", "0.66438000"], ["72732.81000000", "0.00000000"], ["72733.18000000", "0.00008000"], ["72733.19000000", "0.34541000"], ["72733.33000000", "0.00000000"], ["72733.34000000", "0.21591000"], ["72733.40000000", "0.00008000"], ["72733.41000000", "0.00000000"], ["72734.01000000", "0.11120000"], ["72734.54000000", "0.04856000"], ["72734.77000000", "0.00000000"], ["72734.78000000", "0.00000000"], ["72734.82000000", "0.65957000"], ["72734.83000000", "0.79464000"], ["72735.21000000", "0.02385000"], ["72735.30000000", "0.00000000"], ["72735.31000000", "0.44472000"], ["72735.71000000", "0.00000000"], ["72735.72000000", "0.32567000"], ["72735.81000000", "0.16208000"], ["72735.90000000", "0.00000000"], ["72736.00000000", "0.00008000"], ["72736.01000000", "0.00000000"], ["72736.02000000", "0.00000000"], ["72736.12000000", "0.00008000"], ["72736.13000000", "0.07439000"], ["72736.37000000", "0.00741000"], ["72736.60000000", "0.00000000"], ["72736.61000000", "0.15336000"], ["72736.68000000", "0.00000000"], ["72736.72000000", "0.00000000"], ["72736.73000000", "0.00000000"], ["72737.04000000", "0.00000000"], ["72737.28000000", "0.00015000"], ["72737.29000000", "0.00000000"], ["72738.01000000", "0.00000000"], ["72738.02000000", "0.55846000"], ["72738.29000000", "0.33699000"], ["72738.30000000", "0.00000000"], ["72738.51000000", "0.65949000"], ["72739.08000000", "0.00000000"], ["72739.35000000", "0.00008000"], ["72739.63000000", "0.00000000"], ["72740.49000000", "0.00000000"], ["72740.58000000", "0.00000000"], ["72740.80000000", "0.00008000"], ["72740.81000000", "0.00000000"], ["72740.82000000", "0.00000000"], ["72741.06000000", "0.00000000"], ["72741.25000000", "0.00008000"], ["72741.26000000", "0.33140000"], ["72741.98000000", "0.00000000"], ["72741.99000000", "0.55183000"], ["72742.00000000", "0.00008000"], ["72742.01000000", "0.11087000"], ["72742.03000000", "0.00000000"], ["72742.13000000", "0.04000000"], ["72742.56000000", "0.65960000"], ["72742.75000000", "0.00000000"], ["72743.87000000", "0.00400000"], ["72744.40000000", "0.00008000"], ["72744.41000000", "0.68835000"], ["72746.09000000", "0.17122000"], ["72746.10000000", "0.06762000"], ["72746.11000000", "0.00000000"], ["72746.73000000", "0.00000000"], ["72747.54000000", "0.17926000"], ["72747.98000000", "0.00000000"], ["72748.95000000", "0.17926000"], ["72749.07000000", "1.63753000"], ["72749.08000000", "3.40893000"], ["72749.10000000", "0.00008000"], ["72749.11000000", "0.00000000"], ["72749.12000000", "0.00000000"], ["72749.13000000", "0.00000000"], ["72749.29000000", "0.27308000"], ["72749.30000000", "0.00000000"], ["72751.00000000", "0.00108000"], ["72752.00000000", "0.00080000"], ["72753.76000000", "0.00000000"], ["72753.77000000", "0.00883000"], ["72753.78000000", "0.65949000"], ["72753.81000000", "0.00008000"], ["72753.82000000", "1.64273000"], ["72754.98000000", "2.74952000"], ["72754.99000000", "0.00000000"], ["72755.00000000", "0.00000000"], ["72755.12000000", "0.58572000"], ["72757.35000000", "0.00000000"], ["72757.36000000", "0.00008000"], ["72757.37000000", "0.00000000"], ["72757.72000000", "0.00000000"], ["72758.28000000", "0.00000000"], ["72759.26000000", "0.00200000"], ["72759.96000000", "0.00000000"], ["72761.33000000", "0.00436000"], ["72761.44000000", "0.00000000"], ["72761.88000000", "2.74944000"], ["72762.04000000", "0.00028000"], ["72762.47000000", "0.00624000"], ["72762.52000000", "0.00000000"], ["72762.80000000", "0.00000000"], ["72765.51000000", "0.75576000"], ["72765.52000000", "1.03896000"], ["72765.64000000", "0.00008000"], ["72766.21000000", "0.00426000"], ["72766.35000000", "0.00000000"], ["72767.46000000", "0.00433000"], ["72768.68000000", "0.00008000"], ["72769.27000000", "0.00000000"], ["72772.72000000", "0.00000000"], ["72775.62000000", "0.02682000"], ["72777.10000000", "0.20000000"], ["72777.14000000", "0.20000000"], ["72777.21000000", "0.20007000"], ["72777.37000000", "0.00000000"], ["72777.76000000", "0.00000000"], ["72777.82000000", "0.00000000"], ["72779.53000000", "0.00000000"], ["72779.74000000", "0.44492000"], ["72780.00000000", "0.02288000"], ["72780.53000000", "0.00000000"], ["72780.54000000", "0.00000000"], ["72781.72000000", "0.49525000"], ["72785.98000000", "0.40856000"], ["72787.08000000", "1.36184000"], ["72788.23000000", "0.65949000"], ["72793.32000000", "0.00000000"], ["72795.47000000", "0.19134000"], ["72803.35000000", "0.00008000"], ["72810.76000000", "0.00000000"], ["72822.76000000", "0.04155000"], ["72823.43000000", "0.32343000"], ["72826.08000000", "0.56591000"], ["72830.52000000", "0.00000000"], ["72830.94000000", "0.00000000"], ["72834.33000000", "0.04268000"], ["72836.22000000", "0.00000000"], ["72838.48000000", "0.80932000"], ["72845.75000000", "0.06316000"], ["72848.44000000", "1.39567000"], ["72850.07000000", "0.00000000"], ["72865.81000000", "0.00000000"], ["72876.08000000", "0.00008000"], ["72883.50000000", "0.00000000"], ["72892.85000000", "4.12080000"], ["72906.17000000", "0.00000000"], ["72912.48000000", "0.00000000"], ["72928.61000000", "0.00000000"], ["72933.61000000", "0.01902000"], ["72937.43000000", "0.01893000"], ["72970.33000000", "0.00080000"], ["73000.19000000", "0.00010000"], ["73021.54000000", "0.00008000"], ["73028.23000000", "0.00019000"], ["73028.97000000", "0.00000000"], ["73057.17000000", "0.00000000"], ["73094.27000000", "0.00008000"], ["73101.71000000", "0.00000000"], ["73239.73000000", "0.00008000"], ["73247.19000000", "0.00000000"], ["73307.69000000", "0.00058000"], ["73452.56000000", "0.00007000"], ["73538.46000000", "0.00025000"]], "_local_ts_utc": "2026-06-01T07:49:01.610776+00:00"}
