{"e": "depthUpdate", "E": 1780300129015, "s": "ETHUSDT", "U": 76583053518, "u": 76583053778, "b": [["1975.45000000", "81.74990000"], ["1975.44000000", "0.01310000"], ["1975.43000000", "0.68980000"], ["1975.42000000", "0.00800000"], ["1975.41000000", "11.84910000"], ["1975.40000000", "3.26080000"], ["1975.39000000", "3.00260000"], ["1975.38000000", "0.30770000"], ["1975.36000000", "0.03270000"], ["1975.35000000", "22.68780000"], ["1975.31000000", "22.57370000"], ["1975.30000000", "13.40840000"], ["1975.29000000", "0.00000000"], ["1975.28000000", "3.43580000"], ["1975.27000000", "0.99980000"], ["1975.25000000", "13.50320000"], ["1975.24000000", "25.53230000"], ["1975.23000000", "2.53640000"], ["1975.22000000", "0.00000000"], ["1975.21000000", "0.25190000"], ["1975.20000000", "0.03570000"], ["1975.16000000", "6.17520000"], ["1975.15000000", "7.48630000"], ["1975.14000000", "0.00260000"], ["1975.10000000", "19.45460000"], ["1975.07000000", "22.57370000"], ["1975.05000000", "4.90050000"], ["1974.99000000", "3.51330000"], ["1974.93000000", "0.01220000"], ["1974.89000000", "3.05580000"], ["1974.83000000", "10.54790000"], ["1974.77000000", "4.55630000"], ["1974.76000000", "6.63430000"], ["1974.68000000", "21.32010000"], ["1974.52000000", "0.07690000"], ["1974.51000000", "0.00000000"], ["1974.46000000", "0.00380000"], ["1974.44000000", "0.02850000"], ["1974.38000000", "0.05320000"], ["1974.16000000", "13.54240000"], ["1974.10000000", "19.91590000"], ["1974.08000000", "1.52160000"], ["1974.05000000", "6.66000000"], ["1973.98000000", "5.87440000"], ["1973.97000000", "0.00000000"], ["1973.85000000", "5.40210000"], ["1973.75000000", "9.95330000"], ["1973.70000000", "11.20950000"], ["1973.65000000", "3.60420000"], ["1973.58000000", "1.02280000"], ["1973.55000000", "0.01080000"], ["1973.49000000", "25.40270000"], ["1973.40000000", "41.37630000"], ["1973.37000000", "0.20130000"], ["1973.30000000", "15.08950000"], ["1973.23000000", "0.41400000"], ["1973.15000000", "13.58050000"], ["1973.08000000", "6.19330000"], ["1973.03000000", "0.75900000"], ["1972.99000000", "15.50600000"], ["1972.60000000", "0.02310000"], ["1972.58000000", "6.85160000"], ["1972.49000000", "0.00000000"], ["1972.46000000", "3.30360000"], ["1972.45000000", "3.62720000"], ["1972.40000000", "9.60760000"], ["1971.99000000", "0.43310000"], ["1971.31000000", "0.94480000"], ["1971.29000000", "0.00460000"], ["1970.51000000", "0.01520000"], ["1969.39000000", "0.00630000"], ["1969.30000000", "0.00000000"], ["1967.71000000", "0.00390000"], ["1777.91000000", "0.01240000"], ["1474.83000000", "0.00000000"]], "a": [["1975.46000000", "9.37330000"], ["1975.47000000", "0.01280000"], ["1975.50000000", "0.01110000"], ["1975.51000000", "0.55040000"], ["1975.52000000", "0.00760000"], ["1975.56000000", "0.00000000"], ["1975.57000000", "0.00000000"], ["1975.58000000", "0.00000000"], ["1975.60000000", "1.10740000"], ["1975.63000000", "0.00000000"], ["1975.64000000", "0.00000000"], ["1975.68000000", "0.06300000"], ["1975.69000000", "0.00260000"], ["1975.70000000", "0.00570000"], ["1975.71000000", "0.00560000"], ["1975.72000000", "0.00000000"], ["1975.73000000", "0.00000000"], ["1975.81000000", "0.00000000"], ["1975.84000000", "0.03260000"], ["1975.85000000", "0.00000000"], ["1975.87000000", "0.00000000"], ["1975.90000000", "0.00570000"], ["1975.91000000", "0.00000000"], ["1975.92000000", "0.03000000"], ["1975.96000000", "0.00260000"], ["1976.03000000", "4.29360000"], ["1976.07000000", "1.24040000"], ["1976.10000000", "6.03890000"], ["1976.11000000", "0.85570000"], ["1976.12000000", "6.49410000"], ["1976.20000000", "11.25310000"], ["1976.21000000", "8.50700000"], ["1976.22000000", "0.00000000"], ["1976.31000000", "0.00000000"], ["1976.32000000", "6.69400000"], ["1976.36000000", "0.00260000"], ["1976.40000000", "1.34810000"], ["1976.47000000", "0.00000000"], ["1976.51000000", "14.35460000"], ["1976.52000000", "14.17820000"], ["1976.53000000", "0.00000000"], ["1976.57000000", "0.84230000"], ["1976.62000000", "9.77800000"], ["1976.79000000", "0.08640000"], ["1976.80000000", "0.51910000"], ["1976.87000000", "10.05710000"], ["1976.88000000", "1.41450000"], ["1976.89000000", "7.08300000"], ["1976.96000000", "0.03000000"], ["1977.38000000", "0.00000000"], ["1977.42000000", "6.40380000"], ["1977.50000000", "13.94350000"], ["1977.51000000", "0.00000000"], ["1977.57000000", "4.03830000"], ["1977.60000000", "9.99200000"], ["1977.65000000", "0.69270000"], ["1977.73000000", "0.02000000"], ["1977.74000000", "0.28620000"], ["1977.83000000", "16.93780000"], ["1977.84000000", "7.12200000"], ["1977.85000000", "0.00000000"], ["1978.40000000", "37.36480000"], ["1978.41000000", "18.60000000"], ["1978.55000000", "10.77420000"], ["1978.57000000", "0.00300000"], ["1978.77000000", "4.87780000"], ["1980.58000000", "1.20810000"], ["1980.72000000", "0.00260000"], ["1984.00000000", "0.05460000"], ["2474.85000000", "0.00690000"]], "_local_ts_utc": "2026-06-01T07:48:47.911849+00:00"}
{"e": "depthUpdate", "E": 1780300129115, "s": "ETHUSDT", "U": 76583053779, "u": 76583053844, "b": [["1975.45000000", "75.05580000"], ["1975.43000000", "0.63650000"], ["1975.41000000", "18.10220000"], ["1975.38000000", "0.30770000"], ["1975.36000000", "0.03530000"], ["1975.35000000", "23.19470000"], ["1975.34000000", "0.81890000"], ["1975.31000000", "29.06780000"], ["1975.16000000", "3.01700000"], ["1975.12000000", "0.03000000"], ["1975.05000000", "3.60000000"], ["1974.99000000", "2.88230000"], ["1974.93000000", "0.28220000"], ["1974.91000000", "2.94580000"], ["1974.79000000", "0.27470000"], ["1974.78000000", "0.11260000"], ["1974.57000000", "0.37810000"], ["1974.46000000", "0.10380000"], ["1973.78000000", "0.09800000"], ["1973.69000000", "0.49420000"], ["1970.99000000", "0.11560000"], ["1970.72000000", "1.16280000"], ["1969.65000000", "4.29590000"], ["1969.56000000", "1.00900000"], ["1969.47000000", "0.02190000"], ["1968.14000000", "0.03100000"], ["1935.94000000", "0.00000000"], ["1777.91000000", "0.02480000"]], "a": [["1975.47000000", "0.01820000"], ["1975.48000000", "0.15750000"], ["1975.57000000", "0.00540000"], ["1975.58000000", "0.67580000"], ["1975.75000000", "1.01370000"], ["1975.79000000", "1.32650000"], ["1975.82000000", "0.62800000"], ["1975.97000000", "6.49410000"], ["1976.00000000", "22.57460000"], ["1976.08000000", "13.52890000"], ["1976.50000000", "0.00260000"], ["1976.51000000", "17.00130000"], ["1976.89000000", "7.29630000"], ["1977.11000000", "1.52040000"], ["1977.25000000", "0.22950000"], ["1977.62000000", "8.05460000"], ["1978.55000000", "0.00260000"], ["1978.56000000", "0.00000000"], ["1980.81000000", "0.00260000"], ["1980.90000000", "0.00260000"], ["1980.99000000", "0.00260000"], ["1981.08000000", "0.03550000"]], "_local_ts_utc": "2026-06-01T07:48:48.011946+00:00"}
{"e": "depthUpdate", "E": 1780300129215, "s": "ETHUSDT", "U": 76583053845, "u": 76583053933, "b": [["1975.45000000", "55.59010000"], ["1975.42000000", "0.00260000"], ["1975.41000000", "0.00800000"], ["1975.38000000", "0.00800000"], ["1975.37000000", "13.54860000"], ["1975.36000000", "0.03260000"], ["1975.35000000", "0.00260000"], ["1975.32000000", "0.00270000"], ["1975.30000000", "9.63690000"], ["1975.25000000", "0.00000000"], ["1975.21000000", "0.00000000"], ["1975.16000000", "2.39830000"], ["1975.15000000", "7.53630000"], ["1975.10000000", "23.85760000"], ["1975.06000000", "22.69420000"], ["1974.98000000", "0.00000000"], ["1974.77000000", "0.15630000"], ["1974.74000000", "12.07970000"], ["1974.66000000", "0.05690000"], ["1974.46000000", "0.00380000"], ["1974.41000000", "0.10000000"], ["1974.40000000", "9.62230000"], ["1974.33000000", "1.21390000"], ["1974.27000000", "29.98660000"], ["1974.25000000", "8.43190000"], ["1974.04000000", "0.00000000"], ["1777.91000000", "0.03720000"]], "a": [["1975.46000000", "21.33960000"], ["1975.47000000", "0.01560000"], ["1975.74000000", "0.73220000"], ["1975.91000000", "8.73110000"], ["1975.92000000", "8.53430000"], ["1975.93000000", "14.17680000"], ["1975.96000000", "0.00260000"], ["1976.06000000", "26.78700000"], ["1976.35000000", "1.35540000"], ["1977.49000000", "0.00260000"], ["1977.50000000", "5.43650000"], ["1977.60000000", "6.24490000"], ["1977.68000000", "0.12640000"], ["1977.69000000", "0.00300000"], ["1978.54000000", "0.00640000"], ["1979.04000000", "0.79300000"], ["1992.67000000", "0.00000000"]], "_local_ts_utc": "2026-06-01T07:48:48.111421+00:00"}
{"e": "depthUpdate", "E": 1780300129315, "s": "ETHUSDT", "U": 76583053934, "u": 76583054228, "b": [["1975.45000000", "10.15420000"], ["1975.44000000", "0.02090000"], ["1975.43000000", "0.00770000"], ["1975.40000000", "0.01060000"], ["1975.39000000", "3.00260000"], ["1975.38000000", "0.00260000"], ["1975.37000000", "0.00260000"], ["1975.36000000", "0.03520000"], ["1975.35000000", "0.00540000"], ["1975.32000000", "0.00000000"], ["1975.31000000", "0.00270000"], ["1975.30000000", "0.00520000"], ["1975.27000000", "0.00000000"], ["1975.24000000", "2.84710000"], ["1975.20000000", "0.03260000"], ["1975.18000000", "10.45260000"], ["1975.17000000", "0.00000000"], ["1975.16000000", "0.00300000"], ["1975.11000000", "0.00000000"], ["1975.10000000", "14.69260000"], ["1975.08000000", "7.08950000"], ["1975.07000000", "0.00000000"], ["1975.06000000", "0.01160000"], ["1975.05000000", "0.00000000"], ["1974.97000000", "21.93610000"], ["1974.96000000", "0.03000000"], ["1974.94000000", "7.08990000"], ["1974.93000000", "8.78650000"], ["1974.92000000", "11.05660000"], ["1974.89000000", "3.05580000"], ["1974.88000000", "18.55970000"], ["1974.86000000", "7.09070000"], ["1974.85000000", "1.32030000"], ["1974.84000000", "9.36630000"], ["1974.83000000", "3.45880000"], ["1974.82000000", "23.19940000"], ["1974.79000000", "13.77360000"], ["1974.73000000", "0.03000000"], ["1974.72000000", "0.17940000"], ["1974.69000000", "7.29600000"], ["1974.64000000", "17.24370000"], ["1974.63000000", "15.93240000"], ["1974.62000000", "0.00000000"], ["1974.59000000", "0.17480000"], ["1974.55000000", "0.03490000"], ["1974.52000000", "1.57690000"], ["1974.47000000", "22.66710000"], ["1974.46000000", "0.00380000"], ["1974.41000000", "0.00000000"], ["1974.40000000", "9.22230000"], ["1974.37000000", "7.39800000"], ["1974.36000000", "7.17230000"], ["1974.33000000", "0.41390000"], ["1974.32000000", "8.53370000"], ["1974.26000000", "1.89850000"], ["1974.25000000", "8.43190000"], ["1974.04000000", "0.00000000"], ["1973.98000000", "8.05380000"], ["1973.92000000", "8.50430000"], ["1973.89000000", "11.28950000"], ["1973.72000000", "8.78560000"], ["1973.69000000", "7.58110000"], ["1973.58000000", "5.21850000"], ["1973.55000000", "7.09770000"], ["1973.52000000", "9.90860000"], ["1973.50000000", "8.15870000"], ["1973.45000000", "10.90910000"], ["1973.42000000", "8.50940000"], ["1973.31000000", "7.35950000"], ["1973.26000000", "7.09070000"], ["1973.22000000", "1.55220000"], ["1973.19000000", "0.27700000"], ["1973.11000000", "0.01570000"], ["1973.06000000", "7.12990000"], ["1972.78000000", "0.27000000"], ["1972.66000000", "0.27920000"], ["1972.60000000", "10.98350000"], ["1972.59000000", "13.76470000"], ["1972.58000000", "0.00000000"], ["1972.31000000", "13.55480000"], ["1968.14000000", "0.02190000"], ["1964.51000000", "1.33290000"], ["1777.91000000", "0.04960000"], ["1580.36000000", "0.04200000"], ["1580.22000000", "0.00510000"], ["1580.16000000", "0.12000000"], ["1580.10000000", "0.00970000"], ["1580.09000000", "0.00000000"], ["1580.07000000", "0.00000000"]], "a": [["1975.46000000", "32.98540000"], ["1975.49000000", "0.00840000"], ["1975.50000000", "0.52880000"], ["1975.53000000", "0.01160000"], ["1975.54000000", "0.00000000"], ["1975.57000000", "0.00000000"], ["1975.59000000", "0.00000000"], ["1975.60000000", "1.13740000"], ["1975.62000000", "0.01160000"], ["1975.69000000", "0.00520000"], ["1975.71000000", "0.01720000"], ["1975.72000000", "1.46770000"], ["1975.73000000", "1.30070000"], ["1975.74000000", "8.52230000"], ["1975.76000000", "14.20380000"], ["1975.77000000", "0.00000000"], ["1975.78000000", "0.00260000"], ["1975.80000000", "2.01980000"], ["1975.81000000", "6.49410000"], ["1975.85000000", "1.20550000"], ["1975.88000000", "0.25050000"], ["1975.97000000", "0.00000000"], ["1976.10000000", "2.97530000"], ["1976.11000000", "1.44970000"], ["1976.12000000", "7.46610000"], ["1976.24000000", "0.04270000"], ["1976.40000000", "1.37810000"], ["1976.64000000", "0.06990000"], ["1976.80000000", "0.48910000"], ["1976.88000000", "1.38450000"], ["1976.96000000", "0.00000000"], ["1977.28000000", "0.75600000"], ["1977.42000000", "4.11920000"], ["1977.44000000", "14.48390000"], ["1977.52000000", "0.00000000"], ["1977.70000000", "14.02840000"], ["1977.71000000", "0.97460000"], ["1977.72000000", "0.60420000"], ["1991.00000000", "4.88430000"]], "_local_ts_utc": "2026-06-01T07:48:48.211592+00:00"}
{"e": "depthUpdate", "E": 1780300129415, "s": "ETHUSDT", "U": 76583054229, "u": 76583055685, "b": [["1975.45000000", "0.00000000"], ["1975.44000000", "0.00000000"], ["1975.43000000", "0.00000000"], ["1975.42000000", "0.00000000"], ["1975.41000000", "0.00000000"], ["1975.40000000", "0.00000000"], ["1975.39000000", "0.00000000"], ["1975.38000000", "0.00000000"], ["1975.37000000", "0.00000000"], ["1975.36000000", "0.00000000"], ["1975.35000000", "0.00000000"], ["1975.34000000", "0.00000000"], ["1975.33000000", "0.00000000"], ["1975.31000000", "0.00000000"], ["1975.30000000", "0.00000000"], ["1975.29000000", "0.00000000"], ["1975.28000000", "0.00000000"], ["1975.25000000", "0.00000000"], ["1975.24000000", "0.00000000"], ["1975.23000000", "0.00000000"], ["1975.22000000", "0.00000000"], ["1975.21000000", "0.00000000"], ["1975.20000000", "0.00000000"], ["1975.19000000", "0.00000000"], ["1975.18000000", "0.00000000"], ["1975.16000000", "0.00000000"], ["1975.15000000", "0.00000000"], ["1975.14000000", "0.00000000"], ["1975.13000000", "0.00000000"], ["1975.12000000", "0.00000000"], ["1975.10000000", "0.00000000"], ["1975.09000000", "0.00000000"], ["1975.08000000", "0.00000000"], ["1975.06000000", "0.00000000"], ["1975.05000000", "0.00000000"], ["1975.04000000", "0.00000000"], ["1975.03000000", "0.00000000"], ["1975.00000000", "0.00000000"], ["1974.99000000", "0.00000000"], ["1974.98000000", "0.00000000"], ["1974.97000000", "0.00000000"], ["1974.96000000", "2.86950000"], ["1974.95000000", "0.00260000"], ["1974.94000000", "0.00560000"], ["1974.93000000", "0.01760000"], ["1974.92000000", "0.27800000"], ["1974.91000000", "0.02680000"], ["1974.90000000", "0.01060000"], ["1974.89000000", "0.01450000"], ["1974.88000000", "0.03260000"], ["1974.87000000", "0.00260000"], ["1974.86000000", "0.00380000"], ["1974.85000000", "0.00270000"], ["1974.84000000", "0.00000000"], ["1974.82000000", "8.21890000"], ["1974.80000000", "0.03690000"], ["1974.79000000", "0.00470000"], ["1974.78000000", "0.00260000"], ["1974.77000000", "0.05500000"], ["1974.76000000", "0.00000000"], ["1974.74000000", "1.46530000"], ["1974.73000000", "0.03000000"], ["1974.72000000", "0.17940000"], ["1974.70000000", "0.05260000"], ["1974.69000000", "0.20910000"], ["1974.68000000", "0.00000000"], ["1974.67000000", "0.01130000"], ["1974.66000000", "0.00660000"], ["1974.64000000", "0.14480000"], ["1974.63000000", "0.34120000"], ["1974.62000000", "0.00000000"], ["1974.60000000", "7.59840000"], ["1974.59000000", "0.00430000"], ["1974.58000000", "0.02480000"], ["1974.57000000", "0.00000000"], ["1974.54000000", "0.01420000"], ["1974.53000000", "0.00480000"], ["1974.52000000", "0.07690000"], ["1974.51000000", "0.00000000"], ["1974.50000000", "0.06190000"], ["1974.49000000", "12.40070000"], ["1974.48000000", "0.08240000"], ["1974.47000000", "22.71740000"], ["1974.46000000", "8.50810000"], ["1974.45000000", "0.00260000"], ["1974.44000000", "7.11540000"], ["1974.43000000", "7.09090000"], ["1974.40000000", "9.22490000"], ["1974.37000000", "0.25860000"], ["1974.36000000", "15.21920000"], ["1974.34000000", "7.09730000"], ["1974.33000000", "7.50080000"], ["1974.32000000", "0.03000000"], ["1974.31000000", "0.00760000"], ["1974.30000000", "17.93340000"], ["1974.28000000", "13.53180000"], ["1974.27000000", "22.84990000"], ["1974.26000000", "1.79850000"], ["1974.25000000", "1.34550000"], ["1974.24000000", "1.45150000"], ["1974.23000000", "0.81000000"], ["1974.22000000", "0.38550000"], ["1974.20000000", "11.15330000"], ["1974.18000000", "0.04850000"], ["1974.17000000", "7.24100000"], ["1974.16000000", "0.06920000"], ["1974.15000000", "0.00260000"], ["1974.14000000", "13.62800000"], ["1974.10000000", "19.91850000"], ["1974.08000000", "1.55160000"], ["1974.01000000", "8.14170000"], ["1974.00000000", "12.26570000"], ["1973.99000000", "0.03150000"], ["1973.96000000", "0.20080000"], ["1973.95000000", "7.12700000"], ["1973.93000000", "2.75680000"], ["1973.92000000", "9.13430000"], ["1973.89000000", "10.08950000"], ["1973.88000000", "14.26410000"], ["1973.87000000", "0.27000000"], ["1973.82000000", "1.51370000"], ["1973.78000000", "0.89800000"], ["1973.76000000", "0.13000000"], ["1973.68000000", "0.03940000"], ["1973.65000000", "3.75530000"], ["1973.60000000", "0.09290000"], ["1973.58000000", "7.22060000"], ["1973.47000000", "0.00260000"], ["1973.41000000", "22.83540000"], ["1973.40000000", "9.66540000"], ["1973.35000000", "0.02000000"], ["1973.22000000", "10.05650000"], ["1973.17000000", "5.78790000"], ["1973.11000000", "7.10260000"], ["1973.02000000", "8.50430000"], ["1972.94000000", "14.17640000"], ["1972.82000000", "8.54980000"], ["1972.78000000", "0.00000000"], ["1972.75000000", "2.15500000"], ["1972.74000000", "14.17680000"], ["1972.63000000", "8.68930000"], ["1972.54000000", "14.17790000"], ["1972.34000000", "14.17380000"], ["1972.03000000", "13.49890000"], ["1971.76000000", "4.28820000"], ["1971.75000000", "14.29160000"], ["1971.47000000", "13.49890000"], ["1971.38000000", "31.77780000"], ["1971.19000000", "13.50150000"], ["1970.00000000", "410.36310000"], ["1969.69000000", "0.01310000"], ["1969.60000000", "25.43260000"], ["1967.85000000", "3.60000000"], ["1967.65000000", "3.60000000"], ["1967.45000000", "3.60300000"], ["1967.34000000", "0.00800000"], ["1967.05000000", "3.60710000"], ["1965.56000000", "0.23600000"], ["1965.46000000", "0.00260000"], ["1965.40000000", "0.21990000"], ["1964.04000000", "236.54050000"], ["1958.80000000", "1.00000000"], ["1935.89000000", "0.00830000"], ["1935.86000000", "0.05370000"], ["1935.72000000", "1.00000000"], ["1777.91000000", "0.00000000"], ["1777.89000000", "0.00000000"], ["1777.81000000", "0.00000000"], ["1580.36000000", "0.04900000"], ["1580.28000000", "0.02100000"], ["1580.04000000", "0.03780000"], ["1580.00000000", "312.47500000"]], "a": [["1974.97000000", "67.23400000"], ["1974.98000000", "0.00510000"], ["1974.99000000", "0.02210000"], ["1975.00000000", "0.00260000"], ["1975.01000000", "0.00000000"], ["1975.03000000", "0.00000000"], ["1975.04000000", "22.95910000"], ["1975.05000000", "0.00000000"], ["1975.07000000", "0.00000000"], ["1975.09000000", "0.00000000"], ["1975.10000000", "0.00260000"], ["1975.11000000", "0.00000000"], ["1975.13000000", "0.00000000"], ["1975.15000000", "0.01020000"], ["1975.16000000", "0.00000000"], ["1975.17000000", "0.00000000"], ["1975.19000000", "6.46760000"], ["1975.20000000", "0.00570000"], ["1975.21000000", "0.00000000"], ["1975.23000000", "24.29790000"], ["1975.24000000", "9.72080000"], ["1975.25000000", "1.00020000"], ["1975.26000000", "0.00000000"], ["1975.28000000", "0.03000000"], ["1975.29000000", "0.00000000"], ["1975.30000000", "0.00570000"], ["1975.31000000", "0.00000000"], ["1975.32000000", "0.00000000"], ["1975.33000000", "17.07690000"], ["1975.34000000", "0.01140000"], ["1975.35000000", "2.41180000"], ["1975.36000000", "0.23260000"], ["1975.37000000", "0.00000000"], ["1975.38000000", "0.00000000"], ["1975.39000000", "14.17380000"], ["1975.40000000", "14.95430000"], ["1975.41000000", "0.00000000"], ["1975.42000000", "0.00000000"], ["1975.43000000", "6.59640000"], ["1975.44000000", "5.00970000"], ["1975.45000000", "8.50430000"], ["1975.46000000", "1.03320000"], ["1975.47000000", "0.01020000"], ["1975.48000000", "0.16910000"], ["1975.49000000", "0.00300000"], ["1975.50000000", "4.69480000"], ["1975.51000000", "0.55300000"], ["1975.52000000", "0.03760000"], ["1975.53000000", "0.00000000"], ["1975.54000000", "0.00380000"], ["1975.56000000", "0.00000000"], ["1975.57000000", "0.00000000"], ["1975.58000000", "0.00000000"], ["1975.60000000", "14.70520000"], ["1975.61000000", "14.22380000"], ["1975.62000000", "0.00000000"], ["1975.63000000", "0.00260000"], ["1975.65000000", "3.60000000"], ["1975.66000000", "1.82620000"], ["1975.71000000", "0.00560000"], ["1975.72000000", "7.68620000"], ["1975.73000000", "13.49890000"], ["1975.74000000", "8.51070000"], ["1975.76000000", "14.85020000"], ["1975.79000000", "0.01020000"], ["1975.80000000", "0.00830000"], ["1975.81000000", "0.00000000"], ["1975.82000000", "0.00300000"], ["1975.86000000", "0.13760000"], ["1975.88000000", "0.17050000"], ["1975.95000000", "0.00760000"], ["1975.96000000", "0.00000000"], ["1975.99000000", "0.43200000"], ["1976.00000000", "26.17470000"], ["1976.07000000", "0.59400000"], ["1976.09000000", "0.97440000"], ["1976.10000000", "1.40170000"], ["1976.12000000", "0.97200000"], ["1976.20000000", "11.25050000"], ["1976.21000000", "12.10700000"], ["1976.30000000", "13.50890000"], ["1976.32000000", "7.29400000"], ["1976.40000000", "2.16800000"], ["1976.43000000", "0.01020000"], ["1976.48000000", "0.00300000"], ["1976.56000000", "0.00000000"], ["1976.57000000", "0.46420000"], ["1976.60000000", "7.76490000"], ["1976.62000000", "0.67100000"], ["1976.64000000", "0.00000000"], ["1976.69000000", "14.17280000"], ["1976.72000000", "0.00000000"], ["1976.80000000", "15.07530000"], ["1976.82000000", "0.52800000"], ["1976.85000000", "0.56700000"], ["1976.88000000", "1.37700000"], ["1977.04000000", "0.00260000"], ["1977.05000000", "0.00000000"], ["1977.08000000", "0.00000000"], ["1977.20000000", "0.00310000"], ["1977.21000000", "1.51830000"], ["1977.30000000", "1.37700000"], ["1977.31000000", "12.23710000"], ["1977.35000000", "31.64770000"], ["1977.50000000", "1.84130000"], ["1977.71000000", "0.43460000"], ["1977.72000000", "1.03620000"], ["1978.02000000", "0.00300000"], ["1978.03000000", "1.20550000"], ["1978.10000000", "0.00000000"], ["1978.23000000", "0.00000000"], ["1978.25000000", "1.03680000"], ["1978.31000000", "0.00000000"], ["1978.40000000", "31.63680000"], ["1978.77000000", "0.00000000"], ["1978.88000000", "0.00260000"], ["1980.05000000", "0.00000000"], ["1980.25000000", "0.00000000"], ["1980.28000000", "0.00000000"], ["1980.35000000", "0.00000000"], ["1980.40000000", "0.00310000"], ["1980.41000000", "0.00000000"], ["1980.46000000", "0.00260000"], ["1981.08000000", "0.03290000"], ["1983.08000000", "1.00000000"], ["1984.41000000", "1.36900000"], ["1984.64000000", "0.00000000"], ["1986.55000000", "113.37150000"], ["1988.00000000", "0.12030000"], ["2475.46000000", "0.01200000"]], "_local_ts_utc": "2026-06-01T07:48:48.312847+00:00"}
{"e": "depthUpdate", "E": 1780300129515, "s": "ETHUSDT", "U": 76583055686, "u": 76583056304, "b": [["1974.96000000", "0.00000000"], ["1974.95000000", "0.00000000"], ["1974.94000000", "0.00000000"], ["1974.93000000", "0.00000000"], ["1974.92000000", "0.00000000"], ["1974.91000000", "0.00000000"], ["1974.90000000", "0.00000000"], ["1974.89000000", "0.00000000"], ["1974.88000000", "0.00000000"], ["1974.87000000", "0.00000000"], ["1974.86000000", "0.00000000"], ["1974.85000000", "0.00000000"], ["1974.84000000", "0.00000000"], ["1974.83000000", "41.80550000"], ["1974.82000000", "7.61600000"], ["1974.81000000", "0.05880000"], ["1974.80000000", "0.00950000"], ["1974.79000000", "0.00730000"], ["1974.78000000", "0.00260000"], ["1974.77000000", "0.05760000"], ["1974.75000000", "0.13450000"], ["1974.74000000", "1.19790000"], ["1974.73000000", "0.03260000"], ["1974.72000000", "0.00880000"], ["1974.71000000", "0.00000000"], ["1974.70000000", "0.05260000"], ["1974.68000000", "0.09220000"], ["1974.67000000", "0.01130000"], ["1974.65000000", "0.01260000"], ["1974.64000000", "0.11480000"], ["1974.62000000", "3.03350000"], ["1974.61000000", "0.00300000"], ["1974.60000000", "0.13560000"], ["1974.55000000", "0.03490000"], ["1974.54000000", "0.01420000"], ["1974.53000000", "0.61550000"], ["1974.50000000", "0.06190000"], ["1974.49000000", "8.78970000"], ["1974.48000000", "6.55000000"], ["1974.47000000", "22.66710000"], ["1974.46000000", "0.00380000"], ["1974.44000000", "0.02850000"], ["1974.43000000", "0.00400000"], ["1974.42000000", "0.13820000"], ["1974.40000000", "9.22490000"], ["1974.36000000", "6.71490000"], ["1974.35000000", "4.44130000"], ["1974.34000000", "0.01040000"], ["1974.32000000", "2.14400000"], ["1974.31000000", "0.04130000"], ["1974.30000000", "9.36680000"], ["1974.29000000", "0.27380000"], ["1974.28000000", "0.03290000"], ["1974.24000000", "8.40840000"], ["1974.22000000", "8.88980000"], ["1974.15000000", "13.50150000"], ["1974.14000000", "0.13170000"], ["1974.09000000", "0.00260000"], ["1974.03000000", "2.83760000"], ["1974.02000000", "0.32670000"], ["1974.01000000", "34.87970000"], ["1973.98000000", "5.01090000"], ["1973.94000000", "0.27550000"], ["1973.93000000", "1.85680000"], ["1973.92000000", "8.53430000"], ["1973.90000000", "19.22610000"], ["1973.89000000", "11.38950000"], ["1973.86000000", "22.57750000"], ["1973.79000000", "0.37000000"], ["1973.78000000", "0.01270000"], ["1973.76000000", "0.03000000"], ["1973.75000000", "8.69330000"], ["1973.74000000", "0.80000000"], ["1973.69000000", "7.36900000"], ["1973.66000000", "1.10920000"], ["1973.52000000", "9.93860000"], ["1973.44000000", "8.54980000"], ["1973.36000000", "0.30530000"], ["1973.33000000", "2.80040000"], ["1973.28000000", "0.31330000"], ["1973.23000000", "0.33700000"], ["1973.15000000", "13.53240000"], ["1973.10000000", "0.21570000"], ["1973.08000000", "10.06810000"], ["1972.99000000", "10.26880000"], ["1972.92000000", "8.56560000"], ["1972.91000000", "0.00560000"], ["1972.75000000", "3.99650000"], ["1972.69000000", "9.47360000"], ["1972.64000000", "22.69330000"], ["1972.63000000", "0.18500000"], ["1972.46000000", "7.09990000"], ["1972.41000000", "14.27780000"], ["1972.40000000", "16.64000000"], ["1972.34000000", "0.00000000"], ["1971.99000000", "0.00000000"], ["1971.48000000", "7.33240000"], ["1971.46000000", "0.00000000"], ["1971.40000000", "10.61990000"], ["1971.31000000", "0.01530000"], ["1971.20000000", "5.05790000"], ["1971.19000000", "13.51170000"], ["1970.98000000", "13.50150000"], ["1970.92000000", "31.81660000"], ["1969.48000000", "0.00260000"], ["1969.39000000", "0.00890000"], ["1969.30000000", "0.00260000"], ["1969.21000000", "0.00560000"], ["1965.09000000", "0.05070000"], ["1954.88000000", "1.51230000"], ["1935.46000000", "0.23250000"], ["1935.33000000", "0.00970000"], ["1777.35000000", "0.00620000"]], "a": [["1974.84000000", "65.34550000"], ["1974.85000000", "0.00510000"], ["1974.86000000", "0.00510000"], ["1974.87000000", "0.00000000"], ["1974.88000000", "0.03000000"], ["1974.89000000", "0.00000000"], ["1974.90000000", "0.00260000"], ["1974.91000000", "0.00000000"], ["1974.92000000", "0.00540000"], ["1974.93000000", "3.41250000"], ["1974.94000000", "0.10420000"], ["1974.95000000", "6.47300000"], ["1974.96000000", "0.44790000"], ["1974.97000000", "7.03810000"], ["1974.98000000", "0.00000000"], ["1974.99000000", "0.01160000"], ["1975.00000000", "0.00570000"], ["1975.03000000", "23.32150000"], ["1975.04000000", "0.03760000"], ["1975.07000000", "0.00260000"], ["1975.08000000", "0.00000000"], ["1975.10000000", "0.00570000"], ["1975.11000000", "0.64730000"], ["1975.12000000", "0.03000000"], ["1975.14000000", "0.00380000"], ["1975.15000000", "0.01280000"], ["1975.16000000", "0.64940000"], ["1975.18000000", "0.00000000"], ["1975.19000000", "0.00000000"], ["1975.20000000", "0.03570000"], ["1975.21000000", "2.82260000"], ["1975.22000000", "7.08690000"], ["1975.23000000", "15.59120000"], ["1975.24000000", "11.99010000"], ["1975.25000000", "2.33320000"], ["1975.28000000", "0.03000000"], ["1975.32000000", "0.46000000"], ["1975.33000000", "6.63560000"], ["1975.34000000", "0.01400000"], ["1975.39000000", "15.37930000"], ["1975.40000000", "19.18930000"], ["1975.43000000", "11.97380000"], ["1975.45000000", "8.55480000"], ["1975.47000000", "26.74920000"], ["1975.48000000", "0.00000000"], ["1975.50000000", "3.06120000"], ["1975.51000000", "0.00260000"], ["1975.52000000", "0.13890000"], ["1975.55000000", "0.00260000"], ["1975.66000000", "0.52620000"], ["1975.76000000", "14.20380000"], ["1975.85000000", "1.77560000"], ["1975.90000000", "0.00310000"], ["1976.00000000", "19.46390000"], ["1976.03000000", "0.00260000"], ["1976.06000000", "0.05000000"], ["1976.08000000", "13.49890000"], ["1976.09000000", "0.80390000"], ["1976.11000000", "1.64970000"], ["1976.16000000", "0.08690000"], ["1976.17000000", "0.40000000"], ["1976.18000000", "2.00550000"], ["1976.24000000", "0.01270000"], ["1976.29000000", "0.78270000"], ["1976.32000000", "4.68390000"], ["1976.38000000", "0.00000000"], ["1976.39000000", "14.40630000"], ["1976.40000000", "1.33800000"], ["1976.41000000", "5.08930000"], ["1976.60000000", "0.00310000"], ["1976.61000000", "2.41580000"], ["1976.62000000", "0.59400000"], ["1976.69000000", "0.00000000"], ["1976.79000000", "0.00000000"], ["1976.80000000", "10.62180000"], ["1976.85000000", "0.56700000"], ["1976.86000000", "0.76120000"], ["1976.89000000", "7.08300000"], ["1977.01000000", "2.74590000"], ["1977.22000000", "2.36010000"], ["1977.25000000", "0.00300000"], ["1977.57000000", "3.60520000"], ["1977.65000000", "0.00000000"], ["1978.00000000", "10.58250000"], ["1978.10000000", "22.93780000"], ["1978.25000000", "14.70230000"], ["1978.31000000", "0.00000000"], ["1978.33000000", "0.01910000"], ["1978.57000000", "3.69980000"], ["1978.92000000", "0.21410000"], ["1979.27000000", "1.61000000"], ["1979.37000000", "0.00000000"], ["1979.64000000", "0.02020000"], ["1979.69000000", "0.00000000"], ["1979.72000000", "37.38090000"], ["1979.90000000", "1.20810000"], ["1979.96000000", "0.00000000"], ["1980.05000000", "0.00000000"], ["1980.40000000", "0.00310000"], ["1980.46000000", "0.00000000"], ["1980.54000000", "0.13100000"], ["1980.58000000", "1.20550000"], ["1980.66000000", "3.74670000"], ["1980.72000000", "0.00000000"], ["1980.81000000", "0.00000000"], ["1980.90000000", "0.00000000"], ["1980.99000000", "0.00000000"], ["1984.11000000", "0.49180000"]], "_local_ts_utc": "2026-06-01T07:48:48.412468+00:00"}
{"e": "depthUpdate", "E": 1780300129615, "s": "ETHUSDT", "U": 76583056305, "u": 76583056808, "b": [["1974.89000000", "102.57910000"], ["1974.88000000", "6.27890000"], ["1974.87000000", "0.00000000"], ["1974.86000000", "0.00540000"], ["1974.85000000", "0.00260000"], ["1974.84000000", "0.00800000"], ["1974.83000000", "12.54830000"], ["1974.82000000", "7.60820000"], ["1974.80000000", "0.03950000"], ["1974.79000000", "0.01750000"], ["1974.77000000", "0.05500000"], ["1974.75000000", "0.12650000"], ["1974.74000000", "1.19530000"], ["1974.73000000", "0.03000000"], ["1974.72000000", "0.03880000"], ["1974.71000000", "0.00000000"], ["1974.65000000", "0.01260000"], ["1974.64000000", "7.01700000"], ["1974.63000000", "14.51500000"], ["1974.62000000", "8.50430000"], ["1974.60000000", "0.13870000"], ["1974.59000000", "0.00430000"], ["1974.53000000", "0.00480000"], ["1974.52000000", "0.68760000"], ["1974.51000000", "6.78790000"], ["1974.50000000", "22.74000000"], ["1974.49000000", "12.75760000"], ["1974.48000000", "13.58130000"], ["1974.43000000", "3.60400000"], ["1974.40000000", "10.21600000"], ["1974.34000000", "7.09730000"], ["1974.32000000", "10.64830000"], ["1974.31000000", "13.54020000"], ["1974.30000000", "12.85880000"], ["1974.23000000", "0.81000000"], ["1974.10000000", "20.11850000"], ["1974.03000000", "3.23760000"], ["1974.02000000", "8.83100000"], ["1974.00000000", "12.29570000"], ["1973.99000000", "0.03150000"], ["1973.96000000", "0.20080000"], ["1973.90000000", "19.22350000"], ["1973.89000000", "11.98950000"], ["1973.84000000", "7.39860000"], ["1973.82000000", "1.11370000"], ["1973.79000000", "0.27000000"], ["1973.74000000", "0.00000000"], ["1973.60000000", "0.06290000"], ["1973.52000000", "9.90860000"], ["1973.44000000", "8.51980000"], ["1973.36000000", "0.27530000"], ["1973.28000000", "0.28330000"], ["1973.02000000", "0.00000000"], ["1972.92000000", "0.06130000"], ["1972.89000000", "15.11600000"], ["1972.88000000", "33.06270000"], ["1972.82000000", "0.04550000"], ["1972.73000000", "0.27000000"], ["1972.69000000", "5.52670000"], ["1972.64000000", "7.10210000"], ["1972.54000000", "0.00410000"], ["1972.46000000", "3.30360000"], ["1972.44000000", "0.19510000"], ["1972.41000000", "0.10400000"], ["1972.35000000", "0.27480000"], ["1971.20000000", "5.49380000"], ["1970.98000000", "0.00260000"], ["1970.92000000", "0.06570000"], ["1970.50000000", "0.97250000"], ["1969.83000000", "0.00260000"], ["1969.54000000", "0.00260000"], ["1969.12000000", "0.00260000"], ["1969.03000000", "0.00960000"], ["1958.70000000", "3.19240000"], ["1954.88000000", "0.00360000"], ["1935.39000000", "0.02980000"], ["1777.35000000", "0.00000000"]], "a": [["1974.84000000", "0.00000000"], ["1974.85000000", "0.00000000"], ["1974.86000000", "0.00000000"], ["1974.88000000", "0.00000000"], ["1974.90000000", "1.79510000"], ["1974.93000000", "3.00000000"], ["1974.94000000", "0.00000000"], ["1974.95000000", "0.00000000"], ["1974.96000000", "0.00000000"], ["1974.97000000", "0.00000000"], ["1974.99000000", "0.00000000"], ["1975.02000000", "0.00000000"], ["1975.03000000", "0.00000000"], ["1975.04000000", "1.99990000"], ["1975.05000000", "0.00000000"], ["1975.10000000", "0.10570000"], ["1975.11000000", "0.00000000"], ["1975.12000000", "0.03540000"], ["1975.13000000", "0.00000000"], ["1975.14000000", "0.00380000"], ["1975.16000000", "0.00300000"], ["1975.18000000", "0.00540000"], ["1975.19000000", "0.00000000"], ["1975.20000000", "0.03570000"], ["1975.21000000", "0.00000000"], ["1975.22000000", "0.00000000"], ["1975.23000000", "0.00000000"], ["1975.24000000", "4.98230000"], ["1975.25000000", "1.03320000"], ["1975.29000000", "6.46760000"], ["1975.30000000", "0.01730000"], ["1975.31000000", "6.92060000"], ["1975.32000000", "0.46000000"], ["1975.33000000", "0.00000000"], ["1975.35000000", "1.01180000"], ["1975.36000000", "0.03260000"], ["1975.38000000", "0.00000000"], ["1975.39000000", "14.17380000"], ["1975.40000000", "4.24070000"], ["1975.42000000", "0.00000000"], ["1975.48000000", "0.51300000"], ["1975.49000000", "2.14940000"], ["1975.50000000", "3.52020000"], ["1975.52000000", "0.03760000"], ["1975.65000000", "0.00000000"], ["1975.84000000", "0.66540000"], ["1975.98000000", "0.51300000"], ["1976.00000000", "19.92290000"], ["1976.11000000", "1.44970000"], ["1976.17000000", "0.00000000"], ["1976.18000000", "1.20550000"], ["1976.24000000", "0.04270000"], ["1976.25000000", "0.00000000"], ["1976.32000000", "6.11390000"], ["1976.40000000", "3.57590000"], ["1976.41000000", "3.60000000"], ["1976.44000000", "8.50690000"], ["1976.51000000", "14.35460000"], ["1976.67000000", "8.65540000"], ["1976.72000000", "11.64850000"], ["1976.73000000", "14.17380000"], ["1976.74000000", "0.00900000"], ["1976.77000000", "8.72700000"], ["1976.83000000", "1.28680000"], ["1976.94000000", "5.37010000"], ["1976.95000000", "17.77640000"], ["1977.31000000", "3.19920000"], ["1977.35000000", "0.00000000"], ["1977.60000000", "2.44760000"], ["1977.70000000", "4.59800000"], ["1977.71000000", "0.00260000"], ["1977.72000000", "0.44220000"], ["1977.77000000", "14.44390000"], ["1977.99000000", "13.49890000"], ["1979.09000000", "0.00260000"], ["1980.38000000", "0.00000000"], ["1980.44000000", "2.13930000"], ["1983.06000000", "129.82680000"]], "_local_ts_utc": "2026-06-01T07:48:48.511676+00:00"}
{"e": "depthUpdate", "E": 1780300129715, "s": "ETHUSDT", "U": 76583056809, "u": 76583056936, "b": [["1974.89000000", "78.19820000"], ["1974.88000000", "0.00780000"], ["1974.86000000", "0.00260000"], ["1974.85000000", "0.00800000"], ["1974.84000000", "6.05410000"], ["1974.78000000", "0.00000000"], ["1974.75000000", "0.12650000"], ["1974.74000000", "1.20070000"], ["1974.73000000", "6.80090000"], ["1974.72000000", "22.61250000"], ["1974.65000000", "10.65650000"], ["1974.64000000", "0.14480000"], ["1974.54000000", "2.12820000"], ["1974.44000000", "0.03110000"], ["1974.40000000", "10.22610000"], ["1974.36000000", "6.80600000"], ["1974.32000000", "8.53430000"], ["1974.14000000", "0.18200000"], ["1974.12000000", "8.51140000"], ["1973.85000000", "5.50210000"], ["1973.80000000", "1.15210000"], ["1973.78000000", "0.00260000"], ["1971.20000000", "1.25790000"], ["1971.19000000", "0.01280000"], ["1969.03000000", "0.00700000"], ["1777.41000000", "0.01860000"]], "a": [["1974.90000000", "15.26990000"], ["1975.03000000", "0.00000000"], ["1975.04000000", "0.03000000"], ["1975.10000000", "0.00570000"], ["1975.12000000", "0.04160000"], ["1975.16000000", "0.01460000"], ["1975.17000000", "1.94470000"], ["1975.18000000", "6.46760000"], ["1975.19000000", "0.01160000"], ["1975.23000000", "14.17380000"], ["1975.28000000", "1.96570000"], ["1975.29000000", "0.00000000"], ["1975.30000000", "8.52420000"], ["1975.31000000", "4.38210000"], ["1975.35000000", "1.00020000"], ["1975.46000000", "14.53210000"], ["1975.85000000", "1.28280000"], ["1976.61000000", "2.41580000"], ["1976.67000000", "0.15110000"], ["1976.95000000", "3.60260000"], ["1977.98000000", "0.00000000"], ["1977.99000000", "0.00000000"], ["1978.31000000", "14.61170000"], ["1979.93000000", "158.16640000"], ["1983.06000000", "3.60000000"]], "_local_ts_utc": "2026-06-01T07:48:48.611700+00:00"}
{"e": "depthUpdate", "E": 1780300129815, "s": "ETHUSDT", "U": 76583056937, "u": 76583057094, "b": [["1974.89000000", "68.05310000"], ["1974.88000000", "0.00260000"], ["1974.85000000", "0.00800000"], ["1974.84000000", "6.05410000"], ["1974.79000000", "0.01750000"], ["1974.76000000", "0.00540000"], ["1974.75000000", "16.05530000"], ["1974.74000000", "23.87340000"], ["1974.73000000", "0.03000000"], ["1974.67000000", "10.95630000"], ["1974.66000000", "0.00660000"], ["1974.65000000", "0.01260000"], ["1974.64000000", "13.64370000"], ["1974.50000000", "22.74520000"], ["1974.11000000", "3.07830000"], ["1974.03000000", "0.62020000"], ["1973.91000000", "0.05290000"], ["1973.22000000", "1.55220000"], ["1972.75000000", "2.15500000"], ["1972.74000000", "7.08990000"], ["1972.69000000", "3.41120000"], ["1972.64000000", "0.01520000"], ["1972.30000000", "0.01110000"], ["1870.80000000", "0.00430000"], ["1777.41000000", "0.03100000"]], "a": [["1974.90000000", "8.00410000"], ["1974.92000000", "0.00540000"], ["1974.96000000", "0.00000000"], ["1975.05000000", "0.00000000"], ["1975.16000000", "0.01460000"], ["1975.17000000", "0.00000000"], ["1975.18000000", "0.00000000"], ["1975.22000000", "5.62600000"], ["1975.23000000", "0.00000000"], ["1975.27000000", "0.00300000"], ["1975.28000000", "0.03000000"], ["1975.30000000", "13.57440000"], ["1975.32000000", "0.00000000"], ["1975.38000000", "15.59120000"], ["1975.39000000", "0.00000000"], ["1975.42000000", "7.08690000"], ["1975.43000000", "13.17930000"], ["1975.45000000", "0.05050000"], ["1975.46000000", "1.03320000"], ["1975.50000000", "6.57230000"], ["1975.59000000", "20.58580000"], ["1975.60000000", "1.13740000"], ["1975.61000000", "0.05000000"], ["1975.68000000", "7.14990000"], ["1975.70000000", "4.98110000"], ["1975.71000000", "15.59680000"], ["1975.72000000", "0.00000000"], ["1975.73000000", "0.00000000"], ["1975.74000000", "0.00640000"], ["1975.76000000", "0.03000000"], ["1975.84000000", "7.20680000"], ["1975.89000000", "2.67570000"], ["1975.90000000", "22.68120000"], ["1975.91000000", "0.00000000"], ["1975.92000000", "0.03000000"], ["1975.93000000", "0.00300000"], ["1975.95000000", "0.38570000"], ["1975.98000000", "4.67140000"], ["1975.99000000", "13.93090000"], ["1976.00000000", "14.17010000"], ["1976.08000000", "0.00000000"], ["1976.16000000", "0.11690000"], ["1976.26000000", "13.50190000"], ["1976.30000000", "0.00570000"], ["1976.32000000", "6.08390000"], ["1976.61000000", "4.76970000"], ["1976.67000000", "8.65540000"], ["1976.86000000", "9.26550000"], ["1976.94000000", "2.61720000"], ["1976.95000000", "10.68950000"], ["1977.09000000", "0.13130000"], ["1977.15000000", "7.08690000"], ["1977.37000000", "0.00000000"], ["1977.98000000", "4.03120000"], ["1977.99000000", "13.49890000"], ["1978.24000000", "0.00300000"], ["1978.40000000", "37.56330000"], ["1978.57000000", "3.69680000"], ["1980.44000000", "2.13670000"]], "_local_ts_utc": "2026-06-01T07:48:48.711673+00:00"}
{"e": "depthUpdate", "E": 1780300129915, "s": "ETHUSDT", "U": 76583057095, "u": 76583057127, "b": [["1974.89000000", "67.94670000"], ["1974.83000000", "12.54830000"], ["1974.65000000", "0.01520000"], ["1974.50000000", "22.75040000"], ["1974.30000000", "12.90910000"], ["1974.21000000", "0.36260000"], ["1974.17000000", "7.34100000"], ["1974.15000000", "16.54430000"], ["1973.85000000", "5.40210000"], ["1973.71000000", "1.25580000"], ["1969.65000000", "3.71520000"], ["1969.19000000", "0.61390000"], ["1777.41000000", "0.04340000"]], "a": [["1974.90000000", "7.90410000"], ["1974.91000000", "0.00000000"], ["1974.92000000", "0.93250000"], ["1974.99000000", "0.10000000"], ["1975.12000000", "0.03000000"], ["1975.16000000", "0.00300000"], ["1975.62000000", "0.00260000"], ["1975.67000000", "2.13750000"], ["1975.69000000", "0.00260000"], ["1975.88000000", "0.17310000"], ["1977.72000000", "0.01020000"]], "_local_ts_utc": "2026-06-01T07:48:48.811374+00:00"}
{"e": "depthUpdate", "E": 1780300130015, "s": "ETHUSDT", "U": 76583057128, "u": 76583057617, "b": [["1974.99000000", "93.37610000"], ["1974.98000000", "0.00770000"], ["1974.97000000", "0.00510000"], ["1974.96000000", "0.03000000"], ["1974.95000000", "0.00540000"], ["1974.94000000", "6.47300000"], ["1974.93000000", "22.57630000"], ["1974.92000000", "0.00800000"], ["1974.91000000", "15.37340000"], ["1974.90000000", "6.25280000"], ["1974.89000000", "0.32170000"], ["1974.88000000", "0.03260000"], ["1974.85000000", "11.16040000"], ["1974.84000000", "22.67810000"], ["1974.83000000", "6.07270000"], ["1974.82000000", "7.60560000"], ["1974.81000000", "0.05620000"], ["1974.80000000", "1.14760000"], ["1974.79000000", "0.01490000"], ["1974.76000000", "0.00000000"], ["1974.75000000", "16.04990000"], ["1974.70000000", "0.05570000"], ["1974.54000000", "0.01420000"], ["1974.52000000", "0.07690000"], ["1974.51000000", "7.05790000"], ["1974.50000000", "22.75300000"], ["1974.40000000", "10.42610000"], ["1974.33000000", "7.90080000"], ["1974.30000000", "12.63910000"], ["1974.27000000", "22.95120000"], ["1974.18000000", "0.84850000"], ["1974.14000000", "0.17940000"], ["1974.11000000", "3.07830000"], ["1974.04000000", "0.00000000"], ["1974.03000000", "0.02020000"], ["1974.00000000", "12.29310000"], ["1973.89000000", "11.18950000"], ["1973.81000000", "0.19230000"], ["1973.76000000", "0.00000000"], ["1973.68000000", "0.00940000"], ["1973.49000000", "17.01230000"], ["1973.42000000", "0.00510000"], ["1973.31000000", "7.44640000"], ["1972.94000000", "7.08950000"], ["1972.88000000", "32.97740000"], ["1972.81000000", "0.47130000"], ["1972.75000000", "0.01260000"], ["1972.74000000", "0.00300000"], ["1971.47000000", "0.00000000"], ["1969.88000000", "1.21270000"], ["1969.83000000", "0.00260000"], ["1967.34000000", "0.00000000"], ["1935.49000000", "0.08420000"], ["1935.41000000", "0.00000000"], ["1876.24000000", "0.00610000"], ["1876.21000000", "0.00000000"], ["1876.17000000", "0.00280000"], ["1876.16000000", "0.00280000"], ["1876.10000000", "0.00000000"], ["1777.50000000", "0.00620000"], ["1777.41000000", "0.00000000"]], "a": [["1974.90000000", "0.00000000"], ["1974.91000000", "0.00000000"], ["1974.92000000", "0.00000000"], ["1974.93000000", "0.00000000"], ["1974.99000000", "0.00000000"], ["1975.00000000", "0.00260000"], ["1975.04000000", "0.00000000"], ["1975.08000000", "0.10000000"], ["1975.12000000", "0.00000000"], ["1975.15000000", "0.01020000"], ["1975.19000000", "0.00000000"], ["1975.21000000", "0.00540000"], ["1975.22000000", "1.51500000"], ["1975.23000000", "0.00540000"], ["1975.24000000", "0.00520000"], ["1975.25000000", "0.03300000"], ["1975.29000000", "0.00000000"], ["1975.30000000", "0.01370000"], ["1975.31000000", "1.57830000"], ["1975.34000000", "0.01140000"], ["1975.38000000", "0.00000000"], ["1975.41000000", "6.46760000"], ["1975.42000000", "0.00000000"], ["1975.43000000", "11.97380000"], ["1975.48000000", "1.01060000"], ["1975.49000000", "0.64940000"], ["1975.58000000", "15.59120000"], ["1975.59000000", "0.00000000"], ["1975.71000000", "17.09680000"], ["1975.82000000", "12.03670000"], ["1975.83000000", "13.49890000"], ["1975.84000000", "0.03260000"], ["1975.88000000", "0.00260000"], ["1975.90000000", "22.68380000"], ["1975.98000000", "0.51300000"], ["1975.99000000", "0.43200000"], ["1976.04000000", "13.98790000"], ["1976.20000000", "6.31940000"], ["1976.26000000", "0.00300000"], ["1976.32000000", "8.22160000"], ["1976.37000000", "13.50190000"], ["1976.39000000", "14.40630000"], ["1976.40000000", "3.60590000"], ["1976.47000000", "0.60000000"], ["1976.68000000", "1.28600000"], ["1976.80000000", "19.12610000"], ["1976.85000000", "7.65390000"], ["1976.86000000", "0.76120000"], ["1977.01000000", "4.50940000"], ["1977.03000000", "0.76460000"], ["1977.07000000", "8.30260000"], ["1977.29000000", "0.97200000"], ["1977.31000000", "4.90570000"], ["1977.37000000", "7.08690000"], ["1978.24000000", "0.00300000"], ["1984.11000000", "0.00000000"], ["2475.46000000", "0.00000000"]], "_local_ts_utc": "2026-06-01T07:48:48.912165+00:00"}
{"e": "depthUpdate", "E": 1780300130115, "s": "ETHUSDT", "U": 76583057618, "u": 76583057825, "b": [["1975.06000000", "87.98200000"], ["1975.05000000", "0.00510000"], ["1975.04000000", "0.03510000"], ["1975.00000000", "0.00800000"], ["1974.99000000", "32.07550000"], ["1974.98000000", "0.00260000"], ["1974.97000000", "0.00260000"], ["1974.96000000", "0.03800000"], ["1974.95000000", "22.68610000"], ["1974.94000000", "0.00260000"], ["1974.92000000", "0.00260000"], ["1974.91000000", "13.50150000"], ["1974.90000000", "6.10840000"], ["1974.89000000", "0.43190000"], ["1974.88000000", "0.03000000"], ["1974.86000000", "0.00380000"], ["1974.85000000", "11.15780000"], ["1974.84000000", "22.68070000"], ["1974.80000000", "5.55770000"], ["1974.68000000", "2.20620000"], ["1974.66000000", "3.60660000"], ["1974.64000000", "13.79480000"], ["1974.60000000", "0.51680000"], ["1974.50000000", "22.75560000"], ["1974.48000000", "13.85130000"], ["1974.35000000", "0.03730000"], ["1974.31000000", "13.53050000"], ["1974.24000000", "8.27840000"], ["1974.22000000", "11.14490000"], ["1974.00000000", "12.29580000"], ["1973.84000000", "7.36860000"], ["1973.58000000", "5.21850000"], ["1973.52000000", "1.40430000"], ["1973.08000000", "6.19330000"], ["1973.06000000", "0.04300000"], ["1973.00000000", "8.49440000"], ["1972.99000000", "5.94370000"], ["1972.94000000", "0.00260000"], ["1972.76000000", "0.27550000"], ["1972.15000000", "0.11020000"], ["1971.48000000", "2.32720000"], ["1971.08000000", "1.23820000"], ["1970.71000000", "65.96310000"], ["1970.00000000", "410.36040000"], ["1968.39000000", "0.10000000"], ["1968.14000000", "60.87570000"], ["1967.66000000", "0.03650000"], ["1967.05000000", "0.00710000"], ["1965.58000000", "76.13700000"], ["1965.14000000", "0.56250000"], ["1964.07000000", "0.01050000"], ["1935.55000000", "0.03630000"], ["1777.56000000", "0.01240000"], ["1777.50000000", "0.00000000"]], "a": [["1975.00000000", "0.00000000"], ["1975.06000000", "0.00000000"], ["1975.07000000", "0.56190000"], ["1975.08000000", "0.00520000"], ["1975.10000000", "0.00260000"], ["1975.20000000", "0.00570000"], ["1975.21000000", "0.00000000"], ["1975.22000000", "0.00000000"], ["1975.23000000", "0.00000000"], ["1975.24000000", "0.10000000"], ["1975.28000000", "0.00000000"], ["1975.30000000", "0.01370000"], ["1975.34000000", "0.01140000"], ["1975.35000000", "0.00000000"], ["1975.38000000", "0.00300000"], ["1975.39000000", "0.00540000"], ["1975.41000000", "0.00000000"], ["1975.46000000", "1.04480000"], ["1975.49000000", "0.00300000"], ["1975.54000000", "0.57080000"], ["1975.55000000", "6.47020000"], ["1975.57000000", "15.59490000"], ["1975.58000000", "0.00000000"], ["1975.98000000", "1.86420000"], ["1976.00000000", "14.17000000"], ["1976.47000000", "0.00000000"], ["1976.48000000", "0.03300000"], ["1976.54000000", "7.71970000"], ["1976.56000000", "0.03000000"], ["1977.03000000", "0.76460000"], ["1977.29000000", "0.48600000"], ["1977.35000000", "0.56700000"], ["1978.46000000", "0.00260000"], ["1979.79000000", "66.97140000"], ["1980.37000000", "0.16310000"], ["1980.43000000", "0.03550000"], ["1980.52000000", "0.00260000"], ["1980.64000000", "1.19830000"], ["1982.36000000", "62.08120000"], ["1982.62000000", "0.03000000"], ["1982.74000000", "1.30550000"], ["1984.18000000", "0.00000000"], ["1984.92000000", "76.06720000"], ["1985.61000000", "0.33240000"], ["1987.07000000", "0.04000000"], ["1988.00000000", "0.12300000"], ["2001.65000000", "0.10000000"]], "_local_ts_utc": "2026-06-01T07:48:49.011847+00:00"}
{"e": "depthUpdate", "E": 1780300130215, "s": "ETHUSDT", "U": 76583057826, "u": 76583058043, "b": [["1975.10000000", "90.34690000"], ["1975.09000000", "9.37500000"], ["1975.08000000", "0.01050000"], ["1975.07000000", "22.68890000"], ["1975.06000000", "9.88140000"], ["1975.05000000", "0.00260000"], ["1975.04000000", "0.03260000"], ["1975.00000000", "0.01060000"], ["1974.99000000", "28.56860000"], ["1974.96000000", "0.03260000"], ["1974.95000000", "22.68350000"], ["1974.94000000", "0.00000000"], ["1974.93000000", "22.57370000"], ["1974.92000000", "0.00000000"], ["1974.91000000", "13.49890000"], ["1974.78000000", "0.00260000"], ["1974.68000000", "0.09220000"], ["1974.61000000", "0.00560000"], ["1974.50000000", "22.85300000"], ["1974.46000000", "0.05380000"], ["1974.38000000", "0.15450000"], ["1974.31000000", "15.03050000"], ["1974.27000000", "22.84990000"], ["1974.17000000", "7.24100000"], ["1974.10000000", "19.91590000"], ["1973.89000000", "9.88950000"], ["1973.72000000", "0.28130000"], ["1973.26000000", "0.00380000"], ["1973.17000000", "4.10200000"], ["1973.11000000", "0.01570000"], ["1969.12000000", "0.00000000"], ["1935.59000000", "0.00000000"], ["1935.58000000", "0.00000000"], ["1777.59000000", "0.01240000"], ["1777.56000000", "0.00000000"], ["1192.00000000", "0.00000000"]], "a": [["1975.07000000", "0.00000000"], ["1975.08000000", "0.00000000"], ["1975.10000000", "0.00000000"], ["1975.11000000", "0.01280000"], ["1975.12000000", "0.00510000"], ["1975.14000000", "0.00000000"], ["1975.24000000", "0.00000000"], ["1975.28000000", "0.10000000"], ["1975.30000000", "0.01110000"], ["1975.37000000", "0.05000000"], ["1975.41000000", "0.00260000"], ["1975.42000000", "0.00540000"], ["1975.43000000", "11.97380000"], ["1975.46000000", "1.03320000"], ["1975.48000000", "0.99900000"], ["1975.50000000", "8.90810000"], ["1975.53000000", "0.01160000"], ["1975.56000000", "7.08860000"], ["1975.66000000", "0.53780000"], ["1975.79000000", "0.65660000"], ["1976.06000000", "0.00000000"], ["1976.16000000", "0.03000000"], ["1976.57000000", "0.55130000"], ["1976.80000000", "19.12610000"], ["1977.31000000", "3.19920000"], ["1977.35000000", "0.00000000"], ["1977.37000000", "0.00000000"], ["1979.09000000", "0.00000000"], ["1980.58000000", "1.20810000"]], "_local_ts_utc": "2026-06-01T07:48:49.113299+00:00"}
{"e": "depthUpdate", "E": 1780300130315, "s": "ETHUSDT", "U": 76583058044, "u": 76583058291, "b": [["1975.30000000", "82.38260000"], ["1975.29000000", "1.51100000"], ["1975.28000000", "0.00510000"], ["1975.27000000", "0.00540000"], ["1975.26000000", "3.00000000"], ["1975.25000000", "0.00000000"], ["1975.24000000", "0.14180000"], ["1975.23000000", "0.00000000"], ["1975.22000000", "0.00000000"], ["1975.20000000", "0.00260000"], ["1975.19000000", "0.00540000"], ["1975.18000000", "2.54350000"], ["1975.17000000", "6.46760000"], ["1975.12000000", "0.03000000"], ["1975.11000000", "0.00000000"], ["1975.10000000", "13.75590000"], ["1975.09000000", "6.36990000"], ["1975.08000000", "0.00260000"], ["1975.07000000", "22.68610000"], ["1975.06000000", "4.73300000"], ["1975.05000000", "0.64450000"], ["1975.03000000", "0.03300000"], ["1975.00000000", "21.51740000"], ["1974.99000000", "15.14800000"], ["1974.98000000", "0.00000000"], ["1974.97000000", "0.00000000"], ["1974.96000000", "0.03000000"], ["1974.90000000", "6.11410000"], ["1974.89000000", "0.00840000"], ["1974.81000000", "0.05880000"], ["1974.61000000", "0.00300000"], ["1974.58000000", "6.65570000"], ["1974.57000000", "0.10130000"], ["1974.38000000", "0.22370000"], ["1974.32000000", "9.73980000"], ["1974.30000000", "12.63650000"], ["1974.20000000", "11.15070000"], ["1974.01000000", "8.14170000"], ["1973.92000000", "8.50430000"], ["1970.09000000", "0.50440000"], ["1970.04000000", "0.00260000"], ["1969.21000000", "0.00300000"], ["1964.51000000", "0.00690000"], ["1935.79000000", "0.00000000"], ["1777.77000000", "13.12820000"], ["1777.59000000", "0.00000000"]], "a": [["1975.11000000", "0.00000000"], ["1975.12000000", "0.00000000"], ["1975.15000000", "0.00000000"], ["1975.16000000", "0.00000000"], ["1975.20000000", "0.00000000"], ["1975.25000000", "0.00000000"], ["1975.27000000", "0.00000000"], ["1975.28000000", "0.00000000"], ["1975.30000000", "0.00000000"], ["1975.31000000", "7.88800000"], ["1975.36000000", "0.00000000"], ["1975.38000000", "0.00840000"], ["1975.39000000", "1.27120000"], ["1975.41000000", "0.00000000"], ["1975.43000000", "7.46390000"], ["1975.44000000", "0.03260000"], ["1975.45000000", "0.05050000"], ["1975.46000000", "0.03840000"], ["1975.48000000", "0.00000000"], ["1975.49000000", "0.01460000"], ["1975.50000000", "2.29320000"], ["1975.54000000", "0.00650000"], ["1975.56000000", "0.00000000"], ["1975.57000000", "0.00000000"], ["1975.61000000", "0.05260000"], ["1975.71000000", "15.59680000"], ["1975.77000000", "1.50000000"], ["1975.95000000", "0.00760000"], ["1976.10000000", "1.40430000"], ["1976.20000000", "6.32200000"], ["1976.21000000", "12.27750000"], ["1976.33000000", "0.41360000"], ["1976.72000000", "11.67850000"], ["1976.79000000", "0.00260000"], ["1977.00000000", "5.00310000"], ["1977.03000000", "9.27090000"], ["1977.29000000", "7.57460000"], ["1977.37000000", "7.08860000"], ["1980.75000000", "0.00260000"]], "_local_ts_utc": "2026-06-01T07:48:49.211799+00:00"}
{"e": "depthUpdate", "E": 1780300130415, "s": "ETHUSDT", "U": 76583058292, "u": 76583058347, "b": [["1975.30000000", "82.38800000"], ["1975.29000000", "0.94940000"], ["1975.28000000", "0.00770000"], ["1975.27000000", "0.00800000"], ["1975.26000000", "3.00260000"], ["1975.24000000", "0.14440000"], ["1975.20000000", "0.00520000"], ["1975.19000000", "0.00800000"], ["1975.18000000", "8.95990000"], ["1975.17000000", "6.47020000"], ["1975.14000000", "0.00270000"], ["1975.13000000", "22.57370000"], ["1975.10000000", "13.75330000"], ["1975.09000000", "6.36730000"], ["1975.08000000", "0.00000000"], ["1975.07000000", "22.68350000"], ["1975.06000000", "4.73040000"], ["1975.05000000", "0.64190000"], ["1975.04000000", "0.03000000"], ["1975.00000000", "21.51480000"], ["1974.99000000", "15.14540000"], ["1974.80000000", "7.55990000"], ["1974.72000000", "22.88250000"], ["1974.59000000", "26.74430000"], ["1974.36000000", "0.17430000"], ["1974.33000000", "7.63080000"], ["1973.03000000", "0.80670000"], ["1972.35000000", "0.22640000"], ["1969.48000000", "0.00000000"], ["1969.39000000", "0.00630000"], ["1969.30000000", "0.00000000"], ["1777.77000000", "13.14060000"]], "a": [["1975.31000000", "8.64740000"], ["1975.39000000", "1.27380000"], ["1975.49000000", "0.00300000"], ["1975.50000000", "0.00570000"], ["1975.54000000", "0.00380000"], ["1975.55000000", "0.00260000"], ["1975.65000000", "4.22780000"], ["1975.66000000", "7.00540000"], ["1975.67000000", "0.00000000"], ["1975.76000000", "0.62400000"], ["1976.07000000", "0.00000000"], ["1977.33000000", "0.59400000"], ["1980.75000000", "0.00000000"]], "_local_ts_utc": "2026-06-01T07:48:49.311568+00:00"}
{"e": "depthUpdate", "E": 1780300130515, "s": "ETHUSDT", "U": 76583058348, "u": 76583058416, "b": [["1975.30000000", "45.03060000"], ["1975.29000000", "0.00770000"], ["1975.27000000", "0.00800000"], ["1975.18000000", "0.00800000"], ["1975.17000000", "6.47020000"], ["1975.14000000", "0.00540000"], ["1975.11000000", "0.00270000"], ["1975.10000000", "14.17680000"], ["1975.05000000", "0.00300000"], ["1974.91000000", "0.00000000"], ["1974.87000000", "17.15890000"], ["1974.86000000", "13.50590000"], ["1974.85000000", "0.00000000"], ["1974.83000000", "8.18670000"], ["1974.68000000", "0.27000000"], ["1974.50000000", "22.75300000"], ["1974.33000000", "7.73080000"], ["1974.18000000", "0.04850000"], ["1974.17000000", "7.19070000"], ["1973.89000000", "10.68950000"], ["1973.12000000", "0.07590000"], ["1972.44000000", "0.11860000"], ["1954.82000000", "1.53630000"], ["1777.77000000", "13.15300000"]], "a": [["1975.31000000", "24.86830000"], ["1975.35000000", "0.00260000"], ["1975.47000000", "26.76080000"], ["1975.51000000", "0.01420000"], ["1975.54000000", "0.00640000"], ["1975.66000000", "6.99380000"], ["1975.80000000", "0.57530000"], ["1976.30000000", "0.57270000"], ["1976.35000000", "2.82210000"], ["1976.47000000", "0.80000000"], ["1976.64000000", "0.03000000"], ["1976.68000000", "0.48600000"], ["1976.72000000", "11.64850000"], ["1977.80000000", "0.57310000"]], "_local_ts_utc": "2026-06-01T07:48:49.412397+00:00"}
{"e": "depthUpdate", "E": 1780300130615, "s": "ETHUSDT", "U": 76583058417, "u": 76583058448, "b": [["1975.24000000", "0.00260000"], ["1975.19000000", "0.00260000"], ["1975.15000000", "0.04540000"], ["1975.14000000", "7.77050000"], ["1975.11000000", "0.00540000"], ["1975.10000000", "13.75330000"], ["1974.94000000", "0.00300000"], ["1974.89000000", "0.01440000"], ["1974.29000000", "0.00380000"], ["1974.18000000", "0.84850000"], ["1973.89000000", "9.88950000"], ["1777.77000000", "13.16540000"]], "a": [["1975.31000000", "31.12130000"], ["1975.43000000", "7.47550000"], ["1975.53000000", "2.28440000"], ["1975.54000000", "6.47400000"], ["1975.65000000", "2.29380000"], ["1975.66000000", "0.52620000"], ["1975.75000000", "0.00000000"], ["1976.08000000", "0.03000000"], ["1976.64000000", "0.00000000"]], "_local_ts_utc": "2026-06-01T07:48:49.511524+00:00"}
{"e": "depthUpdate", "E": 1780300130715, "s": "ETHUSDT", "U": 76583058449, "u": 76583058493, "b": [["1975.28000000", "0.01310000"], ["1975.27000000", "0.90660000"], ["1975.20000000", "0.01060000"], ["1975.19000000", "0.51730000"], ["1975.17000000", "6.47020000"], ["1975.14000000", "7.76510000"], ["1975.11000000", "0.00000000"], ["1975.10000000", "16.62720000"], ["1975.03000000", "0.67740000"], ["1975.02000000", "0.77200000"], ["1974.91000000", "0.00260000"], ["1974.02000000", "8.88130000"], ["1969.18000000", "0.00000000"], ["1777.77000000", "13.17780000"]], "a": [["1975.31000000", "23.90640000"], ["1975.38000000", "0.00300000"], ["1975.39000000", "0.00260000"], ["1975.40000000", "0.00570000"], ["1975.43000000", "8.53940000"], ["1975.47000000", "26.74920000"], ["1975.52000000", "0.04300000"], ["1975.53000000", "2.28980000"], ["1975.55000000", "1.33230000"], ["1975.58000000", "0.64310000"], ["1975.65000000", "2.93120000"], ["1975.70000000", "9.16010000"], ["1977.30000000", "0.81000000"], ["1977.80000000", "0.00610000"], ["1979.72000000", "0.00000000"]], "_local_ts_utc": "2026-06-01T07:48:49.611969+00:00"}
{"e": "depthUpdate", "E": 1780300130815, "s": "ETHUSDT", "U": 76583058494, "u": 76583058528, "b": [["1975.30000000", "45.45690000"], ["1975.19000000", "0.52270000"], ["1975.18000000", "10.20620000"], ["1975.15000000", "0.04000000"], ["1975.01000000", "13.50210000"], ["1974.91000000", "0.02180000"], ["1974.88000000", "12.30500000"], ["1974.83000000", "6.07270000"], ["1974.32000000", "9.76040000"], ["1973.00000000", "13.49440000"], ["1971.76000000", "0.01280000"], ["1971.75000000", "0.79270000"], ["1777.77000000", "13.19020000"]], "a": [["1975.31000000", "10.30160000"], ["1975.51000000", "0.00260000"], ["1975.53000000", "2.27820000"], ["1975.55000000", "0.00260000"], ["1975.58000000", "0.00000000"], ["1975.86000000", "0.00760000"], ["1977.91000000", "0.02240000"], ["1978.33000000", "0.00000000"], ["1978.50000000", "0.02060000"], ["1978.92000000", "0.19350000"]], "_local_ts_utc": "2026-06-01T07:48:49.711514+00:00"}
{"e": "depthUpdate", "E": 1780300130915, "s": "ETHUSDT", "U": 76583058529, "u": 76583058554, "b": [["1975.24000000", "0.00520000"], ["1975.19000000", "14.33960000"], ["1975.14000000", "0.00000000"], ["1975.10000000", "21.04650000"], ["1975.06000000", "7.26420000"], ["1974.60000000", "17.44190000"], ["1974.51000000", "0.27000000"], ["1972.96000000", "0.01270000"], ["1972.78000000", "0.00260000"], ["1970.23000000", "36.59580000"], ["1900.00000000", "2701.26480000"], ["1777.77000000", "13.20260000"]], "a": [["1975.31000000", "8.78300000"], ["1975.63000000", "0.01420000"], ["1975.65000000", "2.94280000"], ["1975.80000000", "0.57810000"], ["1976.20000000", "6.31920000"], ["1977.01000000", "6.82300000"], ["1978.77000000", "4.51720000"], ["1980.15000000", "36.80890000"]], "_local_ts_utc": "2026-06-01T07:48:49.812531+00:00"}
{"e": "depthUpdate", "E": 1780300131015, "s": "ETHUSDT", "U": 76583058555, "u": 76583058570, "b": [["1975.22000000", "0.00540000"], ["1975.21000000", "0.51530000"], ["1975.19000000", "13.82490000"], ["1975.18000000", "10.20080000"], ["1974.81000000", "0.06160000"], ["1974.78000000", "0.27260000"], ["1974.34000000", "7.09450000"], ["1969.81000000", "0.58070000"], ["1969.19000000", "0.03310000"], ["1777.77000000", "13.21500000"]], "a": [["1975.33000000", "0.00260000"], ["1975.61000000", "0.06420000"], ["1975.69000000", "0.00520000"], ["1975.72000000", "0.94500000"], ["1976.01000000", "1.00020000"]], "_local_ts_utc": "2026-06-01T07:48:49.914720+00:00"}
{"e": "depthUpdate", "E": 1780300131115, "s": "ETHUSDT", "U": 76583058571, "u": 76583058603, "b": [["1975.24000000", "0.00520000"], ["1975.22000000", "0.00800000"], ["1975.21000000", "0.51790000"], ["1975.18000000", "10.19820000"], ["1975.17000000", "6.97450000"], ["1974.70000000", "0.32570000"], ["1974.68000000", "0.54000000"], ["1970.72000000", "0.66280000"], ["1970.44000000", "0.50000000"], ["1777.77000000", "13.22740000"]], "a": [["1975.31000000", "8.77970000"], ["1975.52000000", "0.03760000"], ["1975.53000000", "0.00000000"], ["1975.54000000", "0.00640000"], ["1975.58000000", "0.72140000"], ["1975.59000000", "1.27940000"], ["1975.65000000", "5.10940000"], ["1975.66000000", "6.99380000"], ["1975.80000000", "1.33410000"], ["1975.82000000", "12.84670000"], ["1975.87000000", "0.02000000"]], "_local_ts_utc": "2026-06-01T07:48:50.011502+00:00"}
{"e": "depthUpdate", "E": 1780300131215, "s": "ETHUSDT", "U": 76583058604, "u": 76583058670, "b": [["1975.30000000", "54.79460000"], ["1975.28000000", "0.00770000"], ["1975.27000000", "0.00800000"], ["1975.22000000", "4.39860000"], ["1975.21000000", "0.52330000"], ["1975.20000000", "14.18560000"], ["1975.19000000", "13.82220000"], ["1975.17000000", "6.46760000"], ["1975.02000000", "14.27200000"], ["1975.01000000", "0.00000000"], ["1975.00000000", "21.56480000"], ["1974.91000000", "0.00260000"], ["1974.88000000", "0.03000000"], ["1974.81000000", "12.33750000"], ["1974.46000000", "0.00380000"], ["1974.32000000", "9.73980000"], ["1973.45000000", "3.82220000"], ["1973.40000000", "5.91750000"], ["1973.31000000", "0.35950000"], ["1960.93000000", "0.07870000"], ["1777.77000000", "13.23980000"]], "a": [["1975.31000000", "23.16030000"], ["1975.37000000", "0.00000000"], ["1975.41000000", "0.01160000"], ["1975.51000000", "0.01420000"], ["1975.65000000", "5.72500000"], ["1975.91000000", "0.05000000"], ["1976.09000000", "0.04790000"], ["1976.11000000", "0.63970000"], ["1977.91000000", "0.00300000"], ["1978.48000000", "0.01930000"], ["1978.50000000", "0.00000000"], ["1979.07000000", "0.02060000"]], "_local_ts_utc": "2026-06-01T07:48:50.113555+00:00"}
{"e": "depthUpdate", "E": 1780300131315, "s": "ETHUSDT", "U": 76583058671, "u": 76583058701, "b": [["1975.30000000", "52.36070000"], ["1975.23000000", "0.00540000"], ["1975.19000000", "13.81950000"], ["1974.81000000", "12.33750000"], ["1974.80000000", "7.05990000"], ["1974.76000000", "0.81000000"], ["1974.69000000", "0.47910000"], ["1972.86000000", "0.03850000"], ["1972.78000000", "0.27260000"], ["1971.08000000", "1.20820000"], ["1777.77000000", "13.25220000"]], "a": [["1975.31000000", "23.22930000"], ["1975.46000000", "0.03300000"], ["1975.61000000", "0.06420000"], ["1975.74000000", "1.16740000"], ["1975.75000000", "0.43200000"], ["1975.81000000", "0.48600000"], ["1981.24000000", "0.23000000"], ["1982.62000000", "0.00000000"]], "_local_ts_utc": "2026-06-01T07:48:50.211195+00:00"}
{"e": "depthUpdate", "E": 1780300131415, "s": "ETHUSDT", "U": 76583058702, "u": 76583058780, "b": [["1975.30000000", "13.11670000"], ["1975.29000000", "0.01550000"], ["1975.24000000", "10.14320000"], ["1975.23000000", "0.00260000"], ["1975.22000000", "0.00800000"], ["1975.21000000", "0.51790000"], ["1975.20000000", "0.01060000"], ["1975.19000000", "0.00540000"], ["1975.18000000", "0.00270000"], ["1975.14000000", "0.00000000"], ["1975.13000000", "0.00000000"], ["1975.11000000", "10.19900000"], ["1975.07000000", "0.00000000"], ["1975.06000000", "5.94880000"], ["1975.03000000", "0.03300000"], ["1975.02000000", "0.77200000"], ["1974.76000000", "1.08000000"], ["1974.33000000", "7.33080000"], ["1974.32000000", "8.53430000"], ["1974.25000000", "1.74550000"], ["1974.18000000", "0.84850000"], ["1973.89000000", "9.88950000"], ["1973.45000000", "10.90970000"], ["1973.35000000", "7.10750000"], ["1973.31000000", "7.44700000"], ["1972.78000000", "0.00260000"], ["1964.51000000", "1.33290000"], ["1900.00000000", "2701.26180000"], ["1777.77000000", "13.26460000"]], "a": [["1975.31000000", "31.10120000"], ["1975.39000000", "0.01420000"], ["1975.52000000", "1.24310000"], ["1975.53000000", "6.46760000"], ["1975.63000000", "0.00260000"], ["1975.66000000", "0.52620000"], ["1975.75000000", "0.86400000"], ["1975.77000000", "1.51010000"], ["1976.04000000", "13.50190000"], ["1976.14000000", "1.00660000"], ["1976.53000000", "0.03990000"], ["1977.22000000", "1.38810000"]], "_local_ts_utc": "2026-06-01T07:48:50.312839+00:00"}
{"e": "depthUpdate", "E": 1780300131515, "s": "ETHUSDT", "U": 76583058781, "u": 76583059450, "b": [["1975.30000000", "0.00000000"], ["1975.29000000", "0.00000000"], ["1975.28000000", "0.00000000"], ["1975.27000000", "0.00000000"], ["1975.26000000", "0.00000000"], ["1975.25000000", "0.00000000"], ["1975.24000000", "0.00000000"], ["1975.23000000", "0.00000000"], ["1975.22000000", "0.00000000"], ["1975.21000000", "0.00000000"], ["1975.20000000", "0.00000000"], ["1975.19000000", "0.00000000"], ["1975.18000000", "0.00000000"], ["1975.17000000", "0.00000000"], ["1975.15000000", "0.00000000"], ["1975.14000000", "0.00000000"], ["1975.12000000", "0.00000000"], ["1975.11000000", "0.00000000"], ["1975.10000000", "0.00000000"], ["1975.09000000", "0.00000000"], ["1975.07000000", "0.00000000"], ["1975.06000000", "5.08370000"], ["1975.05000000", "0.01340000"], ["1975.04000000", "0.00260000"], ["1975.03000000", "0.04100000"], ["1975.02000000", "0.77460000"], ["1975.01000000", "0.00000000"], ["1975.00000000", "0.05520000"], ["1974.99000000", "0.00260000"], ["1974.96000000", "0.00260000"], ["1974.95000000", "0.00800000"], ["1974.94000000", "10.14520000"], ["1974.93000000", "0.00000000"], ["1974.91000000", "0.00260000"], ["1974.90000000", "0.00520000"], ["1974.89000000", "0.01980000"], ["1974.88000000", "0.03540000"], ["1974.87000000", "0.00000000"], ["1974.86000000", "0.00380000"], ["1974.84000000", "0.00530000"], ["1974.83000000", "12.54030000"], ["1974.81000000", "0.06160000"], ["1974.80000000", "2.65290000"], ["1974.78000000", "0.00260000"], ["1974.76000000", "0.00000000"], ["1974.75000000", "17.62020000"], ["1974.74000000", "1.19530000"], ["1974.73000000", "22.71000000"], ["1974.72000000", "22.61250000"], ["1974.70000000", "0.05570000"], ["1974.69000000", "0.20910000"], ["1974.68000000", "0.00000000"], ["1974.67000000", "7.64570000"], ["1974.66000000", "0.01620000"], ["1974.65000000", "0.01520000"], ["1974.64000000", "0.14480000"], ["1974.60000000", "17.06380000"], ["1974.57000000", "0.00000000"], ["1974.51000000", "0.27000000"], ["1974.49000000", "17.16960000"], ["1974.40000000", "10.22610000"], ["1974.38000000", "0.05320000"], ["1974.35000000", "12.31490000"], ["1974.33000000", "7.23080000"], ["1974.31000000", "13.53050000"], ["1974.30000000", "12.63910000"], ["1974.28000000", "0.03290000"], ["1974.25000000", "1.34550000"], ["1974.24000000", "8.65650000"], ["1974.22000000", "8.51170000"], ["1974.20000000", "11.15330000"], ["1974.19000000", "0.00520000"], ["1974.18000000", "0.64850000"], ["1974.15000000", "16.54430000"], ["1974.10000000", "19.91850000"], ["1974.07000000", "24.08390000"], ["1974.04000000", "0.10000000"], ["1974.00000000", "13.09580000"], ["1973.84000000", "8.52860000"], ["1973.82000000", "1.11370000"], ["1973.76000000", "0.03000000"], ["1973.72000000", "8.78630000"], ["1973.68000000", "0.03940000"], ["1973.60000000", "0.09290000"], ["1973.52000000", "9.90930000"], ["1973.40000000", "8.34730000"], ["1973.33000000", "1.68040000"], ["1973.32000000", "8.69300000"], ["1973.15000000", "20.61990000"], ["1973.11000000", "7.10320000"], ["1972.95000000", "7.08750000"], ["1972.94000000", "7.09010000"], ["1972.92000000", "10.59800000"], ["1972.81000000", "16.44750000"], ["1972.75000000", "2.23570000"], ["1972.74000000", "7.09050000"], ["1971.76000000", "4.28850000"], ["1971.75000000", "14.29270000"], ["1969.50000000", "0.25640000"], ["1969.41000000", "0.04250000"], ["1965.36000000", "0.00000000"], ["1965.14000000", "0.06860000"], ["1954.82000000", "0.02080000"], ["1935.61000000", "0.00000000"], ["1777.77000000", "13.11580000"], ["1777.61000000", "0.00000000"], ["1777.56000000", "0.00620000"], ["1475.12000000", "0.01200000"]], "a": [["1975.07000000", "38.31710000"], ["1975.08000000", "0.00510000"], ["1975.09000000", "0.00510000"], ["1975.10000000", "0.00570000"], ["1975.11000000", "0.00000000"], ["1975.12000000", "11.75850000"], ["1975.13000000", "5.64820000"], ["1975.14000000", "0.01160000"], ["1975.15000000", "0.01020000"], ["1975.17000000", "0.00000000"], ["1975.18000000", "0.00000000"], ["1975.19000000", "0.00000000"], ["1975.20000000", "0.03570000"], ["1975.21000000", "0.00000000"], ["1975.22000000", "0.00000000"], ["1975.23000000", "0.00000000"], ["1975.24000000", "0.00000000"], ["1975.25000000", "0.00000000"], ["1975.26000000", "0.00000000"], ["1975.27000000", "4.19100000"], ["1975.28000000", "0.03000000"], ["1975.29000000", "22.68000000"], ["1975.30000000", "15.23700000"], ["1975.31000000", "2.28750000"], ["1975.32000000", "0.00000000"], ["1975.33000000", "0.00260000"], ["1975.34000000", "0.00380000"], ["1975.36000000", "0.03260000"], ["1975.39000000", "0.00000000"], ["1975.41000000", "0.00000000"], ["1975.42000000", "8.50500000"], ["1975.43000000", "12.76220000"], ["1975.46000000", "14.20800000"], ["1975.48000000", "1.29910000"], ["1975.50000000", "0.65210000"], ["1975.51000000", "0.00260000"], ["1975.52000000", "6.47260000"], ["1975.53000000", "0.00000000"], ["1975.54000000", "0.64430000"], ["1975.56000000", "0.20000000"], ["1975.58000000", "8.50500000"], ["1975.59000000", "8.36690000"], ["1975.61000000", "0.05260000"], ["1975.64000000", "13.50000000"], ["1975.65000000", "4.08770000"], ["1975.66000000", "0.09110000"], ["1975.70000000", "11.39930000"], ["1975.77000000", "1.31010000"], ["1975.78000000", "3.60260000"], ["1975.79000000", "0.01020000"], ["1975.86000000", "0.10760000"], ["1975.90000000", "23.06190000"], ["1975.99000000", "0.00000000"], ["1976.05000000", "29.77430000"], ["1976.10000000", "0.00310000"], ["1976.11000000", "0.50330000"], ["1976.12000000", "0.00000000"], ["1976.20000000", "6.31660000"], ["1976.25000000", "1.40000000"], ["1976.32000000", "8.19160000"], ["1976.33000000", "0.03550000"], ["1976.35000000", "1.35540000"], ["1976.40000000", "3.57590000"], ["1976.47000000", "0.00000000"], ["1976.48000000", "0.00300000"], ["1976.53000000", "0.00000000"], ["1976.54000000", "7.11970000"], ["1976.56000000", "0.00000000"], ["1976.67000000", "0.15110000"], ["1976.79000000", "0.00260000"], ["1976.80000000", "10.62180000"], ["1976.85000000", "0.56700000"], ["1976.99000000", "0.00000000"], ["1977.01000000", "0.00000000"], ["1977.03000000", "0.76460000"], ["1977.07000000", "1.21570000"], ["1977.15000000", "0.00000000"], ["1977.21000000", "0.01000000"], ["1977.29000000", "0.48600000"], ["1977.37000000", "0.00000000"], ["1977.97000000", "0.00000000"], ["1977.98000000", "0.00000000"], ["1977.99000000", "0.00000000"], ["1979.08000000", "0.50180000"], ["1979.27000000", "0.00000000"], ["1979.49000000", "0.18990000"], ["1979.78000000", "1.80310000"], ["1980.31000000", "0.13110000"], ["1984.36000000", "0.49390000"]], "_local_ts_utc": "2026-06-01T07:48:50.411371+00:00"}
{"e": "depthUpdate", "E": 1780300131615, "s": "ETHUSDT", "U": 76583059451, "u": 76583059583, "b": [["1975.06000000", "12.72510000"], ["1974.95000000", "0.00260000"], ["1974.94000000", "0.00560000"], ["1974.93000000", "0.00540000"], ["1974.92000000", "10.13970000"], ["1974.89000000", "0.01440000"], ["1974.88000000", "0.00000000"], ["1974.84000000", "0.00800000"], ["1974.83000000", "6.07810000"], ["1974.81000000", "0.06430000"], ["1974.80000000", "2.00910000"], ["1974.75000000", "7.41990000"], ["1974.73000000", "0.03000000"], ["1974.69000000", "12.15420000"], ["1974.68000000", "10.20090000"], ["1974.67000000", "0.01130000"], ["1974.65000000", "7.76390000"], ["1974.60000000", "17.06380000"], ["1974.59000000", "27.37590000"], ["1974.51000000", "13.77000000"], ["1974.49000000", "13.81240000"], ["1974.48000000", "0.35240000"], ["1974.41000000", "0.10130000"], ["1974.37000000", "0.00000000"], ["1974.15000000", "13.50150000"], ["1974.14000000", "3.22210000"], ["1974.07000000", "22.58390000"], ["1974.06000000", "0.37050000"], ["1974.05000000", "7.86000000"], ["1973.76000000", "0.28870000"], ["1973.52000000", "9.93930000"], ["1973.44000000", "8.54980000"], ["1973.42000000", "8.51010000"], ["1973.32000000", "0.18800000"], ["1971.47000000", "13.50000000"], ["1954.72000000", "1.49600000"], ["1935.55000000", "0.03630000"], ["1777.56000000", "0.01860000"]], "a": [["1975.07000000", "47.20270000"], ["1975.09000000", "0.00770000"], ["1975.10000000", "0.01110000"], ["1975.11000000", "3.87580000"], ["1975.12000000", "0.03540000"], ["1975.13000000", "12.89120000"], ["1975.27000000", "10.79140000"], ["1975.30000000", "9.13950000"], ["1975.31000000", "1.68630000"], ["1975.33000000", "0.00000000"], ["1975.35000000", "0.00000000"], ["1975.40000000", "19.72910000"], ["1975.41000000", "13.50000000"], ["1975.43000000", "1.07550000"], ["1975.48000000", "0.00000000"], ["1975.54000000", "0.00640000"], ["1975.59000000", "7.08750000"], ["1975.65000000", "3.46050000"], ["1975.98000000", "2.03470000"], ["1976.25000000", "2.86430000"], ["1976.61000000", "2.41580000"], ["1977.05000000", "0.51300000"], ["1977.07000000", "1.67470000"], ["1977.37000000", "31.64750000"], ["1977.70000000", "0.00000000"], ["1977.77000000", "0.94500000"], ["1979.93000000", "31.74030000"], ["1980.15000000", "36.81150000"], ["1980.58000000", "1.20550000"], ["1980.64000000", "1.19570000"]], "_local_ts_utc": "2026-06-01T07:48:50.510837+00:00"}
{"e": "depthUpdate", "E": 1780300131715, "s": "ETHUSDT", "U": 76583059584, "u": 76583059628, "b": [["1975.06000000", "16.41530000"], ["1975.05000000", "0.01340000"], ["1974.94000000", "0.00560000"], ["1974.91000000", "0.00000000"], ["1974.89000000", "0.00840000"], ["1974.85000000", "0.00540000"], ["1974.84000000", "4.71150000"], ["1974.81000000", "0.06160000"], ["1974.76000000", "0.50640000"], ["1974.02000000", "8.83100000"], ["1973.92000000", "8.53430000"], ["1973.44000000", "8.51980000"], ["1972.54000000", "54.91700000"], ["1954.72000000", "0.00000000"], ["1777.56000000", "0.03100000"]], "a": [["1975.13000000", "5.65360000"], ["1975.14000000", "6.47920000"], ["1975.26000000", "1.30740000"], ["1975.29000000", "26.88500000"], ["1975.39000000", "0.50630000"], ["1975.65000000", "0.63740000"], ["1975.70000000", "7.22030000"], ["1976.18000000", "1.29050000"], ["1976.21000000", "12.10700000"], ["1976.25000000", "1.40000000"], ["1976.57000000", "0.46420000"], ["1980.52000000", "0.00000000"]], "_local_ts_utc": "2026-06-01T07:48:50.611498+00:00"}
{"e": "depthUpdate", "E": 1780300131815, "s": "ETHUSDT", "U": 76583059629, "u": 76583059639, "b": [["1975.06000000", "16.41530000"], ["1974.77000000", "6.52260000"], ["1974.65000000", "1.29630000"], ["1973.59000000", "2.75340000"], ["1777.56000000", "0.04340000"]], "a": [["1975.07000000", "55.19100000"]], "_local_ts_utc": "2026-06-01T07:48:50.712513+00:00"}
{"e": "depthUpdate", "E": 1780300131915, "s": "ETHUSDT", "U": 76583059640, "u": 76583059664, "b": [["1975.06000000", "9.55230000"], ["1974.97000000", "0.00540000"], ["1974.96000000", "10.14210000"], ["1974.93000000", "0.00000000"], ["1974.92000000", "0.00000000"], ["1974.67000000", "0.01390000"], ["1974.04000000", "0.27050000"], ["1973.78000000", "0.05290000"], ["1973.58000000", "7.22980000"], ["1777.56000000", "0.04960000"]], "a": [["1975.11000000", "1.71530000"], ["1975.13000000", "5.64820000"], ["1975.14000000", "0.01160000"], ["1975.25000000", "6.46760000"], ["1975.63000000", "6.19700000"], ["1975.65000000", "0.00000000"], ["1976.06000000", "0.00260000"], ["1976.15000000", "0.00560000"], ["1977.05000000", "3.16600000"]], "_local_ts_utc": "2026-06-01T07:48:50.810501+00:00"}
{"e": "depthUpdate", "E": 1780300132015, "s": "ETHUSDT", "U": 76583059665, "u": 76583059708, "b": [["1975.06000000", "1.69320000"], ["1975.05000000", "0.01340000"], ["1974.99000000", "0.00260000"], ["1974.97000000", "0.00260000"], ["1974.96000000", "0.00260000"], ["1974.94000000", "0.00300000"], ["1974.92000000", "0.00540000"], ["1974.91000000", "10.13970000"], ["1974.85000000", "0.00000000"], ["1974.84000000", "0.00800000"], ["1974.81000000", "0.06430000"], ["1974.65000000", "0.01520000"], ["1974.59000000", "26.74430000"], ["1974.52000000", "13.57690000"], ["1974.51000000", "0.27000000"], ["1974.04000000", "0.10000000"], ["1973.93000000", "2.12680000"], ["1969.81000000", "0.00000000"], ["1969.65000000", "4.29590000"], ["1777.56000000", "0.05580000"], ["1475.12000000", "0.00000000"], ["1192.00000000", "0.00000000"]], "a": [["1975.07000000", "55.15050000"], ["1975.52000000", "6.95860000"], ["1977.29000000", "0.97200000"]], "_local_ts_utc": "2026-06-01T07:48:50.910671+00:00"}
{"e": "depthUpdate", "E": 1780300132115, "s": "ETHUSDT", "U": 76583059709, "u": 76583059784, "b": [["1975.06000000", "0.00000000"], ["1975.05000000", "0.00000000"], ["1975.04000000", "0.00000000"], ["1975.03000000", "0.00000000"], ["1975.02000000", "0.55370000"], ["1974.91000000", "0.00000000"], ["1974.86000000", "10.14380000"], ["1974.79000000", "7.32770000"], ["1974.78000000", "10.20310000"], ["1974.76000000", "3.04020000"], ["1974.75000000", "0.12650000"], ["1974.72000000", "0.03880000"], ["1974.69000000", "7.56440000"], ["1974.68000000", "0.00000000"], ["1974.63000000", "0.34120000"], ["1974.62000000", "1.28970000"], ["1974.61000000", "0.50990000"], ["1974.58000000", "7.29580000"], ["1974.52000000", "0.07690000"], ["1974.06000000", "0.07050000"], ["1974.05000000", "6.66000000"], ["1974.04000000", "0.00000000"], ["1974.03000000", "0.72020000"], ["1973.92000000", "9.33430000"], ["1973.87000000", "0.54000000"], ["1973.78000000", "0.15290000"], ["1973.22000000", "10.05820000"], ["1972.81000000", "16.17750000"], ["1972.75000000", "9.32400000"], ["1972.61000000", "7.09090000"], ["1777.56000000", "0.06820000"]], "a": [["1975.03000000", "28.26570000"], ["1975.04000000", "4.00000000"], ["1975.05000000", "4.00000000"], ["1975.06000000", "4.00000000"], ["1975.07000000", "55.15600000"], ["1975.12000000", "0.03000000"], ["1975.17000000", "14.17660000"], ["1975.19000000", "1.28080000"], ["1975.28000000", "1.23550000"], ["1975.58000000", "9.07200000"], ["1976.36000000", "8.50860000"], ["1976.44000000", "0.00260000"], ["1976.73000000", "7.08690000"], ["1976.95000000", "3.60260000"], ["1977.29000000", "0.48600000"], ["1977.35000000", "0.56700000"], ["1980.07000000", "0.03830000"], ["1980.31000000", "0.13380000"]], "_local_ts_utc": "2026-06-01T07:48:51.011173+00:00"}
{"e": "depthUpdate", "E": 1780300132215, "s": "ETHUSDT", "U": 76583059785, "u": 76583060210, "b": [["1975.02000000", "0.00000000"], ["1975.00000000", "0.00000000"], ["1974.99000000", "0.00000000"], ["1974.97000000", "0.00000000"], ["1974.96000000", "0.00000000"], ["1974.95000000", "0.00000000"], ["1974.94000000", "0.00000000"], ["1974.92000000", "0.00000000"], ["1974.90000000", "0.00000000"], ["1974.89000000", "0.00000000"], ["1974.86000000", "23.25480000"], ["1974.85000000", "0.01290000"], ["1974.84000000", "0.01310000"], ["1974.83000000", "6.06790000"], ["1974.82000000", "7.60820000"], ["1974.81000000", "0.06420000"], ["1974.80000000", "2.01170000"], ["1974.79000000", "0.01750000"], ["1974.78000000", "0.00260000"], ["1974.77000000", "0.06300000"], ["1974.76000000", "2.53640000"], ["1974.75000000", "0.12920000"], ["1974.70000000", "0.05260000"], ["1974.69000000", "0.20910000"], ["1974.67000000", "6.06320000"], ["1974.66000000", "6.47420000"], ["1974.62000000", "0.00000000"], ["1974.61000000", "10.20400000"], ["1974.60000000", "8.35230000"], ["1974.58000000", "0.02480000"], ["1974.56000000", "0.55190000"], ["1974.55000000", "1.33080000"], ["1974.51000000", "0.00000000"], ["1974.50000000", "0.07490000"], ["1974.49000000", "17.54480000"], ["1974.48000000", "0.08240000"], ["1974.45000000", "7.09090000"], ["1974.43000000", "7.09230000"], ["1974.42000000", "8.69420000"], ["1974.41000000", "0.00000000"], ["1974.40000000", "8.89530000"], ["1974.37000000", "0.00540000"], ["1974.35000000", "0.03730000"], ["1974.34000000", "7.09590000"], ["1974.31000000", "0.03160000"], ["1974.30000000", "21.74870000"], ["1974.28000000", "12.31130000"], ["1974.25000000", "1.35520000"], ["1974.24000000", "22.15810000"], ["1974.22000000", "15.14520000"], ["1974.18000000", "0.04850000"], ["1974.17000000", "7.19070000"], ["1974.16000000", "0.06920000"], ["1974.15000000", "0.00260000"], ["1974.14000000", "0.17940000"], ["1974.12000000", "8.52150000"], ["1974.08000000", "15.05320000"], ["1974.04000000", "0.20000000"], ["1974.03000000", "0.02020000"], ["1974.00000000", "12.29570000"], ["1973.96000000", "0.60080000"], ["1973.94000000", "13.77710000"], ["1973.93000000", "2.82680000"], ["1973.90000000", "19.22610000"], ["1973.88000000", "0.76520000"], ["1973.73000000", "0.03600000"], ["1973.70000000", "12.00950000"], ["1973.66000000", "14.61080000"], ["1973.59000000", "0.12230000"], ["1973.22000000", "9.04600000"], ["1973.02000000", "8.50600000"], ["1972.76000000", "0.00550000"], ["1972.63000000", "7.27330000"], ["1972.54000000", "0.00410000"], ["1972.43000000", "1.05680000"], ["1972.41000000", "7.19230000"], ["1972.19000000", "0.00300000"], ["1971.20000000", "5.49770000"], ["1971.19000000", "13.51440000"], ["1970.98000000", "13.50420000"], ["1970.82000000", "0.00710000"], ["1970.00000000", "410.36310000"], ["1969.33000000", "0.05980000"], ["1969.24000000", "0.03170000"], ["1967.66000000", "0.02710000"], ["1967.34000000", "0.00920000"], ["1967.05000000", "3.60710000"], ["1935.51000000", "0.00000000"], ["1935.36000000", "0.03920000"], ["1777.56000000", "0.00000000"], ["1777.38000000", "0.01240000"]], "a": [["1974.87000000", "56.87400000"], ["1974.88000000", "0.00510000"], ["1974.89000000", "0.00510000"], ["1974.90000000", "0.00260000"], ["1974.92000000", "0.00000000"], ["1974.93000000", "0.01160000"], ["1974.95000000", "0.01160000"], ["1974.96000000", "0.03260000"], ["1974.97000000", "0.00000000"], ["1974.98000000", "0.00000000"], ["1975.00000000", "0.01110000"], ["1975.01000000", "6.76450000"], ["1975.02000000", "0.00000000"], ["1975.03000000", "9.97820000"], ["1975.04000000", "0.03000000"], ["1975.05000000", "14.17660000"], ["1975.06000000", "0.00000000"], ["1975.07000000", "2.53040000"], ["1975.08000000", "0.00000000"], ["1975.09000000", "0.00000000"], ["1975.10000000", "0.00570000"], ["1975.11000000", "10.16810000"], ["1975.13000000", "12.11580000"], ["1975.14000000", "0.00380000"], ["1975.16000000", "8.50600000"], ["1975.17000000", "14.17920000"], ["1975.19000000", "1.78970000"], ["1975.25000000", "0.03300000"], ["1975.26000000", "0.00000000"], ["1975.27000000", "10.79440000"], ["1975.28000000", "0.03000000"], ["1975.29000000", "28.38500000"], ["1975.30000000", "6.13950000"], ["1975.31000000", "1.67470000"], ["1975.33000000", "0.05000000"], ["1975.36000000", "0.03260000"], ["1975.39000000", "0.00000000"], ["1975.56000000", "0.00000000"], ["1975.61000000", "0.05000000"], ["1975.69000000", "0.00260000"], ["1975.77000000", "0.01010000"], ["1975.90000000", "23.05930000"], ["1975.91000000", "0.00000000"], ["1976.00000000", "14.17010000"], ["1976.16000000", "0.00000000"], ["1976.21000000", "3.60000000"], ["1976.24000000", "0.01270000"], ["1976.26000000", "0.00300000"], ["1976.36000000", "0.00260000"], ["1976.40000000", "1.33800000"], ["1976.51000000", "14.35460000"], ["1976.52000000", "7.08910000"], ["1976.71000000", "0.00000000"], ["1976.72000000", "0.00000000"], ["1976.73000000", "0.00000000"], ["1977.35000000", "0.00000000"], ["1978.31000000", "0.00000000"], ["1978.77000000", "0.00000000"], ["1980.00000000", "8.27750000"], ["1980.07000000", "0.03290000"], ["1980.15000000", "36.80890000"], ["1980.31000000", "0.13110000"], ["1988.00000000", "0.12030000"]], "_local_ts_utc": "2026-06-01T07:48:51.113508+00:00"}
{"e": "depthUpdate", "E": 1780300132315, "s": "ETHUSDT", "U": 76583060211, "u": 76583060263, "b": [["1974.86000000", "24.35210000"], ["1974.85000000", "0.01550000"], ["1974.76000000", "2.53380000"], ["1974.72000000", "0.00880000"], ["1974.53000000", "0.62720000"], ["1974.08000000", "15.05320000"], ["1973.99000000", "0.13150000"], ["1973.78000000", "0.05290000"], ["1973.36000000", "0.30530000"], ["1973.00000000", "8.49440000"], ["1969.15000000", "127.12090000"], ["1969.06000000", "0.00300000"], ["1777.38000000", "0.02480000"]], "a": [["1974.87000000", "64.27090000"], ["1975.00000000", "0.01110000"], ["1975.01000000", "4.75480000"], ["1975.03000000", "8.52020000"], ["1975.05000000", "15.48760000"], ["1975.07000000", "1.78630000"], ["1975.09000000", "0.34000000"], ["1975.19000000", "0.50890000"], ["1975.30000000", "5.49960000"], ["1978.31000000", "0.61850000"], ["1980.37000000", "0.16050000"], ["1980.43000000", "0.03290000"]], "_local_ts_utc": "2026-06-01T07:48:51.211245+00:00"}
{"e": "depthUpdate", "E": 1780300132415, "s": "ETHUSDT", "U": 76583060264, "u": 76583060294, "b": [["1974.86000000", "24.39570000"], ["1974.85000000", "10.15550000"], ["1974.78000000", "0.00800000"], ["1974.77000000", "0.06300000"], ["1974.75000000", "0.12650000"], ["1974.67000000", "5.08740000"], ["1974.50000000", "0.08680000"], ["1974.26000000", "2.06850000"], ["1973.93000000", "2.55680000"], ["1972.84000000", "0.27000000"], ["1960.00000000", "403.67970000"], ["1777.38000000", "0.03100000"]], "a": [["1974.87000000", "64.26050000"], ["1974.93000000", "0.00000000"], ["1975.02000000", "0.00540000"], ["1975.05000000", "14.17660000"], ["1975.11000000", "10.79090000"], ["1975.36000000", "0.62940000"], ["1975.80000000", "1.33130000"], ["1977.33000000", "0.00000000"], ["1977.68000000", "0.00000000"], ["1978.21000000", "0.01940000"], ["1978.48000000", "0.00000000"], ["1978.80000000", "0.02360000"], ["1979.07000000", "0.00000000"], ["1979.33000000", "0.79320000"], ["1980.44000000", "1.34410000"]], "_local_ts_utc": "2026-06-01T07:48:51.311832+00:00"}
{"e": "depthUpdate", "E": 1780300132515, "s": "ETHUSDT", "U": 76583060295, "u": 76583060327, "b": [["1974.86000000", "29.68180000"], ["1974.85000000", "10.15810000"], ["1974.78000000", "0.00260000"], ["1974.21000000", "0.63260000"], ["1973.71000000", "3.79890000"], ["1973.44000000", "8.54980000"], ["1973.36000000", "0.27530000"], ["1972.86000000", "0.00850000"], ["1972.80000000", "0.28610000"], ["1972.66000000", "0.30920000"], ["1777.38000000", "0.04340000"]], "a": [["1974.87000000", "49.40210000"], ["1975.02000000", "0.00000000"], ["1975.03000000", "0.01420000"], ["1975.04000000", "0.03000000"], ["1975.16000000", "8.50900000"], ["1975.38000000", "0.57000000"], ["1976.26000000", "8.50900000"], ["1981.04000000", "0.03000000"], ["1981.24000000", "0.20000000"]], "_local_ts_utc": "2026-06-01T07:48:51.410822+00:00"}
{"e": "depthUpdate", "E": 1780300132615, "s": "ETHUSDT", "U": 76583060328, "u": 76583060343, "b": [["1974.26000000", "5.66850000"], ["1973.89000000", "9.61950000"], ["1954.39000000", "1.50210000"], ["1850.00000000", "1248.81610000"], ["1777.38000000", "0.05580000"]], "a": [["1974.87000000", "40.03450000"], ["1974.95000000", "0.00000000"], ["1975.04000000", "0.03540000"], ["1975.06000000", "0.00540000"], ["1975.09000000", "0.00000000"], ["1975.11000000", "10.16810000"], ["1975.91000000", "1.48160000"]], "_local_ts_utc": "2026-06-01T07:48:51.511227+00:00"}
{"e": "depthUpdate", "E": 1780300132715, "s": "ETHUSDT", "U": 76583060344, "u": 76583060581, "b": [["1974.86000000", "41.46340000"], ["1974.85000000", "19.31520000"], ["1974.84000000", "0.01310000"], ["1974.81000000", "0.05880000"], ["1974.79000000", "0.02020000"], ["1974.78000000", "3.42140000"], ["1974.77000000", "6.52520000"], ["1974.68000000", "0.00000000"], ["1974.67000000", "8.47800000"], ["1974.66000000", "0.00660000"], ["1974.65000000", "0.01520000"], ["1974.64000000", "0.14480000"], ["1974.63000000", "15.93550000"], ["1974.62000000", "0.00000000"], ["1974.61000000", "0.00300000"], ["1974.60000000", "12.53600000"], ["1974.58000000", "0.64760000"], ["1974.55000000", "8.41910000"], ["1974.53000000", "16.22150000"], ["1974.38000000", "13.55480000"], ["1974.26000000", "5.86850000"], ["1974.11000000", "3.07830000"], ["1974.04000000", "0.00000000"], ["1973.96000000", "0.60080000"], ["1973.84000000", "8.55860000"], ["1973.75000000", "9.49330000"], ["1973.70000000", "11.20950000"], ["1973.44000000", "8.51980000"], ["1973.22000000", "0.54000000"], ["1973.02000000", "0.00000000"], ["1972.76000000", "7.09380000"], ["1972.75000000", "0.01260000"], ["1972.74000000", "0.00300000"], ["1972.63000000", "0.18500000"], ["1972.61000000", "0.00260000"], ["1972.41000000", "0.10400000"], ["1971.20000000", "1.25790000"], ["1971.19000000", "0.01280000"], ["1970.98000000", "0.00260000"], ["1965.09000000", "0.53740000"], ["1954.39000000", "0.00000000"], ["1777.38000000", "0.06820000"]], "a": [["1974.87000000", "13.09790000"], ["1974.91000000", "0.00000000"], ["1974.93000000", "0.00000000"], ["1974.96000000", "0.03000000"], ["1975.00000000", "0.00570000"], ["1975.01000000", "0.00000000"], ["1975.03000000", "0.00000000"], ["1975.04000000", "0.03000000"], ["1975.05000000", "0.00000000"], ["1975.06000000", "0.00540000"], ["1975.07000000", "0.77190000"], ["1975.09000000", "0.00260000"], ["1975.10000000", "0.00570000"], ["1975.11000000", "1.27130000"], ["1975.12000000", "0.04160000"], ["1975.13000000", "3.64780000"], ["1975.15000000", "0.01020000"], ["1975.16000000", "0.00300000"], ["1975.17000000", "0.00260000"], ["1975.18000000", "0.01160000"], ["1975.22000000", "1.27810000"], ["1975.23000000", "6.46760000"], ["1975.25000000", "9.55620000"], ["1975.26000000", "23.32760000"], ["1975.27000000", "0.00300000"], ["1975.29000000", "4.20500000"], ["1975.30000000", "9.82260000"], ["1975.39000000", "0.00000000"], ["1975.40000000", "33.23070000"], ["1975.41000000", "0.00000000"], ["1975.47000000", "26.84920000"], ["1975.50000000", "2.05210000"], ["1975.52000000", "5.75310000"], ["1975.89000000", "0.03300000"], ["1975.91000000", "0.00000000"], ["1976.40000000", "3.57640000"], ["1976.49000000", "8.50600000"], ["1976.58000000", "7.08830000"], ["1976.72000000", "0.00000000"], ["1976.74000000", "14.18560000"], ["1976.88000000", "0.81000000"], ["1976.96000000", "7.08830000"], ["1977.15000000", "0.00000000"], ["1977.77000000", "0.94500000"], ["1979.33000000", "0.00000000"], ["1979.54000000", "0.80340000"], ["1980.40000000", "0.00570000"], ["1984.12000000", "0.47710000"], ["1984.36000000", "0.00000000"]], "_local_ts_utc": "2026-06-01T07:48:51.611610+00:00"}
{"e": "depthUpdate", "E": 1780300132815, "s": "ETHUSDT", "U": 76583060582, "u": 76583060636, "b": [["1974.86000000", "31.13520000"], ["1974.85000000", "10.14770000"], ["1974.84000000", "0.01310000"], ["1974.81000000", "0.06420000"], ["1974.79000000", "0.02020000"], ["1974.69000000", "20.98700000"], ["1974.68000000", "32.77410000"], ["1974.67000000", "0.01390000"], ["1974.66000000", "7.09490000"], ["1974.61000000", "13.50460000"], ["1974.19000000", "0.10650000"], ["1777.38000000", "0.08060000"]], "a": [["1974.87000000", "9.14690000"], ["1974.89000000", "0.00770000"], ["1975.07000000", "0.78350000"], ["1975.41000000", "1.20550000"], ["1976.15000000", "2.61470000"]], "_local_ts_utc": "2026-06-01T07:48:51.710590+00:00"}
{"e": "depthUpdate", "E": 1780300132915, "s": "ETHUSDT", "U": 76583060637, "u": 76583060687, "b": [["1974.86000000", "31.13520000"], ["1974.85000000", "10.15310000"], ["1974.84000000", "3.70990000"], ["1974.79000000", "0.01750000"], ["1973.98000000", "9.16350000"], ["1973.96000000", "1.40080000"], ["1973.75000000", "8.69330000"], ["1972.99000000", "13.53680000"], ["1971.48000000", "7.03790000"], ["1777.38000000", "0.09300000"]], "a": [["1974.87000000", "0.34090000"], ["1975.02000000", "0.00540000"], ["1975.03000000", "0.72980000"], ["1975.10000000", "0.01110000"], ["1975.44000000", "0.03520000"], ["1975.53000000", "0.00260000"], ["1976.13000000", "1.46710000"], ["1976.73000000", "11.79620000"], ["1977.31000000", "12.23700000"], ["1979.54000000", "0.01020000"], ["1990.45000000", "0.01910000"]], "_local_ts_utc": "2026-06-01T07:48:51.811501+00:00"}
{"e": "depthUpdate", "E": 1780300133015, "s": "ETHUSDT", "U": 76583060688, "u": 76583060712, "b": [["1974.86000000", "41.33550000"], ["1974.68000000", "22.57370000"], ["1974.64000000", "1.42390000"], ["1974.37000000", "0.27540000"], ["1974.09000000", "0.17310000"], ["1777.38000000", "0.10540000"]], "a": [["1974.87000000", "0.20790000"], ["1974.97000000", "0.10000000"], ["1975.06000000", "0.00000000"], ["1975.07000000", "0.00000000"], ["1975.12000000", "0.04700000"], ["1975.26000000", "23.35130000"], ["1975.32000000", "0.94500000"], ["1980.15000000", "36.81150000"]], "_local_ts_utc": "2026-06-01T07:48:51.911506+00:00"}
{"e": "depthUpdate", "E": 1780300133115, "s": "ETHUSDT", "U": 76583060713, "u": 76583061274, "b": [["1975.08000000", "86.62810000"], ["1975.07000000", "7.92860000"], ["1975.06000000", "10.15710000"], ["1975.05000000", "9.00860000"], ["1975.03000000", "0.44690000"], ["1975.02000000", "0.00000000"], ["1975.01000000", "6.46760000"], ["1975.00000000", "0.00800000"], ["1974.99000000", "3.00000000"], ["1974.96000000", "0.03540000"], ["1974.95000000", "1.93450000"], ["1974.94000000", "0.00000000"], ["1974.93000000", "0.00000000"], ["1974.92000000", "0.00260000"], ["1974.91000000", "0.00000000"], ["1974.90000000", "28.89060000"], ["1974.89000000", "22.57370000"], ["1974.88000000", "0.03000000"], ["1974.87000000", "0.00760000"], ["1974.86000000", "13.56460000"], ["1974.85000000", "0.00260000"], ["1974.84000000", "0.00260000"], ["1974.83000000", "6.06250000"], ["1974.82000000", "8.11520000"], ["1974.81000000", "0.56520000"], ["1974.80000000", "3.60640000"], ["1974.79000000", "0.01490000"], ["1974.78000000", "5.42410000"], ["1974.77000000", "7.14400000"], ["1974.76000000", "18.12970000"], ["1974.73000000", "0.03760000"], ["1974.72000000", "0.03880000"], ["1974.70000000", "1.37560000"], ["1974.64000000", "2.06570000"], ["1974.60000000", "17.08340000"], ["1974.59000000", "26.74690000"], ["1974.56000000", "0.04540000"], ["1974.55000000", "7.12320000"], ["1974.53000000", "15.59910000"], ["1974.50000000", "12.36410000"], ["1974.49000000", "16.93410000"], ["1974.48000000", "3.68240000"], ["1974.37000000", "0.27280000"], ["1974.36000000", "0.08320000"], ["1974.29000000", "0.27380000"], ["1974.28000000", "0.03290000"], ["1974.27000000", "23.11990000"], ["1974.26000000", "5.86850000"], ["1974.22000000", "15.34520000"], ["1974.19000000", "0.20650000"], ["1974.11000000", "3.47830000"], ["1974.00000000", "12.29580000"], ["1973.99000000", "0.03150000"], ["1973.96000000", "1.00080000"], ["1973.93000000", "2.35680000"], ["1973.90000000", "19.22350000"], ["1973.86000000", "22.58510000"], ["1973.76000000", "0.25870000"], ["1973.68000000", "0.00940000"], ["1973.60000000", "0.06290000"], ["1973.58000000", "5.21850000"], ["1973.52000000", "1.40430000"], ["1973.42000000", "0.00510000"], ["1972.99000000", "5.94370000"], ["1972.95000000", "0.00000000"], ["1972.94000000", "0.00260000"], ["1972.76000000", "0.00550000"], ["1970.00000000", "410.36040000"], ["1969.92000000", "0.00820000"], ["1969.86000000", "0.01540000"], ["1969.65000000", "3.71520000"], ["1969.57000000", "0.58340000"], ["1967.05000000", "0.00710000"], ["1935.57000000", "0.00270000"], ["1777.38000000", "0.00000000"]], "a": [["1974.87000000", "0.00000000"], ["1974.88000000", "0.00000000"], ["1974.89000000", "0.00000000"], ["1974.90000000", "0.00000000"], ["1974.96000000", "0.00000000"], ["1974.97000000", "0.00000000"], ["1975.00000000", "0.00000000"], ["1975.02000000", "0.00000000"], ["1975.03000000", "0.00000000"], ["1975.04000000", "0.00000000"], ["1975.09000000", "0.11300000"], ["1975.10000000", "0.01090000"], ["1975.11000000", "0.00000000"], ["1975.12000000", "0.00000000"], ["1975.13000000", "0.00000000"], ["1975.17000000", "0.00000000"], ["1975.18000000", "0.00000000"], ["1975.19000000", "0.00260000"], ["1975.20000000", "0.00570000"], ["1975.21000000", "0.00540000"], ["1975.22000000", "0.00000000"], ["1975.23000000", "0.00000000"], ["1975.24000000", "0.00540000"], ["1975.25000000", "2.99040000"], ["1975.26000000", "0.00000000"], ["1975.28000000", "0.03540000"], ["1975.29000000", "4.20770000"], ["1975.30000000", "7.38850000"], ["1975.31000000", "0.01680000"], ["1975.33000000", "0.05000000"], ["1975.36000000", "0.03280000"], ["1975.38000000", "0.00300000"], ["1975.39000000", "0.00260000"], ["1975.40000000", "9.69130000"], ["1975.41000000", "0.00000000"], ["1975.42000000", "0.81000000"], ["1975.44000000", "0.54150000"], ["1975.45000000", "22.73540000"], ["1975.46000000", "6.50060000"], ["1975.47000000", "26.74920000"], ["1975.50000000", "0.65210000"], ["1975.52000000", "3.17830000"], ["1975.57000000", "14.17800000"], ["1975.58000000", "0.56700000"], ["1975.59000000", "0.00000000"], ["1975.64000000", "0.00000000"], ["1975.67000000", "8.50690000"], ["1975.68000000", "0.06300000"], ["1975.69000000", "15.68060000"], ["1975.70000000", "0.00570000"], ["1975.71000000", "0.00560000"], ["1975.78000000", "0.00260000"], ["1975.80000000", "14.83430000"], ["1975.82000000", "0.81300000"], ["1975.83000000", "0.00000000"], ["1975.90000000", "23.06190000"], ["1975.98000000", "1.86420000"], ["1975.99000000", "13.50300000"], ["1976.00000000", "14.17000000"], ["1976.04000000", "0.00300000"], ["1976.13000000", "0.00000000"], ["1976.15000000", "0.00560000"], ["1976.24000000", "0.04270000"], ["1976.25000000", "0.00000000"], ["1976.31000000", "13.50300000"], ["1976.32000000", "4.68390000"], ["1976.37000000", "0.00300000"], ["1976.40000000", "3.60640000"], ["1976.46000000", "0.60000000"], ["1976.48000000", "0.03300000"], ["1976.50000000", "13.50560000"], ["1976.51000000", "4.31710000"], ["1976.54000000", "7.91970000"], ["1976.56000000", "0.03000000"], ["1976.59000000", "0.00300000"], ["1976.72000000", "8.50690000"], ["1976.79000000", "0.00000000"], ["1976.94000000", "18.21310000"], ["1977.00000000", "0.00310000"], ["1977.15000000", "0.00000000"], ["1977.29000000", "0.61240000"], ["1977.36000000", "0.00940000"], ["1977.77000000", "13.50300000"], ["1978.05000000", "13.53590000"], ["1978.24000000", "0.00300000"], ["1980.15000000", "36.80890000"], ["1980.40000000", "0.00310000"], ["1988.00000000", "0.12300000"], ["2474.96000000", "0.01200000"]], "_local_ts_utc": "2026-06-01T07:48:52.011523+00:00"}
{"e": "depthUpdate", "E": 1780300133215, "s": "ETHUSDT", "U": 76583061275, "u": 76583061447, "b": [["1975.08000000", "98.42600000"], ["1975.07000000", "7.93120000"], ["1975.06000000", "10.15970000"], ["1975.05000000", "9.01120000"], ["1975.04000000", "0.03000000"], ["1975.03000000", "0.44950000"], ["1975.02000000", "0.00540000"], ["1975.01000000", "6.47020000"], ["1975.00000000", "0.01060000"], ["1974.99000000", "3.00260000"], ["1974.96000000", "0.03260000"], ["1974.95000000", "12.47690000"], ["1974.92000000", "22.57370000"], ["1974.91000000", "15.59590000"], ["1974.90000000", "8.61060000"], ["1974.89000000", "0.00000000"], ["1974.87000000", "7.09660000"], ["1974.86000000", "3.36170000"], ["1974.85000000", "0.00000000"], ["1974.84000000", "0.00000000"], ["1974.83000000", "10.47690000"], ["1974.82000000", "8.11260000"], ["1974.81000000", "0.56260000"], ["1974.80000000", "3.60690000"], ["1974.78000000", "23.69780000"], ["1974.77000000", "20.64700000"], ["1974.50000000", "0.08680000"], ["1974.49000000", "12.52210000"], ["1974.40000000", "15.62570000"], ["1974.33000000", "8.53080000"], ["1974.31000000", "0.20210000"], ["1974.22000000", "8.71170000"], ["1974.19000000", "0.10520000"], ["1973.93000000", "1.85680000"], ["1973.92000000", "8.53430000"], ["1973.84000000", "8.52860000"], ["1973.71000000", "1.25580000"], ["1973.15000000", "13.53240000"], ["1971.76000000", "0.01280000"], ["1971.75000000", "0.79270000"], ["1971.48000000", "2.32720000"], ["1971.47000000", "0.00000000"], ["1969.15000000", "127.11830000"], ["1967.34000000", "0.00000000"], ["1777.58000000", "0.01240000"]], "a": [["1975.09000000", "7.42770000"], ["1975.10000000", "0.01350000"], ["1975.14000000", "0.10000000"], ["1975.19000000", "0.00000000"], ["1975.21000000", "0.00000000"], ["1975.24000000", "0.00000000"], ["1975.25000000", "0.03300000"], ["1975.28000000", "1.33490000"], ["1975.29000000", "0.00540000"], ["1975.30000000", "4.98280000"], ["1975.31000000", "0.00520000"], ["1975.32000000", "0.00000000"], ["1975.38000000", "0.00560000"], ["1975.39000000", "0.00260000"], ["1975.40000000", "0.00570000"], ["1975.42000000", "0.00000000"], ["1975.45000000", "0.05050000"], ["1975.46000000", "8.22820000"], ["1975.48000000", "0.01160000"], ["1975.50000000", "0.00570000"], ["1975.51000000", "0.02680000"], ["1975.52000000", "5.20250000"], ["1975.56000000", "14.17800000"], ["1975.57000000", "0.00000000"], ["1975.60000000", "5.37740000"], ["1975.61000000", "6.51760000"], ["1975.69000000", "14.18060000"], ["1975.79000000", "4.43820000"], ["1975.83000000", "1.50000000"], ["1976.11000000", "0.04570000"], ["1976.15000000", "0.00560000"], ["1976.18000000", "1.29310000"], ["1977.15000000", "22.68490000"], ["1977.31000000", "3.19920000"], ["1977.36000000", "0.00940000"], ["1977.37000000", "0.00000000"], ["1979.09000000", "0.00260000"], ["1979.36000000", "31.61570000"], ["1980.44000000", "1.34670000"]], "_local_ts_utc": "2026-06-01T07:48:52.113516+00:00"}
{"e": "depthUpdate", "E": 1780300133315, "s": "ETHUSDT", "U": 76583061448, "u": 76583061510, "b": [["1975.08000000", "90.27660000"], ["1975.05000000", "9.00860000"], ["1975.04000000", "0.03260000"], ["1975.03000000", "0.44950000"], ["1975.02000000", "0.00800000"], ["1974.96000000", "0.03000000"], ["1974.95000000", "12.47430000"], ["1974.90000000", "8.71190000"], ["1974.82000000", "7.60560000"], ["1974.70000000", "0.05570000"], ["1974.69000000", "20.98700000"], ["1974.67000000", "0.82390000"], ["1974.64000000", "0.78660000"], ["1974.60000000", "17.35340000"], ["1974.25000000", "1.34550000"], ["1974.09000000", "0.00260000"], ["1972.78000000", "0.27260000"], ["1967.69000000", "0.00840000"], ["1777.58000000", "0.03100000"]], "a": [["1975.09000000", "12.37380000"], ["1975.11000000", "0.00260000"], ["1975.14000000", "0.00000000"], ["1975.24000000", "0.00260000"], ["1975.27000000", "0.00300000"], ["1975.28000000", "0.00000000"], ["1975.34000000", "0.00000000"], ["1975.39000000", "0.01420000"], ["1975.42000000", "1.31300000"], ["1975.50000000", "8.56300000"], ["1975.51000000", "8.53370000"], ["1975.52000000", "0.52360000"], ["1975.80000000", "15.48070000"], ["1975.89000000", "6.91700000"], ["1975.98000000", "5.59320000"], ["1976.23000000", "0.65650000"], ["1976.64000000", "0.03000000"], ["1977.11000000", "2.08740000"], ["1977.15000000", "14.17800000"], ["1980.53000000", "0.02260000"], ["1980.62000000", "0.00260000"], ["1997.17000000", "0.10130000"], ["1999.50000000", "0.03040000"], ["2342.74000000", "0.13200000"]], "_local_ts_utc": "2026-06-01T07:48:52.211440+00:00"}
{"e": "depthUpdate", "E": 1780300133418, "s": "ETHUSDT", "U": 76583061511, "u": 76583061930, "b": [["1975.08000000", "0.00000000"], ["1975.07000000", "0.00000000"], ["1975.06000000", "0.00000000"], ["1975.05000000", "0.00000000"], ["1975.04000000", "0.00000000"], ["1975.03000000", "0.00000000"], ["1975.02000000", "0.00000000"], ["1975.01000000", "0.00000000"], ["1975.00000000", "0.00000000"], ["1974.99000000", "0.00000000"], ["1974.98000000", "0.00000000"], ["1974.97000000", "0.00000000"], ["1974.96000000", "0.00000000"], ["1974.95000000", "0.00000000"], ["1974.93000000", "0.00000000"], ["1974.92000000", "0.00000000"], ["1974.91000000", "0.00000000"], ["1974.90000000", "0.00000000"], ["1974.88000000", "0.00000000"], ["1974.87000000", "0.00000000"], ["1974.86000000", "0.00000000"], ["1974.83000000", "0.00000000"], ["1974.82000000", "6.01610000"], ["1974.81000000", "1.18570000"], ["1974.80000000", "2.03910000"], ["1974.79000000", "0.01490000"], ["1974.78000000", "0.00000000"], ["1974.77000000", "0.05500000"], ["1974.76000000", "2.53380000"], ["1974.70000000", "0.06210000"], ["1974.69000000", "12.48570000"], ["1974.68000000", "0.00000000"], ["1974.67000000", "0.55390000"], ["1974.66000000", "0.00660000"], ["1974.64000000", "0.14480000"], ["1974.63000000", "0.34120000"], ["1974.61000000", "0.00300000"], ["1974.60000000", "0.49670000"], ["1974.59000000", "0.00690000"], ["1974.58000000", "0.02480000"], ["1974.55000000", "0.03490000"], ["1974.53000000", "0.00480000"], ["1974.49000000", "0.00280000"], ["1974.48000000", "0.08240000"], ["1974.47000000", "0.09340000"], ["1974.45000000", "0.61330000"], ["1974.43000000", "0.00400000"], ["1974.42000000", "0.18820000"], ["1974.40000000", "15.52440000"], ["1974.38000000", "0.05320000"], ["1974.37000000", "0.00280000"], ["1974.34000000", "0.00760000"], ["1974.33000000", "1.34390000"], ["1974.32000000", "0.03000000"], ["1974.31000000", "0.02400000"], ["1974.27000000", "0.27620000"], ["1974.26000000", "2.26850000"], ["1974.25000000", "0.00000000"], ["1974.24000000", "0.17770000"], ["1974.23000000", "0.54000000"], ["1974.22000000", "0.20740000"], ["1974.21000000", "0.36260000"], ["1974.19000000", "0.00520000"], ["1974.17000000", "0.71500000"], ["1974.13000000", "0.00500000"], ["1974.12000000", "0.01780000"], ["1974.11000000", "3.07830000"], ["1974.08000000", "1.55160000"], ["1974.07000000", "0.01020000"], ["1974.04000000", "0.40000000"], ["1974.02000000", "0.32670000"], ["1974.01000000", "1.05530000"], ["1973.96000000", "0.20080000"], ["1973.95000000", "0.04060000"], ["1973.94000000", "0.27550000"], ["1973.92000000", "0.03000000"], ["1973.89000000", "2.53310000"], ["1973.86000000", "0.01140000"], ["1973.84000000", "1.47220000"], ["1973.82000000", "1.91370000"], ["1973.76000000", "0.00000000"], ["1973.75000000", "0.59440000"], ["1973.72000000", "0.28130000"], ["1973.71000000", "0.05030000"], ["1973.69000000", "0.28210000"], ["1973.68000000", "0.03940000"], ["1973.66000000", "1.11680000"], ["1973.65000000", "0.00420000"], ["1973.64000000", "0.00000000"], ["1973.55000000", "0.01080000"], ["1973.52000000", "1.40430000"], ["1973.50000000", "1.07180000"], ["1973.47000000", "0.01020000"], ["1973.45000000", "3.82220000"], ["1973.44000000", "1.43340000"], ["1973.43000000", "0.51690000"], ["1973.41000000", "0.26170000"], ["1973.35000000", "0.02000000"], ["1973.31000000", "0.35950000"], ["1973.24000000", "0.28330000"], ["1973.20000000", "0.13720000"], ["1973.15000000", "0.03450000"], ["1973.11000000", "0.01570000"], ["1973.04000000", "0.00000000"], ["1973.01000000", "0.00000000"], ["1973.00000000", "10.49440000"], ["1972.94000000", "0.00260000"], ["1972.92000000", "0.06130000"], ["1972.88000000", "0.05250000"], ["1972.87000000", "0.03760000"], ["1972.81000000", "0.20130000"], ["1972.78000000", "0.00260000"], ["1972.75000000", "0.01260000"], ["1972.63000000", "0.03390000"], ["1972.62000000", "0.01640000"], ["1972.59000000", "0.26580000"], ["1972.56000000", "8.50690000"], ["1972.42000000", "0.01520000"], ["1972.31000000", "0.05590000"], ["1972.22000000", "0.05080000"], ["1972.08000000", "8.51450000"], ["1972.03000000", "0.00000000"], ["1972.02000000", "0.00270000"], ["1972.01000000", "7.09660000"], ["1971.97000000", "8.50950000"], ["1971.82000000", "0.00260000"], ["1971.75000000", "14.29570000"], ["1971.62000000", "0.00000000"], ["1971.44000000", "0.00000000"], ["1971.42000000", "0.15850000"], ["1971.37000000", "8.63850000"], ["1971.19000000", "7.10180000"], ["1971.11000000", "7.50590000"], ["1970.97000000", "29.61860000"], ["1970.96000000", "0.27410000"], ["1970.94000000", "7.09180000"], ["1970.85000000", "3.74740000"], ["1970.81000000", "2.29710000"], ["1970.71000000", "0.03820000"], ["1970.57000000", "38.17380000"], ["1970.18000000", "7.09390000"], ["1970.17000000", "7.09160000"], ["1967.69000000", "0.00000000"], ["1965.74000000", "7.02760000"], ["1964.64000000", "0.00280000"], ["1964.07000000", "0.16160000"], ["1777.58000000", "0.03720000"], ["1588.49000000", "0.09100000"], ["1587.25000000", "10.00000000"], ["1586.68000000", "0.03250000"], ["1586.45000000", "0.00000000"], ["1583.86000000", "0.09100000"], ["1583.52000000", "0.14000000"], ["1582.64000000", "0.11200000"], ["1580.31000000", "0.00000000"], ["1580.28000000", "0.01400000"], ["1580.24000000", "0.00000000"], ["1579.87000000", "0.00000000"]], "a": [["1974.90000000", "2.50420000"], ["1974.93000000", "2.19790000"], ["1974.96000000", "8.62510000"], ["1974.97000000", "4.86640000"], ["1975.00000000", "18.37210000"], ["1975.01000000", "4.00000000"], ["1975.02000000", "8.40120000"], ["1975.03000000", "14.66440000"], ["1975.04000000", "4.00000000"], ["1975.05000000", "11.88430000"], ["1975.06000000", "4.00000000"], ["1975.07000000", "15.40120000"], ["1975.08000000", "18.72640000"], ["1975.09000000", "31.46740000"], ["1975.10000000", "0.00570000"], ["1975.20000000", "0.03570000"], ["1975.26000000", "0.01160000"], ["1975.28000000", "0.03000000"], ["1975.29000000", "0.00000000"], ["1975.31000000", "0.01680000"], ["1975.34000000", "0.00380000"], ["1975.38000000", "1.94040000"], ["1975.39000000", "6.48180000"], ["1975.45000000", "8.02600000"], ["1975.46000000", "0.03300000"], ["1975.48000000", "0.64790000"], ["1975.50000000", "8.71410000"], ["1975.51000000", "9.18010000"], ["1975.60000000", "18.88040000"], ["1975.61000000", "0.05000000"], ["1975.80000000", "14.83430000"], ["1976.05000000", "30.26710000"], ["1976.16000000", "0.03000000"], ["1976.32000000", "4.71390000"], ["1976.56000000", "0.00000000"], ["1976.64000000", "0.00000000"], ["1976.75000000", "0.01020000"], ["1976.94000000", "2.61720000"], ["1976.96000000", "0.00000000"], ["1977.05000000", "3.59800000"], ["1977.15000000", "0.00000000"], ["1977.77000000", "0.00000000"], ["1978.05000000", "0.03290000"], ["1979.36000000", "0.00000000"], ["1980.09000000", "0.00540000"], ["1980.62000000", "0.00000000"], ["1981.90000000", "1.00000000"], ["2074.15000000", "0.00000000"], ["2074.25000000", "0.05250000"], ["2074.29000000", "0.01700000"], ["2074.81000000", "0.00400000"], ["2076.11000000", "0.00580000"]], "_local_ts_utc": "2026-06-01T07:48:52.315826+00:00"}
{"e": "depthUpdate", "E": 1780300133515, "s": "ETHUSDT", "U": 76583061931, "u": 76583063215, "b": [["1974.87000000", "0.00000000"], ["1974.83000000", "0.00000000"], ["1974.82000000", "40.34900000"], ["1974.81000000", "0.07200000"], ["1974.80000000", "2.01170000"], ["1974.79000000", "0.00730000"], ["1974.78000000", "0.00000000"], ["1974.77000000", "0.06300000"], ["1974.76000000", "0.00260000"], ["1974.75000000", "0.13450000"], ["1974.74000000", "1.19790000"], ["1974.73000000", "0.03260000"], ["1974.72000000", "0.01140000"], ["1974.71000000", "0.00000000"], ["1974.70000000", "0.05260000"], ["1974.69000000", "0.20910000"], ["1974.67000000", "0.01390000"], ["1974.66000000", "0.00280000"], ["1974.64000000", "0.12240000"], ["1974.63000000", "0.03060000"], ["1974.62000000", "0.00540000"], ["1974.61000000", "1.33900000"], ["1974.60000000", "0.13830000"], ["1974.59000000", "1.28240000"], ["1974.58000000", "0.65830000"], ["1974.56000000", "0.01540000"], ["1974.53000000", "0.00480000"], ["1974.52000000", "0.58340000"], ["1974.50000000", "0.08370000"], ["1974.45000000", "0.00260000"], ["1974.41000000", "10.20140000"], ["1974.40000000", "0.03940000"], ["1974.39000000", "0.34750000"], ["1974.36000000", "0.08320000"], ["1974.35000000", "0.03730000"], ["1974.34000000", "0.00760000"], ["1974.33000000", "0.00000000"], ["1974.31000000", "15.61990000"], ["1974.30000000", "0.64630000"], ["1974.29000000", "0.00380000"], ["1974.27000000", "0.00620000"], ["1974.26000000", "1.79850000"], ["1974.24000000", "0.03770000"], ["1974.23000000", "0.00000000"], ["1974.22000000", "7.09640000"], ["1974.21000000", "15.68850000"], ["1974.20000000", "3.64440000"], ["1974.17000000", "0.71500000"], ["1974.16000000", "0.21310000"], ["1974.15000000", "20.13520000"], ["1974.13000000", "0.00500000"], ["1974.12000000", "0.00770000"], ["1974.11000000", "7.24690000"], ["1974.10000000", "13.87030000"], ["1974.08000000", "0.03000000"], ["1974.07000000", "0.01020000"], ["1974.06000000", "0.07050000"], ["1974.05000000", "3.06000000"], ["1974.04000000", "0.00000000"], ["1974.03000000", "15.61610000"], ["1974.01000000", "29.11440000"], ["1974.00000000", "13.81740000"], ["1973.98000000", "0.02220000"], ["1973.95000000", "0.70690000"], ["1973.94000000", "0.29830000"], ["1973.93000000", "0.32370000"], ["1973.91000000", "29.71560000"], ["1973.90000000", "0.21970000"], ["1973.89000000", "2.60140000"], ["1973.86000000", "0.01140000"], ["1973.85000000", "1.80210000"], ["1973.84000000", "1.57220000"], ["1973.83000000", "16.03820000"], ["1973.82000000", "2.64680000"], ["1973.81000000", "14.37030000"], ["1973.80000000", "0.00820000"], ["1973.78000000", "0.06300000"], ["1973.77000000", "1.26240000"], ["1973.76000000", "0.03000000"], ["1973.75000000", "0.04260000"], ["1973.73000000", "15.06020000"], ["1973.72000000", "0.28130000"], ["1973.71000000", "8.53870000"], ["1973.70000000", "0.66160000"], ["1973.68000000", "23.41310000"], ["1973.67000000", "0.25090000"], ["1973.66000000", "0.10400000"], ["1973.65000000", "4.30420000"], ["1973.63000000", "9.13780000"], ["1973.61000000", "15.23910000"], ["1973.60000000", "0.09290000"], ["1973.58000000", "0.00000000"], ["1973.57000000", "2.16340000"], ["1973.56000000", "0.10790000"], ["1973.54000000", "0.00260000"], ["1973.53000000", "0.02000000"], ["1973.52000000", "0.07600000"], ["1973.51000000", "7.10440000"], ["1973.50000000", "24.22580000"], ["1973.49000000", "0.31420000"], ["1973.48000000", "0.00740000"], ["1973.46000000", "22.59030000"], ["1973.45000000", "3.82220000"], ["1973.44000000", "1.25060000"], ["1973.43000000", "0.51690000"], ["1973.41000000", "21.53630000"], ["1973.40000000", "0.15720000"], ["1973.39000000", "15.65580000"], ["1973.38000000", "1.20810000"], ["1973.37000000", "0.20130000"], ["1973.36000000", "0.30530000"], ["1973.34000000", "0.27000000"], ["1973.33000000", "1.68040000"], ["1973.32000000", "0.18800000"], ["1973.31000000", "24.40280000"], ["1973.30000000", "4.48950000"], ["1973.27000000", "1.34610000"], ["1973.26000000", "1.01660000"], ["1973.25000000", "14.17530000"], ["1973.22000000", "14.04300000"], ["1973.21000000", "7.08900000"], ["1973.20000000", "0.13720000"], ["1973.17000000", "0.00000000"], ["1973.16000000", "1.29910000"], ["1973.14000000", "7.08900000"], ["1973.13000000", "0.43620000"], ["1973.12000000", "0.07590000"], ["1973.11000000", "8.52260000"], ["1973.08000000", "0.14530000"], ["1973.03000000", "0.04770000"], ["1973.01000000", "15.19210000"], ["1973.00000000", "8.49440000"], ["1972.99000000", "8.52750000"], ["1972.97000000", "0.00690000"], ["1972.94000000", "29.10150000"], ["1972.89000000", "0.01670000"], ["1972.85000000", "3.65520000"], ["1972.81000000", "14.37930000"], ["1972.74000000", "8.50990000"], ["1972.73000000", "7.35900000"], ["1972.69000000", "0.00000000"], ["1972.61000000", "22.68750000"], ["1972.57000000", "36.07670000"], ["1972.56000000", "0.00000000"], ["1972.46000000", "0.00740000"], ["1972.41000000", "14.43310000"], ["1972.40000000", "9.60760000"], ["1972.39000000", "31.72720000"], ["1972.31000000", "0.05590000"], ["1972.30000000", "0.51740000"], ["1972.29000000", "23.69410000"], ["1972.25000000", "3.81110000"], ["1972.24000000", "0.75900000"], ["1972.22000000", "0.05080000"], ["1972.14000000", "0.00260000"], ["1972.13000000", "0.04350000"], ["1972.11000000", "0.05370000"], ["1972.10000000", "0.00260000"], ["1972.09000000", "12.66850000"], ["1972.08000000", "0.00760000"], ["1972.01000000", "13.51060000"], ["1971.98000000", "0.13160000"], ["1971.97000000", "0.00260000"], ["1971.78000000", "0.02460000"], ["1971.77000000", "0.24860000"], ["1971.76000000", "13.51580000"], ["1971.75000000", "1.82370000"], ["1971.68000000", "1.21900000"], ["1971.61000000", "0.00000000"], ["1971.58000000", "0.50260000"], ["1971.57000000", "0.08300000"], ["1971.48000000", "0.02070000"], ["1971.47000000", "13.50300000"], ["1971.41000000", "0.00000000"], ["1971.37000000", "0.13160000"], ["1971.31000000", "0.01530000"], ["1971.21000000", "0.00000000"], ["1971.19000000", "20.60480000"], ["1971.17000000", "0.00000000"], ["1971.11000000", "0.41690000"], ["1971.01000000", "0.31300000"], ["1970.97000000", "0.03880000"], ["1970.91000000", "13.50300000"], ["1970.89000000", "31.75520000"], ["1970.82000000", "0.00710000"], ["1970.77000000", "0.01060000"], ["1970.74000000", "7.08900000"], ["1970.71000000", "0.03820000"], ["1970.63000000", "13.50560000"], ["1970.62000000", "0.00260000"], ["1970.58000000", "0.13720000"], ["1970.57000000", "29.66690000"], ["1970.42000000", "0.00520000"], ["1970.38000000", "0.00320000"], ["1970.37000000", "7.10250000"], ["1970.35000000", "0.02560000"], ["1970.26000000", "65.93390000"], ["1970.24000000", "23.50470000"], ["1970.18000000", "0.00490000"], ["1970.07000000", "0.22080000"], ["1970.01000000", "22.98630000"], ["1970.00000000", "410.36310000"], ["1969.90000000", "8.77550000"], ["1969.79000000", "0.00940000"], ["1969.65000000", "26.28890000"], ["1969.51000000", "0.00000000"], ["1969.20000000", "0.00570000"], ["1969.11000000", "0.01240000"], ["1967.10000000", "0.05130000"], ["1967.05000000", "3.60710000"], ["1966.85000000", "3.62280000"], ["1966.65000000", "3.60000000"], ["1965.24000000", "0.00000000"], ["1965.09000000", "0.05070000"], ["1964.81000000", "0.47840000"], ["1964.44000000", "106.97470000"], ["1964.37000000", "70.73120000"], ["1963.92000000", "1.21570000"], ["1963.33000000", "0.07830000"], ["1958.70000000", "0.00970000"], ["1958.15000000", "3.10650000"], ["1935.32000000", "0.00310000"], ["1777.58000000", "0.00000000"], ["1777.34000000", "0.01240000"], ["1582.64000000", "0.09800000"], ["1580.36000000", "0.00000000"], ["1580.34000000", "0.00000000"], ["1580.28000000", "0.00000000"], ["1580.07000000", "0.02100000"], ["1579.95000000", "0.01680000"], ["1579.91000000", "0.01400000"], ["1579.86000000", "0.24500000"]], "a": [["1974.83000000", "51.67690000"], ["1974.84000000", "0.00540000"], ["1974.85000000", "4.14840000"], ["1974.86000000", "0.11200000"], ["1974.87000000", "0.00540000"], ["1974.88000000", "5.00710000"], ["1974.89000000", "0.00000000"], ["1974.90000000", "0.00570000"], ["1974.91000000", "0.00540000"], ["1974.92000000", "0.62460000"], ["1974.93000000", "0.00000000"], ["1974.94000000", "2.71270000"], ["1974.95000000", "0.01160000"], ["1974.96000000", "0.03000000"], ["1974.97000000", "4.97710000"], ["1974.98000000", "0.00000000"], ["1974.99000000", "0.00000000"], ["1975.00000000", "0.54270000"], ["1975.01000000", "7.49670000"], ["1975.02000000", "7.08900000"], ["1975.03000000", "0.00000000"], ["1975.04000000", "7.11900000"], ["1975.05000000", "1.50300000"], ["1975.06000000", "0.00000000"], ["1975.07000000", "8.50690000"], ["1975.08000000", "0.00000000"], ["1975.09000000", "3.07280000"], ["1975.10000000", "0.00570000"], ["1975.12000000", "0.03000000"], ["1975.13000000", "0.00000000"], ["1975.14000000", "0.00380000"], ["1975.15000000", "0.51650000"], ["1975.17000000", "5.23850000"], ["1975.18000000", "8.29450000"], ["1975.19000000", "7.09160000"], ["1975.21000000", "3.63960000"], ["1975.22000000", "8.50690000"], ["1975.23000000", "0.00260000"], ["1975.28000000", "0.03000000"], ["1975.29000000", "3.60000000"], ["1975.30000000", "0.00570000"], ["1975.31000000", "0.01680000"], ["1975.32000000", "0.11000000"], ["1975.38000000", "0.00560000"], ["1975.39000000", "0.00260000"], ["1975.40000000", "22.20960000"], ["1975.41000000", "13.50300000"], ["1975.42000000", "0.00000000"], ["1975.44000000", "0.03520000"], ["1975.45000000", "0.05050000"], ["1975.48000000", "1.20550000"], ["1975.50000000", "8.56300000"], ["1975.51000000", "8.61080000"], ["1975.63000000", "6.19700000"], ["1975.66000000", "0.24220000"], ["1975.73000000", "0.37810000"], ["1975.83000000", "0.00000000"], ["1975.89000000", "6.91700000"], ["1975.90000000", "22.68120000"], ["1975.97000000", "0.00000000"], ["1975.98000000", "5.76370000"], ["1976.00000000", "14.17010000"], ["1976.08000000", "9.85600000"], ["1976.10000000", "15.12780000"], ["1976.11000000", "1.44570000"], ["1976.16000000", "0.00000000"], ["1976.18000000", "1.29050000"], ["1976.24000000", "0.00520000"], ["1976.25000000", "8.50690000"], ["1976.26000000", "0.00300000"], ["1976.30000000", "0.57270000"], ["1976.32000000", "0.00000000"], ["1976.39000000", "7.31720000"], ["1976.40000000", "3.57640000"], ["1976.46000000", "0.00000000"], ["1976.48000000", "15.59890000"], ["1976.49000000", "0.00000000"], ["1976.52000000", "0.00000000"], ["1976.54000000", "7.11970000"], ["1976.58000000", "0.00000000"], ["1976.61000000", "9.50480000"], ["1976.71000000", "7.08900000"], ["1976.72000000", "0.00000000"], ["1976.73000000", "0.00000000"], ["1976.74000000", "0.00900000"], ["1976.80000000", "0.48910000"], ["1976.87000000", "0.20050000"], ["1976.94000000", "0.13380000"], ["1977.37000000", "31.64750000"], ["1977.42000000", "0.00260000"], ["1977.44000000", "0.00000000"], ["1977.50000000", "15.34430000"], ["1978.35000000", "0.00000000"], ["1979.09000000", "0.00000000"], ["1979.22000000", "65.92600000"], ["1979.28000000", "8.42660000"], ["1979.59000000", "3.62020000"], ["1979.64000000", "0.00000000"], ["1979.79000000", "0.00000000"], ["1980.09000000", "0.00000000"], ["1980.14000000", "0.00000000"], ["1980.36000000", "0.00260000"], ["1981.57000000", "0.00000000"], ["1981.90000000", "1.00000000"], ["1983.17000000", "0.00000000"], ["1984.12000000", "0.00000000"], ["1985.44000000", "0.02400000"], ["1985.69000000", "0.04580000"], ["1988.00000000", "0.12030000"], ["1991.00000000", "1.78740000"], ["2004.14000000", "9.11840000"], ["2004.61000000", "0.00600000"], ["2073.70000000", "0.00790000"], ["2073.84000000", "0.03620000"]], "_local_ts_utc": "2026-06-01T07:48:52.411827+00:00"}
{"e": "depthUpdate", "E": 1780300133615, "s": "ETHUSDT", "U": 76583063216, "u": 76583063346, "b": [["1974.82000000", "39.14080000"], ["1974.77000000", "0.05760000"], ["1974.62000000", "0.00000000"], ["1974.61000000", "0.00300000"], ["1974.60000000", "0.13560000"], ["1974.59000000", "0.00690000"], ["1974.58000000", "0.02480000"], ["1974.56000000", "0.02080000"], ["1974.55000000", "2.17570000"], ["1974.54000000", "6.48180000"], ["1974.52000000", "0.07690000"], ["1974.43000000", "10.78570000"], ["1974.42000000", "22.87310000"], ["1974.33000000", "12.21000000"], ["1974.32000000", "20.62200000"], ["1974.30000000", "10.15420000"], ["1974.26000000", "1.80800000"], ["1974.21000000", "27.96740000"], ["1974.20000000", "15.47840000"], ["1974.12000000", "1.28320000"], ["1974.11000000", "29.82060000"], ["1973.98000000", "0.29220000"], ["1973.51000000", "14.19340000"], ["1972.81000000", "7.29030000"], ["1972.75000000", "0.28260000"], ["1972.61000000", "7.09160000"], ["1972.41000000", "0.25510000"], ["1972.23000000", "0.27570000"], ["1971.54000000", "0.00700000"], ["1970.63000000", "0.00260000"], ["1969.56000000", "0.00900000"], ["1969.52000000", "1.00000000"], ["1967.59000000", "0.00000000"], ["1967.54000000", "1.00000000"], ["1965.61000000", "0.00000000"], ["1965.57000000", "1.11020000"], ["1963.60000000", "1.00380000"], ["1954.18000000", "0.22060000"], ["1777.34000000", "0.02480000"]], "a": [["1974.83000000", "60.13220000"], ["1974.84000000", "1.71370000"], ["1974.85000000", "1.32530000"], ["1974.86000000", "0.00000000"], ["1974.90000000", "0.01730000"], ["1974.93000000", "0.00000000"], ["1974.94000000", "0.00000000"], ["1974.95000000", "0.01430000"], ["1974.96000000", "3.61090000"], ["1975.00000000", "7.01030000"], ["1975.01000000", "8.14800000"], ["1975.09000000", "1.34900000"], ["1975.14000000", "0.00760000"], ["1975.15000000", "0.01020000"], ["1975.17000000", "8.63410000"], ["1975.20000000", "13.53870000"], ["1975.21000000", "3.64030000"], ["1975.31000000", "0.00520000"], ["1975.34000000", "0.00760000"], ["1975.39000000", "7.09160000"], ["1975.40000000", "7.09470000"], ["1975.61000000", "0.56300000"], ["1975.62000000", "0.17310000"], ["1975.63000000", "6.65600000"], ["1975.70000000", "0.00570000"], ["1976.23000000", "0.48600000"], ["1976.71000000", "0.00000000"], ["1977.50000000", "1.84130000"], ["1980.44000000", "1.34410000"], ["1980.53000000", "0.02000000"], ["2342.74000000", "0.14700000"]], "_local_ts_utc": "2026-06-01T07:48:52.512380+00:00"}
{"e": "depthUpdate", "E": 1780300133715, "s": "ETHUSDT", "U": 76583063347, "u": 76583063780, "b": [["1974.82000000", "0.00000000"], ["1974.81000000", "0.00000000"], ["1974.80000000", "0.00000000"], ["1974.79000000", "0.00000000"], ["1974.77000000", "0.07320000"], ["1974.76000000", "0.01040000"], ["1974.72000000", "0.00880000"], ["1974.70000000", "0.06060000"], ["1974.69000000", "0.21170000"], ["1974.67000000", "0.01650000"], ["1974.66000000", "0.00540000"], ["1974.64000000", "0.11480000"], ["1974.59000000", "0.00430000"], ["1974.56000000", "0.01540000"], ["1974.55000000", "0.03490000"], ["1974.54000000", "0.01420000"], ["1974.47000000", "10.24080000"], ["1974.46000000", "0.51030000"], ["1974.44000000", "5.80600000"], ["1974.43000000", "6.47160000"], ["1974.42000000", "0.19360000"], ["1974.41000000", "10.20140000"], ["1974.36000000", "0.08320000"], ["1974.33000000", "0.00000000"], ["1974.32000000", "0.03000000"], ["1974.31000000", "0.00000000"], ["1974.30000000", "2.76520000"], ["1974.28000000", "0.03550000"], ["1974.23000000", "0.02060000"], ["1974.22000000", "7.09640000"], ["1974.21000000", "0.09260000"], ["1974.20000000", "21.86460000"], ["1974.16000000", "0.21310000"], ["1974.15000000", "6.63220000"], ["1974.13000000", "15.60090000"], ["1974.12000000", "8.37220000"], ["1974.10000000", "21.92470000"], ["1974.04000000", "12.28010000"], ["1974.02000000", "18.23270000"], ["1974.01000000", "15.61140000"], ["1973.91000000", "29.73980000"], ["1973.88000000", "15.80800000"], ["1973.87000000", "14.04300000"], ["1973.84000000", "1.47220000"], ["1973.80000000", "0.01080000"], ["1973.79000000", "0.27000000"], ["1973.69000000", "24.03860000"], ["1973.68000000", "50.15810000"], ["1973.61000000", "15.33910000"], ["1973.56000000", "0.02020000"], ["1973.52000000", "11.54410000"], ["1973.47000000", "14.87820000"], ["1973.45000000", "3.82220000"], ["1973.40000000", "13.33530000"], ["1973.31000000", "24.31590000"], ["1973.12000000", "0.00000000"], ["1973.10000000", "0.00000000"], ["1973.03000000", "0.00000000"], ["1973.02000000", "7.07040000"], ["1972.99000000", "14.72110000"], ["1972.93000000", "22.66010000"], ["1972.86000000", "5.58900000"], ["1972.82000000", "7.13450000"], ["1972.70000000", "0.21790000"], ["1972.66000000", "5.70240000"], ["1972.62000000", "7.10540000"], ["1972.58000000", "8.50690000"], ["1972.44000000", "5.17100000"], ["1972.42000000", "0.09250000"], ["1972.41000000", "15.85100000"], ["1972.29000000", "23.74200000"], ["1972.22000000", "7.13980000"], ["1971.77000000", "4.83680000"], ["1971.69000000", "1.83700000"], ["1971.48000000", "5.17330000"], ["1971.20000000", "7.61420000"], ["1970.95000000", "6.17230000"], ["1970.90000000", "18.03700000"], ["1970.63000000", "0.00260000"], ["1969.11000000", "0.01500000"], ["1969.02000000", "1.76760000"], ["1965.74000000", "6.72530000"], ["1935.27000000", "0.10950000"], ["1777.34000000", "0.00000000"], ["1777.30000000", "0.01240000"]], "a": [["1974.78000000", "144.64440000"], ["1974.79000000", "19.45250000"], ["1974.80000000", "22.72570000"], ["1974.81000000", "1.53550000"], ["1974.82000000", "3.00000000"], ["1974.83000000", "25.06940000"], ["1974.84000000", "0.00000000"], ["1974.87000000", "0.00260000"], ["1974.89000000", "6.46760000"], ["1974.91000000", "0.00000000"], ["1974.93000000", "4.19940000"], ["1974.94000000", "8.50690000"], ["1974.95000000", "0.01160000"], ["1974.96000000", "0.03000000"], ["1975.00000000", "13.63360000"], ["1975.01000000", "13.50560000"], ["1975.03000000", "0.03300000"], ["1975.07000000", "12.75390000"], ["1975.08000000", "0.00260000"], ["1975.09000000", "1.84380000"], ["1975.14000000", "0.00380000"], ["1975.26000000", "0.00000000"], ["1975.34000000", "0.00380000"], ["1975.37000000", "6.77480000"], ["1975.38000000", "8.51250000"], ["1975.39000000", "7.08900000"], ["1975.40000000", "19.81900000"], ["1975.41000000", "13.52270000"], ["1975.60000000", "14.64040000"], ["1975.80000000", "14.83170000"], ["1975.88000000", "0.22050000"], ["1975.98000000", "5.59320000"], ["1976.00000000", "13.68110000"], ["1976.05000000", "21.76010000"], ["1976.10000000", "16.24760000"], ["1976.25000000", "0.00000000"], ["1976.29000000", "0.56700000"], ["1976.30000000", "7.23930000"], ["1976.48000000", "0.00300000"], ["1976.61000000", "2.41580000"], ["1976.76000000", "3.06680000"], ["1976.80000000", "7.87740000"], ["1976.94000000", "1.22070000"], ["1977.10000000", "2.75130000"], ["1977.16000000", "0.00000000"], ["1977.17000000", "0.00260000"], ["1977.31000000", "12.23700000"], ["1977.57000000", "3.60260000"], ["1977.83000000", "16.95710000"], ["1978.21000000", "0.00000000"], ["1978.40000000", "31.63680000"], ["1978.42000000", "0.03080000"], ["1978.57000000", "0.00000000"], ["1978.80000000", "0.00310000"], ["1979.83000000", "0.00000000"], ["1980.03000000", "2.55700000"], ["1982.04000000", "0.00000000"], ["1982.15000000", "3.03460000"], ["1983.87000000", "0.00490000"], ["1985.48000000", "0.10000000"], ["1985.61000000", "0.23240000"], ["1997.80000000", "0.00850000"], ["2033.60000000", "0.00430000"], ["2049.30000000", "0.00000000"], ["2108.99000000", "0.50300000"], ["2128.89000000", "0.03440000"], ["2168.68000000", "0.00000000"], ["2228.37000000", "0.55690000"], ["2268.16000000", "0.50270000"], ["2566.60000000", "0.00000000"], ["2666.09000000", "0.00380000"], ["2685.98000000", "0.00000000"], ["2745.67000000", "0.00000000"], ["2785.46000000", "0.00000000"], ["2845.15000000", "0.00210000"], ["2944.63000000", "0.00000000"], ["2964.53000000", "0.00000000"], ["2984.43000000", "0.00000000"], ["3083.91000000", "0.00000000"], ["3143.59000000", "0.00170000"], ["3262.97000000", "0.00000000"], ["3282.87000000", "0.00000000"], ["3302.76000000", "0.00000000"], ["3322.66000000", "0.00270000"], ["3362.45000000", "0.00170000"], ["3382.35000000", "0.05360000"], ["3422.14000000", "0.00000000"], ["3461.93000000", "0.00000000"], ["3501.73000000", "0.00000000"], ["3521.62000000", "0.00000000"], ["3541.52000000", "0.00000000"], ["3581.31000000", "0.00400000"], ["3601.21000000", "0.00000000"], ["3641.00000000", "0.51320000"], ["3660.90000000", "0.00210000"], ["3740.48000000", "0.00000000"], ["3780.27000000", "0.00000000"], ["3839.96000000", "0.00000000"], ["3859.86000000", "0.00000000"], ["3919.55000000", "0.00000000"]], "_local_ts_utc": "2026-06-01T07:48:52.611214+00:00"}
{"e": "depthUpdate", "E": 1780300133815, "s": "ETHUSDT", "U": 76583063781, "u": 76583064147, "b": [["1974.77000000", "0.00000000"], ["1974.76000000", "0.00000000"], ["1974.75000000", "0.00000000"], ["1974.74000000", "1.02550000"], ["1974.73000000", "0.04040000"], ["1974.69000000", "0.26220000"], ["1974.65000000", "0.01520000"], ["1974.64000000", "0.11740000"], ["1974.63000000", "0.03320000"], ["1974.54000000", "0.01160000"], ["1974.50000000", "0.07070000"], ["1974.49000000", "0.00280000"], ["1974.48000000", "0.05780000"], ["1974.47000000", "10.24080000"], ["1974.45000000", "0.00260000"], ["1974.44000000", "0.03650000"], ["1974.42000000", "0.18820000"], ["1974.41000000", "0.00000000"], ["1974.34000000", "0.00760000"], ["1974.31000000", "1.02930000"], ["1974.30000000", "5.47150000"], ["1974.25000000", "0.00000000"], ["1974.23000000", "25.81940000"], ["1974.22000000", "0.00740000"], ["1974.21000000", "7.18160000"], ["1974.16000000", "0.21310000"], ["1974.11000000", "29.77030000"], ["1974.05000000", "16.56300000"], ["1974.02000000", "4.72970000"], ["1973.95000000", "9.02740000"], ["1973.91000000", "29.68950000"], ["1973.81000000", "14.32000000"], ["1973.74000000", "7.32570000"], ["1973.71000000", "8.48840000"], ["1973.68000000", "49.35810000"], ["1973.66000000", "0.90400000"], ["1973.49000000", "0.05060000"], ["1973.30000000", "11.32620000"], ["1973.15000000", "4.82480000"], ["1973.12000000", "0.03000000"], ["1972.75000000", "5.11050000"], ["1972.44000000", "2.65480000"], ["1972.41000000", "7.34410000"], ["1972.22000000", "0.05080000"], ["1969.02000000", "1.76500000"], ["1969.01000000", "0.61200000"], ["1968.92000000", "0.13440000"], ["1967.62000000", "0.00000000"], ["1965.92000000", "0.95770000"], ["1935.24000000", "0.00000000"], ["1777.30000000", "0.00000000"], ["1777.27000000", "0.00620000"], ["1192.00000000", "0.00000000"]], "a": [["1974.75000000", "138.10260000"], ["1974.76000000", "22.10730000"], ["1974.77000000", "4.98220000"], ["1974.78000000", "19.21080000"], ["1974.79000000", "0.00000000"], ["1974.80000000", "22.72060000"], ["1974.82000000", "0.00000000"], ["1974.83000000", "4.29260000"], ["1974.89000000", "0.00000000"], ["1974.90000000", "0.01730000"], ["1974.95000000", "0.00000000"], ["1974.96000000", "1.23550000"], ["1975.24000000", "0.00000000"], ["1975.37000000", "4.65700000"], ["1975.38000000", "8.50990000"], ["1975.54000000", "0.00380000"], ["1975.81000000", "0.57130000"], ["1975.98000000", "5.08020000"], ["1976.18000000", "1.20550000"], ["1976.80000000", "7.87480000"], ["1977.21000000", "1.08220000"], ["1978.25000000", "0.00000000"], ["1979.78000000", "1.80310000"], ["1980.07000000", "0.03290000"], ["1980.32000000", "0.00000000"], ["1980.36000000", "0.00000000"], ["1980.37000000", "0.16310000"], ["1980.46000000", "0.00260000"], ["1980.77000000", "0.38130000"], ["1984.65000000", "0.01850000"], ["1990.30000000", "0.00000000"], ["1996.34000000", "0.14620000"], ["2020.66000000", "0.00450000"], ["2069.20000000", "0.51380000"], ["2089.10000000", "0.01810000"], ["2148.78000000", "0.50260000"], ["2172.26000000", "0.00520000"], ["2188.58000000", "0.51500000"], ["2208.47000000", "0.00000000"], ["2248.27000000", "0.00770000"], ["2288.06000000", "0.00570000"], ["2307.95000000", "0.50000000"], ["2327.85000000", "0.00000000"], ["2347.75000000", "0.50000000"], ["2367.64000000", "0.04890000"], ["2387.54000000", "0.00280000"], ["2407.44000000", "1.00960000"], ["2427.33000000", "0.02710000"], ["2447.23000000", "0.00490000"], ["2467.12000000", "0.00000000"], ["2487.02000000", "0.00280000"], ["2506.92000000", "0.00220000"], ["2526.81000000", "0.00000000"], ["2546.71000000", "0.00000000"], ["2586.50000000", "0.00000000"], ["2606.40000000", "0.00240000"], ["2626.29000000", "0.03950000"], ["2646.19000000", "0.00400000"], ["2705.88000000", "0.16070000"], ["2725.77000000", "0.00000000"], ["2765.57000000", "0.00000000"], ["2805.36000000", "0.00640000"], ["2825.26000000", "0.00000000"], ["2865.05000000", "0.00000000"], ["2884.94000000", "0.00000000"], ["2904.84000000", "0.00000000"], ["2924.74000000", "0.00000000"], ["3004.32000000", "0.00000000"], ["3024.22000000", "0.00000000"], ["3044.11000000", "0.04750000"], ["3064.01000000", "0.00000000"], ["3103.80000000", "0.00510000"], ["3123.70000000", "0.11400000"], ["3163.49000000", "0.00000000"], ["3183.39000000", "0.01670000"], ["3203.28000000", "0.00000000"], ["3223.18000000", "0.00000000"], ["3243.08000000", "0.00000000"], ["3342.56000000", "0.00000000"], ["3402.25000000", "0.04030000"], ["3442.04000000", "0.00000000"], ["3481.83000000", "0.00000000"], ["3561.41000000", "0.00000000"], ["3621.10000000", "0.00000000"], ["3680.79000000", "0.00180000"], ["3700.69000000", "0.00480000"], ["3720.58000000", "0.00400000"], ["3760.38000000", "0.00000000"], ["3800.17000000", "0.00000000"], ["3820.07000000", "0.00000000"], ["3879.75000000", "0.01350000"], ["3899.65000000", "0.00320000"], ["3939.44000000", "0.00000000"], ["3959.34000000", "0.00000000"]], "_local_ts_utc": "2026-06-01T07:48:52.712261+00:00"}
{"e": "depthUpdate", "E": 1780300133915, "s": "ETHUSDT", "U": 76583064148, "u": 76583064911, "b": [["1974.74000000", "0.00000000"], ["1974.73000000", "0.00000000"], ["1974.72000000", "0.00000000"], ["1974.70000000", "0.00000000"], ["1974.69000000", "0.00000000"], ["1974.68000000", "0.00000000"], ["1974.67000000", "0.00000000"], ["1974.66000000", "0.00000000"], ["1974.65000000", "0.00000000"], ["1974.64000000", "0.00000000"], ["1974.63000000", "0.00000000"], ["1974.61000000", "0.00000000"], ["1974.60000000", "8.68990000"], ["1974.59000000", "0.01470000"], ["1974.58000000", "0.02740000"], ["1974.56000000", "0.01800000"], ["1974.55000000", "0.03750000"], ["1974.54000000", "0.01420000"], ["1974.53000000", "0.00740000"], ["1974.52000000", "0.07950000"], ["1974.50000000", "0.07330000"], ["1974.49000000", "0.00540000"], ["1974.48000000", "0.05240000"], ["1974.47000000", "0.09880000"], ["1974.45000000", "0.00000000"], ["1974.44000000", "0.02850000"], ["1974.43000000", "0.00940000"], ["1974.40000000", "0.01480000"], ["1974.39000000", "0.34750000"], ["1974.36000000", "0.08860000"], ["1974.35000000", "0.03730000"], ["1974.32000000", "0.00000000"], ["1974.31000000", "0.00270000"], ["1974.30000000", "0.00520000"], ["1974.26000000", "1.79850000"], ["1974.24000000", "3.49660000"], ["1974.23000000", "10.22350000"], ["1974.21000000", "0.09260000"], ["1974.20000000", "12.37010000"], ["1974.19000000", "6.47280000"], ["1974.14000000", "1.43720000"], ["1974.13000000", "0.00500000"], ["1974.12000000", "0.00770000"], ["1974.11000000", "0.10760000"], ["1974.10000000", "19.93000000"], ["1974.06000000", "0.07050000"], ["1974.05000000", "3.06000000"], ["1974.04000000", "0.00000000"], ["1974.03000000", "0.01020000"], ["1974.02000000", "11.81870000"], ["1974.01000000", "1.05530000"], ["1973.95000000", "14.75930000"], ["1973.94000000", "0.20720000"], ["1973.93000000", "15.91960000"], ["1973.92000000", "7.11900000"], ["1973.90000000", "0.02280000"], ["1973.89000000", "28.38580000"], ["1973.88000000", "11.70270000"], ["1973.87000000", "0.74950000"], ["1973.83000000", "15.63820000"], ["1973.78000000", "0.00260000"], ["1973.75000000", "7.35330000"], ["1973.74000000", "13.50300000"], ["1973.73000000", "1.55720000"], ["1973.70000000", "0.66420000"], ["1973.69000000", "24.03860000"], ["1973.66000000", "0.50400000"], ["1973.65000000", "3.60420000"], ["1973.63000000", "9.51590000"], ["1973.61000000", "15.23910000"], ["1973.60000000", "13.59590000"], ["1973.57000000", "2.16340000"], ["1973.55000000", "0.01080000"], ["1973.53000000", "0.03010000"], ["1973.52000000", "7.51350000"], ["1973.50000000", "10.72280000"], ["1973.44000000", "1.34180000"], ["1973.43000000", "1.21690000"], ["1973.39000000", "15.75580000"], ["1973.38000000", "1.21810000"], ["1973.31000000", "22.95750000"], ["1973.29000000", "0.01100000"], ["1973.28000000", "0.31330000"], ["1973.25000000", "14.17530000"], ["1973.23000000", "7.42600000"], ["1973.21000000", "7.88900000"], ["1973.20000000", "1.45880000"], ["1973.11000000", "8.78620000"], ["1972.96000000", "0.04270000"], ["1972.70000000", "1.57640000"], ["1972.44000000", "6.98590000"], ["1972.42000000", "15.68840000"], ["1972.30000000", "12.21240000"], ["1972.29000000", "13.55630000"], ["1972.22000000", "14.22880000"], ["1972.20000000", "0.00830000"], ["1972.15000000", "0.01020000"], ["1972.14000000", "3.17770000"], ["1972.13000000", "10.58070000"], ["1972.09000000", "17.76570000"], ["1972.02000000", "0.00270000"], ["1972.01000000", "29.48760000"], ["1971.75000000", "1.03100000"], ["1970.63000000", "13.50560000"], ["1970.56000000", "0.21160000"], ["1970.50000000", "71.27930000"], ["1970.42000000", "0.00260000"], ["1970.35000000", "106.62970000"], ["1968.92000000", "0.13180000"], ["1968.39000000", "0.00000000"], ["1968.14000000", "0.02190000"], ["1967.44000000", "0.00260000"], ["1967.24000000", "0.00000000"], ["1967.10000000", "0.04200000"], ["1966.62000000", "127.48370000"], ["1965.53000000", "2.34910000"], ["1965.48000000", "5.00880000"], ["1965.22000000", "0.20160000"], ["1964.81000000", "0.00000000"], ["1964.52000000", "1.55530000"], ["1935.19000000", "0.00000000"], ["1777.27000000", "0.00000000"], ["1777.14000000", "0.00920000"]], "a": [["1974.61000000", "111.85200000"], ["1974.62000000", "0.00510000"], ["1974.63000000", "0.00510000"], ["1974.64000000", "9.49760000"], ["1974.65000000", "25.00740000"], ["1974.66000000", "0.00000000"], ["1974.67000000", "0.00000000"], ["1974.68000000", "0.00000000"], ["1974.69000000", "42.04580000"], ["1974.70000000", "21.09870000"], ["1974.71000000", "1.10090000"], ["1974.72000000", "0.03000000"], ["1974.73000000", "0.00000000"], ["1974.74000000", "4.97710000"], ["1974.75000000", "13.30980000"], ["1974.76000000", "0.77920000"], ["1974.77000000", "0.00000000"], ["1974.78000000", "12.63120000"], ["1974.79000000", "0.00000000"], ["1974.81000000", "0.20000000"], ["1974.82000000", "3.17690000"], ["1974.83000000", "4.18000000"], ["1974.90000000", "0.00570000"], ["1974.92000000", "0.41260000"], ["1974.94000000", "8.51370000"], ["1974.97000000", "0.00000000"], ["1975.05000000", "1.51560000"], ["1975.11000000", "0.00000000"], ["1975.26000000", "0.00260000"], ["1975.31000000", "0.38330000"], ["1975.35000000", "0.00260000"], ["1975.37000000", "4.65960000"], ["1975.39000000", "7.36080000"], ["1975.42000000", "0.20070000"], ["1975.51000000", "8.50950000"], ["1975.60000000", "14.63780000"], ["1975.70000000", "0.00310000"], ["1975.73000000", "0.00000000"], ["1975.84000000", "0.00260000"], ["1975.86000000", "1.50760000"], ["1975.90000000", "14.17690000"], ["1975.92000000", "0.00000000"], ["1975.95000000", "0.00000000"], ["1976.10000000", "15.80440000"], ["1976.11000000", "0.04570000"], ["1976.18000000", "1.20810000"], ["1976.27000000", "8.08470000"], ["1976.39000000", "0.22810000"], ["1976.80000000", "12.86430000"], ["1976.81000000", "0.00300000"], ["1976.83000000", "14.78980000"], ["1976.88000000", "32.46540000"], ["1977.39000000", "15.01020000"], ["1977.49000000", "0.00000000"], ["1978.00000000", "0.00580000"], ["1978.10000000", "0.00000000"], ["1978.24000000", "0.00000000"], ["1978.41000000", "3.60000000"], ["1978.94000000", "0.00000000"], ["1979.06000000", "0.00320000"], ["1979.70000000", "0.25090000"], ["1979.71000000", "0.00260000"], ["1979.75000000", "0.00000000"], ["1980.14000000", "0.00260000"], ["1980.31000000", "0.13110000"], ["1980.64000000", "1.04570000"], ["1980.70000000", "0.95540000"], ["1981.11000000", "0.18150000"], ["1982.00000000", "0.00310000"], ["1982.36000000", "1.22740000"], ["1982.74000000", "1.20550000"], ["1983.05000000", "0.00650000"], ["1983.18000000", "0.48790000"], ["1983.42000000", "3.50710000"], ["1984.13000000", "0.00000000"], ["1984.41000000", "0.00000000"], ["1985.43000000", "0.01480000"], ["1985.79000000", "0.01550000"], ["1985.94000000", "0.00000000"], ["1987.30000000", "0.00000000"], ["1989.83000000", "3.13560000"], ["1990.08000000", "0.00710000"], ["1993.33000000", "0.09010000"], ["2001.65000000", "0.00000000"], ["2055.26000000", "1.81510000"], ["2172.26000000", "0.00260000"]], "_local_ts_utc": "2026-06-01T07:48:52.811786+00:00"}
{"e": "depthUpdate", "E": 1780300134015, "s": "ETHUSDT", "U": 76583064912, "u": 76583065225, "b": [["1974.60000000", "32.82850000"], ["1974.59000000", "0.01210000"], ["1974.55000000", "10.17910000"], ["1974.53000000", "3.08570000"], ["1974.52000000", "0.07950000"], ["1974.44000000", "0.03390000"], ["1974.43000000", "0.00400000"], ["1974.42000000", "0.18820000"], ["1974.41000000", "0.00540000"], ["1974.40000000", "1.96130000"], ["1974.39000000", "0.34750000"], ["1974.38000000", "0.05320000"], ["1974.36000000", "0.08320000"], ["1974.35000000", "0.03990000"], ["1974.32000000", "6.46760000"], ["1974.31000000", "0.00000000"], ["1974.27000000", "0.00620000"], ["1974.25000000", "9.33040000"], ["1974.24000000", "22.72260000"], ["1974.20000000", "10.21970000"], ["1974.19000000", "0.00520000"], ["1974.14000000", "22.81400000"], ["1974.13000000", "1.29110000"], ["1974.11000000", "22.68130000"], ["1974.10000000", "17.49770000"], ["1974.03000000", "29.10910000"], ["1973.98000000", "0.02220000"], ["1973.97000000", "1.27670000"], ["1973.90000000", "19.43630000"], ["1973.88000000", "0.76520000"], ["1973.59000000", "0.22230000"], ["1973.56000000", "0.07050000"], ["1973.42000000", "13.50810000"], ["1973.39000000", "15.65580000"], ["1973.20000000", "1.48880000"], ["1972.96000000", "0.01270000"], ["1972.81000000", "7.56030000"], ["1972.58000000", "0.00000000"], ["1972.44000000", "4.56940000"], ["1972.43000000", "14.55980000"], ["1972.42000000", "0.09250000"], ["1972.41000000", "0.25510000"], ["1972.22000000", "0.05080000"], ["1971.37000000", "0.13160000"], ["1970.95000000", "2.14170000"], ["1970.91000000", "0.00000000"], ["1970.75000000", "2.88930000"], ["1970.73000000", "0.81330000"], ["1970.63000000", "0.00260000"], ["1969.07000000", "0.32660000"], ["1968.89000000", "0.00260000"], ["1968.20000000", "1.33490000"], ["1967.52000000", "0.00740000"], ["1966.86000000", "0.01650000"], ["1965.89000000", "2.27640000"], ["1956.68000000", "0.04620000"], ["1935.10000000", "27.66560000"], ["1777.14000000", "0.02160000"]], "a": [["1974.61000000", "37.79010000"], ["1974.62000000", "0.00510000"], ["1974.63000000", "0.01050000"], ["1974.64000000", "3.03000000"], ["1974.65000000", "0.00740000"], ["1974.67000000", "0.00000000"], ["1974.68000000", "0.00000000"], ["1974.69000000", "0.00000000"], ["1974.70000000", "0.01490000"], ["1974.71000000", "1.00770000"], ["1974.72000000", "0.03540000"], ["1974.73000000", "1.34400000"], ["1974.74000000", "0.00270000"], ["1974.75000000", "0.00000000"], ["1974.76000000", "0.00000000"], ["1974.78000000", "8.75410000"], ["1974.79000000", "0.00000000"], ["1974.80000000", "0.03570000"], ["1974.81000000", "0.00000000"], ["1974.83000000", "3.45960000"], ["1974.84000000", "0.00260000"], ["1974.85000000", "0.00000000"], ["1974.86000000", "0.01010000"], ["1974.88000000", "5.00710000"], ["1974.89000000", "0.01160000"], ["1974.93000000", "2.58220000"], ["1974.96000000", "0.03000000"], ["1975.00000000", "9.74800000"], ["1975.01000000", "13.50740000"], ["1975.03000000", "0.03300000"], ["1975.05000000", "1.30300000"], ["1975.06000000", "0.68600000"], ["1975.29000000", "3.70130000"], ["1975.39000000", "7.08900000"], ["1975.40000000", "19.86720000"], ["1975.62000000", "0.00260000"], ["1975.66000000", "0.15110000"], ["1975.77000000", "0.00000000"], ["1975.86000000", "0.10760000"], ["1975.87000000", "6.85690000"], ["1975.88000000", "8.72740000"], ["1975.89000000", "0.03300000"], ["1975.93000000", "1.40300000"], ["1976.00000000", "18.97880000"], ["1976.04000000", "8.50990000"], ["1976.09000000", "0.00000000"], ["1976.20000000", "3.97870000"], ["1976.27000000", "7.08910000"], ["1976.29000000", "7.65600000"], ["1976.30000000", "5.12010000"], ["1976.40000000", "9.01400000"], ["1976.49000000", "14.17800000"], ["1976.71000000", "7.08900000"], ["1976.80000000", "7.44580000"], ["1976.88000000", "0.81000000"], ["1977.16000000", "0.00000000"], ["1978.00000000", "10.58250000"], ["1978.10000000", "27.59080000"], ["1980.21000000", "0.00000000"], ["1980.27000000", "22.83480000"], ["1980.37000000", "0.16050000"], ["1980.46000000", "0.00000000"], ["1982.58000000", "129.85710000"], ["1985.20000000", "0.00000000"], ["1985.62000000", "0.02780000"], ["2010.83000000", "0.00480000"], ["2474.96000000", "0.00000000"]], "_local_ts_utc": "2026-06-01T07:48:52.911826+00:00"}
{"e": "depthUpdate", "E": 1780300134115, "s": "ETHUSDT", "U": 76583065226, "u": 76583065471, "b": [["1974.60000000", "48.80870000"], ["1974.59000000", "4.95100000"], ["1974.58000000", "10.16880000"], ["1974.57000000", "0.00000000"], ["1974.56000000", "0.02340000"], ["1974.55000000", "6.50510000"], ["1974.54000000", "0.01420000"], ["1974.53000000", "0.00740000"], ["1974.47000000", "0.09340000"], ["1974.46000000", "0.51030000"], ["1974.45000000", "0.00000000"], ["1974.44000000", "0.02850000"], ["1974.41000000", "0.00000000"], ["1974.40000000", "0.03940000"], ["1974.35000000", "4.70970000"], ["1974.34000000", "22.69560000"], ["1974.32000000", "0.03000000"], ["1974.31000000", "0.00000000"], ["1974.28000000", "1.35270000"], ["1974.25000000", "20.33890000"], ["1974.23000000", "0.00000000"], ["1974.21000000", "0.09520000"], ["1974.20000000", "16.36290000"], ["1974.13000000", "0.00500000"], ["1974.01000000", "1.10560000"], ["1973.97000000", "0.00000000"], ["1973.87000000", "0.74950000"], ["1973.80000000", "0.11080000"], ["1973.76000000", "0.08030000"], ["1973.72000000", "0.68130000"], ["1973.69000000", "24.23860000"], ["1973.66000000", "0.10400000"], ["1973.63000000", "9.13780000"], ["1973.59000000", "0.12230000"], ["1973.50000000", "10.72280000"], ["1973.43000000", "1.01690000"], ["1973.28000000", "1.11330000"], ["1973.21000000", "7.08900000"], ["1973.20000000", "1.45880000"], ["1973.12000000", "0.00000000"], ["1972.76000000", "0.27550000"], ["1972.75000000", "2.97670000"], ["1972.74000000", "0.00300000"], ["1972.66000000", "0.30920000"], ["1972.62000000", "0.01640000"], ["1972.61000000", "0.00260000"], ["1971.20000000", "3.58350000"], ["1971.19000000", "7.10180000"], ["1970.73000000", "0.02000000"], ["1970.44000000", "0.00000000"], ["1970.23000000", "0.00000000"], ["1970.17000000", "7.59160000"], ["1969.57000000", "0.00270000"], ["1968.91000000", "0.00000000"], ["1968.69000000", "0.58100000"], ["1967.10000000", "0.05010000"], ["1966.86000000", "0.00730000"], ["1955.46000000", "0.13340000"], ["1777.14000000", "0.03400000"]], "a": [["1974.61000000", "0.78790000"], ["1974.64000000", "3.00000000"], ["1974.65000000", "0.00740000"], ["1974.70000000", "0.00570000"], ["1974.71000000", "0.00000000"], ["1974.72000000", "0.03000000"], ["1974.73000000", "0.00000000"], ["1974.74000000", "0.00000000"], ["1974.77000000", "0.00000000"], ["1974.78000000", "0.00000000"], ["1974.81000000", "0.00540000"], ["1974.82000000", "2.38220000"], ["1974.83000000", "2.82310000"], ["1974.84000000", "0.00260000"], ["1974.86000000", "0.00000000"], ["1974.87000000", "0.00260000"], ["1974.89000000", "0.00000000"], ["1974.93000000", "8.59910000"], ["1974.94000000", "0.00680000"], ["1975.01000000", "0.00260000"], ["1975.02000000", "7.10060000"], ["1975.05000000", "1.31460000"], ["1975.10000000", "0.01580000"], ["1975.11000000", "0.56700000"], ["1975.15000000", "8.65160000"], ["1975.16000000", "13.50780000"], ["1975.17000000", "0.00000000"], ["1975.19000000", "7.11130000"], ["1975.20000000", "0.03570000"], ["1975.31000000", "0.00520000"], ["1975.41000000", "13.50300000"], ["1976.00000000", "19.00880000"], ["1976.20000000", "7.65800000"], ["1976.26000000", "0.00300000"], ["1976.35000000", "2.35870000"], ["1976.48000000", "7.09300000"], ["1976.49000000", "7.08900000"], ["1976.70000000", "2.90560000"], ["1976.71000000", "7.09000000"], ["1976.76000000", "0.03290000"], ["1976.80000000", "6.95980000"], ["1977.10000000", "6.43070000"], ["1977.16000000", "13.50480000"], ["1977.36000000", "0.00940000"], ["1977.83000000", "16.93780000"], ["1978.25000000", "15.78350000"], ["1978.29000000", "0.02180000"], ["1978.42000000", "0.01020000"], ["1978.88000000", "0.02320000"], ["1980.14000000", "0.00000000"], ["1980.15000000", "0.00000000"], ["1992.78000000", "0.03000000"], ["1994.49000000", "0.12650000"]], "_local_ts_utc": "2026-06-01T07:48:53.011697+00:00"}
{"e": "depthUpdate", "E": 1780300134215, "s": "ETHUSDT", "U": 76583065472, "u": 76583065551, "b": [["1974.60000000", "48.81380000"], ["1974.59000000", "4.95610000"], ["1974.58000000", "10.17390000"], ["1974.48000000", "0.08240000"], ["1974.47000000", "0.09880000"], ["1974.46000000", "7.35280000"], ["1974.45000000", "7.09000000"], ["1974.44000000", "15.62650000"], ["1974.37000000", "13.56450000"], ["1974.36000000", "22.65690000"], ["1974.35000000", "0.04510000"], ["1974.26000000", "12.44780000"], ["1974.25000000", "13.50480000"], ["1974.21000000", "0.09780000"], ["1974.00000000", "17.46740000"], ["1973.91000000", "29.73980000"], ["1973.84000000", "0.31220000"], ["1973.66000000", "0.15430000"], ["1973.61000000", "16.61910000"], ["1973.50000000", "11.52280000"], ["1973.28000000", "0.28330000"], ["1973.21000000", "9.71520000"], ["1972.94000000", "20.59460000"], ["1972.86000000", "1.43750000"], ["1972.82000000", "0.04550000"], ["1972.81000000", "0.47130000"], ["1972.66000000", "1.47030000"], ["1971.97000000", "0.00560000"], ["1777.14000000", "0.04640000"]], "a": [["1974.61000000", "8.96720000"], ["1974.65000000", "0.10740000"], ["1974.67000000", "0.00260000"], ["1974.82000000", "0.89330000"], ["1974.83000000", "2.82610000"], ["1974.87000000", "0.00000000"], ["1974.88000000", "0.03000000"], ["1974.91000000", "0.05000000"], ["1974.92000000", "0.00260000"], ["1974.93000000", "0.09110000"], ["1975.00000000", "9.78330000"], ["1975.08000000", "6.47020000"], ["1975.29000000", "3.60000000"], ["1975.37000000", "7.28730000"], ["1975.61000000", "0.51300000"], ["1975.62000000", "0.17310000"], ["1976.20000000", "7.65800000"], ["1976.26000000", "8.51100000"], ["1976.70000000", "4.65090000"], ["1976.85000000", "0.00000000"], ["1978.13000000", "0.00000000"], ["1979.55000000", "23.92370000"], ["1979.78000000", "0.23310000"]], "_local_ts_utc": "2026-06-01T07:48:53.111292+00:00"}
{"e": "depthUpdate", "E": 1780300134315, "s": "ETHUSDT", "U": 76583065552, "u": 76583065566, "b": [["1974.60000000", "48.86610000"], ["1974.21000000", "0.10300000"], ["1974.12000000", "1.28440000"], ["1974.02000000", "12.19680000"], ["1973.82000000", "2.69710000"], ["1973.32000000", "0.23830000"], ["1969.16000000", "35.72870000"], ["1777.14000000", "0.05260000"]], "a": [["1974.63000000", "0.94050000"], ["1974.72000000", "0.00000000"], ["1975.43000000", "0.00000000"], ["1975.64000000", "0.37810000"], ["1976.08000000", "9.88600000"], ["1979.58000000", "36.21670000"]], "_local_ts_utc": "2026-06-01T07:48:53.210840+00:00"}
{"e": "depthUpdate", "E": 1780300134415, "s": "ETHUSDT", "U": 76583065567, "u": 76583065699, "b": [["1974.60000000", "3.78280000"], ["1974.59000000", "0.02520000"], ["1974.58000000", "0.03250000"], ["1974.55000000", "0.03750000"], ["1974.48000000", "0.08780000"], ["1974.47000000", "0.09880000"], ["1974.46000000", "0.51030000"], ["1974.45000000", "0.00000000"], ["1974.44000000", "6.49610000"], ["1974.38000000", "10.25860000"], ["1974.37000000", "6.82620000"], ["1974.36000000", "0.08320000"], ["1974.34000000", "0.00760000"], ["1974.32000000", "4.43400000"], ["1974.25000000", "0.00000000"], ["1974.10000000", "16.87560000"], ["1974.02000000", "7.79380000"], ["1974.01000000", "1.37560000"], ["1974.00000000", "13.86740000"], ["1973.93000000", "15.91960000"], ["1973.80000000", "0.01080000"], ["1973.71000000", "8.48840000"], ["1973.68000000", "49.35810000"], ["1973.65000000", "3.70420000"], ["1973.50000000", "10.72280000"], ["1973.45000000", "3.82220000"], ["1973.43000000", "1.81690000"], ["1972.95000000", "8.50800000"], ["1972.81000000", "14.65130000"], ["1972.35000000", "0.22640000"], ["1900.00000000", "2701.22430000"], ["1811.88000000", "0.00380000"], ["1777.14000000", "0.06500000"], ["1666.66000000", "5.18850000"]], "a": [["1974.61000000", "36.49630000"], ["1974.62000000", "0.01050000"], ["1974.64000000", "3.00260000"], ["1974.65000000", "0.00740000"], ["1974.81000000", "0.00000000"], ["1974.82000000", "0.89950000"], ["1974.84000000", "6.47020000"], ["1974.86000000", "1.28790000"], ["1974.89000000", "0.01160000"], ["1974.91000000", "0.68870000"], ["1974.95000000", "2.11210000"], ["1974.96000000", "0.03000000"], ["1975.05000000", "1.30300000"], ["1975.08000000", "0.00260000"], ["1975.22000000", "9.10090000"], ["1975.92000000", "0.03000000"], ["1976.08000000", "9.85600000"], ["1977.33000000", "0.00000000"]], "_local_ts_utc": "2026-06-01T07:48:53.311714+00:00"}
{"e": "depthUpdate", "E": 1780300134515, "s": "ETHUSDT", "U": 76583065700, "u": 76583065834, "b": [["1974.60000000", "20.31630000"], ["1974.59000000", "0.01980000"], ["1974.56000000", "0.01800000"], ["1974.48000000", "0.05240000"], ["1974.46000000", "10.65230000"], ["1974.45000000", "0.00000000"], ["1974.44000000", "0.02850000"], ["1974.40000000", "0.03940000"], ["1974.39000000", "0.34750000"], ["1974.38000000", "0.05320000"], ["1974.37000000", "0.00280000"], ["1974.36000000", "0.08860000"], ["1974.35000000", "7.66200000"], ["1974.34000000", "6.47520000"], ["1974.33000000", "0.00000000"], ["1974.31000000", "0.00000000"], ["1974.30000000", "10.20830000"], ["1974.28000000", "0.03550000"], ["1974.26000000", "8.99240000"], ["1974.21000000", "1.41860000"], ["1974.19000000", "0.65370000"], ["1973.97000000", "0.27000000"], ["1973.87000000", "0.54950000"], ["1973.72000000", "0.48130000"], ["1973.65000000", "4.10420000"], ["1973.45000000", "3.82220000"], ["1973.43000000", "1.81690000"], ["1973.21000000", "7.08900000"], ["1973.04000000", "0.03000000"], ["1972.86000000", "5.48750000"], ["1972.31000000", "0.32590000"], ["1777.14000000", "0.07120000"]], "a": [["1974.61000000", "50.79830000"], ["1974.67000000", "0.00260000"], ["1974.72000000", "0.03000000"], ["1974.74000000", "0.00540000"], ["1974.75000000", "1.28030000"], ["1974.82000000", "5.13020000"], ["1974.86000000", "1.91610000"], ["1974.90000000", "14.18570000"], ["1974.93000000", "2.80720000"], ["1974.94000000", "8.51480000"], ["1974.95000000", "0.00000000"], ["1975.00000000", "9.75960000"], ["1975.02000000", "7.08900000"], ["1975.26000000", "0.56960000"], ["1975.29000000", "3.70130000"], ["1975.84000000", "0.03260000"], ["1975.92000000", "0.00000000"], ["1976.00000000", "18.97880000"], ["1976.26000000", "0.00300000"], ["1976.48000000", "0.00300000"], ["1976.70000000", "2.90560000"], ["1976.71000000", "0.00000000"], ["1976.79000000", "0.56700000"], ["1976.80000000", "15.77920000"], ["1976.88000000", "32.46540000"], ["1981.94000000", "0.00260000"]], "_local_ts_utc": "2026-06-01T07:48:53.411812+00:00"}
{"e": "depthUpdate", "E": 1780300134615, "s": "ETHUSDT", "U": 76583065835, "u": 76583065960, "b": [["1974.60000000", "28.50730000"], ["1974.55000000", "0.03750000"], ["1974.49000000", "0.00540000"], ["1974.48000000", "0.05240000"], ["1974.46000000", "0.51030000"], ["1974.43000000", "0.00940000"], ["1974.40000000", "0.04480000"], ["1974.36000000", "0.08860000"], ["1974.35000000", "7.65660000"], ["1974.26000000", "8.49720000"], ["1974.25000000", "15.59800000"], ["1974.24000000", "0.03770000"], ["1974.15000000", "22.23020000"], ["1974.14000000", "0.12910000"], ["1974.12000000", "8.37440000"], ["1974.10000000", "11.75410000"], ["1974.04000000", "13.50480000"], ["1974.03000000", "15.60610000"], ["1973.81000000", "17.36330000"], ["1973.72000000", "0.88130000"], ["1973.65000000", "3.70420000"], ["1973.43000000", "1.81690000"], ["1972.76000000", "5.59360000"], ["1972.75000000", "8.79060000"], ["1972.66000000", "5.55460000"], ["1972.61000000", "14.18260000"], ["1972.58000000", "0.00000000"], ["1972.41000000", "0.25510000"], ["1971.86000000", "0.00850000"], ["1971.26000000", "12.92960000"], ["1971.25000000", "17.11620000"], ["1971.24000000", "0.00000000"], ["1954.17000000", "2.51520000"], ["1777.14000000", "0.08360000"]], "a": [["1974.61000000", "27.32100000"], ["1974.74000000", "0.00000000"], ["1974.75000000", "0.00000000"], ["1974.76000000", "0.00000000"], ["1974.80000000", "10.78580000"], ["1974.81000000", "9.78540000"], ["1974.82000000", "0.04460000"], ["1974.88000000", "0.36000000"], ["1974.89000000", "0.01160000"], ["1975.68000000", "1.54740000"], ["1976.04000000", "0.00300000"], ["1977.10000000", "6.43070000"], ["1977.15000000", "13.50480000"], ["1977.16000000", "0.00000000"]], "_local_ts_utc": "2026-06-01T07:48:53.510747+00:00"}
{"e": "depthUpdate", "E": 1780300134715, "s": "ETHUSDT", "U": 76583065961, "u": 76583066060, "b": [["1974.60000000", "46.91000000"], ["1974.59000000", "3.12290000"], ["1974.58000000", "10.17390000"], ["1974.47000000", "0.09340000"], ["1974.45000000", "6.46760000"], ["1974.43000000", "0.00400000"], ["1974.40000000", "0.03940000"], ["1974.36000000", "0.08320000"], ["1974.35000000", "6.89380000"], ["1974.34000000", "0.00760000"], ["1974.30000000", "0.00520000"], ["1974.28000000", "0.03290000"], ["1974.22000000", "7.09740000"], ["1974.12000000", "7.09770000"], ["1974.11000000", "22.68390000"], ["1974.10000000", "16.28200000"], ["1974.00000000", "17.46740000"], ["1972.31000000", "0.05590000"], ["1944.98000000", "0.13250000"], ["1777.14000000", "0.09600000"]], "a": [["1974.61000000", "5.46340000"], ["1974.79000000", "0.00540000"], ["1974.80000000", "7.72800000"], ["1974.81000000", "0.00000000"], ["1974.82000000", "0.03840000"], ["1974.83000000", "2.82880000"], ["1974.86000000", "0.00000000"], ["1974.89000000", "14.19160000"], ["1974.90000000", "0.00570000"], ["1974.91000000", "0.05260000"], ["1975.08000000", "0.00000000"], ["1975.37000000", "4.65960000"], ["1976.04000000", "8.51100000"], ["1976.35000000", "1.35540000"], ["1976.48000000", "0.00300000"], ["1976.71000000", "0.00000000"], ["1976.79000000", "0.00000000"], ["1976.80000000", "6.95980000"], ["1976.88000000", "0.81000000"], ["1982.51000000", "0.18210000"], ["1982.62000000", "126.25480000"], ["1983.60000000", "0.00310000"]], "_local_ts_utc": "2026-06-01T07:48:53.611313+00:00"}
{"e": "depthUpdate", "E": 1780300134815, "s": "ETHUSDT", "U": 76583066061, "u": 76583066132, "b": [["1974.60000000", "52.65960000"], ["1974.59000000", "0.01740000"], ["1974.50000000", "0.35670000"], ["1974.47000000", "0.09880000"], ["1974.46000000", "0.51570000"], ["1974.36000000", "1.42500000"], ["1974.35000000", "0.04510000"], ["1974.32000000", "11.52400000"], ["1974.30000000", "0.00830000"], ["1974.26000000", "14.06280000"], ["1974.21000000", "14.92340000"], ["1974.13000000", "0.00500000"], ["1972.61000000", "7.09260000"], ["1971.26000000", "8.89840000"], ["1971.25000000", "3.61140000"], ["1777.14000000", "0.10840000"]], "a": [["1974.61000000", "3.28660000"], ["1974.62000000", "0.00510000"], ["1974.63000000", "0.01050000"], ["1974.67000000", "0.00000000"], ["1974.72000000", "0.00000000"], ["1974.80000000", "0.99350000"], ["1974.83000000", "2.82610000"], ["1974.84000000", "0.00260000"], ["1974.88000000", "0.03000000"], ["1974.89000000", "0.01160000"], ["1974.93000000", "4.39050000"], ["1974.99000000", "6.46760000"], ["1975.03000000", "0.05720000"], ["1976.04000000", "12.48500000"], ["1976.48000000", "7.09300000"], ["1976.70000000", "4.65180000"], ["1976.71000000", "7.09000000"], ["1977.28000000", "0.78600000"]], "_local_ts_utc": "2026-06-01T07:48:53.711524+00:00"}
{"e": "depthUpdate", "E": 1780300134915, "s": "ETHUSDT", "U": 76583066133, "u": 76583066176, "b": [["1974.59000000", "3.20750000"], ["1974.46000000", "2.51850000"], ["1974.36000000", "9.84770000"], ["1974.35000000", "15.64310000"], ["1974.33000000", "22.57370000"], ["1974.14000000", "1.40580000"], ["1973.94000000", "0.80720000"], ["1973.87000000", "0.54950000"], ["1973.72000000", "0.28130000"], ["1973.64000000", "2.56800000"], ["1973.58000000", "0.80000000"], ["1973.43000000", "1.01690000"], ["1972.76000000", "3.05400000"], ["1972.75000000", "0.28260000"], ["1972.66000000", "3.43820000"], ["1972.61000000", "0.00260000"], ["1777.14000000", "0.11460000"]], "a": [["1974.61000000", "0.86620000"], ["1975.05000000", "0.00300000"], ["1975.06000000", "0.48600000"], ["1975.17000000", "0.00260000"], ["1975.24000000", "1.50000000"], ["1975.49000000", "2.62970000"], ["1975.97000000", "0.00260000"]], "_local_ts_utc": "2026-06-01T07:48:53.811210+00:00"}
{"e": "depthUpdate", "E": 1780300135015, "s": "ETHUSDT", "U": 76583066177, "u": 76583066369, "b": [["1974.61000000", "98.85770000"], ["1974.60000000", "3.27390000"], ["1974.59000000", "0.01740000"], ["1974.58000000", "6.49500000"], ["1974.49000000", "0.00280000"], ["1974.48000000", "0.05240000"], ["1974.47000000", "0.09880000"], ["1974.46000000", "0.51030000"], ["1974.45000000", "0.00000000"], ["1974.37000000", "6.07260000"], ["1974.36000000", "0.08320000"], ["1974.33000000", "0.00000000"], ["1974.14000000", "0.39910000"], ["1973.94000000", "0.50850000"], ["1973.89000000", "28.31750000"], ["1973.87000000", "0.67950000"], ["1973.78000000", "0.00260000"], ["1973.70000000", "0.73250000"], ["1973.58000000", "0.80000000"], ["1973.41000000", "21.52870000"], ["1973.15000000", "5.09480000"], ["1972.66000000", "1.47030000"], ["1935.11000000", "0.00000000"], ["1777.15000000", "0.00620000"], ["1777.14000000", "0.00300000"], ["1474.60000000", "0.00000000"]], "a": [["1974.61000000", "0.00000000"], ["1974.62000000", "1.65280000"], ["1974.66000000", "0.00260000"], ["1974.75000000", "0.00760000"], ["1974.79000000", "0.00800000"], ["1974.92000000", "4.65150000"], ["1974.93000000", "8.50800000"], ["1974.94000000", "0.00680000"], ["1974.96000000", "0.03760000"], ["1975.10000000", "0.96080000"], ["1975.18000000", "8.38560000"], ["1975.29000000", "3.60000000"], ["1975.30000000", "0.01330000"], ["1975.55000000", "0.01020000"], ["1975.60000000", "14.64040000"], ["1976.26000000", "0.00300000"], ["1977.27000000", "0.96500000"], ["1979.40000000", "0.18070000"], ["1979.59000000", "3.60000000"], ["1983.18000000", "0.00000000"]], "_local_ts_utc": "2026-06-01T07:48:53.911819+00:00"}
{"e": "depthUpdate", "E": 1780300135115, "s": "ETHUSDT", "U": 76583066370, "u": 76583066403, "b": [["1974.61000000", "98.40090000"], ["1974.60000000", "3.27930000"], ["1974.59000000", "2.10940000"], ["1974.54000000", "0.52120000"], ["1974.47000000", "0.09340000"], ["1974.19000000", "1.93040000"], ["1974.06000000", "0.34050000"], ["1974.04000000", "13.77480000"], ["1973.65000000", "3.60420000"], ["1973.56000000", "0.17050000"], ["1973.07000000", "0.29560000"], ["1973.05000000", "3.87000000"], ["1972.26000000", "54.93860000"], ["1777.15000000", "0.02480000"]], "a": [["1974.62000000", "4.62620000"], ["1974.63000000", "0.91150000"], ["1974.78000000", "0.01160000"], ["1975.25000000", "0.78900000"], ["1975.27000000", "0.81300000"], ["1977.27000000", "0.02000000"]], "_local_ts_utc": "2026-06-01T07:48:54.012192+00:00"}
{"e": "depthUpdate", "E": 1780300135215, "s": "ETHUSDT", "U": 76583066404, "u": 76583066429, "b": [["1974.61000000", "91.37340000"], ["1974.60000000", "3.28190000"], ["1974.55000000", "0.04290000"], ["1974.54000000", "0.01420000"], ["1973.94000000", "0.30850000"], ["1973.87000000", "0.47950000"], ["1973.79000000", "0.00000000"], ["1973.77000000", "0.99240000"], ["1973.58000000", "0.40000000"], ["1973.43000000", "1.81690000"], ["1972.30000000", "28.03980000"], ["1969.17000000", "0.58090000"], ["1968.69000000", "0.00000000"], ["1962.85000000", "0.19760000"], ["1954.17000000", "1.04130000"], ["1777.15000000", "0.03720000"]], "a": [["1974.62000000", "9.60850000"]], "_local_ts_utc": "2026-06-01T07:48:54.111384+00:00"}
{"e": "depthUpdate", "E": 1780300135315, "s": "ETHUSDT", "U": 76583066430, "u": 76583066452, "b": [["1974.61000000", "91.17080000"], ["1974.60000000", "3.15670000"], ["1974.55000000", "0.03750000"], ["1974.47000000", "0.09880000"], ["1974.12000000", "7.90770000"], ["1974.05000000", "3.33000000"], ["1972.73000000", "7.62900000"], ["1972.69000000", "0.27000000"], ["1972.17000000", "0.43110000"], ["1777.15000000", "0.04960000"]], "a": [["1974.62000000", "9.67150000"], ["1975.00000000", "9.22260000"], ["1975.20000000", "1.62870000"], ["1975.27000000", "1.29900000"], ["1977.30000000", "0.00000000"]], "_local_ts_utc": "2026-06-01T07:48:54.211654+00:00"}
{"e": "depthUpdate", "E": 1780300135415, "s": "ETHUSDT", "U": 76583066453, "u": 76583066466, "b": [["1974.61000000", "90.88340000"], ["1974.26000000", "10.71780000"], ["1974.21000000", "1.41860000"], ["1974.12000000", "8.17770000"], ["1973.78000000", "0.17310000"], ["1777.15000000", "0.06200000"]], "a": [["1974.62000000", "9.82150000"], ["1975.03000000", "0.03300000"], ["1975.20000000", "2.06070000"], ["1977.11000000", "1.52040000"]], "_local_ts_utc": "2026-06-01T07:48:54.312492+00:00"}
{"e": "depthUpdate", "E": 1780300135515, "s": "ETHUSDT", "U": 76583066467, "u": 76583066519, "b": [["1974.61000000", "70.65120000"], ["1974.59000000", "2.86150000"], ["1974.47000000", "0.09340000"], ["1974.38000000", "0.05860000"], ["1974.37000000", "3.48580000"], ["1974.35000000", "0.04510000"], ["1973.87000000", "0.27950000"], ["1973.72000000", "0.48130000"], ["1973.65000000", "4.00420000"], ["1973.58000000", "0.00000000"], ["1973.43000000", "1.81690000"], ["1965.31000000", "0.49160000"], ["1782.41000000", "0.00000000"], ["1777.15000000", "0.07440000"]], "a": [["1974.62000000", "14.79080000"], ["1974.79000000", "0.00540000"], ["1974.80000000", "3.11770000"], ["1974.82000000", "0.03300000"], ["1974.83000000", "3.56250000"], ["1974.90000000", "14.18550000"], ["1975.00000000", "10.32740000"], ["1976.48000000", "0.00300000"], ["1976.70000000", "2.90560000"], ["1976.71000000", "0.00000000"], ["1977.05000000", "3.16600000"], ["1977.21000000", "0.62370000"], ["1977.28000000", "0.03000000"], ["1983.19000000", "0.47700000"], ["1992.20000000", "0.00000000"]], "_local_ts_utc": "2026-06-01T07:48:54.410685+00:00"}
{"e": "depthUpdate", "E": 1780300135615, "s": "ETHUSDT", "U": 76583066520, "u": 76583066616, "b": [["1974.61000000", "70.63570000"], ["1974.60000000", "3.14890000"], ["1974.59000000", "0.76410000"], ["1974.58000000", "0.02740000"], ["1974.51000000", "0.00540000"], ["1974.48000000", "0.05780000"], ["1974.47000000", "2.25930000"], ["1974.46000000", "6.97790000"], ["1974.38000000", "0.05320000"], ["1974.37000000", "7.42410000"], ["1974.33000000", "0.00000000"], ["1974.21000000", "0.10300000"], ["1974.08000000", "0.30000000"], ["1974.06000000", "0.61050000"], ["1972.73000000", "7.35900000"], ["1972.69000000", "0.00000000"], ["1972.30000000", "12.21240000"], ["1972.26000000", "0.00620000"], ["1972.17000000", "0.16110000"], ["1953.64000000", "1.47530000"], ["1777.15000000", "0.08680000"], ["1192.00000000", "0.00000000"]], "a": [["1974.62000000", "6.93020000"], ["1974.77000000", "0.00540000"], ["1974.78000000", "3.11950000"], ["1974.79000000", "8.51330000"], ["1974.80000000", "4.96250000"], ["1974.90000000", "15.50690000"], ["1974.91000000", "8.90290000"], ["1974.92000000", "13.50730000"], ["1975.25000000", "1.30200000"], ["1975.27000000", "1.75800000"], ["1976.00000000", "23.97880000"], ["1976.04000000", "3.97700000"], ["1977.10000000", "2.75130000"], ["1977.12000000", "0.03000000"], ["1977.15000000", "0.00000000"], ["1977.21000000", "0.01000000"], ["1977.22000000", "0.36210000"], ["1977.28000000", "0.00000000"], ["1977.29000000", "0.12640000"]], "_local_ts_utc": "2026-06-01T07:48:54.511815+00:00"}
{"e": "depthUpdate", "E": 1780300135715, "s": "ETHUSDT", "U": 76583066617, "u": 76583066715, "b": [["1974.61000000", "79.44080000"], ["1974.52000000", "0.07950000"], ["1974.51000000", "0.00800000"], ["1974.50000000", "0.35410000"], ["1974.49000000", "0.00280000"], ["1974.48000000", "0.05240000"], ["1974.47000000", "0.09340000"], ["1974.46000000", "0.51030000"], ["1974.37000000", "4.82410000"], ["1974.33000000", "22.57370000"], ["1974.32000000", "12.15520000"], ["1974.28000000", "6.50050000"], ["1974.21000000", "13.60770000"], ["1974.19000000", "1.28190000"], ["1974.11000000", "22.68130000"], ["1973.94000000", "0.50850000"], ["1973.91000000", "29.83980000"], ["1973.87000000", "0.67950000"], ["1973.76000000", "0.18030000"], ["1973.72000000", "0.28130000"], ["1973.65000000", "3.60420000"], ["1973.56000000", "0.07050000"], ["1777.15000000", "0.09920000"]], "a": [["1974.62000000", "2.96840000"], ["1974.63000000", "0.01050000"], ["1974.70000000", "0.01110000"], ["1974.71000000", "0.00540000"], ["1974.72000000", "6.46760000"], ["1974.77000000", "0.00000000"], ["1974.78000000", "0.00000000"], ["1974.79000000", "0.00270000"], ["1974.89000000", "0.00000000"], ["1974.90000000", "1.32710000"], ["1974.91000000", "2.93860000"], ["1974.92000000", "0.00260000"], ["1974.93000000", "0.00000000"], ["1974.96000000", "0.67410000"], ["1974.99000000", "0.00000000"], ["1975.29000000", "0.00000000"], ["1975.63000000", "6.19700000"], ["1975.93000000", "0.00300000"], ["1976.00000000", "25.37880000"], ["1976.03000000", "8.51050000"], ["1976.26000000", "8.51090000"], ["1976.44000000", "0.00260000"], ["1976.48000000", "7.09290000"], ["1976.71000000", "7.08990000"], ["1977.16000000", "13.50470000"], ["1986.96000000", "0.00000000"]], "_local_ts_utc": "2026-06-01T07:48:54.610500+00:00"}
{"e": "depthUpdate", "E": 1780300135815, "s": "ETHUSDT", "U": 76583066716, "u": 76583067463, "b": [["1974.82000000", "102.73500000"], ["1974.81000000", "0.00510000"], ["1974.80000000", "0.01310000"], ["1974.79000000", "25.53070000"], ["1974.78000000", "9.08800000"], ["1974.77000000", "0.00000000"], ["1974.76000000", "0.00000000"], ["1974.75000000", "2.95510000"], ["1974.74000000", "3.38410000"], ["1974.71000000", "0.00540000"], ["1974.70000000", "7.03790000"], ["1974.69000000", "9.23970000"], ["1974.68000000", "0.00000000"], ["1974.67000000", "0.00000000"], ["1974.66000000", "5.99830000"], ["1974.65000000", "0.00000000"], ["1974.64000000", "0.00000000"], ["1974.63000000", "2.85490000"], ["1974.62000000", "0.00000000"], ["1974.61000000", "6.29530000"], ["1974.60000000", "3.17140000"], ["1974.59000000", "0.75900000"], ["1974.58000000", "0.02480000"], ["1974.56000000", "16.31210000"], ["1974.55000000", "6.50250000"], ["1974.54000000", "0.01160000"], ["1974.53000000", "22.57850000"], ["1974.52000000", "0.07690000"], ["1974.51000000", "0.00000000"], ["1974.50000000", "1.66550000"], ["1974.49000000", "7.58460000"], ["1974.48000000", "15.65020000"], ["1974.47000000", "0.09600000"], ["1974.46000000", "1.12100000"], ["1974.45000000", "7.08990000"], ["1974.42000000", "0.19080000"], ["1974.41000000", "0.00000000"], ["1974.40000000", "0.04250000"], ["1974.37000000", "13.89200000"], ["1974.35000000", "15.64290000"], ["1974.33000000", "22.57630000"], ["1974.28000000", "0.03290000"], ["1974.27000000", "12.16660000"], ["1974.26000000", "1.79850000"], ["1974.17000000", "0.10430000"], ["1974.12000000", "8.17770000"], ["1973.98000000", "0.12220000"], ["1973.94000000", "0.40720000"], ["1973.91000000", "30.83980000"], ["1973.87000000", "1.17950000"], ["1973.82000000", "2.42710000"], ["1973.80000000", "0.00820000"], ["1973.76000000", "0.08030000"], ["1973.70000000", "0.72990000"], ["1973.69000000", "24.03860000"], ["1973.47000000", "14.87060000"], ["1973.44000000", "0.54180000"], ["1973.43000000", "1.31690000"], ["1973.01000000", "8.10310000"], ["1972.95000000", "0.00000000"], ["1972.86000000", "4.40020000"], ["1972.84000000", "10.80720000"], ["1972.81000000", "0.47130000"], ["1972.14000000", "0.00260000"], ["1972.13000000", "0.04350000"], ["1971.47000000", "0.00000000"], ["1969.69000000", "0.01310000"], ["1969.60000000", "25.43260000"], ["1967.10000000", "0.04200000"], ["1966.65000000", "0.00000000"], ["1935.32000000", "0.00310000"], ["1935.28000000", "0.00000000"], ["1777.34000000", "0.00620000"], ["1777.15000000", "0.00000000"]], "a": [["1974.62000000", "0.00000000"], ["1974.63000000", "0.00000000"], ["1974.64000000", "0.00000000"], ["1974.65000000", "0.00000000"], ["1974.66000000", "0.00000000"], ["1974.70000000", "0.00000000"], ["1974.71000000", "0.00000000"], ["1974.72000000", "0.00000000"], ["1974.75000000", "0.00000000"], ["1974.76000000", "0.00000000"], ["1974.79000000", "0.00000000"], ["1974.80000000", "0.00000000"], ["1974.82000000", "0.00000000"], ["1974.83000000", "0.84370000"], ["1974.84000000", "0.00000000"], ["1974.85000000", "0.00000000"], ["1974.88000000", "0.13000000"], ["1974.89000000", "0.00000000"], ["1974.90000000", "0.00570000"], ["1974.91000000", "0.05000000"], ["1974.92000000", "0.00000000"], ["1974.95000000", "0.00000000"], ["1974.96000000", "1.97520000"], ["1974.97000000", "0.00000000"], ["1974.99000000", "0.00540000"], ["1975.00000000", "3.38510000"], ["1975.02000000", "0.00000000"], ["1975.04000000", "0.03000000"], ["1975.05000000", "0.00840000"], ["1975.06000000", "0.49140000"], ["1975.07000000", "4.24700000"], ["1975.08000000", "6.47030000"], ["1975.09000000", "1.19740000"], ["1975.10000000", "0.95070000"], ["1975.13000000", "0.00520000"], ["1975.15000000", "4.89300000"], ["1975.16000000", "0.00300000"], ["1975.18000000", "7.08900000"], ["1975.24000000", "0.01160000"], ["1975.30000000", "0.71330000"], ["1975.32000000", "0.01010000"], ["1975.34000000", "0.80380000"], ["1975.35000000", "10.83200000"], ["1975.36000000", "13.53750000"], ["1975.37000000", "0.00000000"], ["1975.38000000", "8.51250000"], ["1975.40000000", "7.14290000"], ["1975.41000000", "0.64640000"], ["1975.42000000", "0.29180000"], ["1975.46000000", "9.16410000"], ["1975.61000000", "0.00000000"], ["1975.62000000", "0.00260000"], ["1975.68000000", "0.06300000"], ["1975.70000000", "0.00570000"], ["1975.80000000", "14.83430000"], ["1975.81000000", "2.08650000"], ["1975.82000000", "0.81300000"], ["1976.08000000", "0.00000000"], ["1976.14000000", "1.01420000"], ["1976.18000000", "1.20550000"], ["1976.44000000", "0.00260000"], ["1976.47000000", "8.50790000"], ["1976.48000000", "7.12290000"], ["1976.56000000", "0.00000000"], ["1976.70000000", "9.24490000"], ["1976.72000000", "7.08990000"], ["1976.75000000", "9.86620000"], ["1976.92000000", "3.25140000"], ["1976.93000000", "7.08990000"], ["1976.94000000", "0.13380000"], ["1977.10000000", "6.27040000"], ["1977.31000000", "19.59020000"], ["1977.36000000", "13.51410000"], ["1978.31000000", "13.83110000"], ["1979.09000000", "0.00260000"], ["1980.15000000", "0.00260000"], ["1983.19000000", "0.00000000"], ["1983.42000000", "2.13200000"], ["1983.60000000", "1.35460000"], ["1984.65000000", "0.02110000"], ["1989.83000000", "0.00310000"]], "_local_ts_utc": "2026-06-01T07:48:54.711402+00:00"}
{"e": "depthUpdate", "E": 1780300135915, "s": "ETHUSDT", "U": 76583067464, "u": 76583067608, "b": [["1974.82000000", "100.95170000"], ["1974.81000000", "3.13670000"], ["1974.80000000", "0.01030000"], ["1974.79000000", "0.00800000"], ["1974.76000000", "0.00540000"], ["1974.75000000", "2.96050000"], ["1974.74000000", "3.38410000"], ["1974.71000000", "0.00800000"], ["1974.70000000", "7.04050000"], ["1974.68000000", "1.29390000"], ["1974.66000000", "3.12510000"], ["1974.63000000", "2.85230000"], ["1974.61000000", "6.29270000"], ["1974.60000000", "3.16880000"], ["1974.59000000", "0.75640000"], ["1974.58000000", "15.62260000"], ["1974.57000000", "14.07340000"], ["1974.56000000", "7.10790000"], ["1974.50000000", "0.35720000"], ["1974.38000000", "13.55790000"], ["1974.35000000", "16.91960000"], ["1974.26000000", "1.80820000"], ["1974.19000000", "0.00520000"], ["1974.14000000", "0.50040000"], ["1973.87000000", "1.17000000"], ["1973.15000000", "2.63410000"], ["1973.11000000", "0.27930000"], ["1973.02000000", "2.83830000"], ["1973.01000000", "1.01410000"], ["1971.48000000", "1.14260000"], ["1969.07000000", "0.32400000"], ["1969.01000000", "0.60940000"], ["1968.89000000", "0.00000000"], ["1967.32000000", "0.09170000"], ["1953.64000000", "0.00000000"], ["1777.34000000", "0.01860000"]], "a": [["1974.83000000", "15.55720000"], ["1974.88000000", "0.00000000"], ["1974.91000000", "0.05260000"], ["1974.94000000", "0.00680000"], ["1974.95000000", "0.00000000"], ["1974.96000000", "0.03760000"], ["1975.00000000", "5.36250000"], ["1975.05000000", "0.00300000"], ["1975.06000000", "0.00000000"], ["1975.07000000", "4.24700000"], ["1975.08000000", "6.46760000"], ["1975.09000000", "2.50690000"], ["1975.10000000", "0.01730000"], ["1975.11000000", "0.00000000"], ["1975.15000000", "4.52740000"], ["1975.17000000", "7.09250000"], ["1975.18000000", "0.00000000"], ["1975.22000000", "9.12470000"], ["1975.66000000", "0.00000000"], ["1975.81000000", "0.57130000"], ["1975.85000000", "1.45330000"], ["1976.00000000", "20.37880000"], ["1976.16000000", "0.03000000"], ["1976.68000000", "0.48860000"], ["1976.80000000", "6.95980000"], ["1977.15000000", "0.00000000"], ["1977.31000000", "19.59280000"], ["1980.15000000", "0.00000000"], ["1980.18000000", "0.00520000"], ["1980.27000000", "22.83740000"], ["1980.72000000", "0.79320000"], ["1981.90000000", "1.15110000"], ["2000.22000000", "0.00000000"]], "_local_ts_utc": "2026-06-01T07:48:54.812667+00:00"}
{"e": "depthUpdate", "E": 1780300136015, "s": "ETHUSDT", "U": 76583067609, "u": 76583068001, "b": [["1974.82000000", "24.67470000"], ["1974.81000000", "10.15570000"], ["1974.78000000", "3.00260000"], ["1974.76000000", "0.00260000"], ["1974.75000000", "0.00260000"], ["1974.74000000", "0.00260000"], ["1974.71000000", "0.00260000"], ["1974.70000000", "0.00520000"], ["1974.69000000", "0.00000000"], ["1974.68000000", "0.00000000"], ["1974.66000000", "0.00000000"], ["1974.64000000", "0.00540000"], ["1974.62000000", "2.50040000"], ["1974.61000000", "6.29810000"], ["1974.60000000", "3.17150000"], ["1974.58000000", "0.02480000"], ["1974.57000000", "0.00000000"], ["1974.56000000", "0.01800000"], ["1974.55000000", "6.94070000"], ["1974.54000000", "0.01160000"], ["1974.53000000", "0.00480000"], ["1974.50000000", "1.64330000"], ["1974.48000000", "0.05240000"], ["1974.45000000", "0.00000000"], ["1974.44000000", "23.36190000"], ["1974.38000000", "0.05320000"], ["1974.36000000", "13.58650000"], ["1974.35000000", "1.32180000"], ["1974.34000000", "22.69530000"], ["1974.33000000", "0.00260000"], ["1974.32000000", "4.43400000"], ["1974.31000000", "22.57370000"], ["1974.29000000", "0.27380000"], ["1974.25000000", "0.00000000"], ["1974.23000000", "14.17980000"], ["1974.22000000", "13.51210000"], ["1974.21000000", "0.10300000"], ["1974.15000000", "6.63220000"], ["1974.13000000", "7.09490000"], ["1974.12000000", "1.08770000"], ["1974.07000000", "8.51810000"], ["1974.05000000", "23.92460000"], ["1974.04000000", "0.27000000"], ["1974.03000000", "0.01020000"], ["1974.02000000", "0.70480000"], ["1973.98000000", "0.02220000"], ["1973.96000000", "8.70870000"], ["1973.94000000", "14.78700000"], ["1973.93000000", "7.14360000"], ["1973.92000000", "0.03000000"], ["1973.91000000", "22.75080000"], ["1973.90000000", "0.02280000"], ["1973.89000000", "2.53310000"], ["1973.88000000", "0.76520000"], ["1973.87000000", "1.27000000"], ["1973.83000000", "0.04230000"], ["1973.81000000", "3.18530000"], ["1973.78000000", "1.67310000"], ["1973.77000000", "14.49710000"], ["1973.76000000", "8.58820000"], ["1973.75000000", "14.44320000"], ["1973.74000000", "0.00000000"], ["1973.73000000", "8.64710000"], ["1973.72000000", "0.28130000"], ["1973.71000000", "1.39940000"], ["1973.70000000", "7.81980000"], ["1973.69000000", "17.21650000"], ["1973.64000000", "0.00000000"], ["1973.63000000", "0.63090000"], ["1973.61000000", "2.44110000"], ["1973.60000000", "0.09290000"], ["1973.58000000", "0.10000000"], ["1973.57000000", "13.68960000"], ["1973.56000000", "8.57840000"], ["1973.55000000", "7.10070000"], ["1973.52000000", "20.67060000"], ["1973.51000000", "0.01540000"], ["1973.50000000", "2.21590000"], ["1973.48000000", "0.15850000"], ["1973.43000000", "9.02480000"], ["1973.42000000", "0.00510000"], ["1973.40000000", "13.18420000"], ["1973.22000000", "14.04300000"], ["1973.11000000", "8.78720000"], ["1973.01000000", "8.10400000"], ["1972.95000000", "15.59780000"], ["1972.86000000", "6.13770000"], ["1972.81000000", "7.56120000"], ["1972.75000000", "7.37250000"], ["1972.61000000", "0.00260000"], ["1972.58000000", "0.00000000"], ["1972.53000000", "7.09250000"], ["1972.41000000", "0.25510000"], ["1972.22000000", "0.05080000"], ["1971.49000000", "3.95610000"], ["1971.48000000", "13.52540000"], ["1971.24000000", "13.50470000"], ["1777.34000000", "0.03100000"], ["1580.07000000", "0.01400000"], ["1580.04000000", "0.00980000"], ["1579.86000000", "0.28000000"]], "a": [["1974.83000000", "60.37080000"], ["1974.91000000", "0.05260000"], ["1974.94000000", "0.00680000"], ["1974.95000000", "1.94720000"], ["1974.96000000", "6.50520000"], ["1974.98000000", "0.01160000"], ["1974.99000000", "0.00540000"], ["1975.06000000", "8.50700000"], ["1975.07000000", "4.24700000"], ["1975.08000000", "0.00000000"], ["1975.10000000", "0.01730000"], ["1975.14000000", "0.64780000"], ["1975.15000000", "8.69260000"], ["1975.16000000", "0.00300000"], ["1975.17000000", "8.29800000"], ["1975.22000000", "9.10090000"], ["1975.24000000", "0.01420000"], ["1975.63000000", "9.79700000"], ["1975.66000000", "0.15110000"], ["1976.00000000", "20.37880000"], ["1976.07000000", "0.00000000"], ["1976.22000000", "0.00000000"], ["1976.46000000", "0.00000000"], ["1976.47000000", "0.00000000"], ["1976.73000000", "0.48600000"], ["1977.35000000", "13.50470000"], ["1977.36000000", "0.00940000"], ["1980.27000000", "22.83480000"], ["1981.90000000", "1.00000000"], ["1983.36000000", "0.48880000"], ["1990.00000000", "9.48920000"]], "_local_ts_utc": "2026-06-01T07:48:54.912346+00:00"}
{"e": "depthUpdate", "E": 1780300136115, "s": "ETHUSDT", "U": 76583068002, "u": 76583068721, "b": [["1974.82000000", "0.00000000"], ["1974.81000000", "0.00000000"], ["1974.80000000", "0.00000000"], ["1974.79000000", "0.00000000"], ["1974.78000000", "0.00000000"], ["1974.76000000", "0.00000000"], ["1974.75000000", "0.00000000"], ["1974.74000000", "0.00000000"], ["1974.71000000", "0.00000000"], ["1974.70000000", "0.00000000"], ["1974.64000000", "0.00000000"], ["1974.63000000", "0.00000000"], ["1974.62000000", "0.00000000"], ["1974.61000000", "0.00000000"], ["1974.60000000", "0.00000000"], ["1974.59000000", "7.12060000"], ["1974.58000000", "0.03520000"], ["1974.56000000", "0.01800000"], ["1974.55000000", "0.03750000"], ["1974.54000000", "0.01420000"], ["1974.53000000", "0.00740000"], ["1974.52000000", "0.07950000"], ["1974.51000000", "0.00540000"], ["1974.50000000", "0.07330000"], ["1974.49000000", "0.00540000"], ["1974.48000000", "0.05500000"], ["1974.47000000", "0.09880000"], ["1974.46000000", "0.51030000"], ["1974.45000000", "0.00000000"], ["1974.44000000", "0.02850000"], ["1974.43000000", "1.29550000"], ["1974.42000000", "0.18820000"], ["1974.41000000", "0.00000000"], ["1974.40000000", "0.04480000"], ["1974.39000000", "0.98880000"], ["1974.38000000", "0.05590000"], ["1974.37000000", "0.00280000"], ["1974.36000000", "0.08320000"], ["1974.35000000", "0.04510000"], ["1974.34000000", "0.00760000"], ["1974.32000000", "0.03000000"], ["1974.31000000", "0.00000000"], ["1974.30000000", "0.00520000"], ["1974.29000000", "0.00380000"], ["1974.27000000", "1.53180000"], ["1974.23000000", "1.27670000"], ["1974.22000000", "0.00740000"], ["1974.21000000", "0.71370000"], ["1974.20000000", "10.65560000"], ["1974.13000000", "0.00500000"], ["1974.12000000", "23.66140000"], ["1974.11000000", "0.10760000"], ["1974.10000000", "11.75410000"], ["1974.09000000", "8.50960000"], ["1974.07000000", "0.01020000"], ["1974.06000000", "7.69970000"], ["1974.05000000", "3.33000000"], ["1974.04000000", "7.35920000"], ["1974.00000000", "31.29240000"], ["1973.99000000", "15.62770000"], ["1973.98000000", "0.02220000"], ["1973.96000000", "0.20080000"], ["1973.95000000", "7.12980000"], ["1973.94000000", "0.20720000"], ["1973.93000000", "0.05370000"], ["1973.92000000", "0.03000000"], ["1973.90000000", "7.60900000"], ["1973.88000000", "9.27220000"], ["1973.87000000", "0.27000000"], ["1973.85000000", "15.30540000"], ["1973.84000000", "7.40140000"], ["1973.81000000", "0.14200000"], ["1973.80000000", "0.01080000"], ["1973.78000000", "14.43970000"], ["1973.77000000", "0.99240000"], ["1973.76000000", "0.08030000"], ["1973.75000000", "7.13180000"], ["1973.74000000", "7.08920000"], ["1973.73000000", "1.55720000"], ["1973.72000000", "7.97050000"], ["1973.70000000", "22.74280000"], ["1973.65000000", "3.60420000"], ["1973.61000000", "2.44110000"], ["1973.59000000", "0.82230000"], ["1973.58000000", "0.00000000"], ["1973.56000000", "8.67840000"], ["1973.46000000", "23.39030000"], ["1973.29000000", "0.01100000"], ["1973.26000000", "0.00380000"], ["1973.22000000", "14.84300000"], ["1973.15000000", "4.87590000"], ["1973.02000000", "4.59180000"], ["1972.77000000", "9.02820000"], ["1972.76000000", "8.78250000"], ["1972.66000000", "3.40800000"], ["1972.61000000", "7.09180000"], ["1972.60000000", "16.35530000"], ["1972.58000000", "15.59620000"], ["1972.41000000", "14.43350000"], ["1972.23000000", "0.00570000"], ["1972.22000000", "14.22920000"], ["1972.02000000", "14.18110000"], ["1970.97000000", "6.29300000"], ["1970.96000000", "13.77740000"], ["1970.95000000", "0.00000000"], ["1970.68000000", "13.50700000"], ["1970.17000000", "7.09160000"], ["1969.90000000", "9.27550000"], ["1967.32000000", "0.08370000"], ["1967.00000000", "47.92700000"], ["1965.31000000", "0.00000000"], ["1935.09000000", "0.00000000"], ["1777.34000000", "0.00000000"], ["1777.32000000", "0.00000000"], ["1580.07000000", "0.00000000"], ["1579.95000000", "0.00980000"], ["1579.91000000", "0.00000000"], ["1579.86000000", "0.28000000"], ["1579.84000000", "0.03050000"], ["1579.68000000", "0.03060000"], ["1474.79000000", "0.09320000"]], "a": [["1974.60000000", "110.86720000"], ["1974.61000000", "7.20960000"], ["1974.62000000", "0.00000000"], ["1974.63000000", "0.79970000"], ["1974.64000000", "0.00000000"], ["1974.65000000", "0.00000000"], ["1974.70000000", "6.88580000"], ["1974.71000000", "0.00000000"], ["1974.72000000", "0.00000000"], ["1974.75000000", "0.00000000"], ["1974.76000000", "7.08920000"], ["1974.77000000", "36.68090000"], ["1974.78000000", "7.08920000"], ["1974.79000000", "0.52430000"], ["1974.80000000", "12.35120000"], ["1974.81000000", "8.50700000"], ["1974.82000000", "0.03300000"], ["1974.83000000", "1.31490000"], ["1974.88000000", "0.00000000"], ["1974.90000000", "0.01730000"], ["1974.92000000", "0.00260000"], ["1974.93000000", "0.80000000"], ["1974.94000000", "0.01840000"], ["1974.95000000", "0.00000000"], ["1974.96000000", "0.03760000"], ["1974.99000000", "2.50710000"], ["1975.00000000", "9.98210000"], ["1975.05000000", "14.18140000"], ["1975.08000000", "0.20000000"], ["1975.09000000", "1.19740000"], ["1975.10000000", "0.00570000"], ["1975.12000000", "0.67640000"], ["1975.14000000", "0.00380000"], ["1975.15000000", "8.58980000"], ["1975.16000000", "13.50630000"], ["1975.19000000", "7.09160000"], ["1975.24000000", "0.00260000"], ["1975.30000000", "0.51330000"], ["1975.34000000", "0.00380000"], ["1975.41000000", "0.00000000"], ["1975.43000000", "3.60000000"], ["1975.52000000", "0.69410000"], ["1975.60000000", "14.63780000"], ["1975.70000000", "0.00310000"], ["1975.71000000", "0.60560000"], ["1975.80000000", "14.83170000"], ["1976.00000000", "19.77880000"], ["1976.26000000", "0.00300000"], ["1976.48000000", "0.03300000"], ["1976.56000000", "1.02020000"], ["1976.69000000", "0.00000000"], ["1976.70000000", "6.54490000"], ["1976.71000000", "0.00000000"], ["1976.72000000", "0.00000000"], ["1976.78000000", "1.51200000"], ["1976.80000000", "6.96240000"], ["1976.87000000", "31.85590000"], ["1976.92000000", "1.13500000"], ["1976.93000000", "0.00000000"], ["1976.96000000", "0.03000000"], ["1977.12000000", "0.00000000"], ["1977.15000000", "13.50330000"], ["1977.16000000", "0.00000000"], ["1977.35000000", "0.00000000"], ["1977.36000000", "0.00940000"], ["1978.31000000", "0.61850000"], ["1979.70000000", "0.25090000"], ["1979.76000000", "0.00000000"], ["1979.83000000", "0.00000000"], ["1981.04000000", "0.00000000"], ["1982.62000000", "0.00000000"], ["1984.65000000", "0.01850000"], ["1984.75000000", "0.04200000"], ["2474.83000000", "0.06330000"]], "_local_ts_utc": "2026-06-01T07:48:55.011632+00:00"}
{"e": "depthUpdate", "E": 1780300136215, "s": "ETHUSDT", "U": 76583068722, "u": 76583068959, "b": [["1974.59000000", "8.89950000"], ["1974.58000000", "0.03520000"], ["1974.52000000", "0.07950000"], ["1974.51000000", "0.00260000"], ["1974.48000000", "0.05240000"], ["1974.44000000", "0.02850000"], ["1974.43000000", "0.00940000"], ["1974.40000000", "0.01480000"], ["1974.39000000", "0.33730000"], ["1974.38000000", "0.19510000"], ["1974.28000000", "0.03290000"], ["1974.27000000", "0.76900000"], ["1974.26000000", "1.79850000"], ["1974.23000000", "0.00000000"], ["1974.20000000", "3.53740000"], ["1974.17000000", "1.38710000"], ["1974.16000000", "0.21310000"], ["1974.13000000", "0.00500000"], ["1974.12000000", "1.08770000"], ["1974.11000000", "22.68130000"], ["1974.10000000", "6.17530000"], ["1974.09000000", "0.00260000"], ["1974.06000000", "0.61050000"], ["1974.04000000", "0.27000000"], ["1974.02000000", "1.60340000"], ["1974.01000000", "1.37560000"], ["1974.00000000", "27.69240000"], ["1973.99000000", "0.03150000"], ["1973.95000000", "0.04060000"], ["1973.92000000", "36.21870000"], ["1973.88000000", "5.17620000"], ["1973.85000000", "1.80210000"], ["1973.84000000", "0.31220000"], ["1973.83000000", "1.42230000"], ["1973.82000000", "9.51630000"], ["1973.81000000", "15.73820000"], ["1973.78000000", "0.00260000"], ["1973.75000000", "0.04260000"], ["1973.74000000", "10.41630000"], ["1973.73000000", "15.06050000"], ["1973.72000000", "10.61400000"], ["1973.71000000", "8.48860000"], ["1973.70000000", "0.73250000"], ["1973.69000000", "25.72350000"], ["1973.65000000", "4.00420000"], ["1973.62000000", "7.28860000"], ["1973.61000000", "1.06110000"], ["1973.60000000", "12.88730000"], ["1973.59000000", "9.32930000"], ["1973.58000000", "13.50330000"], ["1973.57000000", "2.16340000"], ["1973.56000000", "0.07050000"], ["1973.55000000", "0.01080000"], ["1973.53000000", "7.11930000"], ["1973.52000000", "0.07600000"], ["1973.51000000", "7.10460000"], ["1973.42000000", "13.50840000"], ["1973.37000000", "0.30130000"], ["1973.33000000", "0.16130000"], ["1973.32000000", "2.83500000"], ["1973.22000000", "0.54000000"], ["1973.15000000", "8.62000000"], ["1973.14000000", "20.59230000"], ["1973.00000000", "9.29440000"], ["1972.86000000", "3.55380000"], ["1972.84000000", "0.27000000"], ["1972.66000000", "5.69570000"], ["1972.62000000", "8.52340000"], ["1972.58000000", "7.08920000"], ["1972.46000000", "0.01120000"], ["1972.44000000", "8.23260000"], ["1972.42000000", "8.59950000"], ["1972.33000000", "7.10350000"], ["1972.23000000", "0.00570000"], ["1972.03000000", "7.08920000"], ["1972.02000000", "7.09190000"], ["1971.84000000", "0.03260000"], ["1971.83000000", "0.01020000"], ["1971.82000000", "0.00260000"], ["1971.62000000", "0.00000000"], ["1970.87000000", "22.59890000"], ["1970.69000000", "0.00310000"], ["1970.68000000", "0.00370000"], ["1970.26000000", "0.00790000"], ["1969.06000000", "0.00560000"], ["1968.97000000", "0.00260000"], ["1968.86000000", "0.67890000"], ["1968.77000000", "0.00760000"], ["1966.65000000", "3.60000000"], ["1965.58000000", "0.06980000"], ["1777.14000000", "0.01540000"]], "a": [["1974.60000000", "126.24120000"], ["1974.61000000", "1.32100000"], ["1974.62000000", "0.00540000"], ["1974.63000000", "0.00000000"], ["1974.64000000", "0.00260000"], ["1974.66000000", "0.00540000"], ["1974.67000000", "0.62630000"], ["1974.69000000", "0.00540000"], ["1974.70000000", "0.41820000"], ["1974.75000000", "0.00000000"], ["1974.76000000", "12.54550000"], ["1974.77000000", "0.00000000"], ["1974.79000000", "1.72980000"], ["1974.80000000", "11.18990000"], ["1974.83000000", "1.49990000"], ["1974.93000000", "0.80000000"], ["1974.99000000", "1.86970000"], ["1975.20000000", "5.66070000"], ["1975.27000000", "2.13610000"], ["1975.32000000", "0.14010000"], ["1975.64000000", "0.00000000"], ["1975.85000000", "1.28280000"], ["1975.96000000", "8.28860000"], ["1975.97000000", "9.85860000"], ["1975.98000000", "0.00000000"], ["1976.70000000", "3.22170000"], ["1976.75000000", "0.01020000"], ["1976.80000000", "15.78180000"], ["1977.14000000", "13.51010000"], ["1977.15000000", "0.00000000"], ["1978.00000000", "7.26260000"], ["1978.10000000", "0.00000000"], ["1978.25000000", "0.00000000"], ["1979.22000000", "0.00000000"], ["1979.55000000", "22.57370000"], ["1979.77000000", "1.35000000"], ["1980.01000000", "7.60000000"], ["1980.10000000", "0.00000000"], ["1980.18000000", "0.00260000"], ["1981.10000000", "1.00000000"], ["1983.08000000", "0.00000000"], ["1984.92000000", "0.00000000"], ["1985.34000000", "11.33160000"], ["1986.47000000", "0.00000000"], ["2003.87000000", "14.63530000"], ["2004.14000000", "0.00000000"], ["2013.57000000", "0.02330000"]], "_local_ts_utc": "2026-06-01T07:48:55.111591+00:00"}
{"e": "depthUpdate", "E": 1780300136315, "s": "ETHUSDT", "U": 76583068960, "u": 76583069026, "b": [["1974.59000000", "0.24020000"], ["1974.46000000", "0.50650000"], ["1974.39000000", "0.34270000"], ["1974.32000000", "0.00000000"], ["1974.28000000", "0.03560000"], ["1974.20000000", "16.55250000"], ["1974.14000000", "0.23040000"], ["1974.12000000", "22.69310000"], ["1974.10000000", "12.56080000"], ["1974.08000000", "6.49760000"], ["1974.06000000", "0.07050000"], ["1974.05000000", "3.06000000"], ["1974.04000000", "0.00000000"], ["1974.02000000", "24.28880000"], ["1973.87000000", "0.27960000"], ["1973.72000000", "7.57050000"], ["1973.71000000", "11.53210000"], ["1973.22000000", "1.34000000"], ["1973.00000000", "8.49440000"], ["1972.73000000", "8.87830000"], ["1972.66000000", "3.55640000"], ["1972.62000000", "0.01640000"], ["1972.48000000", "0.04480000"], ["1972.42000000", "0.09250000"], ["1972.22000000", "0.05080000"], ["1972.03000000", "0.00000000"], ["1972.02000000", "0.00270000"], ["1969.17000000", "0.00000000"], ["1969.08000000", "0.58090000"], ["1968.77000000", "0.00500000"], ["1777.14000000", "0.02780000"]], "a": [["1974.62000000", "0.00000000"], ["1974.69000000", "0.00000000"], ["1974.83000000", "1.29780000"], ["1974.89000000", "0.33000000"], ["1974.97000000", "13.50330000"], ["1975.12000000", "0.03000000"], ["1975.45000000", "0.49050000"], ["1977.14000000", "0.00680000"], ["1979.42000000", "0.15000000"]], "_local_ts_utc": "2026-06-01T07:48:55.211160+00:00"}
{"e": "depthUpdate", "E": 1780300136415, "s": "ETHUSDT", "U": 76583069027, "u": 76583069074, "b": [["1974.59000000", "1.89290000"], ["1974.13000000", "22.57870000"], ["1974.12000000", "0.00770000"], ["1974.11000000", "0.10760000"], ["1973.81000000", "15.82930000"], ["1973.77000000", "1.00250000"], ["1973.75000000", "0.14390000"], ["1973.65000000", "3.60420000"], ["1973.61000000", "1.23160000"], ["1973.53000000", "7.10920000"], ["1973.44000000", "0.45060000"], ["1973.40000000", "0.00610000"], ["1973.39000000", "0.65580000"], ["1973.32000000", "9.77830000"], ["1973.29000000", "0.41100000"], ["1973.16000000", "23.87280000"], ["1972.78000000", "12.74440000"], ["1972.77000000", "15.98610000"], ["1968.93000000", "0.00260000"], ["1968.86000000", "0.67630000"], ["1777.14000000", "0.04020000"]], "a": [["1974.60000000", "134.30730000"], ["1974.66000000", "0.00000000"], ["1974.70000000", "4.67320000"], ["1974.76000000", "9.20530000"], ["1974.91000000", "0.05000000"], ["1974.94000000", "0.61240000"], ["1974.96000000", "4.56260000"], ["1974.99000000", "0.00000000"], ["1975.07000000", "0.00000000"], ["1975.22000000", "8.50690000"], ["1977.10000000", "2.75130000"], ["1977.31000000", "19.66780000"], ["1978.10000000", "4.20400000"], ["1979.68000000", "0.00000000"]], "_local_ts_utc": "2026-06-01T07:48:55.311227+00:00"}
