{"e": "depthUpdate", "E": 1780300146115, "s": "ETHUSDT", "U": 76583101899, "u": 76583103001, "b": [["1971.86000000", "0.00000000"], ["1971.85000000", "0.00000000"], ["1971.84000000", "0.00000000"], ["1971.83000000", "0.00000000"], ["1971.82000000", "0.00000000"], ["1971.81000000", "0.00000000"], ["1971.80000000", "0.00000000"], ["1971.79000000", "0.00000000"], ["1971.78000000", "0.00000000"], ["1971.77000000", "0.00000000"], ["1971.76000000", "0.00000000"], ["1971.75000000", "0.00000000"], ["1971.74000000", "0.00000000"], ["1971.73000000", "0.00000000"], ["1971.72000000", "0.00000000"], ["1971.71000000", "0.00000000"], ["1971.70000000", "8.30140000"], ["1971.69000000", "0.37670000"], ["1971.68000000", "0.01610000"], ["1971.67000000", "0.07710000"], ["1971.66000000", "0.04590000"], ["1971.65000000", "0.06810000"], ["1971.64000000", "0.68900000"], ["1971.63000000", "0.01370000"], ["1971.62000000", "0.00800000"], ["1971.61000000", "0.00000000"], ["1971.60000000", "0.00780000"], ["1971.59000000", "0.00540000"], ["1971.58000000", "10.65690000"], ["1971.57000000", "0.08300000"], ["1971.56000000", "0.00950000"], ["1971.55000000", "1.01840000"], ["1971.54000000", "0.63270000"], ["1971.53000000", "0.00300000"], ["1971.52000000", "0.03000000"], ["1971.51000000", "0.01550000"], ["1971.50000000", "1.01250000"], ["1971.48000000", "0.02070000"], ["1971.47000000", "0.00000000"], ["1971.46000000", "0.01410000"], ["1971.44000000", "0.50760000"], ["1971.43000000", "0.00000000"], ["1971.42000000", "0.15850000"], ["1971.41000000", "0.00000000"], ["1971.40000000", "0.00260000"], ["1971.36000000", "0.06560000"], ["1971.35000000", "0.00000000"], ["1971.33000000", "25.59620000"], ["1971.32000000", "0.02020000"], ["1971.31000000", "0.01830000"], ["1971.30000000", "3.72780000"], ["1971.29000000", "0.00460000"], ["1971.26000000", "0.71820000"], ["1971.25000000", "7.15130000"], ["1971.22000000", "7.09990000"], ["1971.21000000", "0.00000000"], ["1971.20000000", "4.06100000"], ["1971.19000000", "10.13120000"], ["1971.17000000", "6.85000000"], ["1971.16000000", "0.41270000"], ["1971.15000000", "13.52610000"], ["1971.14000000", "16.13950000"], ["1971.12000000", "7.30440000"], ["1971.10000000", "0.20570000"], ["1971.09000000", "17.84880000"], ["1971.08000000", "0.00270000"], ["1971.07000000", "0.00530000"], ["1971.06000000", "22.57760000"], ["1971.04000000", "7.15490000"], ["1971.03000000", "7.09990000"], ["1971.00000000", "8.18440000"], ["1970.98000000", "0.00560000"], ["1970.97000000", "0.03880000"], ["1970.96000000", "0.00390000"], ["1970.95000000", "0.00000000"], ["1970.93000000", "0.01730000"], ["1970.92000000", "7.41650000"], ["1970.91000000", "37.12160000"], ["1970.90000000", "27.82060000"], ["1970.89000000", "0.14810000"], ["1970.87000000", "0.02820000"], ["1970.80000000", "0.79810000"], ["1970.79000000", "0.00910000"], ["1970.73000000", "0.02000000"], ["1970.71000000", "0.30820000"], ["1970.70000000", "15.03440000"], ["1970.57000000", "22.57790000"], ["1970.48000000", "43.33660000"], ["1970.33000000", "43.62210000"], ["1970.29000000", "8.58430000"], ["1970.28000000", "0.03300000"], ["1970.18000000", "1.73530000"], ["1970.14000000", "8.64770000"], ["1970.03000000", "8.73950000"], ["1969.97000000", "0.08660000"], ["1969.96000000", "1.17540000"], ["1969.88000000", "9.11320000"], ["1969.83000000", "8.52240000"], ["1969.82000000", "14.20220000"], ["1969.74000000", "7.12690000"], ["1969.63000000", "8.64060000"], ["1969.62000000", "16.93860000"], ["1969.54000000", "7.10240000"], ["1969.46000000", "9.46620000"], ["1969.43000000", "7.09980000"], ["1969.35000000", "4.37820000"], ["1969.30000000", "18.60780000"], ["1969.23000000", "0.00760000"], ["1969.15000000", "0.13490000"], ["1969.12000000", "0.03000000"], ["1968.58000000", "10.11190000"], ["1968.51000000", "13.83610000"], ["1968.23000000", "13.53000000"], ["1967.21000000", "0.00000000"], ["1960.97000000", "1.24130000"], ["1959.75000000", "0.00770000"], ["1952.57000000", "0.12780000"], ["1947.42000000", "1.51630000"], ["1927.56000000", "0.00000000"], ["1927.04000000", "0.07120000"], ["1912.71000000", "0.13310000"], ["1912.69000000", "0.37570000"], ["1774.68000000", "0.00000000"], ["1774.55000000", "0.05590000"], ["1577.57000000", "0.00000000"], ["1577.51000000", "0.00700000"], ["1577.49000000", "0.00700000"], ["1577.48000000", "0.18200000"], ["1577.47000000", "0.03500000"], ["1577.38000000", "0.01400000"]], "a": [["1971.71000000", "43.92410000"], ["1971.73000000", "11.67740000"], ["1971.74000000", "1.59630000"], ["1971.75000000", "0.11170000"], ["1971.76000000", "0.00800000"], ["1971.77000000", "0.00260000"], ["1971.78000000", "0.00800000"], ["1971.79000000", "1.49400000"], ["1971.80000000", "1.90680000"], ["1971.81000000", "0.00000000"], ["1971.82000000", "0.00000000"], ["1971.83000000", "49.99420000"], ["1971.84000000", "15.94650000"], ["1971.85000000", "0.00260000"], ["1971.86000000", "4.97970000"], ["1971.87000000", "4.08500000"], ["1971.88000000", "0.00000000"], ["1971.89000000", "0.00000000"], ["1971.90000000", "0.00570000"], ["1971.91000000", "0.00260000"], ["1971.92000000", "0.01160000"], ["1971.93000000", "0.00000000"], ["1971.94000000", "1.28610000"], ["1971.95000000", "0.00000000"], ["1971.96000000", "0.00000000"], ["1971.98000000", "0.10000000"], ["1971.99000000", "0.01160000"], ["1972.00000000", "0.58770000"], ["1972.01000000", "7.13590000"], ["1972.04000000", "0.60000000"], ["1972.07000000", "0.00000000"], ["1972.08000000", "0.00300000"], ["1972.09000000", "0.00760000"], ["1972.10000000", "7.10590000"], ["1972.11000000", "0.01280000"], ["1972.12000000", "7.10020000"], ["1972.13000000", "7.10020000"], ["1972.14000000", "4.34290000"], ["1972.15000000", "7.14580000"], ["1972.16000000", "22.60370000"], ["1972.20000000", "0.00570000"], ["1972.22000000", "29.17700000"], ["1972.24000000", "0.00000000"], ["1972.25000000", "0.00000000"], ["1972.26000000", "0.00260000"], ["1972.27000000", "7.10780000"], ["1972.28000000", "0.00000000"], ["1972.29000000", "0.00000000"], ["1972.30000000", "11.60000000"], ["1972.31000000", "0.00000000"], ["1972.35000000", "14.20050000"], ["1972.37000000", "9.39350000"], ["1972.40000000", "18.97350000"], ["1972.41000000", "13.52350000"], ["1972.42000000", "3.29990000"], ["1972.43000000", "29.71480000"], ["1972.50000000", "0.25720000"], ["1972.55000000", "0.65940000"], ["1972.56000000", "7.87080000"], ["1972.60000000", "9.37400000"], ["1972.62000000", "0.01020000"], ["1972.65000000", "4.20000000"], ["1972.68000000", "0.15110000"], ["1972.70000000", "0.00310000"], ["1972.75000000", "7.10400000"], ["1972.80000000", "11.84340000"], ["1972.82000000", "9.98390000"], ["1972.90000000", "12.79490000"], ["1972.97000000", "3.61020000"], ["1973.19000000", "0.00000000"], ["1973.26000000", "24.56770000"], ["1973.32000000", "0.01150000"], ["1973.37000000", "4.89140000"], ["1973.40000000", "0.23740000"], ["1973.42000000", "8.52290000"], ["1973.43000000", "7.09990000"], ["1973.44000000", "3.63000000"], ["1973.64000000", "0.00000000"], ["1973.65000000", "0.00000000"], ["1973.66000000", "0.00260000"], ["1973.67000000", "0.74510000"], ["1973.68000000", "0.00000000"], ["1973.88000000", "0.00000000"], ["1973.89000000", "0.00000000"], ["1974.24000000", "0.10260000"], ["1974.28000000", "13.52910000"], ["1974.29000000", "0.00000000"], ["1974.36000000", "31.69570000"], ["1974.40000000", "0.00310000"], ["1974.92000000", "0.00260000"], ["1974.99000000", "0.00000000"], ["1975.94000000", "0.00260000"], ["1976.84000000", "0.00000000"], ["1976.85000000", "0.00000000"], ["1976.87000000", "0.20050000"], ["1976.90000000", "0.00000000"], ["1978.65000000", "0.00000000"], ["1979.96000000", "0.49420000"], ["1980.06000000", "0.00000000"], ["1980.54000000", "1.33740000"], ["1980.66000000", "6.77510000"], ["1980.68000000", "0.25090000"], ["1981.62000000", "0.00000000"], ["1986.37000000", "0.04000000"], ["1986.90000000", "0.00000000"], ["1999.00000000", "0.14420000"], ["2331.01000000", "0.01260000"], ["2471.86000000", "0.01200000"]], "_local_ts_utc": "2026-06-01T07:49:05.012268+00:00"}
{"e": "depthUpdate", "E": 1780300146215, "s": "ETHUSDT", "U": 76583103002, "u": 76583103438, "b": [["1971.70000000", "41.82490000"], ["1971.68000000", "3.32440000"], ["1971.67000000", "10.23350000"], ["1971.66000000", "0.04200000"], ["1971.65000000", "0.07350000"], ["1971.62000000", "0.00260000"], ["1971.61000000", "0.00000000"], ["1971.60000000", "0.00520000"], ["1971.59000000", "0.00540000"], ["1971.58000000", "0.50000000"], ["1971.57000000", "0.08570000"], ["1971.56000000", "0.81450000"], ["1971.55000000", "1.01840000"], ["1971.51000000", "0.01280000"], ["1971.49000000", "1.39360000"], ["1971.48000000", "0.02070000"], ["1971.47000000", "0.00260000"], ["1971.44000000", "0.00000000"], ["1971.35000000", "0.98380000"], ["1971.34000000", "30.20370000"], ["1971.33000000", "2.87540000"], ["1971.30000000", "3.81960000"], ["1971.27000000", "0.05350000"], ["1971.26000000", "23.54580000"], ["1971.25000000", "0.05140000"], ["1971.24000000", "14.20080000"], ["1971.22000000", "7.10040000"], ["1971.21000000", "13.52350000"], ["1971.20000000", "12.17460000"], ["1971.19000000", "8.53270000"], ["1971.16000000", "0.01270000"], ["1971.15000000", "0.00260000"], ["1971.10000000", "0.00570000"], ["1971.09000000", "21.99850000"], ["1971.07000000", "13.52880000"], ["1971.00000000", "12.52640000"], ["1970.93000000", "0.61730000"], ["1970.92000000", "18.49900000"], ["1970.90000000", "0.00570000"], ["1970.87000000", "8.57970000"], ["1970.82000000", "0.00710000"], ["1970.78000000", "0.00460000"], ["1970.72000000", "28.25880000"], ["1970.70000000", "14.83440000"], ["1970.68000000", "14.72630000"], ["1970.47000000", "0.10000000"], ["1970.36000000", "1.01450000"], ["1970.21000000", "0.00720000"], ["1970.18000000", "1.63530000"], ["1969.63000000", "0.12080000"], ["1969.54000000", "8.11190000"], ["1969.46000000", "9.44730000"], ["1969.43000000", "0.00000000"], ["1969.39000000", "0.25980000"], ["1969.36000000", "6.70990000"], ["1969.35000000", "0.00000000"], ["1969.30000000", "17.89680000"], ["1969.23000000", "0.00760000"], ["1969.16000000", "2.17810000"], ["1969.15000000", "0.13490000"], ["1968.24000000", "9.91940000"], ["1968.23000000", "0.00650000"], ["1967.86000000", "7.87270000"], ["1966.83000000", "0.58840000"], ["1966.22000000", "0.06720000"], ["1965.99000000", "0.00260000"], ["1965.90000000", "0.00970000"], ["1965.70000000", "0.00780000"], ["1962.19000000", "0.51950000"], ["1962.06000000", "0.07780000"], ["1961.84000000", "0.03320000"], ["1961.63000000", "0.31160000"], ["1961.41000000", "0.03590000"], ["1961.20000000", "0.12210000"], ["1960.97000000", "0.03580000"], ["1957.86000000", "0.42560000"], ["1955.84000000", "1.26500000"], ["1952.57000000", "0.25560000"], ["1950.31000000", "0.01410000"], ["1947.42000000", "0.00680000"], ["1946.36000000", "0.12710000"], ["1942.12000000", "0.12850000"], ["1934.19000000", "0.51160000"], ["1924.32000000", "0.25990000"], ["1774.53000000", "0.02610000"]], "a": [["1971.71000000", "17.37660000"], ["1971.72000000", "0.00000000"], ["1971.73000000", "0.00800000"], ["1971.74000000", "0.00260000"], ["1971.75000000", "0.00800000"], ["1971.76000000", "0.00260000"], ["1971.78000000", "0.00260000"], ["1971.79000000", "0.01820000"], ["1971.80000000", "0.01370000"], ["1971.81000000", "0.00270000"], ["1971.82000000", "0.00270000"], ["1971.83000000", "0.00260000"], ["1971.84000000", "0.03000000"], ["1971.85000000", "1.33050000"], ["1971.86000000", "0.00000000"], ["1971.92000000", "0.00000000"], ["1971.93000000", "4.46920000"], ["1971.94000000", "7.75630000"], ["1971.97000000", "0.00000000"], ["1971.98000000", "0.00000000"], ["1972.00000000", "7.18580000"], ["1972.04000000", "0.00000000"], ["1972.06000000", "8.52310000"], ["1972.15000000", "7.14580000"], ["1972.21000000", "24.35700000"], ["1972.22000000", "15.65350000"], ["1972.23000000", "0.00000000"], ["1972.27000000", "7.50780000"], ["1972.28000000", "0.20000000"], ["1972.30000000", "16.26880000"], ["1972.40000000", "22.62620000"], ["1972.41000000", "7.10030000"], ["1972.51000000", "0.00000000"], ["1972.55000000", "9.43640000"], ["1972.58000000", "13.85350000"], ["1972.65000000", "0.60000000"], ["1972.74000000", "11.27840000"], ["1972.82000000", "8.51570000"], ["1973.04000000", "1.45000000"], ["1973.05000000", "9.65950000"], ["1973.14000000", "1.01820000"], ["1973.19000000", "8.52050000"], ["1973.20000000", "20.19020000"], ["1973.21000000", "16.09590000"], ["1973.22000000", "7.10040000"], ["1973.25000000", "0.00000000"], ["1973.26000000", "23.16770000"], ["1973.33000000", "7.10040000"], ["1973.37000000", "0.85690000"], ["1973.41000000", "7.10040000"], ["1973.42000000", "0.00260000"], ["1973.43000000", "0.00000000"], ["1973.45000000", "7.09990000"], ["1973.56000000", "7.10040000"], ["1973.66000000", "0.00260000"], ["1973.67000000", "7.84550000"], ["1973.79000000", "1.11180000"], ["1974.46000000", "15.00000000"], ["1974.61000000", "0.00300000"], ["1976.79000000", "0.00260000"], ["1976.86000000", "31.65560000"], ["1976.92000000", "0.00260000"], ["1976.98000000", "0.03290000"], ["1977.00000000", "0.00000000"], ["1977.43000000", "0.06840000"], ["1977.59000000", "0.00000000"], ["1977.96000000", "0.00000000"], ["1978.23000000", "0.03800000"], ["1978.74000000", "0.00510000"], ["1978.84000000", "3.85090000"], ["1980.68000000", "0.00000000"], ["1984.95000000", "0.00270000"], ["1986.88000000", "3.18200000"], ["1989.13000000", "0.96980000"], ["1995.65000000", "0.02600000"]], "_local_ts_utc": "2026-06-01T07:49:05.111755+00:00"}
{"e": "depthUpdate", "E": 1780300146315, "s": "ETHUSDT", "U": 76583103439, "u": 76583104796, "b": [["1972.05000000", "99.42700000"], ["1972.04000000", "0.00510000"], ["1972.03000000", "0.00510000"], ["1972.02000000", "3.00000000"], ["1972.01000000", "0.00540000"], ["1972.00000000", "21.60750000"], ["1971.99000000", "1.28750000"], ["1971.98000000", "0.00000000"], ["1971.97000000", "0.00000000"], ["1971.96000000", "0.00000000"], ["1971.94000000", "0.00540000"], ["1971.93000000", "1.16840000"], ["1971.92000000", "0.00000000"], ["1971.91000000", "0.00000000"], ["1971.90000000", "2.48090000"], ["1971.89000000", "22.54180000"], ["1971.88000000", "0.00000000"], ["1971.87000000", "0.00000000"], ["1971.86000000", "0.00000000"], ["1971.85000000", "0.00000000"], ["1971.84000000", "8.55050000"], ["1971.83000000", "0.01020000"], ["1971.82000000", "0.00000000"], ["1971.81000000", "7.10040000"], ["1971.80000000", "0.00570000"], ["1971.79000000", "11.36040000"], ["1971.78000000", "7.10040000"], ["1971.77000000", "18.44930000"], ["1971.76000000", "9.66210000"], ["1971.75000000", "2.73430000"], ["1971.74000000", "0.00260000"], ["1971.73000000", "0.00260000"], ["1971.72000000", "9.02770000"], ["1971.71000000", "7.10040000"], ["1971.70000000", "3.86590000"], ["1971.69000000", "7.46670000"], ["1971.68000000", "7.14390000"], ["1971.67000000", "22.65080000"], ["1971.66000000", "0.04330000"], ["1971.65000000", "0.06550000"], ["1971.64000000", "0.68640000"], ["1971.63000000", "0.01110000"], ["1971.62000000", "0.00000000"], ["1971.60000000", "8.52880000"], ["1971.59000000", "3.66100000"], ["1971.58000000", "0.50260000"], ["1971.57000000", "14.28380000"], ["1971.56000000", "7.10450000"], ["1971.55000000", "0.51110000"], ["1971.54000000", "0.00700000"], ["1971.53000000", "4.34700000"], ["1971.50000000", "23.31340000"], ["1971.49000000", "0.00000000"], ["1971.48000000", "12.36390000"], ["1971.47000000", "36.77710000"], ["1971.46000000", "7.11450000"], ["1971.40000000", "0.05570000"], ["1971.35000000", "30.43140000"], ["1971.34000000", "29.82560000"], ["1971.33000000", "3.07540000"], ["1971.27000000", "17.49240000"], ["1971.26000000", "23.29190000"], ["1971.24000000", "14.30230000"], ["1971.23000000", "0.60840000"], ["1971.17000000", "6.58000000"], ["1971.16000000", "3.05290000"], ["1971.15000000", "0.40260000"], ["1971.13000000", "0.02050000"], ["1971.12000000", "7.40440000"], ["1971.11000000", "1.61690000"], ["1971.10000000", "0.05570000"], ["1971.08000000", "0.20270000"], ["1971.07000000", "13.67990000"], ["1971.02000000", "1.52330000"], ["1971.01000000", "0.31300000"], ["1971.00000000", "8.18180000"], ["1970.94000000", "1.27580000"], ["1970.93000000", "0.01730000"], ["1970.91000000", "36.51320000"], ["1970.90000000", "0.00310000"], ["1970.88000000", "0.03260000"], ["1970.86000000", "23.37760000"], ["1970.83000000", "0.11640000"], ["1970.80000000", "9.07220000"], ["1970.72000000", "27.45880000"], ["1970.70000000", "13.53440000"], ["1970.68000000", "14.72630000"], ["1970.50000000", "0.04450000"], ["1970.47000000", "0.00000000"], ["1970.33000000", "35.10230000"], ["1970.22000000", "32.74460000"], ["1970.14000000", "0.12790000"], ["1970.13000000", "7.20750000"], ["1970.03000000", "0.21970000"], ["1970.02000000", "0.13180000"], ["1969.87000000", "0.00000000"], ["1969.83000000", "0.00260000"], ["1969.82000000", "0.00260000"], ["1969.74000000", "0.02710000"], ["1969.62000000", "2.73900000"], ["1969.54000000", "1.01210000"], ["1969.46000000", "5.97010000"], ["1969.44000000", "0.20470000"], ["1969.36000000", "4.37820000"], ["1969.30000000", "18.45550000"], ["1969.28000000", "1.21230000"], ["1969.16000000", "0.00000000"], ["1969.12000000", "0.00000000"], ["1969.07000000", "0.32400000"], ["1968.79000000", "0.17420000"], ["1968.58000000", "6.96530000"], ["1968.51000000", "0.31260000"], ["1968.34000000", "0.20280000"], ["1968.24000000", "6.74500000"], ["1967.39000000", "8.57680000"], ["1966.89000000", "0.00350000"], ["1966.83000000", "0.58840000"], ["1966.70000000", "0.02460000"], ["1966.05000000", "6.45240000"], ["1965.99000000", "0.00000000"], ["1965.90000000", "0.00710000"], ["1962.96000000", "0.44040000"], ["1962.94000000", "0.00000000"], ["1962.78000000", "0.64020000"], ["1960.98000000", "0.03600000"], ["1960.77000000", "0.03820000"], ["1960.55000000", "0.03830000"], ["1960.33000000", "0.05840000"], ["1960.12000000", "0.04070000"], ["1959.90000000", "0.03320000"], ["1959.69000000", "0.03320000"], ["1956.04000000", "0.00000000"], ["1944.37000000", "0.00000000"], ["1942.72000000", "32.84460000"], ["1938.93000000", "0.03620000"], ["1938.91000000", "0.00300000"], ["1874.51000000", "0.00870000"], ["1874.25000000", "0.00000000"], ["1873.30000000", "0.00760000"], ["1873.14000000", "0.00290000"], ["1873.11000000", "0.00720000"], ["1774.80000000", "0.00710000"], ["1774.68000000", "0.04540000"], ["1774.60000000", "0.00000000"], ["1774.53000000", "0.01370000"]], "a": [["1971.71000000", "0.00000000"], ["1971.73000000", "0.00000000"], ["1971.74000000", "0.00000000"], ["1971.75000000", "0.00000000"], ["1971.76000000", "0.00000000"], ["1971.77000000", "0.00000000"], ["1971.78000000", "0.00000000"], ["1971.79000000", "0.00000000"], ["1971.80000000", "0.00000000"], ["1971.81000000", "0.00000000"], ["1971.82000000", "0.00000000"], ["1971.83000000", "0.00000000"], ["1971.84000000", "0.00000000"], ["1971.85000000", "0.00000000"], ["1971.86000000", "0.00000000"], ["1971.87000000", "0.00000000"], ["1971.90000000", "0.00000000"], ["1971.91000000", "0.00000000"], ["1971.92000000", "0.00000000"], ["1971.93000000", "0.00000000"], ["1971.94000000", "0.00000000"], ["1971.95000000", "0.00000000"], ["1971.97000000", "0.00000000"], ["1971.99000000", "0.00000000"], ["1972.00000000", "0.00000000"], ["1972.01000000", "0.00000000"], ["1972.03000000", "0.00000000"], ["1972.04000000", "0.00000000"], ["1972.06000000", "0.00520000"], ["1972.08000000", "0.00560000"], ["1972.09000000", "0.00260000"], ["1972.10000000", "0.00830000"], ["1972.11000000", "0.00260000"], ["1972.12000000", "0.00260000"], ["1972.13000000", "0.00800000"], ["1972.14000000", "0.00650000"], ["1972.15000000", "0.00260000"], ["1972.16000000", "0.03260000"], ["1972.17000000", "0.10800000"], ["1972.18000000", "0.00540000"], ["1972.19000000", "0.66530000"], ["1972.21000000", "0.00000000"], ["1972.22000000", "0.03300000"], ["1972.27000000", "0.00000000"], ["1972.28000000", "0.00000000"], ["1972.30000000", "0.00870000"], ["1972.31000000", "0.05000000"], ["1972.32000000", "0.65730000"], ["1972.33000000", "0.00000000"], ["1972.34000000", "14.83880000"], ["1972.35000000", "0.51870000"], ["1972.36000000", "0.00000000"], ["1972.37000000", "0.87320000"], ["1972.39000000", "0.00000000"], ["1972.40000000", "12.59340000"], ["1972.41000000", "0.00000000"], ["1972.43000000", "29.61480000"], ["1972.48000000", "4.37300000"], ["1972.50000000", "0.25720000"], ["1972.51000000", "0.00000000"], ["1972.54000000", "0.00390000"], ["1972.56000000", "0.77440000"], ["1972.57000000", "0.00000000"], ["1972.58000000", "0.33000000"], ["1972.59000000", "0.51560000"], ["1972.60000000", "9.37400000"], ["1972.61000000", "0.00000000"], ["1972.63000000", "9.93140000"], ["1972.66000000", "0.45900000"], ["1972.67000000", "0.00260000"], ["1972.68000000", "0.00000000"], ["1972.69000000", "0.00000000"], ["1972.70000000", "0.70570000"], ["1972.74000000", "10.85030000"], ["1972.75000000", "0.00760000"], ["1972.76000000", "0.07980000"], ["1972.78000000", "0.00000000"], ["1972.79000000", "0.00000000"], ["1972.80000000", "11.84600000"], ["1972.81000000", "1.20550000"], ["1972.82000000", "0.00000000"], ["1972.90000000", "5.70110000"], ["1972.91000000", "0.00000000"], ["1972.92000000", "8.30380000"], ["1972.94000000", "7.10430000"], ["1973.00000000", "0.00570000"], ["1973.01000000", "8.52050000"], ["1973.03000000", "22.57630000"], ["1973.04000000", "0.00000000"], ["1973.05000000", "0.00000000"], ["1973.07000000", "0.00560000"], ["1973.08000000", "0.00000000"], ["1973.09000000", "0.57790000"], ["1973.14000000", "10.64880000"], ["1973.16000000", "15.87480000"], ["1973.18000000", "9.03650000"], ["1973.19000000", "0.00000000"], ["1973.21000000", "0.94500000"], ["1973.22000000", "0.00000000"], ["1973.23000000", "1.29670000"], ["1973.26000000", "23.76770000"], ["1973.32000000", "6.22930000"], ["1973.33000000", "0.80000000"], ["1973.38000000", "0.00000000"], ["1973.42000000", "13.00460000"], ["1973.43000000", "8.52050000"], ["1973.48000000", "1.22580000"], ["1973.54000000", "13.62120000"], ["1973.55000000", "7.21840000"], ["1973.57000000", "0.00260000"], ["1973.63000000", "7.10300000"], ["1973.66000000", "7.95870000"], ["1973.67000000", "16.37360000"], ["1973.73000000", "0.00300000"], ["1973.76000000", "6.25900000"], ["1973.77000000", "0.00260000"], ["1973.78000000", "9.65950000"], ["1973.80000000", "7.10350000"], ["1973.85000000", "7.10040000"], ["1973.87000000", "28.67700000"], ["1973.89000000", "7.10040000"], ["1973.91000000", "12.12050000"], ["1973.95000000", "7.99210000"], ["1973.96000000", "0.84580000"], ["1973.99000000", "7.10040000"], ["1974.07000000", "7.91300000"], ["1974.11000000", "10.70300000"], ["1974.15000000", "9.72600000"], ["1974.20000000", "21.27760000"], ["1974.24000000", "0.13260000"], ["1974.28000000", "0.00560000"], ["1974.29000000", "7.10040000"], ["1974.33000000", "7.61730000"], ["1974.35000000", "9.77950000"], ["1974.36000000", "0.00000000"], ["1974.44000000", "7.10040000"], ["1974.45000000", "8.04960000"], ["1974.53000000", "13.52350000"], ["1974.55000000", "7.10300000"], ["1974.56000000", "0.03000000"], ["1974.59000000", "0.00000000"], ["1974.61000000", "0.00300000"], ["1974.67000000", "7.10300000"], ["1974.77000000", "7.10040000"], ["1974.86000000", "0.00000000"], ["1974.99000000", "0.00000000"], ["1975.19000000", "13.70180000"], ["1975.26000000", "22.57370000"], ["1975.48000000", "14.72900000"], ["1975.81000000", "13.52350000"], ["1976.14000000", "13.52610000"], ["1976.17000000", "0.01930000"], ["1976.76000000", "0.05350000"], ["1976.79000000", "0.00000000"], ["1976.84000000", "0.00260000"], ["1976.93000000", "0.00260000"], ["1978.23000000", "0.00760000"], ["1978.25000000", "0.03040000"], ["1978.65000000", "0.15110000"], ["1978.84000000", "3.85090000"], ["1979.96000000", "0.00000000"], ["1980.07000000", "126.41970000"], ["1980.53000000", "0.02000000"], ["1980.54000000", "0.00000000"], ["1980.64000000", "0.00000000"], ["1980.71000000", "0.48720000"], ["1981.62000000", "0.00260000"], ["1986.88000000", "0.00000000"], ["1987.15000000", "0.00000000"], ["1987.30000000", "0.00000000"], ["2346.65000000", "0.00380000"]], "_local_ts_utc": "2026-06-01T07:49:05.211752+00:00"}
{"e": "depthUpdate", "E": 1780300146415, "s": "ETHUSDT", "U": 76583104797, "u": 76583105088, "b": [["1972.05000000", "79.55630000"], ["1972.04000000", "0.00770000"], ["1972.03000000", "0.00770000"], ["1972.02000000", "0.00260000"], ["1972.01000000", "0.00800000"], ["1972.00000000", "0.15350000"], ["1971.99000000", "1.28750000"], ["1971.96000000", "0.00000000"], ["1971.94000000", "0.00800000"], ["1971.93000000", "1.16840000"], ["1971.91000000", "0.00540000"], ["1971.90000000", "13.55440000"], ["1971.89000000", "17.56210000"], ["1971.88000000", "22.57370000"], ["1971.85000000", "0.00000000"], ["1971.84000000", "0.03000000"], ["1971.83000000", "0.01280000"], ["1971.82000000", "0.25380000"], ["1971.81000000", "0.00000000"], ["1971.80000000", "0.00570000"], ["1971.79000000", "15.87730000"], ["1971.78000000", "7.10040000"], ["1971.77000000", "18.44670000"], ["1971.76000000", "9.65950000"], ["1971.75000000", "2.73170000"], ["1971.74000000", "0.00000000"], ["1971.73000000", "0.00000000"], ["1971.69000000", "19.14690000"], ["1971.66000000", "13.56680000"], ["1971.59000000", "14.49040000"], ["1971.58000000", "1.11100000"], ["1971.50000000", "23.05960000"], ["1971.48000000", "12.74200000"], ["1971.46000000", "7.11190000"], ["1971.36000000", "42.92340000"], ["1971.35000000", "20.11160000"], ["1971.24000000", "14.20080000"], ["1971.23000000", "0.00000000"], ["1971.17000000", "0.00000000"], ["1970.87000000", "8.84970000"], ["1970.80000000", "0.55670000"], ["1970.72000000", "0.69280000"], ["1970.67000000", "0.58160000"], ["1970.35000000", "2.97780000"], ["1970.34000000", "7.17450000"], ["1970.29000000", "17.27140000"], ["1970.19000000", "3.81980000"], ["1969.89000000", "2.66800000"], ["1969.88000000", "1.48270000"], ["1969.60000000", "25.43260000"], ["1969.34000000", "0.01710000"], ["1969.30000000", "32.44520000"], ["1969.25000000", "58.59280000"], ["1969.08000000", "4.78520000"], ["1968.80000000", "0.05070000"], ["1968.35000000", "0.00000000"], ["1966.12000000", "0.02630000"], ["1965.66000000", "0.00000000"], ["1960.78000000", "0.12700000"], ["1959.75000000", "90.00770000"], ["1959.47000000", "0.06130000"], ["1959.26000000", "0.03630000"], ["1959.04000000", "0.04800000"], ["1946.20000000", "0.21040000"], ["1774.85000000", "0.01240000"], ["1192.00000000", "0.00000000"]], "a": [["1972.06000000", "25.60690000"], ["1972.07000000", "0.00000000"], ["1972.10000000", "0.01370000"], ["1972.11000000", "0.61000000"], ["1972.13000000", "0.00260000"], ["1972.14000000", "0.00260000"], ["1972.16000000", "0.00260000"], ["1972.17000000", "0.00000000"], ["1972.18000000", "0.00000000"], ["1972.19000000", "0.00300000"], ["1972.26000000", "0.00000000"], ["1972.27000000", "0.00000000"], ["1972.30000000", "0.03050000"], ["1972.31000000", "0.05000000"], ["1972.32000000", "1.33470000"], ["1972.33000000", "7.73330000"], ["1972.34000000", "4.01300000"], ["1972.36000000", "0.00260000"], ["1972.39000000", "7.10040000"], ["1972.47000000", "22.72130000"], ["1972.53000000", "7.53540000"], ["1972.54000000", "7.10430000"], ["1972.55000000", "0.09460000"], ["1972.59000000", "27.72690000"], ["1972.60000000", "12.38880000"], ["1972.61000000", "6.46760000"], ["1972.62000000", "31.10440000"], ["1972.64000000", "0.90670000"], ["1972.65000000", "0.03300000"], ["1972.66000000", "0.00000000"], ["1972.68000000", "0.00000000"], ["1972.70000000", "0.00570000"], ["1972.71000000", "1.50000000"], ["1972.74000000", "0.00690000"], ["1972.76000000", "7.18020000"], ["1972.77000000", "10.83050000"], ["1972.78000000", "14.20080000"], ["1972.79000000", "22.04400000"], ["1972.80000000", "0.03830000"], ["1972.82000000", "6.78510000"], ["1972.88000000", "0.64800000"], ["1972.92000000", "15.40420000"], ["1973.00000000", "9.46320000"], ["1973.01000000", "22.04400000"], ["1973.02000000", "0.00000000"], ["1973.14000000", "14.56430000"], ["1973.16000000", "15.97610000"], ["1973.20000000", "9.10410000"], ["1973.24000000", "6.36530000"], ["1973.30000000", "7.70510000"], ["1973.31000000", "0.88290000"], ["1973.32000000", "0.01150000"], ["1973.34000000", "13.52740000"], ["1973.40000000", "7.33780000"], ["1973.48000000", "1.21570000"], ["1973.53000000", "6.51380000"], ["1973.54000000", "13.53000000"], ["1973.55000000", "1.05300000"], ["1973.66000000", "11.72460000"], ["1973.86000000", "11.21070000"], ["1973.90000000", "14.42740000"], ["1973.91000000", "3.60000000"], ["1973.95000000", "0.03600000"], ["1974.04000000", "3.10530000"], ["1974.10000000", "0.00000000"], ["1974.15000000", "1.20550000"], ["1974.20000000", "23.30300000"], ["1974.33000000", "0.51690000"], ["1974.35000000", "0.45900000"], ["1974.44000000", "0.00000000"], ["1974.45000000", "0.94920000"], ["1974.55000000", "0.00260000"], ["1974.67000000", "0.00260000"], ["1974.68000000", "0.00000000"], ["1974.69000000", "0.00000000"], ["1974.72000000", "0.03300000"], ["1974.76000000", "0.01020000"], ["1974.77000000", "0.00000000"], ["1974.86000000", "13.52350000"], ["1975.19000000", "0.17830000"], ["1975.48000000", "1.20550000"], ["1975.81000000", "0.00000000"], ["1976.14000000", "0.00260000"], ["1976.78000000", "0.00260000"], ["1977.00000000", "0.00260000"], ["1977.09000000", "0.13390000"], ["1977.14000000", "0.00000000"], ["1980.71000000", "0.00000000"]], "_local_ts_utc": "2026-06-01T07:49:05.311716+00:00"}
{"e": "depthUpdate", "E": 1780300146515, "s": "ETHUSDT", "U": 76583105089, "u": 76583105780, "b": [["1972.10000000", "88.01310000"], ["1972.09000000", "14.97650000"], ["1972.08000000", "0.05490000"], ["1972.07000000", "0.00000000"], ["1972.06000000", "0.00540000"], ["1972.05000000", "7.58520000"], ["1972.04000000", "0.00260000"], ["1972.03000000", "0.00260000"], ["1972.01000000", "0.00260000"], ["1972.00000000", "0.14810000"], ["1971.99000000", "1.23770000"], ["1971.95000000", "0.00000000"], ["1971.94000000", "0.00000000"], ["1971.93000000", "1.16580000"], ["1971.91000000", "14.20080000"], ["1971.90000000", "0.00260000"], ["1971.89000000", "18.87910000"], ["1971.88000000", "0.00000000"], ["1971.86000000", "0.00690000"], ["1971.85000000", "0.00000000"], ["1971.83000000", "6.79590000"], ["1971.82000000", "8.52050000"], ["1971.81000000", "7.10040000"], ["1971.80000000", "8.41600000"], ["1971.79000000", "0.66110000"], ["1971.78000000", "23.42710000"], ["1971.77000000", "18.45690000"], ["1971.76000000", "0.00000000"], ["1971.70000000", "3.86590000"], ["1971.69000000", "19.22270000"], ["1971.68000000", "20.66740000"], ["1971.66000000", "0.04720000"], ["1971.65000000", "0.01520000"], ["1971.61000000", "0.25380000"], ["1971.59000000", "0.00000000"], ["1971.58000000", "15.84370000"], ["1971.54000000", "13.80050000"], ["1971.51000000", "0.34830000"], ["1971.50000000", "13.13610000"], ["1971.48000000", "13.57950000"], ["1971.45000000", "0.00280000"], ["1971.41000000", "0.10150000"], ["1971.40000000", "13.57920000"], ["1971.39000000", "0.20000000"], ["1971.37000000", "17.77310000"], ["1971.36000000", "26.83160000"], ["1971.35000000", "6.58810000"], ["1971.33000000", "2.87540000"], ["1971.24000000", "14.20080000"], ["1971.14000000", "16.13950000"], ["1971.11000000", "0.81690000"], ["1971.10000000", "0.05310000"], ["1971.08000000", "1.00270000"], ["1970.89000000", "0.24810000"], ["1970.83000000", "0.01640000"], ["1970.79000000", "0.00910000"], ["1970.67000000", "0.58160000"], ["1970.60000000", "13.93050000"], ["1970.56000000", "1.04440000"], ["1970.55000000", "1.80760000"], ["1970.49000000", "14.43620000"], ["1970.35000000", "0.15790000"], ["1970.34000000", "7.17450000"], ["1970.33000000", "20.90250000"], ["1970.19000000", "1.70050000"], ["1970.13000000", "7.20800000"], ["1969.94000000", "1.52150000"], ["1969.69000000", "0.24510000"], ["1969.66000000", "16.33270000"], ["1969.36000000", "0.51010000"], ["1969.31000000", "14.54560000"], ["1969.03000000", "0.00700000"], ["1966.83000000", "0.00690000"], ["1965.70000000", "0.58970000"], ["1964.05000000", "0.00420000"], ["1932.39000000", "0.25820000"], ["1774.89000000", "0.00620000"], ["1774.85000000", "0.00000000"], ["1577.67000000", "0.02100000"], ["1577.64000000", "0.03100000"], ["1577.48000000", "0.14700000"]], "a": [["1972.06000000", "0.00000000"], ["1972.08000000", "0.00000000"], ["1972.09000000", "0.00000000"], ["1972.10000000", "0.00000000"], ["1972.11000000", "0.62550000"], ["1972.12000000", "0.00770000"], ["1972.13000000", "0.00770000"], ["1972.14000000", "0.00260000"], ["1972.15000000", "0.10260000"], ["1972.16000000", "0.00260000"], ["1972.17000000", "0.00000000"], ["1972.19000000", "0.00560000"], ["1972.20000000", "0.00830000"], ["1972.21000000", "0.00260000"], ["1972.22000000", "0.03560000"], ["1972.26000000", "0.00540000"], ["1972.27000000", "1.33940000"], ["1972.30000000", "0.02150000"], ["1972.31000000", "0.05000000"], ["1972.32000000", "1.33470000"], ["1972.33000000", "0.63290000"], ["1972.34000000", "0.00390000"], ["1972.35000000", "0.50710000"], ["1972.36000000", "0.01020000"], ["1972.37000000", "0.00000000"], ["1972.38000000", "0.00260000"], ["1972.39000000", "0.00000000"], ["1972.40000000", "12.59340000"], ["1972.41000000", "0.00000000"], ["1972.42000000", "3.29990000"], ["1972.43000000", "2.84980000"], ["1972.46000000", "29.67410000"], ["1972.47000000", "0.00000000"], ["1972.48000000", "4.37300000"], ["1972.49000000", "0.00260000"], ["1972.50000000", "0.26880000"], ["1972.52000000", "8.52050000"], ["1972.53000000", "10.60000000"], ["1972.54000000", "0.00390000"], ["1972.58000000", "21.30120000"], ["1972.59000000", "0.00260000"], ["1972.60000000", "4.76480000"], ["1972.61000000", "0.00000000"], ["1972.62000000", "0.01020000"], ["1972.68000000", "1.20550000"], ["1972.71000000", "0.00000000"], ["1972.72000000", "8.52050000"], ["1972.73000000", "0.20000000"], ["1972.74000000", "13.70640000"], ["1972.75000000", "43.88250000"], ["1972.76000000", "0.07980000"], ["1972.77000000", "1.30000000"], ["1972.78000000", "0.00000000"], ["1972.79000000", "0.00000000"], ["1972.80000000", "0.63230000"], ["1972.81000000", "0.00000000"], ["1972.82000000", "0.00000000"], ["1972.83000000", "0.00000000"], ["1972.90000000", "13.54150000"], ["1972.91000000", "29.14440000"], ["1972.92000000", "1.20340000"], ["1972.94000000", "0.00390000"], ["1972.95000000", "7.10300000"], ["1972.97000000", "0.01020000"], ["1973.00000000", "15.81980000"], ["1973.01000000", "0.00000000"], ["1973.03000000", "29.67670000"], ["1973.07000000", "26.77160000"], ["1973.12000000", "10.56910000"], ["1973.13000000", "27.88800000"], ["1973.14000000", "0.00390000"], ["1973.16000000", "1.77530000"], ["1973.18000000", "0.51600000"], ["1973.20000000", "13.39150000"], ["1973.24000000", "15.36100000"], ["1973.25000000", "7.10040000"], ["1973.26000000", "23.16770000"], ["1973.30000000", "13.88060000"], ["1973.31000000", "0.84300000"], ["1973.33000000", "7.70040000"], ["1973.34000000", "0.00390000"], ["1973.37000000", "7.95730000"], ["1973.39000000", "29.14440000"], ["1973.40000000", "1.03740000"], ["1973.41000000", "12.22050000"], ["1973.42000000", "0.00260000"], ["1973.43000000", "0.00000000"], ["1973.45000000", "0.00000000"], ["1973.51000000", "3.07670000"], ["1973.52000000", "9.19690000"], ["1973.53000000", "0.00260000"], ["1973.54000000", "0.00650000"], ["1973.56000000", "0.00000000"], ["1973.60000000", "21.05120000"], ["1973.61000000", "14.20080000"], ["1973.63000000", "8.52310000"], ["1973.65000000", "20.77500000"], ["1973.66000000", "0.00260000"], ["1973.67000000", "0.59400000"], ["1973.83000000", "15.75820000"], ["1973.84000000", "13.52910000"], ["1973.85000000", "15.62090000"], ["1973.86000000", "0.17050000"], ["1973.87000000", "15.15350000"], ["1973.90000000", "1.20810000"], ["1973.95000000", "0.03600000"], ["1973.98000000", "0.00260000"], ["1974.04000000", "0.00000000"], ["1974.09000000", "0.00000000"], ["1974.19000000", "7.10040000"], ["1974.20000000", "14.17720000"], ["1974.29000000", "0.00000000"], ["1974.33000000", "7.61730000"], ["1974.41000000", "0.03130000"], ["1974.43000000", "3.60260000"], ["1974.45000000", "0.94920000"], ["1974.46000000", "0.00000000"], ["1974.55000000", "0.00260000"], ["1974.56000000", "0.15660000"], ["1974.57000000", "0.13200000"], ["1974.63000000", "0.00000000"], ["1974.77000000", "0.00000000"], ["1974.85000000", "0.00260000"], ["1974.99000000", "0.00000000"], ["1975.08000000", "15.00000000"], ["1975.19000000", "0.17830000"], ["1975.48000000", "1.20550000"], ["1975.81000000", "0.00000000"], ["1976.46000000", "0.00000000"], ["1976.78000000", "0.00000000"], ["1977.14000000", "0.00260000"], ["1977.23000000", "0.00970000"], ["1979.31000000", "0.25090000"], ["1980.75000000", "0.00000000"], ["1980.99000000", "1.33590000"], ["1987.37000000", "0.00000000"]], "_local_ts_utc": "2026-06-01T07:49:05.411372+00:00"}
{"e": "depthUpdate", "E": 1780300146615, "s": "ETHUSDT", "U": 76583105781, "u": 76583106708, "b": [["1972.29000000", "71.84700000"], ["1972.28000000", "0.00510000"], ["1972.27000000", "10.62710000"], ["1972.26000000", "4.97710000"], ["1972.25000000", "0.00260000"], ["1972.24000000", "0.00000000"], ["1972.23000000", "0.00540000"], ["1972.22000000", "3.00540000"], ["1972.21000000", "6.47020000"], ["1972.20000000", "0.00260000"], ["1972.19000000", "0.01320000"], ["1972.18000000", "1.00740000"], ["1972.17000000", "0.00000000"], ["1972.16000000", "6.36000000"], ["1972.15000000", "0.00260000"], ["1972.14000000", "0.00000000"], ["1972.13000000", "0.00260000"], ["1972.12000000", "0.00270000"], ["1972.11000000", "21.30120000"], ["1972.10000000", "5.23400000"], ["1972.09000000", "0.03800000"], ["1972.08000000", "0.00000000"], ["1972.07000000", "0.00260000"], ["1972.06000000", "0.00390000"], ["1972.05000000", "1.11500000"], ["1972.04000000", "0.00000000"], ["1972.03000000", "0.00000000"], ["1972.02000000", "8.52050000"], ["1972.01000000", "7.10040000"], ["1972.00000000", "0.17850000"], ["1971.99000000", "10.11670000"], ["1971.98000000", "7.10300000"], ["1971.97000000", "1.31220000"], ["1971.93000000", "1.16580000"], ["1971.92000000", "8.52050000"], ["1971.90000000", "0.00570000"], ["1971.88000000", "24.86020000"], ["1971.87000000", "22.57370000"], ["1971.86000000", "0.62970000"], ["1971.83000000", "13.53630000"], ["1971.80000000", "7.10610000"], ["1971.79000000", "16.27580000"], ["1971.78000000", "7.10040000"], ["1971.77000000", "18.45430000"], ["1971.72000000", "8.52050000"], ["1971.67000000", "22.60050000"], ["1971.66000000", "0.04330000"], ["1971.60000000", "15.11690000"], ["1971.58000000", "15.94520000"], ["1971.54000000", "13.53050000"], ["1971.51000000", "0.74830000"], ["1971.50000000", "13.93610000"], ["1971.41000000", "0.00000000"], ["1971.37000000", "18.17310000"], ["1971.30000000", "3.81700000"], ["1971.29000000", "1.00460000"], ["1971.22000000", "7.10040000"], ["1971.20000000", "12.17200000"], ["1971.17000000", "0.00000000"], ["1971.15000000", "0.00260000"], ["1971.11000000", "0.41690000"], ["1971.09000000", "22.09850000"], ["1971.08000000", "0.00270000"], ["1970.93000000", "0.01730000"], ["1970.91000000", "37.64320000"], ["1970.89000000", "0.14810000"], ["1970.86000000", "22.57760000"], ["1970.59000000", "22.71960000"], ["1970.49000000", "7.51670000"], ["1970.48000000", "13.51710000"], ["1970.43000000", "1.94980000"], ["1970.40000000", "1.22190000"], ["1970.34000000", "4.26360000"], ["1970.33000000", "13.80260000"], ["1970.29000000", "17.48550000"], ["1970.19000000", "1.70050000"], ["1970.13000000", "0.10760000"], ["1969.97000000", "0.00000000"], ["1969.36000000", "0.51010000"], ["1969.31000000", "1.02210000"], ["1969.08000000", "4.02520000"], ["1966.26000000", "0.01900000"], ["1966.17000000", "0.14510000"], ["1964.45000000", "0.00550000"], ["1955.84000000", "1.13850000"], ["1934.19000000", "0.38370000"], ["1924.32000000", "0.13130000"], ["1775.07000000", "0.00620000"], ["1774.89000000", "0.00000000"]], "a": [["1972.11000000", "0.00000000"], ["1972.12000000", "0.00000000"], ["1972.13000000", "0.00000000"], ["1972.14000000", "0.00000000"], ["1972.15000000", "0.00000000"], ["1972.16000000", "0.00000000"], ["1972.19000000", "0.00000000"], ["1972.20000000", "0.00000000"], ["1972.21000000", "0.00000000"], ["1972.22000000", "0.00000000"], ["1972.23000000", "0.00000000"], ["1972.26000000", "0.00000000"], ["1972.27000000", "0.00000000"], ["1972.30000000", "9.25560000"], ["1972.31000000", "0.05260000"], ["1972.32000000", "0.00260000"], ["1972.33000000", "0.00260000"], ["1972.34000000", "0.00650000"], ["1972.35000000", "0.00260000"], ["1972.36000000", "0.00260000"], ["1972.38000000", "0.00260000"], ["1972.39000000", "0.00540000"], ["1972.40000000", "0.00830000"], ["1972.41000000", "0.00000000"], ["1972.42000000", "0.00260000"], ["1972.43000000", "0.00000000"], ["1972.45000000", "0.00000000"], ["1972.46000000", "0.00000000"], ["1972.47000000", "0.01160000"], ["1972.48000000", "0.03000000"], ["1972.49000000", "0.00260000"], ["1972.51000000", "0.00000000"], ["1972.52000000", "0.00300000"], ["1972.53000000", "0.66230000"], ["1972.57000000", "0.00000000"], ["1972.58000000", "0.00000000"], ["1972.60000000", "2.22490000"], ["1972.62000000", "13.57820000"], ["1972.63000000", "0.00000000"], ["1972.68000000", "0.00000000"], ["1972.70000000", "14.61620000"], ["1972.71000000", "14.20080000"], ["1972.72000000", "0.00000000"], ["1972.73000000", "0.00000000"], ["1972.74000000", "15.62780000"], ["1972.75000000", "22.58130000"], ["1972.77000000", "0.00000000"], ["1972.79000000", "4.34500000"], ["1972.81000000", "0.00000000"], ["1972.88000000", "6.56340000"], ["1972.89000000", "7.20040000"], ["1972.90000000", "21.14510000"], ["1972.91000000", "15.62090000"], ["1972.92000000", "0.00000000"], ["1972.93000000", "1.50000000"], ["1972.98000000", "9.93140000"], ["1973.06000000", "8.52050000"], ["1973.09000000", "0.49200000"], ["1973.10000000", "0.00570000"], ["1973.13000000", "14.36450000"], ["1973.19000000", "13.52350000"], ["1973.20000000", "13.39410000"], ["1973.29000000", "0.43900000"], ["1973.33000000", "7.10040000"], ["1973.40000000", "0.23740000"], ["1973.41000000", "9.06220000"], ["1973.42000000", "0.00260000"], ["1973.47000000", "0.00260000"], ["1973.49000000", "0.00000000"], ["1973.51000000", "3.27670000"], ["1973.53000000", "0.40260000"], ["1973.62000000", "0.81320000"], ["1973.75000000", "0.01020000"], ["1973.82000000", "8.52050000"], ["1973.85000000", "7.10040000"], ["1973.98000000", "7.84920000"], ["1974.06000000", "0.00300000"], ["1974.16000000", "0.00000000"], ["1974.19000000", "7.10040000"], ["1974.29000000", "7.10040000"], ["1974.32000000", "7.10300000"], ["1974.33000000", "0.51690000"], ["1974.43000000", "10.70300000"], ["1974.48000000", "7.10040000"], ["1974.67000000", "0.00260000"], ["1974.69000000", "0.00000000"], ["1974.88000000", "0.03000000"], ["1975.19000000", "13.70180000"], ["1975.48000000", "1.20550000"], ["1976.84000000", "1.57260000"], ["1977.29000000", "0.00260000"], ["1977.38000000", "0.00260000"], ["1978.37000000", "0.00380000"], ["1980.99000000", "0.00000000"], ["1987.52000000", "0.00000000"], ["2000.52000000", "0.03010000"], ["2362.75000000", "0.00380000"]], "_local_ts_utc": "2026-06-01T07:49:05.511366+00:00"}
{"e": "depthUpdate", "E": 1780300146715, "s": "ETHUSDT", "U": 76583106709, "u": 76583106818, "b": [["1972.29000000", "71.85240000"], ["1972.28000000", "2.55450000"], ["1972.27000000", "0.51310000"], ["1972.26000000", "0.00520000"], ["1972.25000000", "0.00260000"], ["1972.23000000", "0.00800000"], ["1972.22000000", "3.00800000"], ["1972.21000000", "6.47020000"], ["1972.19000000", "0.00780000"], ["1972.18000000", "1.42060000"], ["1972.17000000", "0.00000000"], ["1972.16000000", "12.12540000"], ["1972.15000000", "0.00000000"], ["1972.13000000", "0.00000000"], ["1972.12000000", "22.04400000"], ["1972.10000000", "11.39780000"], ["1972.09000000", "0.03540000"], ["1972.08000000", "22.57370000"], ["1972.05000000", "1.06770000"], ["1971.99000000", "13.62580000"], ["1971.98000000", "7.61020000"], ["1971.97000000", "13.52350000"], ["1971.96000000", "0.64420000"], ["1971.89000000", "17.56470000"], ["1971.79000000", "15.64770000"], ["1971.69000000", "23.69300000"], ["1971.66000000", "0.04590000"], ["1971.35000000", "0.00000000"], ["1971.09000000", "21.99850000"], ["1970.95000000", "0.10000000"], ["1970.87000000", "8.90000000"], ["1970.75000000", "3.33200000"], ["1970.59000000", "14.19980000"], ["1970.08000000", "1.12540000"], ["1970.01000000", "145.22750000"], ["1969.79000000", "0.00940000"], ["1969.56000000", "0.00900000"], ["1969.55000000", "0.67930000"], ["1969.51000000", "0.00000000"], ["1969.41000000", "0.04250000"], ["1969.33000000", "0.05980000"], ["1968.18000000", "0.00320000"], ["1966.34000000", "0.00000000"], ["1955.84000000", "1.01200000"], ["1952.73000000", "0.62780000"], ["1950.08000000", "0.51990000"], ["1946.23000000", "0.12820000"], ["1922.35000000", "0.39240000"], ["1775.07000000", "0.01860000"]], "a": [["1972.30000000", "2.61380000"], ["1972.38000000", "0.00260000"], ["1972.39000000", "0.00260000"], ["1972.42000000", "0.00000000"], ["1972.44000000", "0.07060000"], ["1972.55000000", "0.72510000"], ["1972.57000000", "1.33520000"], ["1972.60000000", "8.42220000"], ["1972.61000000", "0.50700000"], ["1972.62000000", "14.22070000"], ["1972.64000000", "0.03000000"], ["1972.76000000", "0.00260000"], ["1972.80000000", "0.03830000"], ["1972.88000000", "4.79630000"], ["1973.23000000", "1.08260000"], ["1973.43000000", "0.07710000"], ["1973.56000000", "0.08660000"], ["1973.67000000", "0.80580000"], ["1973.86000000", "0.00000000"], ["1977.47000000", "0.14340000"], ["1977.56000000", "0.00000000"]], "_local_ts_utc": "2026-06-01T07:49:05.611499+00:00"}
{"e": "depthUpdate", "E": 1780300146815, "s": "ETHUSDT", "U": 76583106819, "u": 76583106898, "b": [["1972.29000000", "71.71710000"], ["1972.28000000", "0.01310000"], ["1972.27000000", "0.50770000"], ["1972.24000000", "0.00000000"], ["1972.23000000", "0.00800000"], ["1972.19000000", "0.01320000"], ["1972.17000000", "0.00270000"], ["1972.16000000", "0.00000000"], ["1972.13000000", "0.00000000"], ["1972.12000000", "0.00000000"], ["1972.11000000", "0.00000000"], ["1972.01000000", "7.72410000"], ["1971.95000000", "2.53560000"], ["1971.90000000", "0.01090000"], ["1971.65000000", "3.14490000"], ["1971.51000000", "0.79860000"], ["1971.31000000", "0.06860000"], ["1970.80000000", "1.35380000"], ["1970.20000000", "0.95660000"], ["1970.19000000", "1.08040000"], ["1968.86000000", "1.10940000"], ["1952.72000000", "0.14220000"], ["1950.08000000", "0.39300000"], ["1946.13000000", "0.51300000"], ["1942.27000000", "0.25680000"], ["1775.07000000", "0.03100000"]], "a": [["1972.30000000", "17.21850000"], ["1972.38000000", "0.00520000"], ["1972.39000000", "0.01420000"], ["1972.40000000", "0.01370000"], ["1972.41000000", "0.53010000"], ["1972.42000000", "1.33540000"], ["1972.50000000", "0.25720000"], ["1972.55000000", "2.76400000"], ["1972.59000000", "7.10300000"], ["1972.77000000", "1.20550000"], ["1973.77000000", "7.10300000"], ["1974.32000000", "0.00260000"], ["1974.48000000", "0.00000000"], ["2379.33000000", "0.00380000"]], "_local_ts_utc": "2026-06-01T07:49:05.711282+00:00"}
{"e": "depthUpdate", "E": 1780300146915, "s": "ETHUSDT", "U": 76583106899, "u": 76583106997, "b": [["1972.29000000", "22.18200000"], ["1972.28000000", "0.02090000"], ["1972.24000000", "0.00000000"], ["1972.22000000", "3.00260000"], ["1972.21000000", "0.00260000"], ["1972.20000000", "0.00520000"], ["1972.17000000", "0.00000000"], ["1972.11000000", "0.00540000"], ["1972.10000000", "0.53180000"], ["1972.08000000", "0.00000000"], ["1972.06000000", "0.00660000"], ["1972.04000000", "1.31870000"], ["1972.03000000", "4.90230000"], ["1972.00000000", "6.64610000"], ["1971.99000000", "10.11670000"], ["1971.98000000", "7.61020000"], ["1971.97000000", "0.00300000"], ["1971.90000000", "0.01350000"], ["1971.61000000", "0.35380000"], ["1971.60000000", "15.16720000"], ["1971.29000000", "0.20460000"], ["1971.26000000", "24.09190000"], ["1970.95000000", "0.00000000"], ["1970.86000000", "22.67760000"], ["1969.79000000", "13.53290000"], ["1955.84000000", "0.88550000"], ["1946.36000000", "0.00000000"], ["1934.19000000", "0.25580000"], ["1775.07000000", "0.04340000"]], "a": [["1972.30000000", "33.96020000"], ["1972.40000000", "0.00830000"], ["1972.41000000", "0.52470000"], ["1972.47000000", "0.00000000"], ["1972.52000000", "6.47060000"], ["1972.53000000", "10.17990000"], ["1972.54000000", "29.67800000"], ["1972.55000000", "0.09460000"], ["1972.57000000", "0.00000000"], ["1972.58000000", "8.52050000"], ["1972.62000000", "7.75310000"], ["1973.81000000", "0.00000000"], ["1973.82000000", "0.00000000"], ["1974.40000000", "0.03310000"], ["1974.42000000", "0.00000000"], ["1974.43000000", "3.60260000"], ["1974.88000000", "0.00000000"], ["1989.40000000", "0.00000000"], ["1990.33000000", "0.00000000"]], "_local_ts_utc": "2026-06-01T07:49:05.812404+00:00"}
{"e": "depthUpdate", "E": 1780300147015, "s": "ETHUSDT", "U": 76583106998, "u": 76583107300, "b": [["1972.29000000", "0.00000000"], ["1972.28000000", "0.00000000"], ["1972.27000000", "0.00000000"], ["1972.26000000", "0.00000000"], ["1972.25000000", "0.00000000"], ["1972.23000000", "0.00000000"], ["1972.22000000", "5.04140000"], ["1972.21000000", "0.00780000"], ["1972.19000000", "0.00800000"], ["1972.18000000", "1.41840000"], ["1972.17000000", "0.00000000"], ["1972.16000000", "0.00000000"], ["1972.11000000", "10.15670000"], ["1972.10000000", "0.03440000"], ["1972.09000000", "0.03800000"], ["1972.07000000", "0.00520000"], ["1972.06000000", "0.00930000"], ["1972.04000000", "0.00000000"], ["1972.03000000", "0.00000000"], ["1972.02000000", "0.00540000"], ["1972.01000000", "0.62370000"], ["1972.00000000", "0.18390000"], ["1971.99000000", "1.24040000"], ["1971.98000000", "0.50980000"], ["1971.96000000", "5.77170000"], ["1971.94000000", "1.32350000"], ["1971.92000000", "8.52050000"], ["1971.91000000", "0.00000000"], ["1971.90000000", "25.49790000"], ["1971.89000000", "31.13270000"], ["1971.88000000", "0.00000000"], ["1971.87000000", "0.00000000"], ["1971.84000000", "13.55350000"], ["1971.83000000", "0.01280000"], ["1971.82000000", "8.52050000"], ["1971.81000000", "7.10040000"], ["1971.80000000", "7.10610000"], ["1971.78000000", "7.37040000"], ["1971.51000000", "0.39860000"], ["1971.50000000", "13.13610000"], ["1971.48000000", "16.11780000"], ["1971.39000000", "0.00000000"], ["1971.37000000", "17.77310000"], ["1971.33000000", "3.27540000"], ["1971.31000000", "1.46860000"], ["1971.30000000", "3.81960000"], ["1971.29000000", "0.00460000"], ["1971.26000000", "23.49190000"], ["1971.11000000", "1.21690000"], ["1970.97000000", "0.03880000"], ["1970.89000000", "0.14810000"], ["1970.50000000", "15.66540000"], ["1970.40000000", "15.04540000"], ["1970.39000000", "14.20080000"], ["1970.34000000", "0.00000000"], ["1970.30000000", "15.62350000"], ["1970.25000000", "11.21130000"], ["1970.20000000", "2.95550000"], ["1970.10000000", "7.18790000"], ["1970.05000000", "4.38030000"], ["1970.00000000", "420.09140000"], ["1969.55000000", "4.62920000"], ["1969.51000000", "13.52350000"], ["1968.48000000", "0.01200000"], ["1968.26000000", "0.02560000"], ["1962.78000000", "0.15600000"], ["1922.80000000", "0.54510000"], ["1775.07000000", "0.00000000"], ["1775.00000000", "24.92710000"]], "a": [["1972.23000000", "97.26250000"], ["1972.24000000", "0.00000000"], ["1972.26000000", "0.00000000"], ["1972.27000000", "10.93300000"], ["1972.28000000", "3.41250000"], ["1972.29000000", "4.97970000"], ["1972.30000000", "5.41140000"], ["1972.32000000", "0.03260000"], ["1972.35000000", "0.01020000"], ["1972.38000000", "1.94250000"], ["1972.39000000", "6.47920000"], ["1972.40000000", "0.00570000"], ["1972.41000000", "2.13310000"], ["1972.44000000", "0.07060000"], ["1972.47000000", "4.34900000"], ["1972.50000000", "7.35760000"], ["1972.52000000", "1.20850000"], ["1972.60000000", "6.24950000"], ["1972.63000000", "0.00300000"], ["1972.69000000", "2.53830000"], ["1972.70000000", "28.13970000"], ["1972.73000000", "0.20000000"], ["1972.79000000", "0.00000000"], ["1972.85000000", "0.94500000"], ["1972.93000000", "1.30000000"], ["1973.36000000", "0.93470000"], ["1973.62000000", "0.01320000"], ["1973.75000000", "0.00260000"], ["1973.83000000", "0.00260000"], ["1973.98000000", "0.00260000"], ["1974.11000000", "3.60260000"], ["1974.16000000", "1.00200000"], ["1974.72000000", "0.00300000"], ["1975.19000000", "0.17830000"], ["1980.90000000", "0.48560000"], ["1989.87000000", "0.00000000"], ["2471.86000000", "0.00000000"]], "_local_ts_utc": "2026-06-01T07:49:05.911760+00:00"}
{"e": "depthUpdate", "E": 1780300147115, "s": "ETHUSDT", "U": 76583107301, "u": 76583107544, "b": [["1972.22000000", "6.80560000"], ["1972.21000000", "0.00520000"], ["1972.18000000", "0.00260000"], ["1972.17000000", "0.00540000"], ["1972.16000000", "0.41400000"], ["1972.14000000", "0.00000000"], ["1972.12000000", "0.00000000"], ["1972.11000000", "0.00260000"], ["1972.10000000", "0.00520000"], ["1972.09000000", "0.00260000"], ["1972.07000000", "0.01060000"], ["1972.06000000", "0.00930000"], ["1972.05000000", "0.00000000"], ["1972.04000000", "10.15450000"], ["1972.00000000", "0.14850000"], ["1971.99000000", "1.23770000"], ["1971.96000000", "0.00000000"], ["1971.94000000", "0.00000000"], ["1971.92000000", "0.00000000"], ["1971.91000000", "0.00000000"], ["1971.90000000", "19.72080000"], ["1971.89000000", "17.56470000"], ["1971.85000000", "0.02190000"], ["1971.84000000", "0.03000000"], ["1971.83000000", "0.01280000"], ["1971.82000000", "0.00000000"], ["1971.81000000", "0.00000000"], ["1971.80000000", "29.81940000"], ["1971.78000000", "0.00000000"], ["1971.76000000", "0.00000000"], ["1971.73000000", "13.52370000"], ["1971.72000000", "0.00000000"], ["1971.71000000", "0.00000000"], ["1971.70000000", "33.67960000"], ["1971.69000000", "16.59260000"], ["1971.68000000", "0.29730000"], ["1971.63000000", "0.04150000"], ["1971.61000000", "0.10000000"], ["1971.59000000", "13.52110000"], ["1971.57000000", "14.28380000"], ["1971.54000000", "0.00700000"], ["1971.48000000", "13.57950000"], ["1971.42000000", "13.67960000"], ["1971.40000000", "0.05570000"], ["1971.33000000", "2.87540000"], ["1971.31000000", "0.13700000"], ["1971.26000000", "23.52350000"], ["1971.20000000", "12.87200000"], ["1971.12000000", "7.30440000"], ["1971.11000000", "1.61690000"], ["1971.08000000", "0.80270000"], ["1970.86000000", "22.57760000"], ["1970.82000000", "0.00710000"], ["1970.75000000", "0.42550000"], ["1970.72000000", "0.79280000"], ["1970.60000000", "14.20050000"], ["1970.58000000", "0.40720000"], ["1970.26000000", "8.12470000"], ["1970.20000000", "0.95660000"], ["1970.11000000", "15.67740000"], ["1970.10000000", "0.08750000"], ["1970.08000000", "1.12540000"], ["1970.05000000", "11.47880000"], ["1970.01000000", "145.22750000"], ["1969.85000000", "3.89200000"], ["1969.50000000", "0.25640000"], ["1969.44000000", "0.23470000"], ["1969.31000000", "14.54320000"], ["1969.22000000", "32.36110000"], ["1969.03000000", "0.00700000"], ["1966.41000000", "0.00260000"], ["1956.47000000", "0.27330000"], ["1947.60000000", "0.00280000"], ["1938.93000000", "0.00580000"], ["1927.04000000", "0.00280000"], ["1775.00000000", "24.93950000"]], "a": [["1972.23000000", "97.57400000"], ["1972.26000000", "0.00000000"], ["1972.27000000", "4.12300000"], ["1972.28000000", "3.41510000"], ["1972.29000000", "4.97970000"], ["1972.30000000", "5.39980000"], ["1972.35000000", "0.63950000"], ["1972.36000000", "0.00000000"], ["1972.37000000", "0.01160000"], ["1972.38000000", "9.03840000"], ["1972.41000000", "3.66420000"], ["1972.46000000", "7.09850000"], ["1972.62000000", "7.11060000"], ["1972.88000000", "7.71140000"], ["1972.90000000", "21.95510000"], ["1972.99000000", "0.00000000"], ["1973.21000000", "0.00000000"], ["1973.29000000", "0.06090000"], ["1973.36000000", "0.13470000"], ["1973.44000000", "4.43000000"], ["1973.89000000", "0.00000000"], ["1974.29000000", "0.00000000"], ["1976.89000000", "0.14960000"], ["1977.43000000", "0.00000000"], ["1977.51000000", "0.03040000"], ["1978.25000000", "0.00000000"], ["1981.08000000", "0.70670000"], ["1984.25000000", "0.00000000"], ["2396.42000000", "0.15910000"]], "_local_ts_utc": "2026-06-01T07:49:06.011584+00:00"}
{"e": "depthUpdate", "E": 1780300147215, "s": "ETHUSDT", "U": 76583107545, "u": 76583108403, "b": [["1972.22000000", "0.00000000"], ["1972.21000000", "0.00000000"], ["1972.20000000", "0.00000000"], ["1972.19000000", "0.00000000"], ["1972.18000000", "0.00000000"], ["1972.17000000", "0.00000000"], ["1972.16000000", "0.00000000"], ["1972.11000000", "0.00000000"], ["1972.10000000", "0.00000000"], ["1972.09000000", "0.00000000"], ["1972.07000000", "0.00000000"], ["1972.06000000", "0.00000000"], ["1972.05000000", "0.00000000"], ["1972.04000000", "0.00000000"], ["1972.03000000", "0.00000000"], ["1972.02000000", "0.00000000"], ["1972.01000000", "0.00000000"], ["1972.00000000", "0.00000000"], ["1971.99000000", "0.00000000"], ["1971.98000000", "0.00000000"], ["1971.97000000", "0.00000000"], ["1971.96000000", "0.00000000"], ["1971.95000000", "20.27120000"], ["1971.94000000", "0.01320000"], ["1971.93000000", "1.16840000"], ["1971.91000000", "0.00000000"], ["1971.90000000", "0.01840000"], ["1971.89000000", "1.43420000"], ["1971.88000000", "0.00000000"], ["1971.87000000", "0.50000000"], ["1971.86000000", "0.00950000"], ["1971.85000000", "0.02450000"], ["1971.84000000", "0.03260000"], ["1971.83000000", "0.01540000"], ["1971.82000000", "0.00000000"], ["1971.80000000", "0.01060000"], ["1971.79000000", "7.51430000"], ["1971.78000000", "0.00540000"], ["1971.76000000", "0.00270000"], ["1971.75000000", "2.73470000"], ["1971.73000000", "0.00260000"], ["1971.71000000", "0.00000000"], ["1971.70000000", "3.86280000"], ["1971.69000000", "1.60340000"], ["1971.68000000", "0.04350000"], ["1971.67000000", "0.02680000"], ["1971.62000000", "0.00000000"], ["1971.61000000", "0.10000000"], ["1971.60000000", "8.57370000"], ["1971.59000000", "0.00000000"], ["1971.58000000", "5.63950000"], ["1971.57000000", "14.28000000"], ["1971.56000000", "7.10260000"], ["1971.52000000", "0.28380000"], ["1971.50000000", "9.53610000"], ["1971.49000000", "13.52110000"], ["1971.45000000", "6.59090000"], ["1971.42000000", "0.15850000"], ["1971.35000000", "13.52110000"], ["1971.33000000", "2.87540000"], ["1971.20000000", "12.17460000"], ["1971.11000000", "0.81690000"], ["1971.10000000", "0.05570000"], ["1971.09000000", "22.69850000"], ["1971.00000000", "8.18440000"], ["1970.97000000", "0.03880000"], ["1970.93000000", "0.81730000"], ["1970.89000000", "0.14810000"], ["1970.80000000", "0.55670000"], ["1970.72000000", "0.69280000"], ["1970.57000000", "22.67790000"], ["1970.22000000", "0.98260000"], ["1970.20000000", "5.49760000"], ["1970.12000000", "15.66210000"], ["1970.11000000", "0.06070000"], ["1970.08000000", "8.22390000"], ["1970.02000000", "15.74850000"], ["1969.89000000", "10.69010000"], ["1969.88000000", "8.58120000"], ["1969.85000000", "10.99050000"], ["1969.82000000", "15.61930000"], ["1969.74000000", "7.12560000"], ["1969.60000000", "25.46260000"], ["1969.44000000", "0.20470000"], ["1969.36000000", "4.46650000"], ["1969.25000000", "3.60000000"], ["1969.08000000", "7.54660000"], ["1969.03000000", "13.52810000"], ["1968.76000000", "4.15110000"], ["1968.75000000", "0.06270000"], ["1968.26000000", "17.33570000"], ["1968.25000000", "35.39410000"], ["1968.24000000", "0.00000000"], ["1964.45000000", "3.60550000"], ["1962.92000000", "0.00000000"], ["1959.75000000", "90.00770000"], ["1922.56000000", "0.12980000"], ["1775.00000000", "24.92090000"], ["1774.96000000", "0.00000000"], ["1577.78000000", "0.03280000"], ["1577.48000000", "0.11900000"], ["1472.20000000", "0.01200000"]], "a": [["1971.96000000", "68.95650000"], ["1971.97000000", "2.68970000"], ["1971.98000000", "4.98220000"], ["1971.99000000", "0.00000000"], ["1972.00000000", "0.00570000"], ["1972.01000000", "4.00000000"], ["1972.02000000", "0.00000000"], ["1972.03000000", "0.00000000"], ["1972.04000000", "0.00000000"], ["1972.05000000", "0.00000000"], ["1972.06000000", "0.00000000"], ["1972.07000000", "0.00000000"], ["1972.08000000", "0.00000000"], ["1972.10000000", "0.00570000"], ["1972.11000000", "0.00000000"], ["1972.12000000", "3.00000000"], ["1972.14000000", "0.01160000"], ["1972.17000000", "17.27040000"], ["1972.18000000", "6.18480000"], ["1972.19000000", "0.00260000"], ["1972.20000000", "14.84130000"], ["1972.21000000", "9.74480000"], ["1972.22000000", "22.74820000"], ["1972.23000000", "2.23170000"], ["1972.26000000", "0.00260000"], ["1972.27000000", "0.00260000"], ["1972.28000000", "0.00260000"], ["1972.29000000", "0.00260000"], ["1972.30000000", "4.09740000"], ["1972.31000000", "1.36830000"], ["1972.32000000", "0.03000000"], ["1972.33000000", "0.00000000"], ["1972.34000000", "0.00390000"], ["1972.35000000", "0.64850000"], ["1972.36000000", "8.21030000"], ["1972.37000000", "29.82530000"], ["1972.38000000", "0.00260000"], ["1972.39000000", "0.00000000"], ["1972.41000000", "5.95090000"], ["1972.42000000", "2.54090000"], ["1972.43000000", "1.50000000"], ["1972.44000000", "0.06160000"], ["1972.46000000", "0.00000000"], ["1972.49000000", "13.52370000"], ["1972.50000000", "0.25720000"], ["1972.51000000", "16.07180000"], ["1972.52000000", "15.61970000"], ["1972.53000000", "7.76080000"], ["1972.54000000", "22.57760000"], ["1972.57000000", "7.09850000"], ["1972.58000000", "1.08980000"], ["1972.59000000", "0.00260000"], ["1972.60000000", "11.94240000"], ["1972.61000000", "0.00000000"], ["1972.62000000", "0.01020000"], ["1972.65000000", "9.96760000"], ["1972.69000000", "38.77460000"], ["1972.70000000", "8.84550000"], ["1972.71000000", "0.00000000"], ["1972.72000000", "1.20550000"], ["1972.73000000", "7.09850000"], ["1972.74000000", "0.00690000"], ["1972.77000000", "0.00000000"], ["1972.86000000", "10.05600000"], ["1972.87000000", "8.55120000"], ["1972.88000000", "15.33020000"], ["1972.90000000", "8.43160000"], ["1972.91000000", "7.10040000"], ["1972.93000000", "0.00000000"], ["1972.98000000", "13.53140000"], ["1973.00000000", "18.73140000"], ["1973.10000000", "0.00310000"], ["1973.12000000", "9.40120000"], ["1973.20000000", "0.00310000"], ["1973.23000000", "14.14000000"], ["1973.24000000", "12.59570000"], ["1973.30000000", "0.78870000"], ["1973.39000000", "20.62390000"], ["1973.41000000", "0.00000000"], ["1973.51000000", "3.42200000"], ["1973.60000000", "18.57110000"], ["1973.63000000", "0.00260000"], ["1973.76000000", "0.00000000"], ["1973.83000000", "0.00260000"], ["1973.98000000", "0.00260000"], ["1973.99000000", "0.00000000"], ["1974.06000000", "0.00300000"], ["1974.07000000", "0.81260000"], ["1974.14000000", "1.96310000"], ["1974.18000000", "0.00000000"], ["1974.19000000", "0.00000000"], ["1974.29000000", "0.00000000"], ["1974.38000000", "31.72850000"], ["1974.40000000", "0.03310000"], ["1974.42000000", "0.00000000"], ["1974.86000000", "0.00000000"], ["1975.19000000", "0.17830000"], ["1977.06000000", "0.00000000"], ["1977.11000000", "1.51780000"], ["1977.38000000", "0.00000000"], ["1977.47000000", "0.14080000"], ["1980.07000000", "0.00260000"], ["1981.17000000", "1.34620000"], ["1987.54000000", "3.07470000"]], "_local_ts_utc": "2026-06-01T07:49:06.111584+00:00"}
{"e": "depthUpdate", "E": 1780300147315, "s": "ETHUSDT", "U": 76583108404, "u": 76583108568, "b": [["1971.95000000", "39.74300000"], ["1971.94000000", "10.17080000"], ["1971.92000000", "0.05000000"], ["1971.90000000", "0.01060000"], ["1971.89000000", "1.43960000"], ["1971.88000000", "0.50720000"], ["1971.80000000", "0.00800000"], ["1971.79000000", "10.04730000"], ["1971.76000000", "0.00000000"], ["1971.72000000", "6.46760000"], ["1971.69000000", "1.60340000"], ["1971.66000000", "0.04330000"], ["1971.62000000", "0.05000000"], ["1971.60000000", "0.00520000"], ["1971.58000000", "5.03110000"], ["1971.57000000", "0.08300000"], ["1971.56000000", "0.00410000"], ["1971.52000000", "0.03000000"], ["1971.51000000", "0.34830000"], ["1971.48000000", "13.20140000"], ["1971.43000000", "0.25380000"], ["1971.40000000", "0.27570000"], ["1971.39000000", "0.54000000"], ["1971.32000000", "0.29020000"], ["1971.31000000", "0.08670000"], ["1971.27000000", "17.59390000"], ["1971.23000000", "0.60840000"], ["1971.17000000", "0.37810000"], ["1971.10000000", "0.00570000"], ["1970.93000000", "0.01730000"], ["1970.87000000", "8.84970000"], ["1970.86000000", "23.37760000"], ["1970.40000000", "15.58540000"], ["1969.30000000", "18.45550000"], ["1968.76000000", "0.04920000"], ["1966.42000000", "0.00720000"], ["1966.33000000", "0.01280000"], ["1966.24000000", "0.00560000"], ["1966.15000000", "0.04690000"], ["1959.75000000", "0.00770000"], ["1950.09000000", "24.35690000"], ["1950.08000000", "0.26610000"], ["1946.22000000", "0.25640000"], ["1946.13000000", "0.25880000"], ["1946.05000000", "0.12820000"], ["1934.19000000", "0.12790000"], ["1912.70000000", "0.14580000"], ["1912.68000000", "0.14930000"], ["1774.76000000", "0.01240000"]], "a": [["1971.96000000", "32.57980000"], ["1971.97000000", "2.70320000"], ["1971.98000000", "0.00770000"], ["1971.99000000", "0.00260000"], ["1972.00000000", "0.01370000"], ["1972.01000000", "4.00260000"], ["1972.10000000", "0.00830000"], ["1972.12000000", "3.00260000"], ["1972.14000000", "0.00260000"], ["1972.16000000", "6.49760000"], ["1972.17000000", "12.21550000"], ["1972.19000000", "22.57670000"], ["1972.21000000", "9.74220000"], ["1972.23000000", "2.22910000"], ["1972.25000000", "0.40000000"], ["1972.27000000", "0.00260000"], ["1972.28000000", "0.00000000"], ["1972.29000000", "0.00000000"], ["1972.30000000", "3.39840000"], ["1972.31000000", "1.31570000"], ["1972.36000000", "8.21290000"], ["1972.37000000", "29.81370000"], ["1972.51000000", "16.57880000"], ["1972.53000000", "7.81080000"], ["1972.59000000", "0.62360000"], ["1972.60000000", "12.40140000"], ["1972.61000000", "0.59400000"], ["1972.67000000", "0.51560000"], ["1972.83000000", "0.05000000"], ["1973.16000000", "1.86210000"], ["1973.24000000", "12.81050000"], ["1973.32000000", "9.75910000"], ["1973.45000000", "1.16600000"], ["1973.56000000", "0.00000000"], ["1973.67000000", "0.59400000"], ["1974.56000000", "0.12660000"], ["1975.17000000", "1.34000000"], ["1977.23000000", "0.00710000"], ["1977.29000000", "0.00000000"], ["2414.01000000", "0.00900000"]], "_local_ts_utc": "2026-06-01T07:49:06.213404+00:00"}
{"e": "depthUpdate", "E": 1780300147415, "s": "ETHUSDT", "U": 76583108569, "u": 76583108739, "b": [["1971.95000000", "41.32860000"], ["1971.94000000", "13.11380000"], ["1971.93000000", "1.16840000"], ["1971.92000000", "0.05260000"], ["1971.89000000", "1.43420000"], ["1971.88000000", "0.50980000"], ["1971.84000000", "0.03540000"], ["1971.83000000", "6.48040000"], ["1971.80000000", "0.00260000"], ["1971.79000000", "9.28450000"], ["1971.78000000", "1.29440000"], ["1971.72000000", "0.00000000"], ["1971.70000000", "12.38100000"], ["1971.69000000", "15.03890000"], ["1971.68000000", "7.14200000"], ["1971.67000000", "29.69900000"], ["1971.66000000", "7.39560000"], ["1971.60000000", "8.52340000"], ["1971.58000000", "15.69760000"], ["1971.57000000", "7.18150000"], ["1971.56000000", "7.10260000"], ["1971.43000000", "0.00000000"], ["1971.40000000", "0.54570000"], ["1971.33000000", "3.27540000"], ["1971.11000000", "1.21690000"], ["1970.86000000", "22.57760000"], ["1970.51000000", "2.92060000"], ["1969.89000000", "6.85060000"], ["1969.88000000", "1.48270000"], ["1969.82000000", "0.00260000"], ["1969.74000000", "0.02710000"], ["1959.75000000", "90.00770000"], ["1955.92000000", "0.00270000"], ["1952.82000000", "0.12770000"], ["1934.19000000", "0.00000000"], ["1932.25000000", "0.13270000"], ["1924.32000000", "0.00270000"], ["1774.76000000", "0.02480000"]], "a": [["1971.96000000", "3.85260000"], ["1971.97000000", "0.00770000"], ["1971.98000000", "0.00770000"], ["1971.99000000", "0.00520000"], ["1972.00000000", "0.00830000"], ["1972.01000000", "0.00260000"], ["1972.03000000", "0.00260000"], ["1972.11000000", "0.00540000"], ["1972.14000000", "0.00260000"], ["1972.15000000", "0.00000000"], ["1972.16000000", "0.03800000"], ["1972.17000000", "0.92200000"], ["1972.18000000", "0.00520000"], ["1972.19000000", "0.00300000"], ["1972.20000000", "3.08070000"], ["1972.21000000", "11.02300000"], ["1972.22000000", "0.03300000"], ["1972.23000000", "0.89420000"], ["1972.25000000", "0.00000000"], ["1972.28000000", "6.46760000"], ["1972.31000000", "0.00000000"], ["1972.36000000", "16.73110000"], ["1972.37000000", "21.29550000"], ["1972.38000000", "0.00000000"], ["1972.41000000", "1.92320000"], ["1972.42000000", "1.33540000"], ["1972.43000000", "0.00000000"], ["1972.49000000", "0.00260000"], ["1972.50000000", "13.77830000"], ["1972.53000000", "8.51080000"], ["1972.58000000", "0.00000000"], ["1972.59000000", "1.08260000"], ["1972.60000000", "11.41760000"], ["1972.61000000", "0.59400000"], ["1972.66000000", "0.80000000"], ["1972.98000000", "3.60000000"], ["1973.30000000", "3.57350000"], ["1973.44000000", "15.50060000"], ["1973.45000000", "8.51820000"], ["1973.52000000", "7.59240000"], ["1973.64000000", "0.00000000"], ["1973.99000000", "14.19700000"], ["1974.05000000", "1.86300000"], ["1974.07000000", "7.91110000"], ["1974.38000000", "0.03300000"], ["1974.86000000", "0.00000000"], ["1980.08000000", "126.41720000"]], "_local_ts_utc": "2026-06-01T07:49:06.311395+00:00"}
{"e": "depthUpdate", "E": 1780300147515, "s": "ETHUSDT", "U": 76583108740, "u": 76583108909, "b": [["1971.95000000", "40.71930000"], ["1971.94000000", "10.17080000"], ["1971.93000000", "0.00260000"], ["1971.87000000", "0.00260000"], ["1971.84000000", "0.03000000"], ["1971.83000000", "0.01280000"], ["1971.81000000", "0.00540000"], ["1971.80000000", "0.00530000"], ["1971.79000000", "15.99430000"], ["1971.78000000", "0.00000000"], ["1971.77000000", "19.09470000"], ["1971.71000000", "0.00000000"], ["1971.70000000", "3.86590000"], ["1971.68000000", "31.13540000"], ["1971.67000000", "0.02680000"], ["1971.66000000", "0.04330000"], ["1971.61000000", "7.19850000"], ["1971.60000000", "0.00830000"], ["1971.59000000", "14.19700000"], ["1971.58000000", "8.59910000"], ["1971.57000000", "0.08300000"], ["1971.56000000", "8.52750000"], ["1971.51000000", "7.44680000"], ["1971.50000000", "14.53670000"], ["1971.49000000", "0.00000000"], ["1971.48000000", "20.29990000"], ["1971.47000000", "29.67670000"], ["1971.46000000", "0.01150000"], ["1971.35000000", "0.00000000"], ["1971.33000000", "2.87540000"], ["1971.26000000", "23.57380000"], ["1971.11000000", "0.81690000"], ["1971.04000000", "7.95490000"], ["1970.77000000", "0.15220000"], ["1970.63000000", "0.10260000"], ["1970.57000000", "22.57790000"], ["1970.51000000", "0.01520000"], ["1970.09000000", "7.10110000"], ["1970.08000000", "1.12540000"], ["1970.02000000", "15.74850000"], ["1969.99000000", "0.00300000"], ["1969.89000000", "4.73170000"], ["1969.82000000", "0.00260000"], ["1969.74000000", "0.02710000"], ["1969.08000000", "4.02520000"], ["1969.04000000", "13.52370000"], ["1969.03000000", "0.00700000"], ["1955.84000000", "0.63250000"], ["1950.08000000", "0.13920000"], ["1946.13000000", "0.00460000"], ["1922.35000000", "0.13280000"], ["1774.76000000", "0.03720000"], ["1577.56000000", "0.01400000"], ["1577.48000000", "0.11200000"], ["1577.47000000", "0.02800000"]], "a": [["1971.96000000", "25.46370000"], ["1972.01000000", "0.00260000"], ["1972.03000000", "0.00520000"], ["1972.10000000", "0.00830000"], ["1972.11000000", "0.00260000"], ["1972.14000000", "0.00000000"], ["1972.16000000", "0.03000000"], ["1972.17000000", "0.00000000"], ["1972.20000000", "1.55320000"], ["1972.21000000", "0.00000000"], ["1972.22000000", "0.04460000"], ["1972.24000000", "1.31870000"], ["1972.27000000", "22.57630000"], ["1972.28000000", "0.00000000"], ["1972.29000000", "0.63060000"], ["1972.40000000", "6.47330000"], ["1972.41000000", "5.59190000"], ["1972.90000000", "0.82590000"], ["1974.37000000", "0.00260000"], ["1975.15000000", "1.78460000"], ["1976.17000000", "0.00000000"], ["1976.69000000", "0.01930000"], ["1976.76000000", "0.03290000"], ["1977.28000000", "0.02060000"]], "_local_ts_utc": "2026-06-01T07:49:06.411715+00:00"}
{"e": "depthUpdate", "E": 1780300147615, "s": "ETHUSDT", "U": 76583108910, "u": 76583109058, "b": [["1971.95000000", "40.70890000"], ["1971.94000000", "10.15760000"], ["1971.91000000", "6.46760000"], ["1971.89000000", "1.43960000"], ["1971.84000000", "0.03540000"], ["1971.83000000", "0.64880000"], ["1971.81000000", "0.00000000"], ["1971.80000000", "0.00260000"], ["1971.79000000", "9.90930000"], ["1971.78000000", "0.00000000"], ["1971.71000000", "0.00000000"], ["1971.70000000", "3.86590000"], ["1971.69000000", "24.49950000"], ["1971.68000000", "22.61720000"], ["1971.64000000", "0.94020000"], ["1971.60000000", "14.98960000"], ["1971.58000000", "0.50260000"], ["1971.56000000", "8.53270000"], ["1971.52000000", "13.55110000"], ["1971.50000000", "1.01560000"], ["1971.38000000", "13.55540000"], ["1971.35000000", "0.27000000"], ["1971.33000000", "3.54540000"], ["1971.22000000", "20.62150000"], ["1971.21000000", "0.00000000"], ["1971.17000000", "0.42840000"], ["1971.11000000", "0.41690000"], ["1970.97000000", "0.08910000"], ["1969.08000000", "7.54660000"], ["1969.04000000", "0.00260000"], ["1969.03000000", "13.52810000"], ["1968.76000000", "0.04920000"], ["1966.69000000", "7.19780000"], ["1965.70000000", "0.00780000"], ["1950.08000000", "0.01230000"], ["1774.76000000", "0.05580000"]], "a": [["1971.96000000", "3.75910000"], ["1972.10000000", "0.01370000"], ["1972.11000000", "5.24840000"], ["1972.12000000", "3.00260000"], ["1972.14000000", "0.00540000"], ["1972.15000000", "0.53040000"], ["1972.19000000", "0.00300000"], ["1972.20000000", "8.42420000"], ["1972.21000000", "0.00260000"], ["1972.23000000", "0.89420000"], ["1972.26000000", "0.00260000"], ["1972.27000000", "0.00260000"], ["1972.30000000", "3.40140000"], ["1972.64000000", "0.54300000"], ["1972.65000000", "10.42660000"], ["1972.90000000", "6.15510000"], ["1973.98000000", "21.29810000"], ["1973.99000000", "0.00000000"], ["1974.07000000", "0.81260000"], ["1974.82000000", "0.54600000"], ["1974.85000000", "0.46160000"], ["1975.05000000", "0.43500000"], ["1975.11000000", "0.00000000"], ["1975.93000000", "0.00000000"], ["2432.13000000", "0.00910000"]], "_local_ts_utc": "2026-06-01T07:49:06.511288+00:00"}
{"e": "depthUpdate", "E": 1780300147715, "s": "ETHUSDT", "U": 76583109059, "u": 76583109654, "b": [["1972.08000000", "74.73590000"], ["1972.07000000", "0.00510000"], ["1972.06000000", "0.00510000"], ["1972.05000000", "0.00540000"], ["1972.04000000", "0.00540000"], ["1972.03000000", "6.47300000"], ["1972.02000000", "13.75780000"], ["1972.01000000", "0.00540000"], ["1972.00000000", "3.39020000"], ["1971.99000000", "0.00530000"], ["1971.98000000", "3.37460000"], ["1971.97000000", "0.00260000"], ["1971.96000000", "0.00000000"], ["1971.95000000", "5.55780000"], ["1971.94000000", "0.00260000"], ["1971.93000000", "0.00260000"], ["1971.92000000", "0.05000000"], ["1971.91000000", "0.00000000"], ["1971.90000000", "0.00260000"], ["1971.89000000", "1.43160000"], ["1971.88000000", "23.08090000"], ["1971.87000000", "0.00000000"], ["1971.86000000", "1.31230000"], ["1971.85000000", "0.02190000"], ["1971.84000000", "0.03000000"], ["1971.80000000", "8.52390000"], ["1971.79000000", "32.19560000"], ["1971.71000000", "7.09850000"], ["1971.70000000", "25.90520000"], ["1971.56000000", "12.74110000"], ["1971.54000000", "0.38510000"], ["1971.53000000", "17.86810000"], ["1971.52000000", "0.03000000"], ["1971.47000000", "29.67670000"], ["1971.40000000", "1.54570000"], ["1971.38000000", "13.65690000"], ["1971.33000000", "3.54540000"], ["1971.29000000", "0.20460000"], ["1971.27000000", "17.49240000"], ["1971.26000000", "23.37380000"], ["1971.23000000", "0.00000000"], ["1971.17000000", "0.05030000"], ["1971.11000000", "0.41690000"], ["1971.09000000", "22.49850000"], ["1971.04000000", "7.15490000"], ["1971.00000000", "8.18180000"], ["1970.85000000", "3.84740000"], ["1970.63000000", "0.00260000"], ["1970.21000000", "31.76950000"], ["1970.02000000", "8.65000000"], ["1969.85000000", "3.89200000"], ["1969.60000000", "25.43260000"], ["1969.08000000", "4.96470000"], ["1969.04000000", "0.00260000"], ["1969.03000000", "0.00700000"], ["1968.26000000", "7.84520000"], ["1968.25000000", "3.60000000"], ["1962.77000000", "0.49150000"], ["1952.83000000", "2.80790000"], ["1946.22000000", "0.38460000"], ["1874.51000000", "0.00580000"], ["1873.37000000", "0.00290000"], ["1774.88000000", "0.01240000"], ["1774.76000000", "0.00000000"]], "a": [["1971.96000000", "0.00000000"], ["1971.97000000", "0.00000000"], ["1971.98000000", "0.00000000"], ["1971.99000000", "0.00000000"], ["1972.00000000", "0.00000000"], ["1972.01000000", "0.00000000"], ["1972.03000000", "0.00000000"], ["1972.09000000", "8.60710000"], ["1972.10000000", "0.00830000"], ["1972.11000000", "0.00260000"], ["1972.12000000", "0.00260000"], ["1972.13000000", "0.00000000"], ["1972.14000000", "0.00260000"], ["1972.15000000", "0.10260000"], ["1972.16000000", "0.00260000"], ["1972.18000000", "0.00260000"], ["1972.19000000", "0.00560000"], ["1972.20000000", "0.00830000"], ["1972.22000000", "0.03840000"], ["1972.24000000", "0.00000000"], ["1972.26000000", "0.00000000"], ["1972.27000000", "0.00000000"], ["1972.28000000", "0.00000000"], ["1972.29000000", "0.00000000"], ["1972.35000000", "0.63690000"], ["1972.36000000", "0.00260000"], ["1972.37000000", "0.00000000"], ["1972.38000000", "6.93520000"], ["1972.39000000", "14.19700000"], ["1972.40000000", "0.00570000"], ["1972.41000000", "1.92320000"], ["1972.43000000", "0.01160000"], ["1972.49000000", "0.01420000"], ["1972.50000000", "0.25720000"], ["1972.51000000", "23.04640000"], ["1972.53000000", "7.81080000"], ["1972.57000000", "7.10110000"], ["1972.62000000", "0.01020000"], ["1972.66000000", "0.00000000"], ["1972.69000000", "22.71520000"], ["1972.72000000", "1.50550000"], ["1972.77000000", "1.20000000"], ["1972.84000000", "9.80890000"], ["1972.85000000", "14.46610000"], ["1972.86000000", "0.00800000"], ["1972.88000000", "1.80910000"], ["1972.89000000", "9.73840000"], ["1972.98000000", "0.00000000"], ["1973.00000000", "18.73400000"], ["1973.44000000", "11.36330000"], ["1973.58000000", "0.80000000"], ["1973.64000000", "8.51820000"], ["1973.76000000", "3.79980000"], ["1973.80000000", "7.10350000"], ["1974.19000000", "7.09850000"], ["1974.72000000", "0.03300000"], ["1974.86000000", "13.52110000"], ["1975.05000000", "0.00300000"], ["1975.19000000", "13.69940000"], ["1976.18000000", "1.20810000"], ["1977.26000000", "0.00260000"], ["1980.65000000", "0.03290000"], ["1980.90000000", "0.00000000"], ["2010.75000000", "0.00000000"]], "_local_ts_utc": "2026-06-01T07:49:06.613591+00:00"}
{"e": "depthUpdate", "E": 1780300147815, "s": "ETHUSDT", "U": 76583109655, "u": 76583109747, "b": [["1972.08000000", "66.39850000"], ["1972.07000000", "0.00770000"], ["1972.06000000", "0.01030000"], ["1972.05000000", "0.00260000"], ["1972.04000000", "0.00800000"], ["1972.03000000", "6.47560000"], ["1972.02000000", "6.03400000"], ["1972.00000000", "3.39290000"], ["1971.99000000", "2.68930000"], ["1971.98000000", "3.37200000"], ["1971.97000000", "0.00000000"], ["1971.96000000", "0.00000000"], ["1971.95000000", "5.55520000"], ["1971.94000000", "0.00000000"], ["1971.93000000", "0.00000000"], ["1971.89000000", "11.46650000"], ["1971.81000000", "0.00000000"], ["1971.80000000", "0.00570000"], ["1971.79000000", "17.99860000"], ["1971.77000000", "18.45430000"], ["1971.70000000", "12.38410000"], ["1971.56000000", "12.74370000"], ["1971.40000000", "0.74570000"], ["1971.31000000", "0.88670000"], ["1970.95000000", "2.76620000"], ["1970.87000000", "8.90000000"], ["1970.85000000", "3.74740000"], ["1970.77000000", "1.50030000"], ["1970.72000000", "0.79280000"], ["1970.09000000", "0.00260000"], ["1969.89000000", "2.61280000"], ["1955.84000000", "0.50600000"], ["1774.88000000", "0.02480000"]], "a": [["1972.09000000", "25.63320000"], ["1972.15000000", "0.00260000"], ["1972.22000000", "0.03300000"], ["1972.29000000", "1.40640000"], ["1972.30000000", "4.71170000"], ["1972.34000000", "0.01550000"], ["1972.38000000", "11.33800000"], ["1972.64000000", "14.06410000"], ["1972.83000000", "7.14850000"], ["1973.76000000", "4.82990000"], ["1973.98000000", "14.19960000"], ["1974.19000000", "0.00000000"], ["1974.82000000", "0.03300000"], ["1975.19000000", "0.17830000"], ["2450.80000000", "0.11200000"]], "_local_ts_utc": "2026-06-01T07:49:06.710748+00:00"}
{"e": "depthUpdate", "E": 1780300147915, "s": "ETHUSDT", "U": 76583109748, "u": 76583109786, "b": [["1972.08000000", "48.96480000"], ["1972.07000000", "0.01030000"], ["1972.04000000", "0.00800000"], ["1972.02000000", "5.62150000"], ["1972.00000000", "3.08780000"], ["1971.92000000", "0.67170000"], ["1971.89000000", "8.92380000"], ["1971.71000000", "20.61960000"], ["1971.04000000", "8.16910000"], ["1970.80000000", "0.00570000"], ["1970.78000000", "0.99880000"], ["1970.74000000", "0.74530000"], ["1969.88000000", "1.48570000"], ["1967.56000000", "0.00290000"], ["1922.39000000", "0.15430000"], ["1774.88000000", "0.03720000"]], "a": [["1972.09000000", "31.88480000"], ["1972.15000000", "0.00520000"], ["1972.22000000", "0.03300000"], ["1972.26000000", "0.01160000"], ["1972.49000000", "0.00260000"], ["1974.56000000", "0.15660000"], ["1974.72000000", "0.00300000"], ["1977.95000000", "1.24270000"]], "_local_ts_utc": "2026-06-01T07:49:06.811341+00:00"}
{"e": "depthUpdate", "E": 1780300148015, "s": "ETHUSDT", "U": 76583109787, "u": 76583109837, "b": [["1972.08000000", "48.97520000"], ["1972.07000000", "0.01550000"], ["1972.00000000", "3.05240000"], ["1971.99000000", "0.00800000"], ["1971.96000000", "0.00270000"], ["1971.82000000", "0.00000000"], ["1971.73000000", "0.09380000"], ["1971.72000000", "0.01010000"], ["1971.69000000", "24.49950000"], ["1971.59000000", "14.46700000"], ["1971.51000000", "9.98510000"], ["1971.33000000", "4.34540000"], ["1971.31000000", "0.08670000"], ["1971.08000000", "0.80270000"], ["1971.00000000", "8.17170000"], ["1970.80000000", "0.00570000"], ["1970.77000000", "1.40900000"], ["1969.50000000", "0.52640000"], ["1969.44000000", "0.23470000"], ["1952.96000000", "0.12770000"], ["1774.88000000", "0.04960000"], ["1472.20000000", "0.00000000"]], "a": [["1972.09000000", "31.86940000"], ["1972.22000000", "0.03840000"], ["1972.33000000", "0.00000000"], ["1972.41000000", "1.92620000"], ["1972.62000000", "0.52320000"], ["1973.13000000", "14.36710000"], ["1973.22000000", "0.00260000"], ["1974.45000000", "1.46220000"], ["1975.82000000", "0.00000000"]], "_local_ts_utc": "2026-06-01T07:49:06.911429+00:00"}
{"e": "depthUpdate", "E": 1780300148115, "s": "ETHUSDT", "U": 76583109838, "u": 76583109889, "b": [["1972.08000000", "48.96740000"], ["1972.07000000", "0.01290000"], ["1972.04000000", "4.53330000"], ["1972.00000000", "6.78200000"], ["1971.99000000", "0.00800000"], ["1971.96000000", "0.00000000"], ["1971.85000000", "0.52950000"], ["1971.74000000", "0.00300000"], ["1971.71000000", "7.09850000"], ["1971.70000000", "25.90610000"], ["1971.54000000", "0.65510000"], ["1971.33000000", "3.54540000"], ["1971.26000000", "24.17380000"], ["1969.50000000", "0.25640000"], ["1969.30000000", "17.89680000"], ["1966.79000000", "37.29730000"], ["1952.70000000", "0.02200000"], ["1946.71000000", "1.51570000"], ["1922.79000000", "0.13570000"], ["1774.88000000", "0.06200000"]], "a": [["1972.09000000", "14.09910000"], ["1972.21000000", "0.00000000"], ["1972.22000000", "0.05000000"], ["1972.43000000", "0.00000000"], ["1972.51000000", "23.04900000"], ["1972.67000000", "1.08260000"], ["1973.21000000", "1.46540000"], ["1974.45000000", "0.94920000"], ["1974.46000000", "0.56700000"], ["1974.85000000", "0.00260000"], ["1975.23000000", "0.00260000"], ["1977.50000000", "36.20860000"], ["1980.00000000", "8.31040000"], ["2470.03000000", "0.00380000"]], "_local_ts_utc": "2026-06-01T07:49:07.011678+00:00"}
{"e": "depthUpdate", "E": 1780300148215, "s": "ETHUSDT", "U": 76583109890, "u": 76583109973, "b": [["1972.08000000", "49.01090000"], ["1972.07000000", "0.00770000"], ["1972.05000000", "0.00800000"], ["1972.04000000", "4.53170000"], ["1972.00000000", "6.77660000"], ["1971.96000000", "0.00000000"], ["1971.89000000", "14.82270000"], ["1971.85000000", "0.02190000"], ["1971.84000000", "0.28380000"], ["1971.80000000", "22.72260000"], ["1971.74000000", "0.00000000"], ["1971.71000000", "7.09850000"], ["1971.70000000", "25.90610000"], ["1971.64000000", "0.68640000"], ["1971.52000000", "0.03300000"], ["1970.40000000", "15.59910000"], ["1969.77000000", "0.00800000"], ["1969.22000000", "33.08260000"], ["1963.21000000", "0.05090000"], ["1962.22000000", "0.23140000"], ["1946.71000000", "0.00000000"], ["1946.31000000", "0.12820000"], ["1774.88000000", "0.07440000"], ["1192.00000000", "0.00000000"]], "a": [["1972.09000000", "7.16010000"], ["1972.20000000", "0.00830000"], ["1972.22000000", "0.03840000"], ["1972.24000000", "0.00000000"], ["1972.26000000", "0.00000000"], ["1972.28000000", "0.00540000"], ["1972.29000000", "1.41180000"], ["1972.30000000", "4.70010000"], ["1972.34000000", "0.00390000"], ["1972.36000000", "8.90390000"], ["1972.37000000", "8.51890000"], ["1972.38000000", "7.09850000"], ["1972.47000000", "4.36060000"], ["1973.21000000", "0.00000000"], ["1973.64000000", "0.00000000"], ["1974.46000000", "0.00000000"], ["1975.14000000", "1.53180000"]], "_local_ts_utc": "2026-06-01T07:49:07.111592+00:00"}
{"e": "depthUpdate", "E": 1780300148315, "s": "ETHUSDT", "U": 76583109974, "u": 76583110617, "b": [["1972.31000000", "56.74200000"], ["1972.30000000", "0.00770000"], ["1972.29000000", "0.00510000"], ["1972.28000000", "3.41790000"], ["1972.27000000", "9.75140000"], ["1972.23000000", "0.00540000"], ["1972.22000000", "2.27650000"], ["1972.21000000", "0.00260000"], ["1972.20000000", "13.10960000"], ["1972.19000000", "8.15480000"], ["1972.18000000", "0.00000000"], ["1972.17000000", "0.00000000"], ["1972.16000000", "0.00000000"], ["1972.15000000", "6.47300000"], ["1972.14000000", "0.00260000"], ["1972.13000000", "0.00260000"], ["1972.11000000", "0.00260000"], ["1972.10000000", "0.00520000"], ["1972.09000000", "20.51400000"], ["1972.08000000", "4.99180000"], ["1972.07000000", "0.00000000"], ["1972.06000000", "0.00260000"], ["1972.05000000", "0.00000000"], ["1972.04000000", "0.25380000"], ["1972.03000000", "0.00000000"], ["1972.02000000", "0.00000000"], ["1972.01000000", "0.00000000"], ["1972.00000000", "7.08680000"], ["1971.99000000", "0.00000000"], ["1971.92000000", "7.77070000"], ["1971.90000000", "22.71950000"], ["1971.89000000", "14.82530000"], ["1971.88000000", "22.57370000"], ["1971.84000000", "0.03000000"], ["1971.81000000", "7.09900000"], ["1971.69000000", "24.50210000"], ["1971.55000000", "0.91110000"], ["1971.45000000", "0.00280000"], ["1971.33000000", "3.14540000"], ["1971.30000000", "3.81700000"], ["1971.20000000", "12.17200000"], ["1971.10000000", "0.00310000"], ["1970.94000000", "1.37580000"], ["1970.80000000", "0.05600000"], ["1970.72000000", "0.69280000"], ["1970.26000000", "1.02620000"], ["1970.20000000", "3.37870000"], ["1970.18000000", "17.64000000"], ["1970.12000000", "8.56360000"], ["1970.05000000", "4.38030000"], ["1970.02000000", "0.13180000"], ["1969.60000000", "25.43260000"], ["1969.44000000", "0.20470000"], ["1969.42000000", "0.00000000"], ["1967.53000000", "0.00000000"], ["1962.43000000", "0.00000000"], ["1952.96000000", "0.25540000"], ["1946.45000000", "0.12820000"], ["1942.50000000", "0.16340000"], ["1774.88000000", "0.00000000"], ["1472.08000000", "0.00600000"]], "a": [["1972.09000000", "0.00000000"], ["1972.10000000", "0.00000000"], ["1972.11000000", "0.00000000"], ["1972.12000000", "0.00000000"], ["1972.14000000", "0.00000000"], ["1972.15000000", "0.00000000"], ["1972.16000000", "0.00000000"], ["1972.18000000", "0.00000000"], ["1972.19000000", "0.00000000"], ["1972.20000000", "0.00000000"], ["1972.22000000", "0.00000000"], ["1972.23000000", "0.00000000"], ["1972.28000000", "0.00000000"], ["1972.29000000", "0.00000000"], ["1972.30000000", "0.00000000"], ["1972.32000000", "16.81090000"], ["1972.34000000", "0.01190000"], ["1972.35000000", "0.01560000"], ["1972.36000000", "8.90930000"], ["1972.37000000", "0.00800000"], ["1972.38000000", "0.00530000"], ["1972.39000000", "0.00260000"], ["1972.40000000", "0.00830000"], ["1972.41000000", "1.92880000"], ["1972.42000000", "1.33800000"], ["1972.47000000", "4.34900000"], ["1972.51000000", "16.07440000"], ["1972.52000000", "0.00300000"], ["1972.53000000", "0.71230000"], ["1972.57000000", "0.00260000"], ["1972.62000000", "6.99080000"], ["1972.64000000", "0.54300000"], ["1972.69000000", "14.20860000"], ["1972.72000000", "9.72440000"], ["1972.78000000", "0.30000000"], ["1972.85000000", "0.94800000"], ["1972.88000000", "1.43100000"], ["1972.89000000", "7.20040000"], ["1972.99000000", "13.52200000"], ["1973.05000000", "2.53790000"], ["1973.10000000", "0.00570000"], ["1973.19000000", "0.00000000"], ["1973.20000000", "0.00570000"], ["1973.22000000", "13.90270000"], ["1973.30000000", "3.57610000"], ["1973.39000000", "7.10040000"], ["1973.43000000", "13.59910000"], ["1973.51000000", "3.22200000"], ["1973.53000000", "0.00260000"], ["1973.58000000", "0.60000000"], ["1973.64000000", "8.51890000"], ["1973.66000000", "0.80260000"], ["1973.83000000", "8.52150000"], ["1974.07000000", "7.91160000"], ["1974.19000000", "14.19800000"], ["1974.29000000", "7.09900000"], ["1974.41000000", "7.13030000"], ["1974.43000000", "10.70160000"], ["1975.14000000", "0.00380000"], ["1975.19000000", "13.70030000"], ["1975.48000000", "1.20550000"], ["1975.71000000", "0.00000000"], ["1975.81000000", "0.00000000"], ["1976.18000000", "1.20550000"], ["1978.82000000", "0.50440000"], ["1979.08000000", "0.00000000"], ["1980.68000000", "0.47120000"], ["2000.00000000", "261.59940000"], ["2472.15000000", "0.00840000"], ["2489.83000000", "0.00380000"]], "_local_ts_utc": "2026-06-01T07:49:07.211585+00:00"}
{"e": "depthUpdate", "E": 1780300148415, "s": "ETHUSDT", "U": 76583110618, "u": 76583110915, "b": [["1972.31000000", "62.19190000"], ["1972.30000000", "0.01570000"], ["1972.29000000", "4.23320000"], ["1972.28000000", "3.42310000"], ["1972.27000000", "6.51740000"], ["1972.23000000", "0.00800000"], ["1972.22000000", "2.27110000"], ["1972.21000000", "0.00800000"], ["1972.20000000", "10.77990000"], ["1972.19000000", "8.15220000"], ["1972.16000000", "0.00000000"], ["1972.15000000", "0.00000000"], ["1972.14000000", "0.00000000"], ["1972.13000000", "0.00000000"], ["1972.11000000", "8.51890000"], ["1972.10000000", "21.62980000"], ["1972.09000000", "0.00260000"], ["1972.08000000", "4.98920000"], ["1972.06000000", "0.00390000"], ["1972.02000000", "1.30600000"], ["1972.01000000", "15.61790000"], ["1972.00000000", "18.03450000"], ["1971.91000000", "13.52200000"], ["1971.90000000", "22.72260000"], ["1971.86000000", "0.00690000"], ["1971.70000000", "42.34650000"], ["1971.69000000", "14.56590000"], ["1971.63000000", "6.73550000"], ["1971.52000000", "0.03000000"], ["1971.49000000", "1.50000000"], ["1971.48000000", "16.25190000"], ["1971.38000000", "13.82540000"], ["1971.29000000", "0.00460000"], ["1971.09000000", "21.99850000"], ["1971.08000000", "0.00270000"], ["1970.40000000", "7.88810000"], ["1970.39000000", "0.00000000"], ["1970.30000000", "0.00260000"], ["1970.25000000", "4.11090000"], ["1970.20000000", "5.30380000"], ["1970.12000000", "0.04540000"], ["1969.46000000", "1.16100000"], ["1969.40000000", "0.53550000"], ["1969.39000000", "0.25980000"], ["1969.36000000", "0.00000000"], ["1969.31000000", "1.02210000"], ["1966.46000000", "0.00000000"], ["1966.42000000", "0.00460000"], ["1966.33000000", "0.01020000"], ["1966.24000000", "0.00300000"], ["1952.82000000", "0.25540000"], ["1946.31000000", "0.25640000"], ["1932.51000000", "0.12910000"], ["1775.08000000", "0.01240000"], ["1577.85000000", "0.00700000"], ["1577.47000000", "0.02100000"]], "a": [["1972.32000000", "8.23300000"], ["1972.34000000", "0.00650000"], ["1972.35000000", "0.01020000"], ["1972.36000000", "0.00260000"], ["1972.37000000", "0.00260000"], ["1972.38000000", "0.00260000"], ["1972.39000000", "0.00260000"], ["1972.40000000", "0.00830000"], ["1972.41000000", "0.01100000"], ["1972.46000000", "0.00540000"], ["1972.51000000", "0.63720000"], ["1972.53000000", "1.23900000"], ["1972.54000000", "0.00390000"], ["1972.59000000", "0.00260000"], ["1972.60000000", "0.00570000"], ["1972.61000000", "0.01160000"], ["1972.62000000", "0.01020000"], ["1972.64000000", "0.03000000"], ["1972.65000000", "0.03300000"], ["1972.67000000", "0.00260000"], ["1972.68000000", "14.19800000"], ["1972.69000000", "0.01160000"], ["1972.71000000", "0.00000000"], ["1972.72000000", "0.00000000"], ["1972.73000000", "6.46760000"], ["1972.74000000", "7.10590000"], ["1972.77000000", "0.00000000"], ["1972.78000000", "0.00000000"], ["1972.81000000", "7.79490000"], ["1972.82000000", "8.51890000"], ["1972.84000000", "0.00000000"], ["1972.87000000", "0.03300000"], ["1972.90000000", "8.43620000"], ["1972.92000000", "1.50000000"], ["1972.98000000", "13.52200000"], ["1972.99000000", "0.00000000"], ["1973.01000000", "9.93170000"], ["1973.12000000", "5.39190000"], ["1973.24000000", "12.59570000"], ["1973.32000000", "6.73790000"], ["1973.42000000", "14.94320000"], ["1973.44000000", "3.63000000"], ["1973.76000000", "6.83840000"], ["1973.83000000", "19.56330000"], ["1973.97000000", "12.50550000"], ["1974.06000000", "8.52190000"], ["1974.14000000", "8.06900000"], ["1974.29000000", "7.09900000"], ["1974.32000000", "0.67920000"], ["1974.41000000", "7.13030000"], ["1974.42000000", "10.30560000"], ["1974.48000000", "0.00000000"], ["1974.63000000", "0.00000000"], ["1974.67000000", "0.00260000"], ["1974.85000000", "0.00260000"], ["1974.88000000", "0.03000000"], ["1975.03000000", "1.53640000"], ["1977.31000000", "0.00260000"], ["1977.40000000", "0.22360000"]], "_local_ts_utc": "2026-06-01T07:49:07.311153+00:00"}
{"e": "depthUpdate", "E": 1780300148515, "s": "ETHUSDT", "U": 76583110916, "u": 76583110947, "b": [["1972.23000000", "0.01060000"], ["1972.11000000", "15.61790000"], ["1972.02000000", "1.81310000"], ["1971.60000000", "14.99260000"], ["1971.55000000", "1.18110000"], ["1970.50000000", "8.56500000"], ["1969.46000000", "56.16720000"], ["1969.22000000", "32.37160000"], ["1946.45000000", "0.25640000"], ["1942.50000000", "0.29180000"], ["1775.08000000", "0.02480000"]], "a": [["1972.32000000", "8.18780000"], ["1972.65000000", "0.54000000"], ["1972.66000000", "8.05360000"], ["1972.67000000", "8.52150000"], ["1972.77000000", "1.20550000"], ["1972.97000000", "0.60420000"], ["1973.16000000", "1.77530000"], ["1973.57000000", "0.08970000"], ["1973.66000000", "0.00260000"], ["1973.67000000", "0.80910000"], ["1973.79000000", "0.42640000"], ["1973.87000000", "15.95350000"], ["1974.05000000", "1.86300000"], ["1974.06000000", "0.00300000"], ["1979.65000000", "0.25090000"], ["1980.13000000", "2.47470000"], ["2001.39000000", "0.05260000"]], "_local_ts_utc": "2026-06-01T07:49:07.412351+00:00"}
{"e": "depthUpdate", "E": 1780300148615, "s": "ETHUSDT", "U": 76583110948, "u": 76583111538, "b": [["1972.49000000", "108.32980000"], ["1972.48000000", "0.00510000"], ["1972.47000000", "0.00510000"], ["1972.46000000", "0.00000000"], ["1972.45000000", "0.00000000"], ["1972.43000000", "0.00000000"], ["1972.42000000", "0.00540000"], ["1972.41000000", "0.00000000"], ["1972.40000000", "0.00260000"], ["1972.39000000", "6.46760000"], ["1972.38000000", "47.95630000"], ["1972.37000000", "1.05320000"], ["1972.36000000", "0.00000000"], ["1972.35000000", "0.00540000"], ["1972.34000000", "0.00000000"], ["1972.33000000", "0.00000000"], ["1972.32000000", "0.00000000"], ["1972.31000000", "1.00250000"], ["1972.30000000", "0.00520000"], ["1972.29000000", "4.22270000"], ["1972.28000000", "3.41770000"], ["1972.27000000", "1.28150000"], ["1972.26000000", "0.00390000"], ["1972.23000000", "0.25890000"], ["1972.22000000", "7.10160000"], ["1972.21000000", "22.71950000"], ["1972.20000000", "18.69050000"], ["1972.16000000", "0.04020000"], ["1972.15000000", "0.00260000"], ["1972.12000000", "36.09570000"], ["1972.08000000", "4.94630000"], ["1972.06000000", "0.65250000"], ["1972.04000000", "0.00000000"], ["1972.02000000", "0.50710000"], ["1971.96000000", "2.53780000"], ["1971.95000000", "4.26790000"], ["1971.92000000", "7.14900000"], ["1971.88000000", "23.18210000"], ["1971.86000000", "4.42240000"], ["1971.83000000", "0.01280000"], ["1971.77000000", "22.05430000"], ["1971.72000000", "0.01310000"], ["1971.70000000", "39.48630000"], ["1971.63000000", "0.14290000"], ["1971.62000000", "0.25000000"], ["1971.60000000", "14.98960000"], ["1971.56000000", "12.38620000"], ["1971.55000000", "1.18110000"], ["1971.53000000", "13.52410000"], ["1971.52000000", "1.23550000"], ["1971.51000000", "7.44680000"], ["1971.50000000", "1.01300000"], ["1971.40000000", "1.34310000"], ["1971.26000000", "23.37380000"], ["1971.14000000", "16.23950000"], ["1970.94000000", "1.27580000"], ["1970.91000000", "30.54330000"], ["1970.69000000", "14.20290000"], ["1970.60000000", "10.03970000"], ["1970.59000000", "0.00000000"], ["1970.50000000", "0.04450000"], ["1970.33000000", "13.55170000"], ["1969.76000000", "0.17180000"], ["1969.55000000", "0.67930000"], ["1969.51000000", "0.00000000"], ["1969.47000000", "12.27710000"], ["1969.46000000", "55.01790000"], ["1969.13000000", "0.61320000"], ["1967.51000000", "1.48550000"], ["1967.27000000", "0.63130000"], ["1966.69000000", "6.61620000"], ["1964.45000000", "0.00550000"], ["1962.77000000", "0.00770000"], ["1961.56000000", "0.00000000"], ["1775.14000000", "0.00000000"], ["1775.08000000", "0.00000000"]], "a": [["1972.32000000", "0.00000000"], ["1972.34000000", "0.00000000"], ["1972.35000000", "0.00000000"], ["1972.36000000", "0.00000000"], ["1972.37000000", "0.00000000"], ["1972.38000000", "0.00000000"], ["1972.39000000", "0.00000000"], ["1972.40000000", "0.00000000"], ["1972.41000000", "0.00000000"], ["1972.42000000", "0.00000000"], ["1972.43000000", "0.00000000"], ["1972.44000000", "0.00000000"], ["1972.46000000", "0.00000000"], ["1972.47000000", "0.00000000"], ["1972.48000000", "0.00000000"], ["1972.49000000", "0.00000000"], ["1972.50000000", "8.36900000"], ["1972.51000000", "0.00780000"], ["1972.52000000", "0.01100000"], ["1972.53000000", "0.05260000"], ["1972.54000000", "0.00650000"], ["1972.55000000", "0.00800000"], ["1972.56000000", "0.00260000"], ["1972.57000000", "0.00260000"], ["1972.59000000", "0.00260000"], ["1972.60000000", "0.00830000"], ["1972.61000000", "0.00000000"], ["1972.64000000", "0.03540000"], ["1972.65000000", "0.54540000"], ["1972.66000000", "0.00000000"], ["1972.67000000", "0.00260000"], ["1972.68000000", "0.00000000"], ["1972.69000000", "0.00270000"], ["1972.70000000", "0.00570000"], ["1972.73000000", "0.00000000"], ["1972.74000000", "0.00690000"], ["1972.75000000", "0.00760000"], ["1972.77000000", "0.00000000"], ["1972.80000000", "0.03830000"], ["1972.81000000", "26.75500000"], ["1972.82000000", "0.01160000"], ["1972.83000000", "4.41300000"], ["1972.86000000", "0.01060000"], ["1972.88000000", "2.09330000"], ["1972.90000000", "6.15510000"], ["1972.92000000", "0.00000000"], ["1972.95000000", "7.10300000"], ["1972.96000000", "0.03560000"], ["1972.97000000", "0.60420000"], ["1972.98000000", "0.00000000"], ["1973.01000000", "10.23170000"], ["1973.05000000", "0.00000000"], ["1973.09000000", "1.29200000"], ["1973.24000000", "11.53330000"], ["1973.26000000", "22.57370000"], ["1973.30000000", "0.79130000"], ["1973.40000000", "0.24000000"], ["1973.56000000", "0.03990000"], ["1973.58000000", "0.00000000"], ["1973.65000000", "20.97500000"], ["1973.73000000", "0.00300000"], ["1973.75000000", "0.01020000"], ["1973.87000000", "16.35350000"], ["1974.06000000", "8.52190000"], ["1974.16000000", "0.00000000"], ["1974.20000000", "23.30260000"], ["1974.30000000", "8.51890000"], ["1974.48000000", "7.09900000"], ["1974.49000000", "23.27060000"], ["1974.63000000", "7.09900000"], ["1974.67000000", "7.10160000"], ["1974.69000000", "7.09900000"], ["1974.87000000", "0.00000000"], ["1975.04000000", "0.03000000"], ["1975.48000000", "19.11050000"], ["1977.60000000", "126.57880000"], ["2510.23000000", "0.01380000"]], "_local_ts_utc": "2026-06-01T07:49:07.511759+00:00"}
{"e": "depthUpdate", "E": 1780300148715, "s": "ETHUSDT", "U": 76583111539, "u": 76583113152, "b": [["1972.82000000", "101.18070000"], ["1972.81000000", "0.05490000"], ["1972.80000000", "3.01570000"], ["1972.79000000", "42.72660000"], ["1972.75000000", "0.00540000"], ["1972.74000000", "13.26090000"], ["1972.73000000", "0.00000000"], ["1972.72000000", "0.00000000"], ["1972.70000000", "31.23140000"], ["1972.69000000", "8.51890000"], ["1972.68000000", "3.75030000"], ["1972.67000000", "0.00000000"], ["1972.66000000", "3.30090000"], ["1972.65000000", "7.09900000"], ["1972.64000000", "19.18870000"], ["1972.63000000", "12.67730000"], ["1972.62000000", "1.00190000"], ["1972.61000000", "4.23460000"], ["1972.60000000", "0.00520000"], ["1972.59000000", "0.00000000"], ["1972.58000000", "8.07010000"], ["1972.57000000", "0.00000000"], ["1972.56000000", "9.01890000"], ["1972.55000000", "3.05500000"], ["1972.54000000", "0.00000000"], ["1972.53000000", "21.29700000"], ["1972.52000000", "22.57370000"], ["1972.51000000", "0.00000000"], ["1972.50000000", "1.26640000"], ["1972.49000000", "0.00590000"], ["1972.48000000", "0.04020000"], ["1972.47000000", "0.00000000"], ["1972.46000000", "0.00650000"], ["1972.43000000", "20.75520000"], ["1972.42000000", "22.71690000"], ["1972.41000000", "13.52200000"], ["1972.40000000", "15.37080000"], ["1972.39000000", "0.00260000"], ["1972.38000000", "0.00000000"], ["1972.37000000", "1.05320000"], ["1972.35000000", "0.00000000"], ["1972.34000000", "4.36700000"], ["1972.33000000", "1.31660000"], ["1972.32000000", "52.41960000"], ["1972.31000000", "1.51890000"], ["1972.30000000", "0.00830000"], ["1972.29000000", "13.71440000"], ["1972.28000000", "0.00260000"], ["1972.27000000", "1.27890000"], ["1972.26000000", "13.52590000"], ["1972.23000000", "0.00260000"], ["1972.22000000", "10.73200000"], ["1972.21000000", "22.71690000"], ["1972.20000000", "18.69360000"], ["1972.19000000", "1.61100000"], ["1972.11000000", "22.21050000"], ["1972.10000000", "21.63290000"], ["1972.08000000", "2.00300000"], ["1972.06000000", "0.00390000"], ["1972.02000000", "3.60000000"], ["1972.01000000", "15.81790000"], ["1971.98000000", "6.59260000"], ["1971.96000000", "29.30980000"], ["1971.95000000", "1.00000000"], ["1971.94000000", "0.37810000"], ["1971.92000000", "7.34900000"], ["1971.89000000", "14.69370000"], ["1971.88000000", "22.57370000"], ["1971.86000000", "0.00690000"], ["1971.85000000", "0.27280000"], ["1971.80000000", "22.72000000"], ["1971.79000000", "12.73760000"], ["1971.77000000", "4.61280000"], ["1971.76000000", "0.40000000"], ["1971.75000000", "0.00300000"], ["1971.70000000", "38.48370000"], ["1971.64000000", "1.48640000"], ["1971.63000000", "0.04150000"], ["1971.62000000", "0.05000000"], ["1971.60000000", "14.98700000"], ["1971.56000000", "12.37580000"], ["1971.55000000", "0.78110000"], ["1971.54000000", "0.37700000"], ["1971.52000000", "1.23810000"], ["1971.49000000", "0.00000000"], ["1971.47000000", "29.67410000"], ["1971.46000000", "0.00390000"], ["1971.40000000", "0.54310000"], ["1971.37000000", "11.22370000"], ["1971.36000000", "0.06560000"], ["1971.34000000", "29.82560000"], ["1971.33000000", "3.21380000"], ["1971.31000000", "0.01830000"], ["1971.27000000", "17.44210000"], ["1971.26000000", "23.31590000"], ["1971.24000000", "7.10040000"], ["1971.22000000", "13.52110000"], ["1971.20000000", "5.40500000"], ["1971.19000000", "0.01280000"], ["1971.17000000", "0.00000000"], ["1971.14000000", "1.93970000"], ["1971.12000000", "0.20450000"], ["1971.11000000", "1.48690000"], ["1971.09000000", "13.47860000"], ["1971.04000000", "1.06920000"], ["1971.03000000", "0.00000000"], ["1970.97000000", "0.03880000"], ["1970.95000000", "7.27050000"], ["1970.93000000", "0.01730000"], ["1970.92000000", "0.31660000"], ["1970.91000000", "13.79350000"], ["1970.88000000", "0.11760000"], ["1970.78000000", "13.39990000"], ["1970.77000000", "1.35870000"], ["1970.76000000", "10.46940000"], ["1970.74000000", "32.02380000"], ["1970.71000000", "0.52240000"], ["1970.70000000", "5.79210000"], ["1970.69000000", "0.00310000"], ["1970.56000000", "0.79350000"], ["1970.40000000", "7.80180000"], ["1970.29000000", "17.27140000"], ["1970.24000000", "23.52480000"], ["1970.08000000", "1.09540000"], ["1970.07000000", "0.00000000"], ["1970.00000000", "414.63310000"], ["1969.92000000", "0.00820000"], ["1969.79000000", "0.00940000"], ["1969.55000000", "0.00000000"], ["1969.54000000", "0.00260000"], ["1968.99000000", "6.76630000"], ["1968.93000000", "22.57370000"], ["1968.34000000", "1.10810000"], ["1968.22000000", "0.79690000"], ["1967.89000000", "9.18460000"], ["1967.51000000", "0.58130000"], ["1967.39000000", "0.00260000"], ["1966.97000000", "0.00670000"], ["1966.90000000", "0.28350000"], ["1966.81000000", "0.00000000"], ["1966.72000000", "0.04100000"], ["1966.63000000", "0.07430000"], ["1966.55000000", "0.08210000"], ["1965.05000000", "0.00000000"], ["1964.85000000", "0.00290000"], ["1964.06000000", "0.49100000"], ["1963.75000000", "7.14640000"], ["1963.61000000", "0.00430000"], ["1962.82000000", "0.00000000"], ["1956.02000000", "0.00000000"], ["1943.36000000", "39.72230000"], ["1942.72000000", "0.01650000"], ["1775.47000000", "0.00000000"], ["1775.35000000", "0.00000000"]], "a": [["1972.50000000", "0.00000000"], ["1972.51000000", "0.00000000"], ["1972.52000000", "0.00000000"], ["1972.53000000", "0.00000000"], ["1972.54000000", "0.00000000"], ["1972.55000000", "0.00000000"], ["1972.56000000", "0.00000000"], ["1972.57000000", "0.00000000"], ["1972.59000000", "0.00000000"], ["1972.60000000", "0.00000000"], ["1972.62000000", "0.00000000"], ["1972.63000000", "0.00000000"], ["1972.64000000", "0.00000000"], ["1972.65000000", "0.00000000"], ["1972.67000000", "0.00000000"], ["1972.69000000", "0.00000000"], ["1972.70000000", "0.00000000"], ["1972.73000000", "0.00000000"], ["1972.74000000", "0.00000000"], ["1972.75000000", "0.00000000"], ["1972.76000000", "0.00000000"], ["1972.80000000", "0.00000000"], ["1972.81000000", "0.00000000"], ["1972.82000000", "0.00000000"], ["1972.83000000", "0.05520000"], ["1972.84000000", "0.00000000"], ["1972.85000000", "0.00560000"], ["1972.86000000", "0.00780000"], ["1972.87000000", "0.03560000"], ["1972.88000000", "0.00260000"], ["1972.89000000", "0.10260000"], ["1972.90000000", "0.00830000"], ["1972.91000000", "0.00260000"], ["1972.94000000", "0.00650000"], ["1972.95000000", "0.00520000"], ["1972.96000000", "0.03300000"], ["1972.97000000", "0.01020000"], ["1972.99000000", "0.00000000"], ["1973.00000000", "0.00570000"], ["1973.01000000", "0.00000000"], ["1973.02000000", "0.00000000"], ["1973.03000000", "0.00000000"], ["1973.05000000", "0.00000000"], ["1973.06000000", "0.00000000"], ["1973.07000000", "26.77160000"], ["1973.08000000", "0.41000000"], ["1973.09000000", "0.03300000"], ["1973.10000000", "0.00570000"], ["1973.11000000", "0.00000000"], ["1973.12000000", "0.03000000"], ["1973.13000000", "0.67320000"], ["1973.15000000", "0.00000000"], ["1973.16000000", "1.67400000"], ["1973.20000000", "17.34170000"], ["1973.21000000", "0.00000000"], ["1973.22000000", "0.00260000"], ["1973.23000000", "1.08520000"], ["1973.24000000", "0.00000000"], ["1973.25000000", "7.09900000"], ["1973.29000000", "0.06370000"], ["1973.30000000", "0.80290000"], ["1973.36000000", "1.23470000"], ["1973.40000000", "0.00870000"], ["1973.41000000", "0.00000000"], ["1973.42000000", "20.16480000"], ["1973.43000000", "0.07710000"], ["1973.44000000", "13.55200000"], ["1973.49000000", "0.00000000"], ["1973.50000000", "0.51870000"], ["1973.54000000", "0.00390000"], ["1973.56000000", "0.00000000"], ["1973.60000000", "18.57370000"], ["1973.62000000", "0.01320000"], ["1973.63000000", "13.52460000"], ["1973.65000000", "7.10040000"], ["1973.67000000", "0.80910000"], ["1973.70000000", "0.13260000"], ["1973.71000000", "0.00260000"], ["1973.73000000", "2.54000000"], ["1973.76000000", "4.24060000"], ["1973.78000000", "0.00000000"], ["1973.79000000", "0.00000000"], ["1973.80000000", "7.10610000"], ["1973.82000000", "2.48250000"], ["1973.83000000", "8.52150000"], ["1973.84000000", "0.00560000"], ["1973.87000000", "0.38070000"], ["1973.89000000", "0.00000000"], ["1973.93000000", "0.00260000"], ["1973.94000000", "0.01660000"], ["1973.96000000", "14.36780000"], ["1974.00000000", "22.72060000"], ["1974.05000000", "6.77740000"], ["1974.14000000", "8.07660000"], ["1974.24000000", "0.35900000"], ["1974.27000000", "0.00000000"], ["1974.32000000", "0.68680000"], ["1974.42000000", "16.71870000"], ["1974.44000000", "9.65950000"], ["1974.45000000", "0.94920000"], ["1974.47000000", "8.53890000"], ["1974.50000000", "0.20420000"], ["1974.52000000", "8.17200000"], ["1974.57000000", "15.28290000"], ["1974.58000000", "0.59290000"], ["1974.66000000", "9.00870000"], ["1974.68000000", "8.51890000"], ["1974.77000000", "3.66170000"], ["1974.85000000", "16.58420000"], ["1974.89000000", "14.19800000"], ["1975.00000000", "0.00570000"], ["1975.07000000", "7.09900000"], ["1975.09000000", "0.00260000"], ["1975.11000000", "7.09900000"], ["1975.13000000", "7.10160000"], ["1975.15000000", "0.02020000"], ["1975.20000000", "0.03310000"], ["1975.25000000", "0.03300000"], ["1975.36000000", "0.03000000"], ["1975.37000000", "0.00000000"], ["1975.47000000", "22.58390000"], ["1975.72000000", "0.07600000"], ["1975.76000000", "0.50990000"], ["1975.79000000", "1.90850000"], ["1975.81000000", "13.52200000"], ["1975.83000000", "22.57370000"], ["1975.87000000", "9.39810000"], ["1976.80000000", "0.00310000"], ["1976.84000000", "0.00260000"], ["1977.05000000", "1.64000000"], ["1977.19000000", "0.03550000"], ["1977.49000000", "0.00260000"], ["1977.58000000", "0.00520000"], ["1977.64000000", "0.00260000"], ["1977.86000000", "40.66380000"], ["1979.92000000", "0.15380000"], ["1980.68000000", "0.00000000"], ["1980.88000000", "0.14690000"], ["1981.10000000", "126.35160000"], ["1981.17000000", "0.00000000"], ["1982.63000000", "0.00850000"], ["1987.54000000", "0.00000000"], ["1987.67000000", "0.00000000"], ["2025.45000000", "0.04560000"]], "_local_ts_utc": "2026-06-01T07:49:07.611766+00:00"}
{"e": "depthUpdate", "E": 1780300148815, "s": "ETHUSDT", "U": 76583113153, "u": 76583113344, "b": [["1972.82000000", "78.18190000"], ["1972.81000000", "0.06030000"], ["1972.80000000", "10.87790000"], ["1972.79000000", "10.15320000"], ["1972.75000000", "0.00800000"], ["1972.74000000", "7.46950000"], ["1972.71000000", "0.00540000"], ["1972.70000000", "8.70300000"], ["1972.69000000", "0.00530000"], ["1972.66000000", "5.23900000"], ["1972.65000000", "0.00000000"], ["1972.64000000", "3.18810000"], ["1972.62000000", "0.99930000"], ["1972.61000000", "2.43460000"], ["1972.60000000", "0.00520000"], ["1972.58000000", "16.04570000"], ["1972.55000000", "1.25500000"], ["1972.44000000", "20.02940000"], ["1972.43000000", "7.63200000"], ["1972.33000000", "0.00000000"], ["1972.27000000", "0.00000000"], ["1972.14000000", "0.10140000"], ["1972.13000000", "0.15110000"], ["1972.00000000", "29.92510000"], ["1971.98000000", "0.00000000"], ["1971.69000000", "14.56330000"], ["1971.56000000", "12.37320000"], ["1971.45000000", "0.00000000"], ["1971.20000000", "2.86180000"], ["1970.87000000", "8.84970000"], ["1970.80000000", "0.00570000"], ["1969.30000000", "36.45280000"], ["1969.28000000", "70.99210000"], ["1969.15000000", "32.19890000"], ["1969.14000000", "106.78890000"], ["1969.13000000", "0.01660000"], ["1967.91000000", "0.10520000"], ["1967.90000000", "0.16110000"], ["1967.76000000", "0.05310000"], ["1966.93000000", "0.00260000"], ["1966.84000000", "0.00000000"], ["1960.11000000", "0.03920000"], ["1775.54000000", "0.01550000"]], "a": [["1972.83000000", "24.63340000"], ["1972.84000000", "0.00000000"], ["1972.86000000", "0.00520000"], ["1972.87000000", "0.04100000"], ["1972.88000000", "1.28180000"], ["1972.89000000", "0.10800000"], ["1972.90000000", "0.63880000"], ["1972.93000000", "0.01160000"], ["1972.94000000", "0.00260000"], ["1973.06000000", "8.12870000"], ["1973.07000000", "26.78320000"], ["1973.15000000", "0.00000000"], ["1973.16000000", "0.00000000"], ["1973.18000000", "4.24110000"], ["1973.19000000", "14.19800000"], ["1973.20000000", "11.92760000"], ["1973.23000000", "0.01680000"], ["1973.25000000", "22.08550000"], ["1973.28000000", "4.39500000"], ["1973.30000000", "0.01990000"], ["1973.31000000", "0.03300000"], ["1973.44000000", "13.55200000"], ["1973.57000000", "0.00260000"], ["1973.67000000", "0.59400000"], ["1973.89000000", "0.60000000"], ["1973.95000000", "16.65730000"], ["1973.97000000", "1.51200000"], ["1973.99000000", "2.88260000"], ["1974.04000000", "0.80000000"], ["1974.06000000", "8.60660000"], ["1974.17000000", "0.84930000"], ["1974.66000000", "12.53870000"], ["1974.68000000", "0.00000000"], ["1974.85000000", "20.91060000"], ["1974.97000000", "1.07630000"], ["1975.03000000", "0.97800000"], ["1975.06000000", "2.50930000"], ["1975.11000000", "0.00000000"], ["1975.13000000", "0.00260000"], ["1975.25000000", "0.03300000"], ["1975.39000000", "31.67920000"], ["1975.48000000", "14.72750000"], ["1976.14000000", "0.00260000"], ["1976.91000000", "31.99060000"], ["1977.60000000", "0.00310000"], ["1977.76000000", "0.00260000"], ["1977.85000000", "0.00260000"], ["1977.91000000", "0.00260000"], ["1978.00000000", "0.01240000"], ["1980.08000000", "0.00000000"], ["1982.60000000", "0.00000000"], ["1982.62000000", "113.37150000"], ["2531.24000000", "0.00720000"]], "_local_ts_utc": "2026-06-01T07:49:07.711743+00:00"}
{"e": "depthUpdate", "E": 1780300148916, "s": "ETHUSDT", "U": 76583113345, "u": 76583113688, "b": [["1972.94000000", "33.70110000"], ["1972.93000000", "3.00000000"], ["1972.92000000", "15.62800000"], ["1972.91000000", "8.13700000"], ["1972.90000000", "91.92870000"], ["1972.89000000", "0.00000000"], ["1972.88000000", "0.00000000"], ["1972.87000000", "0.00000000"], ["1972.86000000", "8.54950000"], ["1972.85000000", "7.23270000"], ["1972.84000000", "40.94340000"], ["1972.83000000", "38.35600000"], ["1972.82000000", "6.74420000"], ["1972.81000000", "0.04980000"], ["1972.80000000", "5.26950000"], ["1972.79000000", "0.00260000"], ["1972.75000000", "0.00260000"], ["1972.74000000", "7.46690000"], ["1972.71000000", "0.00000000"], ["1972.70000000", "0.95660000"], ["1972.69000000", "0.00000000"], ["1972.68000000", "3.74770000"], ["1972.67000000", "13.71320000"], ["1972.66000000", "13.75790000"], ["1972.64000000", "24.48510000"], ["1972.59000000", "13.52200000"], ["1972.58000000", "0.00000000"], ["1972.54000000", "13.47430000"], ["1972.52000000", "22.57670000"], ["1972.44000000", "0.00000000"], ["1972.43000000", "18.45450000"], ["1972.40000000", "0.00570000"], ["1972.37000000", "1.01000000"], ["1972.33000000", "15.96330000"], ["1972.31000000", "1.05040000"], ["1972.28000000", "0.00000000"], ["1972.23000000", "0.05290000"], ["1972.15000000", "0.25350000"], ["1971.97000000", "0.40000000"], ["1971.90000000", "22.72000000"], ["1971.84000000", "0.08030000"], ["1971.76000000", "0.00000000"], ["1971.34000000", "21.30510000"], ["1970.92000000", "0.06570000"], ["1970.76000000", "11.50420000"], ["1970.33000000", "0.03460000"], ["1969.64000000", "0.59640000"], ["1968.39000000", "8.17020000"], ["1967.89000000", "0.50050000"], ["1967.68000000", "0.61700000"], ["1967.51000000", "0.00000000"], ["1965.81000000", "0.00000000"], ["1965.25000000", "0.12290000"], ["1957.14000000", "3.75800000"], ["1943.36000000", "0.00000000"], ["1874.51000000", "0.00290000"], ["1874.25000000", "0.00290000"], ["1775.54000000", "0.00000000"]], "a": [["1972.83000000", "0.00000000"], ["1972.84000000", "0.00000000"], ["1972.85000000", "0.00000000"], ["1972.86000000", "0.00000000"], ["1972.87000000", "0.00000000"], ["1972.88000000", "0.00000000"], ["1972.89000000", "0.00000000"], ["1972.90000000", "0.00000000"], ["1972.91000000", "0.00000000"], ["1972.93000000", "0.00000000"], ["1972.94000000", "0.00000000"], ["1972.95000000", "0.00800000"], ["1972.96000000", "0.10560000"], ["1972.97000000", "0.01280000"], ["1973.05000000", "0.00540000"], ["1973.06000000", "0.00000000"], ["1973.07000000", "0.00560000"], ["1973.08000000", "0.00000000"], ["1973.12000000", "0.03270000"], ["1973.17000000", "1.27130000"], ["1973.18000000", "0.00300000"], ["1973.19000000", "0.00000000"], ["1973.23000000", "0.00520000"], ["1973.25000000", "6.46760000"], ["1973.26000000", "0.00000000"], ["1973.28000000", "0.03000000"], ["1973.36000000", "0.13470000"], ["1973.42000000", "19.76480000"], ["1973.44000000", "0.03000000"], ["1973.48000000", "1.51570000"], ["1973.89000000", "0.00000000"], ["1973.90000000", "1.20550000"], ["1973.91000000", "3.60000000"], ["1973.93000000", "0.00260000"], ["1973.96000000", "14.96780000"], ["1974.04000000", "0.00000000"], ["1974.07000000", "7.91160000"], ["1974.11000000", "4.40260000"], ["1974.64000000", "0.00000000"], ["1974.65000000", "8.51890000"], ["1975.08000000", "0.00000000"], ["1975.11000000", "7.09900000"], ["1975.13000000", "7.10160000"], ["1975.25000000", "7.13200000"], ["1975.39000000", "0.00000000"], ["1975.52000000", "0.03000000"], ["1975.57000000", "0.55830000"], ["1975.74000000", "15.00640000"], ["1976.19000000", "22.57370000"], ["1978.09000000", "3.71020000"], ["1978.18000000", "0.00260000"], ["1978.28000000", "0.00260000"], ["1978.37000000", "0.00380000"], ["1981.08000000", "127.05970000"], ["1987.86000000", "0.00000000"]], "_local_ts_utc": "2026-06-01T07:49:07.812764+00:00"}
{"e": "depthUpdate", "E": 1780300149015, "s": "ETHUSDT", "U": 76583113689, "u": 76583114490, "b": [["1973.08000000", "91.76540000"], ["1973.07000000", "14.61280000"], ["1973.06000000", "0.00510000"], ["1973.05000000", "0.00540000"], ["1973.04000000", "1.38820000"], ["1973.03000000", "0.00000000"], ["1973.02000000", "0.00000000"], ["1973.01000000", "0.00540000"], ["1973.00000000", "11.62660000"], ["1972.99000000", "6.63750000"], ["1972.98000000", "0.00000000"], ["1972.96000000", "0.00270000"], ["1972.95000000", "8.51890000"], ["1972.94000000", "4.68960000"], ["1972.93000000", "0.00260000"], ["1972.92000000", "0.00260000"], ["1972.91000000", "7.10160000"], ["1972.90000000", "6.57040000"], ["1972.89000000", "0.00000000"], ["1972.88000000", "0.00000000"], ["1972.87000000", "0.03300000"], ["1972.86000000", "2.77740000"], ["1972.85000000", "0.00000000"], ["1972.84000000", "8.51890000"], ["1972.83000000", "0.01020000"], ["1972.82000000", "6.74420000"], ["1972.81000000", "0.75370000"], ["1972.80000000", "13.85040000"], ["1972.79000000", "14.19800000"], ["1972.75000000", "0.00000000"], ["1972.74000000", "0.99930000"], ["1972.73000000", "22.57370000"], ["1972.72000000", "0.00260000"], ["1972.70000000", "0.95970000"], ["1972.68000000", "3.75030000"], ["1972.67000000", "18.26770000"], ["1972.66000000", "13.76180000"], ["1972.65000000", "0.03300000"], ["1972.60000000", "0.00830000"], ["1972.55000000", "0.00000000"], ["1972.54000000", "17.07690000"], ["1972.53000000", "21.90540000"], ["1972.50000000", "0.50570000"], ["1972.49000000", "0.00000000"], ["1972.44000000", "11.43830000"], ["1972.43000000", "7.64240000"], ["1972.40000000", "6.69970000"], ["1972.37000000", "0.99980000"], ["1972.28000000", "0.27000000"], ["1972.25000000", "0.60000000"], ["1972.23000000", "0.05030000"], ["1972.22000000", "10.93200000"], ["1972.19000000", "1.00260000"], ["1972.14000000", "0.00000000"], ["1972.04000000", "0.05030000"], ["1972.01000000", "15.61790000"], ["1972.00000000", "29.92520000"], ["1971.97000000", "0.00000000"], ["1971.96000000", "27.57460000"], ["1971.94000000", "0.00000000"], ["1971.92000000", "7.14900000"], ["1971.74000000", "0.10000000"], ["1971.64000000", "0.73670000"], ["1971.56000000", "3.85500000"], ["1971.54000000", "0.27700000"], ["1971.50000000", "1.00990000"], ["1971.48000000", "9.15340000"], ["1971.47000000", "22.57370000"], ["1971.39000000", "9.07810000"], ["1971.37000000", "0.00000000"], ["1971.34000000", "0.00390000"], ["1971.31000000", "7.11730000"], ["1971.30000000", "3.81390000"], ["1971.29000000", "0.27460000"], ["1971.27000000", "11.01440000"], ["1971.24000000", "0.00000000"], ["1971.21000000", "0.21260000"], ["1971.10000000", "0.00000000"], ["1971.05000000", "3.60000000"], ["1970.90000000", "0.00000000"], ["1970.88000000", "0.03260000"], ["1970.84000000", "0.00520000"], ["1970.79000000", "0.08580000"], ["1970.71000000", "0.35630000"], ["1970.45000000", "4.97450000"], ["1970.40000000", "2.47130000"], ["1970.32000000", "0.27710000"], ["1970.30000000", "0.00520000"], ["1970.26000000", "1.02360000"], ["1970.08000000", "1.01830000"], ["1970.01000000", "145.17930000"], ["1969.69000000", "0.01310000"], ["1969.63000000", "0.80480000"], ["1969.60000000", "25.43520000"], ["1969.59000000", "0.01020000"], ["1969.56000000", "0.44220000"], ["1968.87000000", "0.22170000"], ["1968.86000000", "0.48010000"], ["1968.66000000", "128.33400000"], ["1968.19000000", "0.05740000"], ["1968.13000000", "0.54730000"], ["1967.40000000", "0.00770000"], ["1967.27000000", "0.62870000"], ["1967.18000000", "4.18880000"], ["1967.10000000", "0.04200000"], ["1967.01000000", "0.54070000"], ["1966.93000000", "0.00000000"], ["1966.68000000", "0.50720000"], ["1965.95000000", "0.00000000"], ["1965.23000000", "0.00700000"], ["1965.22000000", "0.00000000"], ["1964.49000000", "0.00940000"], ["1963.76000000", "0.00640000"], ["1963.04000000", "0.00840000"], ["1962.31000000", "0.00000000"], ["1961.94000000", "236.64220000"], ["1961.58000000", "0.00360000"], ["1960.25000000", "0.00000000"], ["1944.00000000", "5.54060000"], ["1943.71000000", "35.14250000"], ["1775.78000000", "0.00620000"], ["1775.65000000", "0.00300000"], ["1472.08000000", "0.00000000"]], "a": [["1972.95000000", "0.00000000"], ["1972.96000000", "0.00000000"], ["1972.97000000", "0.00000000"], ["1973.00000000", "0.00000000"], ["1973.05000000", "0.00000000"], ["1973.06000000", "0.00000000"], ["1973.07000000", "0.00000000"], ["1973.08000000", "0.00000000"], ["1973.09000000", "8.80990000"], ["1973.10000000", "0.01090000"], ["1973.12000000", "0.00800000"], ["1973.13000000", "0.16630000"], ["1973.14000000", "0.00650000"], ["1973.16000000", "0.00000000"], ["1973.17000000", "0.00520000"], ["1973.18000000", "0.00560000"], ["1973.19000000", "0.00540000"], ["1973.20000000", "0.00830000"], ["1973.22000000", "0.00520000"], ["1973.23000000", "0.00260000"], ["1973.25000000", "0.00000000"], ["1973.29000000", "0.01600000"], ["1973.30000000", "0.00830000"], ["1973.32000000", "0.01150000"], ["1973.33000000", "0.01160000"], ["1973.35000000", "0.01160000"], ["1973.37000000", "0.20890000"], ["1973.38000000", "0.00000000"], ["1973.39000000", "0.00000000"], ["1973.41000000", "0.00000000"], ["1973.42000000", "9.83310000"], ["1973.43000000", "0.00000000"], ["1973.45000000", "18.66640000"], ["1973.46000000", "23.51870000"], ["1973.48000000", "0.02180000"], ["1973.51000000", "3.22200000"], ["1973.52000000", "8.79790000"], ["1973.57000000", "0.00520000"], ["1973.60000000", "18.87370000"], ["1973.62000000", "14.73520000"], ["1973.63000000", "0.00260000"], ["1973.70000000", "0.00570000"], ["1973.73000000", "14.78720000"], ["1973.74000000", "26.80990000"], ["1973.76000000", "0.00000000"], ["1973.78000000", "9.93170000"], ["1973.82000000", "4.82170000"], ["1973.90000000", "1.20810000"], ["1973.91000000", "0.00000000"], ["1973.96000000", "14.16700000"], ["1974.00000000", "22.72050000"], ["1974.02000000", "0.00000000"], ["1974.05000000", "6.82490000"], ["1974.11000000", "3.60260000"], ["1974.14000000", "8.15330000"], ["1974.19000000", "14.19800000"], ["1974.21000000", "23.17370000"], ["1974.36000000", "0.80000000"], ["1974.39000000", "1.22130000"], ["1974.83000000", "1.02480000"], ["1974.84000000", "8.51890000"], ["1975.10000000", "6.33030000"], ["1975.33000000", "7.09900000"], ["1975.35000000", "0.00260000"], ["1975.42000000", "0.00000000"], ["1975.46000000", "0.03300000"], ["1975.53000000", "0.94500000"], ["1975.68000000", "0.06300000"], ["1975.87000000", "0.02000000"], ["1976.13000000", "0.90900000"], ["1976.14000000", "13.52460000"], ["1976.78000000", "0.00000000"], ["1976.85000000", "9.37810000"], ["1976.87000000", "0.00000000"], ["1977.70000000", "0.00260000"], ["1977.82000000", "0.00870000"], ["1977.90000000", "0.00000000"], ["1978.00000000", "0.01510000"], ["1978.22000000", "0.00260000"], ["1978.33000000", "0.00870000"], ["1978.44000000", "0.00260000"], ["1978.53000000", "0.00000000"], ["1978.93000000", "0.00260000"], ["1979.05000000", "0.00000000"], ["1979.19000000", "0.38470000"], ["1979.24000000", "0.94490000"], ["1979.78000000", "0.03290000"], ["1980.51000000", "0.00000000"], ["1981.24000000", "0.00000000"], ["1981.97000000", "0.00000000"], ["1982.62000000", "0.00000000"], ["1982.69000000", "0.00000000"], ["1982.71000000", "0.00000000"], ["1983.42000000", "0.00380000"], ["1984.15000000", "0.00000000"], ["1984.31000000", "113.40630000"], ["1984.88000000", "0.00000000"], ["1985.61000000", "0.03280000"], ["1986.34000000", "0.01700000"], ["1987.06000000", "0.00000000"], ["1987.79000000", "0.00000000"], ["1988.52000000", "0.00000000"], ["1989.25000000", "0.00000000"], ["1989.98000000", "0.00000000"], ["1990.70000000", "0.00000000"], ["2472.15000000", "0.00240000"]], "_local_ts_utc": "2026-06-01T07:49:07.911766+00:00"}
{"e": "depthUpdate", "E": 1780300149115, "s": "ETHUSDT", "U": 76583114491, "u": 76583114799, "b": [["1973.08000000", "7.59580000"], ["1973.07000000", "0.00770000"], ["1973.06000000", "0.00770000"], ["1973.05000000", "0.00260000"], ["1973.04000000", "0.00260000"], ["1973.02000000", "0.00000000"], ["1973.01000000", "0.00260000"], ["1973.00000000", "0.01060000"], ["1972.99000000", "0.00260000"], ["1972.96000000", "0.00260000"], ["1972.95000000", "0.00800000"], ["1972.94000000", "0.58800000"], ["1972.93000000", "0.00000000"], ["1972.92000000", "0.00000000"], ["1972.91000000", "0.00000000"], ["1972.90000000", "0.00260000"], ["1972.89000000", "0.00000000"], ["1972.87000000", "0.03300000"], ["1972.86000000", "0.00390000"], ["1972.85000000", "0.00000000"], ["1972.84000000", "0.00000000"], ["1972.83000000", "0.01560000"], ["1972.82000000", "6.21340000"], ["1972.81000000", "0.00000000"], ["1972.80000000", "0.03260000"], ["1972.79000000", "0.00000000"], ["1972.77000000", "0.50700000"], ["1972.75000000", "0.00540000"], ["1972.74000000", "0.99930000"], ["1972.73000000", "0.00000000"], ["1972.70000000", "0.95660000"], ["1972.69000000", "18.20410000"], ["1972.68000000", "26.96320000"], ["1972.67000000", "0.00000000"], ["1972.66000000", "3.94870000"], ["1972.65000000", "7.12840000"], ["1972.64000000", "3.18810000"], ["1972.59000000", "0.00000000"], ["1972.58000000", "7.09540000"], ["1972.57000000", "19.23040000"], ["1972.56000000", "9.01450000"], ["1972.55000000", "7.09540000"], ["1972.54000000", "0.00260000"], ["1972.53000000", "0.60840000"], ["1972.49000000", "2.53700000"], ["1972.43000000", "20.66280000"], ["1972.42000000", "23.09500000"], ["1972.41000000", "0.00000000"], ["1972.25000000", "0.00000000"], ["1972.22000000", "11.33200000"], ["1972.21000000", "22.98690000"], ["1972.19000000", "1.27260000"], ["1972.13000000", "0.20140000"], ["1972.11000000", "15.61790000"], ["1972.05000000", "0.20000000"], ["1971.96000000", "26.77460000"], ["1971.93000000", "0.00000000"], ["1971.90000000", "23.52000000"], ["1971.74000000", "0.00000000"], ["1971.69000000", "14.56330000"], ["1971.65000000", "3.14490000"], ["1971.61000000", "7.29850000"], ["1971.54000000", "0.32730000"], ["1971.50000000", "9.52440000"], ["1971.40000000", "14.73390000"], ["1971.25000000", "0.13840000"], ["1971.22000000", "13.79110000"], ["1971.20000000", "19.18310000"], ["1971.11000000", "8.58230000"], ["1970.95000000", "4.50430000"], ["1970.25000000", "17.62610000"], ["1969.22000000", "31.87160000"], ["1968.95000000", "0.51280000"], ["1962.86000000", "0.50180000"], ["1947.39000000", "1.46360000"], ["1946.58000000", "0.12820000"], ["1775.78000000", "0.01860000"], ["1578.47000000", "0.00700000"], ["1577.47000000", "0.01400000"]], "a": [["1973.09000000", "55.93820000"], ["1973.10000000", "0.01990000"], ["1973.12000000", "0.00260000"], ["1973.14000000", "0.00260000"], ["1973.15000000", "0.61860000"], ["1973.18000000", "0.00560000"], ["1973.19000000", "0.00260000"], ["1973.22000000", "0.54260000"], ["1973.23000000", "1.73440000"], ["1973.30000000", "0.01990000"], ["1973.35000000", "6.46760000"], ["1973.39000000", "2.32060000"], ["1973.40000000", "7.61090000"], ["1973.42000000", "15.97780000"], ["1973.45000000", "27.18090000"], ["1973.48000000", "0.01020000"], ["1973.52000000", "9.46020000"], ["1973.60000000", "18.72420000"], ["1973.61000000", "14.98380000"], ["1973.63000000", "0.81260000"], ["1973.76000000", "0.03000000"], ["1973.89000000", "3.60000000"], ["1973.91000000", "1.50170000"], ["1974.60000000", "0.81910000"], ["1974.62000000", "0.81000000"], ["1974.84000000", "0.00000000"], ["1975.25000000", "0.03300000"], ["1975.33000000", "0.00000000"], ["1975.53000000", "0.00000000"], ["1975.57000000", "1.47180000"], ["1975.68000000", "0.03300000"], ["1977.90000000", "126.55650000"], ["1978.15000000", "0.02160000"], ["1978.74000000", "0.03650000"], ["1981.10000000", "0.00000000"], ["1981.11000000", "0.69990000"], ["1988.04000000", "3.18900000"], ["2552.88000000", "0.00380000"]], "_local_ts_utc": "2026-06-01T07:49:08.011433+00:00"}
{"e": "depthUpdate", "E": 1780300149215, "s": "ETHUSDT", "U": 76583114800, "u": 76583115257, "b": [["1973.08000000", "0.00000000"], ["1973.07000000", "0.00000000"], ["1973.06000000", "0.00000000"], ["1973.05000000", "0.00000000"], ["1973.04000000", "0.00000000"], ["1973.01000000", "0.00000000"], ["1973.00000000", "0.00000000"], ["1972.99000000", "0.00000000"], ["1972.96000000", "0.00000000"], ["1972.95000000", "0.00000000"], ["1972.94000000", "0.00000000"], ["1972.90000000", "0.00000000"], ["1972.87000000", "0.00000000"], ["1972.86000000", "0.00000000"], ["1972.83000000", "0.00000000"], ["1972.82000000", "6.84460000"], ["1972.80000000", "0.00520000"], ["1972.79000000", "0.00000000"], ["1972.78000000", "0.00540000"], ["1972.77000000", "0.00260000"], ["1972.75000000", "0.00260000"], ["1972.74000000", "0.00260000"], ["1972.73000000", "0.00000000"], ["1972.72000000", "0.00520000"], ["1972.71000000", "0.00540000"], ["1972.70000000", "0.95920000"], ["1972.69000000", "0.00800000"], ["1972.68000000", "1.00450000"], ["1972.67000000", "0.00000000"], ["1972.66000000", "0.00650000"], ["1972.65000000", "0.03300000"], ["1972.64000000", "0.03000000"], ["1972.63000000", "0.00540000"], ["1972.62000000", "1.00200000"], ["1972.60000000", "10.15680000"], ["1972.58000000", "0.00000000"], ["1972.57000000", "0.00000000"], ["1972.56000000", "0.50000000"], ["1972.55000000", "0.00000000"], ["1972.54000000", "16.17400000"], ["1972.53000000", "0.00000000"], ["1972.50000000", "0.50570000"], ["1972.49000000", "0.00000000"], ["1972.47000000", "0.00000000"], ["1972.45000000", "0.00280000"], ["1972.44000000", "12.06800000"], ["1972.43000000", "7.14760000"], ["1972.42000000", "22.71690000"], ["1972.41000000", "0.00300000"], ["1972.38000000", "0.00000000"], ["1972.30000000", "0.00830000"], ["1972.22000000", "7.13200000"], ["1972.21000000", "23.24060000"], ["1972.17000000", "0.60840000"], ["1972.09000000", "2.54010000"], ["1972.06000000", "0.00390000"], ["1972.05000000", "0.00000000"], ["1972.02000000", "3.60000000"], ["1972.00000000", "29.92230000"], ["1971.99000000", "0.37810000"], ["1971.96000000", "26.79380000"], ["1971.90000000", "22.72260000"], ["1971.89000000", "13.39370000"], ["1971.88000000", "22.87370000"], ["1971.81000000", "8.29900000"], ["1971.77000000", "5.27350000"], ["1971.76000000", "0.80000000"], ["1971.64000000", "0.06300000"], ["1971.61000000", "7.19850000"], ["1971.50000000", "9.56440000"], ["1971.49000000", "0.00000000"], ["1971.37000000", "0.02070000"], ["1971.34000000", "0.10390000"], ["1971.30000000", "12.32840000"], ["1971.25000000", "0.09840000"], ["1971.01000000", "14.50380000"], ["1970.92000000", "7.16110000"], ["1970.76000000", "10.46940000"], ["1970.24000000", "23.55480000"], ["1967.86000000", "8.45390000"], ["1967.68000000", "0.03570000"], ["1967.29000000", "0.00260000"], ["1967.20000000", "0.01500000"], ["1965.25000000", "3.72290000"], ["1962.36000000", "0.01670000"], ["1947.39000000", "0.00000000"], ["1946.58000000", "0.25640000"], ["1944.00000000", "5.54330000"], ["1942.90000000", "0.15230000"], ["1913.05000000", "0.13040000"], ["1775.78000000", "0.00000000"], ["1775.54000000", "0.00620000"]], "a": [["1972.83000000", "72.79020000"], ["1972.84000000", "3.00000000"], ["1972.85000000", "0.01160000"], ["1972.88000000", "0.90280000"], ["1972.89000000", "1.71110000"], ["1972.90000000", "2.02560000"], ["1972.91000000", "4.00000000"], ["1972.95000000", "0.00000000"], ["1972.96000000", "0.68580000"], ["1972.97000000", "0.00000000"], ["1973.00000000", "6.47330000"], ["1973.01000000", "0.00000000"], ["1973.02000000", "0.00000000"], ["1973.05000000", "0.00000000"], ["1973.06000000", "0.00000000"], ["1973.07000000", "4.59640000"], ["1973.08000000", "26.27090000"], ["1973.09000000", "4.07490000"], ["1973.10000000", "0.00830000"], ["1973.11000000", "2.37810000"], ["1973.12000000", "0.03260000"], ["1973.14000000", "0.00650000"], ["1973.15000000", "0.00260000"], ["1973.17000000", "0.00780000"], ["1973.19000000", "0.66490000"], ["1973.20000000", "0.00570000"], ["1973.21000000", "7.09540000"], ["1973.22000000", "7.83780000"], ["1973.23000000", "1.73700000"], ["1973.26000000", "22.57370000"], ["1973.27000000", "7.09540000"], ["1973.29000000", "7.11140000"], ["1973.30000000", "8.52280000"], ["1973.32000000", "6.05780000"], ["1973.33000000", "7.09540000"], ["1973.34000000", "0.00390000"], ["1973.35000000", "0.00000000"], ["1973.37000000", "0.20130000"], ["1973.39000000", "0.20000000"], ["1973.40000000", "7.10410000"], ["1973.41000000", "13.51520000"], ["1973.52000000", "18.72680000"], ["1973.62000000", "13.53520000"], ["1973.63000000", "4.41260000"], ["1973.87000000", "1.40260000"], ["1973.90000000", "1.20550000"], ["1974.00000000", "22.72060000"], ["1974.16000000", "0.00000000"], ["1974.21000000", "22.57370000"], ["1974.36000000", "0.00000000"], ["1974.65000000", "0.00000000"], ["1974.66000000", "3.68110000"], ["1974.84000000", "0.00000000"], ["1974.85000000", "0.00260000"], ["1974.89000000", "0.00000000"], ["1974.95000000", "0.01910000"], ["1974.97000000", "0.00000000"], ["1975.06000000", "0.00000000"], ["1975.07000000", "0.00000000"], ["1975.10000000", "0.00000000"], ["1975.11000000", "0.00000000"], ["1975.13000000", "0.00260000"], ["1975.36000000", "0.00000000"], ["1975.38000000", "31.69850000"], ["1975.52000000", "0.00000000"], ["1975.54000000", "0.02450000"], ["1975.57000000", "0.00000000"], ["1975.74000000", "15.56460000"], ["1975.87000000", "9.39810000"], ["1976.14000000", "0.00260000"], ["1976.69000000", "0.00000000"], ["1976.85000000", "0.00000000"], ["1977.28000000", "0.00000000"], ["1977.90000000", "0.00000000"], ["1978.00000000", "0.01240000"], ["1978.28000000", "0.00000000"], ["1978.33000000", "0.00610000"], ["1978.44000000", "0.00000000"], ["1981.71000000", "1.34560000"], ["1986.37000000", "0.00000000"], ["1986.63000000", "0.04280000"]], "_local_ts_utc": "2026-06-01T07:49:08.112479+00:00"}
{"e": "depthUpdate", "E": 1780300149315, "s": "ETHUSDT", "U": 76583115258, "u": 76583116066, "b": [["1972.82000000", "0.00000000"], ["1972.80000000", "0.00000000"], ["1972.78000000", "0.00000000"], ["1972.77000000", "0.00000000"], ["1972.75000000", "0.00000000"], ["1972.74000000", "0.00000000"], ["1972.72000000", "0.00000000"], ["1972.71000000", "0.00000000"], ["1972.70000000", "0.00000000"], ["1972.69000000", "0.00000000"], ["1972.68000000", "0.00000000"], ["1972.66000000", "0.00000000"], ["1972.65000000", "0.00000000"], ["1972.64000000", "0.00000000"], ["1972.63000000", "0.00000000"], ["1972.62000000", "0.00000000"], ["1972.61000000", "0.00000000"], ["1972.60000000", "0.00000000"], ["1972.57000000", "0.00000000"], ["1972.56000000", "7.08540000"], ["1972.55000000", "0.00000000"], ["1972.54000000", "0.00260000"], ["1972.52000000", "0.00560000"], ["1972.51000000", "0.00540000"], ["1972.50000000", "0.50520000"], ["1972.49000000", "0.00000000"], ["1972.48000000", "0.06280000"], ["1972.46000000", "0.00650000"], ["1972.45000000", "0.00540000"], ["1972.44000000", "0.00260000"], ["1972.43000000", "0.03820000"], ["1972.42000000", "0.00260000"], ["1972.41000000", "0.00300000"], ["1972.40000000", "0.00260000"], ["1972.39000000", "0.00260000"], ["1972.37000000", "0.00000000"], ["1972.36000000", "0.76350000"], ["1972.35000000", "0.00000000"], ["1972.34000000", "0.00000000"], ["1972.33000000", "0.00000000"], ["1972.32000000", "0.03540000"], ["1972.30000000", "10.15830000"], ["1972.29000000", "0.00000000"], ["1972.28000000", "0.00000000"], ["1972.27000000", "0.50710000"], ["1972.26000000", "0.00390000"], ["1972.25000000", "0.00260000"], ["1972.23000000", "0.01010000"], ["1972.22000000", "0.03300000"], ["1972.21000000", "0.00000000"], ["1972.20000000", "7.28690000"], ["1972.19000000", "1.00260000"], ["1972.17000000", "0.00000000"], ["1972.15000000", "0.00260000"], ["1972.14000000", "0.00000000"], ["1972.13000000", "0.00000000"], ["1972.12000000", "22.57370000"], ["1972.11000000", "0.27000000"], ["1972.10000000", "5.31020000"], ["1972.09000000", "0.00260000"], ["1972.08000000", "2.00300000"], ["1972.05000000", "0.10140000"], ["1972.04000000", "0.00000000"], ["1972.03000000", "0.00000000"], ["1972.02000000", "0.00000000"], ["1972.01000000", "14.19080000"], ["1972.00000000", "22.82330000"], ["1971.98000000", "8.51450000"], ["1971.96000000", "27.04750000"], ["1971.93000000", "7.09540000"], ["1971.92000000", "0.27300000"], ["1971.91000000", "14.46080000"], ["1971.90000000", "0.00570000"], ["1971.89000000", "13.66370000"], ["1971.88000000", "29.16630000"], ["1971.84000000", "0.63840000"], ["1971.81000000", "7.09900000"], ["1971.80000000", "22.72260000"], ["1971.78000000", "13.51520000"], ["1971.77000000", "4.67350000"], ["1971.76000000", "0.00000000"], ["1971.72000000", "0.01010000"], ["1971.70000000", "24.96430000"], ["1971.68000000", "22.68560000"], ["1971.64000000", "13.52790000"], ["1971.62000000", "0.00000000"], ["1971.60000000", "14.98960000"], ["1971.57000000", "0.08300000"], ["1971.55000000", "0.78110000"], ["1971.53000000", "0.00300000"], ["1971.52000000", "0.03000000"], ["1971.51000000", "8.74680000"], ["1971.50000000", "9.76440000"], ["1971.46000000", "0.00390000"], ["1971.43000000", "0.60000000"], ["1971.34000000", "0.00390000"], ["1971.33000000", "3.14540000"], ["1971.29000000", "0.27460000"], ["1971.25000000", "0.01140000"], ["1971.21000000", "0.80000000"], ["1971.20000000", "21.68980000"], ["1971.12000000", "0.30450000"], ["1971.10000000", "8.51450000"], ["1970.95000000", "8.68150000"], ["1970.93000000", "0.26820000"], ["1970.90000000", "8.51450000"], ["1970.81000000", "16.48790000"], ["1970.80000000", "0.09230000"], ["1970.78000000", "5.36820000"], ["1970.77000000", "1.57500000"], ["1970.76000000", "0.01110000"], ["1970.75000000", "16.03540000"], ["1970.74000000", "0.27000000"], ["1970.70000000", "9.58880000"], ["1970.61000000", "14.19390000"], ["1970.58000000", "16.01710000"], ["1970.41000000", "15.21420000"], ["1970.40000000", "6.96780000"], ["1970.39000000", "0.00000000"], ["1970.38000000", "15.61310000"], ["1970.29000000", "29.08990000"], ["1970.26000000", "30.82430000"], ["1970.25000000", "17.89610000"], ["1970.17000000", "0.27260000"], ["1970.08000000", "1.04830000"], ["1970.06000000", "14.24020000"], ["1970.02000000", "13.64700000"], ["1969.92000000", "0.03820000"], ["1969.91000000", "0.28610000"], ["1969.74000000", "13.54230000"], ["1969.49000000", "5.21070000"], ["1969.48000000", "13.51520000"], ["1969.47000000", "0.02190000"], ["1969.46000000", "0.01170000"], ["1969.40000000", "4.42110000"], ["1969.31000000", "14.53730000"], ["1968.74000000", "9.53730000"], ["1968.73000000", "31.91820000"], ["1968.66000000", "1.18420000"], ["1967.21000000", "0.00260000"], ["1967.12000000", "0.00260000"], ["1965.05000000", "3.60000000"], ["1964.68000000", "127.40720000"], ["1964.06000000", "0.00000000"], ["1963.35000000", "0.00320000"], ["1961.56000000", "1.20550000"], ["1957.14000000", "0.53100000"], ["1956.72000000", "0.00000000"], ["1942.73000000", "0.12840000"], ["1932.64000000", "0.14850000"], ["1775.54000000", "0.00000000"], ["1775.31000000", "0.00620000"], ["1578.05000000", "0.04650000"], ["1577.49000000", "0.00000000"], ["1577.48000000", "0.10500000"]], "a": [["1972.57000000", "101.11280000"], ["1972.58000000", "0.00000000"], ["1972.59000000", "0.00000000"], ["1972.60000000", "0.00570000"], ["1972.62000000", "0.00000000"], ["1972.66000000", "0.00760000"], ["1972.67000000", "0.00260000"], ["1972.69000000", "0.00000000"], ["1972.70000000", "0.00570000"], ["1972.71000000", "0.00000000"], ["1972.72000000", "9.55380000"], ["1972.73000000", "6.46760000"], ["1972.74000000", "0.00000000"], ["1972.75000000", "0.00520000"], ["1972.76000000", "4.99390000"], ["1972.78000000", "0.00000000"], ["1972.79000000", "0.00000000"], ["1972.80000000", "0.03570000"], ["1972.81000000", "13.60300000"], ["1972.82000000", "15.60990000"], ["1972.83000000", "4.86640000"], ["1972.84000000", "0.00260000"], ["1972.85000000", "0.21420000"], ["1972.87000000", "0.03300000"], ["1972.88000000", "0.66750000"], ["1972.89000000", "1.70210000"], ["1972.90000000", "2.23280000"], ["1972.91000000", "0.00260000"], ["1972.92000000", "6.72820000"], ["1972.93000000", "7.09540000"], ["1972.94000000", "7.09930000"], ["1972.95000000", "7.09540000"], ["1972.96000000", "0.04020000"], ["1972.98000000", "0.00260000"], ["1972.99000000", "14.72070000"], ["1973.00000000", "0.00570000"], ["1973.05000000", "18.20570000"], ["1973.06000000", "31.08820000"], ["1973.07000000", "0.02300000"], ["1973.08000000", "21.34430000"], ["1973.09000000", "3.31720000"], ["1973.10000000", "0.10570000"], ["1973.11000000", "0.00000000"], ["1973.12000000", "0.03000000"], ["1973.13000000", "0.16370000"], ["1973.14000000", "26.77690000"], ["1973.15000000", "0.00000000"], ["1973.17000000", "0.00520000"], ["1973.18000000", "0.00300000"], ["1973.19000000", "4.03600000"], ["1973.20000000", "13.52090000"], ["1973.22000000", "14.40480000"], ["1973.29000000", "17.04030000"], ["1973.32000000", "3.13470000"], ["1973.39000000", "0.05000000"], ["1973.45000000", "27.07950000"], ["1973.50000000", "1.59870000"], ["1973.51000000", "5.52570000"], ["1973.53000000", "0.02260000"], ["1973.56000000", "0.51300000"], ["1973.57000000", "0.00260000"], ["1973.60000000", "18.57110000"], ["1973.61000000", "15.13490000"], ["1973.69000000", "22.62370000"], ["1973.70000000", "0.00310000"], ["1973.74000000", "0.03690000"], ["1973.78000000", "0.00000000"], ["1973.80000000", "7.10350000"], ["1973.82000000", "10.42400000"], ["1973.85000000", "22.25130000"], ["1974.05000000", "1.91050000"], ["1974.14000000", "0.08820000"], ["1974.20000000", "14.17720000"], ["1974.30000000", "0.00000000"], ["1974.32000000", "0.67920000"], ["1974.41000000", "0.03130000"], ["1974.42000000", "0.00000000"], ["1974.47000000", "0.02000000"], ["1974.48000000", "0.00000000"], ["1974.49000000", "23.86460000"], ["1974.52000000", "0.00000000"], ["1974.57000000", "0.13200000"], ["1974.63000000", "0.00000000"], ["1974.66000000", "0.15110000"], ["1974.67000000", "0.00260000"], ["1974.68000000", "0.00000000"], ["1974.69000000", "0.00000000"], ["1974.77000000", "0.00000000"], ["1974.89000000", "31.68730000"], ["1975.20000000", "0.00310000"], ["1975.48000000", "1.20550000"], ["1975.71000000", "0.79400000"], ["1975.81000000", "0.00000000"], ["1976.89000000", "0.08120000"], ["1977.26000000", "0.07100000"], ["1977.36000000", "8.55840000"], ["1977.54000000", "0.00000000"], ["1977.86000000", "31.63950000"], ["1978.00000000", "0.00980000"], ["1978.09000000", "3.70760000"], ["1978.18000000", "0.00000000"], ["1978.22000000", "0.00000000"], ["1979.92000000", "0.00270000"], ["1981.08000000", "0.70670000"], ["1981.11000000", "0.20770000"], ["1981.22000000", "0.47170000"], ["1982.63000000", "0.00590000"], ["2001.10000000", "0.00000000"], ["2002.02000000", "20.21860000"], ["2575.17000000", "0.02060000"]], "_local_ts_utc": "2026-06-01T07:49:08.211750+00:00"}
{"e": "depthUpdate", "E": 1780300149415, "s": "ETHUSDT", "U": 76583116067, "u": 76583116232, "b": [["1972.56000000", "26.94000000"], ["1972.52000000", "0.00560000"], ["1972.51000000", "0.00260000"], ["1972.50000000", "0.00520000"], ["1972.46000000", "0.00260000"], ["1972.44000000", "0.00260000"], ["1972.43000000", "0.03560000"], ["1972.42000000", "0.00000000"], ["1972.37000000", "0.55900000"], ["1972.34000000", "0.00000000"], ["1972.31000000", "1.05040000"], ["1972.30000000", "0.00520000"], ["1972.26000000", "2.34140000"], ["1972.25000000", "1.32000000"], ["1972.21000000", "6.46760000"], ["1972.20000000", "10.44110000"], ["1972.19000000", "1.62150000"], ["1972.13000000", "21.28620000"], ["1972.11000000", "0.00000000"], ["1972.08000000", "10.51750000"], ["1972.03000000", "7.09540000"], ["1971.92000000", "13.78820000"], ["1971.86000000", "0.27690000"], ["1971.82000000", "0.60000000"], ["1971.80000000", "27.09360000"], ["1971.54000000", "0.27700000"], ["1971.46000000", "0.80390000"], ["1971.43000000", "0.00000000"], ["1971.35000000", "0.27000000"], ["1971.21000000", "0.00000000"], ["1971.08000000", "0.00270000"], ["1970.26000000", "23.72890000"], ["1970.21000000", "32.03950000"], ["1970.06000000", "0.04940000"], ["1969.64000000", "0.00000000"], ["1967.03000000", "0.50440000"], ["1966.94000000", "0.02960000"], ["1958.60000000", "0.27520000"], ["1958.13000000", "0.03130000"], ["1942.37000000", "0.13350000"], ["1775.31000000", "0.02480000"]], "a": [["1972.57000000", "60.51500000"], ["1972.60000000", "0.00830000"], ["1972.61000000", "1.95200000"], ["1972.62000000", "6.46760000"], ["1972.64000000", "0.03000000"], ["1972.66000000", "0.01020000"], ["1972.67000000", "0.00520000"], ["1972.70000000", "0.00830000"], ["1972.71000000", "15.72990000"], ["1972.72000000", "3.01420000"], ["1972.73000000", "0.00260000"], ["1972.76000000", "4.99390000"], ["1972.77000000", "1.20550000"], ["1972.80000000", "40.91660000"], ["1972.81000000", "7.09540000"], ["1972.83000000", "2.92380000"], ["1972.84000000", "0.00000000"], ["1972.85000000", "0.21160000"], ["1972.86000000", "4.37000000"], ["1972.88000000", "0.66490000"], ["1972.89000000", "1.69950000"], ["1972.90000000", "0.92260000"], ["1972.91000000", "0.00000000"], ["1972.92000000", "9.90350000"], ["1973.12000000", "0.48900000"], ["1973.13000000", "13.39980000"], ["1973.19000000", "0.00000000"], ["1973.45000000", "22.71250000"], ["1973.51000000", "3.22200000"], ["1973.52000000", "8.79790000"], ["1973.67000000", "0.68070000"], ["1973.73000000", "6.80370000"], ["1973.77000000", "7.31980000"], ["1973.91000000", "0.00000000"], ["1973.95000000", "0.03600000"], ["1974.06000000", "8.52190000"], ["1974.11000000", "4.06160000"], ["1974.17000000", "0.63260000"], ["1974.43000000", "3.60260000"], ["1975.04000000", "0.00000000"], ["1975.31000000", "0.02790000"], ["1995.79000000", "6.56900000"]], "_local_ts_utc": "2026-06-01T07:49:08.312927+00:00"}
{"e": "depthUpdate", "E": 1780300149515, "s": "ETHUSDT", "U": 76583116233, "u": 76583116322, "b": [["1972.56000000", "24.06110000"], ["1972.51000000", "0.00520000"], ["1972.45000000", "0.01080000"], ["1972.44000000", "10.15500000"], ["1972.43000000", "0.03560000"], ["1972.38000000", "0.00540000"], ["1972.26000000", "2.34440000"], ["1972.17000000", "0.00520000"], ["1972.10000000", "8.87440000"], ["1971.92000000", "13.78520000"], ["1971.87000000", "0.05030000"], ["1971.82000000", "0.00000000"], ["1971.79000000", "12.73760000"], ["1971.69000000", "14.76330000"], ["1971.66000000", "0.04330000"], ["1971.46000000", "0.00390000"], ["1971.38000000", "13.87570000"], ["1971.37000000", "0.42070000"], ["1971.09000000", "0.00300000"], ["1971.08000000", "20.29760000"], ["1971.06000000", "25.44170000"], ["1971.01000000", "14.50380000"], ["1970.21000000", "31.76950000"], ["1969.81000000", "0.59650000"], ["1967.86000000", "7.87270000"], ["1967.78000000", "0.58590000"], ["1962.04000000", "0.02370000"], ["1957.67000000", "0.02430000"], ["1775.31000000", "0.03720000"]], "a": [["1972.57000000", "76.29970000"], ["1972.60000000", "0.00830000"], ["1972.61000000", "3.82530000"], ["1972.62000000", "6.47020000"], ["1972.64000000", "0.04420000"], ["1972.70000000", "7.11530000"], ["1972.71000000", "15.73250000"], ["1972.73000000", "0.00000000"], ["1972.75000000", "0.00260000"], ["1972.76000000", "4.99130000"], ["1972.80000000", "54.42920000"], ["1972.83000000", "2.91220000"], ["1972.85000000", "0.20000000"], ["1973.05000000", "11.68940000"], ["1973.51000000", "3.60010000"], ["1974.19000000", "7.09900000"], ["1975.19000000", "0.17830000"], ["1976.32000000", "0.79410000"]], "_local_ts_utc": "2026-06-01T07:49:08.412413+00:00"}
{"e": "depthUpdate", "E": 1780300149615, "s": "ETHUSDT", "U": 76583116323, "u": 76583116502, "b": [["1972.56000000", "6.84580000"], ["1972.55000000", "0.00260000"], ["1972.47000000", "0.00260000"], ["1972.45000000", "0.00540000"], ["1972.44000000", "0.00260000"], ["1972.39000000", "0.00000000"], ["1972.38000000", "0.00000000"], ["1972.37000000", "0.00540000"], ["1972.36000000", "0.76350000"], ["1972.32000000", "0.00000000"], ["1972.31000000", "0.05050000"], ["1972.30000000", "0.00820000"], ["1972.28000000", "0.00540000"], ["1972.27000000", "0.50710000"], ["1972.26000000", "0.00390000"], ["1972.25000000", "1.32000000"], ["1972.20000000", "0.00260000"], ["1972.17000000", "0.01040000"], ["1972.14000000", "0.00000000"], ["1972.13000000", "0.00000000"], ["1972.12000000", "0.00000000"], ["1972.10000000", "0.00570000"], ["1972.08000000", "2.00300000"], ["1972.05000000", "0.00000000"], ["1972.03000000", "0.00000000"], ["1972.02000000", "7.09540000"], ["1972.01000000", "15.60990000"], ["1972.00000000", "0.07130000"], ["1971.99000000", "0.00000000"], ["1971.98000000", "0.00000000"], ["1971.97000000", "13.56550000"], ["1971.96000000", "27.02830000"], ["1971.93000000", "7.09540000"], ["1971.92000000", "0.27000000"], ["1971.91000000", "15.87990000"], ["1971.90000000", "7.10110000"], ["1971.89000000", "21.96160000"], ["1971.88000000", "29.26770000"], ["1971.81000000", "20.88420000"], ["1971.79000000", "8.92880000"], ["1971.78000000", "0.00000000"], ["1971.69000000", "14.56330000"], ["1971.67000000", "0.22680000"], ["1971.60000000", "15.36770000"], ["1971.58000000", "0.55290000"], ["1971.38000000", "14.27570000"], ["1971.37000000", "0.00000000"], ["1971.31000000", "7.91730000"], ["1971.30000000", "12.32840000"], ["1971.12000000", "0.20450000"], ["1971.01000000", "14.50380000"], ["1970.95000000", "8.78150000"], ["1970.79000000", "0.00910000"], ["1970.71000000", "0.30820000"], ["1970.27000000", "7.13190000"], ["1970.25000000", "17.62610000"], ["1970.17000000", "0.00260000"], ["1970.11000000", "0.13740000"], ["1970.07000000", "7.09540000"], ["1970.06000000", "14.24020000"], ["1969.86000000", "0.01930000"], ["1969.82000000", "0.27260000"], ["1969.76000000", "0.20180000"], ["1969.63000000", "0.12080000"], ["1969.56000000", "0.00900000"], ["1969.55000000", "0.27000000"], ["1966.90000000", "0.28610000"], ["1966.81000000", "0.00000000"], ["1775.31000000", "0.04960000"]], "a": [["1972.57000000", "76.29970000"], ["1972.58000000", "0.01160000"], ["1972.61000000", "5.70560000"], ["1972.62000000", "6.48040000"], ["1972.65000000", "1.20550000"], ["1972.69000000", "7.09540000"], ["1972.72000000", "3.01420000"], ["1972.76000000", "4.97970000"], ["1972.77000000", "0.00000000"], ["1972.80000000", "53.19170000"], ["1972.83000000", "2.81070000"], ["1972.85000000", "0.20300000"], ["1973.09000000", "3.83020000"], ["1973.10000000", "0.56470000"], ["1973.17000000", "0.00260000"], ["1973.32000000", "5.04170000"], ["1973.37000000", "3.84890000"], ["1973.46000000", "23.59470000"], ["1973.65000000", "8.50040000"], ["1973.87000000", "0.00260000"], ["1974.05000000", "1.86300000"], ["1974.14000000", "0.01150000"], ["1974.18000000", "7.09540000"], ["1974.19000000", "0.00000000"], ["1974.29000000", "0.00000000"], ["1974.82000000", "0.54600000"], ["1974.85000000", "0.46160000"], ["1974.95000000", "0.00000000"], ["1975.54000000", "0.00380000"], ["1975.67000000", "0.01910000"], ["1976.26000000", "0.02070000"]], "_local_ts_utc": "2026-06-01T07:49:08.513468+00:00"}
{"e": "depthUpdate", "E": 1780300149715, "s": "ETHUSDT", "U": 76583116503, "u": 76583117045, "b": [["1972.56000000", "0.00000000"], ["1972.55000000", "0.00000000"], ["1972.54000000", "0.00000000"], ["1972.52000000", "0.00000000"], ["1972.51000000", "0.00000000"], ["1972.50000000", "0.00000000"], ["1972.48000000", "0.00000000"], ["1972.47000000", "0.00000000"], ["1972.46000000", "0.00000000"], ["1972.45000000", "0.00000000"], ["1972.44000000", "0.00000000"], ["1972.43000000", "0.00000000"], ["1972.41000000", "0.00000000"], ["1972.40000000", "0.00000000"], ["1972.39000000", "0.00000000"], ["1972.37000000", "0.00000000"], ["1972.36000000", "13.18660000"], ["1972.35000000", "0.00780000"], ["1972.31000000", "0.00260000"], ["1972.30000000", "0.00820000"], ["1972.28000000", "0.00800000"], ["1972.27000000", "0.50970000"], ["1972.26000000", "0.00650000"], ["1972.25000000", "0.00260000"], ["1972.23000000", "0.01270000"], ["1972.22000000", "0.04100000"], ["1972.21000000", "0.00260000"], ["1972.20000000", "0.00800000"], ["1972.19000000", "1.00260000"], ["1972.17000000", "0.01300000"], ["1972.14000000", "0.00000000"], ["1972.10000000", "0.00800000"], ["1972.09000000", "18.26120000"], ["1972.08000000", "2.00300000"], ["1972.03000000", "0.00000000"], ["1972.02000000", "0.00000000"], ["1972.01000000", "0.00000000"], ["1971.98000000", "22.70530000"], ["1971.97000000", "17.47510000"], ["1971.96000000", "26.77460000"], ["1971.93000000", "0.00000000"], ["1971.92000000", "7.09540000"], ["1971.91000000", "0.00000000"], ["1971.90000000", "0.00570000"], ["1971.89000000", "21.69160000"], ["1971.88000000", "29.52150000"], ["1971.85000000", "0.02190000"], ["1971.82000000", "7.09540000"], ["1971.81000000", "7.36540000"], ["1971.80000000", "4.37670000"], ["1971.77000000", "13.18800000"], ["1971.75000000", "7.09840000"], ["1971.72000000", "0.00000000"], ["1971.71000000", "20.61060000"], ["1971.70000000", "16.44610000"], ["1971.69000000", "7.46170000"], ["1971.67000000", "8.54130000"], ["1971.65000000", "10.24030000"], ["1971.64000000", "0.01270000"], ["1971.61000000", "0.10000000"], ["1971.59000000", "0.27000000"], ["1971.54000000", "13.79220000"], ["1971.53000000", "0.40300000"], ["1971.51000000", "7.44370000"], ["1971.50000000", "1.05250000"], ["1971.48000000", "17.66790000"], ["1971.45000000", "8.59540000"], ["1971.41000000", "0.01010000"], ["1971.40000000", "7.64110000"], ["1971.38000000", "1.35460000"], ["1971.31000000", "7.11730000"], ["1971.28000000", "0.05910000"], ["1971.06000000", "22.57760000"], ["1971.02000000", "1.52330000"], ["1970.73000000", "0.27090000"], ["1970.45000000", "4.74580000"], ["1970.11000000", "0.13740000"], ["1970.08000000", "8.14370000"], ["1970.07000000", "8.51450000"], ["1970.02000000", "13.69460000"], ["1969.91000000", "0.01610000"], ["1969.88000000", "8.58110000"], ["1969.87000000", "0.00000000"], ["1969.86000000", "14.21010000"], ["1969.81000000", "0.00000000"], ["1969.75000000", "14.32310000"], ["1969.74000000", "13.77200000"], ["1969.55000000", "0.27000000"], ["1968.90000000", "0.70760000"], ["1968.83000000", "0.43910000"], ["1968.39000000", "0.00000000"], ["1967.49000000", "30.32150000"], ["1775.31000000", "0.00000000"], ["1578.05000000", "0.05350000"], ["1578.02000000", "0.00700000"], ["1577.99000000", "0.03450000"], ["1577.48000000", "0.09100000"], ["1577.47000000", "0.00700000"], ["1472.55000000", "0.00600000"]], "a": [["1972.37000000", "91.19090000"], ["1972.38000000", "0.00510000"], ["1972.39000000", "0.00510000"], ["1972.40000000", "0.00570000"], ["1972.41000000", "1.19400000"], ["1972.45000000", "0.01160000"], ["1972.46000000", "0.00000000"], ["1972.47000000", "0.00000000"], ["1972.48000000", "3.00000000"], ["1972.49000000", "0.00520000"], ["1972.50000000", "0.00570000"], ["1972.51000000", "0.00000000"], ["1972.52000000", "0.00000000"], ["1972.53000000", "0.00000000"], ["1972.54000000", "0.00000000"], ["1972.55000000", "13.55850000"], ["1972.56000000", "26.15090000"], ["1972.57000000", "15.23960000"], ["1972.58000000", "0.01420000"], ["1972.61000000", "0.00260000"], ["1972.63000000", "0.63580000"], ["1972.64000000", "0.04420000"], ["1972.65000000", "0.00260000"], ["1972.66000000", "1.30910000"], ["1972.67000000", "0.00000000"], ["1972.69000000", "7.09540000"], ["1972.70000000", "7.11270000"], ["1972.71000000", "15.72990000"], ["1972.72000000", "0.00000000"], ["1972.78000000", "1.20550000"], ["1972.79000000", "1.20000000"], ["1972.80000000", "53.19430000"], ["1973.22000000", "13.20480000"], ["1973.40000000", "7.10150000"], ["1973.50000000", "1.59610000"], ["1973.54000000", "0.00650000"], ["1973.95000000", "0.03600000"], ["1973.97000000", "1.51200000"], ["1973.98000000", "7.10110000"], ["1974.07000000", "0.81260000"], ["1975.19000000", "0.17830000"], ["2472.57000000", "0.27060000"]], "_local_ts_utc": "2026-06-01T07:49:08.611477+00:00"}
{"e": "depthUpdate", "E": 1780300149815, "s": "ETHUSDT", "U": 76583117046, "u": 76583117560, "b": [["1972.36000000", "0.00000000"], ["1972.35000000", "0.00000000"], ["1972.31000000", "0.00000000"], ["1972.30000000", "0.00000000"], ["1972.28000000", "0.00000000"], ["1972.27000000", "0.00000000"], ["1972.26000000", "0.00000000"], ["1972.25000000", "0.00000000"], ["1972.23000000", "0.00000000"], ["1972.22000000", "0.00000000"], ["1972.21000000", "0.00000000"], ["1972.20000000", "0.00000000"], ["1972.19000000", "18.38620000"], ["1972.18000000", "0.00780000"], ["1972.17000000", "0.01820000"], ["1972.16000000", "0.04280000"], ["1972.15000000", "0.00260000"], ["1972.13000000", "0.00540000"], ["1972.12000000", "0.00540000"], ["1972.11000000", "0.00000000"], ["1972.10000000", "0.00520000"], ["1972.09000000", "0.01060000"], ["1972.08000000", "2.00560000"], ["1972.07000000", "0.00000000"], ["1972.06000000", "0.51360000"], ["1972.01000000", "0.00540000"], ["1972.00000000", "17.27370000"], ["1971.99000000", "0.00000000"], ["1971.98000000", "0.00260000"], ["1971.97000000", "0.05030000"], ["1971.96000000", "0.00260000"], ["1971.92000000", "0.00000000"], ["1971.90000000", "0.00570000"], ["1971.89000000", "15.99000000"], ["1971.88000000", "22.57370000"], ["1971.85000000", "7.16780000"], ["1971.79000000", "11.76180000"], ["1971.78000000", "0.05030000"], ["1971.69000000", "7.71550000"], ["1971.60000000", "8.82300000"], ["1971.53000000", "0.00300000"], ["1971.51000000", "14.13120000"], ["1971.50000000", "1.05560000"], ["1971.45000000", "7.09540000"], ["1971.41000000", "0.01010000"], ["1971.38000000", "0.55460000"], ["1971.35000000", "1.77000000"], ["1971.33000000", "29.91940000"], ["1971.31000000", "7.11730000"], ["1971.30000000", "12.33100000"], ["1971.24000000", "0.40000000"], ["1971.11000000", "8.76470000"], ["1971.09000000", "0.80300000"], ["1971.02000000", "1.52330000"], ["1970.95000000", "8.68150000"], ["1970.89000000", "0.24810000"], ["1970.87000000", "12.85220000"], ["1970.86000000", "25.36330000"], ["1970.80000000", "0.00570000"], ["1970.77000000", "1.35870000"], ["1969.89000000", "8.72580000"], ["1969.75000000", "7.22770000"], ["1969.63000000", "0.15860000"], ["1969.55000000", "0.00000000"], ["1966.83000000", "0.00950000"], ["1966.74000000", "0.13510000"], ["1962.43000000", "0.00260000"], ["1775.13000000", "0.00000000"], ["1774.98000000", "0.00620000"]], "a": [["1972.20000000", "16.59530000"], ["1972.21000000", "0.00510000"], ["1972.22000000", "0.00770000"], ["1972.23000000", "0.00260000"], ["1972.24000000", "0.00260000"], ["1972.25000000", "0.00000000"], ["1972.26000000", "0.00260000"], ["1972.27000000", "0.00260000"], ["1972.28000000", "0.00800000"], ["1972.29000000", "0.00260000"], ["1972.30000000", "0.01110000"], ["1972.31000000", "6.75000000"], ["1972.32000000", "0.00260000"], ["1972.35000000", "0.00540000"], ["1972.36000000", "0.00270000"], ["1972.37000000", "19.60600000"], ["1972.38000000", "0.00000000"], ["1972.39000000", "0.00000000"], ["1972.40000000", "0.00570000"], ["1972.41000000", "1.19400000"], ["1972.42000000", "0.01160000"], ["1972.44000000", "0.03300000"], ["1972.45000000", "0.01160000"], ["1972.48000000", "3.03000000"], ["1972.49000000", "0.00260000"], ["1972.50000000", "0.00570000"], ["1972.53000000", "0.00000000"], ["1972.54000000", "5.77460000"], ["1972.55000000", "12.73480000"], ["1972.56000000", "7.09800000"], ["1972.57000000", "0.00000000"], ["1972.58000000", "0.01160000"], ["1972.60000000", "0.00570000"], ["1972.61000000", "24.26180000"], ["1972.62000000", "6.47780000"], ["1972.64000000", "0.03000000"], ["1972.65000000", "0.03300000"], ["1972.66000000", "16.91900000"], ["1972.69000000", "7.70500000"], ["1972.70000000", "7.10110000"], ["1972.71000000", "11.13700000"], ["1972.74000000", "0.00390000"], ["1972.76000000", "4.97710000"], ["1972.88000000", "0.00260000"], ["1972.89000000", "11.62840000"], ["1972.90000000", "0.41570000"], ["1973.05000000", "18.44210000"], ["1973.06000000", "41.01710000"], ["1973.10000000", "0.46470000"], ["1973.20000000", "13.51830000"], ["1973.29000000", "7.11140000"], ["1973.30000000", "8.52020000"], ["1973.51000000", "3.22200000"], ["1973.99000000", "0.00000000"], ["1974.06000000", "0.00300000"], ["1974.18000000", "0.00000000"], ["1974.44000000", "0.00000000"], ["1974.82000000", "0.03300000"], ["1974.85000000", "0.46160000"], ["1974.86000000", "0.00000000"], ["1974.88000000", "0.00000000"], ["1975.29000000", "0.92420000"], ["1976.13000000", "0.00000000"], ["1977.76000000", "0.00000000"], ["1977.85000000", "0.00000000"], ["1977.91000000", "0.00000000"]], "_local_ts_utc": "2026-06-01T07:49:08.711298+00:00"}
{"e": "depthUpdate", "E": 1780300149915, "s": "ETHUSDT", "U": 76583117561, "u": 76583117739, "b": [["1972.19000000", "35.83370000"], ["1972.18000000", "0.00260000"], ["1972.16000000", "0.01280000"], ["1972.15000000", "0.00260000"], ["1972.13000000", "0.00260000"], ["1972.12000000", "0.00800000"], ["1972.11000000", "1.32600000"], ["1972.10000000", "0.01060000"], ["1972.09000000", "5.32470000"], ["1972.07000000", "0.00540000"], ["1972.06000000", "6.97860000"], ["1972.05000000", "0.62170000"], ["1972.01000000", "15.86370000"], ["1972.00000000", "0.07130000"], ["1971.98000000", "0.00000000"], ["1971.97000000", "0.05330000"], ["1971.92000000", "11.75670000"], ["1971.91000000", "7.09540000"], ["1971.90000000", "8.52020000"], ["1971.89000000", "29.50520000"], ["1971.86000000", "0.00690000"], ["1971.84000000", "0.03000000"], ["1971.81000000", "7.09540000"], ["1971.79000000", "11.49180000"], ["1971.69000000", "7.46170000"], ["1971.58000000", "1.16130000"], ["1971.53000000", "0.40300000"], ["1971.52000000", "7.12540000"], ["1971.39000000", "14.98590000"], ["1971.24000000", "0.00000000"], ["1970.41000000", "15.30030000"], ["1970.40000000", "6.99780000"], ["1970.39000000", "0.21530000"], ["1970.07000000", "0.00000000"], ["1969.88000000", "1.48570000"], ["1969.75000000", "0.13230000"], ["1969.60000000", "25.43520000"], ["1966.66000000", "26.83860000"], ["1966.57000000", "0.00260000"], ["1963.03000000", "0.49170000"], ["1962.81000000", "1.45150000"], ["1956.39000000", "3.19070000"], ["1932.75000000", "0.12910000"], ["1774.98000000", "0.01860000"]], "a": [["1972.20000000", "0.68350000"], ["1972.21000000", "0.00770000"], ["1972.24000000", "0.10260000"], ["1972.28000000", "0.00260000"], ["1972.29000000", "0.00800000"], ["1972.30000000", "0.00830000"], ["1972.31000000", "0.00000000"], ["1972.32000000", "0.00000000"], ["1972.35000000", "0.00000000"], ["1972.36000000", "0.00000000"], ["1972.37000000", "0.00660000"], ["1972.40000000", "0.01110000"], ["1972.42000000", "0.00260000"], ["1972.45000000", "0.00540000"], ["1972.46000000", "1.33480000"], ["1972.52000000", "6.46760000"], ["1972.55000000", "7.75770000"], ["1972.56000000", "8.38860000"], ["1972.60000000", "9.08170000"], ["1972.61000000", "0.00000000"], ["1972.62000000", "0.01020000"], ["1972.63000000", "0.00000000"], ["1972.66000000", "15.61750000"], ["1972.69000000", "7.60500000"], ["1972.78000000", "0.00000000"], ["1972.79000000", "0.00000000"], ["1972.80000000", "53.29430000"], ["1972.81000000", "7.09800000"], ["1972.92000000", "11.10350000"], ["1973.06000000", "31.08820000"], ["1973.11000000", "0.51040000"], ["1973.13000000", "13.77790000"], ["1973.72000000", "9.65650000"], ["1974.86000000", "13.51520000"], ["1977.58000000", "0.00260000"], ["1977.64000000", "0.00000000"], ["1977.70000000", "0.00000000"], ["1981.22000000", "0.00000000"]], "_local_ts_utc": "2026-06-01T07:49:08.811749+00:00"}
{"e": "depthUpdate", "E": 1780300150015, "s": "ETHUSDT", "U": 76583117740, "u": 76583117804, "b": [["1972.19000000", "43.12710000"], ["1972.18000000", "6.47020000"], ["1972.12000000", "0.00800000"], ["1972.11000000", "1.32860000"], ["1972.09000000", "9.05270000"], ["1972.08000000", "2.00300000"], ["1972.07000000", "0.00000000"], ["1972.06000000", "0.51100000"], ["1972.02000000", "7.09540000"], ["1971.95000000", "8.09540000"], ["1971.93000000", "8.17060000"], ["1971.92000000", "7.09540000"], ["1971.82000000", "9.63320000"], ["1971.70000000", "16.44890000"], ["1971.60000000", "12.04120000"], ["1971.55000000", "7.87650000"], ["1971.34000000", "7.09930000"], ["1970.06000000", "7.14480000"], ["1970.00000000", "409.63310000"], ["1969.89000000", "2.61280000"], ["1969.86000000", "0.01930000"], ["1969.63000000", "0.71730000"], ["1956.88000000", "0.63550000"], ["1932.75000000", "0.25820000"], ["1774.98000000", "0.03100000"], ["1472.55000000", "0.00000000"], ["1192.00000000", "0.00000000"]], "a": [["1972.21000000", "0.01030000"], ["1972.29000000", "0.00260000"], ["1972.30000000", "0.00830000"], ["1972.37000000", "0.00400000"], ["1972.40000000", "0.00570000"], ["1972.41000000", "0.00000000"], ["1972.45000000", "1.31240000"], ["1972.47000000", "0.00540000"], ["1972.52000000", "0.00300000"], ["1972.63000000", "6.46760000"], ["1972.86000000", "4.37280000"], ["1972.91000000", "0.51300000"], ["1973.04000000", "0.00260000"], ["1973.05000000", "18.43950000"], ["1973.29000000", "7.10860000"], ["1973.31000000", "0.03560000"], ["1973.40000000", "7.61450000"], ["1973.50000000", "1.76660000"], ["1975.74000000", "15.00640000"], ["1977.57000000", "3.73440000"], ["1977.66000000", "0.00260000"], ["2472.57000000", "0.26460000"]], "_local_ts_utc": "2026-06-01T07:49:08.911755+00:00"}
{"e": "depthUpdate", "E": 1780300150115, "s": "ETHUSDT", "U": 76583117805, "u": 76583118299, "b": [["1972.35000000", "85.46440000"], ["1972.31000000", "0.00540000"], ["1972.30000000", "6.47560000"], ["1972.29000000", "1.00580000"], ["1972.28000000", "0.00540000"], ["1972.27000000", "3.00000000"], ["1972.26000000", "30.34820000"], ["1972.25000000", "0.31830000"], ["1972.24000000", "23.07630000"], ["1972.23000000", "15.87160000"], ["1972.22000000", "0.00260000"], ["1972.21000000", "8.52100000"], ["1972.20000000", "5.03520000"], ["1972.19000000", "4.28210000"], ["1972.18000000", "0.00260000"], ["1972.16000000", "0.04020000"], ["1972.15000000", "0.00000000"], ["1972.13000000", "7.17810000"], ["1972.12000000", "7.09860000"], ["1972.11000000", "16.94300000"], ["1972.10000000", "0.00570000"], ["1972.09000000", "9.04470000"], ["1972.07000000", "7.09860000"], ["1971.68000000", "22.61720000"], ["1971.65000000", "16.92780000"], ["1971.60000000", "12.24120000"], ["1971.53000000", "1.20300000"], ["1971.44000000", "0.06840000"], ["1971.38000000", "0.35460000"], ["1971.30000000", "12.32840000"], ["1971.24000000", "0.00000000"], ["1971.11000000", "8.86470000"], ["1971.09000000", "0.00300000"], ["1970.92000000", "7.43110000"], ["1970.89000000", "0.14810000"], ["1970.40000000", "4.52050000"], ["1970.38000000", "7.09860000"], ["1970.27000000", "0.03650000"], ["1970.26000000", "8.11900000"], ["1970.11000000", "1.16650000"], ["1970.08000000", "1.04830000"], ["1970.06000000", "0.04940000"], ["1969.76000000", "0.17180000"], ["1969.69000000", "0.28310000"], ["1969.39000000", "0.35980000"], ["1968.53000000", "0.03000000"], ["1967.89000000", "66.50390000"], ["1967.20000000", "0.01500000"], ["1967.19000000", "0.00000000"], ["1966.57000000", "0.00000000"], ["1965.32000000", "63.42750000"], ["1965.30000000", "0.14180000"], ["1964.88000000", "0.00870000"], ["1962.76000000", "76.16070000"], ["1962.43000000", "0.00000000"], ["1957.60000000", "0.22710000"], ["1945.02000000", "1.50460000"], ["1942.62000000", "0.13180000"], ["1922.89000000", "0.13240000"], ["1775.12000000", "0.00620000"], ["1775.01000000", "0.00000000"], ["1774.98000000", "0.00000000"]], "a": [["1972.20000000", "0.00000000"], ["1972.21000000", "0.00000000"], ["1972.22000000", "0.00000000"], ["1972.23000000", "0.00000000"], ["1972.24000000", "0.00000000"], ["1972.26000000", "0.00000000"], ["1972.27000000", "0.00000000"], ["1972.28000000", "0.00000000"], ["1972.29000000", "0.00000000"], ["1972.30000000", "0.00000000"], ["1972.36000000", "0.10780000"], ["1972.37000000", "0.00660000"], ["1972.40000000", "0.00830000"], ["1972.42000000", "0.00260000"], ["1972.44000000", "0.03560000"], ["1972.45000000", "0.00260000"], ["1972.46000000", "0.00260000"], ["1972.47000000", "0.00800000"], ["1972.48000000", "3.03260000"], ["1972.49000000", "0.00260000"], ["1972.51000000", "0.00000000"], ["1972.53000000", "0.00540000"], ["1972.54000000", "0.56140000"], ["1972.55000000", "0.66770000"], ["1972.56000000", "1.29320000"], ["1972.58000000", "0.00000000"], ["1972.59000000", "0.00270000"], ["1972.60000000", "4.42220000"], ["1972.63000000", "0.00000000"], ["1972.66000000", "0.01020000"], ["1972.73000000", "0.01160000"], ["1972.74000000", "6.47150000"], ["1972.80000000", "39.67910000"], ["1972.84000000", "0.10000000"], ["1972.92000000", "10.30350000"], ["1972.96000000", "0.60720000"], ["1973.02000000", "0.80260000"], ["1973.17000000", "0.00260000"], ["1973.20000000", "13.52090000"], ["1973.30000000", "8.52280000"], ["1973.37000000", "6.70450000"], ["1973.45000000", "23.27950000"], ["1973.65000000", "7.10040000"], ["1973.70000000", "0.20310000"], ["1973.71000000", "6.77700000"], ["1973.73000000", "2.54000000"], ["1973.78000000", "0.40000000"], ["1973.85000000", "23.05130000"], ["1973.95000000", "8.70780000"], ["1974.07000000", "16.42960000"], ["1974.19000000", "7.09860000"], ["1974.85000000", "0.00260000"], ["1975.19000000", "13.69960000"], ["1975.46000000", "0.62900000"], ["1976.95000000", "69.60600000"], ["1977.01000000", "0.06840000"], ["1977.26000000", "0.00260000"], ["1977.67000000", "0.00580000"], ["1979.52000000", "60.92610000"], ["1980.06000000", "0.03000000"], ["1980.78000000", "0.10260000"], ["1982.08000000", "78.68560000"], ["1983.71000000", "0.10000000"], ["1987.08000000", "0.02000000"], ["1998.50000000", "0.10000000"]], "_local_ts_utc": "2026-06-01T07:49:09.011580+00:00"}
{"e": "depthUpdate", "E": 1780300150215, "s": "ETHUSDT", "U": 76583118300, "u": 76583118333, "b": [["1972.35000000", "85.46700000"], ["1972.31000000", "0.00800000"], ["1972.30000000", "6.47820000"], ["1972.29000000", "1.00840000"], ["1972.28000000", "0.00800000"], ["1972.27000000", "3.00540000"], ["1972.26000000", "15.54060000"], ["1972.22000000", "0.00000000"], ["1972.21000000", "8.51840000"], ["1972.19000000", "4.27950000"], ["1972.18000000", "0.00000000"], ["1972.17000000", "0.01560000"], ["1971.51000000", "7.44370000"], ["1970.20000000", "8.50860000"], ["1970.19000000", "11.53540000"], ["1969.69000000", "0.01310000"], ["1969.66000000", "16.33570000"], ["1969.63000000", "0.12080000"], ["1969.37000000", "0.74850000"], ["1958.31000000", "0.21210000"], ["1775.12000000", "0.01860000"]], "a": [["1972.36000000", "0.62260000"], ["1972.42000000", "0.00520000"], ["1972.48000000", "3.00260000"], ["1972.66000000", "0.01280000"], ["1973.23000000", "1.20810000"], ["1975.04000000", "0.03000000"]], "_local_ts_utc": "2026-06-01T07:49:09.110542+00:00"}
{"e": "depthUpdate", "E": 1780300150315, "s": "ETHUSDT", "U": 76583118334, "u": 76583118939, "b": [["1972.47000000", "105.17250000"], ["1972.46000000", "0.86450000"], ["1972.45000000", "0.00510000"], ["1972.44000000", "5.04120000"], ["1972.43000000", "0.28860000"], ["1972.42000000", "0.00540000"], ["1972.41000000", "11.78760000"], ["1972.40000000", "0.00260000"], ["1972.39000000", "0.00260000"], ["1972.38000000", "5.41240000"], ["1972.37000000", "0.00000000"], ["1972.36000000", "0.00000000"], ["1972.35000000", "10.60260000"], ["1972.34000000", "0.50710000"], ["1972.32000000", "0.03000000"], ["1972.31000000", "8.52100000"], ["1972.30000000", "0.00830000"], ["1972.29000000", "22.57630000"], ["1972.28000000", "14.98230000"], ["1972.27000000", "21.29840000"], ["1972.26000000", "0.00390000"], ["1972.25000000", "0.25890000"], ["1972.24000000", "0.50000000"], ["1972.23000000", "15.31470000"], ["1972.22000000", "0.03300000"], ["1972.21000000", "8.52600000"], ["1972.20000000", "5.01830000"], ["1972.19000000", "4.28710000"], ["1972.16000000", "0.04280000"], ["1972.15000000", "11.21420000"], ["1972.14000000", "13.52130000"], ["1972.13000000", "0.00000000"], ["1972.09000000", "15.30210000"], ["1972.08000000", "24.57670000"], ["1972.06000000", "0.00390000"], ["1972.05000000", "0.67170000"], ["1972.01000000", "15.60990000"], ["1971.98000000", "0.37810000"], ["1971.96000000", "9.38250000"], ["1971.95000000", "8.10300000"], ["1971.93000000", "0.00000000"], ["1971.91000000", "7.70380000"], ["1971.86000000", "1.67740000"], ["1971.77000000", "19.77950000"], ["1971.75000000", "7.64980000"], ["1971.65000000", "16.82640000"], ["1971.61000000", "0.10000000"], ["1971.60000000", "11.86310000"], ["1971.58000000", "0.55290000"], ["1971.56000000", "3.86260000"], ["1971.53000000", "0.80300000"], ["1971.44000000", "1.27390000"], ["1971.43000000", "0.00760000"], ["1971.40000000", "7.63850000"], ["1971.35000000", "0.27000000"], ["1971.32000000", "0.39020000"], ["1971.27000000", "11.06470000"], ["1971.20000000", "21.69740000"], ["1971.11000000", "8.76470000"], ["1970.58000000", "7.50260000"], ["1970.41000000", "1.10950000"], ["1970.26000000", "1.02360000"], ["1969.92000000", "0.00820000"], ["1969.78000000", "0.01000000"], ["1969.40000000", "0.53550000"], ["1969.31000000", "1.02210000"], ["1967.35000000", "0.00000000"], ["1967.25000000", "3.63760000"], ["1967.19000000", "0.00000000"], ["1966.74000000", "0.13250000"], ["1966.66000000", "26.83600000"], ["1965.12000000", "0.02490000"], ["1964.88000000", "0.00000000"], ["1963.03000000", "0.00000000"], ["1961.56000000", "0.00000000"], ["1961.30000000", "0.02340000"], ["1959.02000000", "0.20370000"], ["1775.23000000", "0.00620000"], ["1775.12000000", "0.00000000"]], "a": [["1972.36000000", "0.00000000"], ["1972.37000000", "0.00000000"], ["1972.40000000", "0.00000000"], ["1972.42000000", "0.00000000"], ["1972.44000000", "0.00000000"], ["1972.45000000", "0.00000000"], ["1972.46000000", "0.00000000"], ["1972.47000000", "0.00000000"], ["1972.48000000", "2.58500000"], ["1972.49000000", "0.01040000"], ["1972.50000000", "0.00520000"], ["1972.52000000", "0.00560000"], ["1972.53000000", "0.00260000"], ["1972.54000000", "0.00650000"], ["1972.55000000", "0.00260000"], ["1972.56000000", "0.00260000"], ["1972.59000000", "0.00260000"], ["1972.60000000", "0.01090000"], ["1972.64000000", "0.00000000"], ["1972.66000000", "0.05260000"], ["1972.69000000", "0.00260000"], ["1972.70000000", "0.00570000"], ["1972.71000000", "0.10000000"], ["1972.73000000", "0.00000000"], ["1972.74000000", "0.00690000"], ["1972.75000000", "0.00260000"], ["1972.76000000", "0.00000000"], ["1972.78000000", "0.00260000"], ["1972.80000000", "0.03830000"], ["1972.81000000", "0.00260000"], ["1972.82000000", "0.00000000"], ["1972.84000000", "0.00000000"], ["1972.85000000", "0.00300000"], ["1972.86000000", "0.00280000"], ["1972.88000000", "0.65230000"], ["1972.89000000", "1.69950000"], ["1972.90000000", "4.68410000"], ["1972.91000000", "0.00000000"], ["1972.92000000", "0.00000000"], ["1972.93000000", "0.00000000"], ["1972.94000000", "7.10250000"], ["1972.95000000", "0.00000000"], ["1972.96000000", "0.09020000"], ["1972.97000000", "0.50690000"], ["1972.99000000", "0.00000000"], ["1973.00000000", "0.00570000"], ["1973.01000000", "0.00000000"], ["1973.02000000", "0.00260000"], ["1973.03000000", "0.10000000"], ["1973.04000000", "0.00260000"], ["1973.06000000", "22.57370000"], ["1973.11000000", "7.23900000"], ["1973.12000000", "9.00740000"], ["1973.13000000", "0.16370000"], ["1973.14000000", "0.00390000"], ["1973.15000000", "0.00260000"], ["1973.16000000", "0.00000000"], ["1973.17000000", "9.92820000"], ["1973.19000000", "13.52130000"], ["1973.20000000", "1.40570000"], ["1973.29000000", "9.64600000"], ["1973.32000000", "8.98570000"], ["1973.37000000", "3.84890000"], ["1973.39000000", "13.52130000"], ["1973.40000000", "7.61710000"], ["1973.41000000", "0.00000000"], ["1973.49000000", "1.50790000"], ["1973.50000000", "1.59610000"], ["1973.51000000", "3.60010000"], ["1973.69000000", "22.57370000"], ["1973.70000000", "0.00310000"], ["1973.71000000", "4.39070000"], ["1973.72000000", "0.00000000"], ["1973.73000000", "0.00300000"], ["1973.78000000", "0.00000000"], ["1973.85000000", "22.85130000"], ["1973.92000000", "0.03000000"], ["1973.95000000", "20.51540000"], ["1973.96000000", "14.17700000"], ["1973.99000000", "0.80000000"], ["1974.06000000", "4.92380000"], ["1974.16000000", "8.17450000"], ["1974.17000000", "7.73120000"], ["1974.20000000", "22.22080000"], ["1974.29000000", "7.09860000"], ["1974.30000000", "5.07860000"], ["1974.31000000", "8.51840000"], ["1974.32000000", "0.00260000"], ["1974.39000000", "8.31990000"], ["1974.42000000", "22.44360000"], ["1974.43000000", "10.70120000"], ["1974.48000000", "7.09860000"], ["1974.52000000", "2.55470000"], ["1974.61000000", "7.10160000"], ["1974.67000000", "0.00260000"], ["1974.69000000", "7.09860000"], ["1974.88000000", "0.03000000"], ["1974.89000000", "0.00000000"], ["1975.46000000", "14.15030000"], ["1975.79000000", "1.90850000"], ["1977.74000000", "0.13390000"], ["1979.60000000", "0.02570000"], ["1980.60000000", "126.38610000"], ["1981.09000000", "3.60000000"], ["1988.04000000", "0.02330000"]], "_local_ts_utc": "2026-06-01T07:49:09.213256+00:00"}
{"e": "depthUpdate", "E": 1780300150415, "s": "ETHUSDT", "U": 76583118940, "u": 76583119742, "b": [["1972.63000000", "65.26790000"], ["1972.62000000", "7.84990000"], ["1972.61000000", "5.13110000"], ["1972.60000000", "0.00260000"], ["1972.59000000", "0.00260000"], ["1972.58000000", "0.00260000"], ["1972.57000000", "0.00000000"], ["1972.56000000", "0.01300000"], ["1972.55000000", "6.47020000"], ["1972.54000000", "0.01020000"], ["1972.53000000", "0.00540000"], ["1972.52000000", "8.51840000"], ["1972.51000000", "0.31400000"], ["1972.50000000", "19.79790000"], ["1972.49000000", "22.57370000"], ["1972.48000000", "21.32840000"], ["1972.47000000", "7.53640000"], ["1972.46000000", "0.00260000"], ["1972.45000000", "0.00000000"], ["1972.44000000", "0.00000000"], ["1972.43000000", "0.00000000"], ["1972.42000000", "0.00000000"], ["1972.41000000", "13.81840000"], ["1972.40000000", "0.00570000"], ["1972.39000000", "17.57610000"], ["1972.38000000", "0.00000000"], ["1972.37000000", "21.29580000"], ["1972.35000000", "10.60000000"], ["1972.31000000", "8.51840000"], ["1972.30000000", "30.38120000"], ["1972.29000000", "22.57370000"], ["1972.28000000", "0.00000000"], ["1972.27000000", "21.29580000"], ["1972.23000000", "16.58330000"], ["1972.19000000", "8.48210000"], ["1972.11000000", "15.78750000"], ["1972.05000000", "0.05000000"], ["1972.01000000", "19.20990000"], ["1971.93000000", "26.77500000"], ["1971.90000000", "15.21310000"], ["1971.82000000", "10.10320000"], ["1971.80000000", "0.00570000"], ["1971.78000000", "2.58890000"], ["1971.77000000", "13.18800000"], ["1971.75000000", "8.34840000"], ["1971.65000000", "10.24030000"], ["1971.60000000", "11.66050000"], ["1971.53000000", "0.00300000"], ["1971.52000000", "7.12800000"], ["1971.50000000", "1.05300000"], ["1971.33000000", "3.14540000"], ["1971.20000000", "21.68980000"], ["1970.90000000", "0.00000000"], ["1970.85000000", "3.83310000"], ["1970.83000000", "0.23220000"], ["1970.81000000", "9.39250000"], ["1970.78000000", "12.20000000"], ["1970.75000000", "7.52090000"], ["1970.71000000", "32.06250000"], ["1970.70000000", "5.79210000"], ["1970.61000000", "0.00310000"], ["1970.58000000", "0.40720000"], ["1970.41000000", "1.02340000"], ["1970.40000000", "2.50630000"], ["1970.39000000", "0.00000000"], ["1970.38000000", "0.00320000"], ["1970.08000000", "1.01830000"], ["1969.88000000", "1.21570000"], ["1969.49000000", "1.17640000"], ["1969.48000000", "0.00000000"], ["1968.35000000", "65.99070000"], ["1968.00000000", "83.97510000"], ["1967.89000000", "0.50050000"], ["1967.51000000", "0.00000000"], ["1967.49000000", "22.57370000"], ["1967.48000000", "1.21070000"], ["1967.47000000", "0.05310000"], ["1967.25000000", "3.63760000"], ["1967.19000000", "0.00000000"], ["1966.90000000", "0.28350000"], ["1966.83000000", "0.00690000"], ["1964.68000000", "0.00000000"], ["1959.74000000", "0.24280000"], ["1945.02000000", "0.00000000"], ["1943.71000000", "0.01010000"], ["1943.35000000", "33.90500000"], ["1775.37000000", "0.00620000"], ["1775.35000000", "0.00000000"], ["1775.23000000", "0.00000000"]], "a": [["1972.48000000", "0.00000000"], ["1972.49000000", "0.00000000"], ["1972.50000000", "0.00000000"], ["1972.52000000", "0.00000000"], ["1972.53000000", "0.00000000"], ["1972.54000000", "0.00000000"], ["1972.55000000", "0.00000000"], ["1972.56000000", "0.00000000"], ["1972.59000000", "0.00000000"], ["1972.60000000", "0.00000000"], ["1972.62000000", "0.00000000"], ["1972.63000000", "0.00000000"], ["1972.64000000", "0.00930000"], ["1972.65000000", "0.04080000"], ["1972.66000000", "0.05520000"], ["1972.67000000", "0.10000000"], ["1972.69000000", "0.00260000"], ["1972.70000000", "0.00830000"], ["1972.71000000", "0.00260000"], ["1972.74000000", "0.00950000"], ["1972.75000000", "0.00260000"], ["1972.76000000", "0.00000000"], ["1972.78000000", "0.00260000"], ["1972.80000000", "0.04090000"], ["1972.81000000", "0.00000000"], ["1972.82000000", "0.00000000"], ["1972.83000000", "0.00000000"], ["1972.87000000", "0.03840000"], ["1972.88000000", "0.64610000"], ["1972.89000000", "1.70490000"], ["1972.90000000", "0.41570000"], ["1972.93000000", "1.49190000"], ["1972.94000000", "4.38090000"], ["1972.96000000", "0.09020000"], ["1973.01000000", "0.01160000"], ["1973.03000000", "0.11160000"], ["1973.06000000", "29.04130000"], ["1973.09000000", "3.31460000"], ["1973.10000000", "0.00570000"], ["1973.11000000", "6.72860000"], ["1973.19000000", "0.00000000"], ["1973.20000000", "0.00570000"], ["1973.22000000", "21.14970000"], ["1973.23000000", "28.63110000"], ["1973.28000000", "1.43000000"], ["1973.29000000", "7.10860000"], ["1973.37000000", "0.24890000"], ["1973.48000000", "2.54740000"], ["1973.49000000", "0.00000000"], ["1973.50000000", "1.59870000"], ["1973.54000000", "0.00390000"], ["1973.60000000", "18.57370000"], ["1973.85000000", "22.45130000"], ["1973.92000000", "0.43000000"], ["1974.67000000", "7.10120000"], ["1975.79000000", "15.42980000"], ["1976.32000000", "0.00000000"], ["1976.63000000", "0.79420000"], ["1976.78000000", "0.00000000"], ["1976.95000000", "3.60260000"], ["1977.30000000", "65.99340000"], ["1977.61000000", "0.00260000"], ["1977.79000000", "0.00260000"], ["1977.86000000", "31.64210000"]], "_local_ts_utc": "2026-06-01T07:49:09.312756+00:00"}
{"e": "depthUpdate", "E": 1780300150515, "s": "ETHUSDT", "U": 76583119743, "u": 76583119850, "b": [["1972.63000000", "50.77560000"], ["1972.62000000", "6.04990000"], ["1972.61000000", "5.13110000"], ["1972.60000000", "0.00520000"], ["1972.58000000", "0.00260000"], ["1972.56000000", "0.01560000"], ["1972.55000000", "6.47020000"], ["1972.54000000", "0.01280000"], ["1972.53000000", "0.00800000"], ["1972.51000000", "0.31410000"], ["1972.48000000", "21.32580000"], ["1972.47000000", "7.53380000"], ["1972.46000000", "0.00000000"], ["1972.42000000", "0.25370000"], ["1972.25000000", "0.00520000"], ["1972.24000000", "1.10840000"], ["1972.23000000", "15.25740000"], ["1972.12000000", "7.10140000"], ["1972.10000000", "0.15680000"], ["1971.96000000", "18.17610000"], ["1971.91000000", "7.09540000"], ["1971.86000000", "1.50690000"], ["1971.83000000", "0.28280000"], ["1971.75000000", "7.54840000"], ["1971.73000000", "0.00260000"], ["1971.70000000", "16.44610000"], ["1971.39000000", "9.07810000"], ["1971.38000000", "1.15460000"], ["1970.86000000", "22.57760000"], ["1970.05000000", "4.65030000"], ["1967.78000000", "0.00460000"], ["1967.06000000", "0.58150000"], ["1965.12000000", "0.01510000"], ["1960.45000000", "0.20350000"], ["1775.37000000", "0.01860000"]], "a": [["1972.64000000", "11.54170000"], ["1972.65000000", "0.04080000"], ["1972.66000000", "0.05520000"], ["1972.67000000", "0.00260000"], ["1972.74000000", "0.00560000"], ["1972.80000000", "0.01370000"], ["1972.81000000", "0.54510000"], ["1972.87000000", "0.03300000"], ["1972.88000000", "0.50990000"], ["1972.89000000", "1.71110000"], ["1972.90000000", "1.28420000"], ["1972.95000000", "0.01160000"], ["1973.03000000", "0.10000000"], ["1973.20000000", "13.52700000"], ["1973.22000000", "21.78780000"], ["1973.35000000", "0.59400000"], ["1973.78000000", "0.80000000"], ["1973.95000000", "23.40820000"], ["1973.99000000", "0.00000000"], ["1974.66000000", "0.74510000"], ["1975.36000000", "0.03000000"], ["1975.79000000", "1.90850000"], ["1977.90000000", "0.00260000"], ["1977.99000000", "2.53310000"], ["1990.03000000", "0.03610000"]], "_local_ts_utc": "2026-06-01T07:49:09.411430+00:00"}
{"e": "depthUpdate", "E": 1780300150615, "s": "ETHUSDT", "U": 76583119851, "u": 76583119872, "b": [["1972.47000000", "7.71020000"], ["1972.42000000", "0.00000000"], ["1972.41000000", "13.82140000"], ["1972.32000000", "0.28370000"], ["1972.29000000", "22.66490000"], ["1971.55000000", "7.60650000"], ["1969.37000000", "0.15200000"], ["1965.35000000", "0.01280000"], ["1961.17000000", "0.32210000"], ["1775.37000000", "0.03100000"]], "a": [["1972.64000000", "10.04450000"], ["1972.65000000", "0.03820000"], ["1972.83000000", "0.01160000"], ["1972.96000000", "0.09320000"], ["1973.67000000", "0.08670000"], ["1973.79000000", "0.03990000"], ["1983.31000000", "0.09640000"]], "_local_ts_utc": "2026-06-01T07:49:09.511422+00:00"}
{"e": "depthUpdate", "E": 1780300150715, "s": "ETHUSDT", "U": 76583119873, "u": 76583119908, "b": [["1972.51000000", "22.88780000"], ["1972.50000000", "13.16970000"], ["1972.49000000", "0.00000000"], ["1972.47000000", "7.53380000"], ["1972.42000000", "0.62650000"], ["1972.29000000", "22.66490000"], ["1971.82000000", "9.90320000"], ["1971.75000000", "7.14840000"], ["1971.53000000", "1.40300000"], ["1971.38000000", "0.35460000"], ["1971.24000000", "0.00000000"], ["1971.11000000", "7.69470000"], ["1969.54000000", "0.59900000"], ["1961.88000000", "3.74680000"], ["1923.31000000", "0.12970000"], ["1775.37000000", "0.04340000"]], "a": [["1972.64000000", "0.19900000"], ["1972.83000000", "0.00000000"], ["1972.87000000", "0.03840000"], ["1972.93000000", "3.23260000"], ["1972.95000000", "0.63540000"], ["1972.96000000", "6.56080000"], ["1973.06000000", "22.57370000"]], "_local_ts_utc": "2026-06-01T07:49:09.611373+00:00"}
{"e": "depthUpdate", "E": 1780300150815, "s": "ETHUSDT", "U": 76583119909, "u": 76583120265, "b": [["1972.73000000", "91.09370000"], ["1972.72000000", "0.00510000"], ["1972.71000000", "0.00510000"], ["1972.70000000", "3.14700000"], ["1972.69000000", "0.00800000"], ["1972.68000000", "9.97810000"], ["1972.67000000", "0.00540000"], ["1972.66000000", "0.00540000"], ["1972.65000000", "0.00000000"], ["1972.64000000", "0.00540000"], ["1972.63000000", "0.01120000"], ["1972.62000000", "0.00830000"], ["1972.61000000", "2.12600000"], ["1972.56000000", "0.00760000"], ["1972.55000000", "6.46760000"], ["1972.54000000", "0.01020000"], ["1972.53000000", "8.51840000"], ["1972.52000000", "7.09860000"], ["1972.51000000", "22.88510000"], ["1972.50000000", "6.57480000"], ["1972.48000000", "0.03000000"], ["1972.47000000", "23.04900000"], ["1972.46000000", "0.00390000"], ["1971.96000000", "18.42700000"], ["1971.90000000", "8.62160000"], ["1971.82000000", "10.50320000"], ["1971.70000000", "16.44350000"], ["1971.59000000", "3.04750000"], ["1971.53000000", "0.00300000"], ["1971.38000000", "1.15460000"], ["1971.09000000", "0.00300000"], ["1970.73000000", "0.02000000"], ["1969.74000000", "0.25680000"], ["1967.63000000", "0.00000000"], ["1967.61000000", "0.01890000"], ["1967.19000000", "0.00000000"], ["1962.96000000", "0.93700000"], ["1962.60000000", "0.25350000"], ["1961.07000000", "1.00900000"], ["1775.37000000", "0.00000000"]], "a": [["1972.64000000", "0.00000000"], ["1972.65000000", "0.00000000"], ["1972.66000000", "0.00000000"], ["1972.67000000", "0.00000000"], ["1972.69000000", "0.00000000"], ["1972.70000000", "0.00000000"], ["1972.71000000", "0.00000000"], ["1972.74000000", "9.96500000"], ["1972.75000000", "0.00780000"], ["1972.80000000", "0.01630000"], ["1972.81000000", "0.54770000"], ["1972.85000000", "0.00560000"], ["1972.86000000", "0.00540000"], ["1972.87000000", "0.04100000"], ["1972.88000000", "0.51530000"], ["1972.89000000", "1.70750000"], ["1972.90000000", "0.00570000"], ["1972.92000000", "0.00270000"], ["1972.95000000", "0.00260000"], ["1972.96000000", "0.09320000"], ["1973.05000000", "24.90710000"], ["1973.06000000", "0.00000000"], ["1973.07000000", "0.02300000"], ["1973.08000000", "0.05810000"], ["1973.12000000", "0.48900000"], ["1973.20000000", "0.00570000"], ["1973.23000000", "27.42560000"], ["1973.28000000", "0.03000000"], ["1973.29000000", "7.10860000"], ["1973.33000000", "8.49540000"], ["1973.61000000", "14.98380000"], ["1973.63000000", "0.81260000"], ["1973.70000000", "0.00570000"], ["1973.78000000", "0.00000000"], ["1973.79000000", "0.00000000"], ["1973.94000000", "0.81660000"], ["1974.47000000", "8.53840000"], ["1974.83000000", "8.12340000"], ["1974.89000000", "14.19720000"], ["1975.71000000", "0.00000000"], ["1975.79000000", "15.42980000"], ["1975.87000000", "0.02000000"], ["1976.18000000", "10.58360000"], ["1976.43000000", "0.80430000"], ["1980.59000000", "0.15110000"], ["1981.90000000", "1.47800000"], ["1988.20000000", "0.25090000"], ["2472.69000000", "0.01200000"]], "_local_ts_utc": "2026-06-01T07:49:09.712754+00:00"}
{"e": "depthUpdate", "E": 1780300150915, "s": "ETHUSDT", "U": 76583120266, "u": 76583120432, "b": [["1972.73000000", "78.89050000"], ["1972.72000000", "1.60620000"], ["1972.71000000", "0.01310000"], ["1972.70000000", "9.61460000"], ["1972.69000000", "0.00260000"], ["1972.68000000", "0.02260000"], ["1972.67000000", "0.00260000"], ["1972.66000000", "0.00260000"], ["1972.64000000", "0.03000000"], ["1972.63000000", "0.18490000"], ["1972.62000000", "0.01110000"], ["1972.61000000", "2.12340000"], ["1972.60000000", "0.10400000"], ["1972.59000000", "0.00000000"], ["1972.58000000", "0.00540000"], ["1972.57000000", "14.19720000"], ["1972.56000000", "14.38090000"], ["1972.55000000", "0.00000000"], ["1972.54000000", "13.53150000"], ["1972.53000000", "9.15590000"], ["1972.51000000", "0.31140000"], ["1972.50000000", "16.63030000"], ["1972.49000000", "22.57370000"], ["1972.43000000", "0.03300000"], ["1972.30000000", "30.38420000"], ["1972.05000000", "6.64150000"], ["1972.03000000", "0.10140000"], ["1971.90000000", "8.52020000"], ["1971.68000000", "22.64720000"], ["1971.20000000", "18.88330000"], ["1971.10000000", "0.00000000"], ["1970.87000000", "8.84970000"], ["1970.81000000", "2.29710000"], ["1970.75000000", "0.42550000"], ["1970.24000000", "23.52480000"], ["1968.53000000", "0.00000000"], ["1966.94000000", "0.02700000"], ["1963.31000000", "0.20320000"], ["1933.11000000", "0.12900000"], ["1913.19000000", "0.13040000"], ["1775.46000000", "0.01870000"]], "a": [["1972.74000000", "2.76660000"], ["1972.75000000", "0.00260000"], ["1972.80000000", "0.01090000"], ["1972.81000000", "0.00260000"], ["1972.86000000", "0.00260000"], ["1972.89000000", "1.70210000"], ["1972.92000000", "0.00000000"], ["1972.93000000", "0.00000000"], ["1972.94000000", "0.00390000"], ["1972.97000000", "0.00000000"], ["1972.98000000", "0.66000000"], ["1973.04000000", "1.01790000"], ["1973.05000000", "6.46760000"], ["1973.10000000", "0.00570000"], ["1973.11000000", "2.99750000"], ["1973.12000000", "0.03000000"], ["1973.14000000", "0.51080000"], ["1973.29000000", "11.47760000"], ["1973.38000000", "13.52130000"], ["1973.39000000", "0.00000000"], ["1973.41000000", "0.00000000"], ["1973.51000000", "7.11940000"], ["1973.58000000", "0.00280000"], ["1973.59000000", "13.52390000"], ["1973.62000000", "0.01320000"], ["1973.79000000", "0.80000000"], ["1973.94000000", "0.01660000"], ["1974.01000000", "0.01020000"], ["1974.67000000", "12.10120000"], ["1974.85000000", "7.10120000"], ["1974.89000000", "7.09860000"], ["1975.67000000", "0.00000000"], ["1976.12000000", "0.00000000"], ["1976.26000000", "0.00000000"], ["1976.63000000", "0.00000000"], ["1977.33000000", "0.01930000"], ["1977.92000000", "0.02320000"], ["1978.00000000", "0.01240000"], ["1978.09000000", "3.70760000"], ["1997.17000000", "0.00000000"]], "_local_ts_utc": "2026-06-01T07:49:09.811580+00:00"}
{"e": "depthUpdate", "E": 1780300151015, "s": "ETHUSDT", "U": 76583120433, "u": 76583120478, "b": [["1972.72000000", "3.41530000"], ["1972.59000000", "0.00540000"], ["1972.58000000", "17.51460000"], ["1972.57000000", "14.19720000"], ["1972.56000000", "0.00760000"], ["1972.34000000", "0.00000000"], ["1972.25000000", "0.27520000"], ["1971.82000000", "10.90380000"], ["1971.65000000", "10.84130000"], ["1971.53000000", "0.00300000"], ["1970.04000000", "0.27260000"], ["1968.93000000", "22.57630000"], ["1968.71000000", "0.00970000"], ["1964.02000000", "0.20310000"], ["1775.46000000", "0.03110000"]], "a": [["1972.74000000", "0.75010000"], ["1972.95000000", "0.01420000"], ["1972.97000000", "0.00540000"], ["1973.04000000", "1.02050000"], ["1973.05000000", "0.00000000"], ["1973.11000000", "4.72460000"], ["1973.19000000", "6.46760000"], ["1973.67000000", "0.00000000"], ["1973.77000000", "7.10300000"], ["1973.79000000", "0.00000000"], ["1973.92000000", "0.03000000"], ["1973.99000000", "0.40000000"], ["1974.01000000", "0.81020000"], ["1974.07000000", "16.51650000"], ["1974.17000000", "7.94610000"], ["1994.85000000", "0.13620000"], ["2472.69000000", "0.00000000"]], "_local_ts_utc": "2026-06-01T07:49:09.911741+00:00"}
{"e": "depthUpdate", "E": 1780300151117, "s": "ETHUSDT", "U": 76583120479, "u": 76583120514, "b": [["1972.73000000", "89.60900000"], ["1972.71000000", "0.01570000"], ["1972.63000000", "0.00850000"], ["1972.59000000", "0.00000000"], ["1972.53000000", "9.66290000"], ["1972.47000000", "21.73100000"], ["1972.40000000", "12.29610000"], ["1972.27000000", "21.30530000"], ["1972.26000000", "0.02810000"], ["1972.18000000", "0.27000000"], ["1972.16000000", "0.31280000"], ["1971.05000000", "4.40130000"], ["1970.10000000", "0.35750000"], ["1970.08000000", "1.28830000"], ["1970.04000000", "0.00260000"], ["1968.95000000", "0.01280000"], ["1968.67000000", "0.50260000"], ["1967.64000000", "0.25310000"], ["1964.74000000", "0.20570000"], ["1945.57000000", "1.49130000"], ["1775.46000000", "0.04350000"]], "a": [["1972.74000000", "0.75010000"], ["1972.87000000", "0.03560000"], ["1972.88000000", "0.00800000"], ["1972.92000000", "1.32370000"], ["1973.22000000", "21.88920000"], ["1973.38000000", "14.30430000"], ["1973.40000000", "8.42710000"], ["1974.01000000", "0.01020000"], ["1974.08000000", "0.83000000"], ["1977.94000000", "0.00260000"], ["1978.00000000", "0.00980000"]], "_local_ts_utc": "2026-06-01T07:49:10.012439+00:00"}
{"e": "depthUpdate", "E": 1780300151215, "s": "ETHUSDT", "U": 76583120515, "u": 76583120946, "b": [["1972.80000000", "42.96860000"], ["1972.79000000", "0.00510000"], ["1972.78000000", "0.01050000"], ["1972.77000000", "3.00000000"], ["1972.76000000", "0.00000000"], ["1972.75000000", "0.00000000"], ["1972.74000000", "0.02800000"], ["1972.73000000", "1.00520000"], ["1972.72000000", "0.00260000"], ["1972.71000000", "0.00520000"], ["1972.70000000", "0.00520000"], ["1972.68000000", "0.00260000"], ["1972.64000000", "0.03000000"], ["1972.63000000", "0.00590000"], ["1972.62000000", "0.01110000"], ["1972.60000000", "0.10940000"], ["1972.59000000", "10.21170000"], ["1972.58000000", "0.00260000"], ["1972.57000000", "0.00270000"], ["1972.56000000", "6.47520000"], ["1972.54000000", "0.01020000"], ["1972.53000000", "1.14450000"], ["1972.52000000", "0.00300000"], ["1972.51000000", "0.31140000"], ["1972.48000000", "14.22340000"], ["1972.47000000", "7.53380000"], ["1972.40000000", "0.00570000"], ["1972.32000000", "12.57500000"], ["1972.31000000", "22.03860000"], ["1972.30000000", "16.86290000"], ["1972.29000000", "22.71540000"], ["1972.20000000", "7.55560000"], ["1972.19000000", "5.37820000"], ["1971.85000000", "7.11730000"], ["1971.82000000", "7.76600000"], ["1971.80000000", "0.00310000"], ["1971.63000000", "0.01110000"], ["1971.61000000", "0.13040000"], ["1971.53000000", "0.60300000"], ["1971.52000000", "7.12800000"], ["1971.43000000", "0.00000000"], ["1971.38000000", "1.15460000"], ["1971.34000000", "7.19930000"], ["1971.32000000", "0.29020000"], ["1971.24000000", "0.00000000"], ["1970.81000000", "9.39380000"], ["1970.72000000", "7.78950000"], ["1969.74000000", "13.77440000"], ["1967.55000000", "0.00000000"], ["1967.12000000", "0.00000000"], ["1967.03000000", "0.50180000"], ["1965.45000000", "3.89940000"], ["1775.52000000", "0.41240000"], ["1775.46000000", "0.00630000"]], "a": [["1972.74000000", "0.00000000"], ["1972.75000000", "0.00000000"], ["1972.78000000", "0.00000000"], ["1972.80000000", "0.00000000"], ["1972.81000000", "23.35410000"], ["1972.82000000", "0.00000000"], ["1972.87000000", "0.04100000"], ["1972.88000000", "0.53020000"], ["1972.90000000", "0.01370000"], ["1972.91000000", "0.62710000"], ["1972.92000000", "1.32630000"], ["1972.94000000", "0.00650000"], ["1972.95000000", "0.00520000"], ["1972.97000000", "0.00000000"], ["1972.98000000", "0.64580000"], ["1973.01000000", "0.00000000"], ["1973.03000000", "0.10000000"], ["1973.04000000", "9.17640000"], ["1973.06000000", "6.46760000"], ["1973.08000000", "14.25150000"], ["1973.10000000", "7.10240000"], ["1973.11000000", "0.57700000"], ["1973.14000000", "0.52240000"], ["1973.17000000", "1.20550000"], ["1973.19000000", "0.00000000"], ["1973.33000000", "7.69540000"], ["1973.48000000", "3.34740000"], ["1973.50000000", "11.52320000"], ["1973.59000000", "13.53400000"], ["1973.60000000", "18.66490000"], ["1973.61000000", "14.20080000"], ["1973.63000000", "1.40260000"], ["1973.79000000", "0.00000000"], ["1973.85000000", "22.25130000"], ["1973.86000000", "0.00000000"], ["1973.94000000", "0.00650000"], ["1973.99000000", "0.00000000"], ["1974.00000000", "22.62950000"], ["1974.08000000", "0.03000000"], ["1974.83000000", "0.00300000"], ["1974.85000000", "0.00260000"], ["1974.89000000", "0.00000000"], ["1976.18000000", "10.58620000"], ["1977.49000000", "0.03300000"], ["1977.51000000", "0.00000000"], ["1977.94000000", "0.00000000"], ["1977.98000000", "0.00260000"], ["1981.90000000", "1.00000000"], ["1982.63000000", "0.00850000"]], "_local_ts_utc": "2026-06-01T07:49:10.111240+00:00"}
