{"e": "depthUpdate", "E": 1780300128995, "s": "SOLUSDT", "U": 29045626641, "u": 29045626826, "b": [["80.76000000", "1283.43400000"], ["80.75000000", "627.30500000"], ["80.74000000", "429.48900000"], ["80.73000000", "387.36700000"], ["80.72000000", "516.03900000"], ["80.71000000", "704.94900000"], ["80.70000000", "1989.08500000"], ["80.69000000", "683.04700000"], ["80.64000000", "1490.15800000"], ["80.63000000", "1263.31600000"], ["80.62000000", "99.05800000"], ["80.58000000", "613.22900000"], ["80.57000000", "760.80400000"], ["80.54000000", "62.86200000"], ["80.09000000", "38.82900000"], ["80.00000000", "23863.86000000"], ["79.64000000", "11.38300000"], ["79.56000000", "500.85900000"]], "a": [["80.76000000", "0.00000000"], ["80.77000000", "334.35600000"], ["80.78000000", "459.59700000"], ["80.79000000", "409.06700000"], ["80.80000000", "439.15700000"], ["80.81000000", "1028.33000000"], ["80.82000000", "376.36700000"], ["80.83000000", "324.90900000"], ["80.84000000", "310.18100000"], ["80.85000000", "684.45700000"], ["80.86000000", "578.15300000"], ["80.87000000", "2424.33700000"], ["80.88000000", "1195.03700000"], ["80.94000000", "106.30900000"], ["80.95000000", "479.49700000"], ["80.96000000", "346.52100000"], ["81.52000000", "45.34200000"]], "_local_ts_utc": "2026-06-01T07:48:47.892032+00:00"}
{"e": "depthUpdate", "E": 1780300129095, "s": "SOLUSDT", "U": 29045626827, "u": 29045626859, "b": [["80.76000000", "1345.16700000"], ["80.75000000", "659.84700000"], ["80.74000000", "383.64400000"], ["80.73000000", "194.18900000"], ["79.14000000", "21.21600000"]], "a": [["80.77000000", "326.83900000"], ["80.78000000", "454.03300000"], ["80.84000000", "310.18100000"], ["80.88000000", "1194.96900000"], ["80.89000000", "920.26800000"], ["81.10000000", "85.69700000"], ["81.34000000", "4.08100000"], ["81.56000000", "3.53700000"]], "_local_ts_utc": "2026-06-01T07:48:47.992030+00:00"}
{"e": "depthUpdate", "E": 1780300129195, "s": "SOLUSDT", "U": 29045626860, "u": 29045626879, "b": [["80.76000000", "1243.35300000"], ["80.75000000", "702.56300000"], ["80.74000000", "383.70700000"]], "a": [["80.77000000", "327.87000000"], ["80.78000000", "454.03300000"], ["80.79000000", "412.60600000"], ["80.80000000", "438.12600000"], ["80.82000000", "515.97700000"], ["80.89000000", "920.33600000"], ["81.11000000", "3086.03800000"], ["81.35000000", "51.23500000"], ["81.57000000", "6.81700000"]], "_local_ts_utc": "2026-06-01T07:48:48.092020+00:00"}
{"e": "depthUpdate", "E": 1780300129295, "s": "SOLUSDT", "U": 29045626880, "u": 29045626888, "b": [["80.76000000", "1091.00600000"], ["80.75000000", "702.56300000"], ["80.74000000", "384.40000000"]], "a": [["80.77000000", "327.62300000"], ["80.79000000", "415.72900000"], ["80.80000000", "435.05100000"]], "_local_ts_utc": "2026-06-01T07:48:48.192030+00:00"}
{"e": "depthUpdate", "E": 1780300129395, "s": "SOLUSDT", "U": 29045626889, "u": 29045626994, "b": [["80.76000000", "16.28500000"], ["80.75000000", "205.85100000"], ["80.74000000", "402.68200000"], ["80.73000000", "76.34300000"], ["80.72000000", "123.05800000"], ["80.71000000", "708.57400000"], ["80.70000000", "1992.71000000"], ["80.69000000", "548.12000000"], ["80.68000000", "386.89200000"], ["80.67000000", "542.10400000"], ["80.40000000", "542.41100000"]], "a": [["80.77000000", "647.24300000"], ["80.78000000", "383.20600000"], ["80.79000000", "409.47400000"], ["80.82000000", "512.17300000"], ["81.00000000", "918.67300000"], ["81.02000000", "274.20900000"]], "_local_ts_utc": "2026-06-01T07:48:48.292063+00:00"}
{"e": "depthUpdate", "E": 1780300129495, "s": "SOLUSDT", "U": 29045626995, "u": 29045627308, "b": [["80.76000000", "0.00000000"], ["80.75000000", "0.00000000"], ["80.74000000", "328.37700000"], ["80.73000000", "118.82400000"], ["80.72000000", "268.77300000"], ["80.71000000", "727.39700000"], ["80.70000000", "1868.70800000"], ["80.69000000", "685.88900000"], ["80.68000000", "386.28800000"], ["80.67000000", "542.74000000"], ["80.66000000", "1119.35600000"], ["80.65000000", "1904.60700000"], ["80.64000000", "1490.40800000"], ["80.63000000", "1265.26300000"], ["80.62000000", "139.55800000"], ["80.58000000", "645.49000000"], ["80.57000000", "885.06100000"], ["80.51000000", "55.71700000"], ["80.49000000", "72.62000000"], ["80.46000000", "89.43800000"], ["80.00000000", "23863.92300000"], ["79.99000000", "64.11600000"], ["79.13000000", "25.46000000"], ["79.12000000", "5.36600000"]], "a": [["80.75000000", "975.40200000"], ["80.76000000", "608.73300000"], ["80.77000000", "487.20200000"], ["80.78000000", "379.87600000"], ["80.79000000", "408.84100000"], ["80.80000000", "428.22400000"], ["80.81000000", "1021.45900000"], ["80.82000000", "512.03700000"], ["80.83000000", "448.26700000"], ["80.87000000", "2324.89000000"], ["80.88000000", "1094.88700000"], ["80.94000000", "106.24700000"], ["80.95000000", "479.43500000"], ["80.96000000", "222.83700000"], ["81.16000000", "80.55300000"], ["81.23000000", "41.58500000"], ["81.51000000", "215.92200000"], ["81.52000000", "5.78600000"]], "_local_ts_utc": "2026-06-01T07:48:48.392779+00:00"}
{"e": "depthUpdate", "E": 1780300129595, "s": "SOLUSDT", "U": 29045627309, "u": 29045627451, "b": [["80.74000000", "476.75900000"], ["80.73000000", "426.60800000"], ["80.72000000", "672.45100000"], ["80.71000000", "713.39700000"], ["80.69000000", "682.26400000"], ["80.67000000", "542.60400000"], ["80.66000000", "1131.56000000"], ["80.60000000", "2950.56000000"], ["80.58000000", "645.49000000"], ["80.57000000", "885.49500000"]], "a": [["80.75000000", "131.94900000"], ["80.76000000", "467.60000000"], ["80.77000000", "465.82300000"], ["80.78000000", "379.79600000"], ["80.80000000", "431.99900000"], ["80.82000000", "372.56300000"], ["80.83000000", "448.64800000"], ["80.89000000", "920.26800000"], ["80.90000000", "313.30200000"], ["80.94000000", "105.81300000"], ["81.11000000", "3085.95900000"], ["81.35000000", "51.14500000"], ["81.57000000", "6.44000000"]], "_local_ts_utc": "2026-06-01T07:48:48.492044+00:00"}
{"e": "depthUpdate", "E": 1780300129695, "s": "SOLUSDT", "U": 29045627452, "u": 29045627524, "b": [["80.74000000", "418.64300000"], ["80.73000000", "201.39900000"], ["80.72000000", "330.49200000"], ["80.67000000", "542.74000000"], ["80.66000000", "1119.35600000"]], "a": [["80.75000000", "292.13600000"], ["80.76000000", "548.05700000"], ["80.77000000", "453.70200000"], ["80.79000000", "405.30200000"], ["80.82000000", "372.42700000"], ["80.87000000", "2324.95800000"], ["81.09000000", "1061.89700000"], ["81.33000000", "48.55900000"], ["81.55000000", "7.28200000"]], "_local_ts_utc": "2026-06-01T07:48:48.592027+00:00"}
{"e": "depthUpdate", "E": 1780300129795, "s": "SOLUSDT", "U": 29045627525, "u": 29045627546, "b": [["80.74000000", "328.49300000"], ["80.73000000", "259.85200000"], ["80.72000000", "688.45100000"], ["80.69000000", "685.88900000"]], "a": [["80.75000000", "246.05200000"], ["80.76000000", "501.18100000"], ["80.78000000", "412.74200000"], ["80.80000000", "428.22400000"], ["80.83000000", "448.26700000"], ["88.82000000", "35.37300000"]], "_local_ts_utc": "2026-06-01T07:48:48.692081+00:00"}
{"e": "depthUpdate", "E": 1780300129895, "s": "SOLUSDT", "U": 29045627547, "u": 29045627556, "b": [["80.73000000", "376.33300000"], ["80.71000000", "787.75100000"], ["80.53000000", "27.08600000"], ["80.48000000", "424.74600000"]], "a": [["80.75000000", "247.08300000"], ["80.76000000", "501.18100000"], ["80.77000000", "453.70200000"], ["80.78000000", "411.71100000"], ["80.79000000", "439.84800000"], ["80.80000000", "564.61000000"], ["88.82000000", "35.31100000"]], "_local_ts_utc": "2026-06-01T07:48:48.792010+00:00"}
{"e": "depthUpdate", "E": 1780300129995, "s": "SOLUSDT", "U": 29045627557, "u": 29045627584, "b": [["80.74000000", "418.77900000"], ["80.73000000", "318.75700000"], ["80.72000000", "705.69700000"], ["80.71000000", "800.15100000"], ["80.69000000", "682.26400000"], ["80.67000000", "542.60400000"]], "a": [["80.75000000", "232.54500000"], ["80.76000000", "498.56000000"], ["80.86000000", "749.56000000"], ["80.87000000", "2153.79900000"]], "_local_ts_utc": "2026-06-01T07:48:48.892009+00:00"}
{"e": "depthUpdate", "E": 1780300130095, "s": "SOLUSDT", "U": 29045627585, "u": 29045627613, "b": [["80.74000000", "459.11800000"], ["80.73000000", "329.29600000"]], "a": [["80.75000000", "70.53600000"], ["80.76000000", "496.07800000"], ["80.77000000", "455.34800000"], ["80.78000000", "378.76500000"], ["80.80000000", "568.38500000"], ["80.82000000", "372.42700000"], ["80.83000000", "448.65100000"], ["80.85000000", "732.20400000"], ["80.87000000", "2324.95800000"], ["80.89000000", "748.61300000"]], "_local_ts_utc": "2026-06-01T07:48:48.992009+00:00"}
{"e": "depthUpdate", "E": 1780300130195, "s": "SOLUSDT", "U": 29045627614, "u": 29045627617, "b": [["80.15000000", "57.93300000"], ["79.66000000", "13.92800000"], ["79.17000000", "3.57700000"], ["78.69000000", "239.03300000"], ["78.20000000", "490.36000000"], ["77.71000000", "1.74800000"], ["77.23000000", "34.31600000"], ["76.74000000", "66.68000000"], ["76.25000000", "23.54000000"], ["75.77000000", "10.06400000"]], "a": [["80.76000000", "496.14100000"], ["80.77000000", "458.39700000"]], "_local_ts_utc": "2026-06-01T07:48:49.092038+00:00"}
{"e": "depthUpdate", "E": 1780300130296, "s": "SOLUSDT", "U": 29045627618, "u": 29045627620, "b": [["80.73000000", "331.29600000"], ["80.72000000", "703.69700000"]], "a": [["80.76000000", "455.64100000"]], "_local_ts_utc": "2026-06-01T07:48:49.192775+00:00"}
{"e": "depthUpdate", "E": 1780300130395, "s": "SOLUSDT", "U": 29045627621, "u": 29045627638, "b": [["80.74000000", "522.68000000"], ["80.73000000", "268.88900000"], ["80.71000000", "787.75100000"], ["80.66000000", "1120.80300000"], ["80.63000000", "1263.31600000"], ["52.49000000", "0.62600000"]], "a": [["80.75000000", "70.40000000"], ["80.82000000", "372.56300000"]], "_local_ts_utc": "2026-06-01T07:48:49.292360+00:00"}
{"e": "depthUpdate", "E": 1780300130495, "s": "SOLUSDT", "U": 29045627639, "u": 29045627675, "b": [["80.74000000", "522.36800000"], ["80.73000000", "259.65500000"], ["80.72000000", "704.09700000"], ["80.69000000", "548.12000000"], ["80.65000000", "1904.90700000"], ["80.59000000", "362.66400000"], ["80.41000000", "45.15400000"]], "a": [["80.75000000", "319.55600000"], ["80.76000000", "461.22200000"], ["80.77000000", "457.28300000"], ["80.78000000", "378.70300000"], ["80.79000000", "439.44800000"], ["80.82000000", "372.42700000"], ["80.88000000", "923.72800000"], ["80.89000000", "405.30300000"], ["80.90000000", "141.02800000"], ["81.00000000", "918.61100000"], ["81.03000000", "590.02300000"]], "_local_ts_utc": "2026-06-01T07:48:49.391514+00:00"}
{"e": "depthUpdate", "E": 1780300130595, "s": "SOLUSDT", "U": 29045627676, "u": 29045627695, "b": [["80.73000000", "322.84100000"], ["80.72000000", "704.22100000"], ["80.69000000", "688.81300000"], ["79.72000000", "37.89900000"]], "a": [["80.75000000", "317.35900000"], ["80.79000000", "404.90200000"], ["80.80000000", "431.99900000"], ["80.85000000", "777.26500000"], ["80.86000000", "1434.94000000"]], "_local_ts_utc": "2026-06-01T07:48:49.492007+00:00"}
{"e": "depthUpdate", "E": 1780300130695, "s": "SOLUSDT", "U": 29045627696, "u": 29045627724, "b": [["80.73000000", "332.54400000"], ["80.72000000", "704.22100000"], ["80.70000000", "1868.70800000"], ["80.69000000", "688.81300000"], ["80.39000000", "1379.57300000"]], "a": [["80.75000000", "68.01700000"], ["80.76000000", "455.70300000"], ["80.77000000", "458.77000000"], ["80.78000000", "378.70300000"], ["80.79000000", "404.90200000"], ["80.80000000", "431.99900000"], ["80.82000000", "372.56300000"], ["80.85000000", "924.92500000"], ["80.87000000", "2182.73700000"], ["80.88000000", "751.94900000"]], "_local_ts_utc": "2026-06-01T07:48:49.592007+00:00"}
{"e": "depthUpdate", "E": 1780300130795, "s": "SOLUSDT", "U": 29045627725, "u": 29045627733, "b": [], "a": [["80.75000000", "66.96700000"], ["80.83000000", "448.72000000"], ["80.87000000", "2182.73700000"], ["81.22000000", "125.85200000"]], "_local_ts_utc": "2026-06-01T07:48:49.692013+00:00"}
{"e": "depthUpdate", "E": 1780300130895, "s": "SOLUSDT", "U": 29045627734, "u": 29045627739, "b": [["79.54000000", "47.84700000"]], "a": [["80.75000000", "66.53400000"], ["80.80000000", "509.49600000"], ["80.81000000", "1161.53000000"], ["80.87000000", "2354.02000000"]], "_local_ts_utc": "2026-06-01T07:48:49.792007+00:00"}
{"e": "depthUpdate", "E": 1780300130995, "s": "SOLUSDT", "U": 29045627740, "u": 29045627746, "b": [["80.71000000", "800.15100000"], ["80.65000000", "1904.60700000"], ["80.51000000", "459.29700000"], ["80.48000000", "21.01500000"], ["80.11000000", "62.78600000"]], "a": [["80.75000000", "68.15500000"]], "_local_ts_utc": "2026-06-01T07:48:49.891995+00:00"}
{"e": "depthUpdate", "E": 1780300131095, "s": "SOLUSDT", "U": 29045627747, "u": 29045627749, "b": [["80.73000000", "269.48200000"]], "a": [["80.75000000", "66.87500000"], ["83.09000000", "22.78300000"]], "_local_ts_utc": "2026-06-01T07:48:49.992016+00:00"}
{"e": "depthUpdate", "E": 1780300131195, "s": "SOLUSDT", "U": 29045627750, "u": 29045627780, "b": [["80.73000000", "260.86600000"], ["80.72000000", "704.22100000"], ["80.71000000", "797.45400000"], ["80.70000000", "1868.70800000"], ["80.69000000", "688.81300000"], ["52.49000000", "0.74100000"]], "a": [["80.75000000", "381.32500000"], ["80.76000000", "462.18800000"], ["80.77000000", "457.28300000"], ["80.78000000", "378.70300000"], ["80.79000000", "437.84800000"], ["80.80000000", "509.49600000"], ["80.82000000", "372.56300000"], ["80.87000000", "2268.13300000"]], "_local_ts_utc": "2026-06-01T07:48:50.091067+00:00"}
{"e": "depthUpdate", "E": 1780300131295, "s": "SOLUSDT", "U": 29045627781, "u": 29045627783, "b": [["80.73000000", "271.76600000"], ["80.72000000", "704.94100000"]], "a": [["80.77000000", "432.51300000"]], "_local_ts_utc": "2026-06-01T07:48:50.192007+00:00"}
{"e": "depthUpdate", "E": 1780300131395, "s": "SOLUSDT", "U": 29045627784, "u": 29045627786, "b": [["76.71000000", "8.45700000"], ["70.82000000", "11.28000000"], ["52.49000000", "0.85600000"]], "a": [], "_local_ts_utc": "2026-06-01T07:48:50.292002+00:00"}
{"e": "depthUpdate", "E": 1780300131495, "s": "SOLUSDT", "U": 29045627787, "u": 29045627832, "b": [["80.74000000", "394.38000000"], ["80.73000000", "257.55500000"], ["80.72000000", "348.98200000"], ["80.70000000", "1869.00800000"], ["80.67000000", "542.74000000"], ["52.49000000", "0.97100000"]], "a": [["80.75000000", "439.33800000"], ["80.76000000", "462.55300000"], ["80.77000000", "432.38100000"], ["80.80000000", "505.72100000"], ["80.82000000", "372.42700000"]], "_local_ts_utc": "2026-06-01T07:48:50.392017+00:00"}
{"e": "depthUpdate", "E": 1780300131595, "s": "SOLUSDT", "U": 29045627833, "u": 29045627878, "b": [["80.74000000", "328.25000000"], ["80.73000000", "313.83000000"], ["80.72000000", "411.91600000"], ["80.71000000", "787.77600000"], ["80.69000000", "551.74500000"], ["80.66000000", "1119.35600000"], ["80.64000000", "1492.35500000"], ["80.36000000", "58.71100000"], ["80.34000000", "51.88500000"], ["79.96000000", "2.20500000"], ["79.94000000", "11.44200000"], ["52.49000000", "1.08600000"]], "a": [["80.75000000", "455.89600000"], ["80.76000000", "400.69700000"], ["80.79000000", "448.83000000"], ["80.83000000", "448.33600000"], ["80.88000000", "751.82100000"], ["81.14000000", "85.81900000"], ["81.16000000", "80.77000000"], ["81.55000000", "7.01400000"], ["81.56000000", "3.75400000"]], "_local_ts_utc": "2026-06-01T07:48:50.492011+00:00"}
{"e": "depthUpdate", "E": 1780300131695, "s": "SOLUSDT", "U": 29045627879, "u": 29045627895, "b": [["80.74000000", "390.25500000"], ["80.73000000", "253.31100000"], ["80.66000000", "1119.48400000"], ["79.77000000", "38.22800000"], ["70.82000000", "11.20000000"]], "a": [["80.75000000", "519.33900000"], ["80.76000000", "413.08000000"], ["80.82000000", "372.55500000"]], "_local_ts_utc": "2026-06-01T07:48:50.592011+00:00"}
{"e": "depthUpdate", "E": 1780300131795, "s": "SOLUSDT", "U": 29045627896, "u": 29045627900, "b": [["80.73000000", "340.66700000"], ["80.72000000", "706.81300000"], ["80.68000000", "524.96900000"]], "a": [["80.76000000", "476.14200000"]], "_local_ts_utc": "2026-06-01T07:48:50.691682+00:00"}
{"e": "depthUpdate", "E": 1780300131895, "s": "SOLUSDT", "U": 29045627901, "u": 29045627903, "b": [["80.69000000", "602.88500000"], ["80.51000000", "55.71700000"], ["80.48000000", "424.74600000"]], "a": [["80.76000000", "463.75900000"]], "_local_ts_utc": "2026-06-01T07:48:50.792005+00:00"}
{"e": "depthUpdate", "E": 1780300131995, "s": "SOLUSDT", "U": 29045627904, "u": 29045627904, "b": [["79.29000000", "4.93000000"]], "a": [], "_local_ts_utc": "2026-06-01T07:48:50.892001+00:00"}
{"e": "depthUpdate", "E": 1780300132095, "s": "SOLUSDT", "U": 29045627905, "u": 29045627915, "b": [["80.74000000", "328.25000000"], ["80.73000000", "312.79900000"], ["80.72000000", "348.85400000"], ["80.71000000", "800.17700000"], ["80.68000000", "386.28800000"]], "a": [["80.76000000", "467.07100000"], ["80.77000000", "444.76200000"]], "_local_ts_utc": "2026-06-01T07:48:50.992011+00:00"}
{"e": "depthUpdate", "E": 1780300132195, "s": "SOLUSDT", "U": 29045627916, "u": 29045627920, "b": [["80.74000000", "328.31400000"], ["80.69000000", "602.17800000"], ["80.68000000", "522.60100000"]], "a": [["80.87000000", "2211.94000000"]], "_local_ts_utc": "2026-06-01T07:48:51.091999+00:00"}
{"e": "depthUpdate", "E": 1780300132295, "s": "SOLUSDT", "U": 29045627921, "u": 29045627923, "b": [["80.74000000", "328.25000000"], ["80.68000000", "523.24400000"], ["78.80000000", "303.10100000"]], "a": [], "_local_ts_utc": "2026-06-01T07:48:51.192011+00:00"}
{"e": "depthUpdate", "E": 1780300132395, "s": "SOLUSDT", "U": 29045627924, "u": 29045627931, "b": [["80.74000000", "325.12700000"]], "a": [["80.75000000", "451.48100000"], ["80.79000000", "404.90200000"]], "_local_ts_utc": "2026-06-01T07:48:51.291833+00:00"}
{"e": "depthUpdate", "E": 1780300132495, "s": "SOLUSDT", "U": 29045627932, "u": 29045627934, "b": [], "a": [["80.75000000", "458.25600000"], ["80.76000000", "464.07100000"]], "_local_ts_utc": "2026-06-01T07:48:51.391501+00:00"}
{"e": "depthUpdate", "E": 1780300132595, "s": "SOLUSDT", "U": 29045627935, "u": 29045627942, "b": [["80.74000000", "387.06300000"], ["80.73000000", "252.56500000"], ["78.32000000", "6.41800000"]], "a": [["80.76000000", "461.38600000"]], "_local_ts_utc": "2026-06-01T07:48:51.491017+00:00"}
{"e": "depthUpdate", "E": 1780300132695, "s": "SOLUSDT", "U": 29045627943, "u": 29045627947, "b": [["80.74000000", "387.19900000"], ["80.72000000", "706.81300000"], ["80.67000000", "542.60400000"], ["79.95000000", "264.07600000"]], "a": [["80.82000000", "427.84700000"]], "_local_ts_utc": "2026-06-01T07:48:51.591559+00:00"}
{"e": "depthUpdate", "E": 1780300132795, "s": "SOLUSDT", "U": 29045627948, "u": 29045627951, "b": [["80.74000000", "387.13200000"], ["80.73000000", "321.09700000"], ["80.67000000", "542.74000000"]], "a": [], "_local_ts_utc": "2026-06-01T07:48:51.691999+00:00"}
{"e": "depthUpdate", "E": 1780300132895, "s": "SOLUSDT", "U": 29045627952, "u": 29045627953, "b": [["80.51000000", "459.29700000"], ["80.48000000", "21.01500000"], ["77.83000000", "7.17500000"]], "a": [], "_local_ts_utc": "2026-06-01T07:48:51.791873+00:00"}
{"e": "depthUpdate", "E": 1780300132995, "s": "SOLUSDT", "U": 29045627954, "u": 29045627961, "b": [["80.74000000", "390.73800000"], ["80.69000000", "598.55300000"], ["80.67000000", "542.60400000"]], "a": [["80.80000000", "518.12100000"], ["80.90000000", "140.54400000"], ["80.91000000", "92.68100000"]], "_local_ts_utc": "2026-06-01T07:48:51.892009+00:00"}
{"e": "depthUpdate", "E": 1780300133095, "s": "SOLUSDT", "U": 29045627962, "u": 29045627992, "b": [["80.74000000", "531.29300000"], ["80.73000000", "323.09700000"], ["80.72000000", "704.81300000"], ["80.00000000", "23864.42300000"]], "a": [["80.75000000", "137.95900000"], ["80.76000000", "463.38600000"], ["80.77000000", "444.89400000"], ["80.80000000", "509.49600000"], ["80.82000000", "427.98300000"], ["81.12000000", "1320.15300000"], ["81.21000000", "74.03000000"]], "_local_ts_utc": "2026-06-01T07:48:51.991829+00:00"}
{"e": "depthUpdate", "E": 1780300133195, "s": "SOLUSDT", "U": 29045627993, "u": 29045628043, "b": [["80.74000000", "768.38500000"], ["80.73000000", "340.38200000"], ["80.66000000", "1118.98400000"], ["80.39000000", "1383.82200000"], ["77.35000000", "30.93200000"]], "a": [["80.75000000", "165.47500000"], ["80.76000000", "434.18700000"], ["80.77000000", "444.89400000"], ["80.78000000", "380.96100000"], ["80.83000000", "448.72000000"]], "_local_ts_utc": "2026-06-01T07:48:52.092664+00:00"}
{"e": "depthUpdate", "E": 1780300133295, "s": "SOLUSDT", "U": 29045628044, "u": 29045628054, "b": [["80.74000000", "741.12900000"], ["80.73000000", "340.38200000"]], "a": [["80.75000000", "56.38600000"], ["80.77000000", "446.27600000"], ["80.78000000", "378.70300000"], ["80.83000000", "449.08100000"]], "_local_ts_utc": "2026-06-01T07:48:52.191994+00:00"}
{"e": "depthUpdate", "E": 1780300133395, "s": "SOLUSDT", "U": 29045628055, "u": 29045628089, "b": [["80.74000000", "607.63700000"], ["80.73000000", "331.47500000"], ["80.72000000", "706.81300000"], ["80.67000000", "542.74000000"], ["80.33000000", "321.24800000"]], "a": [["80.75000000", "354.34300000"], ["80.76000000", "437.80500000"], ["80.77000000", "444.76200000"], ["80.82000000", "427.84700000"], ["80.84000000", "311.91800000"], ["80.89000000", "403.56600000"]], "_local_ts_utc": "2026-06-01T07:48:52.292006+00:00"}
{"e": "depthUpdate", "E": 1780300133495, "s": "SOLUSDT", "U": 29045628090, "u": 29045628226, "b": [["80.74000000", "259.60600000"], ["80.73000000", "132.64400000"], ["80.72000000", "280.95100000"], ["80.71000000", "208.54200000"], ["80.70000000", "350.77800000"], ["80.69000000", "1003.82200000"], ["80.68000000", "1868.13900000"], ["80.67000000", "542.74000000"], ["80.66000000", "1119.48400000"], ["80.64000000", "1504.96600000"], ["80.63000000", "1263.56600000"], ["76.86000000", "7.88500000"]], "a": [["80.75000000", "439.60300000"], ["80.76000000", "370.94400000"], ["80.77000000", "563.23500000"], ["80.78000000", "736.66200000"], ["80.80000000", "505.72100000"], ["80.82000000", "559.61700000"], ["80.83000000", "448.69700000"], ["80.85000000", "793.20400000"], ["80.86000000", "1155.34000000"], ["80.94000000", "982.97900000"], ["81.00000000", "41.98700000"], ["81.16000000", "43.74800000"]], "_local_ts_utc": "2026-06-01T07:48:52.392402+00:00"}
{"e": "depthUpdate", "E": 1780300133595, "s": "SOLUSDT", "U": 29045628227, "u": 29045628246, "b": [["80.74000000", "169.07500000"], ["80.73000000", "200.32500000"], ["80.72000000", "343.77400000"]], "a": [["80.75000000", "502.92300000"], ["80.76000000", "372.54000000"]], "_local_ts_utc": "2026-06-01T07:48:52.491992+00:00"}
{"e": "depthUpdate", "E": 1780300133695, "s": "SOLUSDT", "U": 29045628247, "u": 29045628259, "b": [["80.74000000", "103.24900000"], ["80.73000000", "188.22200000"], ["80.72000000", "328.92100000"]], "a": [["80.75000000", "519.00700000"], ["80.77000000", "550.85400000"], ["80.78000000", "780.59100000"]], "_local_ts_utc": "2026-06-01T07:48:52.591008+00:00"}
{"e": "depthUpdate", "E": 1780300133795, "s": "SOLUSDT", "U": 29045628260, "u": 29045628271, "b": [["80.74000000", "103.45300000"], ["80.72000000", "367.31000000"], ["80.67000000", "676.73500000"], ["76.38000000", "436.12100000"]], "a": [["80.75000000", "505.77100000"], ["80.76000000", "384.92300000"], ["80.78000000", "790.40400000"], ["80.81000000", "1021.45900000"], ["80.82000000", "549.80700000"]], "_local_ts_utc": "2026-06-01T07:48:52.693267+00:00"}
{"e": "depthUpdate", "E": 1780300133895, "s": "SOLUSDT", "U": 29045628272, "u": 29045628284, "b": [["80.73000000", "143.46100000"], ["80.68000000", "1871.76400000"], ["80.66000000", "1119.62000000"], ["80.65000000", "1905.10700000"], ["80.59000000", "403.16400000"], ["80.57000000", "885.31700000"], ["80.53000000", "27.26400000"]], "a": [["80.76000000", "384.79100000"], ["80.99000000", "155.44100000"], ["81.04000000", "523.32400000"]], "_local_ts_utc": "2026-06-01T07:48:52.791992+00:00"}
{"e": "depthUpdate", "E": 1780300133995, "s": "SOLUSDT", "U": 29045628285, "u": 29045628290, "b": [["80.74000000", "103.70300000"], ["80.73000000", "143.59700000"], ["80.69000000", "1016.22200000"], ["80.67000000", "542.74000000"], ["80.66000000", "1119.48400000"], ["80.51000000", "55.71700000"], ["80.48000000", "424.74600000"]], "a": [], "_local_ts_utc": "2026-06-01T07:48:52.892001+00:00"}
{"e": "depthUpdate", "E": 1780300134095, "s": "SOLUSDT", "U": 29045628291, "u": 29045628326, "b": [["80.74000000", "232.55300000"], ["80.73000000", "86.08800000"], ["80.72000000", "366.96100000"], ["80.71000000", "206.54200000"], ["80.70000000", "350.47800000"], ["80.67000000", "681.27800000"]], "a": [["80.75000000", "396.24000000"], ["80.76000000", "380.57300000"], ["80.78000000", "746.47500000"], ["80.99000000", "155.51100000"], ["83.88000000", "119.56400000"]], "_local_ts_utc": "2026-06-01T07:48:52.992374+00:00"}
{"e": "depthUpdate", "E": 1780300134195, "s": "SOLUSDT", "U": 29045628327, "u": 29045628338, "b": [["80.74000000", "232.48100000"], ["80.73000000", "87.94800000"], ["80.68000000", "1868.13900000"], ["80.67000000", "681.41400000"], ["80.34000000", "52.69000000"], ["75.90000000", "98.24800000"]], "a": [["80.75000000", "398.24000000"], ["80.76000000", "380.78000000"]], "_local_ts_utc": "2026-06-01T07:48:53.091999+00:00"}
{"e": "depthUpdate", "E": 1780300134295, "s": "SOLUSDT", "U": 29045628339, "u": 29045628341, "b": [], "a": [["80.75000000", "461.23300000"], ["80.76000000", "380.98000000"]], "_local_ts_utc": "2026-06-01T07:48:53.191420+00:00"}
{"e": "depthUpdate", "E": 1780300134395, "s": "SOLUSDT", "U": 29045628342, "u": 29045628349, "b": [["80.72000000", "364.96100000"], ["80.71000000", "208.54200000"], ["80.70000000", "351.17700000"], ["80.39000000", "1384.02200000"], ["80.37000000", "37.00800000"]], "a": [["80.75000000", "485.81700000"], ["80.77000000", "551.05400000"]], "_local_ts_utc": "2026-06-01T07:48:53.291969+00:00"}
{"e": "depthUpdate", "E": 1780300134495, "s": "SOLUSDT", "U": 29045628350, "u": 29045628379, "b": [["80.74000000", "103.70300000"], ["80.73000000", "133.85300000"], ["80.72000000", "428.63300000"], ["80.69000000", "1003.82200000"], ["80.66000000", "1119.62000000"], ["80.36000000", "58.91100000"], ["75.41000000", "8.20900000"]], "a": [["80.75000000", "502.03800000"], ["80.76000000", "389.00300000"], ["80.78000000", "785.32400000"], ["80.79000000", "543.83000000"]], "_local_ts_utc": "2026-06-01T07:48:53.392005+00:00"}
{"e": "depthUpdate", "E": 1780300134595, "s": "SOLUSDT", "U": 29045628380, "u": 29045628398, "b": [["80.74000000", "169.13300000"], ["80.73000000", "196.00000000"], ["80.72000000", "367.45800000"], ["80.66000000", "1119.48400000"], ["80.65000000", "1905.40700000"]], "a": [["80.75000000", "501.64700000"], ["80.76000000", "384.11600000"]], "_local_ts_utc": "2026-06-01T07:48:53.491328+00:00"}
{"e": "depthUpdate", "E": 1780300134695, "s": "SOLUSDT", "U": 29045628399, "u": 29045628418, "b": [["80.74000000", "321.69400000"], ["80.73000000", "139.89000000"], ["80.72000000", "364.96100000"], ["80.67000000", "681.27800000"]], "a": [["80.75000000", "460.68300000"], ["80.76000000", "379.74600000"], ["80.77000000", "573.01800000"]], "_local_ts_utc": "2026-06-01T07:48:53.590994+00:00"}
{"e": "depthUpdate", "E": 1780300134795, "s": "SOLUSDT", "U": 29045628419, "u": 29045628426, "b": [["80.74000000", "322.73700000"], ["80.73000000", "138.61200000"], ["80.72000000", "366.96100000"], ["80.71000000", "206.54200000"], ["80.67000000", "681.41400000"], ["72.67000000", "9.06600000"]], "a": [["80.77000000", "551.05400000"]], "_local_ts_utc": "2026-06-01T07:48:53.691493+00:00"}
{"e": "depthUpdate", "E": 1780300134895, "s": "SOLUSDT", "U": 29045628427, "u": 29045628427, "b": [["72.67000000", "8.99000000"]], "a": [], "_local_ts_utc": "2026-06-01T07:48:53.792001+00:00"}
{"e": "depthUpdate", "E": 1780300135095, "s": "SOLUSDT", "U": 29045628428, "u": 29045628429, "b": [["80.70000000", "363.57800000"]], "a": [["80.79000000", "404.90200000"]], "_local_ts_utc": "2026-06-01T07:48:53.991984+00:00"}
{"e": "depthUpdate", "E": 1780300135195, "s": "SOLUSDT", "U": 29045628430, "u": 29045628434, "b": [["80.74000000", "321.49900000"], ["80.70000000", "363.70100000"]], "a": [["80.75000000", "459.31200000"], ["81.06000000", "56.52000000"], ["81.17000000", "5.93000000"]], "_local_ts_utc": "2026-06-01T07:48:54.090984+00:00"}
{"e": "depthUpdate", "E": 1780300135295, "s": "SOLUSDT", "U": 29045628435, "u": 29045628442, "b": [["80.74000000", "231.07900000"], ["80.73000000", "136.12400000"], ["80.68000000", "1925.65000000"]], "a": [["80.76000000", "381.90900000"], ["80.79000000", "405.27100000"]], "_local_ts_utc": "2026-06-01T07:48:54.191118+00:00"}
{"e": "depthUpdate", "E": 1780300135395, "s": "SOLUSDT", "U": 29045628443, "u": 29045628445, "b": [], "a": [["80.75000000", "484.46800000"], ["80.79000000", "543.49800000"]], "_local_ts_utc": "2026-06-01T07:48:54.291049+00:00"}
{"e": "depthUpdate", "E": 1780300135495, "s": "SOLUSDT", "U": 29045628446, "u": 29045628447, "b": [], "a": [["80.84000000", "262.92800000"], ["80.96000000", "160.42400000"]], "_local_ts_utc": "2026-06-01T07:48:54.391997+00:00"}
{"e": "depthUpdate", "E": 1780300135595, "s": "SOLUSDT", "U": 29045628448, "u": 29045628456, "b": [["80.73000000", "132.71100000"], ["80.72000000", "369.99700000"], ["80.70000000", "438.06400000"]], "a": [["80.75000000", "598.44700000"], ["80.76000000", "386.13500000"]], "_local_ts_utc": "2026-06-01T07:48:54.491994+00:00"}
{"e": "depthUpdate", "E": 1780300135695, "s": "SOLUSDT", "U": 29045628457, "u": 29045628460, "b": [["80.74000000", "231.07900000"]], "a": [["80.75000000", "573.15300000"]], "_local_ts_utc": "2026-06-01T07:48:54.591993+00:00"}
{"e": "depthUpdate", "E": 1780300135795, "s": "SOLUSDT", "U": 29045628461, "u": 29045628539, "b": [["80.74000000", "343.11700000"], ["80.73000000", "163.71000000"], ["80.72000000", "305.37800000"], ["80.71000000", "192.54200000"], ["80.70000000", "462.68500000"], ["80.69000000", "1000.19700000"], ["80.67000000", "681.27800000"], ["80.66000000", "1118.98400000"], ["80.65000000", "1904.90700000"], ["75.20000000", "184.07400000"]], "a": [["80.75000000", "374.36400000"], ["80.76000000", "441.62200000"], ["80.77000000", "492.46000000"], ["80.78000000", "427.36500000"], ["80.79000000", "453.81000000"], ["80.80000000", "509.71400000"], ["80.82000000", "418.17300000"], ["80.83000000", "449.08100000"], ["80.85000000", "924.94100000"], ["80.94000000", "983.42500000"], ["81.03000000", "608.56000000"], ["81.04000000", "522.87900000"], ["81.05000000", "82.88100000"]], "_local_ts_utc": "2026-06-01T07:48:54.691986+00:00"}
{"e": "depthUpdate", "E": 1780300135895, "s": "SOLUSDT", "U": 29045628540, "u": 29045628566, "b": [["80.74000000", "330.73100000"], ["80.73000000", "179.06500000"]], "a": [["80.75000000", "214.58900000"], ["80.76000000", "437.07700000"], ["80.77000000", "492.46000000"], ["80.78000000", "444.69000000"], ["80.82000000", "418.03700000"]], "_local_ts_utc": "2026-06-01T07:48:54.791993+00:00"}
{"e": "depthUpdate", "E": 1780300135995, "s": "SOLUSDT", "U": 29045628567, "u": 29045628591, "b": [["80.74000000", "259.82500000"], ["80.73000000", "110.64100000"], ["80.71000000", "192.54200000"], ["80.67000000", "681.41400000"]], "a": [["80.75000000", "323.06100000"], ["80.76000000", "441.66500000"], ["80.78000000", "785.32400000"], ["80.86000000", "1172.82000000"], ["80.91000000", "154.02300000"]], "_local_ts_utc": "2026-06-01T07:48:54.892489+00:00"}
{"e": "depthUpdate", "E": 1780300136095, "s": "SOLUSDT", "U": 29045628592, "u": 29045628623, "b": [["80.74000000", "235.36900000"], ["80.73000000", "111.88400000"], ["80.72000000", "303.37800000"], ["80.71000000", "194.54200000"], ["80.69000000", "1007.93700000"], ["80.67000000", "681.41400000"]], "a": [["80.75000000", "376.25000000"], ["80.76000000", "377.33200000"], ["80.77000000", "560.29200000"], ["80.80000000", "645.28900000"]], "_local_ts_utc": "2026-06-01T07:48:54.991980+00:00"}
{"e": "depthUpdate", "E": 1780300136195, "s": "SOLUSDT", "U": 29045628624, "u": 29045628670, "b": [["80.74000000", "169.07400000"], ["80.73000000", "166.81100000"], ["80.72000000", "289.37800000"], ["80.71000000", "236.48900000"], ["80.70000000", "425.66300000"], ["80.69000000", "1011.72700000"], ["80.66000000", "1119.48400000"], ["80.52000000", "122.85500000"], ["80.51000000", "459.29700000"], ["80.48000000", "21.01500000"]], "a": [["80.75000000", "449.67600000"], ["80.76000000", "370.00300000"], ["80.80000000", "641.29600000"], ["80.83000000", "448.69700000"], ["81.13000000", "292.19800000"]], "_local_ts_utc": "2026-06-01T07:48:55.092054+00:00"}
{"e": "depthUpdate", "E": 1780300136295, "s": "SOLUSDT", "U": 29045628671, "u": 29045628705, "b": [["80.73000000", "162.68600000"], ["80.72000000", "354.97600000"], ["80.71000000", "236.48900000"], ["80.68000000", "1929.44000000"], ["80.64000000", "1503.51900000"], ["80.62000000", "141.50500000"]], "a": [["80.75000000", "455.28600000"], ["80.76000000", "371.60100000"], ["80.79000000", "488.11400000"], ["80.82000000", "549.77400000"], ["80.85000000", "793.60500000"]], "_local_ts_utc": "2026-06-01T07:48:55.191026+00:00"}
{"e": "depthUpdate", "E": 1780300136395, "s": "SOLUSDT", "U": 29045628706, "u": 29045628714, "b": [["80.74000000", "103.64400000"], ["80.72000000", "354.12300000"], ["80.67000000", "542.74000000"], ["80.62000000", "139.55800000"], ["80.39000000", "2290.55600000"]], "a": [["80.76000000", "374.59200000"], ["81.05000000", "989.41500000"]], "_local_ts_utc": "2026-06-01T07:48:55.291978+00:00"}
{"e": "depthUpdate", "E": 1780300136495, "s": "SOLUSDT", "U": 29045628715, "u": 29045628718, "b": [["80.74000000", "169.00500000"], ["80.65000000", "1905.40700000"], ["80.64000000", "1503.01900000"]], "a": [], "_local_ts_utc": "2026-06-01T07:48:55.391977+00:00"}
{"e": "depthUpdate", "E": 1780300136595, "s": "SOLUSDT", "U": 29045628719, "u": 29045628944, "b": [["80.74000000", "0.00000000"], ["80.73000000", "259.96900000"], ["80.72000000", "159.41200000"], ["80.71000000", "416.42100000"], ["80.70000000", "235.89400000"], ["80.69000000", "559.71200000"], ["80.68000000", "447.58900000"], ["80.67000000", "554.32200000"], ["80.66000000", "1119.62000000"], ["80.65000000", "1631.63500000"], ["80.64000000", "512.10100000"], ["80.63000000", "1424.37000000"], ["80.62000000", "1165.22500000"], ["80.58000000", "613.22900000"], ["80.57000000", "689.44700000"], ["80.56000000", "1952.72300000"], ["80.52000000", "279.95300000"], ["80.45000000", "1005.51100000"], ["80.40000000", "1603.71800000"], ["80.38000000", "19.34400000"], ["80.35000000", "125.81700000"], ["80.14000000", "308.62900000"], ["79.98000000", "13.75500000"], ["79.86000000", "6.19800000"], ["79.11000000", "11.31500000"]], "a": [["80.74000000", "1077.15500000"], ["80.75000000", "372.67800000"], ["80.76000000", "357.66000000"], ["80.77000000", "473.47700000"], ["80.78000000", "789.24100000"], ["80.79000000", "484.21200000"], ["80.81000000", "925.57800000"], ["80.82000000", "549.39600000"], ["80.83000000", "290.09700000"], ["80.86000000", "1074.55700000"], ["80.93000000", "415.52000000"], ["80.94000000", "983.17500000"], ["80.95000000", "479.34200000"], ["80.96000000", "29.66300000"], ["81.04000000", "1226.22700000"], ["81.09000000", "0.59000000"], ["81.21000000", "73.96200000"], ["81.49000000", "45.82700000"], ["81.50000000", "24.75000000"], ["81.94000000", "521.64400000"], ["81.96000000", "3.24600000"], ["82.38000000", "5.56600000"]], "_local_ts_utc": "2026-06-01T07:48:55.491980+00:00"}
{"e": "depthUpdate", "E": 1780300136695, "s": "SOLUSDT", "U": 29045628945, "u": 29045628991, "b": [["80.73000000", "321.88800000"], ["80.72000000", "170.36500000"], ["80.71000000", "387.47400000"], ["80.70000000", "231.41900000"], ["80.68000000", "447.52700000"], ["80.66000000", "1119.62000000"], ["80.45000000", "1005.57400000"]], "a": [["80.74000000", "903.72700000"], ["80.75000000", "358.12400000"], ["80.77000000", "502.52100000"], ["80.78000000", "785.41700000"], ["80.79000000", "490.41300000"], ["80.82000000", "549.45800000"], ["80.86000000", "1082.86300000"], ["80.87000000", "2211.87200000"], ["80.89000000", "404.06500000"], ["80.90000000", "132.41200000"], ["80.91000000", "153.58900000"], ["81.02000000", "274.14700000"], ["81.03000000", "608.49800000"], ["81.09000000", "0.51100000"], ["81.13000000", "292.44800000"], ["81.16000000", "43.53100000"], ["81.33000000", "48.46900000"], ["81.53000000", "6.83200000"], ["81.54000000", "10.22400000"], ["81.55000000", "6.63700000"], ["81.56000000", "3.53700000"], ["95.06000000", "40.24100000"]], "_local_ts_utc": "2026-06-01T07:48:55.591645+00:00"}
{"e": "depthUpdate", "E": 1780300136795, "s": "SOLUSDT", "U": 29045628992, "u": 29045629017, "b": [["80.72000000", "170.36500000"], ["80.71000000", "387.47400000"], ["80.69000000", "559.71200000"], ["80.68000000", "447.52700000"], ["80.62000000", "1156.90900000"], ["80.58000000", "621.32200000"], ["64.00000000", "5694.32900000"]], "a": [["80.74000000", "793.16100000"], ["80.75000000", "358.12400000"], ["80.76000000", "370.04300000"], ["80.77000000", "501.55900000"], ["80.78000000", "785.41700000"], ["80.79000000", "456.10900000"], ["80.80000000", "505.65200000"], ["80.86000000", "1082.93100000"], ["81.08000000", "45.96500000"], ["81.32000000", "98.88400000"]], "_local_ts_utc": "2026-06-01T07:48:55.691977+00:00"}
{"e": "depthUpdate", "E": 1780300136895, "s": "SOLUSDT", "U": 29045629018, "u": 29045629034, "b": [["80.73000000", "321.88800000"], ["80.72000000", "168.30100000"], ["80.71000000", "322.34800000"], ["80.69000000", "561.77700000"], ["80.68000000", "449.59100000"], ["80.66000000", "1119.62000000"], ["80.59000000", "546.87800000"]], "a": [["80.74000000", "790.15000000"], ["80.75000000", "357.09300000"], ["80.76000000", "369.01200000"], ["80.77000000", "502.59000000"], ["80.78000000", "786.44800000"], ["80.79000000", "457.14000000"], ["80.85000000", "793.54100000"]], "_local_ts_utc": "2026-06-01T07:48:55.791975+00:00"}
{"e": "depthUpdate", "E": 1780300136995, "s": "SOLUSDT", "U": 29045629035, "u": 29045629050, "b": [["80.72000000", "170.36500000"], ["80.71000000", "453.44900000"], ["80.70000000", "379.62400000"], ["80.69000000", "646.48400000"], ["80.68000000", "447.52700000"]], "a": [["80.74000000", "896.60400000"], ["80.75000000", "358.12400000"], ["80.76000000", "370.04300000"], ["80.77000000", "501.55900000"], ["80.78000000", "785.41700000"], ["80.79000000", "590.89300000"]], "_local_ts_utc": "2026-06-01T07:48:55.900305+00:00"}
{"e": "depthUpdate", "E": 1780300137095, "s": "SOLUSDT", "U": 29045629051, "u": 29045629063, "b": [["80.72000000", "168.30100000"], ["80.71000000", "451.38500000"], ["80.69000000", "648.54900000"], ["80.68000000", "449.59100000"], ["80.64000000", "567.31800000"], ["80.63000000", "1080.81200000"], ["80.62000000", "1328.31600000"], ["80.61000000", "1106.55900000"], ["80.56000000", "1914.33400000"]], "a": [["80.74000000", "895.44000000"], ["80.75000000", "357.09300000"], ["80.76000000", "369.01200000"], ["80.77000000", "502.59000000"], ["80.78000000", "786.44800000"], ["80.79000000", "591.92400000"], ["81.50000000", "24.67600000"]], "_local_ts_utc": "2026-06-01T07:48:55.991864+00:00"}
{"e": "depthUpdate", "E": 1780300137195, "s": "SOLUSDT", "U": 29045629064, "u": 29045629081, "b": [["80.73000000", "163.54200000"], ["80.72000000", "170.36500000"], ["80.71000000", "450.18800000"], ["80.70000000", "381.60400000"], ["80.69000000", "646.48400000"], ["80.68000000", "447.52700000"], ["80.54000000", "62.54200000"], ["80.51000000", "55.71700000"], ["80.46000000", "493.26900000"]], "a": [["80.74000000", "896.60900000"], ["80.75000000", "359.91300000"], ["80.76000000", "370.04300000"], ["80.77000000", "501.55900000"], ["80.78000000", "785.41700000"], ["80.79000000", "590.89300000"], ["80.83000000", "291.33500000"], ["81.16000000", "42.29900000"], ["81.35000000", "50.82500000"], ["95.06000000", "40.44100000"]], "_local_ts_utc": "2026-06-01T07:48:56.091987+00:00"}
{"e": "depthUpdate", "E": 1780300137295, "s": "SOLUSDT", "U": 29045629082, "u": 29045629089, "b": [["80.73000000", "228.24400000"], ["80.71000000", "410.11300000"]], "a": [["80.76000000", "370.42900000"], ["80.90000000", "164.80000000"], ["80.94000000", "950.09800000"]], "_local_ts_utc": "2026-06-01T07:48:56.191955+00:00"}
{"e": "depthUpdate", "E": 1780300137395, "s": "SOLUSDT", "U": 29045629090, "u": 29045629115, "b": [["80.72000000", "168.30100000"], ["80.71000000", "408.04900000"], ["80.69000000", "648.54900000"], ["80.68000000", "449.59100000"], ["80.66000000", "1259.93200000"], ["80.32000000", "6.37200000"], ["80.23000000", "103.77800000"], ["79.95000000", "273.36100000"]], "a": [["80.74000000", "895.57700000"], ["80.75000000", "358.88200000"], ["80.76000000", "369.39800000"], ["80.77000000", "502.59000000"], ["80.78000000", "786.44800000"], ["80.79000000", "457.14000000"], ["80.98000000", "398.99900000"], ["81.02000000", "274.21300000"], ["81.05000000", "989.48800000"], ["81.09000000", "0.65500000"], ["81.13000000", "292.53800000"], ["81.14000000", "85.90400000"], ["81.21000000", "74.03200000"], ["81.53000000", "7.51600000"], ["81.94000000", "521.75200000"], ["82.34000000", "7.68100000"], ["83.15000000", "179.64100000"]], "_local_ts_utc": "2026-06-01T07:48:56.291973+00:00"}
{"e": "depthUpdate", "E": 1780300137495, "s": "SOLUSDT", "U": 29045629116, "u": 29045629147, "b": [["80.73000000", "219.13300000"], ["80.72000000", "168.30100000"], ["80.71000000", "345.11100000"], ["80.69000000", "648.54900000"], ["80.68000000", "449.59100000"], ["80.50000000", "2722.36700000"]], "a": [["80.74000000", "895.57700000"], ["80.75000000", "358.88200000"], ["80.76000000", "369.79800000"], ["80.77000000", "502.19000000"], ["80.78000000", "786.44800000"], ["80.79000000", "457.14000000"], ["81.09000000", "0.73200000"], ["81.21000000", "74.09900000"], ["81.27000000", "49.55500000"], ["81.37000000", "43.05900000"], ["81.45000000", "3.39400000"], ["81.70000000", "10.23700000"], ["81.89000000", "51.38500000"], ["82.13000000", "1.48800000"], ["82.50000000", "152.10500000"], ["82.67000000", "48.64500000"], ["83.95000000", "13.99500000"]], "_local_ts_utc": "2026-06-01T07:48:56.391972+00:00"}
{"e": "depthUpdate", "E": 1780300137595, "s": "SOLUSDT", "U": 29045629148, "u": 29045629168, "b": [["80.73000000", "309.48400000"], ["80.72000000", "170.36500000"], ["80.71000000", "410.23700000"], ["80.69000000", "646.48400000"], ["80.68000000", "447.52700000"]], "a": [["80.74000000", "898.05100000"], ["80.75000000", "359.91300000"], ["80.76000000", "370.82900000"], ["80.77000000", "501.15900000"], ["80.78000000", "785.41700000"], ["80.79000000", "456.10900000"], ["82.74000000", "10.25300000"]], "_local_ts_utc": "2026-06-01T07:48:56.491973+00:00"}
{"e": "depthUpdate", "E": 1780300137695, "s": "SOLUSDT", "U": 29045629169, "u": 29045629201, "b": [["80.73000000", "431.01600000"], ["80.72000000", "170.36500000"], ["80.71000000", "416.91100000"], ["80.70000000", "377.62400000"], ["80.69000000", "646.48400000"], ["80.68000000", "447.52700000"], ["80.66000000", "1259.79600000"]], "a": [["80.74000000", "685.61800000"], ["80.75000000", "331.01100000"], ["80.76000000", "370.82900000"], ["80.77000000", "501.15900000"], ["80.78000000", "923.11000000"], ["80.79000000", "456.10900000"], ["84.76000000", "2.81500000"]], "_local_ts_utc": "2026-06-01T07:48:56.591972+00:00"}
{"e": "depthUpdate", "E": 1780300137795, "s": "SOLUSDT", "U": 29045629202, "u": 29045629292, "b": [["80.73000000", "508.53100000"], ["80.72000000", "249.42400000"], ["80.71000000", "363.17500000"], ["80.70000000", "363.62400000"], ["80.68000000", "1924.94500000"], ["80.66000000", "1119.48400000"]], "a": [["80.74000000", "264.74100000"], ["80.75000000", "218.44100000"], ["80.76000000", "370.57500000"], ["80.78000000", "785.41700000"], ["80.79000000", "453.53200000"], ["80.80000000", "505.84600000"], ["80.81000000", "925.71400000"], ["83.15000000", "179.78500000"]], "_local_ts_utc": "2026-06-01T07:48:56.691971+00:00"}
{"e": "depthUpdate", "E": 1780300137895, "s": "SOLUSDT", "U": 29045629293, "u": 29045629298, "b": [["80.73000000", "504.03100000"], ["80.47000000", "1770.61800000"]], "a": [["80.74000000", "264.87700000"], ["80.75000000", "281.50300000"], ["80.81000000", "925.57800000"], ["81.29000000", "115.21200000"]], "_local_ts_utc": "2026-06-01T07:48:56.791971+00:00"}
{"e": "depthUpdate", "E": 1780300137996, "s": "SOLUSDT", "U": 29045629299, "u": 29045629314, "b": [["80.73000000", "439.85000000"], ["80.67000000", "691.34600000"], ["80.66000000", "1119.62000000"]], "a": [["80.74000000", "262.67800000"], ["80.78000000", "797.81900000"], ["80.79000000", "449.53900000"], ["80.80000000", "642.31800000"], ["85.57000000", "22.19800000"]], "_local_ts_utc": "2026-06-01T07:48:56.891983+00:00"}
{"e": "depthUpdate", "E": 1780300138095, "s": "SOLUSDT", "U": 29045629315, "u": 29045629322, "b": [["80.72000000", "247.36000000"], ["80.71000000", "361.11100000"], ["80.69000000", "648.54900000"], ["80.68000000", "1930.79900000"]], "a": [["80.74000000", "261.64600000"], ["80.75000000", "280.47200000"], ["80.76000000", "369.54400000"], ["80.77000000", "502.19000000"], ["80.78000000", "798.85000000"], ["80.79000000", "485.17900000"], ["83.55000000", "15.98800000"]], "_local_ts_utc": "2026-06-01T07:48:56.991478+00:00"}
{"e": "depthUpdate", "E": 1780300138195, "s": "SOLUSDT", "U": 29045629323, "u": 29045629336, "b": [["80.73000000", "439.98600000"], ["80.72000000", "249.42400000"], ["80.71000000", "363.17500000"], ["80.69000000", "646.48400000"], ["80.68000000", "1928.73500000"], ["80.66000000", "1119.48400000"], ["79.00000000", "7858.46900000"]], "a": [["80.74000000", "261.83100000"], ["80.77000000", "501.15900000"], ["80.82000000", "518.67300000"], ["80.83000000", "263.45200000"], ["86.38000000", "45.87300000"]], "_local_ts_utc": "2026-06-01T07:48:57.090971+00:00"}
{"e": "depthUpdate", "E": 1780300138295, "s": "SOLUSDT", "U": 29045629337, "u": 29045629385, "b": [["80.73000000", "488.98100000"], ["80.72000000", "242.90700000"], ["80.71000000", "347.17500000"], ["80.70000000", "400.64600000"], ["80.69000000", "1098.35000000"], ["80.68000000", "1885.50400000"], ["80.65000000", "1631.13500000"], ["80.63000000", "1261.71400000"], ["80.55000000", "1772.67900000"], ["80.48000000", "424.74600000"], ["80.46000000", "89.43800000"]], "a": [["80.74000000", "1.53600000"], ["80.75000000", "83.32400000"], ["80.76000000", "372.30500000"], ["80.78000000", "786.44800000"], ["80.79000000", "489.17200000"], ["80.80000000", "505.84600000"], ["80.81000000", "925.71400000"], ["80.84000000", "261.19100000"], ["83.95000000", "14.17000000"]], "_local_ts_utc": "2026-06-01T07:48:57.192636+00:00"}
{"e": "depthUpdate", "E": 1780300138395, "s": "SOLUSDT", "U": 29045629386, "u": 29045629677, "b": [["80.74000000", "136.47600000"], ["80.73000000", "394.42100000"], ["80.72000000", "351.32800000"], ["80.71000000", "363.05100000"], ["80.70000000", "325.23500000"], ["80.69000000", "1052.53900000"], ["80.67000000", "554.18600000"], ["80.64000000", "1597.33900000"], ["80.63000000", "917.93800000"], ["80.62000000", "215.47200000"], ["80.61000000", "935.15200000"], ["80.52000000", "122.85500000"], ["79.98000000", "13.69200000"], ["79.56000000", "7.37700000"], ["79.54000000", "508.47900000"], ["79.12000000", "5.36600000"]], "a": [["80.74000000", "0.00000000"], ["80.75000000", "684.01900000"], ["80.76000000", "404.03400000"], ["80.77000000", "472.17800000"], ["80.79000000", "454.69000000"], ["80.80000000", "511.85200000"], ["80.81000000", "925.71400000"], ["80.82000000", "518.67300000"], ["80.86000000", "1841.79400000"], ["80.87000000", "1870.79300000"], ["80.88000000", "408.01500000"], ["80.89000000", "232.90600000"], ["80.93000000", "415.58200000"], ["81.24000000", "1288.92300000"], ["81.50000000", "24.73900000"], ["83.68000000", "33.29900000"]], "_local_ts_utc": "2026-06-01T07:48:57.291977+00:00"}
{"e": "depthUpdate", "E": 1780300138495, "s": "SOLUSDT", "U": 29045629678, "u": 29045629731, "b": [["80.74000000", "137.85700000"], ["80.73000000", "323.35900000"], ["80.72000000", "343.35000000"], ["80.71000000", "170.18100000"], ["80.60000000", "2950.62300000"], ["80.45000000", "1005.51100000"]], "a": [["80.75000000", "597.34400000"], ["80.76000000", "416.81900000"], ["80.81000000", "925.77600000"], ["80.86000000", "1841.72600000"], ["81.08000000", "45.88600000"], ["81.32000000", "98.79400000"], ["81.54000000", "9.84700000"], ["83.47000000", "38.66600000"], ["87.18000000", "69.21400000"]], "_local_ts_utc": "2026-06-01T07:48:57.392719+00:00"}
{"e": "depthUpdate", "E": 1780300138595, "s": "SOLUSDT", "U": 29045629732, "u": 29045629740, "b": [["80.74000000", "146.21400000"]], "a": [["80.75000000", "597.42400000"], ["80.76000000", "416.73900000"], ["80.87000000", "1870.86100000"], ["81.09000000", "0.81100000"], ["81.33000000", "48.55900000"], ["81.55000000", "7.01400000"], ["84.36000000", "10.89800000"]], "_local_ts_utc": "2026-06-01T07:48:57.491973+00:00"}
{"e": "depthUpdate", "E": 1780300138695, "s": "SOLUSDT", "U": 29045629741, "u": 29045629750, "b": [["80.73000000", "323.35900000"], ["80.67000000", "690.46800000"], ["80.64000000", "1424.69300000"], ["80.62000000", "388.24200000"]], "a": [["80.81000000", "1060.89600000"], ["82.05000000", "10.70300000"], ["87.99000000", "48.30200000"]], "_local_ts_utc": "2026-06-01T07:48:57.591485+00:00"}
{"e": "depthUpdate", "E": 1780300138795, "s": "SOLUSDT", "U": 29045629751, "u": 29045629777, "b": [["80.74000000", "103.06800000"], ["80.73000000", "331.45600000"], ["80.72000000", "341.55200000"], ["80.71000000", "171.94400000"], ["80.68000000", "1889.29400000"], ["80.65000000", "1631.63500000"], ["80.64000000", "1165.53800000"], ["80.62000000", "647.14900000"], ["80.56000000", "1975.89600000"]], "a": [["80.75000000", "609.61000000"], ["80.76000000", "417.93400000"], ["84.76000000", "3.02700000"]], "_local_ts_utc": "2026-06-01T07:48:57.691355+00:00"}
{"e": "depthUpdate", "E": 1780300138896, "s": "SOLUSDT", "U": 29045629778, "u": 29045629840, "b": [["80.74000000", "94.92000000"], ["80.73000000", "243.94300000"], ["80.72000000", "162.14500000"], ["80.71000000", "336.65800000"], ["80.70000000", "339.23500000"], ["80.69000000", "1044.79900000"], ["80.68000000", "1889.29400000"], ["80.67000000", "554.18600000"], ["80.64000000", "560.47700000"], ["80.62000000", "1078.95000000"], ["80.61000000", "1107.67400000"], ["80.56000000", "1914.33400000"]], "a": [["80.75000000", "643.74700000"], ["83.29000000", "15.88300000"], ["83.70000000", "115.35500000"], ["88.80000000", "1096.63500000"]], "_local_ts_utc": "2026-06-01T07:48:57.791969+00:00"}
{"e": "depthUpdate", "E": 1780300138995, "s": "SOLUSDT", "U": 29045629841, "u": 29045629852, "b": [["80.74000000", "95.17000000"], ["80.73000000", "290.08800000"], ["80.72000000", "341.23000000"]], "a": [["80.75000000", "647.23100000"], ["80.77000000", "468.64300000"], ["80.79000000", "467.09100000"], ["80.81000000", "925.77600000"]], "_local_ts_utc": "2026-06-01T07:48:57.891980+00:00"}
{"e": "depthUpdate", "E": 1780300139095, "s": "SOLUSDT", "U": 29045629853, "u": 29045629886, "b": [["80.73000000", "325.41300000"], ["80.72000000", "306.70800000"], ["80.71000000", "221.00600000"]], "a": [["80.75000000", "800.48900000"], ["80.77000000", "468.76700000"], ["80.81000000", "1065.14100000"], ["80.89000000", "214.80600000"], ["85.17000000", "4.32000000"]], "_local_ts_utc": "2026-06-01T07:48:57.990967+00:00"}
{"e": "depthUpdate", "E": 1780300139195, "s": "SOLUSDT", "U": 29045629887, "u": 29045629888, "b": [], "a": [["80.75000000", "804.49900000"], ["89.61000000", "17.96200000"]], "_local_ts_utc": "2026-06-01T07:48:58.092047+00:00"}
{"e": "depthUpdate", "E": 1780300139295, "s": "SOLUSDT", "U": 29045629889, "u": 29045629892, "b": [["80.73000000", "251.69900000"], ["80.64000000", "561.05100000"]], "a": [["85.57000000", "22.45400000"]], "_local_ts_utc": "2026-06-01T07:48:58.191059+00:00"}
{"e": "depthUpdate", "E": 1780300139395, "s": "SOLUSDT", "U": 29045629893, "u": 29045630764, "b": [["80.74000000", "0.00000000"], ["80.73000000", "0.00000000"], ["80.72000000", "0.00000000"], ["80.71000000", "0.00000000"], ["80.70000000", "150.59100000"], ["80.69000000", "134.62300000"], ["80.68000000", "163.41200000"], ["80.67000000", "527.27600000"], ["80.66000000", "205.92100000"], ["80.65000000", "296.99000000"], ["80.64000000", "2185.02900000"], ["80.63000000", "105.50100000"], ["80.62000000", "334.45400000"], ["80.61000000", "1158.88300000"], ["80.60000000", "2885.20900000"], ["80.59000000", "555.64400000"], ["80.58000000", "1636.32800000"], ["80.57000000", "929.91700000"], ["80.56000000", "671.58500000"], ["80.55000000", "1756.62900000"], ["80.54000000", "360.21300000"], ["80.53000000", "509.54200000"], ["80.52000000", "122.78800000"], ["80.51000000", "1536.92500000"], ["80.50000000", "2861.48500000"], ["80.48000000", "782.70500000"], ["80.47000000", "1263.11900000"], ["80.46000000", "126.46000000"], ["80.45000000", "34.05400000"], ["80.44000000", "8.13200000"], ["80.43000000", "57.59000000"], ["80.42000000", "512.39800000"], ["80.38000000", "20.58200000"], ["80.37000000", "979.05900000"], ["80.33000000", "269.70300000"], ["80.32000000", "6.51000000"], ["80.31000000", "1257.33000000"], ["80.28000000", "109.82200000"], ["80.27000000", "50.47000000"], ["80.26000000", "29.64600000"], ["80.22000000", "41.04800000"], ["80.21000000", "1266.17000000"], ["80.14000000", "33.48600000"], ["79.99000000", "339.50700000"], ["79.98000000", "13.75500000"], ["79.97000000", "10.21500000"], ["79.93000000", "132.05300000"], ["79.92000000", "33.85000000"], ["79.09000000", "40.15000000"], ["79.08000000", "8.11500000"], ["64.60000000", "5.37500000"], ["64.56000000", "0.29700000"], ["52.49000000", "1.20100000"]], "a": [["80.71000000", "2377.86300000"], ["80.72000000", "642.29800000"], ["80.73000000", "567.39300000"], ["80.74000000", "676.89100000"], ["80.75000000", "853.24000000"], ["80.76000000", "363.24200000"], ["80.77000000", "693.02200000"], ["80.78000000", "702.46700000"], ["80.79000000", "651.93800000"], ["80.80000000", "429.82300000"], ["80.81000000", "951.96300000"], ["80.82000000", "1078.68600000"], ["80.83000000", "1245.10700000"], ["80.84000000", "47.31700000"], ["80.85000000", "526.34000000"], ["80.86000000", "97.86400000"], ["80.87000000", "1574.20000000"], ["80.89000000", "216.07000000"], ["80.90000000", "319.48600000"], ["80.91000000", "149.97700000"], ["80.92000000", "521.31000000"], ["80.93000000", "155.27500000"], ["80.94000000", "950.00500000"], ["80.95000000", "462.60500000"], ["80.96000000", "1266.40800000"], ["80.97000000", "138.43700000"], ["80.98000000", "913.25700000"], ["81.01000000", "489.81400000"], ["81.03000000", "100.55300000"], ["81.05000000", "989.56100000"], ["81.06000000", "56.60800000"], ["81.07000000", "74.83700000"], ["81.08000000", "45.94900000"], ["81.12000000", "1276.75600000"], ["81.13000000", "323.87700000"], ["81.14000000", "47.34700000"], ["81.15000000", "194.88500000"], ["81.17000000", "1246.79600000"], ["81.18000000", "270.80800000"], ["81.20000000", "5.89100000"], ["81.21000000", "74.17200000"], ["81.22000000", "125.85200000"], ["81.23000000", "41.58500000"], ["81.24000000", "49.26800000"], ["81.25000000", "56.62700000"], ["81.28000000", "69.08500000"], ["81.29000000", "115.46500000"], ["81.30000000", "44.34700000"], ["81.31000000", "75.95000000"], ["81.32000000", "98.96600000"], ["81.33000000", "48.90100000"], ["81.35000000", "46.92400000"], ["81.42000000", "4.75700000"], ["81.44000000", "7.59700000"], ["81.46000000", "1358.88100000"], ["81.47000000", "0.84800000"], ["81.48000000", "4.06400000"], ["81.49000000", "5.26400000"], ["81.50000000", "24.67600000"], ["81.58000000", "89.17300000"], ["81.60000000", "9.84000000"], ["81.64000000", "9.75300000"], ["81.65000000", "332.71000000"], ["81.68000000", "1.53000000"], ["81.73000000", "1.32100000"], ["81.75000000", "4.60800000"], ["81.78000000", "2.59500000"], ["81.87000000", "3.47300000"], ["81.91000000", "482.33200000"], ["81.94000000", "6.52300000"], ["82.14000000", "4.24500000"], ["82.17000000", "4.58900000"], ["82.64000000", "10.94600000"], ["82.85000000", "18.56800000"], ["84.78000000", "75.62000000"], ["84.90000000", "210.15300000"], ["86.04000000", "2.84100000"], ["90.41000000", "10.31900000"]], "_local_ts_utc": "2026-06-01T07:48:58.292157+00:00"}
{"e": "depthUpdate", "E": 1780300139495, "s": "SOLUSDT", "U": 29045630765, "u": 29045631129, "b": [["80.70000000", "0.00000000"], ["80.69000000", "105.26400000"], ["80.68000000", "236.27300000"], ["80.67000000", "383.74000000"], ["80.66000000", "433.03800000"], ["80.65000000", "759.49100000"], ["80.64000000", "2187.92900000"], ["80.63000000", "168.92800000"], ["80.62000000", "167.97200000"], ["80.61000000", "1146.49300000"], ["80.60000000", "2888.67200000"], ["80.59000000", "750.62200000"], ["80.58000000", "1829.52600000"], ["80.57000000", "949.94800000"], ["80.56000000", "679.75600000"], ["80.55000000", "1816.23700000"], ["80.54000000", "214.64000000"], ["80.53000000", "536.34100000"], ["80.52000000", "90.21200000"], ["80.51000000", "1600.16100000"], ["80.49000000", "70.49500000"], ["80.47000000", "1296.32000000"], ["80.46000000", "41.57100000"], ["80.44000000", "10.32000000"], ["80.40000000", "1603.78500000"], ["80.36000000", "91.82000000"], ["80.33000000", "269.61500000"], ["80.30000000", "1033.62900000"], ["80.23000000", "185.84100000"], ["80.08000000", "47.54800000"], ["79.96000000", "2.26800000"], ["79.95000000", "273.42400000"], ["79.90000000", "683.43000000"], ["79.88000000", "166.04700000"]], "a": [["80.70000000", "1130.81500000"], ["80.71000000", "737.20700000"], ["80.72000000", "629.52400000"], ["80.73000000", "573.04700000"], ["80.74000000", "686.79900000"], ["80.75000000", "831.99400000"], ["80.76000000", "504.80800000"], ["80.77000000", "630.38300000"], ["80.78000000", "692.25700000"], ["80.79000000", "509.87900000"], ["80.80000000", "340.53800000"], ["80.81000000", "793.36300000"], ["80.85000000", "526.88800000"], ["80.86000000", "975.46300000"], ["80.87000000", "1574.13200000"], ["80.88000000", "405.01500000"], ["80.89000000", "305.50900000"], ["80.90000000", "319.23600000"], ["80.91000000", "149.88400000"], ["80.94000000", "72.83900000"], ["80.95000000", "456.60500000"], ["81.00000000", "74.62700000"], ["81.01000000", "399.81400000"], ["81.05000000", "989.64000000"], ["81.07000000", "42.37200000"], ["81.08000000", "46.19600000"], ["81.09000000", "0.73200000"], ["81.12000000", "1359.91600000"], ["81.14000000", "44.33700000"], ["81.22000000", "42.52600000"], ["81.29000000", "115.55500000"], ["81.33000000", "48.81100000"], ["81.41000000", "3.09500000"], ["81.45000000", "3.33200000"], ["81.46000000", "1358.81800000"], ["81.51000000", "216.30000000"], ["81.55000000", "6.63700000"], ["81.58000000", "241.34500000"], ["81.77000000", "7.62200000"], ["82.34000000", "7.58900000"], ["95.00000000", "11315.68000000"]], "_local_ts_utc": "2026-06-01T07:48:58.392198+00:00"}
{"e": "depthUpdate", "E": 1780300139595, "s": "SOLUSDT", "U": 29045631130, "u": 29045631281, "b": [["80.69000000", "57.75300000"], ["80.68000000", "94.57700000"], ["80.67000000", "504.75200000"], ["80.66000000", "431.51000000"], ["80.63000000", "176.67300000"], ["80.62000000", "154.47300000"], ["80.61000000", "1152.94300000"], ["80.60000000", "2888.60900000"], ["80.59000000", "750.12200000"], ["80.58000000", "1821.43300000"], ["80.57000000", "955.16100000"], ["80.55000000", "1913.85200000"], ["80.54000000", "222.82300000"], ["80.53000000", "675.62200000"], ["80.52000000", "567.86000000"], ["80.42000000", "512.46100000"], ["79.94000000", "11.50500000"]], "a": [["80.70000000", "1118.82200000"], ["80.71000000", "733.20700000"], ["80.73000000", "570.56900000"], ["80.74000000", "686.86800000"], ["80.75000000", "832.05600000"], ["80.77000000", "630.31400000"], ["80.80000000", "263.04100000"], ["80.81000000", "801.54600000"], ["80.83000000", "1245.10700000"], ["80.85000000", "559.94400000"], ["80.86000000", "967.15700000"], ["80.88000000", "399.52200000"], ["80.90000000", "287.17900000"], ["81.04000000", "1226.68900000"], ["81.05000000", "989.56100000"], ["81.22000000", "42.60600000"], ["81.28000000", "69.17500000"], ["81.29000000", "115.46500000"], ["81.33000000", "49.40300000"], ["81.40000000", "49.89700000"], ["81.42000000", "5.21400000"], ["81.50000000", "25.05400000"], ["81.51000000", "215.92200000"], ["81.60000000", "9.91500000"], ["81.65000000", "332.81200000"], ["81.67000000", "11.18400000"], ["81.83000000", "5.06200000"], ["81.84000000", "3.31200000"], ["81.88000000", "1.85300000"], ["81.95000000", "15.12800000"], ["82.44000000", "21.54000000"], ["82.69000000", "7.26900000"], ["83.17000000", "165.11900000"], ["84.06000000", "9.85700000"], ["84.31000000", "9.46600000"], ["84.40000000", "149.08900000"], ["85.97000000", "39.26200000"], ["87.76000000", "10.45300000"], ["87.83000000", "12.67600000"], ["91.36000000", "4.96200000"], ["91.40000000", "8.54600000"], ["95.10000000", "7.27100000"], ["95.12000000", "7.98700000"], ["99.00000000", "4009.33700000"]], "_local_ts_utc": "2026-06-01T07:48:58.491255+00:00"}
{"e": "depthUpdate", "E": 1780300139695, "s": "SOLUSDT", "U": 29045631282, "u": 29045631308, "b": [["80.69000000", "159.53900000"], ["80.68000000", "240.68900000"], ["80.67000000", "566.60800000"], ["80.66000000", "433.39500000"], ["80.65000000", "761.98300000"], ["80.62000000", "163.71700000"], ["80.61000000", "1153.24300000"], ["79.40000000", "209.62900000"], ["79.08000000", "11.24400000"]], "a": [["80.70000000", "1118.26600000"], ["80.71000000", "733.20700000"], ["80.72000000", "633.01700000"], ["80.75000000", "828.57200000"], ["80.76000000", "648.15700000"], ["80.82000000", "1078.75400000"], ["83.08000000", "92.99400000"], ["83.49000000", "10.43400000"], ["91.22000000", "37.17200000"]], "_local_ts_utc": "2026-06-01T07:48:58.591637+00:00"}
{"e": "depthUpdate", "E": 1780300139795, "s": "SOLUSDT", "U": 29045631309, "u": 29045631341, "b": [["80.69000000", "48.58700000"], ["80.68000000", "94.48400000"], ["80.67000000", "646.39800000"], ["80.66000000", "254.08900000"], ["80.63000000", "155.64300000"], ["80.62000000", "148.58400000"], ["80.60000000", "2776.48700000"], ["80.58000000", "1977.66900000"], ["80.55000000", "1875.46300000"], ["80.48000000", "378.97400000"], ["80.41000000", "449.23600000"]], "a": [["80.70000000", "1115.91500000"], ["80.71000000", "733.20700000"], ["80.72000000", "645.40600000"], ["80.79000000", "511.11800000"], ["80.99000000", "158.52100000"], ["81.12000000", "1358.68300000"], ["86.38000000", "46.18300000"], ["88.77000000", "7.76300000"]], "_local_ts_utc": "2026-06-01T07:48:58.691963+00:00"}
{"e": "depthUpdate", "E": 1780300139895, "s": "SOLUSDT", "U": 29045631342, "u": 29045631403, "b": [["80.69000000", "37.51700000"], ["80.68000000", "94.40900000"], ["80.67000000", "500.88500000"], ["80.66000000", "255.75000000"], ["80.65000000", "775.98300000"], ["80.63000000", "147.89800000"], ["80.60000000", "2764.04500000"], ["80.59000000", "750.37200000"], ["80.58000000", "1470.38900000"], ["80.56000000", "1018.10800000"], ["80.51000000", "1536.92500000"], ["80.49000000", "58.53500000"], ["80.41000000", "461.19600000"]], "a": [["80.70000000", "1045.39500000"], ["80.71000000", "1094.02000000"], ["80.97000000", "138.56000000"], ["81.01000000", "41.85500000"], ["88.77000000", "7.70100000"]], "_local_ts_utc": "2026-06-01T07:48:58.791981+00:00"}
{"e": "depthUpdate", "E": 1780300139995, "s": "SOLUSDT", "U": 29045631404, "u": 29045631453, "b": [["80.69000000", "112.36300000"], ["80.68000000", "262.41000000"], ["80.67000000", "566.60800000"], ["80.66000000", "257.27700000"], ["80.64000000", "2063.77900000"], ["80.63000000", "160.30100000"], ["80.57000000", "1272.25100000"], ["80.53000000", "536.34100000"], ["80.51000000", "1661.27800000"]], "a": [["80.70000000", "1040.81400000"], ["80.71000000", "736.06100000"], ["80.76000000", "695.67400000"], ["80.77000000", "754.28800000"], ["80.89000000", "181.72100000"], ["92.03000000", "8.07500000"]], "_local_ts_utc": "2026-06-01T07:48:58.891812+00:00"}
{"e": "depthUpdate", "E": 1780300140095, "s": "SOLUSDT", "U": 29045631454, "u": 29045631533, "b": [["80.69000000", "40.05000000"], ["80.68000000", "94.40900000"], ["80.67000000", "627.84200000"], ["80.66000000", "255.75000000"], ["80.63000000", "147.89800000"], ["80.61000000", "1153.30700000"], ["80.58000000", "1132.03700000"], ["80.56000000", "1356.46000000"], ["80.43000000", "461.57200000"], ["80.41000000", "57.11400000"]], "a": [["80.70000000", "1462.21600000"], ["80.71000000", "737.30100000"], ["80.72000000", "705.48600000"], ["80.73000000", "827.54300000"], ["80.74000000", "2168.07600000"], ["80.76000000", "695.73800000"], ["80.80000000", "111.70000000"], ["80.81000000", "701.15000000"], ["80.87000000", "92.84900000"], ["80.89000000", "181.64600000"], ["81.03000000", "100.80000000"], ["81.46000000", "1358.74400000"], ["82.38000000", "5.49300000"], ["82.80000000", "96.18300000"], ["86.78000000", "37.49700000"]], "_local_ts_utc": "2026-06-01T07:48:58.991973+00:00"}
{"e": "depthUpdate", "E": 1780300140195, "s": "SOLUSDT", "U": 29045631534, "u": 29045631609, "b": [["80.69000000", "332.81300000"], ["80.68000000", "94.48400000"], ["80.67000000", "565.62100000"], ["80.66000000", "269.82500000"], ["80.65000000", "761.98300000"], ["80.62000000", "148.58400000"], ["80.61000000", "1153.00700000"], ["80.59000000", "633.59400000"], ["80.57000000", "1362.27700000"]], "a": [["80.70000000", "768.87800000"], ["80.71000000", "1108.43000000"], ["80.74000000", "680.66600000"], ["80.75000000", "836.82300000"], ["80.76000000", "552.38900000"], ["80.77000000", "2235.49600000"], ["92.83000000", "6.32400000"]], "_local_ts_utc": "2026-06-01T07:48:59.091959+00:00"}
{"e": "depthUpdate", "E": 1780300140295, "s": "SOLUSDT", "U": 29045631610, "u": 29045631676, "b": [["80.69000000", "133.35400000"], ["80.68000000", "94.40900000"], ["80.67000000", "564.78300000"], ["80.66000000", "255.75000000"], ["80.65000000", "775.98300000"], ["80.63000000", "148.51100000"]], "a": [["80.70000000", "877.85500000"], ["80.71000000", "1109.67700000"], ["80.72000000", "1003.36500000"], ["80.73000000", "570.63300000"], ["80.74000000", "680.66600000"], ["80.75000000", "913.25200000"], ["80.76000000", "816.00000000"], ["80.80000000", "60.63500000"], ["87.18000000", "69.58900000"]], "_local_ts_utc": "2026-06-01T07:48:59.202686+00:00"}
{"e": "depthUpdate", "E": 1780300140395, "s": "SOLUSDT", "U": 29045631677, "u": 29045631908, "b": [["80.69000000", "0.00000000"], ["80.68000000", "409.42900000"], ["80.67000000", "318.91800000"], ["80.66000000", "369.36500000"], ["80.65000000", "202.96500000"], ["80.64000000", "166.39800000"], ["80.63000000", "163.68900000"], ["80.62000000", "208.58400000"], ["80.58000000", "963.36100000"], ["80.57000000", "1323.29600000"], ["80.55000000", "1777.84800000"], ["80.33000000", "239.41500000"], ["80.29000000", "37.93100000"], ["80.28000000", "109.88500000"], ["80.10000000", "864.70700000"], ["79.94000000", "989.28100000"], ["79.93000000", "132.11600000"], ["79.80000000", "997.95200000"], ["79.39000000", "2.23900000"], ["79.07000000", "10.28900000"], ["78.99000000", "125.12300000"], ["78.66000000", "674.24100000"]], "a": [["80.69000000", "1078.25800000"], ["80.70000000", "1003.89100000"], ["80.71000000", "692.10900000"], ["80.72000000", "786.17800000"], ["80.73000000", "572.68000000"], ["80.74000000", "676.87800000"], ["80.75000000", "1062.56000000"], ["80.76000000", "767.42400000"], ["80.77000000", "2235.09900000"], ["80.78000000", "634.45400000"], ["80.79000000", "319.81100000"], ["80.86000000", "967.51600000"], ["80.88000000", "399.46000000"], ["80.89000000", "181.39600000"], ["80.90000000", "287.08600000"], ["80.91000000", "145.38400000"], ["81.06000000", "56.67900000"], ["81.10000000", "48.67500000"], ["81.25000000", "56.69400000"], ["81.38000000", "404.78700000"], ["81.41000000", "3.16300000"], ["81.44000000", "7.53500000"], ["81.46000000", "1114.44700000"], ["81.89000000", "537.12000000"], ["81.91000000", "3.19300000"], ["82.15000000", "8.99500000"], ["82.30000000", "1921.66900000"], ["82.46000000", "12.62000000"], ["86.45000000", "21.51000000"], ["93.64000000", "8.99700000"]], "_local_ts_utc": "2026-06-01T07:48:59.292382+00:00"}
{"e": "depthUpdate", "E": 1780300140495, "s": "SOLUSDT", "U": 29045631909, "u": 29045631993, "b": [["80.68000000", "511.89500000"], ["80.67000000", "392.48100000"], ["80.66000000", "401.20100000"], ["80.65000000", "214.81600000"], ["80.64000000", "153.38900000"], ["80.61000000", "1153.08200000"], ["80.59000000", "634.09400000"], ["80.58000000", "962.86100000"], ["80.56000000", "1187.40800000"], ["80.53000000", "632.93000000"], ["80.49000000", "121.15300000"], ["80.48000000", "378.91100000"], ["80.38000000", "20.65100000"]], "a": [["80.69000000", "852.64300000"], ["80.70000000", "1022.29700000"], ["80.71000000", "627.34700000"], ["80.72000000", "425.74100000"], ["80.73000000", "572.28000000"], ["80.76000000", "767.81800000"], ["80.79000000", "292.49200000"], ["80.83000000", "906.87900000"], ["80.85000000", "622.16200000"], ["80.91000000", "84.04200000"], ["81.45000000", "3.26900000"]], "_local_ts_utc": "2026-06-01T07:48:59.402452+00:00"}
{"e": "depthUpdate", "E": 1780300140595, "s": "SOLUSDT", "U": 29045631994, "u": 29045632059, "b": [["80.68000000", "212.53400000"], ["80.67000000", "318.90000000"], ["80.66000000", "402.17800000"], ["80.65000000", "216.81600000"], ["80.57000000", "1323.35900000"], ["80.42000000", "512.52400000"]], "a": [["80.69000000", "955.80700000"], ["80.70000000", "977.87200000"], ["80.72000000", "481.29800000"], ["80.73000000", "572.34200000"], ["80.75000000", "986.13100000"], ["80.80000000", "60.69700000"], ["80.95000000", "456.54300000"], ["80.96000000", "1266.34600000"], ["80.97000000", "138.49800000"], ["87.59000000", "19.30000000"], ["94.89000000", "14.23000000"]], "_local_ts_utc": "2026-06-01T07:48:59.492467+00:00"}
{"e": "depthUpdate", "E": 1780300140695, "s": "SOLUSDT", "U": 29045632060, "u": 29045632115, "b": [["80.68000000", "212.59800000"], ["80.67000000", "318.82500000"], ["80.66000000", "458.54300000"], ["80.65000000", "224.70900000"], ["80.64000000", "167.38900000"], ["80.62000000", "212.37400000"], ["80.60000000", "2912.54400000"], ["80.59000000", "634.39400000"], ["80.43000000", "57.59000000"], ["80.41000000", "461.19600000"], ["80.36000000", "91.88900000"], ["80.20000000", "728.08800000"]], "a": [["80.69000000", "1080.81000000"], ["80.70000000", "996.73200000"], ["80.71000000", "609.31600000"], ["80.75000000", "832.77600000"], ["81.19000000", "3.38600000"], ["81.22000000", "42.40000000"], ["92.13000000", "8.86700000"], ["93.00000000", "3818.46000000"], ["93.03000000", "5.81800000"], ["93.87000000", "15.67000000"], ["93.99000000", "11.56900000"], ["94.45000000", "337.90100000"], ["94.89000000", "15.71500000"]], "_local_ts_utc": "2026-06-01T07:48:59.603460+00:00"}
{"e": "depthUpdate", "E": 1780300140847, "s": "SOLUSDT", "U": 29045632116, "u": 29045632653, "b": [["80.68000000", "0.00000000"], ["80.67000000", "0.00000000"], ["80.66000000", "0.00000000"], ["80.65000000", "471.11100000"], ["80.64000000", "50.32000000"], ["80.63000000", "70.05600000"], ["80.62000000", "112.00700000"], ["80.61000000", "2240.12600000"], ["80.60000000", "1222.41200000"], ["80.59000000", "298.60400000"], ["80.58000000", "2096.52000000"], ["80.57000000", "465.79700000"], ["80.56000000", "1113.69600000"], ["80.55000000", "2800.53100000"], ["80.54000000", "222.99000000"], ["80.53000000", "706.73100000"], ["80.52000000", "780.09500000"], ["80.51000000", "2499.77000000"], ["80.50000000", "2722.36700000"], ["80.49000000", "58.53500000"], ["80.48000000", "765.86300000"], ["80.47000000", "1420.73300000"], ["80.46000000", "1671.34500000"], ["80.44000000", "8.19500000"], ["80.42000000", "6.70400000"], ["80.41000000", "498.21800000"], ["80.40000000", "542.47800000"], ["80.39000000", "1384.02200000"], ["80.35000000", "1187.12400000"], ["80.33000000", "74.53200000"], ["80.32000000", "7.74900000"], ["80.30000000", "837.63200000"], ["80.25000000", "243.21000000"], ["80.21000000", "1461.79400000"], ["80.18000000", "69.86400000"], ["79.92000000", "33.91300000"], ["79.91000000", "4.58300000"], ["79.84000000", "7.11000000"], ["79.38000000", "6.00800000"], ["79.37000000", "31.26100000"], ["79.06000000", "22.32700000"], ["79.05000000", "121.00400000"], ["79.04000000", "5.92000000"], ["78.97000000", "55.30800000"], ["78.96000000", "23.40200000"], ["78.84000000", "11.78200000"], ["78.64000000", "85.31300000"], ["78.63000000", "8.63900000"]], "a": [["80.66000000", "637.30200000"], ["80.67000000", "467.25800000"], ["80.68000000", "603.89500000"], ["80.69000000", "356.57300000"], ["80.70000000", "949.40900000"], ["80.71000000", "610.17300000"], ["80.72000000", "990.02200000"], ["80.73000000", "616.01400000"], ["80.74000000", "390.33200000"], ["80.75000000", "598.59800000"], ["80.76000000", "949.54200000"], ["80.77000000", "1708.65700000"], ["80.78000000", "402.58600000"], ["80.79000000", "292.50200000"], ["80.82000000", "233.12200000"], ["80.83000000", "106.22300000"], ["80.85000000", "494.40700000"], ["80.86000000", "967.45400000"], ["80.87000000", "248.53700000"], ["80.88000000", "399.11700000"], ["80.89000000", "176.47900000"], ["80.90000000", "132.53900000"], ["80.91000000", "77.97800000"], ["80.92000000", "1029.25500000"], ["80.93000000", "149.34600000"], ["80.94000000", "60.99900000"], ["80.98000000", "405.31200000"], ["80.99000000", "1219.82800000"], ["81.02000000", "49.31900000"], ["81.03000000", "100.80000000"], ["81.04000000", "165.38200000"], ["81.05000000", "1278.63100000"], ["81.08000000", "39.31200000"], ["81.10000000", "261.21000000"], ["81.13000000", "4.60700000"], ["81.15000000", "3.52300000"], ["81.17000000", "1247.16200000"], ["81.26000000", "47.87800000"], ["81.34000000", "4.26700000"], ["81.41000000", "3.10100000"], ["81.42000000", "5.15200000"], ["81.43000000", "6.80600000"], ["81.44000000", "7.47200000"], ["81.71000000", "9.46700000"], ["81.87000000", "474.64800000"], ["81.88000000", "1.85300000"], ["81.89000000", "51.38500000"], ["82.30000000", "1921.57700000"], ["85.03000000", "18.69800000"], ["87.99000000", "48.75600000"], ["92.08000000", "5.91800000"], ["92.13000000", "10.39500000"]], "_local_ts_utc": "2026-06-01T07:48:59.745121+00:00"}
{"e": "depthUpdate", "E": 1780300140927, "s": "SOLUSDT", "U": 29045632654, "u": 29045632930, "b": [["80.65000000", "746.50600000"], ["80.64000000", "56.01700000"], ["80.63000000", "278.13400000"], ["80.62000000", "511.70600000"], ["80.61000000", "2246.59900000"], ["80.60000000", "1156.75800000"], ["80.59000000", "341.83600000"], ["80.58000000", "2154.54200000"], ["80.57000000", "368.57800000"], ["80.56000000", "941.39600000"], ["80.55000000", "2003.62600000"], ["80.54000000", "222.14700000"], ["80.53000000", "757.07100000"], ["80.52000000", "776.66100000"], ["80.51000000", "2505.01800000"], ["80.50000000", "2836.46700000"], ["80.49000000", "168.64000000"], ["80.47000000", "1249.70000000"], ["80.46000000", "1732.66100000"], ["80.43000000", "90.48800000"], ["80.42000000", "4.57900000"], ["80.40000000", "544.60300000"], ["80.37000000", "1487.00400000"], ["80.26000000", "29.72100000"], ["79.90000000", "683.49300000"], ["79.37000000", "18.68500000"], ["79.36000000", "4.66100000"], ["79.04000000", "24.70600000"], ["78.97000000", "42.66800000"], ["78.96000000", "13.92200000"], ["78.63000000", "30.66800000"]], "a": [["80.66000000", "234.77700000"], ["80.67000000", "358.94400000"], ["80.68000000", "396.35200000"], ["80.69000000", "728.20700000"], ["80.70000000", "904.39300000"], ["80.71000000", "612.02500000"], ["80.72000000", "980.32400000"], ["80.73000000", "430.36000000"], ["80.74000000", "301.59100000"], ["80.75000000", "682.00300000"], ["80.76000000", "949.98800000"], ["80.77000000", "1879.07800000"], ["80.79000000", "235.79200000"], ["80.82000000", "8.65400000"], ["80.84000000", "59.15700000"], ["80.86000000", "1091.04100000"], ["80.87000000", "197.81000000"], ["80.92000000", "1254.21100000"], ["80.93000000", "149.42200000"], ["80.94000000", "61.21900000"], ["80.98000000", "47.35300000"], ["81.00000000", "77.18400000"], ["81.02000000", "46.31900000"], ["81.03000000", "97.80000000"], ["81.05000000", "1275.63100000"], ["81.08000000", "36.31200000"], ["81.10000000", "258.56200000"], ["81.18000000", "270.88700000"], ["81.26000000", "47.94500000"], ["81.30000000", "44.43500000"], ["81.33000000", "54.11700000"], ["81.41000000", "3.93900000"], ["81.42000000", "5.08900000"], ["81.43000000", "6.74300000"], ["82.00000000", "408.54300000"], ["83.17000000", "165.22600000"], ["91.22000000", "37.17200000"]], "_local_ts_utc": "2026-06-01T07:48:59.824292+00:00"}
{"e": "depthUpdate", "E": 1780300140995, "s": "SOLUSDT", "U": 29045632931, "u": 29045633105, "b": [["80.65000000", "701.79700000"], ["80.64000000", "156.08100000"], ["80.63000000", "303.87000000"], ["80.62000000", "73.79500000"], ["80.61000000", "1926.54400000"], ["80.60000000", "1148.41200000"], ["80.59000000", "242.68400000"], ["80.58000000", "2080.93800000"], ["80.57000000", "212.42000000"], ["80.56000000", "219.93100000"], ["80.55000000", "1982.85300000"], ["80.54000000", "70.04900000"], ["80.53000000", "734.58600000"], ["80.52000000", "86.87100000"], ["80.51000000", "1666.52600000"], ["80.50000000", "2818.99400000"], ["80.49000000", "55.53500000"], ["80.48000000", "379.34500000"], ["80.34000000", "52.47300000"], ["80.26000000", "40.15900000"], ["80.24000000", "42.21800000"]], "a": [["80.66000000", "11.82900000"], ["80.67000000", "319.42200000"], ["80.68000000", "396.48400000"], ["80.69000000", "730.05800000"], ["80.71000000", "614.07200000"], ["80.72000000", "1075.46000000"], ["80.73000000", "390.30000000"], ["80.74000000", "188.61100000"], ["80.75000000", "535.94200000"], ["80.76000000", "643.36300000"], ["80.77000000", "1813.56200000"], ["80.80000000", "60.69700000"], ["80.81000000", "701.21500000"], ["80.82000000", "9.05200000"], ["80.85000000", "493.85900000"], ["80.97000000", "138.60000000"], ["81.00000000", "81.71300000"], ["81.04000000", "165.30300000"], ["81.05000000", "1276.10500000"], ["81.06000000", "53.67900000"], ["81.08000000", "36.44100000"], ["81.09000000", "0.93000000"], ["81.11000000", "3086.15700000"], ["81.22000000", "43.67300000"], ["81.24000000", "49.35800000"], ["81.28000000", "69.08500000"], ["81.30000000", "45.21300000"], ["81.33000000", "55.71600000"], ["81.40000000", "50.00800000"], ["81.46000000", "1114.82500000"], ["81.50000000", "24.67600000"], ["82.00000000", "408.84100000"], ["82.10000000", "7.71800000"], ["83.00000000", "2678.69700000"], ["83.33000000", "39.72100000"], ["91.15000000", "22.26200000"], ["94.83000000", "13.25200000"], ["94.90000000", "81.93000000"], ["95.26000000", "7.76900000"]], "_local_ts_utc": "2026-06-01T07:48:59.891961+00:00"}
{"e": "depthUpdate", "E": 1780300141095, "s": "SOLUSDT", "U": 29045633106, "u": 29045633447, "b": [["80.67000000", "1215.59800000"], ["80.66000000", "577.29000000"], ["80.65000000", "767.92200000"], ["80.64000000", "133.63400000"], ["80.63000000", "215.20600000"], ["80.62000000", "466.14500000"], ["80.61000000", "2405.98700000"], ["80.60000000", "1294.53400000"], ["80.59000000", "813.39800000"], ["80.58000000", "2080.43800000"], ["80.57000000", "332.35800000"], ["80.56000000", "811.81300000"], ["80.55000000", "2004.05600000"], ["80.54000000", "244.21400000"], ["80.53000000", "648.65600000"], ["80.52000000", "736.26100000"], ["80.51000000", "2507.99600000"], ["80.50000000", "2722.36700000"], ["80.49000000", "201.18100000"], ["80.48000000", "752.38000000"], ["80.42000000", "6.70400000"], ["80.40000000", "542.47800000"], ["80.32000000", "959.10300000"], ["79.90000000", "683.43000000"]], "a": [["80.66000000", "0.00000000"], ["80.67000000", "0.00000000"], ["80.68000000", "4.38500000"], ["80.69000000", "335.63000000"], ["80.70000000", "909.22000000"], ["80.71000000", "689.13100000"], ["80.72000000", "1077.57200000"], ["80.73000000", "412.91600000"], ["80.74000000", "318.94700000"], ["80.75000000", "642.52900000"], ["80.76000000", "738.93600000"], ["80.77000000", "1933.75400000"], ["80.78000000", "402.65400000"], ["80.79000000", "316.39000000"], ["80.80000000", "99.08600000"], ["80.83000000", "106.14800000"], ["80.84000000", "59.15700000"], ["80.85000000", "493.78400000"], ["81.00000000", "81.81900000"], ["81.08000000", "36.50300000"], ["81.42000000", "5.15200000"], ["81.43000000", "6.80600000"], ["81.44000000", "7.39800000"], ["88.39000000", "3.29300000"], ["92.13000000", "8.86600000"], ["93.03000000", "5.81800000"], ["93.69000000", "16.02100000"], ["93.87000000", "15.67000000"], ["93.99000000", "11.56900000"], ["94.83000000", "14.73800000"]], "_local_ts_utc": "2026-06-01T07:48:59.991958+00:00"}
{"e": "depthUpdate", "E": 1780300141195, "s": "SOLUSDT", "U": 29045633448, "u": 29045633629, "b": [["80.67000000", "1109.46600000"], ["80.66000000", "577.38300000"], ["80.65000000", "874.35700000"], ["80.64000000", "56.48600000"], ["80.63000000", "225.02200000"], ["80.62000000", "616.04000000"], ["80.60000000", "1132.21200000"], ["80.59000000", "269.45100000"], ["80.58000000", "2070.62300000"], ["80.57000000", "224.05700000"], ["80.56000000", "390.52800000"], ["80.55000000", "3026.33400000"], ["80.54000000", "410.89100000"], ["80.53000000", "707.36600000"], ["80.52000000", "86.87100000"], ["80.51000000", "1666.52600000"], ["80.50000000", "2722.36700000"], ["80.49000000", "357.43300000"], ["80.48000000", "378.91100000"], ["80.46000000", "1584.09500000"], ["80.45000000", "37.05400000"], ["80.43000000", "93.48800000"], ["79.94000000", "989.06400000"], ["79.91000000", "4.52000000"], ["79.88000000", "166.30100000"], ["79.54000000", "47.84700000"], ["79.48000000", "489.18800000"]], "a": [["80.68000000", "1.12200000"], ["80.69000000", "301.60800000"], ["80.70000000", "979.80600000"], ["80.71000000", "695.08700000"], ["80.72000000", "1104.58500000"], ["80.73000000", "448.89000000"], ["80.75000000", "642.52900000"], ["80.76000000", "703.41900000"], ["80.77000000", "1643.54100000"], ["80.78000000", "402.58600000"], ["80.79000000", "1258.07000000"], ["80.80000000", "742.38100000"], ["80.82000000", "8.58600000"], ["80.86000000", "1091.47500000"], ["81.00000000", "81.74000000"], ["81.10000000", "258.77900000"], ["81.13000000", "4.35700000"], ["81.24000000", "49.26800000"], ["81.46000000", "1114.44700000"], ["81.51000000", "216.13900000"], ["81.53000000", "7.26600000"], ["91.21000000", "5.08900000"], ["92.13000000", "10.39500000"], ["96.06000000", "8.02000000"], ["97.77000000", "14.03700000"], ["98.00000000", "11658.21200000"], ["98.07000000", "8.75700000"]], "_local_ts_utc": "2026-06-01T07:49:00.091954+00:00"}
{"e": "depthUpdate", "E": 1780300141295, "s": "SOLUSDT", "U": 29045633630, "u": 29045633841, "b": [["80.68000000", "1096.59800000"], ["80.67000000", "726.87500000"], ["80.66000000", "602.84200000"], ["80.65000000", "860.35700000"], ["80.64000000", "54.47300000"], ["80.63000000", "140.73000000"], ["80.62000000", "69.94200000"], ["80.61000000", "2086.02200000"], ["80.42000000", "7.57900000"], ["80.40000000", "545.47800000"], ["80.09000000", "124.88500000"]], "a": [["80.68000000", "0.00000000"], ["80.69000000", "210.10000000"], ["80.70000000", "551.15800000"], ["80.71000000", "1056.54500000"], ["80.72000000", "595.63800000"], ["80.73000000", "451.00000000"], ["80.74000000", "328.76300000"], ["80.75000000", "412.27700000"], ["80.76000000", "239.40500000"], ["80.79000000", "1258.13400000"], ["80.80000000", "742.44900000"], ["80.88000000", "522.92400000"], ["80.91000000", "78.04200000"], ["81.02000000", "46.39800000"], ["81.26000000", "48.03500000"], ["81.44000000", "7.46100000"], ["81.48000000", "4.44200000"], ["88.80000000", "1097.18500000"], ["95.82000000", "13.82600000"], ["96.81000000", "12.62500000"], ["97.72000000", "10.72200000"], ["97.77000000", "14.03600000"], ["98.03000000", "18.18800000"]], "_local_ts_utc": "2026-06-01T07:49:00.191955+00:00"}
{"e": "depthUpdate", "E": 1780300141395, "s": "SOLUSDT", "U": 29045633842, "u": 29045633955, "b": [["80.68000000", "805.65200000"], ["80.67000000", "647.21800000"], ["80.66000000", "718.50300000"], ["80.65000000", "783.20900000"], ["80.64000000", "1893.64000000"], ["80.55000000", "3026.27000000"], ["80.44000000", "10.32000000"], ["80.38000000", "531.59600000"], ["80.37000000", "979.05900000"], ["80.13000000", "13.93600000"], ["80.12000000", "15.40800000"], ["79.92000000", "33.85000000"]], "a": [["80.69000000", "620.21300000"], ["80.70000000", "535.76600000"], ["80.71000000", "845.28100000"], ["80.72000000", "511.20800000"], ["80.73000000", "392.41000000"], ["80.74000000", "202.39500000"], ["80.76000000", "239.40500000"], ["80.92000000", "746.26600000"], ["80.93000000", "657.36700000"], ["96.87000000", "4.14600000"], ["97.77000000", "15.47700000"]], "_local_ts_utc": "2026-06-01T07:49:00.291965+00:00"}
{"e": "depthUpdate", "E": 1780300141495, "s": "SOLUSDT", "U": 29045633956, "u": 29045634035, "b": [["80.68000000", "806.24500000"], ["80.67000000", "634.82100000"], ["80.66000000", "718.90300000"], ["80.65000000", "667.61700000"], ["80.62000000", "69.87300000"], ["80.57000000", "304.24000000"], ["80.56000000", "220.23100000"], ["80.55000000", "1833.57100000"], ["80.54000000", "70.04900000"], ["80.53000000", "537.06900000"], ["80.37000000", "982.05900000"], ["80.35000000", "1190.12400000"]], "a": [["80.69000000", "102.83800000"], ["80.70000000", "547.93800000"], ["80.71000000", "412.07100000"], ["80.72000000", "511.20800000"], ["80.79000000", "235.85600000"], ["80.80000000", "702.22900000"], ["80.81000000", "532.03900000"]], "_local_ts_utc": "2026-06-01T07:49:00.391965+00:00"}
{"e": "depthUpdate", "E": 1780300141595, "s": "SOLUSDT", "U": 29045634036, "u": 29045634099, "b": [["80.68000000", "802.51900000"], ["80.67000000", "641.98300000"], ["80.66000000", "704.90300000"], ["80.65000000", "681.61700000"], ["80.63000000", "144.52000000"], ["80.57000000", "384.42300000"], ["80.42000000", "7.57900000"], ["80.34000000", "55.47300000"], ["80.33000000", "74.73200000"]], "a": [["80.69000000", "409.19000000"], ["80.70000000", "532.93500000"], ["80.71000000", "406.52600000"], ["80.72000000", "514.20800000"], ["80.73000000", "396.24200000"], ["80.74000000", "198.56300000"], ["80.76000000", "252.02600000"], ["80.80000000", "702.22900000"], ["80.88000000", "525.92400000"], ["80.97000000", "138.66200000"], ["80.99000000", "1219.89000000"], ["89.20000000", "274.92100000"]], "_local_ts_utc": "2026-06-01T07:49:00.491693+00:00"}
{"e": "depthUpdate", "E": 1780300141695, "s": "SOLUSDT", "U": 29045634100, "u": 29045634120, "b": [["80.67000000", "627.58600000"], ["80.66000000", "706.90300000"], ["80.57000000", "945.58000000"], ["80.56000000", "219.93100000"]], "a": [["80.69000000", "409.19000000"], ["80.70000000", "520.46300000"], ["80.75000000", "564.15800000"], ["80.89000000", "179.47900000"], ["80.91000000", "81.04200000"], ["81.23000000", "41.38500000"]], "_local_ts_utc": "2026-06-01T07:49:00.591950+00:00"}
{"e": "depthUpdate", "E": 1780300141795, "s": "SOLUSDT", "U": 29045634121, "u": 29045634160, "b": [["80.68000000", "447.63400000"], ["80.67000000", "608.12100000"], ["80.57000000", "1667.22700000"]], "a": [["80.69000000", "514.26800000"], ["80.70000000", "542.87200000"], ["80.79000000", "316.03900000"], ["80.92000000", "749.26600000"], ["80.94000000", "64.21900000"], ["81.20000000", "5.69100000"], ["81.21000000", "73.97200000"], ["89.61000000", "18.62800000"]], "_local_ts_utc": "2026-06-01T07:49:00.691974+00:00"}
{"e": "depthUpdate", "E": 1780300141895, "s": "SOLUSDT", "U": 29045634161, "u": 29045634201, "b": [["80.68000000", "156.07500000"], ["80.67000000", "616.65400000"], ["80.66000000", "709.15300000"], ["80.57000000", "1827.46900000"], ["79.23000000", "108.39700000"], ["78.92000000", "7.47700000"]], "a": [["80.69000000", "514.36500000"], ["80.70000000", "550.97200000"], ["80.71000000", "419.04100000"], ["80.76000000", "252.42700000"], ["80.77000000", "1643.14100000"], ["80.79000000", "716.95400000"], ["80.96000000", "1269.32200000"]], "_local_ts_utc": "2026-06-01T07:49:00.791931+00:00"}
{"e": "depthUpdate", "E": 1780300141995, "s": "SOLUSDT", "U": 29045634202, "u": 29045634231, "b": [["80.68000000", "143.68000000"], ["80.67000000", "475.50600000"], ["80.66000000", "705.03500000"], ["80.65000000", "675.55300000"], ["80.63000000", "156.92800000"], ["80.60000000", "1280.79300000"], ["80.49000000", "761.11300000"], ["80.41000000", "94.13600000"], ["79.99000000", "339.44400000"]], "a": [["80.69000000", "610.53700000"], ["80.70000000", "493.01000000"], ["80.71000000", "780.00000000"], ["80.72000000", "511.20800000"], ["80.79000000", "1037.68600000"]], "_local_ts_utc": "2026-06-01T07:49:00.890952+00:00"}
{"e": "depthUpdate", "E": 1780300142095, "s": "SOLUSDT", "U": 29045634232, "u": 29045634279, "b": [["80.67000000", "685.48000000"], ["80.66000000", "1049.70300000"], ["80.65000000", "1240.80500000"], ["80.63000000", "363.65400000"], ["80.62000000", "692.55100000"], ["80.61000000", "2468.33900000"], ["80.59000000", "888.03200000"], ["79.87000000", "25.24400000"]], "a": [["80.69000000", "610.67400000"], ["80.70000000", "781.17300000"], ["80.71000000", "932.59600000"], ["80.72000000", "629.55500000"], ["80.74000000", "366.96400000"], ["80.75000000", "785.91500000"], ["80.76000000", "742.90500000"], ["80.79000000", "1198.05200000"], ["81.18000000", "270.81900000"], ["81.50000000", "24.73900000"], ["81.62000000", "9.96900000"], ["83.49000000", "9.92300000"], ["90.01000000", "17.00900000"]], "_local_ts_utc": "2026-06-01T07:49:00.991948+00:00"}
{"e": "depthUpdate", "E": 1780300142195, "s": "SOLUSDT", "U": 29045634280, "u": 29045634422, "b": [["80.68000000", "0.00000000"], ["80.67000000", "182.39400000"], ["80.66000000", "693.82700000"], ["80.65000000", "814.04200000"], ["80.64000000", "537.50400000"], ["80.63000000", "350.62400000"], ["80.62000000", "696.64100000"], ["80.58000000", "2616.12200000"], ["80.56000000", "767.25200000"], ["80.51000000", "2479.15300000"], ["79.18000000", "4.35200000"], ["79.07000000", "10.36000000"]], "a": [["80.68000000", "1105.82700000"], ["80.69000000", "621.30400000"], ["80.70000000", "760.01700000"], ["80.71000000", "855.31600000"], ["80.73000000", "501.88600000"], ["80.75000000", "772.54900000"], ["80.76000000", "549.54100000"], ["80.79000000", "1197.98800000"], ["80.91000000", "80.97800000"], ["82.30000000", "1921.64800000"], ["82.43000000", "6.74700000"], ["84.69000000", "6.19400000"]], "_local_ts_utc": "2026-06-01T07:49:01.091951+00:00"}
{"e": "depthUpdate", "E": 1780300142295, "s": "SOLUSDT", "U": 29045634423, "u": 29045634532, "b": [["80.67000000", "378.93200000"], ["80.66000000", "698.23500000"], ["80.65000000", "953.97100000"], ["80.64000000", "179.54500000"], ["80.63000000", "313.60200000"], ["80.60000000", "1397.29000000"], ["80.58000000", "2150.30200000"], ["80.57000000", "671.64600000"], ["80.56000000", "219.93100000"], ["80.55000000", "2073.62400000"], ["80.54000000", "70.04900000"], ["80.52000000", "87.43900000"], ["80.51000000", "1666.52600000"], ["80.49000000", "357.43300000"], ["80.41000000", "498.21800000"], ["79.92000000", "33.91300000"], ["52.45000000", "35.95700000"]], "a": [["80.68000000", "870.18600000"], ["80.69000000", "544.62700000"], ["80.70000000", "765.49700000"], ["80.71000000", "849.83500000"], ["80.75000000", "744.94400000"], ["80.76000000", "252.02600000"], ["80.88000000", "402.11700000"], ["81.44000000", "7.39800000"], ["90.41000000", "11.12400000"]], "_local_ts_utc": "2026-06-01T07:49:01.191965+00:00"}
{"e": "depthUpdate", "E": 1780300142395, "s": "SOLUSDT", "U": 29045634533, "u": 29045634596, "b": [["80.67000000", "181.64500000"], ["80.66000000", "530.06300000"], ["80.65000000", "852.52000000"], ["80.64000000", "73.07300000"], ["80.63000000", "106.87600000"], ["80.62000000", "73.96300000"], ["80.61000000", "2086.02200000"], ["80.60000000", "1285.56900000"], ["80.59000000", "269.95100000"], ["80.58000000", "2071.12300000"], ["80.57000000", "464.60600000"], ["80.56000000", "460.10800000"], ["80.55000000", "2554.47400000"], ["80.10000000", "864.77000000"]], "a": [["80.68000000", "871.32300000"], ["80.69000000", "709.06800000"], ["80.70000000", "619.32900000"], ["80.73000000", "430.73600000"], ["80.74000000", "198.56300000"]], "_local_ts_utc": "2026-06-01T07:49:01.291962+00:00"}
{"e": "depthUpdate", "E": 1780300142495, "s": "SOLUSDT", "U": 29045634597, "u": 29045634830, "b": [["80.67000000", "0.00000000"], ["80.66000000", "0.00000000"], ["80.65000000", "221.16200000"], ["80.64000000", "245.86400000"], ["80.63000000", "106.87600000"], ["80.62000000", "1573.46400000"], ["80.61000000", "484.40200000"], ["80.60000000", "1289.35900000"], ["80.59000000", "240.19700000"], ["80.57000000", "212.42000000"], ["80.56000000", "219.93100000"], ["80.55000000", "1833.57100000"], ["80.54000000", "70.04900000"], ["80.53000000", "440.47800000"], ["80.49000000", "201.18100000"], ["80.48000000", "503.31800000"], ["80.44000000", "8.19500000"], ["80.42000000", "9.70400000"], ["79.91000000", "4.58300000"], ["64.60000000", "5.20400000"], ["64.53000000", "79.28800000"]], "a": [["80.66000000", "156.26700000"], ["80.67000000", "1177.15300000"], ["80.68000000", "870.66700000"], ["80.69000000", "674.23200000"], ["80.70000000", "617.12500000"], ["80.71000000", "847.97900000"], ["80.72000000", "625.82900000"], ["80.73000000", "561.93300000"], ["80.74000000", "198.42700000"], ["80.76000000", "253.26300000"], ["80.79000000", "235.79200000"], ["80.80000000", "59.52900000"], ["80.86000000", "967.63800000"], ["81.08000000", "36.44100000"], ["81.43000000", "6.74300000"]], "_local_ts_utc": "2026-06-01T07:49:01.392954+00:00"}
{"e": "depthUpdate", "E": 1780300142595, "s": "SOLUSDT", "U": 29045634831, "u": 29045635059, "b": [["80.65000000", "211.20700000"], ["80.64000000", "47.78700000"], ["80.63000000", "212.83300000"], ["80.62000000", "155.09300000"], ["80.61000000", "97.01100000"], ["80.59000000", "252.56900000"], ["80.58000000", "2022.91600000"], ["80.56000000", "220.43100000"], ["80.55000000", "1833.82100000"], ["80.54000000", "565.68100000"], ["80.53000000", "2070.01000000"], ["80.50000000", "2730.51000000"], ["80.48000000", "503.75200000"], ["80.46000000", "1522.77900000"], ["80.44000000", "143.99700000"], ["80.42000000", "7.64200000"], ["80.40000000", "547.60300000"], ["80.39000000", "1384.08500000"], ["80.38000000", "568.61800000"], ["80.34000000", "34.11400000"], ["80.21000000", "220.92800000"], ["80.16000000", "1431.54200000"], ["80.01000000", "620.77100000"], ["79.90000000", "683.49300000"]], "a": [["80.66000000", "3067.52400000"], ["80.67000000", "448.72300000"], ["80.68000000", "653.35100000"], ["80.69000000", "408.88400000"], ["80.70000000", "401.43000000"], ["80.71000000", "686.45600000"], ["80.72000000", "507.55100000"], ["80.73000000", "693.64800000"], ["80.74000000", "189.85000000"], ["80.75000000", "913.00700000"], ["80.76000000", "2138.20000000"], ["80.80000000", "59.46100000"], ["80.82000000", "9.05700000"], ["80.86000000", "967.20400000"], ["80.99000000", "1219.82800000"], ["81.02000000", "46.31900000"], ["81.08000000", "35.20800000"], ["81.12000000", "2599.99700000"], ["81.17000000", "6.29600000"], ["81.26000000", "47.94500000"], ["81.29000000", "988.42500000"], ["81.42000000", "5.08900000"], ["81.46000000", "237.48900000"], ["81.48000000", "4.06400000"], ["90.82000000", "8.34700000"]], "_local_ts_utc": "2026-06-01T07:49:01.491568+00:00"}
{"e": "depthUpdate", "E": 1780300142695, "s": "SOLUSDT", "U": 29045635060, "u": 29045635139, "b": [["80.65000000", "455.97200000"], ["80.64000000", "47.72300000"], ["80.63000000", "291.96300000"], ["80.62000000", "216.56700000"], ["80.61000000", "1938.70000000"], ["80.60000000", "1136.00200000"], ["80.57000000", "212.72000000"], ["80.55000000", "1833.88500000"], ["80.48000000", "600.39900000"], ["79.88000000", "13.83500000"], ["79.70000000", "510.32600000"]], "a": [["80.66000000", "2873.98600000"], ["80.67000000", "448.85500000"], ["80.68000000", "884.82600000"], ["80.69000000", "254.79000000"], ["80.70000000", "403.47700000"], ["80.71000000", "686.51800000"], ["80.75000000", "761.12600000"], ["80.77000000", "1651.34500000"], ["80.78000000", "402.65400000"], ["80.81000000", "523.85600000"], ["81.00000000", "81.81900000"], ["81.24000000", "49.35800000"], ["81.46000000", "237.86700000"]], "_local_ts_utc": "2026-06-01T07:49:01.592417+00:00"}
{"e": "depthUpdate", "E": 1780300142795, "s": "SOLUSDT", "U": 29045635140, "u": 29045635223, "b": [["80.65000000", "461.97200000"], ["80.64000000", "126.76600000"], ["80.63000000", "295.80600000"], ["80.62000000", "87.79500000"], ["80.61000000", "1924.70000000"], ["80.59000000", "248.77900000"], ["80.55000000", "1846.30100000"]], "a": [["80.66000000", "1260.14100000"], ["80.67000000", "350.82300000"], ["80.70000000", "403.53900000"], ["80.73000000", "693.64800000"], ["91.22000000", "38.14700000"]], "_local_ts_utc": "2026-06-01T07:49:01.691704+00:00"}
{"e": "depthUpdate", "E": 1780300142895, "s": "SOLUSDT", "U": 29045635224, "u": 29045635235, "b": [["80.65000000", "464.92600000"], ["80.64000000", "126.84100000"]], "a": [["80.66000000", "1257.08600000"], ["80.67000000", "415.88500000"]], "_local_ts_utc": "2026-06-01T07:49:01.791937+00:00"}
{"e": "depthUpdate", "E": 1780300142995, "s": "SOLUSDT", "U": 29045635236, "u": 29045635318, "b": [["80.65000000", "551.25300000"], ["80.64000000", "78.67800000"], ["80.63000000", "311.70600000"], ["80.62000000", "73.79500000"], ["80.61000000", "1961.72200000"], ["80.60000000", "1144.62300000"], ["80.56000000", "368.02600000"], ["80.52000000", "138.03800000"]], "a": [["80.66000000", "1083.62200000"], ["80.67000000", "420.86500000"], ["80.68000000", "878.88400000"], ["80.71000000", "837.26000000"], ["80.73000000", "693.64800000"], ["80.75000000", "593.06300000"], ["80.77000000", "1819.15900000"], ["80.78000000", "454.37700000"]], "_local_ts_utc": "2026-06-01T07:49:01.891648+00:00"}
{"e": "depthUpdate", "E": 1780300143095, "s": "SOLUSDT", "U": 29045635319, "u": 29045635409, "b": [["80.65000000", "561.32200000"], ["80.64000000", "205.91200000"], ["80.63000000", "497.19900000"], ["80.62000000", "659.36900000"], ["80.61000000", "2303.39200000"], ["80.60000000", "1399.13000000"], ["80.59000000", "852.61900000"], ["80.57000000", "487.08500000"], ["80.56000000", "919.14700000"], ["80.55000000", "2178.01100000"], ["80.54000000", "1183.57900000"], ["80.53000000", "2211.96800000"], ["80.52000000", "878.79100000"], ["80.51000000", "2481.58300000"], ["80.50000000", "2877.29800000"], ["80.49000000", "453.36200000"], ["80.48000000", "973.43400000"], ["80.35000000", "1189.91900000"]], "a": [["80.66000000", "1079.96600000"], ["80.67000000", "678.95400000"], ["80.68000000", "781.59800000"], ["80.69000000", "652.57700000"], ["80.70000000", "653.46100000"], ["80.71000000", "918.96100000"], ["80.72000000", "714.60500000"], ["80.74000000", "535.12200000"], ["80.75000000", "631.45200000"], ["80.80000000", "59.46100000"], ["80.82000000", "9.05700000"], ["81.60000000", "10.62400000"], ["82.09000000", "1.04100000"], ["84.74000000", "7.47900000"], ["84.96000000", "6.94500000"], ["91.62000000", "4.63300000"]], "_local_ts_utc": "2026-06-01T07:49:01.991953+00:00"}
{"e": "depthUpdate", "E": 1780300143195, "s": "SOLUSDT", "U": 29045635410, "u": 29045635440, "b": [["80.65000000", "486.72700000"], ["80.64000000", "203.91200000"], ["80.63000000", "499.19000000"], ["80.58000000", "2161.67100000"], ["80.53000000", "2108.39900000"], ["80.52000000", "176.42700000"], ["80.51000000", "1666.52600000"], ["80.50000000", "2730.51000000"], ["80.49000000", "201.18100000"], ["80.48000000", "600.39900000"], ["78.20000000", "285.75700000"]], "a": [["80.66000000", "1079.92300000"], ["80.67000000", "678.78600000"], ["80.69000000", "651.33600000"], ["80.71000000", "994.29700000"], ["80.74000000", "260.37700000"], ["80.75000000", "593.06300000"]], "_local_ts_utc": "2026-06-01T07:49:02.092027+00:00"}
{"e": "depthUpdate", "E": 1780300143295, "s": "SOLUSDT", "U": 29045635441, "u": 29045635479, "b": [["80.65000000", "364.29600000"], ["80.64000000", "267.67800000"], ["80.63000000", "485.19000000"], ["80.62000000", "673.36900000"], ["80.57000000", "486.78500000"], ["80.56000000", "771.05200000"], ["79.70000000", "507.22100000"], ["79.53000000", "42.18400000"], ["78.63000000", "27.52100000"]], "a": [["80.66000000", "1296.04500000"], ["80.67000000", "666.78600000"], ["80.68000000", "1010.24900000"], ["80.69000000", "425.24900000"], ["92.03000000", "9.25400000"]], "_local_ts_utc": "2026-06-01T07:49:02.191944+00:00"}
{"e": "depthUpdate", "E": 1780300143395, "s": "SOLUSDT", "U": 29045635480, "u": 29045635550, "b": [["80.65000000", "454.71600000"], ["80.64000000", "165.86600000"], ["80.63000000", "317.51600000"], ["80.62000000", "673.50500000"], ["80.61000000", "2303.52800000"], ["80.60000000", "1217.94200000"], ["80.59000000", "852.75500000"], ["80.58000000", "2036.60200000"], ["80.57000000", "317.40400000"], ["80.56000000", "919.26900000"], ["80.55000000", "1884.69000000"], ["80.54000000", "565.68100000"], ["80.53000000", "2070.01000000"], ["80.52000000", "138.03800000"], ["80.51000000", "1666.52600000"], ["80.35000000", "1189.98800000"], ["79.70000000", "504.11600000"], ["79.53000000", "39.07200000"], ["79.06000000", "19.19700000"]], "a": [["80.66000000", "1299.70100000"], ["80.67000000", "668.13200000"], ["80.68000000", "955.24700000"], ["80.69000000", "293.24200000"], ["80.71000000", "990.64100000"], ["80.74000000", "191.58700000"], ["81.17000000", "6.22800000"]], "_local_ts_utc": "2026-06-01T07:49:02.291953+00:00"}
{"e": "depthUpdate", "E": 1780300143495, "s": "SOLUSDT", "U": 29045635551, "u": 29045635570, "b": [["80.65000000", "304.29600000"], ["80.64000000", "166.04400000"], ["80.63000000", "314.39500000"], ["80.62000000", "676.63800000"], ["80.55000000", "1846.30100000"]], "a": [["80.67000000", "668.13200000"], ["80.68000000", "919.27400000"], ["80.70000000", "653.06100000"], ["80.71000000", "837.26000000"], ["80.72000000", "507.55100000"]], "_local_ts_utc": "2026-06-01T07:49:02.391749+00:00"}
{"e": "depthUpdate", "E": 1780300143595, "s": "SOLUSDT", "U": 29045635571, "u": 29045635592, "b": [["80.65000000", "201.75600000"], ["80.64000000", "169.80800000"], ["80.63000000", "312.52700000"], ["80.62000000", "677.52500000"], ["80.61000000", "2266.50600000"], ["80.57000000", "317.54000000"]], "a": [["80.66000000", "1362.62600000"], ["80.67000000", "605.07000000"], ["92.43000000", "2.91800000"]], "_local_ts_utc": "2026-06-01T07:49:02.491206+00:00"}
{"e": "depthUpdate", "E": 1780300143695, "s": "SOLUSDT", "U": 29045635593, "u": 29045635615, "b": [["80.64000000", "102.45600000"], ["80.63000000", "290.49900000"], ["80.62000000", "91.95100000"], ["80.61000000", "1924.83600000"], ["80.60000000", "1148.54900000"], ["80.59000000", "252.70500000"], ["80.58000000", "2023.05200000"], ["80.57000000", "212.55600000"], ["80.56000000", "368.64800000"], ["80.02000000", "767.46600000"]], "a": [["80.66000000", "1357.62600000"]], "_local_ts_utc": "2026-06-01T07:49:02.591774+00:00"}
{"e": "depthUpdate", "E": 1780300143795, "s": "SOLUSDT", "U": 29045635616, "u": 29045635647, "b": [["80.65000000", "398.91600000"], ["80.64000000", "102.59200000"], ["80.63000000", "353.56100000"], ["80.62000000", "89.93100000"], ["80.60000000", "1136.13800000"], ["80.59000000", "253.00500000"], ["80.57000000", "212.42000000"], ["80.56000000", "220.43100000"], ["80.50000000", "2950.51000000"], ["80.45000000", "99.97200000"], ["79.72000000", "34.79500000"], ["79.55000000", "377.91000000"], ["79.08000000", "8.11500000"], ["78.66000000", "671.09500000"]], "a": [["80.66000000", "1345.35000000"], ["80.67000000", "580.27400000"], ["80.69000000", "254.85300000"], ["80.70000000", "403.13900000"], ["80.71000000", "689.61000000"], ["81.71000000", "9.37400000"], ["92.83000000", "7.75100000"]], "_local_ts_utc": "2026-06-01T07:49:02.691942+00:00"}
{"e": "depthUpdate", "E": 1780300143895, "s": "SOLUSDT", "U": 29045635648, "u": 29045635658, "b": [["80.64000000", "64.20300000"], ["80.63000000", "355.56100000"], ["80.62000000", "91.04700000"]], "a": [["80.66000000", "1234.56300000"], ["80.67000000", "605.07000000"]], "_local_ts_utc": "2026-06-01T07:49:02.792610+00:00"}
{"e": "depthUpdate", "E": 1780300143995, "s": "SOLUSDT", "U": 29045635659, "u": 29045635679, "b": [["80.65000000", "499.72700000"], ["80.64000000", "76.60200000"], ["80.63000000", "359.59600000"], ["80.62000000", "87.93100000"], ["80.61000000", "1937.25000000"], ["80.58000000", "2169.52000000"], ["80.41000000", "94.13600000"], ["80.36000000", "496.22200000"], ["79.70000000", "497.90600000"], ["79.53000000", "35.96000000"], ["79.05000000", "117.87400000"], ["78.64000000", "82.16600000"], ["78.63000000", "24.37400000"]], "a": [["80.67000000", "604.54400000"], ["80.71000000", "842.90900000"], ["80.80000000", "67.58200000"], ["88.12000000", "14.44500000"]], "_local_ts_utc": "2026-06-01T07:49:02.890945+00:00"}
{"e": "depthUpdate", "E": 1780300144095, "s": "SOLUSDT", "U": 29045635680, "u": 29045635734, "b": [["80.65000000", "500.05600000"], ["80.64000000", "236.93400000"], ["80.63000000", "492.16400000"], ["80.62000000", "666.20000000"], ["80.61000000", "2276.38700000"], ["80.59000000", "896.77600000"], ["80.58000000", "2232.79100000"], ["80.56000000", "771.55200000"], ["80.54000000", "1183.55800000"], ["80.53000000", "2069.94000000"], ["80.40000000", "542.60300000"]], "a": [["80.66000000", "1234.56300000"], ["80.67000000", "604.54400000"], ["80.68000000", "952.05100000"], ["80.70000000", "654.74700000"], ["80.72000000", "714.60500000"], ["80.74000000", "337.45000000"], ["80.75000000", "1231.31600000"], ["80.80000000", "105.97100000"], ["80.82000000", "40.74200000"], ["80.85000000", "493.38300000"], ["93.24000000", "2.67000000"]], "_local_ts_utc": "2026-06-01T07:49:02.992091+00:00"}
{"e": "depthUpdate", "E": 1780300144195, "s": "SOLUSDT", "U": 29045635735, "u": 29045635772, "b": [["80.65000000", "400.21400000"], ["80.60000000", "1403.82600000"], ["80.58000000", "2293.56800000"], ["80.57000000", "442.72800000"], ["80.55000000", "2199.59300000"], ["80.34000000", "33.30900000"], ["79.88000000", "13.58100000"], ["79.84000000", "7.32700000"], ["79.70000000", "491.69600000"], ["79.53000000", "32.84800000"], ["79.05000000", "114.74400000"]], "a": [["80.66000000", "1234.31600000"], ["80.68000000", "1017.65900000"], ["80.69000000", "488.68400000"], ["80.71000000", "1045.28900000"], ["80.73000000", "748.94600000"], ["80.74000000", "337.45000000"], ["80.75000000", "593.06300000"], ["80.80000000", "67.58200000"], ["80.82000000", "9.05700000"]], "_local_ts_utc": "2026-06-01T07:49:03.092112+00:00"}
{"e": "depthUpdate", "E": 1780300144295, "s": "SOLUSDT", "U": 29045635773, "u": 29045635790, "b": [["80.65000000", "201.88000000"], ["80.64000000", "237.52000000"], ["80.63000000", "487.99700000"], ["80.62000000", "668.86400000"], ["80.58000000", "2147.10000000"], ["80.57000000", "442.86400000"]], "a": [["80.66000000", "1233.62800000"], ["80.67000000", "605.07000000"], ["80.68000000", "1020.75100000"], ["80.71000000", "1042.19700000"], ["82.83000000", "7.26700000"], ["93.64000000", "10.72400000"]], "_local_ts_utc": "2026-06-01T07:49:03.191931+00:00"}
{"e": "depthUpdate", "E": 1780300144395, "s": "SOLUSDT", "U": 29045635791, "u": 29045635985, "b": [["80.65000000", "659.51200000"], ["80.64000000", "168.09400000"], ["80.63000000", "430.85100000"], ["80.62000000", "1010.15900000"], ["80.61000000", "1943.03600000"], ["80.60000000", "1190.56300000"], ["80.59000000", "896.77600000"], ["80.58000000", "2146.96400000"], ["80.57000000", "442.72800000"], ["80.56000000", "771.05200000"], ["80.55000000", "2199.38600000"], ["80.52000000", "214.81600000"], ["80.51000000", "2534.24500000"], ["80.48000000", "600.39900000"]], "a": [["80.66000000", "1059.17500000"], ["80.67000000", "395.67000000"], ["80.68000000", "281.45800000"], ["80.69000000", "254.85300000"], ["80.70000000", "764.63100000"], ["80.71000000", "328.55900000"], ["80.72000000", "507.55100000"], ["80.73000000", "561.86000000"], ["80.74000000", "547.80900000"], ["80.75000000", "235.10400000"], ["80.76000000", "2270.11700000"], ["80.77000000", "337.95100000"], ["80.78000000", "1935.58500000"], ["81.05000000", "369.57100000"]], "_local_ts_utc": "2026-06-01T07:49:03.291888+00:00"}
{"e": "depthUpdate", "E": 1780300144495, "s": "SOLUSDT", "U": 29045635986, "u": 29045636032, "b": [["80.65000000", "738.57400000"], ["80.64000000", "139.61200000"], ["80.58000000", "2022.91600000"], ["80.57000000", "226.28500000"], ["80.55000000", "1846.09400000"], ["80.54000000", "565.68100000"], ["80.52000000", "138.03800000"], ["80.51000000", "1666.52600000"]], "a": [["80.66000000", "942.06500000"], ["80.67000000", "348.37000000"], ["80.68000000", "573.91900000"], ["80.71000000", "332.27400000"], ["80.76000000", "2242.13100000"]], "_local_ts_utc": "2026-06-01T07:49:03.391943+00:00"}
{"e": "depthUpdate", "E": 1780300144595, "s": "SOLUSDT", "U": 29045636033, "u": 29045636092, "b": [["80.65000000", "729.07400000"], ["80.64000000", "139.48000000"], ["80.57000000", "225.78500000"], ["80.47000000", "1388.66000000"], ["80.44000000", "8.19500000"], ["79.53000000", "29.73600000"], ["79.48000000", "61.56700000"], ["79.46000000", "464.55700000"]], "a": [["80.66000000", "941.71100000"], ["80.67000000", "357.76700000"], ["80.68000000", "601.46200000"], ["80.71000000", "335.36600000"], ["80.73000000", "437.96300000"], ["80.74000000", "547.80900000"], ["80.76000000", "729.56400000"], ["80.78000000", "3447.52700000"], ["80.86000000", "1091.04200000"], ["80.97000000", "1090.01600000"], ["94.05000000", "3.44600000"]], "_local_ts_utc": "2026-06-01T07:49:03.491553+00:00"}
{"e": "depthUpdate", "E": 1780300144695, "s": "SOLUSDT", "U": 29045636093, "u": 29045636111, "b": [["80.64000000", "127.07900000"], ["80.57000000", "211.92000000"], ["80.56000000", "372.81300000"], ["80.34000000", "33.37800000"], ["79.70000000", "488.59100000"], ["79.04000000", "24.73200000"], ["78.63000000", "21.22700000"], ["78.23000000", "7.15500000"]], "a": [["80.66000000", "941.96100000"], ["80.67000000", "345.37000000"], ["80.68000000", "342.80100000"], ["80.69000000", "488.67200000"], ["80.72000000", "660.42200000"], ["80.89000000", "181.58000000"], ["81.02000000", "44.22100000"], ["81.35000000", "47.16100000"], ["81.38000000", "404.92700000"]], "_local_ts_utc": "2026-06-01T07:49:03.591434+00:00"}
{"e": "depthUpdate", "E": 1780300144795, "s": "SOLUSDT", "U": 29045636112, "u": 29045636119, "b": [["80.64000000", "139.48000000"], ["80.59000000", "896.47600000"], ["72.58000000", "13.42600000"]], "a": [["80.67000000", "357.76700000"], ["80.69000000", "488.74100000"], ["80.71000000", "335.56600000"], ["81.16000000", "42.23100000"], ["94.45000000", "339.99100000"]], "_local_ts_utc": "2026-06-01T07:49:03.691770+00:00"}
{"e": "depthUpdate", "E": 1780300144895, "s": "SOLUSDT", "U": 29045636120, "u": 29045636128, "b": [["80.65000000", "739.00500000"], ["72.58000000", "13.35000000"]], "a": [["80.67000000", "357.68700000"], ["80.68000000", "341.56000000"]], "_local_ts_utc": "2026-06-01T07:49:03.791938+00:00"}
{"e": "depthUpdate", "E": 1780300144995, "s": "SOLUSDT", "U": 29045636129, "u": 29045636137, "b": [["80.65000000", "741.40500000"], ["80.64000000", "127.07900000"], ["80.61000000", "1955.45100000"], ["80.56000000", "219.93100000"], ["78.63000000", "24.40000000"]], "a": [["80.67000000", "345.29000000"], ["80.68000000", "353.95500000"], ["80.72000000", "660.62200000"]], "_local_ts_utc": "2026-06-01T07:49:03.891787+00:00"}
{"e": "depthUpdate", "E": 1780300145095, "s": "SOLUSDT", "U": 29045636138, "u": 29045636186, "b": [["80.65000000", "506.15000000"], ["80.64000000", "125.21100000"], ["80.63000000", "432.85100000"], ["80.58000000", "2023.05200000"], ["80.56000000", "770.99000000"], ["80.51000000", "2547.25300000"], ["80.48000000", "1014.91400000"], ["80.42000000", "7.71200000"], ["80.41000000", "498.21800000"], ["80.36000000", "91.88900000"], ["80.32000000", "959.30300000"], ["79.04000000", "27.88900000"], ["78.63000000", "27.57300000"]], "a": [["80.66000000", "941.84700000"], ["80.67000000", "407.72900000"], ["80.68000000", "437.02100000"], ["80.69000000", "718.22400000"], ["80.71000000", "532.76200000"], ["80.72000000", "840.18400000"], ["80.73000000", "601.54800000"], ["94.85000000", "32.69900000"]], "_local_ts_utc": "2026-06-01T07:49:03.991935+00:00"}
{"e": "depthUpdate", "E": 1780300145195, "s": "SOLUSDT", "U": 29045636187, "u": 29045636256, "b": [["80.65000000", "604.48300000"], ["80.64000000", "244.79800000"], ["80.63000000", "434.71800000"], ["80.61000000", "1943.03600000"], ["80.58000000", "2155.00700000"], ["80.57000000", "442.56100000"], ["80.55000000", "2177.87300000"], ["80.54000000", "1183.80800000"], ["80.53000000", "2329.61600000"], ["80.52000000", "884.52800000"], ["80.50000000", "3100.99400000"], ["80.49000000", "504.13300000"], ["80.31000000", "1257.53000000"], ["80.25000000", "244.01600000"], ["78.23000000", "10.34500000"]], "a": [["80.66000000", "945.49100000"], ["80.67000000", "562.58500000"], ["80.68000000", "674.19100000"], ["80.69000000", "483.16400000"], ["80.70000000", "923.66000000"], ["80.71000000", "529.04700000"], ["81.17000000", "6.02800000"]], "_local_ts_utc": "2026-06-01T07:49:04.091823+00:00"}
{"e": "depthUpdate", "E": 1780300145295, "s": "SOLUSDT", "U": 29045636257, "u": 29045636332, "b": [["80.65000000", "371.64300000"], ["80.64000000", "181.49200000"], ["80.63000000", "423.36900000"], ["80.62000000", "1024.15900000"], ["80.60000000", "1194.65300000"], ["80.58000000", "2155.00700000"], ["80.57000000", "490.41500000"]], "a": [["80.66000000", "1046.07800000"], ["80.67000000", "596.38900000"], ["80.68000000", "677.73200000"], ["80.70000000", "920.12700000"], ["80.72000000", "687.31300000"], ["95.26000000", "10.29800000"]], "_local_ts_utc": "2026-06-01T07:49:04.191969+00:00"}
{"e": "depthUpdate", "E": 1780300145395, "s": "SOLUSDT", "U": 29045636333, "u": 29045636414, "b": [["80.65000000", "201.62100000"], ["80.64000000", "188.27700000"], ["80.63000000", "416.98300000"], ["80.62000000", "1014.22800000"], ["80.61000000", "1920.01400000"], ["80.58000000", "2155.00700000"], ["80.57000000", "490.41500000"], ["80.55000000", "2164.00800000"], ["80.08000000", "47.61100000"], ["80.07000000", "203.46800000"]], "a": [["80.66000000", "1249.87800000"], ["80.67000000", "438.98200000"], ["80.68000000", "605.75000000"], ["80.70000000", "855.24800000"], ["80.71000000", "525.95500000"], ["80.72000000", "783.07500000"], ["80.73000000", "725.58000000"], ["80.75000000", "452.87900000"], ["80.76000000", "881.47100000"], ["80.77000000", "549.67400000"], ["80.86000000", "967.20400000"]], "_local_ts_utc": "2026-06-01T07:49:04.292045+00:00"}
{"e": "depthUpdate", "E": 1780300145508, "s": "SOLUSDT", "U": 29045636415, "u": 29045636779, "b": [["80.65000000", "0.00000000"], ["80.64000000", "0.00000000"], ["80.63000000", "589.87000000"], ["80.62000000", "141.89800000"], ["80.61000000", "498.85800000"], ["80.60000000", "1208.65300000"], ["80.59000000", "865.86200000"], ["80.58000000", "2042.24400000"], ["80.57000000", "273.37200000"], ["80.56000000", "681.62600000"], ["80.55000000", "1934.17600000"], ["80.54000000", "679.99300000"], ["80.53000000", "2069.94000000"], ["80.52000000", "1073.89800000"], ["80.50000000", "2958.85500000"], ["80.49000000", "111.27400000"], ["80.47000000", "1249.70000000"], ["80.43000000", "230.83900000"], ["80.37000000", "9.87700000"], ["80.29000000", "7.73100000"], ["80.25000000", "274.21600000"], ["80.24000000", "42.35600000"], ["79.94000000", "11.28800000"], ["79.89000000", "12.89000000"], ["79.88000000", "991.91000000"]], "a": [["80.64000000", "1424.40500000"], ["80.65000000", "587.59800000"], ["80.66000000", "1088.15400000"], ["80.67000000", "674.25700000"], ["80.68000000", "520.46400000"], ["80.69000000", "1736.00300000"], ["80.70000000", "754.93100000"], ["80.71000000", "233.13800000"], ["80.72000000", "443.86100000"], ["80.73000000", "435.32900000"], ["80.74000000", "416.13700000"], ["80.75000000", "226.35000000"], ["80.76000000", "597.52400000"], ["80.77000000", "337.95100000"], ["80.78000000", "1966.31900000"], ["80.82000000", "6.05700000"], ["80.83000000", "106.08600000"], ["80.84000000", "199.95600000"], ["80.85000000", "493.04000000"], ["80.86000000", "967.11100000"], ["80.87000000", "37.21700000"], ["80.88000000", "1640.09300000"], ["80.89000000", "175.58000000"], ["80.91000000", "82.04100000"], ["80.94000000", "64.15500000"], ["81.05000000", "332.54900000"], ["81.06000000", "52.61600000"], ["81.12000000", "1365.68200000"], ["81.39000000", "186.46500000"], ["81.40000000", "49.88300000"], ["81.41000000", "3.87600000"], ["81.61000000", "0.60000000"], ["81.69000000", "3.55700000"], ["81.84000000", "497.91200000"], ["81.87000000", "3.54500000"], ["98.00000000", "11661.92800000"]], "_local_ts_utc": "2026-06-01T07:49:04.404947+00:00"}
{"e": "depthUpdate", "E": 1780300145595, "s": "SOLUSDT", "U": 29045636780, "u": 29045637100, "b": [["80.64000000", "682.61200000"], ["80.63000000", "525.27200000"], ["80.62000000", "88.42600000"], ["80.61000000", "645.15200000"], ["80.60000000", "1136.43800000"], ["80.59000000", "94.00600000"], ["80.58000000", "2019.59900000"], ["80.57000000", "212.49500000"], ["80.56000000", "130.43100000"], ["80.55000000", "1778.68500000"], ["80.54000000", "62.11600000"], ["80.53000000", "2069.94000000"], ["80.52000000", "423.50300000"], ["80.51000000", "1666.52600000"], ["80.50000000", "2942.09900000"], ["80.49000000", "55.53500000"], ["80.48000000", "600.39900000"], ["80.46000000", "1647.20600000"], ["80.44000000", "98.19500000"], ["79.88000000", "991.84700000"], ["79.63000000", "369.08200000"]], "a": [["80.64000000", "0.00000000"], ["80.65000000", "742.27400000"], ["80.66000000", "1111.12000000"], ["80.67000000", "318.77900000"], ["80.68000000", "518.41700000"], ["80.69000000", "258.96500000"], ["80.71000000", "276.10200000"], ["80.72000000", "448.33500000"], ["80.73000000", "1916.90900000"], ["80.78000000", "1798.31300000"], ["80.80000000", "100.34400000"], ["80.81000000", "523.79400000"], ["80.82000000", "6.17900000"], ["80.85000000", "459.98400000"], ["80.92000000", "749.33700000"], ["80.94000000", "65.49400000"], ["80.96000000", "1269.38700000"], ["81.00000000", "81.74000000"], ["81.01000000", "44.35100000"], ["81.13000000", "4.43100000"], ["81.16000000", "42.61600000"], ["81.17000000", "6.09300000"], ["81.22000000", "43.76300000"], ["81.24000000", "49.26800000"], ["81.26000000", "48.06900000"], ["81.27000000", "49.63600000"], ["81.29000000", "988.65900000"], ["81.30000000", "45.27800000"], ["81.40000000", "9.44600000"], ["81.44000000", "7.77600000"], ["81.46000000", "237.48900000"], ["81.57000000", "6.56400000"], ["81.58000000", "241.64800000"], ["81.61000000", "1.23700000"], ["82.14000000", "4.35700000"], ["82.28000000", "5.57800000"], ["82.52000000", "8.26700000"], ["83.96000000", "78.29100000"], ["95.66000000", "8.86700000"]], "_local_ts_utc": "2026-06-01T07:49:04.491945+00:00"}
{"e": "depthUpdate", "E": 1780300145695, "s": "SOLUSDT", "U": 29045637101, "u": 29045637154, "b": [["80.64000000", "508.27600000"], ["80.63000000", "507.94900000"], ["80.62000000", "344.20400000"], ["80.61000000", "452.28000000"], ["80.57000000", "359.08600000"], ["80.53000000", "2069.76200000"], ["80.46000000", "1647.38400000"], ["80.42000000", "7.58600000"], ["79.70000000", "485.48600000"], ["79.22000000", "75.71600000"], ["79.04000000", "24.75800000"], ["79.02000000", "110.16000000"], ["78.94000000", "10.55700000"], ["78.82000000", "6.17200000"]], "a": [["80.65000000", "780.16600000"], ["80.66000000", "1115.19600000"], ["80.69000000", "299.46500000"], ["80.70000000", "754.86900000"], ["80.72000000", "448.27300000"], ["80.75000000", "256.89900000"], ["80.76000000", "597.59200000"], ["80.80000000", "100.28200000"], ["80.81000000", "523.73200000"], ["80.83000000", "106.02400000"], ["80.94000000", "65.43200000"], ["80.97000000", "1089.95400000"], ["80.98000000", "47.43200000"], ["80.99000000", "1219.65000000"], ["81.37000000", "2.55900000"]], "_local_ts_utc": "2026-06-01T07:49:04.591946+00:00"}
{"e": "depthUpdate", "E": 1780300145795, "s": "SOLUSDT", "U": 29045637155, "u": 29045637247, "b": [["80.64000000", "601.98700000"], ["80.63000000", "523.42200000"], ["80.62000000", "280.74100000"], ["80.61000000", "438.28000000"], ["80.60000000", "1136.13800000"], ["80.59000000", "127.23800000"], ["80.57000000", "358.95000000"], ["80.48000000", "746.08100000"], ["80.37000000", "9.94000000"], ["80.35000000", "2162.89600000"], ["79.95000000", "270.32900000"], ["79.93000000", "129.02000000"], ["79.70000000", "482.38100000"], ["79.53000000", "23.51200000"], ["79.02000000", "113.31800000"], ["78.58000000", "19.20900000"], ["78.57000000", "94.99000000"]], "a": [["80.65000000", "397.51300000"], ["80.66000000", "1145.51800000"], ["80.67000000", "341.17600000"], ["80.72000000", "298.79200000"], ["80.73000000", "1916.53700000"], ["80.76000000", "597.52400000"], ["80.89000000", "175.75800000"], ["80.98000000", "47.35300000"], ["81.22000000", "43.67300000"], ["81.44000000", "7.39800000"], ["81.45000000", "3.64700000"], ["96.06000000", "11.08000000"]], "_local_ts_utc": "2026-06-01T07:49:04.691772+00:00"}
{"e": "depthUpdate", "E": 1780300145895, "s": "SOLUSDT", "U": 29045637248, "u": 29045637293, "b": [["80.64000000", "590.59200000"], ["80.63000000", "462.55500000"], ["80.61000000", "438.39500000"], ["80.60000000", "1210.59300000"], ["80.57000000", "212.49500000"]], "a": [["80.65000000", "318.21900000"], ["80.66000000", "1127.78100000"], ["80.67000000", "344.34200000"], ["80.68000000", "518.41700000"], ["80.70000000", "756.86600000"], ["80.77000000", "338.01900000"], ["80.99000000", "1219.72900000"], ["81.11000000", "3081.94200000"], ["81.23000000", "41.47500000"]], "_local_ts_utc": "2026-06-01T07:49:04.791944+00:00"}
{"e": "depthUpdate", "E": 1780300145995, "s": "SOLUSDT", "U": 29045637294, "u": 29045637324, "b": [["80.64000000", "590.45600000"], ["80.63000000", "534.50000000"], ["80.62000000", "280.74100000"], ["80.61000000", "436.28800000"], ["80.59000000", "127.23800000"], ["80.58000000", "2021.70700000"], ["80.57000000", "362.39500000"], ["80.55000000", "1791.19600000"], ["79.93000000", "122.82800000"], ["78.62000000", "25.75700000"], ["78.56000000", "42.08500000"], ["78.22000000", "17.57200000"]], "a": [["80.66000000", "1132.42500000"], ["80.67000000", "338.17600000"], ["80.71000000", "422.59200000"]], "_local_ts_utc": "2026-06-01T07:49:04.891783+00:00"}
{"e": "depthUpdate", "E": 1780300146096, "s": "SOLUSDT", "U": 29045637325, "u": 29045637448, "b": [["80.64000000", "47.63200000"], ["80.63000000", "448.12800000"], ["80.62000000", "490.92700000"], ["80.61000000", "815.71700000"], ["80.56000000", "130.56700000"], ["80.33000000", "74.80100000"], ["78.23000000", "13.53500000"]], "a": [["80.65000000", "642.29500000"], ["80.66000000", "1255.13000000"], ["80.67000000", "665.88200000"], ["80.68000000", "279.39500000"], ["80.69000000", "525.39000000"], ["80.70000000", "943.37800000"], ["80.71000000", "682.54900000"], ["80.72000000", "870.87800000"], ["80.73000000", "2032.84200000"], ["80.77000000", "338.01900000"], ["80.78000000", "1797.28200000"], ["80.79000000", "234.76100000"], ["80.81000000", "523.65700000"], ["81.15000000", "3.45500000"], ["96.47000000", "11.34900000"]], "_local_ts_utc": "2026-06-01T07:49:04.992973+00:00"}
{"e": "depthUpdate", "E": 1780300146195, "s": "SOLUSDT", "U": 29045637449, "u": 29045637627, "b": [["80.64000000", "0.00000000"], ["80.63000000", "343.75000000"], ["80.62000000", "360.55900000"], ["80.61000000", "577.33800000"], ["80.60000000", "1346.42300000"], ["80.59000000", "685.14800000"], ["80.58000000", "2192.94600000"], ["80.57000000", "560.96900000"], ["80.56000000", "665.23900000"], ["80.55000000", "1993.81700000"], ["80.54000000", "737.23900000"], ["80.53000000", "2236.87200000"], ["80.52000000", "1144.72000000"], ["80.51000000", "2432.70500000"], ["80.49000000", "416.34700000"], ["80.48000000", "1208.75100000"], ["80.47000000", "1288.08900000"], ["79.93000000", "119.73200000"], ["79.88000000", "991.91000000"], ["79.54000000", "44.73600000"], ["79.07000000", "7.23000000"], ["78.63000000", "24.42600000"], ["78.56000000", "38.90900000"]], "a": [["80.64000000", "875.62200000"], ["80.65000000", "712.78200000"], ["80.66000000", "1516.21200000"], ["80.67000000", "431.99900000"], ["80.68000000", "436.22400000"], ["80.69000000", "523.26700000"], ["80.71000000", "573.41300000"], ["80.72000000", "418.10400000"], ["80.73000000", "1916.53700000"], ["81.33000000", "62.49300000"], ["81.51000000", "2.66900000"], ["81.74000000", "5.91600000"]], "_local_ts_utc": "2026-06-01T07:49:05.091944+00:00"}
{"e": "depthUpdate", "E": 1780300146295, "s": "SOLUSDT", "U": 29045637628, "u": 29045637878, "b": [["80.64000000", "1399.24400000"], ["80.63000000", "582.94800000"], ["80.62000000", "251.67900000"], ["80.61000000", "633.86600000"], ["80.60000000", "1136.13800000"], ["80.59000000", "131.02800000"], ["80.58000000", "2022.00700000"], ["80.57000000", "362.25900000"], ["80.56000000", "130.43100000"], ["80.55000000", "1778.68500000"], ["80.54000000", "119.41500000"], ["80.53000000", "2069.76200000"], ["80.52000000", "423.50300000"], ["80.51000000", "1666.52600000"], ["80.50000000", "2942.09900000"], ["80.49000000", "55.53500000"], ["80.48000000", "746.08100000"], ["80.47000000", "1249.70000000"], ["79.93000000", "116.63600000"], ["79.72000000", "31.69100000"], ["78.22000000", "20.76200000"]], "a": [["80.64000000", "0.00000000"], ["80.65000000", "231.96900000"], ["80.66000000", "1153.40400000"], ["80.67000000", "689.79600000"], ["80.68000000", "433.71600000"], ["80.69000000", "525.39000000"], ["80.70000000", "793.25800000"], ["80.71000000", "427.05900000"], ["80.72000000", "298.55500000"], ["80.77000000", "337.95100000"], ["80.99000000", "1219.65000000"], ["81.05000000", "336.76400000"], ["81.23000000", "41.38500000"], ["81.40000000", "9.44600000"], ["81.44000000", "7.77600000"], ["81.45000000", "3.26900000"], ["82.82000000", "437.41500000"], ["96.87000000", "7.84900000"]], "_local_ts_utc": "2026-06-01T07:49:05.191943+00:00"}
{"e": "depthUpdate", "E": 1780300146395, "s": "SOLUSDT", "U": 29045637879, "u": 29045637950, "b": [["80.64000000", "1359.90500000"], ["80.63000000", "423.06900000"], ["80.62000000", "311.24300000"], ["80.61000000", "556.72200000"], ["80.60000000", "1210.58400000"], ["80.59000000", "127.23800000"], ["80.57000000", "212.49500000"], ["80.56000000", "129.93100000"], ["80.09000000", "124.94800000"], ["79.88000000", "991.84700000"]], "a": [["80.65000000", "383.84000000"], ["80.66000000", "1149.99800000"], ["80.67000000", "650.98800000"], ["80.68000000", "283.57800000"], ["80.69000000", "299.46500000"], ["80.70000000", "908.55900000"], ["80.71000000", "276.10200000"], ["80.72000000", "298.41900000"], ["80.73000000", "1916.92000000"], ["80.76000000", "597.52400000"], ["80.98000000", "47.35300000"], ["81.22000000", "43.67300000"], ["81.44000000", "7.39800000"], ["81.45000000", "3.64700000"]], "_local_ts_utc": "2026-06-01T07:49:05.291944+00:00"}
{"e": "depthUpdate", "E": 1780300146495, "s": "SOLUSDT", "U": 29045637951, "u": 29045637997, "b": [["80.64000000", "1030.39700000"], ["80.63000000", "510.93100000"], ["80.62000000", "313.82500000"], ["80.61000000", "441.05500000"], ["80.59000000", "124.68300000"], ["80.57000000", "212.49500000"], ["80.41000000", "94.13600000"], ["80.36000000", "496.22200000"]], "a": [["80.65000000", "318.41000000"], ["80.66000000", "1134.99800000"], ["80.67000000", "342.73800000"], ["80.68000000", "280.03600000"], ["80.77000000", "338.01900000"], ["80.99000000", "1219.72900000"], ["81.23000000", "41.47500000"]], "_local_ts_utc": "2026-06-01T07:49:05.391942+00:00"}
{"e": "depthUpdate", "E": 1780300146595, "s": "SOLUSDT", "U": 29045637998, "u": 29045638028, "b": [["80.63000000", "460.27200000"], ["80.59000000", "248.91700000"], ["80.46000000", "1522.95700000"], ["79.70000000", "479.27600000"], ["79.53000000", "20.40000000"], ["79.04000000", "21.62700000"], ["78.56000000", "35.73300000"]], "a": [["80.65000000", "224.36600000"], ["80.66000000", "1198.06000000"], ["80.67000000", "402.87300000"], ["80.68000000", "281.46600000"], ["80.72000000", "298.55500000"], ["97.27000000", "7.80200000"]], "_local_ts_utc": "2026-06-01T07:49:05.491928+00:00"}
{"e": "depthUpdate", "E": 1780300146695, "s": "SOLUSDT", "U": 29045638029, "u": 29045638054, "b": [["80.63000000", "447.73700000"], ["80.61000000", "1959.28500000"], ["80.58000000", "2172.75700000"], ["80.55000000", "1778.74800000"], ["79.93000000", "110.44400000"], ["79.03000000", "5.05000000"], ["78.63000000", "21.27900000"]], "a": [["80.65000000", "3.10700000"], ["80.66000000", "1134.86200000"], ["80.67000000", "403.43300000"], ["80.68000000", "279.00300000"], ["80.73000000", "1917.05600000"], ["80.95000000", "456.60500000"]], "_local_ts_utc": "2026-06-01T07:49:05.591930+00:00"}
{"e": "depthUpdate", "E": 1780300146795, "s": "SOLUSDT", "U": 29045638055, "u": 29045638085, "b": [["80.64000000", "1030.46600000"], ["80.63000000", "447.73700000"], ["80.58000000", "2172.45700000"], ["79.95000000", "267.23400000"], ["79.71000000", "41.83800000"], ["79.06000000", "16.06700000"], ["78.62000000", "28.93100000"], ["78.57000000", "91.81400000"]], "a": [["80.65000000", "292.25300000"], ["80.66000000", "1135.06200000"], ["80.67000000", "405.75200000"], ["80.68000000", "279.00300000"], ["80.72000000", "298.55500000"], ["80.73000000", "1916.92000000"], ["97.68000000", "10.09900000"]], "_local_ts_utc": "2026-06-01T07:49:05.691927+00:00"}
{"e": "depthUpdate", "E": 1780300146895, "s": "SOLUSDT", "U": 29045638086, "u": 29045638098, "b": [["80.64000000", "1042.86700000"], ["79.53000000", "17.28800000"]], "a": [["80.65000000", "357.81900000"], ["80.72000000", "298.41900000"]], "_local_ts_utc": "2026-06-01T07:49:05.791486+00:00"}
{"e": "depthUpdate", "E": 1780300146995, "s": "SOLUSDT", "U": 29045638099, "u": 29045638132, "b": [["80.64000000", "1042.73100000"], ["80.63000000", "445.86900000"], ["80.62000000", "315.82500000"], ["80.61000000", "1971.70000000"], ["80.57000000", "212.63100000"], ["78.62000000", "32.10500000"]], "a": [["80.65000000", "357.73000000"], ["80.66000000", "1196.12400000"], ["80.67000000", "342.81400000"], ["80.72000000", "298.41900000"]], "_local_ts_utc": "2026-06-01T07:49:05.891926+00:00"}
{"e": "depthUpdate", "E": 1780300147095, "s": "SOLUSDT", "U": 29045638133, "u": 29045638176, "b": [["80.64000000", "979.30500000"], ["80.63000000", "691.57500000"], ["80.62000000", "904.37700000"], ["80.61000000", "2296.03700000"], ["80.60000000", "1478.45600000"], ["80.59000000", "897.39500000"], ["80.57000000", "405.01100000"], ["80.56000000", "661.38700000"]], "a": [["80.65000000", "358.69400000"], ["80.66000000", "1322.76800000"], ["80.67000000", "701.18900000"], ["80.68000000", "437.74600000"], ["80.69000000", "570.08700000"], ["80.70000000", "906.60500000"], ["98.08000000", "34.20800000"]], "_local_ts_utc": "2026-06-01T07:49:05.991936+00:00"}
{"e": "depthUpdate", "E": 1780300147195, "s": "SOLUSDT", "U": 29045638177, "u": 29045638279, "b": [["80.64000000", "343.35200000"], ["80.63000000", "752.89100000"], ["80.62000000", "890.37700000"], ["80.61000000", "2297.62200000"], ["80.59000000", "901.18500000"], ["80.58000000", "2085.13700000"], ["80.57000000", "405.14700000"], ["78.62000000", "35.27900000"]], "a": [["80.65000000", "549.65800000"], ["80.66000000", "1269.70600000"], ["80.67000000", "688.17800000"], ["80.71000000", "365.29400000"], ["80.72000000", "870.88800000"], ["80.73000000", "1916.53700000"]], "_local_ts_utc": "2026-06-01T07:49:06.091928+00:00"}
{"e": "depthUpdate", "E": 1780300147295, "s": "SOLUSDT", "U": 29045638280, "u": 29045638315, "b": [["80.64000000", "455.57300000"], ["80.63000000", "806.11400000"], ["80.62000000", "891.05500000"], ["80.60000000", "1404.01000000"], ["80.59000000", "975.94000000"], ["80.58000000", "2236.00400000"], ["79.70000000", "473.06600000"], ["79.53000000", "11.06400000"], ["79.04000000", "15.36500000"], ["78.63000000", "18.13200000"]], "a": [["80.65000000", "480.42300000"], ["80.66000000", "1344.06900000"], ["80.68000000", "465.78800000"], ["80.70000000", "1061.19500000"], ["80.71000000", "524.65900000"], ["98.49000000", "51.95300000"]], "_local_ts_utc": "2026-06-01T07:49:06.191923+00:00"}
{"e": "depthUpdate", "E": 1780300147395, "s": "SOLUSDT", "U": 29045638316, "u": 29045638359, "b": [["80.64000000", "517.86000000"], ["80.63000000", "583.84100000"], ["80.60000000", "1228.97700000"], ["80.57000000", "250.88400000"], ["80.54000000", "737.23900000"], ["80.51000000", "2544.74300000"], ["80.47000000", "1704.30300000"], ["80.32000000", "959.37200000"], ["80.11000000", "62.84900000"], ["80.06000000", "71.32000000"], ["79.93000000", "107.34800000"], ["79.04000000", "12.23400000"], ["79.03000000", "8.20700000"], ["79.02000000", "116.47600000"], ["78.63000000", "14.98500000"], ["78.22000000", "23.95200000"]], "a": [["80.65000000", "375.16400000"], ["80.66000000", "1338.85500000"], ["80.68000000", "396.43500000"], ["80.70000000", "1061.26400000"], ["80.72000000", "870.88800000"], ["81.14000000", "44.26900000"]], "_local_ts_utc": "2026-06-01T07:49:06.291924+00:00"}
{"e": "depthUpdate", "E": 1780300147495, "s": "SOLUSDT", "U": 29045638360, "u": 29045638387, "b": [["80.55000000", "1998.81400000"], ["80.53000000", "2422.92000000"], ["80.52000000", "1183.10900000"], ["80.50000000", "2980.48800000"], ["80.49000000", "159.72800000"], ["80.48000000", "1065.63400000"], ["80.47000000", "1249.70000000"], ["80.41000000", "498.21800000"], ["80.36000000", "91.88900000"], ["79.93000000", "104.25200000"], ["79.70000000", "469.96100000"], ["79.53000000", "7.95200000"], ["78.56000000", "29.38100000"]], "a": [["80.70000000", "909.52800000"]], "_local_ts_utc": "2026-06-01T07:49:06.391931+00:00"}
{"e": "depthUpdate", "E": 1780300147595, "s": "SOLUSDT", "U": 29045638388, "u": 29045638421, "b": [["80.64000000", "493.21700000"], ["80.63000000", "518.77700000"], ["80.62000000", "889.05300000"], ["80.61000000", "2297.68700000"], ["80.60000000", "1231.10900000"], ["80.59000000", "978.00700000"], ["79.93000000", "101.15600000"], ["79.53000000", "4.84000000"], ["79.04000000", "9.10300000"], ["78.63000000", "11.83800000"]], "a": [["80.65000000", "378.49400000"], ["80.66000000", "1337.82200000"], ["80.67000000", "687.14500000"], ["80.68000000", "397.46700000"], ["80.69000000", "571.12000000"], ["80.70000000", "910.56100000"], ["98.89000000", "275.11800000"]], "_local_ts_utc": "2026-06-01T07:49:06.491927+00:00"}
{"e": "depthUpdate", "E": 1780300147695, "s": "SOLUSDT", "U": 29045638422, "u": 29045638460, "b": [["80.64000000", "668.42400000"], ["80.63000000", "595.96300000"], ["80.62000000", "889.12000000"], ["80.60000000", "1229.04200000"], ["80.59000000", "972.15000000"], ["79.70000000", "466.85600000"]], "a": [["80.65000000", "217.09800000"], ["80.66000000", "398.52500000"], ["80.67000000", "690.93300000"], ["80.68000000", "396.43500000"], ["80.69000000", "570.08700000"], ["80.70000000", "944.92100000"], ["80.71000000", "365.29400000"], ["80.72000000", "871.02400000"]], "_local_ts_utc": "2026-06-01T07:49:06.592292+00:00"}
{"e": "depthUpdate", "E": 1780300147795, "s": "SOLUSDT", "U": 29045638461, "u": 29045638494, "b": [["80.64000000", "579.94800000"], ["80.63000000", "588.92200000"], ["80.62000000", "891.12000000"]], "a": [["80.65000000", "309.65400000"], ["80.66000000", "277.88300000"], ["80.67000000", "485.82100000"], ["80.68000000", "657.06000000"], ["80.72000000", "870.88800000"], ["99.29000000", "8.63100000"]], "_local_ts_utc": "2026-06-01T07:49:06.691934+00:00"}
{"e": "depthUpdate", "E": 1780300147895, "s": "SOLUSDT", "U": 29045638495, "u": 29045638517, "b": [["80.64000000", "497.07600000"], ["80.63000000", "585.15500000"], ["80.62000000", "889.05300000"], ["80.60000000", "1231.10900000"], ["80.59000000", "974.21700000"], ["80.58000000", "2085.13700000"], ["79.93000000", "98.06000000"], ["78.62000000", "38.45300000"]], "a": [["80.65000000", "372.59500000"], ["80.66000000", "278.01000000"], ["80.67000000", "484.78800000"], ["80.68000000", "658.09200000"], ["80.69000000", "571.12000000"], ["80.70000000", "945.95400000"]], "_local_ts_utc": "2026-06-01T07:49:06.791923+00:00"}
{"e": "depthUpdate", "E": 1780300147995, "s": "SOLUSDT", "U": 29045638518, "u": 29045638523, "b": [["80.60000000", "1243.52400000"], ["80.57000000", "400.90100000"]], "a": [["80.65000000", "307.83500000"], ["80.68000000", "658.29200000"], ["83.69000000", "8.24300000"]], "_local_ts_utc": "2026-06-01T07:49:06.891920+00:00"}
{"e": "depthUpdate", "E": 1780300148095, "s": "SOLUSDT", "U": 29045638524, "u": 29045638567, "b": [["80.64000000", "493.28600000"], ["80.63000000", "582.40200000"], ["80.62000000", "891.12000000"], ["80.60000000", "1241.45700000"], ["80.59000000", "975.94000000"], ["80.58000000", "2121.80700000"], ["80.57000000", "400.90100000"], ["80.29000000", "7.93100000"], ["78.62000000", "41.62700000"]], "a": [["80.65000000", "428.25700000"], ["80.66000000", "281.66400000"], ["80.67000000", "487.06200000"], ["80.68000000", "657.26000000"], ["80.69000000", "570.28700000"], ["80.70000000", "984.04000000"]], "_local_ts_utc": "2026-06-01T07:49:06.991591+00:00"}
{"e": "depthUpdate", "E": 1780300148195, "s": "SOLUSDT", "U": 29045638568, "u": 29045638605, "b": [["80.64000000", "611.25500000"], ["80.63000000", "590.12600000"], ["80.62000000", "889.12000000"], ["80.60000000", "1229.04200000"], ["80.56000000", "708.74500000"], ["80.55000000", "1817.13700000"], ["80.53000000", "2186.47000000"], ["80.52000000", "817.66000000"], ["80.50000000", "2959.27600000"], ["70.65000000", "0.18200000"]], "a": [["80.65000000", "265.54800000"], ["80.66000000", "280.26600000"], ["80.72000000", "870.88800000"], ["86.40000000", "876.39800000"]], "_local_ts_utc": "2026-06-01T07:49:07.091728+00:00"}
{"e": "depthUpdate", "E": 1780300148295, "s": "SOLUSDT", "U": 29045638606, "u": 29045638635, "b": [["80.64000000", "615.04500000"], ["80.63000000", "589.96800000"], ["80.62000000", "887.05300000"], ["80.60000000", "1231.10900000"], ["80.59000000", "974.21700000"], ["80.28000000", "110.08500000"]], "a": [["80.65000000", "264.00600000"], ["80.66000000", "275.07500000"], ["80.67000000", "489.59800000"], ["80.68000000", "658.29200000"], ["80.69000000", "617.69400000"], ["80.70000000", "985.07300000"], ["80.72000000", "871.02400000"]], "_local_ts_utc": "2026-06-01T07:49:07.191930+00:00"}
{"e": "depthUpdate", "E": 1780300148395, "s": "SOLUSDT", "U": 29045638636, "u": 29045638677, "b": [["80.64000000", "690.50800000"], ["80.63000000", "522.22100000"], ["80.62000000", "889.12000000"], ["80.60000000", "1229.04200000"], ["80.59000000", "972.15000000"], ["80.49000000", "265.28100000"], ["80.48000000", "1065.20000000"], ["80.27000000", "50.67000000"], ["80.25000000", "274.46100000"], ["80.24000000", "42.13900000"], ["80.05000000", "619.66400000"], ["79.85000000", "45.71400000"], ["79.84000000", "7.11000000"]], "a": [["80.65000000", "190.19400000"], ["80.66000000", "213.04600000"], ["80.67000000", "805.95500000"], ["80.68000000", "396.63500000"], ["80.69000000", "616.66100000"], ["80.70000000", "985.81800000"], ["83.47000000", "43.46900000"]], "_local_ts_utc": "2026-06-01T07:49:07.292047+00:00"}
{"e": "depthUpdate", "E": 1780300148495, "s": "SOLUSDT", "U": 29045638678, "u": 29045638689, "b": [["80.63000000", "522.28400000"], ["80.48000000", "1213.52700000"], ["80.47000000", "1704.30300000"]], "a": [["80.66000000", "307.03100000"], ["80.67000000", "754.99400000"], ["80.73000000", "1954.92600000"]], "_local_ts_utc": "2026-06-01T07:49:07.391933+00:00"}
{"e": "depthUpdate", "E": 1780300148595, "s": "SOLUSDT", "U": 29045638690, "u": 29045638728, "b": [["80.64000000", "690.50800000"], ["80.63000000", "522.28400000"], ["80.62000000", "903.12000000"], ["80.61000000", "2283.68700000"], ["80.58000000", "2085.13700000"], ["80.57000000", "250.88400000"], ["80.55000000", "1829.52300000"]], "a": [["80.65000000", "124.90100000"], ["80.66000000", "293.03100000"], ["80.67000000", "693.70800000"], ["80.70000000", "834.22400000"], ["80.78000000", "1629.34400000"]], "_local_ts_utc": "2026-06-01T07:49:07.491424+00:00"}
{"e": "depthUpdate", "E": 1780300148695, "s": "SOLUSDT", "U": 29045638729, "u": 29045639021, "b": [["80.66000000", "1461.71900000"], ["80.65000000", "1047.78600000"], ["80.64000000", "417.18500000"], ["80.63000000", "669.32800000"], ["80.62000000", "886.92800000"], ["80.61000000", "2316.79100000"], ["80.60000000", "1165.18700000"], ["80.59000000", "912.01400000"], ["80.58000000", "2085.00100000"], ["80.57000000", "251.62300000"], ["80.56000000", "708.24500000"], ["80.55000000", "1826.77900000"], ["80.53000000", "2145.69600000"], ["80.52000000", "701.30200000"], ["80.51000000", "2641.36000000"], ["80.48000000", "1079.90100000"], ["80.46000000", "1667.33900000"], ["80.43000000", "93.48800000"], ["80.42000000", "9.71100000"], ["80.40000000", "540.47800000"], ["80.24000000", "42.07600000"], ["79.89000000", "12.82700000"], ["79.46000000", "506.44200000"], ["70.65000000", "0.10200000"]], "a": [["80.65000000", "0.00000000"], ["80.66000000", "0.00000000"], ["80.67000000", "325.24500000"], ["80.68000000", "667.19900000"], ["80.69000000", "573.61700000"], ["80.70000000", "837.43000000"], ["80.71000000", "521.76600000"], ["80.72000000", "874.68500000"], ["80.73000000", "1699.11300000"], ["80.75000000", "257.27100000"], ["80.76000000", "729.44100000"], ["80.80000000", "236.63900000"], ["80.86000000", "1090.95000000"], ["81.41000000", "3.93900000"], ["81.42000000", "5.15200000"]], "_local_ts_utc": "2026-06-01T07:49:07.591929+00:00"}
{"e": "depthUpdate", "E": 1780300148795, "s": "SOLUSDT", "U": 29045639022, "u": 29045639111, "b": [["80.66000000", "1424.08300000"], ["80.65000000", "965.16200000"], ["80.64000000", "587.25000000"], ["80.63000000", "499.36300000"], ["80.62000000", "694.11000000"], ["80.57000000", "251.68600000"], ["80.55000000", "1814.44300000"], ["80.37000000", "9.87700000"], ["79.90000000", "683.43000000"], ["78.62000000", "44.80100000"], ["78.22000000", "27.14200000"]], "a": [["80.67000000", "424.51300000"], ["80.68000000", "502.32600000"], ["80.69000000", "841.57100000"], ["80.70000000", "877.08900000"], ["80.71000000", "523.81300000"], ["80.72000000", "874.56200000"], ["80.73000000", "1780.10200000"], ["80.74000000", "416.13700000"], ["80.75000000", "295.66000000"], ["80.76000000", "561.43900000"], ["80.77000000", "465.22000000"], ["80.78000000", "1798.89600000"], ["80.80000000", "100.28200000"], ["80.90000000", "132.60100000"], ["80.99000000", "1219.65000000"], ["81.01000000", "44.43000000"], ["81.13000000", "4.36300000"], ["81.23000000", "41.38500000"], ["81.25000000", "56.78400000"], ["81.45000000", "3.26900000"], ["81.47000000", "1.22600000"]], "_local_ts_utc": "2026-06-01T07:49:07.692016+00:00"}
{"e": "depthUpdate", "E": 1780300148895, "s": "SOLUSDT", "U": 29045639112, "u": 29045639136, "b": [["80.66000000", "1485.61600000"], ["80.65000000", "967.16200000"], ["80.64000000", "585.25000000"], ["80.59000000", "911.71400000"], ["80.44000000", "502.12600000"], ["80.41000000", "94.13600000"], ["78.22000000", "30.33200000"]], "a": [["80.67000000", "331.83900000"], ["80.68000000", "504.32600000"], ["80.69000000", "901.32900000"], ["80.70000000", "879.88800000"], ["80.74000000", "416.27300000"], ["80.75000000", "334.04900000"], ["80.77000000", "426.83100000"], ["80.79000000", "234.82900000"], ["80.92000000", "749.39900000"]], "_local_ts_utc": "2026-06-01T07:49:07.791765+00:00"}
{"e": "depthUpdate", "E": 1780300148995, "s": "SOLUSDT", "U": 29045639137, "u": 29045639353, "b": [["80.67000000", "1202.14900000"], ["80.66000000", "839.26700000"], ["80.65000000", "897.41400000"], ["80.64000000", "511.29900000"], ["80.63000000", "495.18500000"], ["80.62000000", "700.02700000"], ["80.61000000", "2448.73900000"], ["80.60000000", "1165.05100000"], ["80.59000000", "1055.99700000"], ["80.58000000", "2084.50100000"], ["80.49000000", "160.21900000"], ["80.48000000", "955.49400000"]], "a": [["80.67000000", "0.00000000"], ["80.68000000", "483.14700000"], ["80.69000000", "502.91200000"], ["80.70000000", "893.78200000"], ["80.71000000", "372.15700000"], ["80.72000000", "876.67400000"], ["80.73000000", "1784.09500000"], ["80.74000000", "454.66200000"], ["80.75000000", "286.45700000"], ["80.76000000", "225.31300000"], ["80.77000000", "475.04800000"], ["80.79000000", "573.93300000"], ["80.80000000", "67.52000000"], ["80.84000000", "58.84500000"], ["80.89000000", "322.40400000"], ["81.08000000", "35.27000000"]], "_local_ts_utc": "2026-06-01T07:49:07.891929+00:00"}
{"e": "depthUpdate", "E": 1780300149095, "s": "SOLUSDT", "U": 29045639354, "u": 29045639416, "b": [["80.67000000", "748.29100000"], ["80.66000000", "872.14400000"], ["80.65000000", "1092.20600000"], ["80.64000000", "395.63300000"], ["80.62000000", "687.61000000"], ["80.60000000", "1165.18700000"], ["79.91000000", "4.52000000"]], "a": [["80.68000000", "584.04100000"], ["80.69000000", "557.54800000"], ["80.70000000", "595.93500000"], ["80.71000000", "979.63100000"], ["80.75000000", "286.32100000"], ["80.76000000", "327.44300000"], ["80.77000000", "502.43400000"], ["80.79000000", "573.86500000"], ["80.80000000", "237.19600000"], ["80.84000000", "91.26800000"], ["81.01000000", "44.35100000"], ["81.02000000", "44.30000000"], ["81.16000000", "42.01700000"], ["81.25000000", "56.69400000"], ["81.26000000", "48.15900000"], ["81.43000000", "6.80600000"], ["81.47000000", "0.84800000"], ["81.48000000", "4.44200000"]], "_local_ts_utc": "2026-06-01T07:49:07.991915+00:00"}
{"e": "depthUpdate", "E": 1780300149195, "s": "SOLUSDT", "U": 29045639417, "u": 29045639524, "b": [["80.67000000", "31.87100000"], ["80.66000000", "371.46200000"], ["80.65000000", "1136.68700000"], ["80.64000000", "387.63300000"], ["80.63000000", "511.82800000"], ["80.62000000", "691.40000000"], ["80.61000000", "2440.99200000"], ["80.59000000", "1056.13300000"], ["78.22000000", "33.52200000"]], "a": [["80.68000000", "792.90700000"], ["80.69000000", "513.25600000"], ["80.70000000", "648.94700000"], ["80.72000000", "879.55500000"], ["80.73000000", "1780.10200000"], ["80.75000000", "351.29900000"], ["80.76000000", "285.58400000"], ["80.77000000", "307.23400000"], ["80.80000000", "237.26400000"]], "_local_ts_utc": "2026-06-01T07:49:08.091916+00:00"}
{"e": "depthUpdate", "E": 1780300149295, "s": "SOLUSDT", "U": 29045639525, "u": 29045639682, "b": [["80.67000000", "0.00000000"], ["80.66000000", "1.05000000"], ["80.65000000", "510.01400000"], ["80.64000000", "560.54100000"], ["80.63000000", "499.82800000"], ["80.62000000", "704.85000000"], ["80.61000000", "839.37300000"], ["80.58000000", "2084.63700000"], ["80.57000000", "252.71600000"], ["80.48000000", "1079.89100000"], ["79.03000000", "11.36400000"]], "a": [["80.67000000", "1337.65400000"], ["80.68000000", "656.42700000"], ["80.69000000", "675.06800000"], ["80.70000000", "651.24700000"], ["80.71000000", "730.11600000"], ["80.72000000", "875.82900000"], ["80.74000000", "481.64200000"], ["80.75000000", "350.92700000"], ["80.77000000", "208.52600000"], ["80.86000000", "1232.41200000"], ["80.89000000", "175.75800000"], ["81.08000000", "35.20800000"], ["81.84000000", "3.31200000"], ["81.86000000", "488.19600000"]], "_local_ts_utc": "2026-06-01T07:49:08.191747+00:00"}
{"e": "depthUpdate", "E": 1780300149395, "s": "SOLUSDT", "U": 29045639683, "u": 29045639823, "b": [["80.66000000", "0.00000000"], ["80.65000000", "625.69100000"], ["80.64000000", "448.62100000"], ["80.63000000", "589.48800000"], ["80.62000000", "254.07700000"], ["80.61000000", "802.77900000"], ["80.56000000", "708.74500000"], ["80.50000000", "2979.37500000"], ["80.49000000", "211.38400000"], ["79.91000000", "4.58300000"], ["79.90000000", "683.49300000"]], "a": [["80.66000000", "663.37900000"], ["80.67000000", "689.14800000"], ["80.68000000", "644.18500000"], ["80.69000000", "671.47900000"], ["80.70000000", "649.31900000"], ["80.71000000", "726.34500000"], ["80.72000000", "870.90100000"], ["80.73000000", "1779.96600000"], ["80.74000000", "628.05500000"], ["80.75000000", "285.94900000"], ["80.76000000", "225.31300000"], ["80.77000000", "170.13700000"], ["80.80000000", "237.19600000"], ["81.02000000", "44.22100000"], ["81.06000000", "52.87400000"], ["81.10000000", "258.56200000"], ["81.25000000", "56.78400000"], ["81.26000000", "48.06900000"], ["81.35000000", "6.66100000"], ["81.42000000", "5.08900000"], ["81.43000000", "6.74300000"], ["81.46000000", "237.74700000"], ["81.47000000", "1.22600000"], ["81.48000000", "4.06400000"], ["81.51000000", "2.45200000"]], "_local_ts_utc": "2026-06-01T07:49:08.292402+00:00"}
{"e": "depthUpdate", "E": 1780300149495, "s": "SOLUSDT", "U": 29045639824, "u": 29045639847, "b": [["80.64000000", "505.88400000"], ["80.63000000", "666.59000000"], ["80.62000000", "243.15400000"], ["80.60000000", "1168.97700000"], ["80.50000000", "2971.89900000"]], "a": [["80.66000000", "665.45900000"], ["80.67000000", "675.47800000"], ["80.68000000", "647.06600000"], ["80.69000000", "668.99800000"], ["80.79000000", "573.93300000"], ["81.01000000", "44.43000000"]], "_local_ts_utc": "2026-06-01T07:49:08.391918+00:00"}
{"e": "depthUpdate", "E": 1780300149595, "s": "SOLUSDT", "U": 29045639848, "u": 29045639865, "b": [["80.65000000", "239.40900000"], ["80.64000000", "503.89800000"], ["80.60000000", "1228.97700000"], ["80.59000000", "902.03300000"]], "a": [["80.66000000", "841.43900000"], ["80.67000000", "601.03800000"], ["80.68000000", "650.62300000"], ["80.70000000", "645.76600000"]], "_local_ts_utc": "2026-06-01T07:49:08.491752+00:00"}
{"e": "depthUpdate", "E": 1780300149695, "s": "SOLUSDT", "U": 29045639866, "u": 29045639890, "b": [["80.65000000", "397.48500000"], ["80.64000000", "446.24400000"], ["80.63000000", "698.78200000"], ["80.62000000", "240.79900000"], ["80.58000000", "2234.76700000"], ["70.65000000", "0.18200000"]], "a": [["80.66000000", "741.88900000"], ["80.67000000", "617.60400000"]], "_local_ts_utc": "2026-06-01T07:49:08.591913+00:00"}
{"e": "depthUpdate", "E": 1780300149795, "s": "SOLUSDT", "U": 29045639891, "u": 29045639913, "b": [["80.65000000", "163.83600000"], ["80.64000000", "440.83600000"], ["80.63000000", "696.78200000"], ["80.62000000", "242.79900000"], ["80.59000000", "909.78200000"], ["80.50000000", "2959.27600000"]], "a": [["80.66000000", "847.19100000"], ["80.67000000", "624.18800000"], ["80.74000000", "481.64200000"], ["88.73000000", "13.72400000"]], "_local_ts_utc": "2026-06-01T07:49:08.691923+00:00"}
{"e": "depthUpdate", "E": 1780300149895, "s": "SOLUSDT", "U": 29045639914, "u": 29045639950, "b": [["80.65000000", "358.38700000"], ["80.64000000", "440.83600000"], ["80.63000000", "692.72200000"], ["80.62000000", "240.79900000"], ["80.61000000", "802.36400000"], ["80.59000000", "919.60400000"], ["80.57000000", "252.71600000"], ["79.05000000", "117.90100000"], ["70.65000000", "0.10200000"]], "a": [["80.66000000", "847.32800000"], ["80.67000000", "807.32800000"], ["80.68000000", "1276.62700000"], ["80.69000000", "413.61500000"], ["88.73000000", "13.66200000"]], "_local_ts_utc": "2026-06-01T07:49:08.791911+00:00"}
{"e": "depthUpdate", "E": 1780300149995, "s": "SOLUSDT", "U": 29045639951, "u": 29045639964, "b": [["80.65000000", "358.45600000"], ["80.64000000", "507.01600000"], ["80.63000000", "688.96000000"], ["80.61000000", "814.77900000"], ["79.04000000", "12.26000000"]], "a": [["80.66000000", "742.02600000"], ["80.67000000", "804.78500000"], ["80.73000000", "1760.61300000"], ["80.74000000", "565.00100000"]], "_local_ts_utc": "2026-06-01T07:49:08.891915+00:00"}
{"e": "depthUpdate", "E": 1780300150095, "s": "SOLUSDT", "U": 29045639965, "u": 29045639987, "b": [["80.65000000", "539.62400000"], ["80.64000000", "449.54800000"], ["80.63000000", "689.02900000"], ["79.03000000", "14.52100000"], ["78.63000000", "15.01100000"]], "a": [["80.66000000", "697.25400000"], ["80.67000000", "864.60600000"], ["80.75000000", "256.96800000"], ["84.59000000", "27.42600000"]], "_local_ts_utc": "2026-06-01T07:49:08.991911+00:00"}
{"e": "depthUpdate", "E": 1780300150195, "s": "SOLUSDT", "U": 29045639988, "u": 29045639991, "b": [["80.65000000", "539.85700000"]], "a": [["80.66000000", "697.49100000"], ["80.67000000", "866.09900000"], ["80.94000000", "65.49600000"]], "_local_ts_utc": "2026-06-01T07:49:09.091691+00:00"}
{"e": "depthUpdate", "E": 1780300150295, "s": "SOLUSDT", "U": 29045639992, "u": 29045640050, "b": [["80.65000000", "548.74000000"], ["80.64000000", "463.58400000"], ["80.63000000", "687.02900000"], ["80.62000000", "677.86700000"], ["80.61000000", "2283.57200000"], ["80.58000000", "2235.13100000"], ["80.56000000", "708.24500000"]], "a": [["80.66000000", "193.89200000"], ["80.67000000", "675.53700000"], ["80.68000000", "924.41400000"], ["80.69000000", "413.61500000"], ["80.70000000", "644.52600000"], ["80.71000000", "878.56100000"], ["80.73000000", "1760.74900000"], ["80.74000000", "416.13700000"], ["80.94000000", "66.09500000"]], "_local_ts_utc": "2026-06-01T07:49:09.191920+00:00"}
{"e": "depthUpdate", "E": 1780300150395, "s": "SOLUSDT", "U": 29045640051, "u": 29045640102, "b": [["80.65000000", "619.52000000"], ["80.64000000", "405.48600000"], ["80.63000000", "701.02900000"], ["80.62000000", "663.86700000"], ["80.61000000", "2320.59400000"], ["80.60000000", "1233.23500000"]], "a": [["80.66000000", "14.22000000"], ["80.67000000", "584.01500000"], ["80.68000000", "999.67600000"], ["80.71000000", "882.19800000"], ["80.74000000", "416.50800000"]], "_local_ts_utc": "2026-06-01T07:49:09.291214+00:00"}
{"e": "depthUpdate", "E": 1780300150495, "s": "SOLUSDT", "U": 29045640103, "u": 29045640122, "b": [["80.65000000", "620.02000000"], ["80.64000000", "380.69000000"], ["80.59000000", "947.27000000"], ["80.57000000", "252.21600000"]], "a": [["80.66000000", "108.42000000"], ["80.67000000", "584.01500000"], ["80.68000000", "972.58800000"]], "_local_ts_utc": "2026-06-01T07:49:09.391318+00:00"}
{"e": "depthUpdate", "E": 1780300150595, "s": "SOLUSDT", "U": 29045640123, "u": 29045640150, "b": [["80.65000000", "632.35100000"], ["80.64000000", "387.68300000"], ["80.63000000", "701.15400000"], ["80.59000000", "919.60400000"]], "a": [["80.66000000", "261.04400000"], ["80.67000000", "584.09500000"], ["80.68000000", "974.45300000"], ["80.73000000", "1760.61300000"]], "_local_ts_utc": "2026-06-01T07:49:09.491191+00:00"}
{"e": "depthUpdate", "E": 1780300150695, "s": "SOLUSDT", "U": 29045640151, "u": 29045640165, "b": [["80.65000000", "529.16600000"], ["80.64000000", "384.55900000"], ["80.54000000", "735.08200000"], ["80.53000000", "2143.53900000"], ["80.51000000", "2645.67400000"]], "a": [["80.66000000", "261.04400000"], ["80.67000000", "587.62000000"], ["80.68000000", "970.82000000"]], "_local_ts_utc": "2026-06-01T07:49:09.592242+00:00"}
{"e": "depthUpdate", "E": 1780300150795, "s": "SOLUSDT", "U": 29045640166, "u": 29045640180, "b": [["80.65000000", "624.86700000"], ["80.64000000", "393.21000000"], ["78.63000000", "18.18400000"]], "a": [["80.66000000", "105.05800000"], ["80.67000000", "584.09500000"], ["80.68000000", "970.82000000"], ["80.69000000", "415.35500000"], ["80.73000000", "1760.74900000"]], "_local_ts_utc": "2026-06-01T07:49:09.691908+00:00"}
{"e": "depthUpdate", "E": 1780300150895, "s": "SOLUSDT", "U": 29045640181, "u": 29045640186, "b": [["79.04000000", "15.41700000"], ["78.23000000", "16.72500000"]], "a": [["80.67000000", "584.09500000"], ["80.68000000", "970.82000000"]], "_local_ts_utc": "2026-06-01T07:49:09.791907+00:00"}
{"e": "depthUpdate", "E": 1780300151095, "s": "SOLUSDT", "U": 29045640187, "u": 29045640192, "b": [["80.65000000", "626.06700000"], ["80.61000000", "2333.00900000"], ["80.58000000", "2085.00100000"], ["80.44000000", "98.19500000"], ["80.41000000", "498.21800000"]], "a": [["80.68000000", "972.31400000"]], "_local_ts_utc": "2026-06-01T07:49:09.990919+00:00"}
{"e": "depthUpdate", "E": 1780300151195, "s": "SOLUSDT", "U": 29045640193, "u": 29045640208, "b": [["80.65000000", "625.29600000"], ["80.64000000", "387.99100000"], ["80.61000000", "2320.59400000"]], "a": [["80.66000000", "260.90800000"], ["80.68000000", "975.91600000"], ["80.69000000", "414.85600000"]], "_local_ts_utc": "2026-06-01T07:49:10.091917+00:00"}
{"e": "depthUpdate", "E": 1780300151295, "s": "SOLUSDT", "U": 29045640209, "u": 29045640217, "b": [["80.64000000", "393.84100000"]], "a": [["80.66000000", "105.05800000"], ["80.68000000", "974.05400000"]], "_local_ts_utc": "2026-06-01T07:49:10.192111+00:00"}
{"e": "depthUpdate", "E": 1780300151395, "s": "SOLUSDT", "U": 29045640218, "u": 29045640220, "b": [["80.31000000", "1257.59900000"]], "a": [["80.71000000", "729.98200000"], ["80.83000000", "101.46400000"]], "_local_ts_utc": "2026-06-01T07:49:10.291905+00:00"}
{"e": "depthUpdate", "E": 1780300151495, "s": "SOLUSDT", "U": 29045640221, "u": 29045640244, "b": [["80.65000000", "516.99000000"], ["80.64000000", "384.77000000"], ["80.58000000", "2085.13700000"], ["78.23000000", "19.91500000"]], "a": [["80.66000000", "260.98000000"], ["80.67000000", "625.04500000"], ["80.68000000", "972.31400000"], ["80.73000000", "1760.61300000"]], "_local_ts_utc": "2026-06-01T07:49:10.391917+00:00"}
{"e": "depthUpdate", "E": 1780300151595, "s": "SOLUSDT", "U": 29045640245, "u": 29045640251, "b": [["80.65000000", "529.45700000"], ["80.58000000", "2085.00100000"], ["80.25000000", "274.66100000"], ["80.24000000", "42.27600000"], ["78.63000000", "21.35700000"]], "a": [], "_local_ts_utc": "2026-06-01T07:49:10.491901+00:00"}
{"e": "depthUpdate", "E": 1780300151695, "s": "SOLUSDT", "U": 29045640252, "u": 29045640262, "b": [["80.65000000", "466.46400000"], ["80.60000000", "1453.23500000"], ["80.59000000", "919.60400000"], ["80.50000000", "2739.27600000"], ["80.00000000", "23864.72300000"]], "a": [["80.72000000", "870.90100000"]], "_local_ts_utc": "2026-06-01T07:49:10.591272+00:00"}
{"e": "depthUpdate", "E": 1780300151795, "s": "SOLUSDT", "U": 29045640263, "u": 29045640282, "b": [["80.65000000", "642.80700000"], ["80.64000000", "455.51600000"], ["80.32000000", "8.01800000"]], "a": [["80.66000000", "161.06000000"], ["80.67000000", "684.37900000"], ["80.68000000", "911.45100000"], ["80.97000000", "138.60000000"]], "_local_ts_utc": "2026-06-01T07:49:10.691912+00:00"}
{"e": "depthUpdate", "E": 1780300151895, "s": "SOLUSDT", "U": 29045640283, "u": 29045640284, "b": [["80.65000000", "643.93100000"]], "a": [["80.66000000", "161.26200000"]], "_local_ts_utc": "2026-06-01T07:49:10.791898+00:00"}
{"e": "depthUpdate", "E": 1780300151995, "s": "SOLUSDT", "U": 29045640285, "u": 29045640291, "b": [["80.61000000", "2333.00600000"], ["80.59000000", "1073.18600000"], ["80.34000000", "984.73200000"]], "a": [["80.66000000", "161.13000000"], ["80.71000000", "764.28800000"], ["80.72000000", "1024.01600000"], ["80.96000000", "2220.74100000"]], "_local_ts_utc": "2026-06-01T07:49:10.891901+00:00"}
{"e": "depthUpdate", "E": 1780300152095, "s": "SOLUSDT", "U": 29045640292, "u": 29045640293, "b": [], "a": [["80.67000000", "684.61900000"], ["81.05000000", "332.54900000"]], "_local_ts_utc": "2026-06-01T07:49:10.990942+00:00"}
{"e": "depthUpdate", "E": 1780300152195, "s": "SOLUSDT", "U": 29045640294, "u": 29045640307, "b": [["80.65000000", "507.70400000"], ["80.64000000", "453.64800000"], ["80.63000000", "703.15400000"], ["80.58000000", "2085.13700000"]], "a": [["80.66000000", "201.25300000"], ["80.67000000", "682.61900000"]], "_local_ts_utc": "2026-06-01T07:49:11.091908+00:00"}
{"e": "depthUpdate", "E": 1780300152295, "s": "SOLUSDT", "U": 29045640308, "u": 29045640549, "b": [["80.66000000", "1282.54700000"], ["80.65000000", "537.31500000"], ["80.64000000", "413.58600000"], ["80.63000000", "685.37300000"], ["80.62000000", "626.01500000"], ["80.61000000", "2393.29100000"], ["80.60000000", "1393.23500000"], ["80.59000000", "1073.05000000"], ["80.58000000", "2084.50100000"], ["80.55000000", "1814.37900000"], ["80.48000000", "955.49400000"], ["78.23000000", "23.10500000"]], "a": [["80.66000000", "0.00000000"], ["80.67000000", "1.62200000"], ["80.68000000", "436.57100000"], ["80.69000000", "706.01400000"], ["80.70000000", "660.05200000"], ["80.71000000", "735.03700000"], ["80.72000000", "340.84100000"], ["80.73000000", "279.54100000"], ["80.74000000", "416.64400000"], ["80.75000000", "257.10400000"], ["80.77000000", "1993.37800000"], ["80.82000000", "36.46600000"], ["81.11000000", "56.31000000"], ["81.42000000", "5.15200000"]], "_local_ts_utc": "2026-06-01T07:49:11.191190+00:00"}
{"e": "depthUpdate", "E": 1780300152395, "s": "SOLUSDT", "U": 29045640550, "u": 29045640721, "b": [["80.67000000", "1048.75500000"], ["80.66000000", "717.85200000"], ["80.65000000", "632.22200000"], ["80.64000000", "374.36700000"], ["80.63000000", "695.26000000"], ["80.62000000", "622.09700000"], ["80.61000000", "2380.87900000"], ["80.60000000", "1420.24300000"], ["80.59000000", "1054.97900000"], ["80.53000000", "2193.05000000"], ["80.52000000", "846.93000000"], ["80.49000000", "160.21900000"], ["80.48000000", "809.81200000"], ["80.46000000", "1667.16100000"], ["79.91000000", "4.52000000"], ["79.90000000", "683.43000000"]], "a": [["80.67000000", "0.00000000"], ["80.68000000", "7.29000000"], ["80.69000000", "377.20900000"], ["80.70000000", "780.76600000"], ["80.71000000", "320.05700000"], ["80.72000000", "342.95300000"], ["80.73000000", "286.05900000"], ["80.76000000", "225.71400000"], ["80.89000000", "175.58000000"], ["81.06000000", "52.61600000"], ["81.08000000", "35.27000000"], ["81.09000000", "1.14700000"], ["81.43000000", "6.80600000"], ["81.46000000", "237.48900000"], ["81.50000000", "24.95600000"]], "_local_ts_utc": "2026-06-01T07:49:11.291902+00:00"}
{"e": "depthUpdate", "E": 1780300152495, "s": "SOLUSDT", "U": 29045640722, "u": 29045640755, "b": [["80.66000000", "709.68500000"], ["80.65000000", "632.62200000"], ["80.63000000", "502.11000000"], ["80.60000000", "1419.94300000"], ["80.56000000", "708.30800000"], ["80.53000000", "2193.56700000"], ["80.49000000", "159.72800000"], ["80.46000000", "1667.33900000"], ["80.44000000", "100.32000000"], ["80.42000000", "7.58600000"]], "a": [["80.68000000", "6.71700000"], ["80.69000000", "363.74700000"], ["80.70000000", "625.90000000"], ["80.71000000", "589.62000000"], ["80.79000000", "573.92700000"], ["80.82000000", "35.99500000"], ["80.86000000", "1232.84600000"], ["80.93000000", "657.60700000"], ["81.00000000", "85.95500000"], ["81.01000000", "44.35100000"], ["81.25000000", "56.69400000"], ["81.47000000", "0.84800000"], ["81.48000000", "4.44200000"]], "_local_ts_utc": "2026-06-01T07:49:11.391903+00:00"}
{"e": "depthUpdate", "E": 1780300152596, "s": "SOLUSDT", "U": 29045640756, "u": 29045640850, "b": [["80.68000000", "1309.79400000"], ["80.67000000", "720.08400000"], ["80.66000000", "765.27200000"], ["80.65000000", "635.19800000"], ["80.64000000", "374.46000000"], ["80.63000000", "495.61400000"], ["80.62000000", "562.22100000"], ["80.61000000", "2380.74300000"], ["80.58000000", "2082.26900000"], ["80.55000000", "1816.48800000"], ["80.49000000", "298.69000000"], ["80.46000000", "1522.95700000"], ["79.49000000", "525.18700000"], ["79.46000000", "31.04500000"]], "a": [["80.68000000", "0.00000000"], ["80.69000000", "223.95600000"], ["80.70000000", "530.59500000"], ["80.73000000", "286.05700000"], ["80.80000000", "237.26400000"], ["80.84000000", "91.76800000"], ["80.91000000", "82.10500000"], ["81.02000000", "44.30000000"], ["81.05000000", "332.04900000"], ["81.26000000", "48.15900000"]], "_local_ts_utc": "2026-06-01T07:49:11.492820+00:00"}
{"e": "depthUpdate", "E": 1780300152695, "s": "SOLUSDT", "U": 29045640851, "u": 29045641188, "b": [["80.69000000", "931.23100000"], ["80.68000000", "781.50600000"], ["80.67000000", "510.66400000"], ["80.66000000", "980.56600000"], ["80.65000000", "1021.97600000"], ["80.64000000", "2209.83600000"], ["80.63000000", "566.20600000"], ["80.62000000", "563.20100000"], ["80.60000000", "1411.69500000"], ["80.58000000", "2251.20200000"], ["80.55000000", "1854.10100000"], ["80.54000000", "831.66300000"], ["80.53000000", "2144.05600000"], ["80.52000000", "678.86700000"], ["80.51000000", "2424.70400000"], ["80.50000000", "2756.74800000"], ["80.44000000", "98.19500000"], ["80.29000000", "38.13100000"], ["80.28000000", "110.02200000"], ["80.25000000", "244.46100000"], ["80.21000000", "1461.97200000"], ["80.16000000", "190.22800000"], ["80.10000000", "864.70600000"], ["79.92000000", "33.85000000"]], "a": [["80.69000000", "0.00000000"], ["80.70000000", "470.82700000"], ["80.71000000", "456.94300000"], ["80.72000000", "149.51300000"], ["80.73000000", "362.32000000"], ["80.74000000", "683.26200000"], ["80.75000000", "350.53800000"], ["80.76000000", "807.79700000"], ["80.77000000", "1681.66600000"], ["80.78000000", "645.38000000"], ["80.79000000", "968.48000000"], ["80.80000000", "1295.69600000"], ["80.81000000", "871.88700000"], ["80.82000000", "5.70800000"], ["80.86000000", "213.78500000"], ["80.88000000", "1763.90000000"], ["80.90000000", "287.47700000"], ["80.92000000", "1627.21500000"], ["81.12000000", "124.36800000"], ["81.17000000", "1247.13700000"], ["81.44000000", "7.46100000"], ["81.45000000", "3.33200000"]], "_local_ts_utc": "2026-06-01T07:49:11.590900+00:00"}
{"e": "depthUpdate", "E": 1780300152795, "s": "SOLUSDT", "U": 29045641189, "u": 29045641432, "b": [["80.70000000", "1077.83100000"], ["80.69000000", "551.75100000"], ["80.68000000", "909.83100000"], ["80.67000000", "707.87300000"], ["80.66000000", "773.47600000"], ["80.65000000", "981.73800000"], ["80.64000000", "2146.78200000"], ["80.63000000", "474.42800000"], ["80.61000000", "2380.24300000"], ["80.60000000", "1927.30800000"], ["80.59000000", "2755.46900000"], ["80.58000000", "2251.27600000"], ["80.54000000", "332.81500000"], ["80.53000000", "463.67600000"], ["80.51000000", "2416.45600000"], ["80.50000000", "2748.60500000"], ["80.49000000", "702.37000000"], ["80.47000000", "1288.08900000"], ["80.46000000", "1525.08200000"], ["80.41000000", "94.13600000"], ["80.26000000", "242.98300000"], ["80.21000000", "1266.34800000"], ["79.93000000", "97.99700000"], ["79.50000000", "2445.91100000"], ["79.49000000", "13.54900000"]], "a": [["80.70000000", "0.00000000"], ["80.71000000", "555.89300000"], ["80.72000000", "163.26800000"], ["80.73000000", "317.30100000"], ["80.74000000", "522.60200000"], ["80.75000000", "297.57000000"], ["80.76000000", "806.68300000"], ["80.77000000", "1650.47200000"], ["80.78000000", "614.14300000"], ["80.79000000", "629.30200000"], ["80.80000000", "1257.23900000"], ["80.81000000", "1043.04900000"], ["80.82000000", "175.63200000"], ["80.83000000", "101.53800000"], ["80.85000000", "397.76600000"], ["80.90000000", "411.25400000"], ["80.93000000", "149.66200000"], ["80.94000000", "574.04000000"], ["81.02000000", "44.22100000"], ["81.26000000", "48.06900000"], ["81.46000000", "237.55200000"], ["81.48000000", "4.06400000"], ["81.50000000", "25.33400000"]], "_local_ts_utc": "2026-06-01T07:49:11.692678+00:00"}
{"e": "depthUpdate", "E": 1780300152895, "s": "SOLUSDT", "U": 29045641433, "u": 29045641469, "b": [["80.70000000", "950.91000000"], ["80.69000000", "543.66100000"], ["80.67000000", "515.11200000"], ["80.65000000", "977.85600000"], ["80.55000000", "1801.46500000"], ["80.47000000", "1321.08800000"], ["80.43000000", "60.59000000"], ["79.94000000", "11.22500000"], ["79.80000000", "997.88800000"]], "a": [["80.71000000", "528.56800000"], ["80.72000000", "244.43000000"], ["80.76000000", "806.23700000"], ["80.78000000", "601.97800000"], ["80.80000000", "917.76300000"], ["80.81000000", "1043.49500000"], ["80.82000000", "515.60500000"], ["81.04000000", "165.30300000"], ["81.28000000", "69.08500000"], ["81.50000000", "24.95600000"], ["81.51000000", "2.83000000"]], "_local_ts_utc": "2026-06-01T07:49:11.791757+00:00"}
{"e": "depthUpdate", "E": 1780300152995, "s": "SOLUSDT", "U": 29045641470, "u": 29045641501, "b": [["80.70000000", "958.85500000"], ["80.69000000", "528.07500000"], ["80.68000000", "868.84500000"], ["80.67000000", "513.91800000"], ["80.66000000", "773.47600000"], ["80.65000000", "976.73200000"], ["80.64000000", "2147.08200000"], ["80.59000000", "2601.88700000"]], "a": [["80.71000000", "621.40100000"], ["80.72000000", "211.31400000"], ["80.73000000", "268.90500000"], ["80.74000000", "422.87400000"], ["80.75000000", "193.93600000"], ["80.77000000", "1804.89700000"], ["80.80000000", "1011.00200000"], ["80.83000000", "101.60600000"], ["81.05000000", "332.12800000"], ["81.29000000", "988.74900000"]], "_local_ts_utc": "2026-06-01T07:49:11.891261+00:00"}
{"e": "depthUpdate", "E": 1780300153095, "s": "SOLUSDT", "U": 29045641502, "u": 29045641518, "b": [["80.70000000", "960.14100000"], ["80.69000000", "529.13100000"], ["80.67000000", "428.85400000"], ["80.66000000", "597.17900000"], ["80.64000000", "2147.45400000"], ["80.55000000", "1889.35100000"]], "a": [["80.71000000", "537.56800000"], ["80.72000000", "280.18300000"], ["80.73000000", "506.40400000"], ["80.78000000", "550.25800000"], ["80.80000000", "1093.40500000"]], "_local_ts_utc": "2026-06-01T07:49:11.991906+00:00"}
{"e": "depthUpdate", "E": 1780300153195, "s": "SOLUSDT", "U": 29045641519, "u": 29045641533, "b": [["80.70000000", "1023.20300000"], ["80.69000000", "470.29700000"], ["80.66000000", "690.52300000"], ["80.38000000", "60.67300000"]], "a": [["80.71000000", "381.71800000"], ["80.72000000", "272.82800000"], ["80.73000000", "511.34300000"], ["80.80000000", "753.43200000"], ["80.82000000", "855.45300000"], ["80.94000000", "66.09500000"]], "_local_ts_utc": "2026-06-01T07:49:12.091894+00:00"}
{"e": "depthUpdate", "E": 1780300153295, "s": "SOLUSDT", "U": 29045641534, "u": 29045641559, "b": [["80.70000000", "1027.83900000"], ["80.69000000", "474.28200000"], ["80.68000000", "866.90800000"], ["80.63000000", "625.70500000"], ["80.43000000", "568.53500000"]], "a": [["80.71000000", "217.34500000"], ["80.72000000", "274.82800000"], ["80.73000000", "569.46600000"], ["80.74000000", "440.92800000"], ["80.75000000", "163.38700000"], ["80.76000000", "809.87400000"], ["80.78000000", "550.39400000"], ["80.79000000", "549.08500000"], ["80.80000000", "854.02800000"], ["80.99000000", "1727.59500000"]], "_local_ts_utc": "2026-06-01T07:49:12.191905+00:00"}
{"e": "depthUpdate", "E": 1780300153395, "s": "SOLUSDT", "U": 29045641560, "u": 29045641700, "b": [["80.71000000", "904.16100000"], ["80.70000000", "660.18200000"], ["80.69000000", "462.08500000"], ["80.68000000", "880.64100000"], ["80.67000000", "510.82700000"], ["80.66000000", "690.52000000"], ["80.65000000", "1100.93500000"], ["80.63000000", "615.94400000"], ["80.62000000", "562.70100000"], ["80.58000000", "2212.88700000"], ["80.57000000", "127.95900000"], ["80.53000000", "505.04200000"], ["80.52000000", "819.64500000"], ["80.49000000", "563.40800000"], ["80.44000000", "98.13200000"], ["80.42000000", "7.52300000"], ["80.41000000", "94.07300000"], ["80.40000000", "1601.78500000"], ["80.39000000", "1384.02200000"], ["80.35000000", "1101.58900000"], ["80.32000000", "172.90100000"], ["80.25000000", "79.57800000"], ["79.51000000", "492.77700000"], ["79.50000000", "1998.43800000"]], "a": [["80.71000000", "0.00000000"], ["80.72000000", "166.25300000"], ["80.73000000", "229.78600000"], ["80.74000000", "450.36200000"], ["80.75000000", "521.34600000"], ["80.77000000", "1650.47200000"], ["80.79000000", "529.21400000"], ["80.80000000", "343.88100000"], ["80.82000000", "1365.47500000"], ["80.88000000", "525.92400000"], ["80.93000000", "149.72400000"], ["80.96000000", "2220.80300000"], ["80.99000000", "666.28800000"], ["81.04000000", "1226.61000000"], ["81.05000000", "43.05800000"], ["81.12000000", "413.50000000"], ["81.13000000", "1238.58500000"], ["81.75000000", "3.01500000"]], "_local_ts_utc": "2026-06-01T07:49:12.291908+00:00"}
{"e": "depthUpdate", "E": 1780300153495, "s": "SOLUSDT", "U": 29045641701, "u": 29045641835, "b": [["80.71000000", "1387.39700000"], ["80.70000000", "444.58600000"], ["80.69000000", "604.42800000"], ["80.68000000", "752.49800000"], ["80.67000000", "520.65100000"], ["80.66000000", "694.31900000"], ["80.65000000", "1002.13400000"], ["80.64000000", "2037.35600000"], ["80.58000000", "2212.95000000"], ["80.57000000", "128.46400000"], ["80.53000000", "504.52500000"], ["80.48000000", "811.93700000"], ["80.46000000", "1522.95700000"], ["79.95000000", "267.17100000"]], "a": [["80.72000000", "462.16700000"], ["80.73000000", "188.98400000"], ["80.74000000", "523.04100000"], ["80.75000000", "516.41800000"], ["80.76000000", "811.98600000"], ["80.77000000", "1656.99000000"], ["80.78000000", "511.27500000"], ["80.79000000", "387.38000000"], ["80.81000000", "1150.80000000"], ["80.83000000", "101.53800000"], ["80.84000000", "59.34500000"], ["80.86000000", "213.35100000"], ["80.88000000", "559.25000000"], ["80.90000000", "411.68800000"], ["80.98000000", "47.41500000"], ["81.01000000", "44.41300000"], ["81.05000000", "42.97900000"], ["81.29000000", "988.65900000"], ["81.47000000", "0.91100000"], ["81.51000000", "2.45200000"], ["82.80000000", "96.24700000"]], "_local_ts_utc": "2026-06-01T07:49:12.391909+00:00"}
{"e": "depthUpdate", "E": 1780300153595, "s": "SOLUSDT", "U": 29045641836, "u": 29045642097, "b": [["80.72000000", "1287.66900000"], ["80.71000000", "700.92300000"], ["80.70000000", "419.63900000"], ["80.69000000", "770.35100000"], ["80.68000000", "1235.25000000"], ["80.67000000", "2356.99000000"], ["80.66000000", "582.41800000"], ["80.65000000", "909.39100000"], ["80.63000000", "408.33500000"], ["80.55000000", "1839.85400000"], ["80.54000000", "236.23400000"], ["80.47000000", "1282.69900000"], ["80.45000000", "37.05400000"], ["80.42000000", "980.06800000"], ["80.35000000", "128.68100000"], ["80.33000000", "105.00100000"], ["80.29000000", "7.93100000"], ["80.19000000", "69.02800000"], ["80.15000000", "56.56800000"], ["79.92000000", "32.46700000"], ["79.67000000", "3.43800000"]], "a": [["80.72000000", "0.00000000"], ["80.73000000", "754.63700000"], ["80.74000000", "148.10900000"], ["80.75000000", "442.63300000"], ["80.76000000", "862.12500000"], ["80.77000000", "1609.73300000"], ["80.78000000", "570.40500000"], ["80.79000000", "82.67000000"], ["80.80000000", "283.78500000"], ["80.81000000", "966.71100000"], ["80.82000000", "1594.28500000"], ["80.83000000", "441.51100000"], ["80.84000000", "260.03800000"], ["80.88000000", "622.51400000"], ["80.92000000", "1750.96100000"], ["81.06000000", "52.69500000"], ["81.08000000", "5.07000000"], ["81.13000000", "1268.78500000"], ["81.30000000", "45.36800000"], ["81.48000000", "4.12700000"], ["81.52000000", "6.16400000"]], "_local_ts_utc": "2026-06-01T07:49:12.491897+00:00"}
{"e": "depthUpdate", "E": 1780300153695, "s": "SOLUSDT", "U": 29045642098, "u": 29045642144, "b": [["80.72000000", "1250.76000000"], ["80.71000000", "683.78400000"], ["80.70000000", "612.30000000"], ["80.69000000", "693.25900000"], ["80.63000000", "407.83500000"], ["80.58000000", "2240.41500000"], ["80.57000000", "225.01200000"], ["80.48000000", "381.03600000"], ["80.46000000", "1522.77900000"], ["79.96000000", "2.20500000"]], "a": [["80.73000000", "542.20200000"], ["80.74000000", "222.23100000"], ["80.75000000", "475.14800000"], ["80.77000000", "1661.07100000"], ["80.80000000", "352.12700000"], ["80.81000000", "927.31200000"], ["80.82000000", "1084.51300000"], ["80.84000000", "742.46300000"], ["80.85000000", "405.96600000"], ["80.93000000", "149.54600000"]], "_local_ts_utc": "2026-06-01T07:49:12.592241+00:00"}
{"e": "depthUpdate", "E": 1780300153795, "s": "SOLUSDT", "U": 29045642145, "u": 29045642150, "b": [["80.72000000", "1258.76700000"], ["80.71000000", "746.84600000"], ["80.69000000", "577.63100000"], ["80.63000000", "256.55800000"]], "a": [["80.74000000", "240.33100000"]], "_local_ts_utc": "2026-06-01T07:49:12.691891+00:00"}
{"e": "depthUpdate", "E": 1780300153895, "s": "SOLUSDT", "U": 29045642151, "u": 29045642188, "b": [["80.72000000", "1166.90100000"], ["80.71000000", "696.95500000"], ["80.70000000", "565.79700000"], ["80.69000000", "427.29700000"], ["80.67000000", "2353.10800000"], ["80.42000000", "1004.75800000"]], "a": [["80.73000000", "100.14500000"], ["80.74000000", "242.33100000"], ["80.75000000", "469.09200000"], ["80.76000000", "861.38700000"], ["80.78000000", "598.71900000"], ["80.80000000", "352.26300000"], ["80.81000000", "787.57400000"], ["80.82000000", "744.66500000"], ["80.84000000", "1084.42200000"], ["81.02000000", "44.28300000"]], "_local_ts_utc": "2026-06-01T07:49:12.791892+00:00"}
{"e": "depthUpdate", "E": 1780300153995, "s": "SOLUSDT", "U": 29045642189, "u": 29045642222, "b": [["80.71000000", "696.95500000"], ["80.70000000", "565.86100000"], ["80.69000000", "439.70200000"], ["80.66000000", "637.10900000"], ["80.65000000", "1056.55800000"], ["80.58000000", "2248.64900000"], ["80.54000000", "228.01700000"], ["80.53000000", "908.00500000"], ["80.50000000", "2731.13300000"], ["80.49000000", "159.72800000"], ["79.98000000", "15.10900000"]], "a": [["80.73000000", "352.53900000"], ["80.74000000", "120.70800000"], ["80.75000000", "329.39700000"], ["80.76000000", "1130.79900000"], ["80.79000000", "82.67000000"], ["80.80000000", "201.51800000"], ["80.81000000", "632.52100000"], ["80.83000000", "543.89900000"]], "_local_ts_utc": "2026-06-01T07:49:12.891312+00:00"}
{"e": "depthUpdate", "E": 1780300154095, "s": "SOLUSDT", "U": 29045642223, "u": 29045642242, "b": [["80.72000000", "1166.97000000"], ["80.71000000", "696.95500000"], ["80.70000000", "565.93000000"], ["80.51000000", "2478.92200000"], ["79.10000000", "103.90300000"]], "a": [["80.73000000", "196.82600000"], ["80.75000000", "326.28700000"], ["80.76000000", "1133.57600000"], ["80.77000000", "179.86300000"], ["80.78000000", "448.15000000"], ["80.81000000", "2236.22300000"], ["80.82000000", "788.03500000"], ["80.83000000", "619.45600000"]], "_local_ts_utc": "2026-06-01T07:49:12.991901+00:00"}
{"e": "depthUpdate", "E": 1780300154195, "s": "SOLUSDT", "U": 29045642243, "u": 29045642439, "b": [["80.73000000", "1172.70800000"], ["80.72000000", "625.63600000"], ["80.71000000", "641.85200000"], ["80.70000000", "582.87700000"], ["80.69000000", "460.01100000"], ["80.68000000", "1235.18500000"], ["80.67000000", "2438.58400000"], ["80.66000000", "539.81600000"], ["80.64000000", "2036.85600000"], ["80.63000000", "167.27300000"], ["80.57000000", "370.64000000"], ["80.55000000", "1715.56400000"], ["80.52000000", "673.35600000"], ["80.32000000", "172.83800000"], ["80.26000000", "1483.29900000"], ["80.21000000", "25.30400000"], ["79.11000000", "11.31500000"]], "a": [["80.73000000", "0.00000000"], ["80.74000000", "486.91400000"], ["80.75000000", "182.59200000"], ["80.76000000", "626.64600000"], ["80.77000000", "177.81600000"], ["80.78000000", "476.67700000"], ["80.79000000", "208.16100000"], ["80.80000000", "668.54100000"], ["80.81000000", "2044.81300000"], ["80.82000000", "318.38800000"], ["80.83000000", "671.02300000"], ["80.84000000", "1157.05300000"], ["80.85000000", "918.96700000"], ["80.88000000", "559.25000000"], ["80.90000000", "256.81200000"], ["80.94000000", "201.14900000"], ["81.17000000", "6.09300000"], ["81.22000000", "1283.98900000"], ["81.49000000", "5.32700000"], ["81.52000000", "7.75700000"]], "_local_ts_utc": "2026-06-01T07:49:13.091898+00:00"}
{"e": "depthUpdate", "E": 1780300154295, "s": "SOLUSDT", "U": 29045642440, "u": 29045642513, "b": [["80.73000000", "768.98800000"], ["80.72000000", "582.01300000"], ["80.71000000", "834.50200000"], ["80.70000000", "505.84800000"], ["80.69000000", "447.60600000"], ["80.68000000", "1231.30300000"], ["80.66000000", "540.68300000"], ["80.65000000", "1059.46500000"], ["80.61000000", "2380.17900000"], ["80.58000000", "2288.60700000"], ["80.53000000", "866.63900000"], ["80.34000000", "984.97600000"], ["80.25000000", "79.33300000"], ["79.97000000", "10.15200000"]], "a": [["80.74000000", "466.33000000"], ["80.75000000", "171.74900000"], ["80.76000000", "619.05400000"], ["80.77000000", "218.31600000"], ["80.78000000", "517.35100000"], ["80.79000000", "360.51100000"], ["80.81000000", "2044.88800000"], ["80.82000000", "326.50900000"], ["80.84000000", "1156.98500000"], ["81.06000000", "52.61600000"], ["81.08000000", "5.14900000"], ["81.30000000", "45.27800000"], ["81.32000000", "99.05600000"], ["81.52000000", "7.37900000"], ["81.54000000", "10.22400000"]], "_local_ts_utc": "2026-06-01T07:49:13.192897+00:00"}
{"e": "depthUpdate", "E": 1780300154395, "s": "SOLUSDT", "U": 29045642514, "u": 29045642533, "b": [["80.73000000", "776.84700000"], ["80.72000000", "645.07500000"], ["80.71000000", "782.49500000"], ["80.70000000", "390.27900000"], ["80.66000000", "540.68300000"], ["80.58000000", "2288.60700000"], ["80.50000000", "2713.95600000"], ["80.49000000", "55.53500000"]], "a": [["80.75000000", "123.74900000"], ["80.86000000", "213.41900000"]], "_local_ts_utc": "2026-06-01T07:49:13.291895+00:00"}
{"e": "depthUpdate", "E": 1780300154495, "s": "SOLUSDT", "U": 29045642534, "u": 29045642582, "b": [["80.73000000", "839.90900000"], ["80.72000000", "603.73400000"], ["80.71000000", "780.95700000"], ["80.69000000", "447.20600000"], ["80.58000000", "2288.54400000"]], "a": [["80.74000000", "100.82500000"], ["80.75000000", "319.33300000"], ["80.76000000", "622.81800000"], ["80.78000000", "455.71500000"], ["80.79000000", "272.17000000"], ["80.81000000", "1921.11400000"], ["80.83000000", "715.91100000"], ["80.84000000", "1269.00800000"], ["80.92000000", "1526.00500000"], ["80.93000000", "149.48400000"], ["81.01000000", "44.47500000"], ["81.04000000", "1226.67200000"], ["81.10000000", "46.02700000"], ["81.20000000", "200.73500000"]], "_local_ts_utc": "2026-06-01T07:49:13.391902+00:00"}
{"e": "depthUpdate", "E": 1780300154598, "s": "SOLUSDT", "U": 29045642583, "u": 29045642791, "b": [["80.74000000", "1279.09100000"], ["80.73000000", "566.63900000"], ["80.72000000", "654.14700000"], ["80.71000000", "794.83300000"], ["80.70000000", "734.23800000"], ["80.69000000", "447.07900000"], ["80.68000000", "1205.64300000"], ["80.67000000", "2281.00500000"], ["80.66000000", "375.57900000"], ["80.65000000", "1058.96500000"], ["80.64000000", "2037.50200000"], ["80.62000000", "562.77500000"], ["80.58000000", "2288.47000000"], ["80.55000000", "1816.30300000"], ["80.54000000", "170.46800000"], ["80.53000000", "790.61200000"], ["80.52000000", "532.57800000"], ["80.50000000", "2716.08100000"], ["80.48000000", "378.91100000"], ["80.32000000", "171.59900000"], ["80.31000000", "1465.52000000"], ["79.98000000", "15.04600000"], ["79.92000000", "33.83600000"], ["79.54000000", "549.87500000"], ["79.51000000", "44.42700000"], ["79.12000000", "5.36600000"]], "a": [["80.74000000", "0.00000000"], ["80.75000000", "156.93700000"], ["80.76000000", "210.84100000"], ["80.77000000", "441.13900000"], ["80.78000000", "420.86700000"], ["80.79000000", "124.76200000"], ["80.80000000", "724.98800000"], ["80.81000000", "2154.94900000"], ["80.82000000", "283.27500000"], ["80.83000000", "375.86400000"], ["80.84000000", "1245.63100000"], ["80.85000000", "1260.95900000"], ["80.86000000", "384.46100000"], ["80.87000000", "37.29100000"], ["81.50000000", "25.01900000"], ["87.92000000", "77.02300000"]], "_local_ts_utc": "2026-06-01T07:49:13.494916+00:00"}
{"e": "depthUpdate", "E": 1780300154695, "s": "SOLUSDT", "U": 29045642792, "u": 29045643040, "b": [["80.75000000", "563.30800000"], ["80.74000000", "528.31400000"], ["80.73000000", "479.15500000"], ["80.72000000", "741.20400000"], ["80.71000000", "1165.40200000"], ["80.70000000", "2215.31900000"], ["80.69000000", "407.08500000"], ["80.68000000", "1096.41500000"], ["80.66000000", "375.07900000"], ["80.65000000", "1165.24700000"], ["80.64000000", "2208.54400000"], ["80.60000000", "1927.83300000"], ["80.59000000", "2440.04000000"], ["80.58000000", "2118.42100000"], ["80.57000000", "273.58700000"], ["80.55000000", "1906.05300000"], ["80.51000000", "2511.28300000"], ["80.47000000", "1249.70000000"], ["80.44000000", "8.13200000"], ["80.34000000", "33.62200000"], ["80.26000000", "1280.47500000"], ["79.55000000", "898.60400000"], ["79.54000000", "44.73600000"], ["79.13000000", "25.46000000"]], "a": [["80.75000000", "0.00000000"], ["80.76000000", "496.92500000"], ["80.77000000", "177.28800000"], ["80.78000000", "338.90200000"], ["80.79000000", "160.46100000"], ["80.80000000", "824.90600000"], ["80.81000000", "2115.44700000"], ["80.82000000", "54.46500000"], ["80.83000000", "229.74400000"], ["80.84000000", "620.77300000"], ["80.85000000", "1609.76100000"], ["80.86000000", "765.82200000"], ["80.87000000", "550.41700000"], ["80.88000000", "525.92400000"], ["80.90000000", "256.37800000"], ["80.93000000", "149.91800000"], ["80.96000000", "1269.44900000"], ["81.08000000", "5.07000000"], ["81.09000000", "1.00900000"], ["81.16000000", "42.07900000"], ["81.18000000", "271.03600000"], ["81.32000000", "98.96600000"], ["81.33000000", "62.58300000"], ["81.54000000", "9.84700000"], ["81.55000000", "7.01400000"]], "_local_ts_utc": "2026-06-01T07:49:13.591888+00:00"}
{"e": "depthUpdate", "E": 1780300154795, "s": "SOLUSDT", "U": 29045643041, "u": 29045643220, "b": [["80.75000000", "698.05000000"], ["80.74000000", "694.73900000"], ["80.73000000", "694.05700000"], ["80.72000000", "649.93400000"], ["80.71000000", "1064.26100000"], ["80.70000000", "2243.48900000"], ["80.69000000", "531.16400000"], ["80.66000000", "469.61100000"], ["80.65000000", "1595.75800000"], ["80.64000000", "3481.29400000"], ["80.62000000", "534.47400000"], ["80.61000000", "2129.63400000"], ["80.60000000", "1412.22000000"], ["80.59000000", "909.59900000"], ["80.54000000", "170.37500000"], ["79.99000000", "339.38100000"], ["72.67000000", "9.06600000"]], "a": [["80.76000000", "410.66400000"], ["80.77000000", "294.95900000"], ["80.78000000", "364.07300000"], ["80.79000000", "155.81400000"], ["80.80000000", "826.95300000"], ["80.81000000", "2115.00100000"], ["80.82000000", "57.06500000"], ["80.83000000", "199.44400000"], ["80.84000000", "439.77600000"], ["80.85000000", "861.42600000"], ["80.86000000", "1696.81200000"], ["80.87000000", "398.30700000"], ["80.92000000", "1558.94100000"], ["81.51000000", "2.51500000"]], "_local_ts_utc": "2026-06-01T07:49:13.691887+00:00"}
{"e": "depthUpdate", "E": 1780300154895, "s": "SOLUSDT", "U": 29045643221, "u": 29045643243, "b": [["80.75000000", "770.56100000"], ["80.74000000", "628.75300000"], ["80.71000000", "1074.08500000"], ["80.67000000", "2271.18100000"], ["80.66000000", "376.26700000"], ["80.60000000", "1508.73200000"], ["80.48000000", "886.85600000"], ["80.43000000", "1011.94400000"], ["72.67000000", "8.99000000"]], "a": [["80.77000000", "259.18700000"], ["80.83000000", "187.26700000"], ["80.99000000", "158.34300000"], ["81.04000000", "1734.61700000"], ["81.07000000", "993.72600000"]], "_local_ts_utc": "2026-06-01T07:49:13.791891+00:00"}
{"e": "depthUpdate", "E": 1780300154995, "s": "SOLUSDT", "U": 29045643244, "u": 29045643254, "b": [["80.74000000", "630.75300000"], ["80.73000000", "692.05700000"], ["80.70000000", "2255.89300000"], ["80.68000000", "1243.34800000"], ["80.65000000", "1445.68400000"]], "a": [["80.76000000", "408.52800000"], ["80.77000000", "261.18700000"], ["80.80000000", "675.18900000"], ["80.83000000", "187.40300000"], ["81.09000000", "1.07400000"]], "_local_ts_utc": "2026-06-01T07:49:13.890888+00:00"}
{"e": "depthUpdate", "E": 1780300155095, "s": "SOLUSDT", "U": 29045643255, "u": 29045643309, "b": [["80.75000000", "774.44300000"], ["80.74000000", "636.21600000"], ["80.73000000", "623.92700000"], ["80.72000000", "510.97700000"], ["80.71000000", "1083.35300000"], ["80.70000000", "2252.01100000"], ["80.69000000", "531.28700000"], ["80.66000000", "281.73500000"], ["80.62000000", "534.35000000"], ["80.61000000", "2287.21500000"], ["80.59000000", "909.52400000"], ["80.57000000", "273.51200000"], ["80.52000000", "178.93500000"], ["80.51000000", "1633.06600000"], ["80.50000000", "2713.95600000"]], "a": [["80.76000000", "393.17200000"], ["80.77000000", "255.68900000"], ["80.78000000", "366.40000000"], ["80.79000000", "120.11500000"], ["80.81000000", "2135.67200000"], ["80.82000000", "57.06500000"], ["80.83000000", "132.22700000"], ["80.84000000", "370.84100000"], ["80.85000000", "900.33700000"], ["80.86000000", "1767.53100000"], ["80.87000000", "499.46400000"], ["81.00000000", "53.25300000"], ["81.07000000", "1026.82700000"]], "_local_ts_utc": "2026-06-01T07:49:13.991851+00:00"}
{"e": "depthUpdate", "E": 1780300155195, "s": "SOLUSDT", "U": 29045643310, "u": 29045643331, "b": [["80.75000000", "774.44300000"], ["80.74000000", "610.46500000"], ["80.68000000", "1244.46300000"], ["80.66000000", "282.63600000"], ["80.62000000", "533.23400000"], ["80.56000000", "1174.29200000"], ["80.53000000", "387.13200000"], ["80.51000000", "1570.60000000"], ["80.25000000", "78.52700000"]], "a": [["80.76000000", "395.17200000"], ["80.77000000", "257.88400000"], ["80.78000000", "364.07300000"], ["80.84000000", "383.46800000"], ["80.92000000", "1621.91000000"]], "_local_ts_utc": "2026-06-01T07:49:14.091898+00:00"}
{"e": "depthUpdate", "E": 1780300155295, "s": "SOLUSDT", "U": 29045643332, "u": 29045643454, "b": [["80.75000000", "131.27400000"], ["80.74000000", "524.95700000"], ["80.73000000", "609.00200000"], ["80.72000000", "439.80000000"], ["80.71000000", "747.72700000"], ["80.70000000", "762.28100000"], ["80.69000000", "544.43700000"], ["80.68000000", "1097.66600000"], ["80.65000000", "1175.34500000"], ["80.64000000", "3030.10900000"], ["80.63000000", "367.98600000"], ["80.62000000", "1255.00600000"], ["80.43000000", "1011.94400000"], ["79.97000000", "13.27200000"]], "a": [["80.76000000", "689.23700000"], ["80.77000000", "233.24400000"], ["80.78000000", "361.07300000"], ["80.81000000", "2132.03500000"]], "_local_ts_utc": "2026-06-01T07:49:14.191884+00:00"}
{"e": "depthUpdate", "E": 1780300155395, "s": "SOLUSDT", "U": 29045643455, "u": 29045643481, "b": [["80.75000000", "306.26900000"], ["80.74000000", "691.28100000"], ["80.73000000", "611.80000000"], ["80.72000000", "437.93900000"], ["80.68000000", "1244.39100000"]], "a": [["80.76000000", "624.54600000"], ["80.77000000", "229.23900000"], ["80.81000000", "2174.74200000"], ["80.82000000", "207.43300000"]], "_local_ts_utc": "2026-06-01T07:49:14.291885+00:00"}
{"e": "depthUpdate", "E": 1780300155495, "s": "SOLUSDT", "U": 29045643482, "u": 29045643532, "b": [["80.75000000", "368.47100000"], ["80.74000000", "630.93100000"], ["80.73000000", "612.26900000"], ["80.71000000", "747.32700000"], ["80.70000000", "762.34300000"], ["80.68000000", "1244.25500000"], ["80.66000000", "283.13600000"], ["80.64000000", "3029.80900000"], ["80.63000000", "372.41200000"], ["80.48000000", "886.79300000"], ["80.46000000", "1522.71500000"], ["80.45000000", "36.99100000"], ["79.11000000", "14.46900000"], ["78.62000000", "38.45300000"]], "a": [["80.76000000", "670.95700000"], ["80.77000000", "227.93200000"], ["80.78000000", "361.47300000"], ["80.79000000", "166.48900000"], ["80.82000000", "237.74200000"], ["80.83000000", "147.88800000"], ["81.01000000", "44.41300000"]], "_local_ts_utc": "2026-06-01T07:49:14.391884+00:00"}
{"e": "depthUpdate", "E": 1780300155595, "s": "SOLUSDT", "U": 29045643533, "u": 29045643561, "b": [["80.75000000", "74.18600000"], ["80.74000000", "524.45700000"], ["80.73000000", "666.23200000"], ["80.72000000", "487.48900000"], ["80.68000000", "1097.66600000"]], "a": [["80.76000000", "675.03600000"], ["80.77000000", "230.50100000"], ["80.78000000", "361.53700000"]], "_local_ts_utc": "2026-06-01T07:49:14.491883+00:00"}
{"e": "depthUpdate", "E": 1780300155695, "s": "SOLUSDT", "U": 29045643562, "u": 29045643596, "b": [["80.75000000", "318.64700000"], ["80.74000000", "703.84300000"], ["80.73000000", "670.01500000"], ["80.72000000", "487.48900000"], ["80.70000000", "603.74300000"], ["80.67000000", "2425.91300000"], ["79.71000000", "43.22400000"]], "a": [["80.76000000", "661.78900000"], ["80.77000000", "230.75200000"], ["80.81000000", "2132.03500000"], ["80.82000000", "87.37400000"], ["80.93000000", "161.75800000"], ["81.01000000", "269.36900000"]], "_local_ts_utc": "2026-06-01T07:49:14.590888+00:00"}
{"e": "depthUpdate", "E": 1780300155795, "s": "SOLUSDT", "U": 29045643597, "u": 29045643684, "b": [["80.75000000", "318.41500000"], ["80.74000000", "710.66800000"], ["80.73000000", "666.45000000"], ["80.69000000", "540.55500000"], ["80.68000000", "1106.93400000"], ["80.66000000", "227.57800000"], ["80.65000000", "1085.23200000"], ["80.64000000", "2820.52300000"], ["80.63000000", "1985.07500000"], ["80.62000000", "533.23400000"], ["79.04000000", "12.26000000"]], "a": [["80.76000000", "661.65700000"], ["80.77000000", "229.82500000"], ["80.84000000", "409.16200000"], ["80.85000000", "1410.23500000"], ["80.86000000", "1745.44400000"], ["80.87000000", "138.51600000"], ["81.04000000", "1743.88500000"], ["81.11000000", "47.04200000"]], "_local_ts_utc": "2026-06-01T07:49:14.691882+00:00"}
{"e": "depthUpdate", "E": 1780300155895, "s": "SOLUSDT", "U": 29045643685, "u": 29045643699, "b": [["80.75000000", "380.47900000"], ["80.74000000", "651.97600000"], ["80.68000000", "1106.79800000"]], "a": [["80.76000000", "562.48000000"], ["80.77000000", "226.31300000"]], "_local_ts_utc": "2026-06-01T07:49:14.791564+00:00"}
{"e": "depthUpdate", "E": 1780300155995, "s": "SOLUSDT", "U": 29045643700, "u": 29045643733, "b": [["80.75000000", "127.59800000"], ["80.74000000", "581.05900000"], ["80.72000000", "489.24600000"], ["80.69000000", "540.85500000"], ["80.68000000", "1106.93400000"], ["79.70000000", "469.98700000"]], "a": [["80.76000000", "665.69200000"], ["80.77000000", "281.75000000"], ["80.78000000", "361.66100000"], ["80.81000000", "2283.92900000"]], "_local_ts_utc": "2026-06-01T07:49:14.891882+00:00"}
{"e": "depthUpdate", "E": 1780300156095, "s": "SOLUSDT", "U": 29045643734, "u": 29045643875, "b": [["80.75000000", "0.00000000"], ["80.74000000", "473.49800000"], ["80.73000000", "478.00100000"], ["80.72000000", "686.03600000"], ["80.71000000", "740.12300000"], ["80.70000000", "603.87000000"], ["80.67000000", "2426.04900000"], ["80.65000000", "1083.16600000"], ["80.64000000", "2818.45700000"], ["80.61000000", "2285.14800000"], ["80.57000000", "422.25100000"], ["80.52000000", "176.81000000"], ["80.50000000", "2716.08100000"], ["79.99000000", "339.44400000"], ["79.12000000", "5.36600000"]], "a": [["80.75000000", "786.10100000"], ["80.76000000", "532.88400000"], ["80.77000000", "198.98800000"], ["80.78000000", "360.02500000"], ["80.79000000", "168.88900000"], ["80.80000000", "675.12400000"], ["80.82000000", "87.23800000"], ["80.85000000", "1346.76000000"], ["80.87000000", "37.35900000"], ["81.12000000", "413.56500000"], ["81.16000000", "42.01700000"], ["81.51000000", "2.45200000"]], "_local_ts_utc": "2026-06-01T07:49:14.991884+00:00"}
{"e": "depthUpdate", "E": 1780300156195, "s": "SOLUSDT", "U": 29045643876, "u": 29045643889, "b": [["80.73000000", "541.06300000"], ["80.69000000", "539.79900000"], ["80.35000000", "129.48600000"], ["80.33000000", "105.00100000"], ["79.93000000", "98.21400000"], ["79.85000000", "45.46900000"]], "a": [["80.75000000", "619.28200000"], ["80.76000000", "532.40200000"]], "_local_ts_utc": "2026-06-01T07:49:15.091880+00:00"}
{"e": "depthUpdate", "E": 1780300156295, "s": "SOLUSDT", "U": 29045643890, "u": 29045643903, "b": [["80.74000000", "473.89400000"], ["80.73000000", "481.39800000"], ["80.72000000", "682.13600000"], ["80.70000000", "604.47900000"], ["80.67000000", "2425.91300000"], ["79.97000000", "16.39200000"]], "a": [["80.75000000", "528.86200000"], ["80.76000000", "527.03800000"]], "_local_ts_utc": "2026-06-01T07:49:15.190893+00:00"}
{"e": "depthUpdate", "E": 1780300156395, "s": "SOLUSDT", "U": 29045643904, "u": 29045643910, "b": [["80.74000000", "520.32400000"], ["80.73000000", "544.46000000"], ["80.69000000", "539.86200000"], ["78.62000000", "35.27900000"]], "a": [["80.75000000", "529.89300000"], ["80.76000000", "527.03800000"], ["80.77000000", "198.98800000"], ["80.78000000", "358.99400000"]], "_local_ts_utc": "2026-06-01T07:49:15.291625+00:00"}
{"e": "depthUpdate", "E": 1780300156495, "s": "SOLUSDT", "U": 29045643911, "u": 29045643939, "b": [["80.74000000", "680.54100000"], ["80.73000000", "486.57300000"], ["80.72000000", "680.13600000"], ["80.58000000", "2078.46300000"], ["80.57000000", "330.08200000"], ["80.56000000", "770.96200000"], ["80.54000000", "573.80500000"], ["79.54000000", "47.87300000"]], "a": [["80.75000000", "92.51900000"], ["80.76000000", "537.79200000"], ["80.77000000", "199.38800000"], ["80.78000000", "358.59400000"], ["80.82000000", "87.37400000"]], "_local_ts_utc": "2026-06-01T07:49:15.391878+00:00"}
{"e": "depthUpdate", "E": 1780300156595, "s": "SOLUSDT", "U": 29045643940, "u": 29045643961, "b": [["80.74000000", "689.75800000"], ["80.73000000", "500.13500000"], ["80.72000000", "679.80700000"], ["80.69000000", "539.92400000"], ["80.65000000", "1083.22800000"]], "a": [["80.75000000", "57.40100000"], ["80.76000000", "419.86300000"], ["80.77000000", "263.77600000"], ["80.78000000", "358.59400000"], ["80.83000000", "147.95000000"], ["81.07000000", "1026.88900000"]], "_local_ts_utc": "2026-06-01T07:49:15.491640+00:00"}
{"e": "depthUpdate", "E": 1780300156695, "s": "SOLUSDT", "U": 29045643962, "u": 29045644134, "b": [["80.75000000", "1325.14300000"], ["80.74000000", "628.27800000"], ["80.73000000", "535.71800000"], ["80.72000000", "733.82800000"], ["80.71000000", "1047.87900000"], ["80.70000000", "2085.56000000"], ["80.68000000", "1106.79800000"], ["80.66000000", "227.07800000"], ["80.63000000", "1970.62800000"], ["80.57000000", "301.85700000"], ["80.52000000", "178.93500000"], ["80.50000000", "2713.95600000"], ["79.99000000", "339.38100000"], ["79.97000000", "19.51200000"], ["79.70000000", "473.11800000"], ["79.54000000", "51.01000000"], ["79.13000000", "25.46000000"]], "a": [["80.75000000", "0.00000000"], ["80.76000000", "434.57900000"], ["80.77000000", "302.09200000"], ["80.78000000", "428.64200000"], ["80.79000000", "169.92000000"], ["80.80000000", "675.18900000"], ["80.81000000", "2135.67200000"], ["80.83000000", "148.08600000"], ["80.85000000", "1363.57800000"], ["81.16000000", "42.07900000"]], "_local_ts_utc": "2026-06-01T07:49:15.592487+00:00"}
{"e": "depthUpdate", "E": 1780300156795, "s": "SOLUSDT", "U": 29045644135, "u": 29045644151, "b": [["80.74000000", "657.21200000"], ["80.73000000", "687.31000000"], ["80.72000000", "541.31400000"], ["79.97000000", "22.63200000"], ["79.70000000", "476.24900000"]], "a": [["80.76000000", "434.48600000"], ["80.77000000", "239.03000000"], ["81.51000000", "2.51500000"]], "_local_ts_utc": "2026-06-01T07:49:15.692106+00:00"}
{"e": "depthUpdate", "E": 1780300156895, "s": "SOLUSDT", "U": 29045644152, "u": 29045644157, "b": [["80.75000000", "1334.09600000"], ["79.54000000", "54.14700000"], ["64.00000000", "5694.32900000"]], "a": [], "_local_ts_utc": "2026-06-01T07:49:15.792067+00:00"}
{"e": "depthUpdate", "E": 1780300156995, "s": "SOLUSDT", "U": 29045644158, "u": 29045644167, "b": [["80.75000000", "1321.61900000"], ["80.74000000", "659.21200000"], ["80.73000000", "685.31000000"], ["80.66000000", "230.18300000"]], "a": [["80.76000000", "432.48600000"], ["80.77000000", "259.13000000"], ["80.81000000", "2179.40800000"], ["80.82000000", "241.18800000"]], "_local_ts_utc": "2026-06-01T07:49:15.891400+00:00"}
{"e": "depthUpdate", "E": 1780300157095, "s": "SOLUSDT", "U": 29045644168, "u": 29045644172, "b": [["80.75000000", "1325.50100000"], ["80.73000000", "612.43900000"], ["80.70000000", "2081.67800000"]], "a": [["80.77000000", "231.69700000"], ["80.79000000", "169.98900000"]], "_local_ts_utc": "2026-06-01T07:49:15.992077+00:00"}
